{"ct":null,"SegmentType":null,"clk":"AIOMAQDMjwEAm4cB","heartbeatms":null,"pt":1780839742769,"initialclk":null,"mc":[{"rc":[{"tv":null,"batb":null,"spb":null,"bdatl":null,"trd":null,"spf":null,"ltp":null,"atb":null,"spl":null,"spn":null,"atl":[[1.1399999999999999,44322.160000000003]],"batl":null,"id":19924823,"hc":null,"bdatb":null}],"img":null,"tv":null,"con":null,"marketdefinition":null,"id":"1.258926623"}],"conflatems":null,"op":"mcm","id":3}
{"ct":null,"SegmentType":null,"clk":"AI6MAQDUjwEAoIcB","heartbeatms":null,"pt":1780839742871,"initialclk":null,"mc":[{"rc":[{"tv":null,"batb":null,"spb":null,"bdatl":null,"trd":null,"spf":null,"ltp":null,"atb":[[8.4000000000000004,96]],"spl":null,"spn":null,"atl":[[10.5,402.67000000000002]],"batl":null,"id":16570658,"hc":null,"bdatb":null},{"tv":null,"batb":null,"spb":null,"bdatl":null,"trd":null,"spf":null,"ltp":null,"atb":[[1.1000000000000001,51317.330000000002]],"spl":null,"spn":null,"atl":[[1.1399999999999999,46280.160000000003]],"batl":null,"id":19924823,"hc":null,"bdatb":null}],"img":null,"tv":null,"con":null,"marketdefinition":null,"id":"1.258926623"}],"conflatems":null,"op":"mcm","id":3}
{"ct":null,"SegmentType":null,"clk":"AKeMAQDujwEAtocB","heartbeatms":null,"pt":1780839743184,"initialclk":null,"mc":[{"rc":[{"tv":null,"batb":null,"spb":null,"bdatl":null,"trd":null,"spf":null,"ltp":null,"atb":[[8.5999999999999996,0]],"spl":null,"spn":null,"atl":null,"batl":null,"id":16570658,"hc":null,"bdatb":null},{"tv":null,"batb":null,"spb":null,"bdatl":null,"trd":null,"spf":null,"ltp":null,"atb":null,"spl":null,"spn":null,"atl":[[1.1399999999999999,46708.040000000001]],"batl":null,"id":19924823,"hc":null,"bdatb":null}],"img":null,"tv":null,"con":null,"marketdefinition":null,"id":"1.258926623"}],"conflatems":null,"op":"mcm","id":3}
{"ct":null,"SegmentType":null,"clk":"ALCMAQD3jwEAwIcB","heartbeatms":null,"pt":1780839743286,"initialclk":null,"mc":[{"rc":[{"tv":null,"batb":null,"spb":null,"bdatl":null,"trd":null,"spf":null,"ltp":null,"atb":null,"spl":null,"spn":null,"atl":[[8.5999999999999996,1.0900000000000001]],"batl":null,"id":16570658,"hc":null,"bdatb":null},{"tv":null,"batb":null,"spb":null,"bdatl":null,"trd":null,"spf":null,"ltp":null,"atb":[[1.1200000000000001,30921.470000000001]],"spl":null,"spn":null,"atl":null,"batl":null,"id":19924823,"hc":null,"bdatb":null}],"img":null,"tv":null,"con":null,"marketdefinition":null,"id":"1.258926623"}],"conflatems":null,"op":"mcm","id":3}
{"ct":null,"SegmentType":null,"clk":"ALeMAQCAkAEAyIcB","heartbeatms":null,"pt":1780839743396,"initialclk":null,"mc":[{"rc":[{"tv":null,"batb":null,"spb":null,"bdatl":null,"trd":null,"spf":null,"ltp":null,"atb":[[8.4000000000000004,250.27000000000001]],"spl":null,"spn":null,"atl":[[8.8000000000000007,225.02000000000001]],"batl":null,"id":16570658,"hc":null,"bdatb":null},{"tv":null,"batb":null,"spb":null,"bdatl":null,"trd":null,"spf":null,"ltp":null,"atb":[[1.1200000000000001,32078.490000000002]],"spl":null,"spn":null,"atl":[[1.1399999999999999,47844.760000000002]],"batl":null,"id":19924823,"hc":null,"bdatb":null}],"img":null,"tv":null,"con":null,"marketdefinition":null,"id":"1.258926623"}],"conflatems":null,"op":"mcm","id":3}
{"ct":null,"SegmentType":null,"clk":"AL6MAQCIkAEAzYcB","heartbeatms":null,"pt":1780839743447,"initialclk":null,"mc":[{"rc":[{"tv":null,"batb":null,"spb":null,"bdatl":null,"trd":null,"spf":null,"ltp":null,"atb":null,"spl":null,"spn":null,"atl":[[9.1999999999999993,198.72]],"batl":null,"id":16570658,"hc":null,"bdatb":null},{"tv":null,"batb":null,"spb":null,"bdatl":null,"trd":null,"spf":null,"ltp":null,"atb":[[1.1299999999999999,1921.75],[1.1200000000000001,32328.490000000002]],"spl":null,"spn":null,"atl":null,"batl":null,"id":19924823,"hc":null,"bdatb":null}],"img":null,"tv":null,"con":null,"marketdefinition":null,"id":"1.258926623"}],"conflatems":null,"op":"mcm","id":3}
{"ct":null,"SegmentType":null,"clk":"AO6MAQC3kAEA64cB","heartbeatms":null,"pt":1780839743961,"initialclk":null,"mc":[{"rc":[{"tv":null,"batb":null,"spb":null,"bdatl":null,"trd":null,"spf":null,"ltp":null,"atb":[[1.1299999999999999,4584.9899999999998]],"spl":null,"spn":null,"atl":null,"batl":null,"id":19924823,"hc":null,"bdatb":null}],"img":null,"tv":null,"con":null,"marketdefinition":null,"id":"1.258926623"}],"conflatems":null,"op":"mcm","id":3}
{"ct":null,"SegmentType":null,"clk":"AP2MAQDMkAEA\u002BYcB","heartbeatms":null,"pt":1780839744166,"initialclk":null,"mc":[{"rc":[{"tv":null,"batb":null,"spb":null,"bdatl":null,"trd":null,"spf":null,"ltp":null,"atb":null,"spl":null,"spn":null,"atl":[[1.1499999999999999,11782.610000000001]],"batl":null,"id":19924823,"hc":null,"bdatb":null}],"img":null,"tv":null,"con":null,"marketdefinition":null,"id":"1.258926623"}],"conflatems":null,"op":"mcm","id":3}
{"ct":null,"SegmentType":null,"clk":"AJCNAQDckAEAhogB","heartbeatms":null,"pt":1780839744370,"initialclk":null,"mc":[{"rc":[{"tv":null,"batb":null,"spb":null,"bdatl":null,"trd":null,"spf":null,"ltp":null,"atb":[[8.1999999999999993,221.03]],"spl":null,"spn":null,"atl":null,"batl":null,"id":16570658,"hc":null,"bdatb":null},{"tv":null,"batb":null,"spb":null,"bdatl":null,"trd":null,"spf":null,"ltp":null,"atb":[[1.1100000000000001,71171.899999999994]],"spl":null,"spn":null,"atl":[[1.1499999999999999,11788.110000000001]],"batl":null,"id":19924823,"hc":null,"bdatb":null}],"img":null,"tv":null,"con":null,"marketdefinition":null,"id":"1.258926623"}],"conflatems":null,"op":"mcm","id":3}
{"ct":null,"SegmentType":null,"clk":"AJuNAQDkkAEAjIgB","heartbeatms":null,"pt":1780839744474,"initialclk":null,"mc":[{"rc":[{"tv":null,"batb":null,"spb":null,"bdatl":null,"trd":null,"spf":null,"ltp":null,"atb":[[1.1299999999999999,4585.0500000000002]],"spl":null,"spn":null,"atl":null,"batl":null,"id":19924823,"hc":null,"bdatb":null}],"img":null,"tv":null,"con":null,"marketdefinition":null,"id":"1.258926623"}],"conflatems":null,"op":"mcm","id":3}
{"ct":null,"SegmentType":null,"clk":"AL\u002BOAQCFkgEArYkB","heartbeatms":null,"pt":1780839746180,"initialclk":null,"mc":[{"rc":[{"tv":null,"batb":null,"spb":null,"bdatl":null,"trd":null,"spf":null,"ltp":null,"atb":[[1.1299999999999999,4776.8100000000004]],"spl":null,"spn":null,"atl":null,"batl":null,"id":19924823,"hc":null,"bdatb":null}],"img":null,"tv":null,"con":null,"marketdefinition":null,"id":"1.258926623"}],"conflatems":null,"op":"mcm","id":3}
{"ct":null,"SegmentType":null,"clk":"AOqOAQC2kgEA0YkB","heartbeatms":null,"pt":1780839746693,"initialclk":null,"mc":[{"rc":[{"tv":null,"batb":null,"spb":null,"bdatl":null,"trd":null,"spf":null,"ltp":null,"atb":[[7,0.98999999999999999],[7.2000000000000002,113.02]],"spl":null,"spn":null,"atl":[[10.5,403.66000000000002],[10,94.150000000000006],[9.5999999999999996,1.73]],"batl":null,"id":16570658,"hc":null,"bdatb":null},{"tv":null,"batb":null,"spb":null,"bdatl":null,"trd":null,"spf":null,"ltp":null,"atb":[[1.1000000000000001,51322.760000000002],[1.1100000000000001,71181.589999999997]],"spl":null,"spn":null,"atl":[[1.1699999999999999,9386.6900000000005],[1.1599999999999999,10165.83]],"batl":null,"id":19924823,"hc":null,"bdatb":null}],"img":null,"tv":null,"con":null,"marketdefinition":null,"id":"1.258926623"}],"conflatems":null,"op":"mcm","id":3}
{"ct":null,"SegmentType":null,"clk":"APGOAQDDkgEA14kB","heartbeatms":null,"pt":1780839746752,"initialclk":null,"mc":[{"rc":[{"tv":null,"batb":null,"spb":null,"bdatl":null,"trd":null,"spf":null,"ltp":null,"atb":null,"spl":null,"spn":null,"atl":[[1.24,205.93000000000001]],"batl":null,"id":19924823,"hc":null,"bdatb":null}],"img":null,"tv":null,"con":null,"marketdefinition":null,"id":"1.258926623"}],"conflatems":null,"op":"mcm","id":3}
{"ct":null,"SegmentType":null,"clk":"APmOAQDNkgEA3IkB","heartbeatms":null,"pt":1780839746856,"initialclk":null,"mc":[{"rc":[{"tv":243427.69,"batb":null,"spb":null,"bdatl":null,"trd":[[8.4000000000000004,169.56999999999999]],"spf":null,"ltp":8.4000000000000004,"atb":[[8.4000000000000004,240.27000000000001]],"spl":null,"spn":null,"atl":null,"batl":null,"id":16570658,"hc":null,"bdatb":null}],"img":null,"tv":2277812.6600000001,"con":null,"marketdefinition":null,"id":"1.258926623"}],"conflatems":null,"op":"mcm","id":3}
{"ct":null,"SegmentType":null,"clk":"AIGPAQDSkgEA3okB","heartbeatms":null,"pt":1780839746986,"initialclk":null,"mc":[{"rc":[{"tv":null,"batb":null,"spb":null,"bdatl":null,"trd":null,"spf":null,"ltp":null,"atb":null,"spl":null,"spn":null,"atl":[[8.5999999999999996,142.25]],"batl":null,"id":16570658,"hc":null,"bdatb":null},{"tv":null,"batb":null,"spb":null,"bdatl":null,"trd":null,"spf":null,"ltp":null,"atb":null,"spl":null,"spn":null,"atl":[[1.1499999999999999,29063.740000000002]],"batl":null,"id":19924823,"hc":null,"bdatb":null}],"img":null,"tv":null,"con":null,"marketdefinition":null,"id":"1.258926623"}],"conflatems":null,"op":"mcm","id":3}
{"ct":null,"SegmentType":null,"clk":"AKGPAQDqkgEA\u002BokB","heartbeatms":null,"pt":1780839747284,"initialclk":null,"mc":[{"rc":[{"tv":null,"batb":null,"spb":null,"bdatl":null,"trd":null,"spf":null,"ltp":null,"atb":null,"spl":null,"spn":null,"atl":[[1.23,483.77999999999997]],"batl":null,"id":19924823,"hc":null,"bdatb":null}],"img":null,"tv":null,"con":null,"marketdefinition":null,"id":"1.258926623"}],"conflatems":null,"op":"mcm","id":3}
{"ct":null,"SegmentType":null,"clk":"AM6PAQCgkwEAqIoB","heartbeatms":null,"pt":1780839747883,"initialclk":null,"mc":[{"rc":[{"tv":null,"batb":null,"spb":null,"bdatl":null,"trd":null,"spf":null,"ltp":null,"atb":null,"spl":null,"spn":null,"atl":[[1000,1.1699999999999999]],"batl":null,"id":19924823,"hc":null,"bdatb":null}],"img":null,"tv":null,"con":null,"marketdefinition":null,"id":"1.258926623"}],"conflatems":null,"op":"mcm","id":3}
{"ct":null,"SegmentType":null,"clk":"ANmPAQCrkwEArooB","heartbeatms":null,"pt":1780839747987,"initialclk":null,"mc":[{"rc":[{"tv":null,"batb":null,"spb":null,"bdatl":null,"trd":null,"spf":null,"ltp":null,"atb":[[8.4000000000000004,240.34]],"spl":null,"spn":null,"atl":null,"batl":null,"id":16570658,"hc":null,"bdatb":null}],"img":null,"tv":null,"con":null,"marketdefinition":null,"id":"1.258926623"}],"conflatems":null,"op":"mcm","id":3}
{"ct":null,"SegmentType":null,"clk":"APePAQDHkwEAzYoB","heartbeatms":null,"pt":1780839748308,"initialclk":null,"mc":[{"rc":[{"tv":null,"batb":null,"spb":null,"bdatl":null,"trd":null,"spf":null,"ltp":null,"atb":[[7.4000000000000004,496.81999999999999]],"spl":null,"spn":null,"atl":[[9.1999999999999993,361.75999999999999]],"batl":null,"id":16570658,"hc":null,"bdatb":null}],"img":null,"tv":null,"con":null,"marketdefinition":null,"id":"1.258926623"}],"conflatems":null,"op":"mcm","id":3}
{"ct":null,"SegmentType":null,"clk":"AP6PAQDPkwEA1ooB","heartbeatms":null,"pt":1780839748402,"initialclk":null,"mc":[{"rc":[{"tv":null,"batb":null,"spb":null,"bdatl":null,"trd":null,"spf":null,"ltp":null,"atb":null,"spl":null,"spn":null,"atl":[[1000,0.88]],"batl":null,"id":19924823,"hc":null,"bdatb":null}],"img":null,"tv":null,"con":null,"marketdefinition":null,"id":"1.258926623"}],"conflatems":null,"op":"mcm","id":3}
{"ct":null,"SegmentType":null,"clk":"ALCQAQCHlAEA/ooB","heartbeatms":null,"pt":1780839748975,"initialclk":null,"mc":[{"rc":[{"tv":243429.07000000001,"batb":null,"spb":null,"bdatl":null,"trd":[[8.4000000000000004,170.94999999999999]],"spf":null,"ltp":null,"atb":[[8.4000000000000004,239.65000000000001]],"spl":null,"spn":null,"atl":null,"batl":null,"id":16570658,"hc":null,"bdatb":null},{"tv":null,"batb":null,"spb":null,"bdatl":null,"trd":null,"spf":null,"ltp":null,"atb":[[1.1100000000000001,71211.589999999997]],"spl":null,"spn":null,"atl":null,"batl":null,"id":19924823,"hc":null,"bdatb":null}],"img":null,"tv":2277814.04,"con":null,"marketdefinition":null,"id":"1.258926623"}],"conflatems":null,"op":"mcm","id":3}
{"ct":null,"SegmentType":null,"clk":"ANWQAQCxlAEAnYsB","heartbeatms":null,"pt":1780839749391,"initialclk":null,"mc":[{"rc":[{"tv":null,"batb":null,"spb":null,"bdatl":null,"trd":null,"spf":null,"ltp":null,"atb":[[7.4000000000000004,495.94999999999999],[7.2000000000000002,112.02]],"spl":null,"spn":null,"atl":[[9.8000000000000007,0],[9.1999999999999993,198.72],[9.5999999999999996,0.85999999999999999]],"batl":null,"id":16570658,"hc":null,"bdatb":null},{"tv":null,"batb":null,"spb":null,"bdatl":null,"trd":null,"spf":null,"ltp":null,"atb":[[1.1000000000000001,51316.459999999999],[1.1100000000000001,71205.75]],"spl":null,"spn":null,"atl":[[1.1699999999999999,9382.6900000000005],[1.1599999999999999,10161.629999999999]],"batl":null,"id":19924823,"hc":null,"bdatb":null}],"img":null,"tv":null,"con":null,"marketdefinition":null,"id":"1.258926623"}],"conflatems":null,"op":"mcm","id":3}
{"ct":null,"SegmentType":null,"clk":"ANyRAQCrlQEA5YsB","heartbeatms":null,"pt":1780839750696,"initialclk":null,"mc":[{"rc":[{"tv":243587.51000000001,"batb":null,"spb":null,"bdatl":null,"trd":[[8.5999999999999996,1879.3800000000001]],"spf":null,"ltp":8.5999999999999996,"atb":null,"spl":null,"spn":null,"atl":[[8.5999999999999996,63.030000000000001]],"batl":null,"id":16570658,"hc":null,"bdatb":null},{"tv":2034537.97,"batb":null,"spb":null,"bdatl":null,"trd":[[1.1299999999999999,220005.92999999999]],"spf":null,"ltp":null,"atb":[[1.1299999999999999,4700.3100000000004]],"spl":null,"spn":null,"atl":null,"batl":null,"id":19924823,"hc":null,"bdatb":null}],"img":null,"tv":2278125.48,"con":null,"marketdefinition":null,"id":"1.258926623"}],"conflatems":null,"op":"mcm","id":3}
{"ct":null,"SegmentType":null,"clk":"AOaRAQC3lQEA74sB","heartbeatms":null,"pt":1780839750798,"initialclk":null,"mc":[{"rc":[{"tv":null,"batb":null,"spb":null,"bdatl":null,"trd":null,"spf":null,"ltp":null,"atb":null,"spl":null,"spn":null,"atl":[[1.1399999999999999,46543.120000000003]],"batl":null,"id":19924823,"hc":null,"bdatb":null}],"img":null,"tv":null,"con":null,"marketdefinition":null,"id":"1.258926623"}],"conflatems":null,"op":"mcm","id":3}
{"ct":null,"SegmentType":null,"clk":"APORAQC\u002BlQEA9osB","heartbeatms":null,"pt":1780839750902,"initialclk":null,"mc":[{"rc":[{"tv":null,"batb":null,"spb":null,"bdatl":null,"trd":null,"spf":null,"ltp":null,"atb":[[1.1100000000000001,72557.100000000006]],"spl":null,"spn":null,"atl":null,"batl":null,"id":19924823,"hc":null,"bdatb":null}],"img":null,"tv":null,"con":null,"marketdefinition":null,"id":"1.258926623"}],"conflatems":null,"op":"mcm","id":3}
{"ct":null,"SegmentType":null,"clk":"AIaSAQDHlQEAg4wB","heartbeatms":null,"pt":1780839751012,"initialclk":null,"mc":[{"rc":[{"tv":243587.64999999999,"batb":null,"spb":null,"bdatl":null,"trd":[[8.5999999999999996,1879.52]],"spf":null,"ltp":null,"atb":null,"spl":null,"spn":null,"atl":[[8.5999999999999996,62.960000000000001]],"batl":null,"id":16570658,"hc":null,"bdatb":null},{"tv":null,"batb":null,"spb":null,"bdatl":null,"trd":null,"spf":null,"ltp":null,"atb":[[1.1200000000000001,30989.209999999999]],"spl":null,"spn":null,"atl":null,"batl":null,"id":19924823,"hc":null,"bdatb":null}],"img":null,"tv":2278125.6200000001,"con":null,"marketdefinition":null,"id":"1.258926623"}],"conflatems":null,"op":"mcm","id":3}
{"ct":null,"SegmentType":null,"clk":"AJaSAQDWlQEAkYwB","heartbeatms":null,"pt":1780839751170,"initialclk":null,"mc":[{"rc":[{"tv":null,"batb":null,"spb":null,"bdatl":null,"trd":null,"spf":null,"ltp":null,"atb":null,"spl":null,"spn":null,"atl":[[1.1399999999999999,46535.620000000003]],"batl":null,"id":19924823,"hc":null,"bdatb":null}],"img":null,"tv":null,"con":null,"marketdefinition":null,"id":"1.258926623"}],"conflatems":null,"op":"mcm","id":3}
{"ct":null,"SegmentType":null,"clk":"AJ\u002BSAQDflQEAm4wB","heartbeatms":null,"pt":1780839751271,"initialclk":null,"mc":[{"rc":[{"tv":243691.31,"batb":null,"spb":null,"bdatl":null,"trd":[[8.5999999999999996,1983.1800000000001]],"spf":null,"ltp":null,"atb":null,"spl":null,"spn":null,"atl":[[8.5999999999999996,11.130000000000001]],"batl":null,"id":16570658,"hc":null,"bdatb":null},{"tv":null,"batb":null,"spb":null,"bdatl":null,"trd":null,"spf":null,"ltp":null,"atb":null,"spl":null,"spn":null,"atl":[[1.23,683.77999999999997]],"batl":null,"id":19924823,"hc":null,"bdatb":null}],"img":null,"tv":2278229.2799999998,"con":null,"marketdefinition":null,"id":"1.258926623"}],"conflatems":null,"op":"mcm","id":3}
{"ct":null,"SegmentType":null,"clk":"ALOSAQDvlQEArYwB","heartbeatms":null,"pt":1780839751483,"initialclk":null,"mc":[{"rc":[{"tv":2034541.3500000001,"batb":null,"spb":null,"bdatl":null,"trd":[[1.1299999999999999,220006.5],[1.1399999999999999,132991.38000000001]],"spf":null,"ltp":1.1399999999999999,"atb":[[1.1299999999999999,4700.0299999999997]],"spl":null,"spn":null,"atl":[[1.1399999999999999,46534.220000000001]],"batl":null,"id":19924823,"hc":null,"bdatb":null}],"img":null,"tv":2278232.6600000001,"con":null,"marketdefinition":null,"id":"1.258926623"}],"conflatems":null,"op":"mcm","id":3}
{"ct":null,"SegmentType":null,"clk":"AM6SAQCElgEAw4wB","heartbeatms":null,"pt":1780839751782,"initialclk":null,"mc":[{"rc":[{"tv":2034543.27,"batb":null,"spb":null,"bdatl":null,"trd":[[1.1399999999999999,132993.29999999999]],"spf":null,"ltp":null,"atb":null,"spl":null,"spn":null,"atl":[[1.24,5.9299999999999997],[1.1399999999999999,46533.260000000002]],"batl":null,"id":19924823,"hc":null,"bdatb":null}],"img":null,"tv":2278234.5800000001,"con":null,"marketdefinition":null,"id":"1.258926623"}],"conflatems":null,"op":"mcm","id":3}
{"ct":null,"SegmentType":null,"clk":"ANiSAQCOlgEAyIwB","heartbeatms":null,"pt":1780839751887,"initialclk":null,"mc":[{"rc":[{"tv":null,"batb":null,"spb":null,"bdatl":null,"trd":null,"spf":null,"ltp":null,"atb":[[1.1200000000000001,31002.43]],"spl":null,"spn":null,"atl":null,"batl":null,"id":19924823,"hc":null,"bdatb":null}],"img":null,"tv":null,"con":null,"marketdefinition":null,"id":"1.258926623"}],"conflatems":null,"op":"mcm","id":3}
{"ct":null,"SegmentType":null,"clk":"AOOTAQCHlwEAso0B","heartbeatms":null,"pt":1780839753391,"initialclk":null,"mc":[{"rc":[{"tv":null,"batb":null,"spb":null,"bdatl":null,"trd":null,"spf":null,"ltp":null,"atb":null,"spl":null,"spn":null,"atl":[[10,95.109999999999999]],"batl":null,"id":16570658,"hc":null,"bdatb":null}],"img":null,"tv":null,"con":null,"marketdefinition":null,"id":"1.258926623"}],"conflatems":null,"op":"mcm","id":3}
{"ct":null,"SegmentType":null,"clk":"APqTAQCclwEAx40B","heartbeatms":null,"pt":1780839753599,"initialclk":null,"mc":[{"rc":[{"tv":null,"batb":null,"spb":null,"bdatl":null,"trd":null,"spf":null,"ltp":null,"atb":[[1.05,74273.130000000005]],"spl":null,"spn":null,"atl":null,"batl":null,"id":19924823,"hc":null,"bdatb":null}],"img":null,"tv":null,"con":null,"marketdefinition":null,"id":"1.258926623"}],"conflatems":null,"op":"mcm","id":3}
{"ct":null,"SegmentType":null,"clk":"AIqUAQCylwEA1Y0B","heartbeatms":null,"pt":1780839753804,"initialclk":null,"mc":[{"rc":[{"tv":243693.31,"batb":null,"spb":null,"bdatl":null,"trd":[[8.5999999999999996,1985.1800000000001]],"spf":null,"ltp":null,"atb":null,"spl":null,"spn":null,"atl":[[8.5999999999999996,10.130000000000001]],"batl":null,"id":16570658,"hc":null,"bdatb":null}],"img":null,"tv":2278236.5800000001,"con":null,"marketdefinition":null,"id":"1.258926623"}],"conflatems":null,"op":"mcm","id":3}
{"ct":null,"SegmentType":null,"clk":"AKCUAQDClwEA6I0B","heartbeatms":null,"pt":1780839754015,"initialclk":null,"mc":[{"rc":[{"tv":2034550.0800000001,"batb":null,"spb":null,"bdatl":null,"trd":[[1.1299999999999999,220013.31]],"spf":null,"ltp":1.1299999999999999,"atb":[[1.1299999999999999,4696.6199999999999]],"spl":null,"spn":null,"atl":null,"batl":null,"id":19924823,"hc":null,"bdatb":null}],"img":null,"tv":2278243.3900000001,"con":null,"marketdefinition":null,"id":"1.258926623"}],"conflatems":null,"op":"mcm","id":3}
{"ct":null,"SegmentType":null,"clk":"AKiUAQDJlwEA7o0B","heartbeatms":null,"pt":1780839754069,"initialclk":null,"mc":[{"rc":[{"tv":243793.31,"batb":null,"spb":null,"bdatl":null,"trd":[[8.4000000000000004,270.94999999999999]],"spf":null,"ltp":8.4000000000000004,"atb":[[8.4000000000000004,189.65000000000001]],"spl":null,"spn":null,"atl":null,"batl":null,"id":16570658,"hc":null,"bdatb":null}],"img":null,"tv":2278343.3900000001,"con":null,"marketdefinition":null,"id":"1.258926623"}],"conflatems":null,"op":"mcm","id":3}
{"ct":null,"SegmentType":null,"clk":"AL6UAQDhlwEA/Y0B","heartbeatms":null,"pt":1780839754276,"initialclk":null,"mc":[{"rc":[{"tv":null,"batb":null,"spb":null,"bdatl":null,"trd":null,"spf":null,"ltp":null,"atb":null,"spl":null,"spn":null,"atl":[[1.1399999999999999,46105.379999999997]],"batl":null,"id":19924823,"hc":null,"bdatb":null}],"img":null,"tv":null,"con":null,"marketdefinition":null,"id":"1.258926623"}],"conflatems":null,"op":"mcm","id":3}
{"ct":null,"SegmentType":null,"clk":"ANGUAQD8lwEAjo4B","heartbeatms":null,"pt":1780839754502,"initialclk":null,"mc":[{"rc":[{"tv":243795.31,"batb":null,"spb":null,"bdatl":null,"trd":[[8.4000000000000004,272.94999999999999]],"spf":null,"ltp":null,"atb":[[8.4000000000000004,188.65000000000001]],"spl":null,"spn":null,"atl":null,"batl":null,"id":16570658,"hc":null,"bdatb":null}],"img":null,"tv":2278345.3900000001,"con":null,"marketdefinition":null,"id":"1.258926623"}],"conflatems":null,"op":"mcm","id":3}
{"ct":null,"SegmentType":null,"clk":"ANiUAQCDmAEAmI4B","heartbeatms":null,"pt":1780839754591,"initialclk":null,"mc":[{"rc":[{"tv":2034555.9299999999,"batb":null,"spb":null,"bdatl":null,"trd":[[1.1399999999999999,132999.14999999999]],"spf":null,"ltp":1.1399999999999999,"atb":[[1.1100000000000001,75588.130000000005]],"spl":null,"spn":null,"atl":[[1.1399999999999999,46102.449999999997]],"batl":null,"id":19924823,"hc":null,"bdatb":null}],"img":null,"tv":2278351.2400000002,"con":null,"marketdefinition":null,"id":"1.258926623"}],"conflatems":null,"op":"mcm","id":3}
{"ct":null,"SegmentType":null,"clk":"AOOUAQCMmAEAoY4B","heartbeatms":null,"pt":1780839754699,"initialclk":null,"mc":[{"rc":[{"tv":243895.31,"batb":null,"spb":null,"bdatl":null,"trd":[[8.4000000000000004,372.94999999999999]],"spf":null,"ltp":null,"atb":[[8.4000000000000004,138.65000000000001]],"spl":null,"spn":null,"atl":null,"batl":null,"id":16570658,"hc":null,"bdatb":null},{"tv":null,"batb":null,"spb":null,"bdatl":null,"trd":null,"spf":null,"ltp":null,"atb":null,"spl":null,"spn":null,"atl":[[1.24,205.93000000000001]],"batl":null,"id":19924823,"hc":null,"bdatb":null}],"img":null,"tv":2278451.2400000002,"con":null,"marketdefinition":null,"id":"1.258926623"}],"conflatems":null,"op":"mcm","id":3}
{"ct":null,"SegmentType":null,"clk":"APyUAQCjmAEAto4B","heartbeatms":null,"pt":1780839754906,"initialclk":null,"mc":[{"rc":[{"tv":null,"batb":null,"spb":null,"bdatl":null,"trd":null,"spf":null,"ltp":null,"atb":[[1.03,88933.740000000005]],"spl":null,"spn":null,"atl":null,"batl":null,"id":19924823,"hc":null,"bdatb":null}],"img":null,"tv":null,"con":null,"marketdefinition":null,"id":"1.258926623"}],"conflatems":null,"op":"mcm","id":3}
{"ct":null,"SegmentType":null,"clk":"ALqVAQDXmAEA8Y4B","heartbeatms":null,"pt":1780839755511,"initialclk":null,"mc":[{"rc":[{"tv":null,"batb":null,"spb":null,"bdatl":null,"trd":null,"spf":null,"ltp":null,"atb":[[8.4000000000000004,138.58000000000001],[8.1999999999999993,368.05000000000001]],"spl":null,"spn":null,"atl":null,"batl":null,"id":16570658,"hc":null,"bdatb":null},{"tv":null,"batb":null,"spb":null,"bdatl":null,"trd":null,"spf":null,"ltp":null,"atb":null,"spl":null,"spn":null,"atl":[[1.22,8862.3500000000004],[1.1399999999999999,46252.449999999997]],"batl":null,"id":19924823,"hc":null,"bdatb":null}],"img":null,"tv":null,"con":null,"marketdefinition":null,"id":"1.258926623"}],"conflatems":null,"op":"mcm","id":3}
{"ct":null,"SegmentType":null,"clk":"AOaVAQD6mAEAlo8B","heartbeatms":null,"pt":1780839755979,"initialclk":null,"mc":[{"rc":[{"tv":null,"batb":null,"spb":null,"bdatl":null,"trd":null,"spf":null,"ltp":null,"atb":[[1.1299999999999999,4696.5600000000004]],"spl":null,"spn":null,"atl":null,"batl":null,"id":19924823,"hc":null,"bdatb":null}],"img":null,"tv":null,"con":null,"marketdefinition":null,"id":"1.258926623"}],"conflatems":null,"op":"mcm","id":3}
{"ct":null,"SegmentType":null,"clk":"AI6WAQCfmQEAto8B","heartbeatms":null,"pt":1780839756395,"initialclk":null,"mc":[{"rc":[{"tv":2034556.0500000001,"batb":null,"spb":null,"bdatl":null,"trd":[[1.1399999999999999,132999.26999999999]],"spf":null,"ltp":null,"atb":null,"spl":null,"spn":null,"atl":[[1.1399999999999999,46252.389999999999]],"batl":null,"id":19924823,"hc":null,"bdatb":null}],"img":null,"tv":2278451.3599999999,"con":null,"marketdefinition":null,"id":"1.258926623"}],"conflatems":null,"op":"mcm","id":3}
{"ct":null,"SegmentType":null,"clk":"AJSWAQChmQEAv48B","heartbeatms":null,"pt":1780839756488,"initialclk":null,"mc":[{"rc":[{"tv":null,"batb":null,"spb":null,"bdatl":null,"trd":null,"spf":null,"ltp":null,"atb":[[7.5999999999999996,201.53]],"spl":null,"spn":null,"atl":[[9.1999999999999993,361.75999999999999]],"batl":null,"id":16570658,"hc":null,"bdatb":null}],"img":null,"tv":null,"con":null,"marketdefinition":null,"id":"1.258926623"}],"conflatems":null,"op":"mcm","id":3}
{"ct":null,"SegmentType":null,"clk":"ALqWAQDMmQEA1Y8B","heartbeatms":null,"pt":1780839756907,"initialclk":null,"mc":[{"rc":[{"tv":null,"batb":null,"spb":null,"bdatl":null,"trd":null,"spf":null,"ltp":null,"atb":[[7.4000000000000004,306.54000000000002]],"spl":null,"spn":null,"atl":null,"batl":null,"id":16570658,"hc":null,"bdatb":null}],"img":null,"tv":null,"con":null,"marketdefinition":null,"id":"1.258926623"}],"conflatems":null,"op":"mcm","id":3}
{"ct":null,"SegmentType":null,"clk":"ALeXAQDSmgEAqZAB","heartbeatms":null,"pt":1780839758195,"initialclk":null,"mc":[{"rc":[{"tv":null,"batb":null,"spb":null,"bdatl":null,"trd":null,"spf":null,"ltp":null,"atb":[[8,662.32000000000005]],"spl":null,"spn":null,"atl":null,"batl":null,"id":16570658,"hc":null,"bdatb":null},{"tv":null,"batb":null,"spb":null,"bdatl":null,"trd":null,"spf":null,"ltp":null,"atb":[[1.03,88934.029999999999]],"spl":null,"spn":null,"atl":null,"batl":null,"id":19924823,"hc":null,"bdatb":null}],"img":null,"tv":null,"con":null,"marketdefinition":null,"id":"1.258926623"}],"conflatems":null,"op":"mcm","id":3}
{"ct":null,"SegmentType":null,"clk":"ANyXAQD9mgEAxpAB","heartbeatms":null,"pt":1780839758612,"initialclk":null,"mc":[{"rc":[{"tv":null,"batb":null,"spb":null,"bdatl":null,"trd":null,"spf":null,"ltp":null,"atb":[[1.03,88933.740000000005]],"spl":null,"spn":null,"atl":null,"batl":null,"id":19924823,"hc":null,"bdatb":null}],"img":null,"tv":null,"con":null,"marketdefinition":null,"id":"1.258926623"}],"conflatems":null,"op":"mcm","id":3}
{"ct":null,"SegmentType":null,"clk":"AOeXAQCOmwEA2JAB","heartbeatms":null,"pt":1780839758766,"initialclk":null,"mc":[{"rc":[{"tv":null,"batb":null,"spb":null,"bdatl":null,"trd":null,"spf":null,"ltp":null,"atb":null,"spl":null,"spn":null,"atl":[[1.22,9062.3500000000004]],"batl":null,"id":19924823,"hc":null,"bdatb":null}],"img":null,"tv":null,"con":null,"marketdefinition":null,"id":"1.258926623"}],"conflatems":null,"op":"mcm","id":3}
{"ct":null,"SegmentType":null,"clk":"APiXAQCgmwEA4pAB","heartbeatms":null,"pt":1780839758967,"initialclk":null,"mc":[{"rc":[{"tv":null,"batb":null,"spb":null,"bdatl":null,"trd":null,"spf":null,"ltp":null,"atb":[[1.1200000000000001,32341.709999999999]],"spl":null,"spn":null,"atl":null,"batl":null,"id":19924823,"hc":null,"bdatb":null}],"img":null,"tv":null,"con":null,"marketdefinition":null,"id":"1.258926623"}],"conflatems":null,"op":"mcm","id":3}
{"ct":null,"SegmentType":null,"clk":"AIaYAQCqmwEA8ZAB","heartbeatms":null,"pt":1780839759074,"initialclk":null,"mc":[{"rc":[{"tv":null,"batb":null,"spb":null,"bdatl":null,"trd":null,"spf":null,"ltp":null,"atb":[[5,19.059999999999999]],"spl":null,"spn":null,"atl":null,"batl":null,"id":16570658,"hc":null,"bdatb":null}],"img":null,"tv":null,"con":null,"marketdefinition":null,"id":"1.258926623"}],"conflatems":null,"op":"mcm","id":3}
{"ct":null,"SegmentType":null,"clk":"AKmYAQDGmwEAlJEB","heartbeatms":null,"pt":1780839759481,"initialclk":null,"mc":[{"rc":[{"tv":null,"batb":null,"spb":null,"bdatl":null,"trd":null,"spf":null,"ltp":null,"atb":[[1.1100000000000001,74236.779999999999]],"spl":null,"spn":null,"atl":null,"batl":null,"id":19924823,"hc":null,"bdatb":null}],"img":null,"tv":null,"con":null,"marketdefinition":null,"id":"1.258926623"}],"conflatems":null,"op":"mcm","id":3}
{"ct":null,"SegmentType":null,"clk":"ALGYAQDOmwEAnZEB","heartbeatms":null,"pt":1780839759587,"initialclk":null,"mc":[{"rc":[{"tv":null,"batb":null,"spb":null,"bdatl":null,"trd":null,"spf":null,"ltp":null,"atb":null,"spl":null,"spn":null,"atl":[[1.24,5.9299999999999997]],"batl":null,"id":19924823,"hc":null,"bdatb":null}],"img":null,"tv":null,"con":null,"marketdefinition":null,"id":"1.258926623"}],"conflatems":null,"op":"mcm","id":3}
{"ct":null,"SegmentType":null,"clk":"ANmYAQD1mwEAv5EB","heartbeatms":null,"pt":1780839759996,"initialclk":null,"mc":[{"rc":[{"tv":null,"batb":null,"spb":null,"bdatl":null,"trd":null,"spf":null,"ltp":null,"atb":null,"spl":null,"spn":null,"atl":[[9,194.25]],"batl":null,"id":16570658,"hc":null,"bdatb":null}],"img":null,"tv":null,"con":null,"marketdefinition":null,"id":"1.258926623"}],"conflatems":null,"op":"mcm","id":3}
{"ct":null,"SegmentType":null,"clk":"AO6YAQCNnAEAzpEB","heartbeatms":null,"pt":1780839760210,"initialclk":null,"mc":[{"rc":[{"tv":243912.01999999999,"batb":null,"spb":null,"bdatl":null,"trd":[[8.4000000000000004,389.66000000000002]],"spf":null,"ltp":null,"atb":[[8.4000000000000004,130.22]],"spl":null,"spn":null,"atl":null,"batl":null,"id":16570658,"hc":null,"bdatb":null}],"img":null,"tv":2278468.0699999998,"con":null,"marketdefinition":null,"id":"1.258926623"}],"conflatems":null,"op":"mcm","id":3}
{"ct":null,"SegmentType":null,"clk":"APuYAQCZnAEA2ZEB","heartbeatms":null,"pt":1780839760312,"initialclk":null,"mc":[{"rc":[{"tv":null,"batb":null,"spb":null,"bdatl":null,"trd":null,"spf":null,"ltp":null,"atb":[[1.03,88945.339999999997]],"spl":null,"spn":null,"atl":null,"batl":null,"id":19924823,"hc":null,"bdatb":null}],"img":null,"tv":null,"con":null,"marketdefinition":null,"id":"1.258926623"}],"conflatems":null,"op":"mcm","id":3}
{"ct":null,"SegmentType":null,"clk":"ALiZAQDPnAEAg5IB","heartbeatms":null,"pt":1780839760888,"initialclk":null,"mc":[{"rc":[{"tv":243916.39999999999,"batb":null,"spb":null,"bdatl":null,"trd":[[8.5999999999999996,1989.56]],"spf":null,"ltp":8.5999999999999996,"atb":null,"spl":null,"spn":null,"atl":[[8.5999999999999996,7.9400000000000004]],"batl":null,"id":16570658,"hc":null,"bdatb":null}],"img":null,"tv":2278472.4500000002,"con":null,"marketdefinition":null,"id":"1.258926623"}],"conflatems":null,"op":"mcm","id":3}
{"ct":null,"SegmentType":null,"clk":"AMGZAQDZnAEAiZIB","heartbeatms":null,"pt":1780839760984,"initialclk":null,"mc":[{"rc":[{"tv":null,"batb":null,"spb":null,"bdatl":null,"trd":null,"spf":null,"ltp":null,"atb":null,"spl":null,"spn":null,"atl":[[1.1399999999999999,46173.779999999999]],"batl":null,"id":19924823,"hc":null,"bdatb":null}],"img":null,"tv":null,"con":null,"marketdefinition":null,"id":"1.258926623"}],"conflatems":null,"op":"mcm","id":3}
{"ct":null,"SegmentType":null,"clk":"ANCZAQDinAEAk5IB","heartbeatms":null,"pt":1780839761089,"initialclk":null,"mc":[{"rc":[{"tv":null,"batb":null,"spb":null,"bdatl":null,"trd":null,"spf":null,"ltp":null,"atb":null,"spl":null,"spn":null,"atl":[[1.1499999999999999,29142.349999999999]],"batl":null,"id":19924823,"hc":null,"bdatb":null}],"img":null,"tv":null,"con":null,"marketdefinition":null,"id":"1.258926623"}],"conflatems":null,"op":"mcm","id":3}
{"ct":null,"SegmentType":null,"clk":"AOWZAQD3nAEAqZIB","heartbeatms":null,"pt":1780839761394,"initialclk":null,"mc":[{"rc":[{"tv":243918.39999999999,"batb":null,"spb":null,"bdatl":null,"trd":[[8.4000000000000004,391.66000000000002]],"spf":null,"ltp":8.4000000000000004,"atb":[[8.4000000000000004,129.22]],"spl":null,"spn":null,"atl":[[9.1999999999999993,253.06],[9,83.140000000000001]],"batl":null,"id":16570658,"hc":null,"bdatb":null}],"img":null,"tv":2278474.4500000002,"con":null,"marketdefinition":null,"id":"1.258926623"}],"conflatems":null,"op":"mcm","id":3}
{"ct":null,"SegmentType":null,"clk":"AO6ZAQCBnQEAsZIB","heartbeatms":null,"pt":1780839761506,"initialclk":null,"mc":[{"rc":[{"tv":null,"batb":null,"spb":null,"bdatl":null,"trd":null,"spf":null,"ltp":null,"atb":[[7.5999999999999996,280.67000000000002],[7.4000000000000004,407.50999999999999]],"spl":null,"spn":null,"atl":[[9.1999999999999993,90.019999999999996]],"batl":null,"id":16570658,"hc":null,"bdatb":null},{"tv":null,"batb":null,"spb":null,"bdatl":null,"trd":null,"spf":null,"ltp":null,"atb":[[1.1000000000000001,53847.769999999997],[1.1100000000000001,76532.479999999996],[1.1200000000000001,31002.43]],"spl":null,"spn":null,"atl":[[1.1599999999999999,8935.1700000000001]],"batl":null,"id":19924823,"hc":null,"bdatb":null}],"img":null,"tv":null,"con":null,"marketdefinition":null,"id":"1.258926623"}],"conflatems":null,"op":"mcm","id":3}
{"ct":null,"SegmentType":null,"clk":"APiZAQCNnQEAuZIB","heartbeatms":null,"pt":1780839761609,"initialclk":null,"mc":[{"rc":[{"tv":null,"batb":null,"spb":null,"bdatl":null,"trd":null,"spf":null,"ltp":null,"atb":[[8.4000000000000004,0],[8.1999999999999993,221.03]],"spl":null,"spn":null,"atl":[[9.4000000000000004,0],[8.4000000000000004,1.4199999999999999],[8.8000000000000007,77.760000000000005],[10.5,286.66000000000003],[8.5999999999999996,0]],"batl":null,"id":16570658,"hc":null,"bdatb":null},{"tv":null,"batb":null,"spb":null,"bdatl":null,"trd":null,"spf":null,"ltp":null,"atb":[[1.1000000000000001,51750.769999999997],[1.1200000000000001,29843.41]],"spl":null,"spn":null,"atl":[[1.1399999999999999,43079.059999999998]],"batl":null,"id":19924823,"hc":null,"bdatb":null}],"img":null,"tv":null,"con":null,"marketdefinition":null,"id":"1.258926623"}],"conflatems":null,"op":"mcm","id":3}
{"ct":null,"SegmentType":null,"clk":"AIGaAQCYnQEAwZIB","heartbeatms":null,"pt":1780839761717,"initialclk":null,"mc":[{"rc":[{"tv":2034556.6399999999,"batb":null,"spb":null,"bdatl":null,"trd":[[1.1399999999999999,132999.85999999999]],"spf":null,"ltp":null,"atb":null,"spl":null,"spn":null,"atl":[[1.1399999999999999,43078.769999999997]],"batl":null,"id":19924823,"hc":null,"bdatb":null}],"img":null,"tv":2278475.04,"con":null,"marketdefinition":null,"id":"1.258926623"}],"conflatems":null,"op":"mcm","id":3}
{"ct":null,"SegmentType":null,"clk":"AI\u002BaAQCdnQEAzJIB","heartbeatms":null,"pt":1780839761813,"initialclk":null,"mc":[{"rc":[{"tv":null,"batb":null,"spb":null,"bdatl":null,"trd":null,"spf":null,"ltp":null,"atb":[[7.4000000000000004,131.19],[8.1999999999999993,33.329999999999998],[7.2000000000000002,12.15],[8,655.39999999999998]],"spl":null,"spn":null,"atl":[[9.4000000000000004,2],[8.8000000000000007,0],[11,105.94],[10.5,11.6],[9.1999999999999993,16.52],[9,7.5700000000000003]],"batl":null,"id":16570658,"hc":null,"bdatb":null},{"tv":null,"batb":null,"spb":null,"bdatl":null,"trd":null,"spf":null,"ltp":null,"atb":[[1.1200000000000001,29845.41]],"spl":null,"spn":null,"atl":null,"batl":null,"id":19924823,"hc":null,"bdatb":null}],"img":null,"tv":null,"con":null,"marketdefinition":null,"id":"1.258926623"}],"conflatems":null,"op":"mcm","id":3}
{"ct":null,"SegmentType":null,"clk":"AKKaAQCwnQEA25IB","heartbeatms":null,"pt":1780839761976,"initialclk":null,"mc":[{"rc":[{"tv":null,"batb":null,"spb":null,"bdatl":null,"trd":null,"spf":null,"ltp":null,"atb":null,"spl":null,"spn":null,"atl":[[1.1599999999999999,9145.7000000000007]],"batl":null,"id":19924823,"hc":null,"bdatb":null}],"img":null,"tv":null,"con":null,"marketdefinition":null,"id":"1.258926623"}],"conflatems":null,"op":"mcm","id":3}
{"ct":null,"SegmentType":null,"clk":"AKuaAQC6nQEA35IB","heartbeatms":null,"pt":1780839762069,"initialclk":null,"mc":[{"rc":[{"tv":null,"batb":null,"spb":null,"bdatl":null,"trd":null,"spf":null,"ltp":null,"atb":[[1.03,88944.589999999997]],"spl":null,"spn":null,"atl":null,"batl":null,"id":19924823,"hc":null,"bdatb":null}],"img":null,"tv":null,"con":null,"marketdefinition":null,"id":"1.258926623"}],"conflatems":null,"op":"mcm","id":3}
{"ct":null,"SegmentType":null,"clk":"AMKaAQDPnQEA8ZIB","heartbeatms":null,"pt":1780839762284,"initialclk":null,"mc":[{"rc":[{"tv":null,"batb":null,"spb":null,"bdatl":null,"trd":null,"spf":null,"ltp":null,"atb":[[1.1100000000000001,77087.979999999996]],"spl":null,"spn":null,"atl":[[1.1699999999999999,9385.0599999999995],[1.1499999999999999,29366.790000000001]],"batl":null,"id":19924823,"hc":null,"bdatb":null}],"img":null,"tv":null,"con":null,"marketdefinition":null,"id":"1.258926623"}],"conflatems":null,"op":"mcm","id":3}
{"ct":null,"SegmentType":null,"clk":"AMyaAQDbnQEA/JIB","heartbeatms":null,"pt":1780839762395,"initialclk":null,"mc":[{"rc":[{"tv":null,"batb":null,"spb":null,"bdatl":null,"trd":null,"spf":null,"ltp":null,"atb":[[1.1200000000000001,29294.869999999999]],"spl":null,"spn":null,"atl":[[1.1399999999999999,42808.970000000001]],"batl":null,"id":19924823,"hc":null,"bdatb":null}],"img":null,"tv":null,"con":null,"marketdefinition":null,"id":"1.258926623"}],"conflatems":null,"op":"mcm","id":3}
{"ct":null,"SegmentType":null,"clk":"ANmaAQDjnQEAhJMB","heartbeatms":null,"pt":1780839762590,"initialclk":null,"mc":[{"rc":[{"tv":2034560.7,"batb":null,"spb":null,"bdatl":null,"trd":[[1.1399999999999999,133003.92000000001]],"spf":null,"ltp":null,"atb":null,"spl":null,"spn":null,"atl":[[1.1399999999999999,42806.940000000002]],"batl":null,"id":19924823,"hc":null,"bdatb":null}],"img":null,"tv":2278479.1000000001,"con":null,"marketdefinition":null,"id":"1.258926623"}],"conflatems":null,"op":"mcm","id":3}
{"ct":null,"SegmentType":null,"clk":"AOuaAQCbngEAl5MB","heartbeatms":null,"pt":1780839762802,"initialclk":null,"mc":[{"rc":[{"tv":2036560.7,"batb":null,"spb":null,"bdatl":null,"trd":[[1.1399999999999999,135003.92000000001]],"spf":null,"ltp":null,"atb":null,"spl":null,"spn":null,"atl":[[1.1399999999999999,41806.940000000002]],"batl":null,"id":19924823,"hc":null,"bdatb":null}],"img":null,"tv":2280479.1000000001,"con":null,"marketdefinition":null,"id":"1.258926623"}],"conflatems":null,"op":"mcm","id":3}
{"ct":null,"SegmentType":null,"clk":"APSaAQChngEAo5MB","heartbeatms":null,"pt":1780839762913,"initialclk":null,"mc":[{"rc":[{"tv":null,"batb":null,"spb":null,"bdatl":null,"trd":null,"spf":null,"ltp":null,"atb":null,"spl":null,"spn":null,"atl":[[1.1799999999999999,8861.3199999999997]],"batl":null,"id":19924823,"hc":null,"bdatb":null}],"img":null,"tv":null,"con":null,"marketdefinition":null,"id":"1.258926623"}],"conflatems":null,"op":"mcm","id":3}
{"ct":null,"SegmentType":null,"clk":"AMabAQCSnwEA4pMB","heartbeatms":null,"pt":1780839763800,"initialclk":null,"mc":[{"rc":[{"tv":null,"batb":null,"spb":null,"bdatl":null,"trd":null,"spf":null,"ltp":null,"atb":null,"spl":null,"spn":null,"atl":[[1.1599999999999999,9148.0799999999999]],"batl":null,"id":19924823,"hc":null,"bdatb":null}],"img":null,"tv":null,"con":null,"marketdefinition":null,"id":"1.258926623"}],"conflatems":null,"op":"mcm","id":3}
{"ct":null,"SegmentType":null,"clk":"AP2bAQC7nwEAkpQB","heartbeatms":null,"pt":1780839764413,"initialclk":null,"mc":[{"rc":[{"tv":null,"batb":null,"spb":null,"bdatl":null,"trd":null,"spf":null,"ltp":null,"atb":null,"spl":null,"spn":null,"atl":[[1.1699999999999999,8874.3899999999994]],"batl":null,"id":19924823,"hc":null,"bdatb":null}],"img":null,"tv":null,"con":null,"marketdefinition":null,"id":"1.258926623"}],"conflatems":null,"op":"mcm","id":3}
{"ct":null,"SegmentType":null,"clk":"AKacAQDdnwEAtJQB","heartbeatms":null,"pt":1780839764876,"initialclk":null,"mc":[{"rc":[{"tv":2036560.8200000001,"batb":null,"spb":null,"bdatl":null,"trd":[[1.1399999999999999,135004.04000000001]],"spf":null,"ltp":null,"atb":null,"spl":null,"spn":null,"atl":[[1.1399999999999999,41806.879999999997]],"batl":null,"id":19924823,"hc":null,"bdatb":null}],"img":null,"tv":2280479.2200000002,"con":null,"marketdefinition":null,"id":"1.258926623"}],"conflatems":null,"op":"mcm","id":3}
{"ct":null,"SegmentType":null,"clk":"ALOcAQDonwEAwJQB","heartbeatms":null,"pt":1780839764980,"initialclk":null,"mc":[{"rc":[{"tv":2036563.72,"batb":null,"spb":null,"bdatl":null,"trd":[[1.1399999999999999,135006.94]],"spf":null,"ltp":null,"atb":null,"spl":null,"spn":null,"atl":[[1.1399999999999999,41805.43],[1.1799999999999999,8863.7000000000007]],"batl":null,"id":19924823,"hc":null,"bdatb":null}],"img":null,"tv":2280482.1200000001,"con":null,"marketdefinition":null,"id":"1.258926623"}],"conflatems":null,"op":"mcm","id":3}
{"ct":null,"SegmentType":null,"clk":"AMicAQD5nwEA0JQB","heartbeatms":null,"pt":1780839765187,"initialclk":null,"mc":[{"rc":[{"tv":null,"batb":null,"spb":null,"bdatl":null,"trd":null,"spf":null,"ltp":null,"atb":[[1.1299999999999999,6237.8599999999997]],"spl":null,"spn":null,"atl":null,"batl":null,"id":19924823,"hc":null,"bdatb":null}],"img":null,"tv":null,"con":null,"marketdefinition":null,"id":"1.258926623"}],"conflatems":null,"op":"mcm","id":3}
{"ct":null,"SegmentType":null,"clk":"ANecAQCKoAEA2ZQB","heartbeatms":null,"pt":1780839765386,"initialclk":null,"mc":[{"rc":[{"tv":null,"batb":null,"spb":null,"bdatl":null,"trd":null,"spf":null,"ltp":null,"atb":null,"spl":null,"spn":null,"atl":[[1.1399999999999999,29979.439999999999]],"batl":null,"id":19924823,"hc":null,"bdatb":null}],"img":null,"tv":null,"con":null,"marketdefinition":null,"id":"1.258926623"}],"conflatems":null,"op":"mcm","id":3}
{"ct":null,"SegmentType":null,"clk":"APucAQCxoAEA95QB","heartbeatms":null,"pt":1780839765702,"initialclk":null,"mc":[{"rc":[{"tv":null,"batb":null,"spb":null,"bdatl":null,"trd":null,"spf":null,"ltp":null,"atb":null,"spl":null,"spn":null,"atl":[[9.5999999999999996,0]],"batl":null,"id":16570658,"hc":null,"bdatb":null},{"tv":null,"batb":null,"spb":null,"bdatl":null,"trd":null,"spf":null,"ltp":null,"atb":[[1.1100000000000001,77083.520000000004]],"spl":null,"spn":null,"atl":null,"batl":null,"id":19924823,"hc":null,"bdatb":null}],"img":null,"tv":null,"con":null,"marketdefinition":null,"id":"1.258926623"}],"conflatems":null,"op":"mcm","id":3}
{"ct":null,"SegmentType":null,"clk":"AKKdAQDgoAEAopUB","heartbeatms":null,"pt":1780839766208,"initialclk":null,"mc":[{"rc":[{"tv":null,"batb":null,"spb":null,"bdatl":null,"trd":null,"spf":null,"ltp":null,"atb":null,"spl":null,"spn":null,"atl":[[1.1599999999999999,9150.4500000000007]],"batl":null,"id":19924823,"hc":null,"bdatb":null}],"img":null,"tv":null,"con":null,"marketdefinition":null,"id":"1.258926623"}],"conflatems":null,"op":"mcm","id":3}
{"ct":null,"SegmentType":null,"clk":"AL6dAQCAoQEAtJUB","heartbeatms":null,"pt":1780839766482,"initialclk":null,"mc":[{"rc":[{"tv":243928.39999999999,"batb":null,"spb":null,"bdatl":null,"trd":[[8.1999999999999993,1172.5999999999999]],"spf":null,"ltp":8.1999999999999993,"atb":[[8.1999999999999993,28.329999999999998]],"spl":null,"spn":null,"atl":null,"batl":null,"id":16570658,"hc":null,"bdatb":null}],"img":null,"tv":2280492.1200000001,"con":null,"marketdefinition":null,"id":"1.258926623"}],"conflatems":null,"op":"mcm","id":3}
{"ct":null,"SegmentType":null,"clk":"AMydAQCOoQEAxZUB","heartbeatms":null,"pt":1780839766685,"initialclk":null,"mc":[{"rc":[{"tv":null,"batb":null,"spb":null,"bdatl":null,"trd":null,"spf":null,"ltp":null,"atb":null,"spl":null,"spn":null,"atl":[[1.1599999999999999,9152.8299999999999]],"batl":null,"id":19924823,"hc":null,"bdatb":null}],"img":null,"tv":null,"con":null,"marketdefinition":null,"id":"1.258926623"}],"conflatems":null,"op":"mcm","id":3}
{"ct":null,"SegmentType":null,"clk":"ANCdAQCQoQEAypUB","heartbeatms":null,"pt":1780839766783,"initialclk":null,"mc":[{"rc":[{"tv":null,"batb":null,"spb":null,"bdatl":null,"trd":null,"spf":null,"ltp":null,"atb":null,"spl":null,"spn":null,"atl":[[8.4000000000000004,0]],"batl":null,"id":16570658,"hc":null,"bdatb":null}],"img":null,"tv":null,"con":null,"marketdefinition":null,"id":"1.258926623"}],"conflatems":null,"op":"mcm","id":3}
{"ct":null,"SegmentType":null,"clk":"APidAQCyoQEA4pUB","heartbeatms":null,"pt":1780839767196,"initialclk":null,"mc":[{"rc":[{"tv":null,"batb":null,"spb":null,"bdatl":null,"trd":null,"spf":null,"ltp":null,"atb":null,"spl":null,"spn":null,"atl":[[1.1599999999999999,9155.2099999999991]],"batl":null,"id":19924823,"hc":null,"bdatb":null}],"img":null,"tv":null,"con":null,"marketdefinition":null,"id":"1.258926623"}],"conflatems":null,"op":"mcm","id":3}
{"ct":null,"SegmentType":null,"clk":"AJSeAQDLoQEA/5UB","heartbeatms":null,"pt":1780839767506,"initialclk":null,"mc":[{"rc":[{"tv":null,"batb":null,"spb":null,"bdatl":null,"trd":null,"spf":null,"ltp":null,"atb":null,"spl":null,"spn":null,"atl":[[8.4000000000000004,29.760000000000002],[8.8000000000000007,379],[8.5999999999999996,116.28],[9,86.659999999999997]],"batl":null,"id":16570658,"hc":null,"bdatb":null},{"tv":null,"batb":null,"spb":null,"bdatl":null,"trd":null,"spf":null,"ltp":null,"atb":[[1.1299999999999999,9154.2600000000002]],"spl":null,"spn":null,"atl":null,"batl":null,"id":19924823,"hc":null,"bdatb":null}],"img":null,"tv":null,"con":null,"marketdefinition":null,"id":"1.258926623"}],"conflatems":null,"op":"mcm","id":3}
{"ct":null,"SegmentType":null,"clk":"AJqeAQDToQEAhJYB","heartbeatms":null,"pt":1780839767609,"initialclk":null,"mc":[{"rc":[{"tv":null,"batb":null,"spb":null,"bdatl":null,"trd":null,"spf":null,"ltp":null,"atb":null,"spl":null,"spn":null,"atl":[[8.8000000000000007,381],[11,112.94]],"batl":null,"id":16570658,"hc":null,"bdatb":null},{"tv":null,"batb":null,"spb":null,"bdatl":null,"trd":null,"spf":null,"ltp":null,"atb":[[1.1299999999999999,9156.2600000000002]],"spl":null,"spn":null,"atl":null,"batl":null,"id":19924823,"hc":null,"bdatb":null}],"img":null,"tv":null,"con":null,"marketdefinition":null,"id":"1.258926623"}],"conflatems":null,"op":"mcm","id":3}
{"ct":null,"SegmentType":null,"clk":"AKmeAQDhoQEAkJYB","heartbeatms":null,"pt":1780839767721,"initialclk":null,"mc":[{"rc":[{"tv":null,"batb":null,"spb":null,"bdatl":null,"trd":null,"spf":null,"ltp":null,"atb":null,"spl":null,"spn":null,"atl":[[9.4000000000000004,2.9900000000000002],[8.4000000000000004,0],[9.1999999999999993,17.379999999999999]],"batl":null,"id":16570658,"hc":null,"bdatb":null},{"tv":null,"batb":null,"spb":null,"bdatl":null,"trd":null,"spf":null,"ltp":null,"atb":[[1.1299999999999999,6239.8599999999997],[1.1200000000000001,29300.470000000001]],"spl":null,"spn":null,"atl":null,"batl":null,"id":19924823,"hc":null,"bdatb":null}],"img":null,"tv":null,"con":null,"marketdefinition":null,"id":"1.258926623"}],"conflatems":null,"op":"mcm","id":3}
{"ct":null,"SegmentType":null,"clk":"AK6eAQDroQEAl5YB","heartbeatms":null,"pt":1780839767816,"initialclk":null,"mc":[{"rc":[{"tv":null,"batb":null,"spb":null,"bdatl":null,"trd":null,"spf":null,"ltp":null,"atb":[[8.1999999999999993,14.44],[7.2000000000000002,65.109999999999999],[8,644.85000000000002]],"spl":null,"spn":null,"atl":[[10.5,10.609999999999999],[10,94.25]],"batl":null,"id":16570658,"hc":null,"bdatb":null},{"tv":null,"batb":null,"spb":null,"bdatl":null,"trd":null,"spf":null,"ltp":null,"atb":[[1.04,73810.729999999996],[1.05,74271.130000000005],[1.0700000000000001,39097.620000000003],[1.0800000000000001,39931.199999999997],[1.1000000000000001,51745.339999999997],[1.0900000000000001,40103.849999999999],[1.0600000000000001,63294.940000000002],[1.02,90703.919999999998],[1.03,88942.589999999997],[1.01,93233.490000000005]],"spl":null,"spn":null,"atl":[[1.1399999999999999,29624.189999999999],[1.1599999999999999,9727.2099999999991]],"batl":null,"id":19924823,"hc":null,"bdatb":null}],"img":null,"tv":null,"con":null,"marketdefinition":null,"id":"1.258926623"}],"conflatems":null,"op":"mcm","id":3}
{"ct":null,"SegmentType":null,"clk":"ALqeAQDwoQEAoJYB","heartbeatms":null,"pt":1780839767923,"initialclk":null,"mc":[{"rc":[{"tv":2036603.72,"batb":null,"spb":null,"bdatl":null,"trd":[[1.1399999999999999,135046.94]],"spf":null,"ltp":null,"atb":null,"spl":null,"spn":null,"atl":[[1.1399999999999999,29604.189999999999],[1.1499999999999999,41089.949999999997]],"batl":null,"id":19924823,"hc":null,"bdatb":null}],"img":null,"tv":2280532.1200000001,"con":null,"marketdefinition":null,"id":"1.258926623"}],"conflatems":null,"op":"mcm","id":3}
{"ct":null,"SegmentType":null,"clk":"AL\u002BeAQD3oQEAppYB","heartbeatms":null,"pt":1780839768016,"initialclk":null,"mc":[{"rc":[{"tv":null,"batb":null,"spb":null,"bdatl":null,"trd":null,"spf":null,"ltp":null,"atb":[[7.5999999999999996,476.13999999999999],[7.2000000000000002,789.38999999999999]],"spl":null,"spn":null,"atl":null,"batl":null,"id":16570658,"hc":null,"bdatb":null},{"tv":null,"batb":null,"spb":null,"bdatl":null,"trd":null,"spf":null,"ltp":null,"atb":[[1.1200000000000001,33326.900000000001]],"spl":null,"spn":null,"atl":null,"batl":null,"id":19924823,"hc":null,"bdatb":null}],"img":null,"tv":null,"con":null,"marketdefinition":null,"id":"1.258926623"}],"conflatems":null,"op":"mcm","id":3}
{"ct":null,"SegmentType":null,"clk":"ANCeAQCMogEAspYB","heartbeatms":null,"pt":1780839768181,"initialclk":null,"mc":[{"rc":[{"tv":null,"batb":null,"spb":null,"bdatl":null,"trd":null,"spf":null,"ltp":null,"atb":[[8,254.43000000000001]],"spl":null,"spn":null,"atl":null,"batl":null,"id":16570658,"hc":null,"bdatb":null},{"tv":null,"batb":null,"spb":null,"bdatl":null,"trd":null,"spf":null,"ltp":null,"atb":[[1.1100000000000001,76813.160000000003]],"spl":null,"spn":null,"atl":null,"batl":null,"id":19924823,"hc":null,"bdatb":null}],"img":null,"tv":null,"con":null,"marketdefinition":null,"id":"1.258926623"}],"conflatems":null,"op":"mcm","id":3}
{"ct":null,"SegmentType":null,"clk":"ANieAQCWogEAvpYB","heartbeatms":null,"pt":1780839768292,"initialclk":null,"mc":[{"rc":[{"tv":null,"batb":null,"spb":null,"bdatl":null,"trd":null,"spf":null,"ltp":null,"atb":[[1.1100000000000001,76805.660000000003]],"spl":null,"spn":null,"atl":null,"batl":null,"id":19924823,"hc":null,"bdatb":null}],"img":null,"tv":null,"con":null,"marketdefinition":null,"id":"1.258926623"}],"conflatems":null,"op":"mcm","id":3}
{"ct":null,"SegmentType":null,"clk":"APOeAQCyogEA3JYB","heartbeatms":null,"pt":1780839768597,"initialclk":null,"mc":[{"rc":[{"tv":null,"batb":null,"spb":null,"bdatl":null,"trd":null,"spf":null,"ltp":null,"atb":[[7.2000000000000002,982.65999999999997]],"spl":null,"spn":null,"atl":[[8.8000000000000007,551.45000000000005]],"batl":null,"id":16570658,"hc":null,"bdatb":null},{"tv":null,"batb":null,"spb":null,"bdatl":null,"trd":null,"spf":null,"ltp":null,"atb":[[1.1299999999999999,7567.29],[1.1100000000000001,75423.740000000005],[1.1200000000000001,31975.73]],"spl":null,"spn":null,"atl":[[1.1699999999999999,10063.75],[1.1399999999999999,28608.209999999999],[1.1499999999999999,39470.5]],"batl":null,"id":19924823,"hc":null,"bdatb":null}],"img":null,"tv":null,"con":null,"marketdefinition":null,"id":"1.258926623"}],"conflatems":null,"op":"mcm","id":3}
{"ct":null,"SegmentType":null,"clk":"AP2eAQC/ogEA6ZYB","heartbeatms":null,"pt":1780839768791,"initialclk":null,"mc":[{"rc":[{"tv":2036604.8600000001,"batb":null,"spb":null,"bdatl":null,"trd":[[1.1299999999999999,220014.45000000001]],"spf":null,"ltp":1.1299999999999999,"atb":[[1.1299999999999999,7574.2200000000003]],"spl":null,"spn":null,"atl":null,"batl":null,"id":19924823,"hc":null,"bdatb":null}],"img":null,"tv":2280533.2599999998,"con":null,"marketdefinition":null,"id":"1.258926623"}],"conflatems":null,"op":"mcm","id":3}
{"ct":null,"SegmentType":null,"clk":"AIafAQDJogEA8pYB","heartbeatms":null,"pt":1780839768905,"initialclk":null,"mc":[{"rc":[{"tv":null,"batb":null,"spb":null,"bdatl":null,"trd":null,"spf":null,"ltp":null,"atb":null,"spl":null,"spn":null,"atl":[[1.1499999999999999,27747.34]],"batl":null,"id":19924823,"hc":null,"bdatb":null}],"img":null,"tv":null,"con":null,"marketdefinition":null,"id":"1.258926623"}],"conflatems":null,"op":"mcm","id":3}
{"ct":null,"SegmentType":null,"clk":"AIufAQDSogEA\u002BpYB","heartbeatms":null,"pt":1780839769009,"initialclk":null,"mc":[{"rc":[{"tv":null,"batb":null,"spb":null,"bdatl":null,"trd":null,"spf":null,"ltp":null,"atb":null,"spl":null,"spn":null,"atl":[[19.5,0]],"batl":null,"id":16570658,"hc":null,"bdatb":null},{"tv":null,"batb":null,"spb":null,"bdatl":null,"trd":null,"spf":null,"ltp":null,"atb":null,"spl":null,"spn":null,"atl":[[1.1699999999999999,10066.129999999999]],"batl":null,"id":19924823,"hc":null,"bdatb":null}],"img":null,"tv":null,"con":null,"marketdefinition":null,"id":"1.258926623"}],"conflatems":null,"op":"mcm","id":3}
{"ct":null,"SegmentType":null,"clk":"AKKfAQDjogEAnJcB","heartbeatms":null,"pt":1780839769325,"initialclk":null,"mc":[{"rc":[{"tv":null,"batb":null,"spb":null,"bdatl":null,"trd":null,"spf":null,"ltp":null,"atb":[[8,294.89999999999998]],"spl":null,"spn":null,"atl":null,"batl":null,"id":16570658,"hc":null,"bdatb":null}],"img":null,"tv":null,"con":null,"marketdefinition":null,"id":"1.258926623"}],"conflatems":null,"op":"mcm","id":3}
{"ct":null,"SegmentType":null,"clk":"AKafAQDtogEAoZcB","heartbeatms":null,"pt":1780839769418,"initialclk":null,"mc":[{"rc":[{"tv":null,"batb":null,"spb":null,"bdatl":null,"trd":null,"spf":null,"ltp":null,"atb":null,"spl":null,"spn":null,"atl":[[17,45.200000000000003]],"batl":null,"id":16570658,"hc":null,"bdatb":null}],"img":null,"tv":null,"con":null,"marketdefinition":null,"id":"1.258926623"}],"conflatems":null,"op":"mcm","id":3}
{"ct":null,"SegmentType":null,"clk":"AK6fAQD1ogEAqJcB","heartbeatms":null,"pt":1780839769515,"initialclk":null,"mc":[{"rc":[{"tv":null,"batb":null,"spb":null,"bdatl":null,"trd":null,"spf":null,"ltp":null,"atb":[[8,335.37]],"spl":null,"spn":null,"atl":null,"batl":null,"id":16570658,"hc":null,"bdatb":null},{"tv":null,"batb":null,"spb":null,"bdatl":null,"trd":null,"spf":null,"ltp":null,"atb":null,"spl":null,"spn":null,"atl":[[1.1699999999999999,10068.5]],"batl":null,"id":19924823,"hc":null,"bdatb":null}],"img":null,"tv":null,"con":null,"marketdefinition":null,"id":"1.258926623"}],"conflatems":null,"op":"mcm","id":3}
{"ct":null,"SegmentType":null,"clk":"ALifAQD8ogEAs5cB","heartbeatms":null,"pt":1780839769588,"initialclk":null,"mc":[{"rc":[{"tv":null,"batb":null,"spb":null,"bdatl":null,"trd":null,"spf":null,"ltp":null,"atb":[[8,375.85000000000002]],"spl":null,"spn":null,"atl":null,"batl":null,"id":16570658,"hc":null,"bdatb":null}],"img":null,"tv":null,"con":null,"marketdefinition":null,"id":"1.258926623"}],"conflatems":null,"op":"mcm","id":3}
{"ct":null,"SegmentType":null,"clk":"AMifAQCKowEAxpcB","heartbeatms":null,"pt":1780839769798,"initialclk":null,"mc":[{"rc":[{"tv":null,"batb":null,"spb":null,"bdatl":null,"trd":null,"spf":null,"ltp":null,"atb":[[8,416.31999999999999]],"spl":null,"spn":null,"atl":null,"batl":null,"id":16570658,"hc":null,"bdatb":null}],"img":null,"tv":null,"con":null,"marketdefinition":null,"id":"1.258926623"}],"conflatems":null,"op":"mcm","id":3}
{"ct":null,"SegmentType":null,"clk":"ANafAQCWowEA15cB","heartbeatms":null,"pt":1780839769985,"initialclk":null,"mc":[{"rc":[{"tv":null,"batb":null,"spb":null,"bdatl":null,"trd":null,"spf":null,"ltp":null,"atb":null,"spl":null,"spn":null,"atl":[[1.1699999999999999,10070.879999999999]],"batl":null,"id":19924823,"hc":null,"bdatb":null}],"img":null,"tv":null,"con":null,"marketdefinition":null,"id":"1.258926623"}],"conflatems":null,"op":"mcm","id":3}
{"ct":null,"SegmentType":null,"clk":"AOKfAQCeowEA5JcB","heartbeatms":null,"pt":1780839770092,"initialclk":null,"mc":[{"rc":[{"tv":null,"batb":null,"spb":null,"bdatl":null,"trd":null,"spf":null,"ltp":null,"atb":null,"spl":null,"spn":null,"atl":[[1000,1.0900000000000001]],"batl":null,"id":19924823,"hc":null,"bdatb":null}],"img":null,"tv":null,"con":null,"marketdefinition":null,"id":"1.258926623"}],"conflatems":null,"op":"mcm","id":3}
{"ct":null,"SegmentType":null,"clk":"AIWgAQC9owEA/5cB","heartbeatms":null,"pt":1780839770502,"initialclk":null,"mc":[{"rc":[{"tv":null,"batb":null,"spb":null,"bdatl":null,"trd":null,"spf":null,"ltp":null,"atb":null,"spl":null,"spn":null,"atl":[[9.1999999999999993,9.3800000000000008],[8.5999999999999996,195.59]],"batl":null,"id":16570658,"hc":null,"bdatb":null},{"tv":null,"batb":null,"spb":null,"bdatl":null,"trd":null,"spf":null,"ltp":null,"atb":null,"spl":null,"spn":null,"atl":[[1000,0.88]],"batl":null,"id":19924823,"hc":null,"bdatb":null}],"img":null,"tv":null,"con":null,"marketdefinition":null,"id":"1.258926623"}],"conflatems":null,"op":"mcm","id":3}
{"ct":null,"SegmentType":null,"clk":"AJCgAQDIowEAhpgB","heartbeatms":null,"pt":1780839770616,"initialclk":null,"mc":[{"rc":[{"tv":null,"batb":null,"spb":null,"bdatl":null,"trd":null,"spf":null,"ltp":null,"atb":null,"spl":null,"spn":null,"atl":[[8.5999999999999996,203.59]],"batl":null,"id":16570658,"hc":null,"bdatb":null}],"img":null,"tv":null,"con":null,"marketdefinition":null,"id":"1.258926623"}],"conflatems":null,"op":"mcm","id":3}
{"ct":null,"SegmentType":null,"clk":"AKKgAQDXowEAlpgB","heartbeatms":null,"pt":1780839770808,"initialclk":null,"mc":[{"rc":[{"tv":null,"batb":null,"spb":null,"bdatl":null,"trd":null,"spf":null,"ltp":null,"atb":null,"spl":null,"spn":null,"atl":[[1.1799999999999999,8866.0699999999997]],"batl":null,"id":19924823,"hc":null,"bdatb":null}],"img":null,"tv":null,"con":null,"marketdefinition":null,"id":"1.258926623"}],"conflatems":null,"op":"mcm","id":3}
{"ct":null,"SegmentType":null,"clk":"ALegAQDpowEAppgB","heartbeatms":null,"pt":1780839771025,"initialclk":null,"mc":[{"rc":[{"tv":null,"batb":null,"spb":null,"bdatl":null,"trd":null,"spf":null,"ltp":null,"atb":null,"spl":null,"spn":null,"atl":[[1.1499999999999999,39470.5]],"batl":null,"id":19924823,"hc":null,"bdatb":null}],"img":null,"tv":null,"con":null,"marketdefinition":null,"id":"1.258926623"}],"conflatems":null,"op":"mcm","id":3}
{"ct":null,"SegmentType":null,"clk":"AMagAQD4owEAsZgB","heartbeatms":null,"pt":1780839771219,"initialclk":null,"mc":[{"rc":[{"tv":null,"batb":null,"spb":null,"bdatl":null,"trd":null,"spf":null,"ltp":null,"atb":[[1.1299999999999999,6246.79]],"spl":null,"spn":null,"atl":null,"batl":null,"id":19924823,"hc":null,"bdatb":null}],"img":null,"tv":null,"con":null,"marketdefinition":null,"id":"1.258926623"}],"conflatems":null,"op":"mcm","id":3}
{"ct":null,"SegmentType":null,"clk":"AM\u002BgAQCCpAEAt5gB","heartbeatms":null,"pt":1780839771326,"initialclk":null,"mc":[{"rc":[{"tv":null,"batb":null,"spb":null,"bdatl":null,"trd":null,"spf":null,"ltp":null,"atb":[[8.4000000000000004,1]],"spl":null,"spn":null,"atl":null,"batl":null,"id":16570658,"hc":null,"bdatb":null},{"tv":null,"batb":null,"spb":null,"bdatl":null,"trd":null,"spf":null,"ltp":null,"atb":[[1.1299999999999999,6912.4499999999998],[1.1200000000000001,34024.879999999997]],"spl":null,"spn":null,"atl":[[1.1399999999999999,29031.630000000001],[1.1499999999999999,41119.480000000003]],"batl":null,"id":19924823,"hc":null,"bdatb":null}],"img":null,"tv":null,"con":null,"marketdefinition":null,"id":"1.258926623"}],"conflatems":null,"op":"mcm","id":3}
{"ct":null,"SegmentType":null,"clk":"ANSgAQCGpAEAupgB","heartbeatms":null,"pt":1780839771388,"initialclk":null,"mc":[{"rc":[{"tv":null,"batb":null,"spb":null,"bdatl":null,"trd":null,"spf":null,"ltp":null,"atb":[[8,498.31999999999999]],"spl":null,"spn":null,"atl":[[10.5,98.609999999999999]],"batl":null,"id":16570658,"hc":null,"bdatb":null},{"tv":null,"batb":null,"spb":null,"bdatl":null,"trd":null,"spf":null,"ltp":null,"atb":[[1.1000000000000001,53420.339999999997]],"spl":null,"spn":null,"atl":[[1.1499999999999999,42580.480000000003]],"batl":null,"id":19924823,"hc":null,"bdatb":null}],"img":null,"tv":null,"con":null,"marketdefinition":null,"id":"1.258926623"}],"conflatems":null,"op":"mcm","id":3}
{"ct":null,"SegmentType":null,"clk":"AOKgAQCPpAEAwJgB","heartbeatms":null,"pt":1780839771488,"initialclk":null,"mc":[{"rc":[{"tv":null,"batb":null,"spb":null,"bdatl":null,"trd":null,"spf":null,"ltp":null,"atb":null,"spl":null,"spn":null,"atl":[[1.1399999999999999,29463.98],[1.1799999999999999,8868.4500000000007]],"batl":null,"id":19924823,"hc":null,"bdatb":null}],"img":null,"tv":null,"con":null,"marketdefinition":null,"id":"1.258926623"}],"conflatems":null,"op":"mcm","id":3}
{"ct":null,"SegmentType":null,"clk":"AOigAQCVpAEAwpgB","heartbeatms":null,"pt":1780839771584,"initialclk":null,"mc":[{"rc":[{"tv":null,"batb":null,"spb":null,"bdatl":null,"trd":null,"spf":null,"ltp":null,"atb":null,"spl":null,"spn":null,"atl":[[1.1499999999999999,43093.519999999997]],"batl":null,"id":19924823,"hc":null,"bdatb":null}],"img":null,"tv":null,"con":null,"marketdefinition":null,"id":"1.258926623"}],"conflatems":null,"op":"mcm","id":3}
{"ct":null,"SegmentType":null,"clk":"APKgAQCbpAEAyZgB","heartbeatms":null,"pt":1780839771689,"initialclk":null,"mc":[{"rc":[{"tv":null,"batb":null,"spb":null,"bdatl":null,"trd":null,"spf":null,"ltp":null,"atb":[[7.2000000000000002,971.37]],"spl":null,"spn":null,"atl":null,"batl":null,"id":16570658,"hc":null,"bdatb":null}],"img":null,"tv":null,"con":null,"marketdefinition":null,"id":"1.258926623"}],"conflatems":null,"op":"mcm","id":3}
{"ct":null,"SegmentType":null,"clk":"APagAQCgpAEAzJgB","heartbeatms":null,"pt":1780839771789,"initialclk":null,"mc":[{"rc":[{"tv":null,"batb":null,"spb":null,"bdatl":null,"trd":null,"spf":null,"ltp":null,"atb":[[8,518.32000000000005]],"spl":null,"spn":null,"atl":null,"batl":null,"id":16570658,"hc":null,"bdatb":null}],"img":null,"tv":null,"con":null,"marketdefinition":null,"id":"1.258926623"}],"conflatems":null,"op":"mcm","id":3}
{"ct":null,"SegmentType":null,"clk":"AIChAQCppAEA1JgB","heartbeatms":null,"pt":1780839771902,"initialclk":null,"mc":[{"rc":[{"tv":null,"batb":null,"spb":null,"bdatl":null,"trd":null,"spf":null,"ltp":null,"atb":[[8.1999999999999993,162.11000000000001]],"spl":null,"spn":null,"atl":[[8.5999999999999996,344.38999999999999]],"batl":null,"id":16570658,"hc":null,"bdatb":null},{"tv":null,"batb":null,"spb":null,"bdatl":null,"trd":null,"spf":null,"ltp":null,"atb":[[1.1299999999999999,7984.0100000000002]],"spl":null,"spn":null,"atl":[[1.1399999999999999,30526.139999999999],[1.1499999999999999,31370.360000000001]],"batl":null,"id":19924823,"hc":null,"bdatb":null}],"img":null,"tv":null,"con":null,"marketdefinition":null,"id":"1.258926623"}],"conflatems":null,"op":"mcm","id":3}
{"ct":null,"SegmentType":null,"clk":"AKehAQDPpAEA9JgB","heartbeatms":null,"pt":1780839772403,"initialclk":null,"mc":[{"rc":[{"tv":null,"batb":null,"spb":null,"bdatl":null,"trd":null,"spf":null,"ltp":null,"atb":[[1.1299999999999999,8234.0100000000002]],"spl":null,"spn":null,"atl":null,"batl":null,"id":19924823,"hc":null,"bdatb":null}],"img":null,"tv":null,"con":null,"marketdefinition":null,"id":"1.258926623"}],"conflatems":null,"op":"mcm","id":3}
{"ct":null,"SegmentType":null,"clk":"ALGhAQDcpAEA/ZgB","heartbeatms":null,"pt":1780839772515,"initialclk":null,"mc":[{"rc":[{"tv":null,"batb":null,"spb":null,"bdatl":null,"trd":null,"spf":null,"ltp":null,"atb":[[8,532.61000000000001]],"spl":null,"spn":null,"atl":null,"batl":null,"id":16570658,"hc":null,"bdatb":null},{"tv":null,"batb":null,"spb":null,"bdatl":null,"trd":null,"spf":null,"ltp":null,"atb":null,"spl":null,"spn":null,"atl":[[1.1599999999999999,9729.2099999999991],[1.1799999999999999,8870.8199999999997]],"batl":null,"id":19924823,"hc":null,"bdatb":null}],"img":null,"tv":null,"con":null,"marketdefinition":null,"id":"1.258926623"}],"conflatems":null,"op":"mcm","id":3}
{"ct":null,"SegmentType":null,"clk":"AL2hAQDgpAEAiJkB","heartbeatms":null,"pt":1780839772618,"initialclk":null,"mc":[{"rc":[{"tv":null,"batb":null,"spb":null,"bdatl":null,"trd":null,"spf":null,"ltp":null,"atb":[[1.1299999999999999,8484.0100000000002]],"spl":null,"spn":null,"atl":null,"batl":null,"id":19924823,"hc":null,"bdatb":null}],"img":null,"tv":null,"con":null,"marketdefinition":null,"id":"1.258926623"}],"conflatems":null,"op":"mcm","id":3}
{"ct":null,"SegmentType":null,"clk":"AMWhAQDppAEAj5kB","heartbeatms":null,"pt":1780839772731,"initialclk":null,"mc":[{"rc":[{"tv":null,"batb":null,"spb":null,"bdatl":null,"trd":null,"spf":null,"ltp":null,"atb":null,"spl":null,"spn":null,"atl":[[1.1699999999999999,10078.370000000001],[1.1599999999999999,9727.2099999999991]],"batl":null,"id":19924823,"hc":null,"bdatb":null}],"img":null,"tv":null,"con":null,"marketdefinition":null,"id":"1.258926623"}],"conflatems":null,"op":"mcm","id":3}
{"ct":null,"SegmentType":null,"clk":"AOihAQCMpQEArJkB","heartbeatms":null,"pt":1780839773078,"initialclk":null,"mc":[{"rc":[{"tv":243934.17999999999,"batb":null,"spb":null,"bdatl":null,"trd":[[8.4000000000000004,393.66000000000002],[8.1999999999999993,1176.3800000000001]],"spf":null,"ltp":null,"atb":[[8.4000000000000004,0],[8.1999999999999993,160.22]],"spl":null,"spn":null,"atl":null,"batl":null,"id":16570658,"hc":null,"bdatb":null}],"img":null,"tv":2280539.04,"con":null,"marketdefinition":null,"id":"1.258926623"}],"conflatems":null,"op":"mcm","id":3}
{"ct":null,"SegmentType":null,"clk":"AP6hAQCepQEAwJkB","heartbeatms":null,"pt":1780839773289,"initialclk":null,"mc":[{"rc":[{"tv":2036637.98,"batb":null,"spb":null,"bdatl":null,"trd":[[1.1399999999999999,135080.06]],"spf":null,"ltp":1.1399999999999999,"atb":null,"spl":null,"spn":null,"atl":[[1.1399999999999999,30509.580000000002]],"batl":null,"id":19924823,"hc":null,"bdatb":null}],"img":null,"tv":2280572.1600000001,"con":null,"marketdefinition":null,"id":"1.258926623"}],"conflatems":null,"op":"mcm","id":3}
{"ct":null,"SegmentType":null,"clk":"AIqiAQCmpQEAwpkB","heartbeatms":null,"pt":1780839773391,"initialclk":null,"mc":[{"rc":[{"tv":null,"batb":null,"spb":null,"bdatl":null,"trd":null,"spf":null,"ltp":null,"atb":null,"spl":null,"spn":null,"atl":[[8.8000000000000007,381]],"batl":null,"id":16570658,"hc":null,"bdatb":null}],"img":null,"tv":null,"con":null,"marketdefinition":null,"id":"1.258926623"}],"conflatems":null,"op":"mcm","id":3}
{"ct":null,"SegmentType":null,"clk":"AKGiAQC3pQEA0pkB","heartbeatms":null,"pt":1780839773596,"initialclk":null,"mc":[{"rc":[{"tv":2036638.3999999999,"batb":null,"spb":null,"bdatl":null,"trd":[[1.1299999999999999,220014.87]],"spf":null,"ltp":1.1299999999999999,"atb":[[1.1299999999999999,8483.7999999999993]],"spl":null,"spn":null,"atl":null,"batl":null,"id":19924823,"hc":null,"bdatb":null}],"img":null,"tv":2280572.5800000001,"con":null,"marketdefinition":null,"id":"1.258926623"}],"conflatems":null,"op":"mcm","id":3}
{"ct":null,"SegmentType":null,"clk":"ALyiAQDcpQEA8JkB","heartbeatms":null,"pt":1780839774012,"initialclk":null,"mc":[{"rc":[{"tv":null,"batb":null,"spb":null,"bdatl":null,"trd":null,"spf":null,"ltp":null,"atb":[[8.1999999999999993,200.69]],"spl":null,"spn":null,"atl":null,"batl":null,"id":16570658,"hc":null,"bdatb":null}],"img":null,"tv":null,"con":null,"marketdefinition":null,"id":"1.258926623"}],"conflatems":null,"op":"mcm","id":3}
{"ct":null,"SegmentType":null,"clk":"AMSiAQDnpQEA\u002BZkB","heartbeatms":null,"pt":1780839774115,"initialclk":null,"mc":[{"rc":[{"tv":null,"batb":null,"spb":null,"bdatl":null,"trd":null,"spf":null,"ltp":null,"atb":[[8.1999999999999993,241.16999999999999]],"spl":null,"spn":null,"atl":null,"batl":null,"id":16570658,"hc":null,"bdatb":null},{"tv":null,"batb":null,"spb":null,"bdatl":null,"trd":null,"spf":null,"ltp":null,"atb":null,"spl":null,"spn":null,"atl":[[1.1799999999999999,8873.2000000000007]],"batl":null,"id":19924823,"hc":null,"bdatb":null}],"img":null,"tv":null,"con":null,"marketdefinition":null,"id":"1.258926623"}],"conflatems":null,"op":"mcm","id":3}
{"ct":null,"SegmentType":null,"clk":"AM6iAQDvpQEA/5kB","heartbeatms":null,"pt":1780839774219,"initialclk":null,"mc":[{"rc":[{"tv":2036640.74,"batb":null,"spb":null,"bdatl":null,"trd":[[1.1399999999999999,135082.39999999999]],"spf":null,"ltp":1.1399999999999999,"atb":[[1.04,73812.729999999996],[1.05,74273.130000000005],[1.0700000000000001,39099.620000000003],[1.0800000000000001,39933.199999999997],[1.0900000000000001,40105.849999999999],[1.0600000000000001,63296.940000000002],[1.02,90705.919999999998],[1.03,88944.589999999997],[1.01,93235.490000000005]],"spl":null,"spn":null,"atl":[[1.1399999999999999,30508.41]],"batl":null,"id":19924823,"hc":null,"bdatb":null}],"img":null,"tv":2280574.9199999999,"con":null,"marketdefinition":null,"id":"1.258926623"}],"conflatems":null,"op":"mcm","id":3}
{"ct":null,"SegmentType":null,"clk":"ANiiAQD8pQEAipoB","heartbeatms":null,"pt":1780839774324,"initialclk":null,"mc":[{"rc":[{"tv":2037640.74,"batb":null,"spb":null,"bdatl":null,"trd":[[1.1299999999999999,221014.87]],"spf":null,"ltp":1.1299999999999999,"atb":[[1.1299999999999999,7983.8000000000002]],"spl":null,"spn":null,"atl":null,"batl":null,"id":19924823,"hc":null,"bdatb":null}],"img":null,"tv":2281574.9199999999,"con":null,"marketdefinition":null,"id":"1.258926623"}],"conflatems":null,"op":"mcm","id":3}
{"ct":null,"SegmentType":null,"clk":"AIejAQC6pgEAs5oB","heartbeatms":null,"pt":1780839774888,"initialclk":null,"mc":[{"rc":[{"tv":2037840.74,"batb":null,"spb":null,"bdatl":null,"trd":[[1.1399999999999999,135282.39999999999]],"spf":null,"ltp":1.1399999999999999,"atb":null,"spl":null,"spn":null,"atl":[[1.1399999999999999,30408.41]],"batl":null,"id":19924823,"hc":null,"bdatb":null}],"img":null,"tv":2281774.9199999999,"con":null,"marketdefinition":null,"id":"1.258926623"}],"conflatems":null,"op":"mcm","id":3}
{"ct":null,"SegmentType":null,"clk":"AJKjAQDJpgEAupoB","heartbeatms":null,"pt":1780839774996,"initialclk":null,"mc":[{"rc":[{"tv":2037842.6599999999,"batb":null,"spb":null,"bdatl":null,"trd":[[1.1399999999999999,135284.32000000001]],"spf":null,"ltp":null,"atb":null,"spl":null,"spn":null,"atl":[[1.1399999999999999,30407.450000000001]],"batl":null,"id":19924823,"hc":null,"bdatb":null}],"img":null,"tv":2281776.8399999999,"con":null,"marketdefinition":null,"id":"1.258926623"}],"conflatems":null,"op":"mcm","id":3}
{"ct":null,"SegmentType":null,"clk":"AJijAQDUpgEAwJoB","heartbeatms":null,"pt":1780839775092,"initialclk":null,"mc":[{"rc":[{"tv":null,"batb":null,"spb":null,"bdatl":null,"trd":null,"spf":null,"ltp":null,"atb":[[6.2000000000000002,0.98999999999999999],[6.4000000000000004,0.85999999999999999],[7.2000000000000002,972.24000000000001]],"spl":null,"spn":null,"atl":[[9.8000000000000007,0.85999999999999999],[10,95.239999999999995]],"batl":null,"id":16570658,"hc":null,"bdatb":null},{"tv":null,"batb":null,"spb":null,"bdatl":null,"trd":null,"spf":null,"ltp":null,"atb":[[1.1000000000000001,53427.160000000003],[1.1100000000000001,75428.220000000001]],"spl":null,"spn":null,"atl":[[1.1699999999999999,10080.75],[1.19,8880.6800000000003],[1.1599999999999999,9732.2800000000007],[1.1799999999999999,8877.5]],"batl":null,"id":19924823,"hc":null,"bdatb":null}],"img":null,"tv":null,"con":null,"marketdefinition":null,"id":"1.258926623"}],"conflatems":null,"op":"mcm","id":3}
{"ct":null,"SegmentType":null,"clk":"ALCjAQDqpgEA2poB","heartbeatms":null,"pt":1780839775303,"initialclk":null,"mc":[{"rc":[{"tv":null,"batb":null,"spb":null,"bdatl":null,"trd":null,"spf":null,"ltp":null,"atb":[[1.1200000000000001,34054.879999999997]],"spl":null,"spn":null,"atl":null,"batl":null,"id":19924823,"hc":null,"bdatb":null}],"img":null,"tv":null,"con":null,"marketdefinition":null,"id":"1.258926623"}],"conflatems":null,"op":"mcm","id":3}
{"ct":null,"SegmentType":null,"clk":"ANujAQCipwEAhZsB","heartbeatms":null,"pt":1780839775824,"initialclk":null,"mc":[{"rc":[{"tv":null,"batb":null,"spb":null,"bdatl":null,"trd":null,"spf":null,"ltp":null,"atb":[[6.5999999999999996,25],[6.2000000000000002,14.449999999999999],[6.4000000000000004,26.780000000000001]],"spl":null,"spn":null,"atl":null,"batl":null,"id":16570658,"hc":null,"bdatb":null},{"tv":2037862.6599999999,"batb":null,"spb":null,"bdatl":null,"trd":[[1.1399999999999999,135304.32000000001]],"spf":null,"ltp":null,"atb":null,"spl":null,"spn":null,"atl":[[1.1399999999999999,30397.450000000001]],"batl":null,"id":19924823,"hc":null,"bdatb":null}],"img":null,"tv":2281796.8399999999,"con":null,"marketdefinition":null,"id":"1.258926623"}],"conflatems":null,"op":"mcm","id":3}
{"ct":null,"SegmentType":null,"clk":"AOajAQCqpwEAjJsB","heartbeatms":null,"pt":1780839775926,"initialclk":null,"mc":[{"rc":[{"tv":null,"batb":null,"spb":null,"bdatl":null,"trd":null,"spf":null,"ltp":null,"atb":null,"spl":null,"spn":null,"atl":[[1.1599999999999999,9734.6599999999999]],"batl":null,"id":19924823,"hc":null,"bdatb":null}],"img":null,"tv":null,"con":null,"marketdefinition":null,"id":"1.258926623"}],"conflatems":null,"op":"mcm","id":3}
{"ct":null,"SegmentType":null,"clk":"APOjAQC0pwEAlpsB","heartbeatms":null,"pt":1780839776025,"initialclk":null,"mc":[{"rc":[{"tv":null,"batb":null,"spb":null,"bdatl":null,"trd":null,"spf":null,"ltp":null,"atb":[[8.4000000000000004,0.080000000000000002]],"spl":null,"spn":null,"atl":null,"batl":null,"id":16570658,"hc":null,"bdatb":null}],"img":null,"tv":null,"con":null,"marketdefinition":null,"id":"1.258926623"}],"conflatems":null,"op":"mcm","id":3}
{"ct":null,"SegmentType":null,"clk":"AKikAQDtpwEAzpsB","heartbeatms":null,"pt":1780839776598,"initialclk":null,"mc":[{"rc":[{"tv":null,"batb":null,"spb":null,"bdatl":null,"trd":null,"spf":null,"ltp":null,"atb":[[7.4000000000000004,322.83999999999997]],"spl":null,"spn":null,"atl":[[9,253.31999999999999]],"batl":null,"id":16570658,"hc":null,"bdatb":null},{"tv":null,"batb":null,"spb":null,"bdatl":null,"trd":null,"spf":null,"ltp":null,"atb":[[1.1200000000000001,35394.160000000003]],"spl":null,"spn":null,"atl":[[1.1599999999999999,10957.25]],"batl":null,"id":19924823,"hc":null,"bdatb":null}],"img":null,"tv":null,"con":null,"marketdefinition":null,"id":"1.258926623"}],"conflatems":null,"op":"mcm","id":3}
{"ct":null,"SegmentType":null,"clk":"AMCkAQCGqAEA6JsB","heartbeatms":null,"pt":1780839776909,"initialclk":null,"mc":[{"rc":[{"tv":null,"batb":null,"spb":null,"bdatl":null,"trd":null,"spf":null,"ltp":null,"atb":[[7.2000000000000002,778.97000000000003]],"spl":null,"spn":null,"atl":null,"batl":null,"id":16570658,"hc":null,"bdatb":null},{"tv":null,"batb":null,"spb":null,"bdatl":null,"trd":null,"spf":null,"ltp":null,"atb":[[1.03,88945.339999999997]],"spl":null,"spn":null,"atl":[[1.1699999999999999,8891.3899999999994]],"batl":null,"id":19924823,"hc":null,"bdatb":null}],"img":null,"tv":null,"con":null,"marketdefinition":null,"id":"1.258926623"}],"conflatems":null,"op":"mcm","id":3}
{"ct":null,"SegmentType":null,"clk":"AMekAQCOqAEA7psB","heartbeatms":null,"pt":1780839777009,"initialclk":null,"mc":[{"rc":[{"tv":null,"batb":null,"spb":null,"bdatl":null,"trd":null,"spf":null,"ltp":null,"atb":[[8.4000000000000004,138.75]],"spl":null,"spn":null,"atl":null,"batl":null,"id":16570658,"hc":null,"bdatb":null}],"img":null,"tv":null,"con":null,"marketdefinition":null,"id":"1.258926623"}],"conflatems":null,"op":"mcm","id":3}
{"ct":null,"SegmentType":null,"clk":"AM\u002BkAQCTqAEA9psB","heartbeatms":null,"pt":1780839777113,"initialclk":null,"mc":[{"rc":[{"tv":null,"batb":null,"spb":null,"bdatl":null,"trd":null,"spf":null,"ltp":null,"atb":[[8.4000000000000004,293.54000000000002]],"spl":null,"spn":null,"atl":null,"batl":null,"id":16570658,"hc":null,"bdatb":null}],"img":null,"tv":null,"con":null,"marketdefinition":null,"id":"1.258926623"}],"conflatems":null,"op":"mcm","id":3}
{"ct":null,"SegmentType":null,"clk":"ANikAQCZqAEA/5sB","heartbeatms":null,"pt":1780839777218,"initialclk":null,"mc":[{"rc":[{"tv":null,"batb":null,"spb":null,"bdatl":null,"trd":null,"spf":null,"ltp":null,"atb":[[7.4000000000000004,300.98000000000002]],"spl":null,"spn":null,"atl":[[9,86.659999999999997]],"batl":null,"id":16570658,"hc":null,"bdatb":null}],"img":null,"tv":null,"con":null,"marketdefinition":null,"id":"1.258926623"}],"conflatems":null,"op":"mcm","id":3}
{"ct":null,"SegmentType":null,"clk":"AOWkAQChqAEAhZwB","heartbeatms":null,"pt":1780839777325,"initialclk":null,"mc":[{"rc":[{"tv":null,"batb":null,"spb":null,"bdatl":null,"trd":null,"spf":null,"ltp":null,"atb":null,"spl":null,"spn":null,"atl":[[13,5.8300000000000001],[12.5,6.0800000000000001],[12,6.3600000000000003]],"batl":null,"id":16570658,"hc":null,"bdatb":null},{"tv":null,"batb":null,"spb":null,"bdatl":null,"trd":null,"spf":null,"ltp":null,"atb":null,"spl":null,"spn":null,"atl":[[1.1399999999999999,30483.830000000002]],"batl":null,"id":19924823,"hc":null,"bdatb":null}],"img":null,"tv":null,"con":null,"marketdefinition":null,"id":"1.258926623"}],"conflatems":null,"op":"mcm","id":3}
{"ct":null,"SegmentType":null,"clk":"AK5bAPxUAKApAPlqAMxS","heartbeatms":null,"pt":1780839777683,"Oc":[{"Accountid":null,"Orc":[{"Mb":null,"Uo":[{"Side":0,"pt":0,"Ot":0,"Status":0,"Sv":0,"P":1.1399999999999999,"Sc":0,"rc":"REG_LGA","S":5,"Pd":1780839777000,"Rac":"","Md":null,"Sl":0,"Avp":null,"Sm":0,"id":"431727077567","Bsp":null,"Sr":5,"Cd":null,"Rfo":"Tab-B-0","Rfs":"NA"}],"id":19924823,"hc":null,"FullImage":null,"Ml":null}],"Closed":null,"id":"1.258926623","FullImage":null}],"initialclk":null,"conflatems":null,"op":"ocm","id":2}
{"ct":null,"SegmentType":null,"clk":"AIilAQC\u002BqAEAo5wB","heartbeatms":null,"pt":1780839777689,"initialclk":null,"mc":[{"rc":[{"tv":null,"batb":null,"spb":null,"bdatl":null,"trd":null,"spf":null,"ltp":null,"atb":null,"spl":null,"spn":null,"atl":[[11,105.94],[10.5,91.25],[10,87.469999999999999]],"batl":null,"id":16570658,"hc":null,"bdatb":null},{"tv":null,"batb":null,"spb":null,"bdatl":null,"trd":null,"spf":null,"ltp":null,"atb":null,"spl":null,"spn":null,"atl":[[1.1399999999999999,30486.470000000001]],"batl":null,"id":19924823,"hc":null,"bdatb":null}],"img":null,"tv":null,"con":null,"marketdefinition":null,"id":"1.258926623"}],"conflatems":null,"op":"mcm","id":3}
{"ct":null,"SegmentType":null,"clk":"ALGlAQDcqAEAxJwB","heartbeatms":null,"pt":1780839778105,"initialclk":null,"mc":[{"rc":[{"tv":2038011.8000000001,"batb":null,"spb":null,"bdatl":null,"trd":[[1.1299999999999999,221164.01000000001]],"spf":null,"ltp":1.1299999999999999,"atb":[[1.1299999999999999,7909.2299999999996]],"spl":null,"spn":null,"atl":null,"batl":null,"id":19924823,"hc":null,"bdatb":null}],"img":null,"tv":2281945.98,"con":null,"marketdefinition":null,"id":"1.258926623"}],"conflatems":null,"op":"mcm","id":3}
{"ct":null,"SegmentType":null,"clk":"AP\u002BlAQDPqQEAj50B","heartbeatms":null,"pt":1780839779000,"initialclk":null,"mc":[{"rc":[{"tv":243934.34,"batb":null,"spb":null,"bdatl":null,"trd":[[8.5999999999999996,1989.72]],"spf":null,"ltp":8.5999999999999996,"atb":null,"spl":null,"spn":null,"atl":[[8.5999999999999996,344.31]],"batl":null,"id":16570658,"hc":null,"bdatb":null}],"img":null,"tv":2281946.1400000001,"con":null,"marketdefinition":null,"id":"1.258926623"}],"conflatems":null,"op":"mcm","id":3}
{"ct":null,"SegmentType":null,"clk":"ANCmAQCsqgEA/J0B","heartbeatms":null,"pt":1780839779922,"initialclk":null,"mc":[{"rc":[{"tv":243937.19,"batb":null,"spb":null,"bdatl":null,"trd":[[8.4000000000000004,396.50999999999999]],"spf":null,"ltp":8.4000000000000004,"atb":[[8.4000000000000004,292.12]],"spl":null,"spn":null,"atl":null,"batl":null,"id":16570658,"hc":null,"bdatb":null}],"img":null,"tv":2281948.9900000002,"con":null,"marketdefinition":null,"id":"1.258926623"}],"conflatems":null,"op":"mcm","id":3}
{"ct":null,"SegmentType":null,"clk":"ANmmAQC2qgEAhZ4B","heartbeatms":null,"pt":1780839780035,"initialclk":null,"mc":[{"rc":[{"tv":244248.14999999999,"batb":null,"spb":null,"bdatl":null,"trd":[[8.5999999999999996,2300.6799999999998]],"spf":null,"ltp":8.5999999999999996,"atb":null,"spl":null,"spn":null,"atl":[[8.5999999999999996,188.83000000000001]],"batl":null,"id":16570658,"hc":null,"bdatb":null}],"img":null,"tv":2282259.9500000002,"con":null,"marketdefinition":null,"id":"1.258926623"}],"conflatems":null,"op":"mcm","id":3}
{"ct":null,"SegmentType":null,"clk":"AOmmAQDLqgEAmZ4B","heartbeatms":null,"pt":1780839780235,"initialclk":null,"mc":[{"rc":[{"tv":null,"batb":null,"spb":null,"bdatl":null,"trd":null,"spf":null,"ltp":null,"atb":null,"spl":null,"spn":null,"atl":[[8.8000000000000007,528.23000000000002]],"batl":null,"id":16570658,"hc":null,"bdatb":null},{"tv":null,"batb":null,"spb":null,"bdatl":null,"trd":null,"spf":null,"ltp":null,"atb":[[1.03,88945.580000000002],[1.1200000000000001,36550.949999999997]],"spl":null,"spn":null,"atl":null,"batl":null,"id":19924823,"hc":null,"bdatb":null}],"img":null,"tv":null,"con":null,"marketdefinition":null,"id":"1.258926623"}],"conflatems":null,"op":"mcm","id":3}
{"ct":null,"SegmentType":null,"clk":"AJCnAQD8qgEAuZ4B","heartbeatms":null,"pt":1780839780606,"initialclk":null,"mc":[{"rc":[{"tv":null,"batb":null,"spb":null,"bdatl":null,"trd":null,"spf":null,"ltp":null,"atb":[[1.03,88945.339999999997]],"spl":null,"spn":null,"atl":[[1.1499999999999999,43093.519999999997]],"batl":null,"id":19924823,"hc":null,"bdatb":null}],"img":null,"tv":null,"con":null,"marketdefinition":null,"id":"1.258926623"}],"conflatems":null,"op":"mcm","id":3}
{"ct":null,"SegmentType":null,"clk":"AJunAQCHqwEAvp4B","heartbeatms":null,"pt":1780839780711,"initialclk":null,"mc":[{"rc":[{"tv":null,"batb":null,"spb":null,"bdatl":null,"trd":null,"spf":null,"ltp":null,"atb":[[6.2000000000000002,0.98999999999999999]],"spl":null,"spn":null,"atl":null,"batl":null,"id":16570658,"hc":null,"bdatb":null}],"img":null,"tv":null,"con":null,"marketdefinition":null,"id":"1.258926623"}],"conflatems":null,"op":"mcm","id":3}
{"ct":null,"SegmentType":null,"clk":"AKenAQCQqwEAyJ4B","heartbeatms":null,"pt":1780839780815,"initialclk":null,"mc":[{"rc":[{"tv":null,"batb":null,"spb":null,"bdatl":null,"trd":null,"spf":null,"ltp":null,"atb":[[6.7999999999999998,24.52]],"spl":null,"spn":null,"atl":null,"batl":null,"id":16570658,"hc":null,"bdatb":null},{"tv":null,"batb":null,"spb":null,"bdatl":null,"trd":null,"spf":null,"ltp":null,"atb":null,"spl":null,"spn":null,"atl":[[1.23,681.25999999999999]],"batl":null,"id":19924823,"hc":null,"bdatb":null}],"img":null,"tv":null,"con":null,"marketdefinition":null,"id":"1.258926623"}],"conflatems":null,"op":"mcm","id":3}
{"ct":null,"SegmentType":null,"clk":"ALunAQCjqwEA2Z4B","heartbeatms":null,"pt":1780839781022,"initialclk":null,"mc":[{"rc":[{"tv":null,"batb":null,"spb":null,"bdatl":null,"trd":null,"spf":null,"ltp":null,"atb":null,"spl":null,"spn":null,"atl":[[8.5999999999999996,148.80000000000001]],"batl":null,"id":16570658,"hc":null,"bdatb":null}],"img":null,"tv":null,"con":null,"marketdefinition":null,"id":"1.258926623"}],"conflatems":null,"op":"mcm","id":3}
{"ct":null,"SegmentType":null,"clk":"APWnAQDZqwEAjJ8B","heartbeatms":null,"pt":1780839781629,"initialclk":null,"mc":[{"rc":[{"tv":null,"batb":null,"spb":null,"bdatl":null,"trd":null,"spf":null,"ltp":null,"atb":null,"spl":null,"spn":null,"atl":[[1.1599999999999999,10960.25]],"batl":null,"id":19924823,"hc":null,"bdatb":null}],"img":null,"tv":null,"con":null,"marketdefinition":null,"id":"1.258926623"}],"conflatems":null,"op":"mcm","id":3}
{"ct":null,"SegmentType":null,"clk":"AMmoAQCkrAEAzp8B","heartbeatms":null,"pt":1780839782416,"initialclk":null,"mc":[{"rc":[{"tv":2038111.8100000001,"batb":null,"spb":null,"bdatl":null,"trd":[[1.1399999999999999,135404.32999999999]],"spf":null,"ltp":1.1399999999999999,"atb":null,"spl":null,"spn":null,"atl":[[1.1399999999999999,30436.470000000001]],"batl":null,"id":19924823,"hc":null,"bdatb":null}],"img":null,"tv":2282359.96,"con":null,"marketdefinition":null,"id":"1.258926623"}],"conflatems":null,"op":"mcm","id":3}
{"ct":null,"SegmentType":null,"clk":"ANyoAQCyrAEA3J8B","heartbeatms":null,"pt":1780839782610,"initialclk":null,"mc":[{"rc":[{"tv":null,"batb":null,"spb":null,"bdatl":null,"trd":null,"spf":null,"ltp":null,"atb":null,"spl":null,"spn":null,"atl":[[1.1399999999999999,30004.119999999999]],"batl":null,"id":19924823,"hc":null,"bdatb":null}],"img":null,"tv":null,"con":null,"marketdefinition":null,"id":"1.258926623"}],"conflatems":null,"op":"mcm","id":3}
{"ct":null,"SegmentType":null,"clk":"AJepAQDvrAEAnqAB","heartbeatms":null,"pt":1780839783136,"initialclk":null,"mc":[{"rc":[{"tv":null,"batb":null,"spb":null,"bdatl":null,"trd":null,"spf":null,"ltp":null,"atb":null,"spl":null,"spn":null,"atl":[[1.1399999999999999,27115.540000000001]],"batl":null,"id":19924823,"hc":null,"bdatb":null}],"img":null,"tv":null,"con":null,"marketdefinition":null,"id":"1.258926623"}],"conflatems":null,"op":"mcm","id":3}
{"ct":null,"SegmentType":null,"clk":"ALqpAQCJrQEAvqAB","heartbeatms":null,"pt":1780839783399,"initialclk":null,"mc":[{"rc":[{"tv":null,"batb":null,"spb":null,"bdatl":null,"trd":null,"spf":null,"ltp":null,"atb":[[1.1200000000000001,36645.830000000002]],"spl":null,"spn":null,"atl":null,"batl":null,"id":19924823,"hc":null,"bdatb":null}],"img":null,"tv":null,"con":null,"marketdefinition":null,"id":"1.258926623"}],"conflatems":null,"op":"mcm","id":3}
{"ct":null,"SegmentType":null,"clk":"AMWpAQCZrQEAyKAB","heartbeatms":null,"pt":1780839783502,"initialclk":null,"mc":[{"rc":[{"tv":2038116.1399999999,"batb":null,"spb":null,"bdatl":null,"trd":[[1.1299999999999999,221168.34]],"spf":null,"ltp":1.1299999999999999,"atb":[[1.1299999999999999,7907.0600000000004]],"spl":null,"spn":null,"atl":null,"batl":null,"id":19924823,"hc":null,"bdatb":null}],"img":null,"tv":2282364.29,"con":null,"marketdefinition":null,"id":"1.258926623"}],"conflatems":null,"op":"mcm","id":3}
{"ct":null,"SegmentType":null,"clk":"AN2pAQCrrQEA3aAB","heartbeatms":null,"pt":1780839783708,"initialclk":null,"mc":[{"rc":[{"tv":2038116.6200000001,"batb":null,"spb":null,"bdatl":null,"trd":[[1.1399999999999999,135404.81]],"spf":null,"ltp":1.1399999999999999,"atb":null,"spl":null,"spn":null,"atl":[[1.1399999999999999,27115.299999999999]],"batl":null,"id":19924823,"hc":null,"bdatb":null}],"img":null,"tv":2282364.77,"con":null,"marketdefinition":null,"id":"1.258926623"}],"conflatems":null,"op":"mcm","id":3}
{"ct":null,"SegmentType":null,"clk":"APGpAQC3rQEA6KAB","heartbeatms":null,"pt":1780839783909,"initialclk":null,"mc":[{"rc":[{"tv":244248.85000000001,"batb":null,"spb":null,"bdatl":null,"trd":[[8.5999999999999996,2301.3800000000001]],"spf":null,"ltp":null,"atb":null,"spl":null,"spn":null,"atl":[[8.5999999999999996,148.44999999999999]],"batl":null,"id":16570658,"hc":null,"bdatb":null}],"img":null,"tv":2282365.4700000002,"con":null,"marketdefinition":null,"id":"1.258926623"}],"conflatems":null,"op":"mcm","id":3}
{"ct":null,"SegmentType":null,"clk":"AI2qAQDPrQEA9qAB","heartbeatms":null,"pt":1780839784120,"initialclk":null,"mc":[{"rc":[{"tv":244328.89999999999,"batb":null,"spb":null,"bdatl":null,"trd":[[8.4000000000000004,476.56]],"spf":null,"ltp":8.4000000000000004,"atb":[[8.4000000000000004,252.09]],"spl":null,"spn":null,"atl":null,"batl":null,"id":16570658,"hc":null,"bdatb":null},{"tv":null,"batb":null,"spb":null,"bdatl":null,"trd":null,"spf":null,"ltp":null,"atb":[[1.03,88944.589999999997]],"spl":null,"spn":null,"atl":null,"batl":null,"id":19924823,"hc":null,"bdatb":null}],"img":null,"tv":2282445.52,"con":null,"marketdefinition":null,"id":"1.258926623"}],"conflatems":null,"op":"mcm","id":3}
{"ct":null,"SegmentType":null,"clk":"AJaqAQDhrQEAgKEB","heartbeatms":null,"pt":1780839784222,"initialclk":null,"mc":[{"rc":[{"tv":null,"batb":null,"spb":null,"bdatl":null,"trd":null,"spf":null,"ltp":null,"atb":[[7.2000000000000002,777.24000000000001]],"spl":null,"spn":null,"atl":null,"batl":null,"id":16570658,"hc":null,"bdatb":null}],"img":null,"tv":null,"con":null,"marketdefinition":null,"id":"1.258926623"}],"conflatems":null,"op":"mcm","id":3}
{"ct":null,"SegmentType":null,"clk":"AJ6qAQDurQEAiKEB","heartbeatms":null,"pt":1780839784326,"initialclk":null,"mc":[{"rc":[{"tv":244334.78,"batb":null,"spb":null,"bdatl":null,"trd":[[8.4000000000000004,482.44]],"spf":null,"ltp":null,"atb":[[8.4000000000000004,249.15000000000001]],"spl":null,"spn":null,"atl":null,"batl":null,"id":16570658,"hc":null,"bdatb":null}],"img":null,"tv":2282451.3999999999,"con":null,"marketdefinition":null,"id":"1.258926623"}],"conflatems":null,"op":"mcm","id":3}
{"ct":null,"SegmentType":null,"clk":"AO\u002BqAQC5rgEAuKEB","heartbeatms":null,"pt":1780839784997,"initialclk":null,"mc":[{"rc":[{"tv":null,"batb":null,"spb":null,"bdatl":null,"trd":null,"spf":null,"ltp":null,"atb":null,"spl":null,"spn":null,"atl":[[9,253.31999999999999]],"batl":null,"id":16570658,"hc":null,"bdatb":null}],"img":null,"tv":null,"con":null,"marketdefinition":null,"id":"1.258926623"}],"conflatems":null,"op":"mcm","id":3}
{"ct":null,"SegmentType":null,"clk":"AJGrAQDYrgEAz6EB","heartbeatms":null,"pt":1780839785314,"initialclk":null,"mc":[{"rc":[{"tv":null,"batb":null,"spb":null,"bdatl":null,"trd":null,"spf":null,"ltp":null,"atb":null,"spl":null,"spn":null,"atl":[[1.1399999999999999,27165.299999999999]],"batl":null,"id":19924823,"hc":null,"bdatb":null}],"img":null,"tv":null,"con":null,"marketdefinition":null,"id":"1.258926623"}],"conflatems":null,"op":"mcm","id":3}
{"ct":null,"SegmentType":null,"clk":"AK6rAQD6rgEA4aEB","heartbeatms":null,"pt":1780839785622,"initialclk":null,"mc":[{"rc":[{"tv":null,"batb":null,"spb":null,"bdatl":null,"trd":null,"spf":null,"ltp":null,"atb":[[8,522.24000000000001]],"spl":null,"spn":null,"atl":null,"batl":null,"id":16570658,"hc":null,"bdatb":null}],"img":null,"tv":null,"con":null,"marketdefinition":null,"id":"1.258926623"}],"conflatems":null,"op":"mcm","id":3}
{"ct":null,"SegmentType":null,"clk":"ALirAQCErwEA6qEB","heartbeatms":null,"pt":1780839785721,"initialclk":null,"mc":[{"rc":[{"tv":null,"batb":null,"spb":null,"bdatl":null,"trd":null,"spf":null,"ltp":null,"atb":[[7,11.359999999999999]],"spl":null,"spn":null,"atl":null,"batl":null,"id":16570658,"hc":null,"bdatb":null}],"img":null,"tv":null,"con":null,"marketdefinition":null,"id":"1.258926623"}],"conflatems":null,"op":"mcm","id":3}
{"ct":null,"SegmentType":null,"clk":"AL6rAQCLrwEA76EB","heartbeatms":null,"pt":1780839785824,"initialclk":null,"mc":[{"rc":[{"tv":2038120.73,"batb":null,"spb":null,"bdatl":null,"trd":[[1.1399999999999999,135408.92000000001]],"spf":null,"ltp":null,"atb":null,"spl":null,"spn":null,"atl":[[1.1399999999999999,27163.25]],"batl":null,"id":19924823,"hc":null,"bdatb":null}],"img":null,"tv":2282455.5099999998,"con":null,"marketdefinition":null,"id":"1.258926623"}],"conflatems":null,"op":"mcm","id":3}
{"ct":null,"SegmentType":null,"clk":"AOirAQCwrwEAiKIB","heartbeatms":null,"pt":1780839786242,"initialclk":null,"mc":[{"rc":[{"tv":2043897.8799999999,"batb":null,"spb":null,"bdatl":null,"trd":[[1.1299999999999999,226945.48999999999]],"spf":null,"ltp":1.1299999999999999,"atb":[[1.1299999999999999,5018.4899999999998]],"spl":null,"spn":null,"atl":null,"batl":null,"id":19924823,"hc":null,"bdatb":null}],"img":null,"tv":2288232.6600000001,"con":null,"marketdefinition":null,"id":"1.258926623"}],"conflatems":null,"op":"mcm","id":3}
{"ct":null,"SegmentType":null,"clk":"AMCsAQCDsAEAzqIB","heartbeatms":null,"pt":1780839787123,"initialclk":null,"mc":[{"rc":[{"tv":244344.78,"batb":null,"spb":null,"bdatl":null,"trd":[[8.4000000000000004,492.44]],"spf":null,"ltp":null,"atb":[[8.4000000000000004,244.15000000000001]],"spl":null,"spn":null,"atl":null,"batl":null,"id":16570658,"hc":null,"bdatb":null}],"img":null,"tv":2288242.6600000001,"con":null,"marketdefinition":null,"id":"1.258926623"}],"conflatems":null,"op":"mcm","id":3}
{"ct":null,"SegmentType":null,"clk":"APqsAQC3sAEA\u002BKIB","heartbeatms":null,"pt":1780839787737,"initialclk":null,"mc":[{"rc":[{"tv":null,"batb":null,"spb":null,"bdatl":null,"trd":null,"spf":null,"ltp":null,"atb":null,"spl":null,"spn":null,"atl":[[1.1499999999999999,31370.360000000001]],"batl":null,"id":19924823,"hc":null,"bdatb":null}],"img":null,"tv":null,"con":null,"marketdefinition":null,"id":"1.258926623"}],"conflatems":null,"op":"mcm","id":3}
{"ct":null,"SegmentType":null,"clk":"AKStAQDssAEAo6MB","heartbeatms":null,"pt":1780839788214,"initialclk":null,"mc":[{"rc":[{"tv":2043911.6299999999,"batb":null,"spb":null,"bdatl":null,"trd":[[1.1299999999999999,226959.23999999999]],"spf":null,"ltp":null,"atb":[[1.1299999999999999,5011.6199999999999]],"spl":null,"spn":null,"atl":null,"batl":null,"id":19924823,"hc":null,"bdatb":null}],"img":null,"tv":2288256.4100000001,"con":null,"marketdefinition":null,"id":"1.258926623"}],"conflatems":null,"op":"mcm","id":3}
{"ct":null,"SegmentType":null,"clk":"ANKtAQClsQEAzKMB","heartbeatms":null,"pt":1780839788733,"initialclk":null,"mc":[{"rc":[{"tv":2043922.6200000001,"batb":null,"spb":null,"bdatl":null,"trd":[[1.1299999999999999,226970.23000000001]],"spf":null,"ltp":null,"atb":[[1.1299999999999999,5006.1199999999999]],"spl":null,"spn":null,"atl":null,"batl":null,"id":19924823,"hc":null,"bdatb":null}],"img":null,"tv":2288267.3999999999,"con":null,"marketdefinition":null,"id":"1.258926623"}],"conflatems":null,"op":"mcm","id":3}
{"ct":null,"SegmentType":null,"clk":"AOitAQC5sQEA2KMB","heartbeatms":null,"pt":1780839789032,"initialclk":null,"mc":[{"rc":[{"tv":2043942.6200000001,"batb":null,"spb":null,"bdatl":null,"trd":[[1.1299999999999999,226990.23000000001]],"spf":null,"ltp":null,"atb":[[1.1299999999999999,4996.1199999999999]],"spl":null,"spn":null,"atl":null,"batl":null,"id":19924823,"hc":null,"bdatb":null}],"img":null,"tv":2288287.3999999999,"con":null,"marketdefinition":null,"id":"1.258926623"}],"conflatems":null,"op":"mcm","id":3}
{"ct":null,"SegmentType":null,"clk":"AP6tAQDTsQEA7KMB","heartbeatms":null,"pt":1780839789250,"initialclk":null,"mc":[{"rc":[{"tv":null,"batb":null,"spb":null,"bdatl":null,"trd":null,"spf":null,"ltp":null,"atb":[[7,0.98999999999999999]],"spl":null,"spn":null,"atl":null,"batl":null,"id":16570658,"hc":null,"bdatb":null}],"img":null,"tv":null,"con":null,"marketdefinition":null,"id":"1.258926623"}],"conflatems":null,"op":"mcm","id":3}
{"ct":null,"SegmentType":null,"clk":"AISuAQDksQEA9KMB","heartbeatms":null,"pt":1780839789357,"initialclk":null,"mc":[{"rc":[{"tv":245402.25,"batb":null,"spb":null,"bdatl":null,"trd":[[8.4000000000000004,980.73000000000002],[8.1999999999999993,1658.72],[8,3816.0799999999999]],"spf":null,"ltp":8,"atb":[[8.4000000000000004,0],[8.1999999999999993,0],[8,478.81999999999999]],"spl":null,"spn":null,"atl":null,"batl":null,"id":16570658,"hc":null,"bdatb":null},{"tv":null,"batb":null,"spb":null,"bdatl":null,"trd":null,"spf":null,"ltp":null,"atb":[[1.1299999999999999,5296.1199999999999]],"spl":null,"spn":null,"atl":null,"batl":null,"id":19924823,"hc":null,"bdatb":null}],"img":null,"tv":2289344.8700000001,"con":null,"marketdefinition":null,"id":"1.258926623"}],"conflatems":null,"op":"mcm","id":3}
{"ct":null,"SegmentType":null,"clk":"AJauAQD1sQEAgqQB","heartbeatms":null,"pt":1780839789505,"initialclk":null,"mc":[{"rc":[{"tv":null,"batb":null,"spb":null,"bdatl":null,"trd":null,"spf":null,"ltp":null,"atb":[[8,549.40999999999997]],"spl":null,"spn":null,"atl":null,"batl":null,"id":16570658,"hc":null,"bdatb":null},{"tv":null,"batb":null,"spb":null,"bdatl":null,"trd":null,"spf":null,"ltp":null,"atb":[[1.1299999999999999,5596.1199999999999]],"spl":null,"spn":null,"atl":null,"batl":null,"id":19924823,"hc":null,"bdatb":null}],"img":null,"tv":null,"con":null,"marketdefinition":null,"id":"1.258926623"}],"conflatems":null,"op":"mcm","id":3}
{"ct":null,"SegmentType":null,"clk":"AKuuAQCNsgEAjqQB","heartbeatms":null,"pt":1780839789707,"initialclk":null,"mc":[{"rc":[{"tv":null,"batb":null,"spb":null,"bdatl":null,"trd":null,"spf":null,"ltp":null,"atb":[[1.1299999999999999,5896.1199999999999]],"spl":null,"spn":null,"atl":null,"batl":null,"id":19924823,"hc":null,"bdatb":null}],"img":null,"tv":null,"con":null,"marketdefinition":null,"id":"1.258926623"}],"conflatems":null,"op":"mcm","id":3}
{"ct":null,"SegmentType":null,"clk":"ALOuAQCasgEAkqQB","heartbeatms":null,"pt":1780839789820,"initialclk":null,"mc":[{"rc":[{"tv":null,"batb":null,"spb":null,"bdatl":null,"trd":null,"spf":null,"ltp":null,"atb":[[8.1999999999999993,153.05000000000001]],"spl":null,"spn":null,"atl":null,"batl":null,"id":16570658,"hc":null,"bdatb":null},{"tv":null,"batb":null,"spb":null,"bdatl":null,"trd":null,"spf":null,"ltp":null,"atb":[[1.1299999999999999,6196.1199999999999]],"spl":null,"spn":null,"atl":null,"batl":null,"id":19924823,"hc":null,"bdatb":null}],"img":null,"tv":null,"con":null,"marketdefinition":null,"id":"1.258926623"}],"conflatems":null,"op":"mcm","id":3}
{"ct":null,"SegmentType":null,"clk":"AMiuAQCwsgEAnqQB","heartbeatms":null,"pt":1780839790033,"initialclk":null,"mc":[{"rc":[{"tv":null,"batb":null,"spb":null,"bdatl":null,"trd":null,"spf":null,"ltp":null,"atb":null,"spl":null,"spn":null,"atl":[[9,86.659999999999997]],"batl":null,"id":16570658,"hc":null,"bdatb":null}],"img":null,"tv":null,"con":null,"marketdefinition":null,"id":"1.258926623"}],"conflatems":null,"op":"mcm","id":3}
{"ct":null,"SegmentType":null,"clk":"AO2uAQDbsgEAs6QB","heartbeatms":null,"pt":1780839790429,"initialclk":null,"mc":[{"rc":[{"tv":null,"batb":null,"spb":null,"bdatl":null,"trd":null,"spf":null,"ltp":null,"atb":[[6.4000000000000004,0.85999999999999999]],"spl":null,"spn":null,"atl":null,"batl":null,"id":16570658,"hc":null,"bdatb":null}],"img":null,"tv":null,"con":null,"marketdefinition":null,"id":"1.258926623"}],"conflatems":null,"op":"mcm","id":3}
{"ct":null,"SegmentType":null,"clk":"APSuAQDjsgEAuaQB","heartbeatms":null,"pt":1780839790537,"initialclk":null,"mc":[{"rc":[{"tv":null,"batb":null,"spb":null,"bdatl":null,"trd":null,"spf":null,"ltp":null,"atb":null,"spl":null,"spn":null,"atl":[[1.24,205.93000000000001]],"batl":null,"id":19924823,"hc":null,"bdatb":null}],"img":null,"tv":null,"con":null,"marketdefinition":null,"id":"1.258926623"}],"conflatems":null,"op":"mcm","id":3}
{"ct":null,"SegmentType":null,"clk":"AP\u002BuAQDpsgEAw6QB","heartbeatms":null,"pt":1780839790646,"initialclk":null,"mc":[{"rc":[{"tv":null,"batb":null,"spb":null,"bdatl":null,"trd":null,"spf":null,"ltp":null,"atb":[[8,478.81999999999999]],"spl":null,"spn":null,"atl":null,"batl":null,"id":16570658,"hc":null,"bdatb":null},{"tv":2043959.6000000001,"batb":null,"spb":null,"bdatl":null,"trd":[[1.1299999999999999,227007.20999999999]],"spf":null,"ltp":null,"atb":[[1.1299999999999999,6775.0600000000004]],"spl":null,"spn":null,"atl":null,"batl":null,"id":19924823,"hc":null,"bdatb":null}],"img":null,"tv":2289361.8500000001,"con":null,"marketdefinition":null,"id":"1.258926623"}],"conflatems":null,"op":"mcm","id":3}
{"ct":null,"SegmentType":null,"clk":"AKCvAQCMswEA6qQB","heartbeatms":null,"pt":1780839791011,"initialclk":null,"mc":[{"rc":[{"tv":245611.51000000001,"batb":null,"spb":null,"bdatl":null,"trd":[[8.1999999999999993,1660.6800000000001],[8.5999999999999996,2508.6799999999998]],"spf":null,"ltp":8.5999999999999996,"atb":[[8.1999999999999993,252.06999999999999]],"spl":null,"spn":null,"atl":[[8.5999999999999996,44.799999999999997]],"batl":null,"id":16570658,"hc":null,"bdatb":null}],"img":null,"tv":2289571.1099999999,"con":null,"marketdefinition":null,"id":"1.258926623"}],"conflatems":null,"op":"mcm","id":3}
{"ct":null,"SegmentType":null,"clk":"ALKvAQCcswEA/aQB","heartbeatms":null,"pt":1780839791220,"initialclk":null,"mc":[{"rc":[{"tv":null,"batb":null,"spb":null,"bdatl":null,"trd":null,"spf":null,"ltp":null,"atb":[[8.1999999999999993,352.06999999999999]],"spl":null,"spn":null,"atl":null,"batl":null,"id":16570658,"hc":null,"bdatb":null}],"img":null,"tv":null,"con":null,"marketdefinition":null,"id":"1.258926623"}],"conflatems":null,"op":"mcm","id":3}
{"ct":null,"SegmentType":null,"clk":"AMGvAQCmswEAi6UB","heartbeatms":null,"pt":1780839791330,"initialclk":null,"mc":[{"rc":[{"tv":null,"batb":null,"spb":null,"bdatl":null,"trd":null,"spf":null,"ltp":null,"atb":[[6.5999999999999996,0]],"spl":null,"spn":null,"atl":null,"batl":null,"id":16570658,"hc":null,"bdatb":null}],"img":null,"tv":null,"con":null,"marketdefinition":null,"id":"1.258926623"}],"conflatems":null,"op":"mcm","id":3}
{"ct":null,"SegmentType":null,"clk":"AMavAQCsswEAlaUB","heartbeatms":null,"pt":1780839791421,"initialclk":null,"mc":[{"rc":[{"tv":null,"batb":null,"spb":null,"bdatl":null,"trd":null,"spf":null,"ltp":null,"atb":[[8.1999999999999993,452.06999999999999]],"spl":null,"spn":null,"atl":null,"batl":null,"id":16570658,"hc":null,"bdatb":null}],"img":null,"tv":null,"con":null,"marketdefinition":null,"id":"1.258926623"}],"conflatems":null,"op":"mcm","id":3}
{"ct":null,"SegmentType":null,"clk":"AM\u002BvAQC4swEAn6UB","heartbeatms":null,"pt":1780839791531,"initialclk":null,"mc":[{"rc":[{"tv":null,"batb":null,"spb":null,"bdatl":null,"trd":null,"spf":null,"ltp":null,"atb":[[8.4000000000000004,151.16]],"spl":null,"spn":null,"atl":null,"batl":null,"id":16570658,"hc":null,"bdatb":null}],"img":null,"tv":null,"con":null,"marketdefinition":null,"id":"1.258926623"}],"conflatems":null,"op":"mcm","id":3}
{"ct":null,"SegmentType":null,"clk":"ANyvAQDBswEAqaUB","heartbeatms":null,"pt":1780839791637,"initialclk":null,"mc":[{"rc":[{"tv":null,"batb":null,"spb":null,"bdatl":null,"trd":null,"spf":null,"ltp":null,"atb":[[8.1999999999999993,552.07000000000005]],"spl":null,"spn":null,"atl":null,"batl":null,"id":16570658,"hc":null,"bdatb":null},{"tv":null,"batb":null,"spb":null,"bdatl":null,"trd":null,"spf":null,"ltp":null,"atb":null,"spl":null,"spn":null,"atl":[[1.1399999999999999,27076.869999999999]],"batl":null,"id":19924823,"hc":null,"bdatb":null}],"img":null,"tv":null,"con":null,"marketdefinition":null,"id":"1.258926623"}],"conflatems":null,"op":"mcm","id":3}
{"ct":null,"SegmentType":null,"clk":"AOivAQDZswEAv6UB","heartbeatms":null,"pt":1780839791842,"initialclk":null,"mc":[{"rc":[{"tv":null,"batb":null,"spb":null,"bdatl":null,"trd":null,"spf":null,"ltp":null,"atb":[[6.5999999999999996,25],[6.4000000000000004,26.780000000000001],[8,602.22000000000003]],"spl":null,"spn":null,"atl":null,"batl":null,"id":16570658,"hc":null,"bdatb":null}],"img":null,"tv":null,"con":null,"marketdefinition":null,"id":"1.258926623"}],"conflatems":null,"op":"mcm","id":3}
{"ct":null,"SegmentType":null,"clk":"AO6vAQDgswEAyqUB","heartbeatms":null,"pt":1780839791938,"initialclk":null,"mc":[{"rc":[{"tv":null,"batb":null,"spb":null,"bdatl":null,"trd":null,"spf":null,"ltp":null,"atb":[[8.1999999999999993,652.07000000000005]],"spl":null,"spn":null,"atl":null,"batl":null,"id":16570658,"hc":null,"bdatb":null}],"img":null,"tv":null,"con":null,"marketdefinition":null,"id":"1.258926623"}],"conflatems":null,"op":"mcm","id":3}
{"ct":null,"SegmentType":null,"clk":"APyvAQDqswEA1KUB","heartbeatms":null,"pt":1780839792050,"initialclk":null,"mc":[{"rc":[{"tv":null,"batb":null,"spb":null,"bdatl":null,"trd":null,"spf":null,"ltp":null,"atb":[[8,725.62]],"spl":null,"spn":null,"atl":null,"batl":null,"id":16570658,"hc":null,"bdatb":null}],"img":null,"tv":null,"con":null,"marketdefinition":null,"id":"1.258926623"}],"conflatems":null,"op":"mcm","id":3}
{"ct":null,"SegmentType":null,"clk":"AIKwAQD0swEA2qUB","heartbeatms":null,"pt":1780839792142,"initialclk":null,"mc":[{"rc":[{"tv":null,"batb":null,"spb":null,"bdatl":null,"trd":null,"spf":null,"ltp":null,"atb":[[7.5999999999999996,474.42000000000002],[7.2000000000000002,773.78999999999996],[8,723.89999999999998]],"spl":null,"spn":null,"atl":null,"batl":null,"id":16570658,"hc":null,"bdatb":null},{"tv":null,"batb":null,"spb":null,"bdatl":null,"trd":null,"spf":null,"ltp":null,"atb":null,"spl":null,"spn":null,"atl":[[1.1599999999999999,10749.709999999999]],"batl":null,"id":19924823,"hc":null,"bdatb":null}],"img":null,"tv":null,"con":null,"marketdefinition":null,"id":"1.258926623"}],"conflatems":null,"op":"mcm","id":3}
{"ct":null,"SegmentType":null,"clk":"AJywAQCptAEA8qUB","heartbeatms":null,"pt":1780839792410,"initialclk":null,"mc":[{"rc":[{"tv":null,"batb":null,"spb":null,"bdatl":null,"trd":null,"spf":null,"ltp":null,"atb":[[1.0700000000000001,38840.489999999998]],"spl":null,"spn":null,"atl":null,"batl":null,"id":19924823,"hc":null,"bdatb":null}],"img":null,"tv":null,"con":null,"marketdefinition":null,"id":"1.258926623"}],"conflatems":null,"op":"mcm","id":3}
{"ct":null,"SegmentType":null,"clk":"ALGwAQCitAEAjKYB","heartbeatms":null,"pt":1780839792619,"initialclk":null,"mc":[{"rc":[{"tv":null,"batb":null,"spb":null,"bdatl":null,"trd":null,"spf":null,"ltp":null,"atb":[[1.0800000000000001,39838.32]],"spl":null,"spn":null,"atl":null,"batl":null,"id":19924823,"hc":null,"bdatb":null}],"img":null,"tv":null,"con":null,"marketdefinition":null,"id":"1.258926623"}],"conflatems":null,"op":"mcm","id":3}
{"ct":null,"SegmentType":null,"clk":"AL6wAQCxtAEAoKYB","heartbeatms":null,"pt":1780839792824,"initialclk":null,"mc":[{"rc":[{"tv":null,"batb":null,"spb":null,"bdatl":null,"trd":null,"spf":null,"ltp":null,"atb":[[5,18.059999999999999]],"spl":null,"spn":null,"atl":null,"batl":null,"id":16570658,"hc":null,"bdatb":null}],"img":null,"tv":null,"con":null,"marketdefinition":null,"id":"1.258926623"}],"conflatems":null,"op":"mcm","id":3}
{"ct":null,"SegmentType":null,"clk":"AMywAQDFtAEArqYB","heartbeatms":null,"pt":1780839793026,"initialclk":null,"mc":[{"rc":[{"tv":null,"batb":null,"spb":null,"bdatl":null,"trd":null,"spf":null,"ltp":null,"atb":null,"spl":null,"spn":null,"atl":[[9.1999999999999993,172.41]],"batl":null,"id":16570658,"hc":null,"bdatb":null}],"img":null,"tv":null,"con":null,"marketdefinition":null,"id":"1.258926623"}],"conflatems":null,"op":"mcm","id":3}
{"ct":null,"SegmentType":null,"clk":"AIixAQCctQEA3aYB","heartbeatms":null,"pt":1780839793644,"initialclk":null,"mc":[{"rc":[{"tv":null,"batb":null,"spb":null,"bdatl":null,"trd":null,"spf":null,"ltp":null,"atb":null,"spl":null,"spn":null,"atl":[[1.1399999999999999,26990.490000000002]],"batl":null,"id":19924823,"hc":null,"bdatb":null}],"img":null,"tv":null,"con":null,"marketdefinition":null,"id":"1.258926623"}],"conflatems":null,"op":"mcm","id":3}
{"ct":null,"SegmentType":null,"clk":"AJixAQCYtQEA7aYB","heartbeatms":null,"pt":1780839793822,"initialclk":null,"mc":[{"rc":[{"tv":null,"batb":null,"spb":null,"bdatl":null,"trd":null,"spf":null,"ltp":null,"atb":[[1.1299999999999999,7075.0600000000004]],"spl":null,"spn":null,"atl":null,"batl":null,"id":19924823,"hc":null,"bdatb":null}],"img":null,"tv":null,"con":null,"marketdefinition":null,"id":"1.258926623"}],"conflatems":null,"op":"mcm","id":3}
{"ct":null,"SegmentType":null,"clk":"AKCxAQCitQEA96YB","heartbeatms":null,"pt":1780839793921,"initialclk":null,"mc":[{"rc":[{"tv":null,"batb":null,"spb":null,"bdatl":null,"trd":null,"spf":null,"ltp":null,"atb":[[1.1299999999999999,7375.0600000000004]],"spl":null,"spn":null,"atl":null,"batl":null,"id":19924823,"hc":null,"bdatb":null}],"img":null,"tv":null,"con":null,"marketdefinition":null,"id":"1.258926623"}],"conflatems":null,"op":"mcm","id":3}
{"ct":null,"SegmentType":null,"clk":"AMGxAQDAtQEAlqcB","heartbeatms":null,"pt":1780839794233,"initialclk":null,"mc":[{"rc":[{"tv":null,"batb":null,"spb":null,"bdatl":null,"trd":null,"spf":null,"ltp":null,"atb":[[1.1299999999999999,7675.0600000000004]],"spl":null,"spn":null,"atl":null,"batl":null,"id":19924823,"hc":null,"bdatb":null}],"img":null,"tv":null,"con":null,"marketdefinition":null,"id":"1.258926623"}],"conflatems":null,"op":"mcm","id":3}
{"ct":null,"SegmentType":null,"clk":"AOexAQDftQEAuacB","heartbeatms":null,"pt":1780839794545,"initialclk":null,"mc":[{"rc":[{"tv":null,"batb":null,"spb":null,"bdatl":null,"trd":null,"spf":null,"ltp":null,"atb":[[1.1299999999999999,7975.0600000000004]],"spl":null,"spn":null,"atl":null,"batl":null,"id":19924823,"hc":null,"bdatb":null}],"img":null,"tv":null,"con":null,"marketdefinition":null,"id":"1.258926623"}],"conflatems":null,"op":"mcm","id":3}
{"ct":null,"SegmentType":null,"clk":"AOqxAQDotQEAv6cB","heartbeatms":null,"pt":1780839794647,"initialclk":null,"mc":[{"rc":[{"tv":null,"batb":null,"spb":null,"bdatl":null,"trd":null,"spf":null,"ltp":null,"atb":[[1.1299999999999999,8275.0599999999995]],"spl":null,"spn":null,"atl":null,"batl":null,"id":19924823,"hc":null,"bdatb":null}],"img":null,"tv":null,"con":null,"marketdefinition":null,"id":"1.258926623"}],"conflatems":null,"op":"mcm","id":3}
{"ct":null,"SegmentType":null,"clk":"APixAQDwtQEAy6cB","heartbeatms":null,"pt":1780839794739,"initialclk":null,"mc":[{"rc":[{"tv":2044132.3500000001,"batb":null,"spb":null,"bdatl":null,"trd":[[1.1299999999999999,227179.95999999999]],"spf":null,"ltp":null,"atb":[[1.1299999999999999,8188.6800000000003]],"spl":null,"spn":null,"atl":null,"batl":null,"id":19924823,"hc":null,"bdatb":null}],"img":null,"tv":2289743.8599999999,"con":null,"marketdefinition":null,"id":"1.258926623"}],"conflatems":null,"op":"mcm","id":3}
{"ct":null,"SegmentType":null,"clk":"AKSyAQChtgEAg6gB","heartbeatms":null,"pt":1780839795111,"initialclk":null,"mc":[{"rc":[{"tv":null,"batb":null,"spb":null,"bdatl":null,"trd":null,"spf":null,"ltp":null,"atb":null,"spl":null,"spn":null,"atl":[[1.1399999999999999,27189.189999999999]],"batl":null,"id":19924823,"hc":null,"bdatb":null}],"img":null,"tv":null,"con":null,"marketdefinition":null,"id":"1.258926623"}],"conflatems":null,"op":"mcm","id":3}
{"ct":null,"SegmentType":null,"clk":"ALOyAQCptgEAjagB","heartbeatms":null,"pt":1780839795218,"initialclk":null,"mc":[{"rc":[{"tv":2044553.4299999999,"batb":null,"spb":null,"bdatl":null,"trd":[[1.1299999999999999,227601.04000000001]],"spf":null,"ltp":null,"atb":[[1.1299999999999999,7978.1499999999996]],"spl":null,"spn":null,"atl":null,"batl":null,"id":19924823,"hc":null,"bdatb":null}],"img":null,"tv":2290164.9399999999,"con":null,"marketdefinition":null,"id":"1.258926623"}],"conflatems":null,"op":"mcm","id":3}
{"ct":null,"SegmentType":null,"clk":"ANuyAQDHtgEAragB","heartbeatms":null,"pt":1780839795727,"initialclk":null,"mc":[{"rc":[{"tv":2044643.27,"batb":null,"spb":null,"bdatl":null,"trd":[[1.1399999999999999,135498.76000000001]],"spf":null,"ltp":1.1399999999999999,"atb":null,"spl":null,"spn":null,"atl":[[1.1399999999999999,27144.27]],"batl":null,"id":19924823,"hc":null,"bdatb":null}],"img":null,"tv":2290254.7799999998,"con":null,"marketdefinition":null,"id":"1.258926623"}],"conflatems":null,"op":"mcm","id":3}
{"ct":null,"SegmentType":null,"clk":"AImzAQD2tgEA1KgB","heartbeatms":null,"pt":1780839796037,"initialclk":null,"mc":[{"rc":[{"tv":2044690.95,"batb":null,"spb":null,"bdatl":null,"trd":[[1.1399999999999999,135546.44]],"spf":null,"ltp":null,"atb":null,"spl":null,"spn":null,"atl":[[1.1399999999999999,27120.43]],"batl":null,"id":19924823,"hc":null,"bdatb":null}],"img":null,"tv":2290302.46,"con":null,"marketdefinition":null,"id":"1.258926623"}],"conflatems":null,"op":"mcm","id":3}
{"ct":null,"SegmentType":null,"clk":"AL2zAQCctwEA/qgB","heartbeatms":null,"pt":1780839796542,"initialclk":null,"mc":[{"rc":[{"tv":null,"batb":null,"spb":null,"bdatl":null,"trd":null,"spf":null,"ltp":null,"atb":[[6.4000000000000004,0.85999999999999999]],"spl":null,"spn":null,"atl":null,"batl":null,"id":16570658,"hc":null,"bdatb":null}],"img":null,"tv":null,"con":null,"marketdefinition":null,"id":"1.258926623"}],"conflatems":null,"op":"mcm","id":3}
{"ct":null,"SegmentType":null,"clk":"AM6zAQCytwEAjakB","heartbeatms":null,"pt":1780839796708,"initialclk":null,"mc":[{"rc":[{"tv":2044694.96,"batb":null,"spb":null,"bdatl":null,"trd":[[1.1399999999999999,135550.45000000001]],"spf":null,"ltp":null,"atb":null,"spl":null,"spn":null,"atl":[[1.1399999999999999,27118.419999999998]],"batl":null,"id":19924823,"hc":null,"bdatb":null}],"img":null,"tv":2290306.4700000002,"con":null,"marketdefinition":null,"id":"1.258926623"}],"conflatems":null,"op":"mcm","id":3}
{"ct":null,"SegmentType":null,"clk":"AKC0AQD4twEA2qkB","heartbeatms":null,"pt":1780839797218,"initialclk":null,"mc":[{"rc":[{"tv":2044760.1899999999,"batb":null,"spb":null,"bdatl":null,"trd":[[1.1399999999999999,135615.67999999999]],"spf":null,"ltp":null,"atb":null,"spl":null,"spn":null,"atl":[[1.1399999999999999,27085.810000000001]],"batl":null,"id":19924823,"hc":null,"bdatb":null}],"img":null,"tv":2290371.7000000002,"con":null,"marketdefinition":null,"id":"1.258926623"}],"conflatems":null,"op":"mcm","id":3}
{"ct":null,"SegmentType":null,"clk":"AKW0AQCBuAEA5KkB","heartbeatms":null,"pt":1780839797322,"initialclk":null,"mc":[{"rc":[{"tv":null,"batb":null,"spb":null,"bdatl":null,"trd":null,"spf":null,"ltp":null,"atb":[[6.5999999999999996,0]],"spl":null,"spn":null,"atl":null,"batl":null,"id":16570658,"hc":null,"bdatb":null}],"img":null,"tv":null,"con":null,"marketdefinition":null,"id":"1.258926623"}],"conflatems":null,"op":"mcm","id":3}
{"ct":null,"SegmentType":null,"clk":"ALq0AQCYuAEA\u002BakB","heartbeatms":null,"pt":1780839797628,"initialclk":null,"mc":[{"rc":[{"tv":null,"batb":null,"spb":null,"bdatl":null,"trd":null,"spf":null,"ltp":null,"atb":[[1.1200000000000001,36732.209999999999]],"spl":null,"spn":null,"atl":null,"batl":null,"id":19924823,"hc":null,"bdatb":null}],"img":null,"tv":null,"con":null,"marketdefinition":null,"id":"1.258926623"}],"conflatems":null,"op":"mcm","id":3}
{"ct":null,"SegmentType":null,"clk":"AM20AQCxuAEAiaoB","heartbeatms":null,"pt":1780839797841,"initialclk":null,"mc":[{"rc":[{"tv":null,"batb":null,"spb":null,"bdatl":null,"trd":null,"spf":null,"ltp":null,"atb":[[6.5999999999999996,25],[6.4000000000000004,26.780000000000001]],"spl":null,"spn":null,"atl":[[8.8000000000000007,526.23000000000002]],"batl":null,"id":16570658,"hc":null,"bdatb":null},{"tv":null,"batb":null,"spb":null,"bdatl":null,"trd":null,"spf":null,"ltp":null,"atb":[[1.1299999999999999,7976.1499999999996]],"spl":null,"spn":null,"atl":null,"batl":null,"id":19924823,"hc":null,"bdatb":null}],"img":null,"tv":null,"con":null,"marketdefinition":null,"id":"1.258926623"}],"conflatems":null,"op":"mcm","id":3}
{"ct":null,"SegmentType":null,"clk":"APq0AQDTuAEAqKoB","heartbeatms":null,"pt":1780839798250,"initialclk":null,"mc":[{"rc":[{"tv":null,"batb":null,"spb":null,"bdatl":null,"trd":null,"spf":null,"ltp":null,"atb":[[1.1200000000000001,36818.589999999997]],"spl":null,"spn":null,"atl":null,"batl":null,"id":19924823,"hc":null,"bdatb":null}],"img":null,"tv":null,"con":null,"marketdefinition":null,"id":"1.258926623"}],"conflatems":null,"op":"mcm","id":3}
{"ct":null,"SegmentType":null,"clk":"AKy1AQCEuQEA1KoB","heartbeatms":null,"pt":1780839798720,"initialclk":null,"mc":[{"rc":[{"tv":2044960.1899999999,"batb":null,"spb":null,"bdatl":null,"trd":[[1.1399999999999999,135815.67999999999]],"spf":null,"ltp":null,"atb":null,"spl":null,"spn":null,"atl":[[1.1399999999999999,26985.810000000001]],"batl":null,"id":19924823,"hc":null,"bdatb":null}],"img":null,"tv":2290571.7000000002,"con":null,"marketdefinition":null,"id":"1.258926623"}],"conflatems":null,"op":"mcm","id":3}
{"ct":null,"SegmentType":null,"clk":"AM22AQCTugEA2KsB","heartbeatms":null,"pt":1780839799944,"initialclk":null,"mc":[{"rc":[{"tv":null,"batb":null,"spb":null,"bdatl":null,"trd":null,"spf":null,"ltp":null,"atb":[[1.1100000000000001,75514.600000000006]],"spl":null,"spn":null,"atl":null,"batl":null,"id":19924823,"hc":null,"bdatb":null}],"img":null,"tv":null,"con":null,"marketdefinition":null,"id":"1.258926623"}],"conflatems":null,"op":"mcm","id":3}
{"ct":null,"SegmentType":null,"clk":"AKO3AQDNugEAmawB","heartbeatms":null,"pt":1780839800831,"initialclk":null,"mc":[{"rc":[{"tv":245611.63000000001,"batb":null,"spb":null,"bdatl":null,"trd":[[8.4000000000000004,980.85000000000002]],"spf":null,"ltp":8.4000000000000004,"atb":[[8.4000000000000004,151.09999999999999]],"spl":null,"spn":null,"atl":null,"batl":null,"id":16570658,"hc":null,"bdatb":null}],"img":null,"tv":2290571.8199999998,"con":null,"marketdefinition":null,"id":"1.258926623"}],"conflatems":null,"op":"mcm","id":3}
{"ct":null,"SegmentType":null,"clk":"APC3AQCcuwEA66wB","heartbeatms":null,"pt":1780839801041,"initialclk":null,"mc":[{"rc":[{"tv":null,"batb":null,"spb":null,"bdatl":null,"trd":null,"spf":null,"ltp":null,"atb":null,"spl":null,"spn":null,"atl":[[9,253.31999999999999]],"batl":null,"id":16570658,"hc":null,"bdatb":null},{"tv":2044974.1200000001,"batb":null,"spb":null,"bdatl":null,"trd":[[1.1399999999999999,135829.60999999999]],"spf":null,"ltp":null,"atb":null,"spl":null,"spn":null,"atl":[[1.1399999999999999,26978.84]],"batl":null,"id":19924823,"hc":null,"bdatb":null}],"img":null,"tv":2290585.75,"con":null,"marketdefinition":null,"id":"1.258926623"}],"conflatems":null,"op":"mcm","id":3}
{"ct":null,"SegmentType":null,"clk":"AK\u002B4AQDduwEAoa0B","heartbeatms":null,"pt":1780839801346,"initialclk":null,"mc":[{"rc":[{"tv":null,"batb":null,"spb":null,"bdatl":null,"trd":null,"spf":null,"ltp":null,"atb":null,"spl":null,"spn":null,"atl":[[9.1999999999999993,9.3800000000000008]],"batl":null,"id":16570658,"hc":null,"bdatb":null},{"tv":null,"batb":null,"spb":null,"bdatl":null,"trd":null,"spf":null,"ltp":null,"atb":null,"spl":null,"spn":null,"atl":[[1.1399999999999999,27078.84]],"batl":null,"id":19924823,"hc":null,"bdatb":null}],"img":null,"tv":null,"con":null,"marketdefinition":null,"id":"1.258926623"}],"conflatems":null,"op":"mcm","id":3}
{"ct":null,"SegmentType":null,"clk":"ANu4AQCFvAEAx60B","heartbeatms":null,"pt":1780839801810,"initialclk":null,"mc":[{"rc":[{"tv":2044991.3899999999,"batb":null,"spb":null,"bdatl":null,"trd":[[1.1299999999999999,227618.31]],"spf":null,"ltp":1.1299999999999999,"atb":[[1.1299999999999999,7967.5100000000002]],"spl":null,"spn":null,"atl":null,"batl":null,"id":19924823,"hc":null,"bdatb":null}],"img":null,"tv":2290603.02,"con":null,"marketdefinition":null,"id":"1.258926623"}],"conflatems":null,"op":"mcm","id":3}
{"ct":null,"SegmentType":null,"clk":"AOa4AQCPvAEA160B","heartbeatms":null,"pt":1780839801930,"initialclk":null,"mc":[{"rc":[{"tv":2044995.45,"batb":null,"spb":null,"bdatl":null,"trd":[[1.1399999999999999,135833.67000000001]],"spf":null,"ltp":1.1399999999999999,"atb":null,"spl":null,"spn":null,"atl":[[1.1399999999999999,27076.810000000001]],"batl":null,"id":19924823,"hc":null,"bdatb":null}],"img":null,"tv":2290607.0800000001,"con":null,"marketdefinition":null,"id":"1.258926623"}],"conflatems":null,"op":"mcm","id":3}
{"ct":null,"SegmentType":null,"clk":"AO\u002B4AQCXvAEA3a0B","heartbeatms":null,"pt":1780839802021,"initialclk":null,"mc":[{"rc":[{"tv":null,"batb":null,"spb":null,"bdatl":null,"trd":null,"spf":null,"ltp":null,"atb":null,"spl":null,"spn":null,"atl":[[1.1499999999999999,31373.310000000001]],"batl":null,"id":19924823,"hc":null,"bdatb":null}],"img":null,"tv":null,"con":null,"marketdefinition":null,"id":"1.258926623"}],"conflatems":null,"op":"mcm","id":3}
{"ct":null,"SegmentType":null,"clk":"AK25AQDSvAEAkK4B","heartbeatms":null,"pt":1780839802647,"initialclk":null,"mc":[{"rc":[{"tv":null,"batb":null,"spb":null,"bdatl":null,"trd":null,"spf":null,"ltp":null,"atb":[[6.4000000000000004,0.85999999999999999]],"spl":null,"spn":null,"atl":null,"batl":null,"id":16570658,"hc":null,"bdatb":null}],"img":null,"tv":null,"con":null,"marketdefinition":null,"id":"1.258926623"}],"conflatems":null,"op":"mcm","id":3}
{"ct":null,"SegmentType":null,"clk":"ALK5AQDYvAEAmK4B","heartbeatms":null,"pt":1780839802740,"initialclk":null,"mc":[{"rc":[{"tv":null,"batb":null,"spb":null,"bdatl":null,"trd":null,"spf":null,"ltp":null,"atb":null,"spl":null,"spn":null,"atl":[[1.1699999999999999,8888.75]],"batl":null,"id":19924823,"hc":null,"bdatb":null}],"img":null,"tv":null,"con":null,"marketdefinition":null,"id":"1.258926623"}],"conflatems":null,"op":"mcm","id":3}
{"ct":null,"SegmentType":null,"clk":"ANa5AQCDvQEAs64B","heartbeatms":null,"pt":1780839803151,"initialclk":null,"mc":[{"rc":[{"tv":2045056.6100000001,"batb":null,"spb":null,"bdatl":null,"trd":[[1.1399999999999999,135894.82999999999]],"spf":null,"ltp":null,"atb":null,"spl":null,"spn":null,"atl":[[1.1399999999999999,27046.23]],"batl":null,"id":19924823,"hc":null,"bdatb":null}],"img":null,"tv":2290668.2400000002,"con":null,"marketdefinition":null,"id":"1.258926623"}],"conflatems":null,"op":"mcm","id":3}
{"ct":null,"SegmentType":null,"clk":"AO65AQClvQEAx64B","heartbeatms":null,"pt":1780839803416,"initialclk":null,"mc":[{"rc":[{"tv":null,"batb":null,"spb":null,"bdatl":null,"trd":null,"spf":null,"ltp":null,"atb":[[6.5999999999999996,0]],"spl":null,"spn":null,"atl":null,"batl":null,"id":16570658,"hc":null,"bdatb":null}],"img":null,"tv":null,"con":null,"marketdefinition":null,"id":"1.258926623"}],"conflatems":null,"op":"mcm","id":3}
{"ct":null,"SegmentType":null,"clk":"AJK6AQDJvQEA164B","heartbeatms":null,"pt":1780839803726,"initialclk":null,"mc":[{"rc":[{"tv":null,"batb":null,"spb":null,"bdatl":null,"trd":null,"spf":null,"ltp":null,"atb":[[6.5999999999999996,25],[6.4000000000000004,26.780000000000001]],"spl":null,"spn":null,"atl":null,"batl":null,"id":16570658,"hc":null,"bdatb":null}],"img":null,"tv":null,"con":null,"marketdefinition":null,"id":"1.258926623"}],"conflatems":null,"op":"mcm","id":3}
{"ct":null,"SegmentType":null,"clk":"AKW6AQDcvQEA5K4B","heartbeatms":null,"pt":1780839803935,"initialclk":null,"mc":[{"rc":[{"tv":null,"batb":null,"spb":null,"bdatl":null,"trd":null,"spf":null,"ltp":null,"atb":[[1.1200000000000001,36848.589999999997]],"spl":null,"spn":null,"atl":null,"batl":null,"id":19924823,"hc":null,"bdatb":null}],"img":null,"tv":null,"con":null,"marketdefinition":null,"id":"1.258926623"}],"conflatems":null,"op":"mcm","id":3}
{"ct":null,"SegmentType":null,"clk":"AK\u002B6AQDpvQEA6a4B","heartbeatms":null,"pt":1780839804041,"initialclk":null,"mc":[{"rc":[{"tv":null,"batb":null,"spb":null,"bdatl":null,"trd":null,"spf":null,"ltp":null,"atb":[[6.7999999999999998,0.40000000000000002]],"spl":null,"spn":null,"atl":null,"batl":null,"id":16570658,"hc":null,"bdatb":null}],"img":null,"tv":null,"con":null,"marketdefinition":null,"id":"1.258926623"}],"conflatems":null,"op":"mcm","id":3}
{"ct":null,"SegmentType":null,"clk":"ANa6AQCWvgEAgq8B","heartbeatms":null,"pt":1780839804451,"initialclk":null,"mc":[{"rc":[{"tv":null,"batb":null,"spb":null,"bdatl":null,"trd":null,"spf":null,"ltp":null,"atb":null,"spl":null,"spn":null,"atl":[[1.1499999999999999,30860.259999999998]],"batl":null,"id":19924823,"hc":null,"bdatb":null}],"img":null,"tv":null,"con":null,"marketdefinition":null,"id":"1.258926623"}],"conflatems":null,"op":"mcm","id":3}
{"ct":null,"SegmentType":null,"clk":"AOK6AQCevgEAiK8B","heartbeatms":null,"pt":1780839804550,"initialclk":null,"mc":[{"rc":[{"tv":null,"batb":null,"spb":null,"bdatl":null,"trd":null,"spf":null,"ltp":null,"atb":[[6.7999999999999998,24.52]],"spl":null,"spn":null,"atl":null,"batl":null,"id":16570658,"hc":null,"bdatb":null}],"img":null,"tv":null,"con":null,"marketdefinition":null,"id":"1.258926623"}],"conflatems":null,"op":"mcm","id":3}
{"ct":null,"SegmentType":null,"clk":"APO6AQCmvgEAj68B","heartbeatms":null,"pt":1780839804656,"initialclk":null,"mc":[{"rc":[{"tv":null,"batb":null,"spb":null,"bdatl":null,"trd":null,"spf":null,"ltp":null,"atb":[[1.1100000000000001,75544.600000000006]],"spl":null,"spn":null,"atl":null,"batl":null,"id":19924823,"hc":null,"bdatb":null}],"img":null,"tv":null,"con":null,"marketdefinition":null,"id":"1.258926623"}],"conflatems":null,"op":"mcm","id":3}
{"ct":null,"SegmentType":null,"clk":"AIe7AQC3vgEAna8B","heartbeatms":null,"pt":1780839804826,"initialclk":null,"mc":[{"rc":[{"tv":245634.82999999999,"batb":null,"spb":null,"bdatl":null,"trd":[[8.4000000000000004,1004.05]],"spf":null,"ltp":null,"atb":[[8.4000000000000004,139.5]],"spl":null,"spn":null,"atl":null,"batl":null,"id":16570658,"hc":null,"bdatb":null}],"img":null,"tv":2290691.4399999999,"con":null,"marketdefinition":null,"id":"1.258926623"}],"conflatems":null,"op":"mcm","id":3}
{"ct":null,"SegmentType":null,"clk":"ALC7AQDdvgEAt68B","heartbeatms":null,"pt":1780839805229,"initialclk":null,"mc":[{"rc":[{"tv":null,"batb":null,"spb":null,"bdatl":null,"trd":null,"spf":null,"ltp":null,"atb":null,"spl":null,"spn":null,"atl":[[1.1399999999999999,27054.389999999999],[1.1499999999999999,30859.139999999999]],"batl":null,"id":19924823,"hc":null,"bdatb":null}],"img":null,"tv":null,"con":null,"marketdefinition":null,"id":"1.258926623"}],"conflatems":null,"op":"mcm","id":3}
{"ct":null,"SegmentType":null,"clk":"AL67AQDqvgEAu68B","heartbeatms":null,"pt":1780839805335,"initialclk":null,"mc":[{"rc":[{"tv":null,"batb":null,"spb":null,"bdatl":null,"trd":null,"spf":null,"ltp":null,"atb":[[1.1000000000000001,53457.160000000003]],"spl":null,"spn":null,"atl":null,"batl":null,"id":19924823,"hc":null,"bdatb":null}],"img":null,"tv":null,"con":null,"marketdefinition":null,"id":"1.258926623"}],"conflatems":null,"op":"mcm","id":3}
{"ct":null,"SegmentType":null,"clk":"APW7AQCWvwEA3a8B","heartbeatms":null,"pt":1780839805854,"initialclk":null,"mc":[{"rc":[{"tv":2045061.8999999999,"batb":null,"spb":null,"bdatl":null,"trd":[[1.1299999999999999,227623.60000000001]],"spf":null,"ltp":1.1299999999999999,"atb":[[1.1299999999999999,7964.8699999999999]],"spl":null,"spn":null,"atl":null,"batl":null,"id":19924823,"hc":null,"bdatb":null}],"img":null,"tv":2290696.73,"con":null,"marketdefinition":null,"id":"1.258926623"}],"conflatems":null,"op":"mcm","id":3}
{"ct":null,"SegmentType":null,"clk":"APy7AQCfvwEA4a8B","heartbeatms":null,"pt":1780839805956,"initialclk":null,"mc":[{"rc":[{"tv":null,"batb":null,"spb":null,"bdatl":null,"trd":null,"spf":null,"ltp":null,"atb":[[1.0900000000000001,40135.849999999999]],"spl":null,"spn":null,"atl":null,"batl":null,"id":19924823,"hc":null,"bdatb":null}],"img":null,"tv":null,"con":null,"marketdefinition":null,"id":"1.258926623"}],"conflatems":null,"op":"mcm","id":3}
{"ct":null,"SegmentType":null,"clk":"AIa8AQCkvwEA7K8B","heartbeatms":null,"pt":1780839806055,"initialclk":null,"mc":[{"rc":[{"tv":2045104,"batb":null,"spb":null,"bdatl":null,"trd":[[1.1399999999999999,135936.92999999999]],"spf":null,"ltp":1.1399999999999999,"atb":null,"spl":null,"spn":null,"atl":[[1.1399999999999999,27033.34]],"batl":null,"id":19924823,"hc":null,"bdatb":null}],"img":null,"tv":2290738.8300000001,"con":null,"marketdefinition":null,"id":"1.258926623"}],"conflatems":null,"op":"mcm","id":3}
{"ct":null,"SegmentType":null,"clk":"AI68AQCuvwEA868B","heartbeatms":null,"pt":1780839806160,"initialclk":null,"mc":[{"rc":[{"tv":2045106.1100000001,"batb":null,"spb":null,"bdatl":null,"trd":[[1.1399999999999999,135939.04000000001]],"spf":null,"ltp":null,"atb":[[1.0800000000000001,39665.57]],"spl":null,"spn":null,"atl":[[1.1399999999999999,27032.279999999999]],"batl":null,"id":19924823,"hc":null,"bdatb":null}],"img":null,"tv":2290740.9399999999,"con":null,"marketdefinition":null,"id":"1.258926623"}],"conflatems":null,"op":"mcm","id":3}
{"ct":null,"SegmentType":null,"clk":"AOe8AQD1vwEAqrAB","heartbeatms":null,"pt":1780839806839,"initialclk":null,"mc":[{"rc":[{"tv":null,"batb":null,"spb":null,"bdatl":null,"trd":null,"spf":null,"ltp":null,"atb":[[1.0800000000000001,39695.57]],"spl":null,"spn":null,"atl":[[1000,1.1499999999999999]],"batl":null,"id":19924823,"hc":null,"bdatb":null}],"img":null,"tv":null,"con":null,"marketdefinition":null,"id":"1.258926623"}],"conflatems":null,"op":"mcm","id":3}
{"ct":null,"SegmentType":null,"clk":"ALG9AQC6wAEA47AB","heartbeatms":null,"pt":1780839807519,"initialclk":null,"mc":[{"rc":[{"tv":2045108.22,"batb":null,"spb":null,"bdatl":null,"trd":[[1.1399999999999999,135941.14999999999]],"spf":null,"ltp":null,"atb":null,"spl":null,"spn":null,"atl":[[1.1399999999999999,27031.23]],"batl":null,"id":19924823,"hc":null,"bdatb":null}],"img":null,"tv":2290743.0499999998,"con":null,"marketdefinition":null,"id":"1.258926623"}],"conflatems":null,"op":"mcm","id":3}
{"ct":null,"SegmentType":null,"clk":"AMS9AQDMwAEA97AB","heartbeatms":null,"pt":1780839807728,"initialclk":null,"mc":[{"rc":[{"tv":2045483.1000000001,"batb":null,"spb":null,"bdatl":null,"trd":[[1.1299999999999999,227998.48000000001]],"spf":null,"ltp":1.1299999999999999,"atb":[[1.0700000000000001,38870.489999999998],[1.1299999999999999,7777.4300000000003]],"spl":null,"spn":null,"atl":[[1000,0.88]],"batl":null,"id":19924823,"hc":null,"bdatb":null}],"img":null,"tv":2291117.9300000002,"con":null,"marketdefinition":null,"id":"1.258926623"}],"conflatems":null,"op":"mcm","id":3}
{"ct":null,"SegmentType":null,"clk":"APO9AQD6wAEAnrEB","heartbeatms":null,"pt":1780839808241,"initialclk":null,"mc":[{"rc":[{"tv":null,"batb":null,"spb":null,"bdatl":null,"trd":null,"spf":null,"ltp":null,"atb":[[6.4000000000000004,0.85999999999999999]],"spl":null,"spn":null,"atl":null,"batl":null,"id":16570658,"hc":null,"bdatb":null}],"img":null,"tv":null,"con":null,"marketdefinition":null,"id":"1.258926623"}],"conflatems":null,"op":"mcm","id":3}
{"ct":null,"SegmentType":null,"clk":"APu9AQCFwQEApLEB","heartbeatms":null,"pt":1780839808337,"initialclk":null,"mc":[{"rc":[{"tv":null,"batb":null,"spb":null,"bdatl":null,"trd":null,"spf":null,"ltp":null,"atb":[[8.1999999999999993,671.50999999999999]],"spl":null,"spn":null,"atl":null,"batl":null,"id":16570658,"hc":null,"bdatb":null}],"img":null,"tv":null,"con":null,"marketdefinition":null,"id":"1.258926623"}],"conflatems":null,"op":"mcm","id":3}
{"ct":null,"SegmentType":null,"clk":"AIi\u002BAQCVwQEAsLEB","heartbeatms":null,"pt":1780839808445,"initialclk":null,"mc":[{"rc":[{"tv":null,"batb":null,"spb":null,"bdatl":null,"trd":null,"spf":null,"ltp":null,"atb":[[1.0600000000000001,63326.940000000002]],"spl":null,"spn":null,"atl":null,"batl":null,"id":19924823,"hc":null,"bdatb":null}],"img":null,"tv":null,"con":null,"marketdefinition":null,"id":"1.258926623"}],"conflatems":null,"op":"mcm","id":3}
{"ct":null,"SegmentType":null,"clk":"AKC\u002BAQCowQEAvrEB","heartbeatms":null,"pt":1780839808649,"initialclk":null,"mc":[{"rc":[{"tv":245640.60999999999,"batb":null,"spb":null,"bdatl":null,"trd":[[8.4000000000000004,1009.83]],"spf":null,"ltp":null,"atb":[[8.4000000000000004,136.61000000000001]],"spl":null,"spn":null,"atl":null,"batl":null,"id":16570658,"hc":null,"bdatb":null}],"img":null,"tv":2291123.71,"con":null,"marketdefinition":null,"id":"1.258926623"}],"conflatems":null,"op":"mcm","id":3}
{"ct":null,"SegmentType":null,"clk":"ALq\u002BAQDLwQEA17EB","heartbeatms":null,"pt":1780839808958,"initialclk":null,"mc":[{"rc":[{"tv":null,"batb":null,"spb":null,"bdatl":null,"trd":null,"spf":null,"ltp":null,"atb":[[6.4000000000000004,26.780000000000001]],"spl":null,"spn":null,"atl":null,"batl":null,"id":16570658,"hc":null,"bdatb":null},{"tv":null,"batb":null,"spb":null,"bdatl":null,"trd":null,"spf":null,"ltp":null,"atb":[[1.05,74303.130000000005]],"spl":null,"spn":null,"atl":null,"batl":null,"id":19924823,"hc":null,"bdatb":null}],"img":null,"tv":null,"con":null,"marketdefinition":null,"id":"1.258926623"}],"conflatems":null,"op":"mcm","id":3}
{"ct":null,"SegmentType":null,"clk":"AKG/AQDAwgEAsLIB","heartbeatms":null,"pt":1780839810049,"initialclk":null,"mc":[{"rc":[{"tv":null,"batb":null,"spb":null,"bdatl":null,"trd":null,"spf":null,"ltp":null,"atb":null,"spl":null,"spn":null,"atl":[[8.5999999999999996,121.98]],"batl":null,"id":16570658,"hc":null,"bdatb":null}],"img":null,"tv":null,"con":null,"marketdefinition":null,"id":"1.258926623"}],"conflatems":null,"op":"mcm","id":3}
{"ct":null,"SegmentType":null,"clk":"AL2/AQDawgEAxLIB","heartbeatms":null,"pt":1780839810353,"initialclk":null,"mc":[{"rc":[{"tv":null,"batb":null,"spb":null,"bdatl":null,"trd":null,"spf":null,"ltp":null,"atb":[[1.1100000000000001,75630.979999999996]],"spl":null,"spn":null,"atl":null,"batl":null,"id":19924823,"hc":null,"bdatb":null}],"img":null,"tv":null,"con":null,"marketdefinition":null,"id":"1.258926623"}],"conflatems":null,"op":"mcm","id":3}
{"ct":null,"SegmentType":null,"clk":"ANq/AQD8wgEA3rIB","heartbeatms":null,"pt":1780839810657,"initialclk":null,"mc":[{"rc":[{"tv":null,"batb":null,"spb":null,"bdatl":null,"trd":null,"spf":null,"ltp":null,"atb":[[1.1100000000000001,75717.360000000001]],"spl":null,"spn":null,"atl":null,"batl":null,"id":19924823,"hc":null,"bdatb":null}],"img":null,"tv":null,"con":null,"marketdefinition":null,"id":"1.258926623"}],"conflatems":null,"op":"mcm","id":3}
{"ct":null,"SegmentType":null,"clk":"AOq/AQCJwwEA6rIB","heartbeatms":null,"pt":1780839810820,"initialclk":null,"mc":[{"rc":[{"tv":2045483.6200000001,"batb":null,"spb":null,"bdatl":null,"trd":[[1.1299999999999999,227999]],"spf":null,"ltp":null,"atb":[[1.1299999999999999,7777.1599999999999]],"spl":null,"spn":null,"atl":null,"batl":null,"id":19924823,"hc":null,"bdatb":null}],"img":null,"tv":2291124.23,"con":null,"marketdefinition":null,"id":"1.258926623"}],"conflatems":null,"op":"mcm","id":3}
{"ct":null,"SegmentType":null,"clk":"APK/AQCXwwEA8rIB","heartbeatms":null,"pt":1780839810927,"initialclk":null,"mc":[{"rc":[{"tv":245915.54999999999,"batb":null,"spb":null,"bdatl":null,"trd":[[8.4000000000000004,1283.05],[8.1999999999999993,1662.4000000000001]],"spf":null,"ltp":8.1999999999999993,"atb":[[8.4000000000000004,0],[7.7999999999999998,186.63999999999999],[8.1999999999999993,670.64999999999998]],"spl":null,"spn":null,"atl":[[9.5999999999999996,156.25]],"batl":null,"id":16570658,"hc":null,"bdatb":null},{"tv":null,"batb":null,"spb":null,"bdatl":null,"trd":null,"spf":null,"ltp":null,"atb":[[1.1100000000000001,77068.710000000006]],"spl":null,"spn":null,"atl":[[1.1499999999999999,32125.040000000001]],"batl":null,"id":19924823,"hc":null,"bdatb":null}],"img":null,"tv":2291399.1699999999,"con":null,"marketdefinition":null,"id":"1.258926623"}],"conflatems":null,"op":"mcm","id":3}
{"ct":null,"SegmentType":null,"clk":"APe/AQChwwEA\u002BLIB","heartbeatms":null,"pt":1780839811024,"initialclk":null,"mc":[{"rc":[{"tv":null,"batb":null,"spb":null,"bdatl":null,"trd":null,"spf":null,"ltp":null,"atb":null,"spl":null,"spn":null,"atl":[[9,86.659999999999997]],"batl":null,"id":16570658,"hc":null,"bdatb":null},{"tv":2046001.8899999999,"batb":null,"spb":null,"bdatl":null,"trd":[[1.1299999999999999,228517.26999999999]],"spf":null,"ltp":null,"atb":[[1.04,73842.729999999996],[1.1299999999999999,7518.0299999999997],[1.1200000000000001,35509.309999999998]],"spl":null,"spn":null,"atl":null,"batl":null,"id":19924823,"hc":null,"bdatb":null}],"img":null,"tv":2291917.4399999999,"con":null,"marketdefinition":null,"id":"1.258926623"}],"conflatems":null,"op":"mcm","id":3}
{"ct":null,"SegmentType":null,"clk":"AILAAQCrwwEAgrMB","heartbeatms":null,"pt":1780839811135,"initialclk":null,"mc":[{"rc":[{"tv":null,"batb":null,"spb":null,"bdatl":null,"trd":null,"spf":null,"ltp":null,"atb":[[1.1299999999999999,7626]],"spl":null,"spn":null,"atl":null,"batl":null,"id":19924823,"hc":null,"bdatb":null}],"img":null,"tv":null,"con":null,"marketdefinition":null,"id":"1.258926623"}],"conflatems":null,"op":"mcm","id":3}
{"ct":null,"SegmentType":null,"clk":"AIvAAQC2wwEAjbMB","heartbeatms":null,"pt":1780839811238,"initialclk":null,"mc":[{"rc":[{"tv":null,"batb":null,"spb":null,"bdatl":null,"trd":null,"spf":null,"ltp":null,"atb":[[7.4000000000000004,109.33]],"spl":null,"spn":null,"atl":null,"batl":null,"id":16570658,"hc":null,"bdatb":null},{"tv":null,"batb":null,"spb":null,"bdatl":null,"trd":null,"spf":null,"ltp":null,"atb":null,"spl":null,"spn":null,"atl":[[1.1599999999999999,9527.1200000000008]],"batl":null,"id":19924823,"hc":null,"bdatb":null}],"img":null,"tv":null,"con":null,"marketdefinition":null,"id":"1.258926623"}],"conflatems":null,"op":"mcm","id":3}
{"ct":null,"SegmentType":null,"clk":"ALHAAQDWwwEAqbMB","heartbeatms":null,"pt":1780839811637,"initialclk":null,"mc":[{"rc":[{"tv":null,"batb":null,"spb":null,"bdatl":null,"trd":null,"spf":null,"ltp":null,"atb":[[1.03,88974.589999999997]],"spl":null,"spn":null,"atl":null,"batl":null,"id":19924823,"hc":null,"bdatb":null}],"img":null,"tv":null,"con":null,"marketdefinition":null,"id":"1.258926623"}],"conflatems":null,"op":"mcm","id":3}
{"ct":null,"SegmentType":null,"clk":"AO3AAQCPxAEA4rMB","heartbeatms":null,"pt":1780839812260,"initialclk":null,"mc":[{"rc":[{"tv":null,"batb":null,"spb":null,"bdatl":null,"trd":null,"spf":null,"ltp":null,"atb":null,"spl":null,"spn":null,"atl":[[8.4000000000000004,106.7]],"batl":null,"id":16570658,"hc":null,"bdatb":null}],"img":null,"tv":null,"con":null,"marketdefinition":null,"id":"1.258926623"}],"conflatems":null,"op":"mcm","id":3}
{"ct":null,"SegmentType":null,"clk":"APvAAQCdxAEA8LMB","heartbeatms":null,"pt":1780839812361,"initialclk":null,"mc":[{"rc":[{"tv":null,"batb":null,"spb":null,"bdatl":null,"trd":null,"spf":null,"ltp":null,"atb":null,"spl":null,"spn":null,"atl":[[8.4000000000000004,107.7]],"batl":null,"id":16570658,"hc":null,"bdatb":null},{"tv":null,"batb":null,"spb":null,"bdatl":null,"trd":null,"spf":null,"ltp":null,"atb":[[1.01,93435.490000000005]],"spl":null,"spn":null,"atl":null,"batl":null,"id":19924823,"hc":null,"bdatb":null}],"img":null,"tv":null,"con":null,"marketdefinition":null,"id":"1.258926623"}],"conflatems":null,"op":"mcm","id":3}
{"ct":null,"SegmentType":null,"clk":"AIPBAQCnxAEA\u002BLMB","heartbeatms":null,"pt":1780839812422,"initialclk":null,"mc":[{"rc":[{"tv":null,"batb":null,"spb":null,"bdatl":null,"trd":null,"spf":null,"ltp":null,"atb":[[7.7999999999999998,0]],"spl":null,"spn":null,"atl":null,"batl":null,"id":16570658,"hc":null,"bdatb":null}],"img":null,"tv":null,"con":null,"marketdefinition":null,"id":"1.258926623"}],"conflatems":null,"op":"mcm","id":3}
{"ct":null,"SegmentType":null,"clk":"AIzBAQCwxAEA/bMB","heartbeatms":null,"pt":1780839812525,"initialclk":null,"mc":[{"rc":[{"tv":null,"batb":null,"spb":null,"bdatl":null,"trd":null,"spf":null,"ltp":null,"atb":[[6.2000000000000002,27.91]],"spl":null,"spn":null,"atl":null,"batl":null,"id":16570658,"hc":null,"bdatb":null},{"tv":null,"batb":null,"spb":null,"bdatl":null,"trd":null,"spf":null,"ltp":null,"atb":[[1.02,90735.919999999998]],"spl":null,"spn":null,"atl":null,"batl":null,"id":19924823,"hc":null,"bdatb":null}],"img":null,"tv":null,"con":null,"marketdefinition":null,"id":"1.258926623"}],"conflatems":null,"op":"mcm","id":3}
{"ct":null,"SegmentType":null,"clk":"AKjBAQDJxAEAlbQB","heartbeatms":null,"pt":1780839812834,"initialclk":null,"mc":[{"rc":[{"tv":null,"batb":null,"spb":null,"bdatl":null,"trd":null,"spf":null,"ltp":null,"atb":null,"spl":null,"spn":null,"atl":[[1.1599999999999999,10040.17]],"batl":null,"id":19924823,"hc":null,"bdatb":null}],"img":null,"tv":null,"con":null,"marketdefinition":null,"id":"1.258926623"}],"conflatems":null,"op":"mcm","id":3}
{"ct":null,"SegmentType":null,"clk":"ALTBAQDQxAEAnLQB","heartbeatms":null,"pt":1780839812937,"initialclk":null,"mc":[{"rc":[{"tv":2046031.7,"batb":null,"spb":null,"bdatl":null,"trd":[[1.1399999999999999,135970.95999999999]],"spf":null,"ltp":1.1399999999999999,"atb":null,"spl":null,"spn":null,"atl":[[1.1399999999999999,27016.32]],"batl":null,"id":19924823,"hc":null,"bdatb":null}],"img":null,"tv":2291947.25,"con":null,"marketdefinition":null,"id":"1.258926623"}],"conflatems":null,"op":"mcm","id":3}
{"ct":null,"SegmentType":null,"clk":"ANnBAQDmxAEAsLQB","heartbeatms":null,"pt":1780839813242,"initialclk":null,"mc":[{"rc":[{"tv":null,"batb":null,"spb":null,"bdatl":null,"trd":null,"spf":null,"ltp":null,"atb":null,"spl":null,"spn":null,"atl":[[8.4000000000000004,186.72999999999999]],"batl":null,"id":16570658,"hc":null,"bdatb":null},{"tv":null,"batb":null,"spb":null,"bdatl":null,"trd":null,"spf":null,"ltp":null,"atb":[[1.1299999999999999,7625.0200000000004]],"spl":null,"spn":null,"atl":null,"batl":null,"id":19924823,"hc":null,"bdatb":null}],"img":null,"tv":null,"con":null,"marketdefinition":null,"id":"1.258926623"}],"conflatems":null,"op":"mcm","id":3}
{"ct":null,"SegmentType":null,"clk":"AOLBAQDwxAEAuLQB","heartbeatms":null,"pt":1780839813347,"initialclk":null,"mc":[{"rc":[{"tv":null,"batb":null,"spb":null,"bdatl":null,"trd":null,"spf":null,"ltp":null,"atb":[[1.01,93465.490000000005]],"spl":null,"spn":null,"atl":null,"batl":null,"id":19924823,"hc":null,"bdatb":null}],"img":null,"tv":null,"con":null,"marketdefinition":null,"id":"1.258926623"}],"conflatems":null,"op":"mcm","id":3}
{"ct":null,"SegmentType":null,"clk":"AOvBAQD4xAEAxbQB","heartbeatms":null,"pt":1780839813448,"initialclk":null,"mc":[{"rc":[{"tv":null,"batb":null,"spb":null,"bdatl":null,"trd":null,"spf":null,"ltp":null,"atb":null,"spl":null,"spn":null,"atl":[[1.1499999999999999,30859.139999999999]],"batl":null,"id":19924823,"hc":null,"bdatb":null}],"img":null,"tv":null,"con":null,"marketdefinition":null,"id":"1.258926623"}],"conflatems":null,"op":"mcm","id":3}
{"ct":null,"SegmentType":null,"clk":"AP/BAQCMxQEA17QB","heartbeatms":null,"pt":1780839813653,"initialclk":null,"mc":[{"rc":[{"tv":null,"batb":null,"spb":null,"bdatl":null,"trd":null,"spf":null,"ltp":null,"atb":null,"spl":null,"spn":null,"atl":[[8.5999999999999996,44.799999999999997]],"batl":null,"id":16570658,"hc":null,"bdatb":null}],"img":null,"tv":null,"con":null,"marketdefinition":null,"id":"1.258926623"}],"conflatems":null,"op":"mcm","id":3}
{"ct":null,"SegmentType":null,"clk":"ALHCAQC5xQEA\u002B7QB","heartbeatms":null,"pt":1780839814117,"initialclk":null,"mc":[{"rc":[{"tv":null,"batb":null,"spb":null,"bdatl":null,"trd":null,"spf":null,"ltp":null,"atb":[[1.03,88975.339999999997]],"spl":null,"spn":null,"atl":null,"batl":null,"id":19924823,"hc":null,"bdatb":null}],"img":null,"tv":null,"con":null,"marketdefinition":null,"id":"1.258926623"}],"conflatems":null,"op":"mcm","id":3}
{"ct":null,"SegmentType":null,"clk":"AL3CAQDFxQEAirUB","heartbeatms":null,"pt":1780839814239,"initialclk":null,"mc":[{"rc":[{"tv":2046041.71,"batb":null,"spb":null,"bdatl":null,"trd":[[1.1399999999999999,135980.97]],"spf":null,"ltp":null,"atb":null,"spl":null,"spn":null,"atl":[[1.1399999999999999,27011.32]],"batl":null,"id":19924823,"hc":null,"bdatb":null}],"img":null,"tv":2291957.2599999998,"con":null,"marketdefinition":null,"id":"1.258926623"}],"conflatems":null,"op":"mcm","id":3}
{"ct":null,"SegmentType":null,"clk":"AIXDAQCIxgEAzbUB","heartbeatms":null,"pt":1780839814953,"initialclk":null,"mc":[{"rc":[{"tv":2046056.2,"batb":null,"spb":null,"bdatl":null,"trd":[[1.1399999999999999,135995.45999999999]],"spf":null,"ltp":null,"atb":null,"spl":null,"spn":null,"atl":[[1.1399999999999999,27004.07]],"batl":null,"id":19924823,"hc":null,"bdatb":null}],"img":null,"tv":2291971.75,"con":null,"marketdefinition":null,"id":"1.258926623"}],"conflatems":null,"op":"mcm","id":3}
{"ct":null,"SegmentType":null,"clk":"AKXDAQctxgEA5rUB","heartbeatms":null,"pt":1780839815352,"initialclk":null,"mc":[{"rc":[{"tv":246113.03,"batb":null,"spb":null,"bdatl":null,"trd":[[8.4000000000000004,1480.53]],"spf":null,"ltp":8.4000000000000004,"atb":null,"spl":null,"spn":null,"atl":[[8.4000000000000004,87.989999999999995]],"batl":null,"id":16570658,"hc":null,"bdatb":null}],"img":null,"tv":2292169.23,"con":null,"marketdefinition":null,"id":"1.258926623"}],"conflatems":null,"op":"mcm","id":3}
{"ct":null,"SegmentType":null,"clk":"AOjDAQD4xgEAsLYB","heartbeatms":null,"pt":1780839816134,"initialclk":null,"mc":[{"rc":[{"tv":null,"batb":null,"spb":null,"bdatl":null,"trd":null,"spf":null,"ltp":null,"atb":null,"spl":null,"spn":null,"atl":[[1.1399999999999999,27076.27]],"batl":null,"id":19924823,"hc":null,"bdatb":null}],"img":null,"tv":null,"con":null,"marketdefinition":null,"id":"1.258926623"}],"conflatems":null,"op":"mcm","id":3}
{"ct":null,"SegmentType":null,"clk":"ALrEAQC7xwEA6bYB","heartbeatms":null,"pt":1780839816958,"initialclk":null,"mc":[{"rc":[{"tv":null,"batb":null,"spb":null,"bdatl":null,"trd":null,"spf":null,"ltp":null,"atb":null,"spl":null,"spn":null,"atl":[[1.1399999999999999,27105.150000000001]],"batl":null,"id":19924823,"hc":null,"bdatb":null}],"img":null,"tv":null,"con":null,"marketdefinition":null,"id":"1.258926623"}],"conflatems":null,"op":"mcm","id":3}
{"ct":null,"SegmentType":null,"clk":"AMPEAQDJxwEA9bYB","heartbeatms":null,"pt":1780839817070,"initialclk":null,"mc":[{"rc":[{"tv":null,"batb":null,"spb":null,"bdatl":null,"trd":null,"spf":null,"ltp":null,"atb":null,"spl":null,"spn":null,"atl":[[1.1499999999999999,30861.200000000001]],"batl":null,"id":19924823,"hc":null,"bdatb":null}],"img":null,"tv":null,"con":null,"marketdefinition":null,"id":"1.258926623"}],"conflatems":null,"op":"mcm","id":3}
{"ct":null,"SegmentType":null,"clk":"AMvEAQDSxwEA/rYB","heartbeatms":null,"pt":1780839817167,"initialclk":null,"mc":[{"rc":[{"tv":null,"batb":null,"spb":null,"bdatl":null,"trd":null,"spf":null,"ltp":null,"atb":[[8,724.89999999999998]],"spl":null,"spn":null,"atl":null,"batl":null,"id":16570658,"hc":null,"bdatb":null}],"img":null,"tv":null,"con":null,"marketdefinition":null,"id":"1.258926623"}],"conflatems":null,"op":"mcm","id":3}
{"ct":null,"SegmentType":null,"clk":"AOnEAQDxxwEAkbcB","heartbeatms":null,"pt":1780839817433,"initialclk":null,"mc":[{"rc":[{"tv":null,"batb":null,"spb":null,"bdatl":null,"trd":null,"spf":null,"ltp":null,"atb":[[1.03,88975.630000000005]],"spl":null,"spn":null,"atl":null,"batl":null,"id":19924823,"hc":null,"bdatb":null}],"img":null,"tv":null,"con":null,"marketdefinition":null,"id":"1.258926623"}],"conflatems":null,"op":"mcm","id":3}
{"ct":null,"SegmentType":null,"clk":"APbEAQD9xwEAnLcB","heartbeatms":null,"pt":1780839817537,"initialclk":null,"mc":[{"rc":[{"tv":2046063.23,"batb":null,"spb":null,"bdatl":null,"trd":[[1.1399999999999999,136002.48999999999]],"spf":null,"ltp":null,"atb":null,"spl":null,"spn":null,"atl":[[1.1399999999999999,27101.630000000001]],"batl":null,"id":19924823,"hc":null,"bdatb":null}],"img":null,"tv":2292176.2599999998,"con":null,"marketdefinition":null,"id":"1.258926623"}],"conflatems":null,"op":"mcm","id":3}
{"ct":null,"SegmentType":null,"clk":"AP/EAQCLyAEAprcB","heartbeatms":null,"pt":1780839817637,"initialclk":null,"mc":[{"rc":[{"tv":null,"batb":null,"spb":null,"bdatl":null,"trd":null,"spf":null,"ltp":null,"atb":null,"spl":null,"spn":null,"atl":[[1.1399999999999999,27173.82]],"batl":null,"id":19924823,"hc":null,"bdatb":null}],"img":null,"tv":null,"con":null,"marketdefinition":null,"id":"1.258926623"}],"conflatems":null,"op":"mcm","id":3}
{"ct":null,"SegmentType":null,"clk":"AJzFAQCbyAEAsrcB","heartbeatms":null,"pt":1780839817847,"initialclk":null,"mc":[{"rc":[{"tv":null,"batb":null,"spb":null,"bdatl":null,"trd":null,"spf":null,"ltp":null,"atb":[[1.03,88975.339999999997]],"spl":null,"spn":null,"atl":null,"batl":null,"id":19924823,"hc":null,"bdatb":null}],"img":null,"tv":null,"con":null,"marketdefinition":null,"id":"1.258926623"}],"conflatems":null,"op":"mcm","id":3}
{"ct":null,"SegmentType":null,"clk":"ALrFAQC5yAEAz7cB","heartbeatms":null,"pt":1780839818157,"initialclk":null,"mc":[{"rc":[{"tv":null,"batb":null,"spb":null,"bdatl":null,"trd":null,"spf":null,"ltp":null,"atb":[[1.1100000000000001,77071.350000000006]],"spl":null,"spn":null,"atl":null,"batl":null,"id":19924823,"hc":null,"bdatb":null}],"img":null,"tv":null,"con":null,"marketdefinition":null,"id":"1.258926623"}],"conflatems":null,"op":"mcm","id":3}
{"ct":null,"SegmentType":null,"clk":"AJ/GAQCGyQEArbgB","heartbeatms":null,"pt":1780839819134,"initialclk":null,"mc":[{"rc":[{"tv":null,"batb":null,"spb":null,"bdatl":null,"trd":null,"spf":null,"ltp":null,"atb":[[7.4000000000000004,301.33999999999997]],"spl":null,"spn":null,"atl":[[9,253.31999999999999]],"batl":null,"id":16570658,"hc":null,"bdatb":null},{"tv":null,"batb":null,"spb":null,"bdatl":null,"trd":null,"spf":null,"ltp":null,"atb":[[1.1200000000000001,36848.589999999997]],"spl":null,"spn":null,"atl":[[1.1599999999999999,11265.06]],"batl":null,"id":19924823,"hc":null,"bdatb":null}],"img":null,"tv":null,"con":null,"marketdefinition":null,"id":"1.258926623"}],"conflatems":null,"op":"mcm","id":3}
{"ct":null,"SegmentType":null,"clk":"ALHGAQCTyQEAvLgB","heartbeatms":null,"pt":1780839819339,"initialclk":null,"mc":[{"rc":[{"tv":null,"batb":null,"spb":null,"bdatl":null,"trd":null,"spf":null,"ltp":null,"atb":[[1.1200000000000001,37098.589999999997]],"spl":null,"spn":null,"atl":null,"batl":null,"id":19924823,"hc":null,"bdatb":null}],"img":null,"tv":null,"con":null,"marketdefinition":null,"id":"1.258926623"}],"conflatems":null,"op":"mcm","id":3}
{"ct":null,"SegmentType":null,"clk":"AL7GAQCeyQEAx7gB","heartbeatms":null,"pt":1780839819447,"initialclk":null,"mc":[{"rc":[{"tv":null,"batb":null,"spb":null,"bdatl":null,"trd":null,"spf":null,"ltp":null,"atb":null,"spl":null,"spn":null,"atl":[[9.5999999999999996,0]],"batl":null,"id":16570658,"hc":null,"bdatb":null},{"tv":null,"batb":null,"spb":null,"bdatl":null,"trd":null,"spf":null,"ltp":null,"atb":[[1.1100000000000001,75720]],"spl":null,"spn":null,"atl":null,"batl":null,"id":19924823,"hc":null,"bdatb":null}],"img":null,"tv":null,"con":null,"marketdefinition":null,"id":"1.258926623"}],"conflatems":null,"op":"mcm","id":3}
{"ct":null,"SegmentType":null,"clk":"ANXGAQCvyQEA2bgB","heartbeatms":null,"pt":1780839819649,"initialclk":null,"mc":[{"rc":[{"tv":null,"batb":null,"spb":null,"bdatl":null,"trd":null,"spf":null,"ltp":null,"atb":[[1.1000000000000001,53504.599999999999]],"spl":null,"spn":null,"atl":null,"batl":null,"id":19924823,"hc":null,"bdatb":null}],"img":null,"tv":null,"con":null,"marketdefinition":null,"id":"1.258926623"}],"conflatems":null,"op":"mcm","id":3}
{"ct":null,"SegmentType":null,"clk":"AOXGAQC7yQEA6LgB","heartbeatms":null,"pt":1780839819852,"initialclk":null,"mc":[{"rc":[{"tv":2046254.5700000001,"batb":null,"spb":null,"bdatl":null,"trd":[[1.1399999999999999,136193.82999999999]],"spf":null,"ltp":null,"atb":null,"spl":null,"spn":null,"atl":[[1.1399999999999999,27078.150000000001]],"batl":null,"id":19924823,"hc":null,"bdatb":null}],"img":null,"tv":2292367.6000000001,"con":null,"marketdefinition":null,"id":"1.258926623"}],"conflatems":null,"op":"mcm","id":3}
{"ct":null,"SegmentType":null,"clk":"AOzGAQDGyQEA8LgB","heartbeatms":null,"pt":1780839819960,"initialclk":null,"mc":[{"rc":[{"tv":246173.03,"batb":null,"spb":null,"bdatl":null,"trd":[[8.1999999999999993,1722.4000000000001]],"spf":null,"ltp":8.1999999999999993,"atb":[[8.1999999999999993,640.64999999999998]],"spl":null,"spn":null,"atl":null,"batl":null,"id":16570658,"hc":null,"bdatb":null}],"img":null,"tv":2292427.6000000001,"con":null,"marketdefinition":null,"id":"1.258926623"}],"conflatems":null,"op":"mcm","id":3}
{"ct":null,"SegmentType":null,"clk":"AI/HAQDnyQEAjbkB","heartbeatms":null,"pt":1780839820371,"initialclk":null,"mc":[{"rc":[{"tv":2046403.71,"batb":null,"spb":null,"bdatl":null,"trd":[[1.1399999999999999,136342.97]],"spf":null,"ltp":null,"atb":null,"spl":null,"spn":null,"atl":[[1.1399999999999999,27003.580000000002]],"batl":null,"id":19924823,"hc":null,"bdatb":null}],"img":null,"tv":2292576.7400000002,"con":null,"marketdefinition":null,"id":"1.258926623"}],"conflatems":null,"op":"mcm","id":3}
{"ct":null,"SegmentType":null,"clk":"AKjHAQD0yQEAn7kB","heartbeatms":null,"pt":1780839820535,"initialclk":null,"mc":[{"rc":[{"tv":null,"batb":null,"spb":null,"bdatl":null,"trd":null,"spf":null,"ltp":null,"atb":null,"spl":null,"spn":null,"atl":[[1.1399999999999999,27075.779999999999]],"batl":null,"id":19924823,"hc":null,"bdatb":null}],"img":null,"tv":null,"con":null,"marketdefinition":null,"id":"1.258926623"}],"conflatems":null,"op":"mcm","id":3}
{"ct":null,"SegmentType":null,"clk":"AL/HAQCBygEAtLkB","heartbeatms":null,"pt":1780839820737,"initialclk":null,"mc":[{"rc":[{"tv":null,"batb":null,"spb":null,"bdatl":null,"trd":null,"spf":null,"ltp":null,"atb":[[1.1200000000000001,45830.900000000001]],"spl":null,"spn":null,"atl":null,"batl":null,"id":19924823,"hc":null,"bdatb":null}],"img":null,"tv":null,"con":null,"marketdefinition":null,"id":"1.258926623"}],"conflatems":null,"op":"mcm","id":3}
{"ct":null,"SegmentType":null,"clk":"AMrHAQCJygEAu7kB","heartbeatms":null,"pt":1780839820842,"initialclk":null,"mc":[{"rc":[{"tv":null,"batb":null,"spb":null,"bdatl":null,"trd":null,"spf":null,"ltp":null,"atb":[[1.1299999999999999,7767.7700000000004]],"spl":null,"spn":null,"atl":[[1.1599999999999999,11977.719999999999],[1.1499999999999999,31143.139999999999]],"batl":null,"id":19924823,"hc":null,"bdatb":null}],"img":null,"tv":null,"con":null,"marketdefinition":null,"id":"1.258926623"}],"conflatems":null,"op":"mcm","id":3}
{"ct":null,"SegmentType":null,"clk":"ANfHAQCSygEAxLkB","heartbeatms":null,"pt":1780839820957,"initialclk":null,"mc":[{"rc":[{"tv":2046404.3000000001,"batb":null,"spb":null,"bdatl":null,"trd":[[1.1399999999999999,136343.56]],"spf":null,"ltp":null,"atb":[[1.1100000000000001,62863.129999999997]],"spl":null,"spn":null,"atl":[[1.1399999999999999,27075.48]],"batl":null,"id":19924823,"hc":null,"bdatb":null}],"img":null,"tv":2292577.3300000001,"con":null,"marketdefinition":null,"id":"1.258926623"}],"conflatems":null,"op":"mcm","id":3}
{"ct":null,"SegmentType":null,"clk":"AN/HAQCaygEA0LkB","heartbeatms":null,"pt":1780839821052,"initialclk":null,"mc":[{"rc":[{"tv":null,"batb":null,"spb":null,"bdatl":null,"trd":null,"spf":null,"ltp":null,"atb":[[1.1200000000000001,45686.870000000003]],"spl":null,"spn":null,"atl":[[1.1399999999999999,26652.060000000001]],"batl":null,"id":19924823,"hc":null,"bdatb":null}],"img":null,"tv":null,"con":null,"marketdefinition":null,"id":"1.258926623"}],"conflatems":null,"op":"mcm","id":3}
{"ct":null,"SegmentType":null,"clk":"AO/HAQCjygEA2bkB","heartbeatms":null,"pt":1780839821156,"initialclk":null,"mc":[{"rc":[{"tv":null,"batb":null,"spb":null,"bdatl":null,"trd":null,"spf":null,"ltp":null,"atb":null,"spl":null,"spn":null,"atl":[[9,245.75]],"batl":null,"id":16570658,"hc":null,"bdatb":null}],"img":null,"tv":null,"con":null,"marketdefinition":null,"id":"1.258926623"}],"conflatems":null,"op":"mcm","id":3}
{"ct":null,"SegmentType":null,"clk":"APPHAQCrygEA3bkB","heartbeatms":null,"pt":1780839821253,"initialclk":null,"mc":[{"rc":[{"tv":null,"batb":null,"spb":null,"bdatl":null,"trd":null,"spf":null,"ltp":null,"atb":null,"spl":null,"spn":null,"atl":[[8.4000000000000004,92.989999999999995]],"batl":null,"id":16570658,"hc":null,"bdatb":null},{"tv":2046406.3000000001,"batb":null,"spb":null,"bdatl":null,"trd":[[1.1299999999999999,228519.26999999999]],"spf":null,"ltp":1.1299999999999999,"atb":[[1.1299999999999999,7766.7700000000004]],"spl":null,"spn":null,"atl":null,"batl":null,"id":19924823,"hc":null,"bdatb":null}],"img":null,"tv":2292579.3300000001,"con":null,"marketdefinition":null,"id":"1.258926623"}],"conflatems":null,"op":"mcm","id":3}
{"ct":null,"SegmentType":null,"clk":"AP7HAQC0ygEA5rkB","heartbeatms":null,"pt":1780839821356,"initialclk":null,"mc":[{"rc":[{"tv":null,"batb":null,"spb":null,"bdatl":null,"trd":null,"spf":null,"ltp":null,"atb":[[1.03,88974.589999999997]],"spl":null,"spn":null,"atl":null,"batl":null,"id":19924823,"hc":null,"bdatb":null}],"img":null,"tv":null,"con":null,"marketdefinition":null,"id":"1.258926623"}],"conflatems":null,"op":"mcm","id":3}
{"ct":null,"SegmentType":null,"clk":"AKvIAQDjygEAk7oB","heartbeatms":null,"pt":1780839821872,"initialclk":null,"mc":[{"rc":[{"tv":2046408.22,"batb":null,"spb":null,"bdatl":null,"trd":[[1.1299999999999999,228521.19]],"spf":null,"ltp":null,"atb":[[1.1299999999999999,7765.8100000000004]],"spl":null,"spn":null,"atl":null,"batl":null,"id":19924823,"hc":null,"bdatb":null}],"img":null,"tv":2292581.25,"con":null,"marketdefinition":null,"id":"1.258926623"}],"conflatems":null,"op":"mcm","id":3}
{"ct":null,"SegmentType":null,"clk":"ALrIAQDxygEAoroB","heartbeatms":null,"pt":1780839822033,"initialclk":null,"mc":[{"rc":[{"tv":246359,"batb":null,"spb":null,"bdatl":null,"trd":[[8.4000000000000004,1666.5]],"spf":null,"ltp":8.4000000000000004,"atb":[[8.4000000000000004,173.53999999999999]],"spl":null,"spn":null,"atl":[[8.4000000000000004,0]],"batl":null,"id":16570658,"hc":null,"bdatb":null}],"img":null,"tv":2292767.2200000002,"con":null,"marketdefinition":null,"id":"1.258926623"}],"conflatems":null,"op":"mcm","id":3}
{"ct":null,"SegmentType":null,"clk":"AMLIAQD5ygEArLoB","heartbeatms":null,"pt":1780839822132,"initialclk":null,"mc":[{"rc":[{"tv":null,"batb":null,"spb":null,"bdatl":null,"trd":null,"spf":null,"ltp":null,"atb":[[8.4000000000000004,218.66]],"spl":null,"spn":null,"atl":null,"batl":null,"id":16570658,"hc":null,"bdatb":null}],"img":null,"tv":null,"con":null,"marketdefinition":null,"id":"1.258926623"}],"conflatems":null,"op":"mcm","id":3}
{"ct":null,"SegmentType":null,"clk":"AP/IAQC7ywEA5roB","heartbeatms":null,"pt":1780839822846,"initialclk":null,"mc":[{"rc":[{"tv":null,"batb":null,"spb":null,"bdatl":null,"trd":null,"spf":null,"ltp":null,"atb":[[6.2000000000000002,0.98999999999999999]],"spl":null,"spn":null,"atl":null,"batl":null,"id":16570658,"hc":null,"bdatb":null}],"img":null,"tv":null,"con":null,"marketdefinition":null,"id":"1.258926623"}],"conflatems":null,"op":"mcm","id":3}
{"ct":null,"SegmentType":null,"clk":"AKzJAQDtywEAlLsB","heartbeatms":null,"pt":1780839823364,"initialclk":null,"mc":[{"rc":[{"tv":246379,"batb":null,"spb":null,"bdatl":null,"trd":[[8.4000000000000004,1686.5]],"spf":null,"ltp":null,"atb":[[8.4000000000000004,208.66]],"spl":null,"spn":null,"atl":null,"batl":null,"id":16570658,"hc":null,"bdatb":null}],"img":null,"tv":2292787.2200000002,"con":null,"marketdefinition":null,"id":"1.258926623"}],"conflatems":null,"op":"mcm","id":3}
{"ct":null,"SegmentType":null,"clk":"ALXJAQDwywEAnrsB","heartbeatms":null,"pt":1780839823418,"initialclk":null,"mc":[{"rc":[{"tv":null,"batb":null,"spb":null,"bdatl":null,"trd":null,"spf":null,"ltp":null,"atb":null,"spl":null,"spn":null,"atl":[[1.1399999999999999,26700.150000000001]],"batl":null,"id":19924823,"hc":null,"bdatb":null}],"img":null,"tv":null,"con":null,"marketdefinition":null,"id":"1.258926623"}],"conflatems":null,"op":"mcm","id":3}
{"ct":null,"SegmentType":null,"clk":"AOjJAQCezAEAyLsB","heartbeatms":null,"pt":1780839824038,"initialclk":null,"mc":[{"rc":[{"tv":2046411.47,"batb":null,"spb":null,"bdatl":null,"trd":[[1.1299999999999999,228524.44]],"spf":null,"ltp":null,"atb":[[1.1299999999999999,7764.1899999999996]],"spl":null,"spn":null,"atl":null,"batl":null,"id":19924823,"hc":null,"bdatb":null}],"img":null,"tv":2292790.4700000002,"con":null,"marketdefinition":null,"id":"1.258926623"}],"conflatems":null,"op":"mcm","id":3}
{"ct":null,"SegmentType":null,"clk":"AIPKAQC6zAEA5bsB","heartbeatms":null,"pt":1780839824350,"initialclk":null,"mc":[{"rc":[{"tv":null,"batb":null,"spb":null,"bdatl":null,"trd":null,"spf":null,"ltp":null,"atb":null,"spl":null,"spn":null,"atl":[[8.8000000000000007,546.23000000000002]],"batl":null,"id":16570658,"hc":null,"bdatb":null}],"img":null,"tv":null,"con":null,"marketdefinition":null,"id":"1.258926623"}],"conflatems":null,"op":"mcm","id":3}
{"ct":null,"SegmentType":null,"clk":"ALbKAQDxzAEAlLwB","heartbeatms":null,"pt":1780839824965,"initialclk":null,"mc":[{"rc":[{"tv":2049611.47,"batb":null,"spb":null,"bdatl":null,"trd":[[1.1299999999999999,231724.44]],"spf":null,"ltp":null,"atb":[[1.1299999999999999,6306.7299999999996]],"spl":null,"spn":null,"atl":[[1.1599999999999999,12114.540000000001]],"batl":null,"id":19924823,"hc":null,"bdatb":null}],"img":null,"tv":2295990.4700000002,"con":null,"marketdefinition":null,"id":"1.258926623"}],"conflatems":null,"op":"mcm","id":3}
{"ct":null,"SegmentType":null,"clk":"AMbKAQD9zAEApbwB","heartbeatms":null,"pt":1780839825074,"initialclk":null,"mc":[{"rc":[{"tv":null,"batb":null,"spb":null,"bdatl":null,"trd":null,"spf":null,"ltp":null,"atb":[[1.1200000000000001,45543.050000000003]],"spl":null,"spn":null,"atl":[[1.1499999999999999,31005.130000000001]],"batl":null,"id":19924823,"hc":null,"bdatb":null}],"img":null,"tv":null,"con":null,"marketdefinition":null,"id":"1.258926623"}],"conflatems":null,"op":"mcm","id":3}
{"ct":null,"SegmentType":null,"clk":"AMrKAQCHzQEArLwB","heartbeatms":null,"pt":1780839825172,"initialclk":null,"mc":[{"rc":[{"tv":null,"batb":null,"spb":null,"bdatl":null,"trd":null,"spf":null,"ltp":null,"atb":null,"spl":null,"spn":null,"atl":[[8.5999999999999996,0]],"batl":null,"id":16570658,"hc":null,"bdatb":null}],"img":null,"tv":null,"con":null,"marketdefinition":null,"id":"1.258926623"}],"conflatems":null,"op":"mcm","id":3}
{"ct":null,"SegmentType":null,"clk":"AIvMAQClzgEA3b0B","heartbeatms":null,"pt":1780839827130,"initialclk":null,"mc":[{"rc":[{"tv":null,"batb":null,"spb":null,"bdatl":null,"trd":null,"spf":null,"ltp":null,"atb":null,"spl":null,"spn":null,"atl":[[200,1]],"batl":null,"id":16570658,"hc":null,"bdatb":null}],"img":null,"tv":null,"con":null,"marketdefinition":null,"id":"1.258926623"}],"conflatems":null,"op":"mcm","id":3}
{"ct":null,"SegmentType":null,"clk":"AKPMAQC1zgEA770B","heartbeatms":null,"pt":1780839827335,"initialclk":null,"mc":[{"rc":[{"tv":2051611.47,"batb":null,"spb":null,"bdatl":null,"trd":[[1.1399999999999999,138343.56]],"spf":null,"ltp":1.1399999999999999,"atb":null,"spl":null,"spn":null,"atl":[[1.1399999999999999,25700.150000000001]],"batl":null,"id":19924823,"hc":null,"bdatb":null}],"img":null,"tv":2297990.4700000002,"con":null,"marketdefinition":null,"id":"1.258926623"}],"conflatems":null,"op":"mcm","id":3}
{"ct":null,"SegmentType":null,"clk":"AL7MAQDHzgEAh74B","heartbeatms":null,"pt":1780839827549,"initialclk":null,"mc":[{"rc":[{"tv":2051962.76,"batb":null,"spb":null,"bdatl":null,"trd":[[1.1399999999999999,138694.85000000001]],"spf":null,"ltp":null,"atb":null,"spl":null,"spn":null,"atl":[[1.1399999999999999,25524.5]],"batl":null,"id":19924823,"hc":null,"bdatb":null}],"img":null,"tv":2298341.7599999998,"con":null,"marketdefinition":null,"id":"1.258926623"}],"conflatems":null,"op":"mcm","id":3}
{"ct":null,"SegmentType":null,"clk":"AOPMAQDezgEAnb4B","heartbeatms":null,"pt":1780839827854,"initialclk":null,"mc":[{"rc":[{"tv":null,"batb":null,"spb":null,"bdatl":null,"trd":null,"spf":null,"ltp":null,"atb":null,"spl":null,"spn":null,"atl":[[1.1399999999999999,25274.5]],"batl":null,"id":19924823,"hc":null,"bdatb":null}],"img":null,"tv":null,"con":null,"marketdefinition":null,"id":"1.258926623"}],"conflatems":null,"op":"mcm","id":3}
{"ct":null,"SegmentType":null,"clk":"AMDNAQC0zwEA6b4B","heartbeatms":null,"pt":1780839828779,"initialclk":null,"mc":[{"rc":[{"tv":null,"batb":null,"spb":null,"bdatl":null,"trd":null,"spf":null,"ltp":null,"atb":[[7.7999999999999998,203.41999999999999],[7,761.54999999999995],[7.4000000000000004,504.75999999999999]],"spl":null,"spn":null,"atl":null,"batl":null,"id":16570658,"hc":null,"bdatb":null}],"img":null,"tv":null,"con":null,"marketdefinition":null,"id":"1.258926623"}],"conflatems":null,"op":"mcm","id":3}
{"ct":null,"SegmentType":null,"clk":"ANLNAQDKzwEA9r4B","heartbeatms":null,"pt":1780839828936,"initialclk":null,"mc":[{"rc":[{"tv":null,"batb":null,"spb":null,"bdatl":null,"trd":null,"spf":null,"ltp":null,"atb":[[7.5999999999999996,280.67000000000002],[7.2000000000000002,54.689999999999998],[8,531.05999999999995]],"spl":null,"spn":null,"atl":null,"batl":null,"id":16570658,"hc":null,"bdatb":null},{"tv":2051998.76,"batb":null,"spb":null,"bdatl":null,"trd":[[1.1299999999999999,231760.44]],"spf":null,"ltp":1.1299999999999999,"atb":[[1.1299999999999999,6288.7299999999996],[1.1200000000000001,45378.07]],"spl":null,"spn":null,"atl":null,"batl":null,"id":19924823,"hc":null,"bdatb":null}],"img":null,"tv":2298377.7599999998,"con":null,"marketdefinition":null,"id":"1.258926623"}],"conflatems":null,"op":"mcm","id":3}
{"ct":null,"SegmentType":null,"clk":"AOHNAQDVzwEAgL8B","heartbeatms":null,"pt":1780839829043,"initialclk":null,"mc":[{"rc":[{"tv":null,"batb":null,"spb":null,"bdatl":null,"trd":null,"spf":null,"ltp":null,"atb":[[1.1299999999999999,6405.6199999999999]],"spl":null,"spn":null,"atl":[[1.1599999999999999,12227.370000000001]],"batl":null,"id":19924823,"hc":null,"bdatb":null}],"img":null,"tv":null,"con":null,"marketdefinition":null,"id":"1.258926623"}],"conflatems":null,"op":"mcm","id":3}
{"ct":null,"SegmentType":null,"clk":"AOjNAQDdzwEAjr8B","heartbeatms":null,"pt":1780839829143,"initialclk":null,"mc":[{"rc":[{"tv":null,"batb":null,"spb":null,"bdatl":null,"trd":null,"spf":null,"ltp":null,"atb":[[1.1200000000000001,45260.150000000001]],"spl":null,"spn":null,"atl":[[1.1499999999999999,30891.32]],"batl":null,"id":19924823,"hc":null,"bdatb":null}],"img":null,"tv":null,"con":null,"marketdefinition":null,"id":"1.258926623"}],"conflatems":null,"op":"mcm","id":3}
{"ct":null,"SegmentType":null,"clk":"AJvOAQCC0AEAwr8B","heartbeatms":null,"pt":1780839829656,"initialclk":null,"mc":[{"rc":[{"tv":2052498.76,"batb":null,"spb":null,"bdatl":null,"trd":[[1.1299999999999999,232260.44]],"spf":null,"ltp":null,"atb":[[1.1299999999999999,6155.6199999999999]],"spl":null,"spn":null,"atl":null,"batl":null,"id":19924823,"hc":null,"bdatb":null}],"img":null,"tv":2298877.7599999998,"con":null,"marketdefinition":null,"id":"1.258926623"}],"conflatems":null,"op":"mcm","id":3}
{"ct":null,"SegmentType":null,"clk":"AOXOAQDA0AEA/L8B","heartbeatms":null,"pt":1780839830436,"initialclk":null,"mc":[{"rc":[{"tv":null,"batb":null,"spb":null,"bdatl":null,"trd":null,"spf":null,"ltp":null,"atb":[[1.1200000000000001,45313.25]],"spl":null,"spn":null,"atl":null,"batl":null,"id":19924823,"hc":null,"bdatb":null}],"img":null,"tv":null,"con":null,"marketdefinition":null,"id":"1.258926623"}],"conflatems":null,"op":"mcm","id":3}
{"ct":null,"SegmentType":null,"clk":"AJHPAQDd0AEAksAB","heartbeatms":null,"pt":1780839830843,"initialclk":null,"mc":[{"rc":[{"tv":2052510.77,"batb":null,"spb":null,"bdatl":null,"trd":[[1.1399999999999999,138706.85999999999]],"spf":null,"ltp":1.1399999999999999,"atb":null,"spl":null,"spn":null,"atl":[[1000,1.0900000000000001],[1.1399999999999999,25268.490000000002]],"batl":null,"id":19924823,"hc":null,"bdatb":null}],"img":null,"tv":2298889.77,"con":null,"marketdefinition":null,"id":"1.258926623"}],"conflatems":null,"op":"mcm","id":3}
{"ct":null,"SegmentType":null,"clk":"AJ/PAQDl0AEAmcAB","heartbeatms":null,"pt":1780839830948,"initialclk":null,"mc":[{"rc":[{"tv":null,"batb":null,"spb":null,"bdatl":null,"trd":null,"spf":null,"ltp":null,"atb":null,"spl":null,"spn":null,"atl":[[1.1399999999999999,25340.689999999999]],"batl":null,"id":19924823,"hc":null,"bdatb":null}],"img":null,"tv":null,"con":null,"marketdefinition":null,"id":"1.258926623"}],"conflatems":null,"op":"mcm","id":3}
{"ct":null,"SegmentType":null,"clk":"AKnPAQDv0AEAnsAB","heartbeatms":null,"pt":1780839831050,"initialclk":null,"mc":[{"rc":[{"tv":null,"batb":null,"spb":null,"bdatl":null,"trd":null,"spf":null,"ltp":null,"atb":null,"spl":null,"spn":null,"atl":[[9,255.75]],"batl":null,"id":16570658,"hc":null,"bdatb":null}],"img":null,"tv":null,"con":null,"marketdefinition":null,"id":"1.258926623"}],"conflatems":null,"op":"mcm","id":3}
{"ct":null,"SegmentType":null,"clk":"ALTPAQD30AEAo8AB","heartbeatms":null,"pt":1780839831155,"initialclk":null,"mc":[{"rc":[{"tv":2052514.02,"batb":null,"spb":null,"bdatl":null,"trd":[[1.1299999999999999,232263.69]],"spf":null,"ltp":1.1299999999999999,"atb":[[1.1299999999999999,6153.9899999999998]],"spl":null,"spn":null,"atl":null,"batl":null,"id":19924823,"hc":null,"bdatb":null}],"img":null,"tv":2298893.02,"con":null,"marketdefinition":null,"id":"1.258926623"}],"conflatems":null,"op":"mcm","id":3}
{"ct":null,"SegmentType":null,"clk":"ALzPAQD\u002B0AEAq8AB","heartbeatms":null,"pt":1780839831260,"initialclk":null,"mc":[{"rc":[{"tv":null,"batb":null,"spb":null,"bdatl":null,"trd":null,"spf":null,"ltp":null,"atb":null,"spl":null,"spn":null,"atl":[[1000,0.88]],"batl":null,"id":19924823,"hc":null,"bdatb":null}],"img":null,"tv":null,"con":null,"marketdefinition":null,"id":"1.258926623"}],"conflatems":null,"op":"mcm","id":3}
{"ct":null,"SegmentType":null,"clk":"ALvQAQDx0QEAi8EB","heartbeatms":null,"pt":1780839832656,"initialclk":null,"mc":[{"rc":[{"tv":2052516.02,"batb":null,"spb":null,"bdatl":null,"trd":[[1.1299999999999999,232265.69]],"spf":null,"ltp":null,"atb":[[1.1299999999999999,6152.9899999999998]],"spl":null,"spn":null,"atl":null,"batl":null,"id":19924823,"hc":null,"bdatb":null}],"img":null,"tv":2298895.02,"con":null,"marketdefinition":null,"id":"1.258926623"}],"conflatems":null,"op":"mcm","id":3}
{"ct":null,"SegmentType":null,"clk":"AN/QAQCJ0gEAocEB","heartbeatms":null,"pt":1780839832966,"initialclk":null,"mc":[{"rc":[{"tv":null,"batb":null,"spb":null,"bdatl":null,"trd":null,"spf":null,"ltp":null,"atb":[[1.1299999999999999,6248.6499999999996]],"spl":null,"spn":null,"atl":[[1.1599999999999999,12320.120000000001]],"batl":null,"id":19924823,"hc":null,"bdatb":null}],"img":null,"tv":null,"con":null,"marketdefinition":null,"id":"1.258926623"}],"conflatems":null,"op":"mcm","id":3}
{"ct":null,"SegmentType":null,"clk":"AOTQAQCQ0gEApcEB","heartbeatms":null,"pt":1780839833068,"initialclk":null,"mc":[{"rc":[{"tv":null,"batb":null,"spb":null,"bdatl":null,"trd":null,"spf":null,"ltp":null,"atb":[[1.1200000000000001,45216.739999999998]],"spl":null,"spn":null,"atl":[[1.1499999999999999,30861.200000000001]],"batl":null,"id":19924823,"hc":null,"bdatb":null}],"img":null,"tv":null,"con":null,"marketdefinition":null,"id":"1.258926623"}],"conflatems":null,"op":"mcm","id":3}
{"ct":null,"SegmentType":null,"clk":"APfQAQCl0gEAs8EB","heartbeatms":null,"pt":1780839833274,"initialclk":null,"mc":[{"rc":[{"tv":null,"batb":null,"spb":null,"bdatl":null,"trd":null,"spf":null,"ltp":null,"atb":[[8.4000000000000004,267.00999999999999]],"spl":null,"spn":null,"atl":null,"batl":null,"id":16570658,"hc":null,"bdatb":null}],"img":null,"tv":null,"con":null,"marketdefinition":null,"id":"1.258926623"}],"conflatems":null,"op":"mcm","id":3}
{"ct":null,"SegmentType":null,"clk":"AKnRAQDY0gEA0sEB","heartbeatms":null,"pt":1780839833735,"initialclk":null,"mc":[{"rc":[{"tv":null,"batb":null,"spb":null,"bdatl":null,"trd":null,"spf":null,"ltp":null,"atb":null,"spl":null,"spn":null,"atl":[[2,22.18]],"batl":null,"id":19924823,"hc":null,"bdatb":null}],"img":null,"tv":null,"con":null,"marketdefinition":null,"id":"1.258926623"}],"conflatems":null,"op":"mcm","id":3}
{"ct":null,"SegmentType":null,"clk":"ALnRAQDq0gEA6MEB","heartbeatms":null,"pt":1780839833943,"initialclk":null,"mc":[{"rc":[{"tv":null,"batb":null,"spb":null,"bdatl":null,"trd":null,"spf":null,"ltp":null,"atb":[[8.4000000000000004,405.74000000000001]],"spl":null,"spn":null,"atl":null,"batl":null,"id":16570658,"hc":null,"bdatb":null}],"img":null,"tv":null,"con":null,"marketdefinition":null,"id":"1.258926623"}],"conflatems":null,"op":"mcm","id":3}
{"ct":null,"SegmentType":null,"clk":"ANvRAQCM0wEAhcIB","heartbeatms":null,"pt":1780839834353,"initialclk":null,"mc":[{"rc":[{"tv":2052516.4199999999,"batb":null,"spb":null,"bdatl":null,"trd":[[1.1299999999999999,232266.09]],"spf":null,"ltp":null,"atb":[[1.1299999999999999,6248.4499999999998]],"spl":null,"spn":null,"atl":null,"batl":null,"id":19924823,"hc":null,"bdatb":null}],"img":null,"tv":2298895.4199999999,"con":null,"marketdefinition":null,"id":"1.258926623"}],"conflatems":null,"op":"mcm","id":3}
{"ct":null,"SegmentType":null,"clk":"AJvSAQDC0wEAvMIB","heartbeatms":null,"pt":1780839834972,"initialclk":null,"mc":[{"rc":[{"tv":2052531.8899999999,"batb":null,"spb":null,"bdatl":null,"trd":[[1.1399999999999999,138722.32999999999]],"spf":null,"ltp":1.1399999999999999,"atb":null,"spl":null,"spn":null,"atl":[[1.1399999999999999,25332.959999999999]],"batl":null,"id":19924823,"hc":null,"bdatb":null}],"img":null,"tv":2298910.8900000001,"con":null,"marketdefinition":null,"id":"1.258926623"}],"conflatems":null,"op":"mcm","id":3}
{"ct":null,"SegmentType":null,"clk":"AKHSAQDP0wEAxsIB","heartbeatms":null,"pt":1780839835076,"initialclk":null,"mc":[{"rc":[{"tv":246389,"batb":null,"spb":null,"bdatl":null,"trd":[[8.4000000000000004,1696.5]],"spf":null,"ltp":null,"atb":[[8.4000000000000004,400.74000000000001]],"spl":null,"spn":null,"atl":null,"batl":null,"id":16570658,"hc":null,"bdatb":null}],"img":null,"tv":2298920.8900000001,"con":null,"marketdefinition":null,"id":"1.258926623"}],"conflatems":null,"op":"mcm","id":3}
{"ct":null,"SegmentType":null,"clk":"AP/SAQCV1AEAksMB","heartbeatms":null,"pt":1780839836052,"initialclk":null,"mc":[{"rc":[{"tv":null,"batb":null,"spb":null,"bdatl":null,"trd":null,"spf":null,"ltp":null,"atb":[[1.1299999999999999,6686.6700000000001]],"spl":null,"spn":null,"atl":null,"batl":null,"id":19924823,"hc":null,"bdatb":null}],"img":null,"tv":null,"con":null,"marketdefinition":null,"id":"1.258926623"}],"conflatems":null,"op":"mcm","id":3}
{"ct":null,"SegmentType":null,"clk":"AKTTAQC51AEAr8MB","heartbeatms":null,"pt":1780839836461,"initialclk":null,"mc":[{"rc":[{"tv":2052550.0700000001,"batb":null,"spb":null,"bdatl":null,"trd":[[1.1299999999999999,232269.35000000001],[1.1399999999999999,138737.25]],"spf":null,"ltp":null,"atb":[[1.1299999999999999,6685.04]],"spl":null,"spn":null,"atl":[[1.1399999999999999,25325.490000000002]],"batl":null,"id":19924823,"hc":null,"bdatb":null}],"img":null,"tv":2298939.0699999998,"con":null,"marketdefinition":null,"id":"1.258926623"}],"conflatems":null,"op":"mcm","id":3}
{"ct":null,"SegmentType":null,"clk":"ALfTAQDR1AEAvsMB","heartbeatms":null,"pt":1780839836667,"initialclk":null,"mc":[{"rc":[{"tv":246394,"batb":null,"spb":null,"bdatl":null,"trd":[[8.4000000000000004,1701.5]],"spf":null,"ltp":null,"atb":[[8.4000000000000004,398.25]],"spl":null,"spn":null,"atl":null,"batl":null,"id":16570658,"hc":null,"bdatb":null}],"img":null,"tv":2298944.0699999998,"con":null,"marketdefinition":null,"id":"1.258926623"}],"conflatems":null,"op":"mcm","id":3}
{"ct":null,"SegmentType":null,"clk":"AMfTAQDg1AEAz8MB","heartbeatms":null,"pt":1780839836875,"initialclk":null,"mc":[{"rc":[{"tv":null,"batb":null,"spb":null,"bdatl":null,"trd":null,"spf":null,"ltp":null,"atb":[[1.1299999999999999,6763.04],[1.1200000000000001,45138.029999999999]],"spl":null,"spn":null,"atl":[[1.1599999999999999,12396.02],[1.1499999999999999,30721.209999999999]],"batl":null,"id":19924823,"hc":null,"bdatb":null}],"img":null,"tv":null,"con":null,"marketdefinition":null,"id":"1.258926623"}],"conflatems":null,"op":"mcm","id":3}
{"ct":null,"SegmentType":null,"clk":"APTTAQCR1QEA\u002BcMB","heartbeatms":null,"pt":1780839837343,"initialclk":null,"mc":[{"rc":[{"tv":2052564.8200000001,"batb":null,"spb":null,"bdatl":null,"trd":[[1.1399999999999999,138752]],"spf":null,"ltp":null,"atb":null,"spl":null,"spn":null,"atl":[[1.1399999999999999,25318.119999999999]],"batl":null,"id":19924823,"hc":null,"bdatb":null}],"img":null,"tv":2298958.8199999998,"con":null,"marketdefinition":null,"id":"1.258926623"}],"conflatems":null,"op":"mcm","id":3}
{"ct":null,"SegmentType":null,"clk":"AJ7UAQC31QEAmMQB","heartbeatms":null,"pt":1780839837755,"initialclk":null,"mc":[{"rc":[{"tv":null,"batb":null,"spb":null,"bdatl":null,"trd":null,"spf":null,"ltp":null,"atb":[[1.03,88975.339999999997]],"spl":null,"spn":null,"atl":null,"batl":null,"id":19924823,"hc":null,"bdatb":null}],"img":null,"tv":null,"con":null,"marketdefinition":null,"id":"1.258926623"}],"conflatems":null,"op":"mcm","id":3}
{"ct":null,"SegmentType":null,"clk":"AL3UAQDR1QEAvMQB","heartbeatms":null,"pt":1780839838063,"initialclk":null,"mc":[{"rc":[{"tv":2052670.5700000001,"batb":null,"spb":null,"bdatl":null,"trd":[[1.1399999999999999,138857.75]],"spf":null,"ltp":null,"atb":null,"spl":null,"spn":null,"atl":[[1.1399999999999999,25265.240000000002]],"batl":null,"id":19924823,"hc":null,"bdatb":null}],"img":null,"tv":2299064.5699999998,"con":null,"marketdefinition":null,"id":"1.258926623"}],"conflatems":null,"op":"mcm","id":3}
{"ct":null,"SegmentType":null,"clk":"ANnVAQDp1gEAqsUB","heartbeatms":null,"pt":1780839839660,"initialclk":null,"mc":[{"rc":[{"tv":246428.64000000001,"batb":null,"spb":null,"bdatl":null,"trd":[[8.4000000000000004,1736.1400000000001]],"spf":null,"ltp":null,"atb":[[8.4000000000000004,380.93000000000001]],"spl":null,"spn":null,"atl":null,"batl":null,"id":16570658,"hc":null,"bdatb":null}],"img":null,"tv":2299099.21,"con":null,"marketdefinition":null,"id":"1.258926623"}],"conflatems":null,"op":"mcm","id":3}
{"ct":null,"SegmentType":null,"clk":"AOXVAQD11gEAs8UB","heartbeatms":null,"pt":1780839839769,"initialclk":null,"mc":[{"rc":[{"tv":null,"batb":null,"spb":null,"bdatl":null,"trd":null,"spf":null,"ltp":null,"atb":null,"spl":null,"spn":null,"atl":[[9.1999999999999993,19.379999999999999]],"batl":null,"id":16570658,"hc":null,"bdatb":null}],"img":null,"tv":null,"con":null,"marketdefinition":null,"id":"1.258926623"}],"conflatems":null,"op":"mcm","id":3}
{"ct":null,"SegmentType":null,"clk":"AOvVAQCB1wEAvMUB","heartbeatms":null,"pt":1780839839868,"initialclk":null,"mc":[{"rc":[{"tv":2052674.0800000001,"batb":null,"spb":null,"bdatl":null,"trd":[[1.1399999999999999,138861.26000000001]],"spf":null,"ltp":null,"atb":null,"spl":null,"spn":null,"atl":[[1.1399999999999999,25263.490000000002]],"batl":null,"id":19924823,"hc":null,"bdatb":null}],"img":null,"tv":2299102.7200000002,"con":null,"marketdefinition":null,"id":"1.258926623"}],"conflatems":null,"op":"mcm","id":3}
{"ct":null,"SegmentType":null,"clk":"AP7VAQCT1wEAzMUB","heartbeatms":null,"pt":1780839840074,"initialclk":null,"mc":[{"rc":[{"tv":2052674.3600000001,"batb":null,"spb":null,"bdatl":null,"trd":[[1.1299999999999999,232269.63000000001]],"spf":null,"ltp":1.1299999999999999,"atb":[[1.1299999999999999,6762.8999999999996]],"spl":null,"spn":null,"atl":null,"batl":null,"id":19924823,"hc":null,"bdatb":null}],"img":null,"tv":2299103,"con":null,"marketdefinition":null,"id":"1.258926623"}],"conflatems":null,"op":"mcm","id":3}
{"ct":null,"SegmentType":null,"clk":"AInWAQCe1wEA08UB","heartbeatms":null,"pt":1780839840179,"initialclk":null,"mc":[{"rc":[{"tv":null,"batb":null,"spb":null,"bdatl":null,"trd":null,"spf":null,"ltp":null,"atb":[[1.1299999999999999,6175.46]],"spl":null,"spn":null,"atl":null,"batl":null,"id":19924823,"hc":null,"bdatb":null}],"img":null,"tv":null,"con":null,"marketdefinition":null,"id":"1.258926623"}],"conflatems":null,"op":"mcm","id":3}
{"ct":null,"SegmentType":null,"clk":"ALzWAQDN1wEAgcYB","heartbeatms":null,"pt":1780839840646,"initialclk":null,"mc":[{"rc":[{"tv":2081404.98,"batb":null,"spb":null,"bdatl":null,"trd":[[1.1399999999999999,167591.88000000001]],"spf":null,"ltp":1.1399999999999999,"atb":null,"spl":null,"spn":null,"atl":[[1.1399999999999999,10898.18]],"batl":null,"id":19924823,"hc":null,"bdatb":null}],"img":null,"tv":2327833.6200000001,"con":null,"marketdefinition":null,"id":"1.258926623"}],"conflatems":null,"op":"mcm","id":3}
{"ct":null,"SegmentType":null,"clk":"AMXWAQDX1wEAi8YB","heartbeatms":null,"pt":1780839840750,"initialclk":null,"mc":[{"rc":[{"tv":null,"batb":null,"spb":null,"bdatl":null,"trd":null,"spf":null,"ltp":null,"atb":null,"spl":null,"spn":null,"atl":[[8.8000000000000007,716.67999999999995]],"batl":null,"id":16570658,"hc":null,"bdatb":null}],"img":null,"tv":null,"con":null,"marketdefinition":null,"id":"1.258926623"}],"conflatems":null,"op":"mcm","id":3}
{"ct":null,"SegmentType":null,"clk":"AOfWAQD11wEAqcYB","heartbeatms":null,"pt":1780839841059,"initialclk":null,"mc":[{"rc":[{"tv":null,"batb":null,"spb":null,"bdatl":null,"trd":null,"spf":null,"ltp":null,"atb":[[1.03,88975.580000000002]],"spl":null,"spn":null,"atl":null,"batl":null,"id":19924823,"hc":null,"bdatb":null}],"img":null,"tv":null,"con":null,"marketdefinition":null,"id":"1.258926623"}],"conflatems":null,"op":"mcm","id":3}
{"ct":null,"SegmentType":null,"clk":"APfWAQCL2AEAvsYB","heartbeatms":null,"pt":1780839841268,"initialclk":null,"mc":[{"rc":[{"tv":246431.54000000001,"batb":null,"spb":null,"bdatl":null,"trd":[[8.8000000000000007,1156.4400000000001]],"spf":null,"ltp":8.8000000000000007,"atb":null,"spl":null,"spn":null,"atl":[[8.8000000000000007,715.23000000000002],[9,89.090000000000003]],"batl":null,"id":16570658,"hc":null,"bdatb":null}],"img":null,"tv":2327836.52,"con":null,"marketdefinition":null,"id":"1.258926623"}],"conflatems":null,"op":"mcm","id":3}
{"ct":null,"SegmentType":null,"clk":"AILXAQCS2AEAw8YB","heartbeatms":null,"pt":1780839841361,"initialclk":null,"mc":[{"rc":[{"tv":null,"batb":null,"spb":null,"bdatl":null,"trd":null,"spf":null,"ltp":null,"atb":[[8,369.17000000000002]],"spl":null,"spn":null,"atl":null,"batl":null,"id":16570658,"hc":null,"bdatb":null}],"img":null,"tv":null,"con":null,"marketdefinition":null,"id":"1.258926623"}],"conflatems":null,"op":"mcm","id":3}
{"ct":null,"SegmentType":null,"clk":"AJ7XAQCn2AEA1MYB","heartbeatms":null,"pt":1780839841583,"initialclk":null,"mc":[{"rc":[{"tv":null,"batb":null,"spb":null,"bdatl":null,"trd":null,"spf":null,"ltp":null,"atb":[[1.03,88975.339999999997]],"spl":null,"spn":null,"atl":null,"batl":null,"id":19924823,"hc":null,"bdatb":null}],"img":null,"tv":null,"con":null,"marketdefinition":null,"id":"1.258926623"}],"conflatems":null,"op":"mcm","id":3}
{"ct":null,"SegmentType":null,"clk":"AKLXAQC02AEA2cYB","heartbeatms":null,"pt":1780839841682,"initialclk":null,"mc":[{"rc":[{"tv":2081408.24,"batb":null,"spb":null,"bdatl":null,"trd":[[1.1299999999999999,232272.89000000001]],"spf":null,"ltp":1.1299999999999999,"atb":[[1.1299999999999999,6173.8299999999999]],"spl":null,"spn":null,"atl":null,"batl":null,"id":19924823,"hc":null,"bdatb":null}],"img":null,"tv":2327839.7799999998,"con":null,"marketdefinition":null,"id":"1.258926623"}],"conflatems":null,"op":"mcm","id":3}
{"ct":null,"SegmentType":null,"clk":"ALfXAQDA2AEA68YB","heartbeatms":null,"pt":1780839841878,"initialclk":null,"mc":[{"rc":[{"tv":246431.66,"batb":null,"spb":null,"bdatl":null,"trd":[[8.4000000000000004,1736.26]],"spf":null,"ltp":8.4000000000000004,"atb":[[8.4000000000000004,380.87]],"spl":null,"spn":null,"atl":null,"batl":null,"id":16570658,"hc":null,"bdatb":null}],"img":null,"tv":2327839.8999999999,"con":null,"marketdefinition":null,"id":"1.258926623"}],"conflatems":null,"op":"mcm","id":3}
{"ct":null,"SegmentType":null,"clk":"AM3XAQDW2AEAgscB","heartbeatms":null,"pt":1780839842186,"initialclk":null,"mc":[{"rc":[{"tv":null,"batb":null,"spb":null,"bdatl":null,"trd":null,"spf":null,"ltp":null,"atb":null,"spl":null,"spn":null,"atl":[[8.8000000000000007,544.77999999999997]],"batl":null,"id":16570658,"hc":null,"bdatb":null}],"img":null,"tv":null,"con":null,"marketdefinition":null,"id":"1.258926623"}],"conflatems":null,"op":"mcm","id":3}
{"ct":null,"SegmentType":null,"clk":"AODXAQDn2AEAl8cB","heartbeatms":null,"pt":1780839842350,"initialclk":null,"mc":[{"rc":[{"tv":2081422.74,"batb":null,"spb":null,"bdatl":null,"trd":[[1.1399999999999999,167606.38000000001]],"spf":null,"ltp":1.1399999999999999,"atb":null,"spl":null,"spn":null,"atl":[[1.1399999999999999,10890.93]],"batl":null,"id":19924823,"hc":null,"bdatb":null}],"img":null,"tv":2327854.3999999999,"con":null,"marketdefinition":null,"id":"1.258926623"}],"conflatems":null,"op":"mcm","id":3}
{"ct":null,"SegmentType":null,"clk":"ALrZAQCS2gEA38gB","heartbeatms":null,"pt":1780839844568,"initialclk":null,"mc":[{"rc":[{"tv":2081479.8700000001,"batb":null,"spb":null,"bdatl":null,"trd":[[1.1399999999999999,167663.51000000001]],"spf":null,"ltp":null,"atb":null,"spl":null,"spn":null,"atl":[[1.1399999999999999,10862.370000000001]],"batl":null,"id":19924823,"hc":null,"bdatb":null}],"img":null,"tv":2327911.5299999998,"con":null,"marketdefinition":null,"id":"1.258926623"}],"conflatems":null,"op":"mcm","id":3}
{"ct":null,"SegmentType":null,"clk":"AMHZAQCb2gEA6MgB","heartbeatms":null,"pt":1780839844663,"initialclk":null,"mc":[{"rc":[{"tv":2081480.3500000001,"batb":null,"spb":null,"bdatl":null,"trd":[[1.1399999999999999,167663.98999999999]],"spf":null,"ltp":null,"atb":null,"spl":null,"spn":null,"atl":[[1.1399999999999999,10862.129999999999]],"batl":null,"id":19924823,"hc":null,"bdatb":null}],"img":null,"tv":2327912.0099999998,"con":null,"marketdefinition":null,"id":"1.258926623"}],"conflatems":null,"op":"mcm","id":3}
{"ct":null,"SegmentType":null,"clk":"AMrZAQCk2gEA8cgB","heartbeatms":null,"pt":1780839844768,"initialclk":null,"mc":[{"rc":[{"tv":2081580.3500000001,"batb":null,"spb":null,"bdatl":null,"trd":[[1.1299999999999999,232372.89000000001]],"spf":null,"ltp":1.1299999999999999,"atb":[[1.1299999999999999,6238.75]],"spl":null,"spn":null,"atl":[[1.1599999999999999,12508.25]],"batl":null,"id":19924823,"hc":null,"bdatb":null}],"img":null,"tv":2328012.0099999998,"con":null,"marketdefinition":null,"id":"1.258926623"}],"conflatems":null,"op":"mcm","id":3}
{"ct":null,"SegmentType":null,"clk":"ANTZAQCr2gEA98gB","heartbeatms":null,"pt":1780839844869,"initialclk":null,"mc":[{"rc":[{"tv":null,"batb":null,"spb":null,"bdatl":null,"trd":null,"spf":null,"ltp":null,"atb":[[1.1200000000000001,45022.089999999997]],"spl":null,"spn":null,"atl":[[1.1499999999999999,30608]],"batl":null,"id":19924823,"hc":null,"bdatb":null}],"img":null,"tv":null,"con":null,"marketdefinition":null,"id":"1.258926623"}],"conflatems":null,"op":"mcm","id":3}
{"ct":null,"SegmentType":null,"clk":"AN/ZAQC02gEA/cgB","heartbeatms":null,"pt":1780839844970,"initialclk":null,"mc":[{"rc":[{"tv":2081582.4099999999,"batb":null,"spb":null,"bdatl":null,"trd":[[1.1399999999999999,167666.04999999999]],"spf":null,"ltp":1.1399999999999999,"atb":null,"spl":null,"spn":null,"atl":[[1.1399999999999999,10861.1]],"batl":null,"id":19924823,"hc":null,"bdatb":null}],"img":null,"tv":2328014.0699999998,"con":null,"marketdefinition":null,"id":"1.258926623"}],"conflatems":null,"op":"mcm","id":3}
{"ct":null,"SegmentType":null,"clk":"AOXZAQDA2gEAh8kB","heartbeatms":null,"pt":1780839845074,"initialclk":null,"mc":[{"rc":[{"tv":null,"batb":null,"spb":null,"bdatl":null,"trd":null,"spf":null,"ltp":null,"atb":null,"spl":null,"spn":null,"atl":[[1.1399999999999999,22687.09]],"batl":null,"id":19924823,"hc":null,"bdatb":null}],"img":null,"tv":null,"con":null,"marketdefinition":null,"id":"1.258926623"}],"conflatems":null,"op":"mcm","id":3}
{"ct":null,"SegmentType":null,"clk":"AO/ZAQDJ2gEAjMkB","heartbeatms":null,"pt":1780839845183,"initialclk":null,"mc":[{"rc":[{"tv":null,"batb":null,"spb":null,"bdatl":null,"trd":null,"spf":null,"ltp":null,"atb":[[1.03,88974.589999999997]],"spl":null,"spn":null,"atl":null,"batl":null,"id":19924823,"hc":null,"bdatb":null}],"img":null,"tv":null,"con":null,"marketdefinition":null,"id":"1.258926623"}],"conflatems":null,"op":"mcm","id":3}
{"ct":null,"SegmentType":null,"clk":"AKfaAQD12gEAx8kB","heartbeatms":null,"pt":1780839845851,"initialclk":null,"mc":[{"rc":[{"tv":246437.66,"batb":null,"spb":null,"bdatl":null,"trd":[[8.4000000000000004,1742.26]],"spf":null,"ltp":null,"atb":[[8.4000000000000004,377.87]],"spl":null,"spn":null,"atl":null,"batl":null,"id":16570658,"hc":null,"bdatb":null}],"img":null,"tv":2328020.0699999998,"con":null,"marketdefinition":null,"id":"1.258926623"}],"conflatems":null,"op":"mcm","id":3}
{"ct":null,"SegmentType":null,"clk":"ALDaAQD/2gEA0skB","heartbeatms":null,"pt":1780839845952,"initialclk":null,"mc":[{"rc":[{"tv":null,"batb":null,"spb":null,"bdatl":null,"trd":null,"spf":null,"ltp":null,"atb":null,"spl":null,"spn":null,"atl":[[1.1399999999999999,22896.34]],"batl":null,"id":19924823,"hc":null,"bdatb":null}],"img":null,"tv":null,"con":null,"marketdefinition":null,"id":"1.258926623"}],"conflatems":null,"op":"mcm","id":3}
{"ct":null,"SegmentType":null,"clk":"ANLaAQCj2wEA8ckB","heartbeatms":null,"pt":1780839846365,"initialclk":null,"mc":[{"rc":[{"tv":null,"batb":null,"spb":null,"bdatl":null,"trd":null,"spf":null,"ltp":null,"atb":[[1.1000000000000001,70780.229999999996]],"spl":null,"spn":null,"atl":null,"batl":null,"id":19924823,"hc":null,"bdatb":null}],"img":null,"tv":null,"con":null,"marketdefinition":null,"id":"1.258926623"}],"conflatems":null,"op":"mcm","id":3}
{"ct":null,"SegmentType":null,"clk":"AIPbAQDP2wEAlcoB","heartbeatms":null,"pt":1780839846878,"initialclk":null,"mc":[{"rc":[{"tv":null,"batb":null,"spb":null,"bdatl":null,"trd":null,"spf":null,"ltp":null,"atb":[[1.1200000000000001,45281.220000000001]],"spl":null,"spn":null,"atl":null,"batl":null,"id":19924823,"hc":null,"bdatb":null}],"img":null,"tv":null,"con":null,"marketdefinition":null,"id":"1.258926623"}],"conflatems":null,"op":"mcm","id":3}
{"ct":null,"SegmentType":null,"clk":"AJPbAQDX2wEAqcoB","heartbeatms":null,"pt":1780839847082,"initialclk":null,"mc":[{"rc":[{"tv":2081594.01,"batb":null,"spb":null,"bdatl":null,"trd":[[1.1399999999999999,167677.64999999999]],"spf":null,"ltp":null,"atb":null,"spl":null,"spn":null,"atl":[[1.1399999999999999,22890.540000000001]],"batl":null,"id":19924823,"hc":null,"bdatb":null}],"img":null,"tv":2328031.6699999999,"con":null,"marketdefinition":null,"id":"1.258926623"}],"conflatems":null,"op":"mcm","id":3}
{"ct":null,"SegmentType":null,"clk":"AKbbAQDs2wEAtcoB","heartbeatms":null,"pt":1780839847289,"initialclk":null,"mc":[{"rc":[{"tv":2081594.3000000001,"batb":null,"spb":null,"bdatl":null,"trd":[[1.1399999999999999,167677.94]],"spf":null,"ltp":null,"atb":null,"spl":null,"spn":null,"atl":[[1.1399999999999999,22890.400000000001]],"batl":null,"id":19924823,"hc":null,"bdatb":null}],"img":null,"tv":2328031.96,"con":null,"marketdefinition":null,"id":"1.258926623"}],"conflatems":null,"op":"mcm","id":3}
{"ct":null,"SegmentType":null,"clk":"AObbAQCs3AEA7coB","heartbeatms":null,"pt":1780839847959,"initialclk":null,"mc":[{"rc":[{"tv":null,"batb":null,"spb":null,"bdatl":null,"trd":null,"spf":null,"ltp":null,"atb":null,"spl":null,"spn":null,"atl":[[1.1399999999999999,22790.400000000001]],"batl":null,"id":19924823,"hc":null,"bdatb":null}],"img":null,"tv":null,"con":null,"marketdefinition":null,"id":"1.258926623"}],"conflatems":null,"op":"mcm","id":3}
{"ct":null,"SegmentType":null,"clk":"AM7cAQD23AEAtssB","heartbeatms":null,"pt":1780839848883,"initialclk":null,"mc":[{"rc":[{"tv":246441.66,"batb":null,"spb":null,"bdatl":null,"trd":[[8.4000000000000004,1746.26]],"spf":null,"ltp":null,"atb":[[8.4000000000000004,375.87]],"spl":null,"spn":null,"atl":null,"batl":null,"id":16570658,"hc":null,"bdatb":null}],"img":null,"tv":2328035.96,"con":null,"marketdefinition":null,"id":"1.258926623"}],"conflatems":null,"op":"mcm","id":3}
{"ct":null,"SegmentType":null,"clk":"AN/cAQD83AEAv8sB","heartbeatms":null,"pt":1780839848992,"initialclk":null,"mc":[{"rc":[{"tv":null,"batb":null,"spb":null,"bdatl":null,"trd":null,"spf":null,"ltp":null,"atb":null,"spl":null,"spn":null,"atl":[[9,255.75]],"batl":null,"id":16570658,"hc":null,"bdatb":null}],"img":null,"tv":null,"con":null,"marketdefinition":null,"id":"1.258926623"}],"conflatems":null,"op":"mcm","id":3}
{"ct":null,"SegmentType":null,"clk":"APDcAQCM3QEAyssB","heartbeatms":null,"pt":1780839849149,"initialclk":null,"mc":[{"rc":[{"tv":2083594.3000000001,"batb":null,"spb":null,"bdatl":null,"trd":[[1.1399999999999999,169677.94]],"spf":null,"ltp":null,"atb":null,"spl":null,"spn":null,"atl":[[1.1399999999999999,21790.400000000001]],"batl":null,"id":19924823,"hc":null,"bdatb":null}],"img":null,"tv":2330035.96,"con":null,"marketdefinition":null,"id":"1.258926623"}],"conflatems":null,"op":"mcm","id":3}
{"ct":null,"SegmentType":null,"clk":"AJXdAQct3QEA6ssB","heartbeatms":null,"pt":1780839849558,"initialclk":null,"mc":[{"rc":[{"tv":2083597.5500000001,"batb":null,"spb":null,"bdatl":null,"trd":[[1.1399999999999999,169681.19]],"spf":null,"ltp":null,"atb":null,"spl":null,"spn":null,"atl":[[1.1399999999999999,21788.77]],"batl":null,"id":19924823,"hc":null,"bdatb":null}],"img":null,"tv":2330039.21,"con":null,"marketdefinition":null,"id":"1.258926623"}],"conflatems":null,"op":"mcm","id":3}
{"ct":null,"SegmentType":null,"clk":"AKHdAQC13QEA8MsB","heartbeatms":null,"pt":1780839849662,"initialclk":null,"mc":[{"rc":[{"tv":2083612.04,"batb":null,"spb":null,"bdatl":null,"trd":[[1.1399999999999999,169695.67999999999]],"spf":null,"ltp":null,"atb":[[1.1299999999999999,6231.2600000000002]],"spl":null,"spn":null,"atl":[[1.1399999999999999,21781.52],[1.1499999999999999,30600.509999999998]],"batl":null,"id":19924823,"hc":null,"bdatb":null}],"img":null,"tv":2330053.7000000002,"con":null,"marketdefinition":null,"id":"1.258926623"}],"conflatems":null,"op":"mcm","id":3}
{"ct":null,"SegmentType":null,"clk":"AKPeAQCw3gEA1MwB","heartbeatms":null,"pt":1780839851062,"initialclk":null,"mc":[{"rc":[{"tv":2083625,"batb":null,"spb":null,"bdatl":null,"trd":[[1.1299999999999999,232385.85000000001]],"spf":null,"ltp":1.1299999999999999,"atb":[[1.1299999999999999,6224.7799999999997]],"spl":null,"spn":null,"atl":null,"batl":null,"id":19924823,"hc":null,"bdatb":null}],"img":null,"tv":2330066.6600000001,"con":null,"marketdefinition":null,"id":"1.258926623"}],"conflatems":null,"op":"mcm","id":3}
{"ct":null,"SegmentType":null,"clk":"AMneAQDU3gEA\u002BcwB","heartbeatms":null,"pt":1780839851470,"initialclk":null,"mc":[{"rc":[{"tv":2083825,"batb":null,"spb":null,"bdatl":null,"trd":[[1.1399999999999999,169895.67999999999]],"spf":null,"ltp":1.1399999999999999,"atb":null,"spl":null,"spn":null,"atl":[[1.1399999999999999,21681.52]],"batl":null,"id":19924823,"hc":null,"bdatb":null}],"img":null,"tv":2330266.6600000001,"con":null,"marketdefinition":null,"id":"1.258926623"}],"conflatems":null,"op":"mcm","id":3}
{"ct":null,"SegmentType":null,"clk":"ANPeAQDf3gEAgc0B","heartbeatms":null,"pt":1780839851577,"initialclk":null,"mc":[{"rc":[{"tv":2084113.78,"batb":null,"spb":null,"bdatl":null,"trd":[[1.1299999999999999,232674.63000000001]],"spf":null,"ltp":1.1299999999999999,"atb":[[1.1299999999999999,6080.3900000000003]],"spl":null,"spn":null,"atl":null,"batl":null,"id":19924823,"hc":null,"bdatb":null}],"img":null,"tv":2330555.4399999999,"con":null,"marketdefinition":null,"id":"1.258926623"}],"conflatems":null,"op":"mcm","id":3}
{"ct":null,"SegmentType":null,"clk":"APDeAQDy3gEAnM0B","heartbeatms":null,"pt":1780839851879,"initialclk":null,"mc":[{"rc":[{"tv":2084151.0600000001,"batb":null,"spb":null,"bdatl":null,"trd":[[1.1399999999999999,169932.95999999999]],"spf":null,"ltp":1.1399999999999999,"atb":null,"spl":null,"spn":null,"atl":[[1.1399999999999999,21662.880000000001]],"batl":null,"id":19924823,"hc":null,"bdatb":null}],"img":null,"tv":2330592.7200000002,"con":null,"marketdefinition":null,"id":"1.258926623"}],"conflatems":null,"op":"mcm","id":3}
{"ct":null,"SegmentType":null,"clk":"AIXfAQD\u002B3gEArM0B","heartbeatms":null,"pt":1780839852096,"initialclk":null,"mc":[{"rc":[{"tv":null,"batb":null,"spb":null,"bdatl":null,"trd":null,"spf":null,"ltp":null,"atb":[[1.1299999999999999,5656.9099999999999]],"spl":null,"spn":null,"atl":null,"batl":null,"id":19924823,"hc":null,"bdatb":null}],"img":null,"tv":null,"con":null,"marketdefinition":null,"id":"1.258926623"}],"conflatems":null,"op":"mcm","id":3}
{"ct":null,"SegmentType":null,"clk":"AKTfAQCn3wEA1c0B","heartbeatms":null,"pt":1780839852500,"initialclk":null,"mc":[{"rc":[{"tv":null,"batb":null,"spb":null,"bdatl":null,"trd":null,"spf":null,"ltp":null,"atb":[[1.1299999999999999,5754.1300000000001]],"spl":null,"spn":null,"atl":null,"batl":null,"id":19924823,"hc":null,"bdatb":null}],"img":null,"tv":null,"con":null,"marketdefinition":null,"id":"1.258926623"}],"conflatems":null,"op":"mcm","id":3}
{"ct":null,"SegmentType":null,"clk":"AK7fAQCy3wEA4s0B","heartbeatms":null,"pt":1780839852553,"initialclk":null,"mc":[{"rc":[{"tv":null,"batb":null,"spb":null,"bdatl":null,"trd":null,"spf":null,"ltp":null,"atb":[[1.1200000000000001,45981.220000000001]],"spl":null,"spn":null,"atl":[[1.1499999999999999,30280.84]],"batl":null,"id":19924823,"hc":null,"bdatb":null}],"img":null,"tv":null,"con":null,"marketdefinition":null,"id":"1.258926623"}],"conflatems":null,"op":"mcm","id":3}
{"ct":null,"SegmentType":null,"clk":"AIHgAQCJ4AEA9c4B","heartbeatms":null,"pt":1780839853485,"initialclk":null,"mc":[{"rc":[{"tv":null,"batb":null,"spb":null,"bdatl":null,"trd":null,"spf":null,"ltp":null,"atb":null,"spl":null,"spn":null,"atl":[[9.4000000000000004,12.99]],"batl":null,"id":16570658,"hc":null,"bdatb":null},{"tv":2084686.0600000001,"batb":null,"spb":null,"bdatl":null,"trd":[[1.1399999999999999,170467.95999999999]],"spf":null,"ltp":null,"atb":null,"spl":null,"spn":null,"atl":[[1.1399999999999999,21395.389999999999]],"batl":null,"id":19924823,"hc":null,"bdatb":null}],"img":null,"tv":2331127.7200000002,"con":null,"marketdefinition":null,"id":"1.258926623"}],"conflatems":null,"op":"mcm","id":3}
{"ct":null,"SegmentType":null,"clk":"AJLgAQCf4AEAhc8B","heartbeatms":null,"pt":1780839853689,"initialclk":null,"mc":[{"rc":[{"tv":null,"batb":null,"spb":null,"bdatl":null,"trd":null,"spf":null,"ltp":null,"atb":[[1.1299999999999999,3054.1300000000001]],"spl":null,"spn":null,"atl":null,"batl":null,"id":19924823,"hc":null,"bdatb":null}],"img":null,"tv":null,"con":null,"marketdefinition":null,"id":"1.258926623"}],"conflatems":null,"op":"mcm","id":3}
{"ct":null,"SegmentType":null,"clk":"ALbgAQDJ4AEAqc8B","heartbeatms":null,"pt":1780839854099,"initialclk":null,"mc":[{"rc":[{"tv":null,"batb":null,"spb":null,"bdatl":null,"trd":null,"spf":null,"ltp":null,"atb":[[8.4000000000000004,316.92000000000002]],"spl":null,"spn":null,"atl":null,"batl":null,"id":16570658,"hc":null,"bdatb":null}],"img":null,"tv":null,"con":null,"marketdefinition":null,"id":"1.258926623"}],"conflatems":null,"op":"mcm","id":3}
{"ct":null,"SegmentType":null,"clk":"AL/gAQDT4AEAss8B","heartbeatms":null,"pt":1780839854158,"initialclk":null,"mc":[{"rc":[{"tv":2090794.3300000001,"batb":null,"spb":null,"bdatl":null,"trd":[[1.1299999999999999,238782.89999999999]],"spf":null,"ltp":1.1299999999999999,"atb":[[1.1299999999999999,0]],"spl":null,"spn":null,"atl":[[1.1299999999999999,26]],"batl":null,"id":19924823,"hc":null,"bdatb":null}],"img":null,"tv":2337235.9900000002,"con":null,"marketdefinition":null,"id":"1.258926623"}],"conflatems":null,"op":"mcm","id":3}
{"ct":null,"SegmentType":null,"clk":"ANPgAQDh4AEAxM8B","heartbeatms":null,"pt":1780839854364,"initialclk":null,"mc":[{"rc":[{"tv":null,"batb":null,"spb":null,"bdatl":null,"trd":null,"spf":null,"ltp":null,"atb":[[8,554.15999999999997]],"spl":null,"spn":null,"atl":null,"batl":null,"id":16570658,"hc":null,"bdatb":null},{"tv":null,"batb":null,"spb":null,"bdatl":null,"trd":null,"spf":null,"ltp":null,"atb":[[1.1100000000000001,64214.480000000003]],"spl":null,"spn":null,"atl":[[1.1399999999999999,21186.139999999999],[1.1499999999999999,31567.759999999998]],"batl":null,"id":19924823,"hc":null,"bdatb":null}],"img":null,"tv":null,"con":null,"marketdefinition":null,"id":"1.258926623"}],"conflatems":null,"op":"mcm","id":3}
{"ct":null,"SegmentType":null,"clk":"AN7gAQDq4AEAz88B","heartbeatms":null,"pt":1780839854468,"initialclk":null,"mc":[{"rc":[{"tv":null,"batb":null,"spb":null,"bdatl":null,"trd":null,"spf":null,"ltp":null,"atb":null,"spl":null,"spn":null,"atl":[[9,89.090000000000003]],"batl":null,"id":16570658,"hc":null,"bdatb":null},{"tv":null,"batb":null,"spb":null,"bdatl":null,"trd":null,"spf":null,"ltp":null,"atb":[[1.1200000000000001,44641.940000000002]],"spl":null,"spn":null,"atl":null,"batl":null,"id":19924823,"hc":null,"bdatb":null}],"img":null,"tv":null,"con":null,"marketdefinition":null,"id":"1.258926623"}],"conflatems":null,"op":"mcm","id":3}
{"ct":null,"SegmentType":null,"clk":"AO3gAQD\u002B4AEA3c8B","heartbeatms":null,"pt":1780839854677,"initialclk":null,"mc":[{"rc":[{"tv":null,"batb":null,"spb":null,"bdatl":null,"trd":null,"spf":null,"ltp":null,"atb":[[7.4000000000000004,312.75]],"spl":null,"spn":null,"atl":null,"batl":null,"id":16570658,"hc":null,"bdatb":null},{"tv":null,"batb":null,"spb":null,"bdatl":null,"trd":null,"spf":null,"ltp":null,"atb":null,"spl":null,"spn":null,"atl":[[1.1599999999999999,11283.360000000001]],"batl":null,"id":19924823,"hc":null,"bdatb":null}],"img":null,"tv":null,"con":null,"marketdefinition":null,"id":"1.258926623"}],"conflatems":null,"op":"mcm","id":3}
{"ct":null,"SegmentType":null,"clk":"AJDhAQC84QEAjtAB","heartbeatms":null,"pt":1780839855087,"initialclk":null,"mc":[{"rc":[{"tv":246752.62,"batb":null,"spb":null,"bdatl":null,"trd":[[8.8000000000000007,1467.4000000000001]],"spf":null,"ltp":8.8000000000000007,"atb":null,"spl":null,"spn":null,"atl":[[8.8000000000000007,389.30000000000001]],"batl":null,"id":16570658,"hc":null,"bdatb":null}],"img":null,"tv":2337546.9500000002,"con":null,"marketdefinition":null,"id":"1.258926623"}],"conflatems":null,"op":"mcm","id":3}
{"ct":null,"SegmentType":null,"clk":"AJ/hAQDW4QEAotAB","heartbeatms":null,"pt":1780839855296,"initialclk":null,"mc":[{"rc":[{"tv":null,"batb":null,"spb":null,"bdatl":null,"trd":null,"spf":null,"ltp":null,"atb":[[6.4000000000000004,0.85999999999999999]],"spl":null,"spn":null,"atl":null,"batl":null,"id":16570658,"hc":null,"bdatb":null},{"tv":null,"batb":null,"spb":null,"bdatl":null,"trd":null,"spf":null,"ltp":null,"atb":null,"spl":null,"spn":null,"atl":[[1.1599999999999999,10752.83]],"batl":null,"id":19924823,"hc":null,"bdatb":null}],"img":null,"tv":null,"con":null,"marketdefinition":null,"id":"1.258926623"}],"conflatems":null,"op":"mcm","id":3}
{"ct":null,"SegmentType":null,"clk":"AKnhAQDg4QEAqdAB","heartbeatms":null,"pt":1780839855398,"initialclk":null,"mc":[{"rc":[{"tv":null,"batb":null,"spb":null,"bdatl":null,"trd":null,"spf":null,"ltp":null,"atb":null,"spl":null,"spn":null,"atl":[[13.5,5.5999999999999996]],"batl":null,"id":16570658,"hc":null,"bdatb":null}],"img":null,"tv":null,"con":null,"marketdefinition":null,"id":"1.258926623"}],"conflatems":null,"op":"mcm","id":3}
