{"ct":null,"SegmentType":null,"clk":"AP49AMFCALtA","heartbeatms":null,"pt":1780839638789,"initialclk":null,"mc":[{"rc":[{"tv":null,"batb":null,"spb":null,"bdatl":null,"trd":null,"spf":null,"ltp":null,"atb":[[9.4000000000000004,0.94999999999999996]],"spl":null,"spn":null,"atl":null,"batl":null,"id":16570658,"hc":null,"bdatb":null}],"img":null,"tv":null,"con":null,"marketdefinition":null,"id":"1.258926623"}],"conflatems":null,"op":"mcm","id":3}
{"ct":null,"SegmentType":null,"clk":"AKc\u002BAONCAOZA","heartbeatms":null,"pt":1780839639192,"initialclk":null,"mc":[{"rc":[{"tv":null,"batb":null,"spb":null,"bdatl":null,"trd":null,"spf":null,"ltp":null,"atb":[[7.5999999999999996,57.909999999999997]],"spl":null,"spn":null,"atl":null,"batl":null,"id":16570658,"hc":null,"bdatb":null},{"tv":1881471.29,"batb":null,"spb":null,"bdatl":null,"trd":[[1.1100000000000001,2101.5999999999999]],"spf":null,"ltp":1.1100000000000001,"atb":[[1.1000000000000001,45163],[1.1100000000000001,51712.230000000003]],"spl":null,"spn":null,"atl":[[1.1499999999999999,10563.959999999999],[1.1200000000000001,6082.8100000000004]],"batl":null,"id":19924823,"hc":null,"bdatb":null}],"img":null,"tv":2122991.29,"con":null,"marketdefinition":null,"id":"1.258926623"}],"conflatems":null,"op":"mcm","id":3}
{"ct":null,"SegmentType":null,"clk":"AK4\u002BAO5CAPRA","heartbeatms":null,"pt":1780839639302,"initialclk":null,"mc":[{"rc":[{"tv":null,"batb":null,"spb":null,"bdatl":null,"trd":null,"spf":null,"ltp":null,"atb":[[7.5999999999999996,81.069999999999993]],"spl":null,"spn":null,"atl":null,"batl":null,"id":16570658,"hc":null,"bdatb":null},{"tv":null,"batb":null,"spb":null,"bdatl":null,"trd":null,"spf":null,"ltp":null,"atb":null,"spl":null,"spn":null,"atl":[[1.1499999999999999,10717]],"batl":null,"id":19924823,"hc":null,"bdatb":null}],"img":null,"tv":null,"con":null,"marketdefinition":null,"id":"1.258926623"}],"conflatems":null,"op":"mcm","id":3}
{"ct":null,"SegmentType":null,"clk":"ALc\u002BAPBCAP5A","heartbeatms":null,"pt":1780839639396,"initialclk":null,"mc":[{"rc":[{"tv":null,"batb":null,"spb":null,"bdatl":null,"trd":null,"spf":null,"ltp":null,"atb":[[7.5999999999999996,115.81]],"spl":null,"spn":null,"atl":null,"batl":null,"id":16570658,"hc":null,"bdatb":null},{"tv":null,"batb":null,"spb":null,"bdatl":null,"trd":null,"spf":null,"ltp":null,"atb":null,"spl":null,"spn":null,"atl":[[1.1299999999999999,23442.400000000001],[1.1499999999999999,10946.56],[1.1200000000000001,14941.75]],"batl":null,"id":19924823,"hc":null,"bdatb":null}],"img":null,"tv":null,"con":null,"marketdefinition":null,"id":"1.258926623"}],"conflatems":null,"op":"mcm","id":3}
{"ct":null,"SegmentType":null,"clk":"AME\u002BAPlCAIlB","heartbeatms":null,"pt":1780839639502,"initialclk":null,"mc":[{"rc":[{"tv":null,"batb":null,"spb":null,"bdatl":null,"trd":null,"spf":null,"ltp":null,"atb":[[8.4000000000000004,1.8600000000000001],[7.5999999999999996,138.97]],"spl":null,"spn":null,"atl":null,"batl":null,"id":16570658,"hc":null,"bdatb":null},{"tv":null,"batb":null,"spb":null,"bdatl":null,"trd":null,"spf":null,"ltp":null,"atb":null,"spl":null,"spn":null,"atl":[[1.1299999999999999,16853.09],[1.1399999999999999,20935.669999999998],[1.1499999999999999,11099.6]],"batl":null,"id":19924823,"hc":null,"bdatb":null}],"img":null,"tv":null,"con":null,"marketdefinition":null,"id":"1.258926623"}],"conflatems":null,"op":"mcm","id":3}
{"ct":null,"SegmentType":null,"clk":"AM8\u002BAIVDAJVB","heartbeatms":null,"pt":1780839639609,"initialclk":null,"mc":[{"rc":[{"tv":null,"batb":null,"spb":null,"bdatl":null,"trd":null,"spf":null,"ltp":null,"atb":[[7.5999999999999996,150.55000000000001],[8.1999999999999993,74.099999999999994],[9.1999999999999993,45.939999999999998]],"spl":null,"spn":null,"atl":null,"batl":null,"id":16570658,"hc":null,"bdatb":null},{"tv":null,"batb":null,"spb":null,"bdatl":null,"trd":null,"spf":null,"ltp":null,"atb":null,"spl":null,"spn":null,"atl":[[1.1399999999999999,21012.860000000001],[1.1499999999999999,11176.120000000001]],"batl":null,"id":19924823,"hc":null,"bdatb":null}],"img":null,"tv":null,"con":null,"marketdefinition":null,"id":"1.258926623"}],"conflatems":null,"op":"mcm","id":3}
{"ct":null,"SegmentType":null,"clk":"AOA\u002BAI9DAKlB","heartbeatms":null,"pt":1780839639782,"initialclk":null,"mc":[{"rc":[{"tv":1881473.45,"batb":null,"spb":null,"bdatl":null,"trd":[[1.1200000000000001,22711.509999999998]],"spf":null,"ltp":1.1200000000000001,"atb":[[1.1000000000000001,44163]],"spl":null,"spn":null,"atl":[[1.1200000000000001,14940.67]],"batl":null,"id":19924823,"hc":null,"bdatb":null}],"img":null,"tv":2122993.4500000002,"con":null,"marketdefinition":null,"id":"1.258926623"}],"conflatems":null,"op":"mcm","id":3}
{"ct":null,"SegmentType":null,"clk":"AOk\u002BAJlDALhB","heartbeatms":null,"pt":1780839639888,"initialclk":null,"mc":[{"rc":[{"tv":null,"batb":null,"spb":null,"bdatl":null,"trd":null,"spf":null,"ltp":null,"atb":null,"spl":null,"spn":null,"atl":[[1.1399999999999999,21262.860000000001]],"batl":null,"id":19924823,"hc":null,"bdatb":null}],"img":null,"tv":null,"con":null,"marketdefinition":null,"id":"1.258926623"}],"conflatems":null,"op":"mcm","id":3}
{"ct":null,"SegmentType":null,"clk":"APE\u002BAKFDAMZB","heartbeatms":null,"pt":1780839639980,"initialclk":null,"mc":[{"rc":[{"tv":null,"batb":null,"spb":null,"bdatl":null,"trd":null,"spf":null,"ltp":null,"atb":[[9,489.50999999999999]],"spl":null,"spn":null,"atl":null,"batl":null,"id":16570658,"hc":null,"bdatb":null},{"tv":1881890.1000000001,"batb":null,"spb":null,"bdatl":null,"trd":[[1.1100000000000001,2518.25]],"spf":null,"ltp":1.1100000000000001,"atb":[[1.1100000000000001,51503.900000000001]],"spl":null,"spn":null,"atl":null,"batl":null,"id":19924823,"hc":null,"bdatb":null}],"img":null,"tv":2123410.1000000001,"con":null,"marketdefinition":null,"id":"1.258926623"}],"conflatems":null,"op":"mcm","id":3}
{"ct":null,"SegmentType":null,"clk":"AKc/AOFDAJJC","heartbeatms":null,"pt":1780839640602,"initialclk":null,"mc":[{"rc":[{"tv":null,"batb":null,"spb":null,"bdatl":null,"trd":null,"spf":null,"ltp":null,"atb":[[1.1000000000000001,45526.629999999997]],"spl":null,"spn":null,"atl":null,"batl":null,"id":19924823,"hc":null,"bdatb":null}],"img":null,"tv":null,"con":null,"marketdefinition":null,"id":"1.258926623"}],"conflatems":null,"op":"mcm","id":3}
{"ct":null,"SegmentType":null,"clk":"ALc/APFDAKVC","heartbeatms":null,"pt":1780839640809,"initialclk":null,"mc":[{"rc":[{"tv":1881890.6499999999,"batb":null,"spb":null,"bdatl":null,"trd":[[1.1200000000000001,22712.060000000001]],"spf":null,"ltp":1.1200000000000001,"atb":null,"spl":null,"spn":null,"atl":[[1.1200000000000001,14940.389999999999]],"batl":null,"id":19924823,"hc":null,"bdatb":null}],"img":null,"tv":2123410.6499999999,"con":null,"marketdefinition":null,"id":"1.258926623"}],"conflatems":null,"op":"mcm","id":3}
{"ct":null,"SegmentType":null,"clk":"Amc/AidEALZC","heartbeatms":null,"pt":1780839641000,"initialclk":null,"mc":[{"rc":[{"tv":1881910.6499999999,"batb":null,"spb":null,"bdatl":null,"trd":[[1.1200000000000001,22732.060000000001]],"spf":null,"ltp":null,"atb":null,"spl":null,"spn":null,"atl":[[1.1200000000000001,14930.389999999999]],"batl":null,"id":19924823,"hc":null,"bdatb":null}],"img":null,"tv":2123430.6499999999,"con":null,"marketdefinition":null,"id":"1.258926623"}],"conflatems":null,"op":"mcm","id":3}
{"ct":null,"SegmentType":null,"clk":"ANk/AJ9EAMpC","heartbeatms":null,"pt":1780839641187,"initialclk":null,"mc":[{"rc":[{"tv":null,"batb":null,"spb":null,"bdatl":null,"trd":null,"spf":null,"ltp":null,"atb":[[1.03,88932.990000000005]],"spl":null,"spn":null,"atl":[[1.1299999999999999,16524.52]],"batl":null,"id":19924823,"hc":null,"bdatb":null}],"img":null,"tv":null,"con":null,"marketdefinition":null,"id":"1.258926623"}],"conflatems":null,"op":"mcm","id":3}
{"ct":null,"SegmentType":null,"clk":"AJpAANxEAJhD","heartbeatms":null,"pt":1780839641899,"initialclk":null,"mc":[{"rc":[{"tv":null,"batb":null,"spb":null,"bdatl":null,"trd":null,"spf":null,"ltp":null,"atb":[[1.1100000000000001,49764.980000000003]],"spl":null,"spn":null,"atl":null,"batl":null,"id":19924823,"hc":null,"bdatb":null}],"img":null,"tv":null,"con":null,"marketdefinition":null,"id":"1.258926623"}],"conflatems":null,"op":"mcm","id":3}
{"ct":null,"SegmentType":null,"clk":"AKtAAO1EALJD","heartbeatms":null,"pt":1780839642104,"initialclk":null,"mc":[{"rc":[{"tv":1881939.53,"batb":null,"spb":null,"bdatl":null,"trd":[[1.1200000000000001,22760.939999999999]],"spf":null,"ltp":null,"atb":null,"spl":null,"spn":null,"atl":[[1.1200000000000001,14915.950000000001]],"batl":null,"id":19924823,"hc":null,"bdatb":null}],"img":null,"tv":2123459.5299999998,"con":null,"marketdefinition":null,"id":"1.258926623"}],"conflatems":null,"op":"mcm","id":3}
{"ct":null,"SegmentType":null,"clk":"AMpAAIxFAN1D","heartbeatms":null,"pt":1780839642488,"initialclk":null,"mc":[{"rc":[{"tv":1881954.03,"batb":null,"spb":null,"bdatl":null,"trd":[[1.1200000000000001,22775.439999999999]],"spf":null,"ltp":null,"atb":null,"spl":null,"spn":null,"atl":[[1.1200000000000001,14908.700000000001]],"batl":null,"id":19924823,"hc":null,"bdatb":null}],"img":null,"tv":2123474.0299999998,"con":null,"marketdefinition":null,"id":"1.258926623"}],"conflatems":null,"op":"mcm","id":3}
{"ct":null,"SegmentType":null,"clk":"ANlAAJhFAOdD","heartbeatms":null,"pt":1780839642586,"initialclk":null,"mc":[{"rc":[{"tv":null,"batb":null,"spb":null,"bdatl":null,"trd":null,"spf":null,"ltp":null,"atb":[[8.1999999999999993,256.17000000000002]],"spl":null,"spn":null,"atl":[[11,163.19]],"batl":null,"id":16570658,"hc":null,"bdatb":null},{"tv":null,"batb":null,"spb":null,"bdatl":null,"trd":null,"spf":null,"ltp":null,"atb":null,"spl":null,"spn":null,"atl":[[1.1399999999999999,22572.529999999999]],"batl":null,"id":19924823,"hc":null,"bdatb":null}],"img":null,"tv":null,"con":null,"marketdefinition":null,"id":"1.258926623"}],"conflatems":null,"op":"mcm","id":3}
{"ct":null,"SegmentType":null,"clk":"ALtBAPJFANlE","heartbeatms":null,"pt":1780839643610,"initialclk":null,"mc":[{"rc":[{"tv":null,"batb":null,"spb":null,"bdatl":null,"trd":null,"spf":null,"ltp":null,"atb":[[1.1000000000000001,47042.07],[1.0900000000000001,56820.120000000003]],"spl":null,"spn":null,"atl":[[1.1299999999999999,16603.130000000001],[1.1200000000000001,16673.990000000002]],"batl":null,"id":19924823,"hc":null,"bdatb":null}],"img":null,"tv":null,"con":null,"marketdefinition":null,"id":"1.258926623"}],"conflatems":null,"op":"mcm","id":3}
{"ct":null,"SegmentType":null,"clk":"AMRBAIZGAOxE","heartbeatms":null,"pt":1780839643770,"initialclk":null,"mc":[{"rc":[{"tv":1881954.3600000001,"batb":null,"spb":null,"bdatl":null,"trd":[[1.1200000000000001,22775.77]],"spf":null,"ltp":null,"atb":null,"spl":null,"spn":null,"atl":[[1.1200000000000001,16673.830000000002]],"batl":null,"id":19924823,"hc":null,"bdatb":null}],"img":null,"tv":2123474.3599999999,"con":null,"marketdefinition":null,"id":"1.258926623"}],"conflatems":null,"op":"mcm","id":3}
{"ct":null,"SegmentType":null,"clk":"AMxBAJJGAP9E","heartbeatms":null,"pt":1780839643881,"initialclk":null,"mc":[{"rc":[{"tv":null,"batb":null,"spb":null,"bdatl":null,"trd":null,"spf":null,"ltp":null,"atb":[[9.1999999999999993,177.97]],"spl":null,"spn":null,"atl":[[9.5999999999999996,88.099999999999994]],"batl":null,"id":16570658,"hc":null,"bdatb":null},{"tv":null,"batb":null,"spb":null,"bdatl":null,"trd":null,"spf":null,"ltp":null,"atb":[[1.1100000000000001,50445.629999999997]],"spl":null,"spn":null,"atl":[[1.1200000000000001,17758.389999999999]],"batl":null,"id":19924823,"hc":null,"bdatb":null}],"img":null,"tv":null,"con":null,"marketdefinition":null,"id":"1.258926623"}],"conflatems":null,"op":"mcm","id":3}
{"ct":null,"SegmentType":null,"clk":"APxBALxGALtF","heartbeatms":null,"pt":1780839644396,"initialclk":null,"mc":[{"rc":[{"tv":null,"batb":null,"spb":null,"bdatl":null,"trd":null,"spf":null,"ltp":null,"atb":[[1.1000000000000001,48286.779999999999]],"spl":null,"spn":null,"atl":null,"batl":null,"id":19924823,"hc":null,"bdatb":null}],"img":null,"tv":null,"con":null,"marketdefinition":null,"id":"1.258926623"}],"conflatems":null,"op":"mcm","id":3}
{"ct":null,"SegmentType":null,"clk":"AI1CAM1GAMxF","heartbeatms":null,"pt":1780839644594,"initialclk":null,"mc":[{"rc":[{"tv":null,"batb":null,"spb":null,"bdatl":null,"trd":null,"spf":null,"ltp":null,"atb":[[1.1000000000000001,49531.489999999998]],"spl":null,"spn":null,"atl":null,"batl":null,"id":19924823,"hc":null,"bdatb":null}],"img":null,"tv":null,"con":null,"marketdefinition":null,"id":"1.258926623"}],"conflatems":null,"op":"mcm","id":3}
{"ct":null,"SegmentType":null,"clk":"AJVCANRGANxF","heartbeatms":null,"pt":1780839644693,"initialclk":null,"mc":[{"rc":[{"tv":null,"batb":null,"spb":null,"bdatl":null,"trd":null,"spf":null,"ltp":null,"atb":[[1.1000000000000001,50776.199999999997]],"spl":null,"spn":null,"atl":null,"batl":null,"id":19924823,"hc":null,"bdatb":null}],"img":null,"tv":null,"con":null,"marketdefinition":null,"id":"1.258926623"}],"conflatems":null,"op":"mcm","id":3}
{"ct":null,"SegmentType":null,"clk":"ALZCAPlGAIxG","heartbeatms":null,"pt":1780839645110,"initialclk":null,"mc":[{"rc":[{"tv":null,"batb":null,"spb":null,"bdatl":null,"trd":null,"spf":null,"ltp":null,"atb":[[4.4000000000000004,8.6400000000000006],[5.2000000000000002,0],[7.5999999999999996,11.59],[7.4000000000000004,207.31],[8.1999999999999993,191.78999999999999],[5,39.700000000000003]],"spl":null,"spn":null,"atl":null,"batl":null,"id":16570658,"hc":null,"bdatb":null},{"tv":null,"batb":null,"spb":null,"bdatl":null,"trd":null,"spf":null,"ltp":null,"atb":null,"spl":null,"spn":null,"atl":[[1.23,686.72000000000003]],"batl":null,"id":19924823,"hc":null,"bdatb":null}],"img":null,"tv":null,"con":null,"marketdefinition":null,"id":"1.258926623"}],"conflatems":null,"op":"mcm","id":3}
{"ct":null,"SegmentType":null,"clk":"AMdCAIVHAKRG","heartbeatms":null,"pt":1780839645275,"initialclk":null,"mc":[{"rc":[{"tv":241525.20000000001,"batb":null,"spb":null,"bdatl":null,"trd":[[9.4000000000000004,3.8999999999999999],[9.1999999999999993,1531.27]],"spf":null,"ltp":9.1999999999999993,"atb":[[9.4000000000000004,0],[9.1999999999999993,176.31999999999999]],"spl":null,"spn":null,"atl":[[9.4000000000000004,14.5]],"batl":null,"id":16570658,"hc":null,"bdatb":null}],"img":null,"tv":2123479.5600000001,"con":null,"marketdefinition":null,"id":"1.258926623"}],"conflatems":null,"op":"mcm","id":3}
{"ct":null,"SegmentType":null,"clk":"AM5CAIxHAKhG","heartbeatms":null,"pt":1780839645373,"initialclk":null,"mc":[{"rc":[{"tv":null,"batb":null,"spb":null,"bdatl":null,"trd":null,"spf":null,"ltp":null,"atb":[[1.1000000000000001,50456.529999999999]],"spl":null,"spn":null,"atl":null,"batl":null,"id":19924823,"hc":null,"bdatb":null}],"img":null,"tv":null,"con":null,"marketdefinition":null,"id":"1.258926623"}],"conflatems":null,"op":"mcm","id":3}
{"ct":null,"SegmentType":null,"clk":"AOdCAJ9HALZG","heartbeatms":null,"pt":1780839645582,"initialclk":null,"mc":[{"rc":[{"tv":1881958.3600000001,"batb":null,"spb":null,"bdatl":null,"trd":[[1.1200000000000001,22779.77]],"spf":null,"ltp":null,"atb":null,"spl":null,"spn":null,"atl":[[1.1200000000000001,17756.389999999999]],"batl":null,"id":19924823,"hc":null,"bdatb":null}],"img":null,"tv":2123483.5600000001,"con":null,"marketdefinition":null,"id":"1.258926623"}],"conflatems":null,"op":"mcm","id":3}
{"ct":null,"SegmentType":null,"clk":"APpCALJHAM9G","heartbeatms":null,"pt":1780839645787,"initialclk":null,"mc":[{"rc":[{"tv":null,"batb":null,"spb":null,"bdatl":null,"trd":null,"spf":null,"ltp":null,"atb":null,"spl":null,"spn":null,"atl":[[1.24,5.9299999999999997],[1.3,894.33000000000004],[1.1399999999999999,22109.389999999999],[1.25,29.16],[1.1599999999999999,8934.5300000000007],[1.1499999999999999,10257.879999999999]],"batl":null,"id":19924823,"hc":null,"bdatb":null}],"img":null,"tv":null,"con":null,"marketdefinition":null,"id":"1.258926623"}],"conflatems":null,"op":"mcm","id":3}
{"ct":null,"SegmentType":null,"clk":"AI5DAMVHAONG","heartbeatms":null,"pt":1780839645987,"initialclk":null,"mc":[{"rc":[{"tv":null,"batb":null,"spb":null,"bdatl":null,"trd":null,"spf":null,"ltp":null,"atb":[[1.1000000000000001,51701.239999999998]],"spl":null,"spn":null,"atl":null,"batl":null,"id":19924823,"hc":null,"bdatb":null}],"img":null,"tv":null,"con":null,"marketdefinition":null,"id":"1.258926623"}],"conflatems":null,"op":"mcm","id":3}
{"ct":null,"SegmentType":null,"clk":"ALxDAPRHAJlH","heartbeatms":null,"pt":1780839646505,"initialclk":null,"mc":[{"rc":[{"tv":1881970.3600000001,"batb":null,"spb":null,"bdatl":null,"trd":[[1.1200000000000001,22791.77]],"spf":null,"ltp":null,"atb":null,"spl":null,"spn":null,"atl":[[1.1200000000000001,17750.389999999999]],"batl":null,"id":19924823,"hc":null,"bdatb":null}],"img":null,"tv":2123495.5600000001,"con":null,"marketdefinition":null,"id":"1.258926623"}],"conflatems":null,"op":"mcm","id":3}
{"ct":null,"SegmentType":null,"clk":"AIxEALBIAOJH","heartbeatms":null,"pt":1780839647292,"initialclk":null,"mc":[{"rc":[{"tv":null,"batb":null,"spb":null,"bdatl":null,"trd":null,"spf":null,"ltp":null,"atb":[[8.4000000000000004,1],[8.1999999999999993,9.7200000000000006]],"spl":null,"spn":null,"atl":[[11,25.960000000000001]],"batl":null,"id":16570658,"hc":null,"bdatb":null},{"tv":null,"batb":null,"spb":null,"bdatl":null,"trd":null,"spf":null,"ltp":null,"atb":[[1.1000000000000001,50332.550000000003]],"spl":null,"spn":null,"atl":[[1.1399999999999999,20795.419999999998],[1.1200000000000001,8891.4500000000007]],"batl":null,"id":19924823,"hc":null,"bdatb":null}],"img":null,"tv":null,"con":null,"marketdefinition":null,"id":"1.258926623"}],"conflatems":null,"op":"mcm","id":3}
{"ct":null,"SegmentType":null,"clk":"AJNEALhIAOZH","heartbeatms":null,"pt":1780839647390,"initialclk":null,"mc":[{"rc":[{"tv":1882021.0800000001,"batb":null,"spb":null,"bdatl":null,"trd":[[1.1200000000000001,22842.490000000002]],"spf":null,"ltp":null,"atb":null,"spl":null,"spn":null,"atl":[[1.1200000000000001,8866.0900000000001]],"batl":null,"id":19924823,"hc":null,"bdatb":null}],"img":null,"tv":2123546.2799999998,"con":null,"marketdefinition":null,"id":"1.258926623"}],"conflatems":null,"op":"mcm","id":3}
{"ct":null,"SegmentType":null,"clk":"AJdEAMFIAO9H","heartbeatms":null,"pt":1780839647497,"initialclk":null,"mc":[{"rc":[{"tv":null,"batb":null,"spb":null,"bdatl":null,"trd":null,"spf":null,"ltp":null,"atb":[[9.1999999999999993,44.289999999999999]],"spl":null,"spn":null,"atl":[[9.5999999999999996,1]],"batl":null,"id":16570658,"hc":null,"bdatb":null},{"tv":null,"batb":null,"spb":null,"bdatl":null,"trd":null,"spf":null,"ltp":null,"atb":[[1.1100000000000001,49764.980000000003]],"spl":null,"spn":null,"atl":[[1.1200000000000001,7781.5299999999997]],"batl":null,"id":19924823,"hc":null,"bdatb":null}],"img":null,"tv":null,"con":null,"marketdefinition":null,"id":"1.258926623"}],"conflatems":null,"op":"mcm","id":3}
{"ct":null,"SegmentType":null,"clk":"AOBEAO5IAKhI","heartbeatms":null,"pt":1780839648113,"initialclk":null,"mc":[{"rc":[{"tv":1882098.1899999999,"batb":null,"spb":null,"bdatl":null,"trd":[[1.1100000000000001,2595.3600000000001]],"spf":null,"ltp":1.1100000000000001,"atb":[[1.0900000000000001,58490.949999999997],[1.1100000000000001,49726.43]],"spl":null,"spn":null,"atl":[[1.1299999999999999,17568.779999999999]],"batl":null,"id":19924823,"hc":null,"bdatb":null}],"img":null,"tv":2123623.3900000001,"con":null,"marketdefinition":null,"id":"1.258926623"}],"conflatems":null,"op":"mcm","id":3}
{"ct":null,"SegmentType":null,"clk":"AOhEAPdIALJI","heartbeatms":null,"pt":1780839648215,"initialclk":null,"mc":[{"rc":[{"tv":null,"batb":null,"spb":null,"bdatl":null,"trd":null,"spf":null,"ltp":null,"atb":[[1.1000000000000001,48676.910000000003]],"spl":null,"spn":null,"atl":[[1.1200000000000001,6479.4300000000003]],"batl":null,"id":19924823,"hc":null,"bdatb":null}],"img":null,"tv":null,"con":null,"marketdefinition":null,"id":"1.258926623"}],"conflatems":null,"op":"mcm","id":3}
{"ct":null,"SegmentType":null,"clk":"APxEAIlJAMVI","heartbeatms":null,"pt":1780839648385,"initialclk":null,"mc":[{"rc":[{"tv":241554.20000000001,"batb":null,"spb":null,"bdatl":null,"trd":[[9.4000000000000004,32.899999999999999]],"spf":null,"ltp":9.4000000000000004,"atb":[[9.4000000000000004,126.34999999999999]],"spl":null,"spn":null,"atl":[[9.4000000000000004,0]],"batl":null,"id":16570658,"hc":null,"bdatb":null}],"img":null,"tv":2123652.3900000001,"con":null,"marketdefinition":null,"id":"1.258926623"}],"conflatems":null,"op":"mcm","id":3}
{"ct":null,"SegmentType":null,"clk":"AJBFAJ1JANRI","heartbeatms":null,"pt":1780839648583,"initialclk":null,"mc":[{"rc":[{"tv":null,"batb":null,"spb":null,"bdatl":null,"trd":null,"spf":null,"ltp":null,"atb":[[9.4000000000000004,0]],"spl":null,"spn":null,"atl":null,"batl":null,"id":16570658,"hc":null,"bdatb":null}],"img":null,"tv":null,"con":null,"marketdefinition":null,"id":"1.258926623"}],"conflatems":null,"op":"mcm","id":3}
{"ct":null,"SegmentType":null,"clk":"AJ1FAKNJAN9I","heartbeatms":null,"pt":1780839648691,"initialclk":null,"mc":[{"rc":[{"tv":1882223.1000000001,"batb":null,"spb":null,"bdatl":null,"trd":[[1.1200000000000001,22967.400000000001]],"spf":null,"ltp":1.1200000000000001,"atb":null,"spl":null,"spn":null,"atl":[[1.1200000000000001,6416.9700000000003]],"batl":null,"id":19924823,"hc":null,"bdatb":null}],"img":null,"tv":2123777.2999999998,"con":null,"marketdefinition":null,"id":"1.258926623"}],"conflatems":null,"op":"mcm","id":3}
{"ct":null,"SegmentType":null,"clk":"AKZFAK1JAOlI","heartbeatms":null,"pt":1780839648790,"initialclk":null,"mc":[{"rc":[{"tv":null,"batb":null,"spb":null,"bdatl":null,"trd":null,"spf":null,"ltp":null,"atb":[[9.4000000000000004,0.94999999999999996]],"spl":null,"spn":null,"atl":null,"batl":null,"id":16570658,"hc":null,"bdatb":null}],"img":null,"tv":null,"con":null,"marketdefinition":null,"id":"1.258926623"}],"conflatems":null,"op":"mcm","id":3}
{"ct":null,"SegmentType":null,"clk":"ALxFAMNJAIlJ","heartbeatms":null,"pt":1780839649099,"initialclk":null,"mc":[{"rc":[{"tv":null,"batb":null,"spb":null,"bdatl":null,"trd":null,"spf":null,"ltp":null,"atb":[[1.0700000000000001,39107.25]],"spl":null,"spn":null,"atl":[[1.1200000000000001,4235.75]],"batl":null,"id":19924823,"hc":null,"bdatb":null}],"img":null,"tv":null,"con":null,"marketdefinition":null,"id":"1.258926623"}],"conflatems":null,"op":"mcm","id":3}
{"ct":null,"SegmentType":null,"clk":"AJBGAJdKAPhJ","heartbeatms":null,"pt":1780839650085,"initialclk":null,"mc":[{"rc":[{"tv":1882281.9199999999,"batb":null,"spb":null,"bdatl":null,"trd":[[1.1200000000000001,23026.220000000001]],"spf":null,"ltp":null,"atb":null,"spl":null,"spn":null,"atl":[[1.1200000000000001,4206.3400000000001]],"batl":null,"id":19924823,"hc":null,"bdatb":null}],"img":null,"tv":2123836.1200000001,"con":null,"marketdefinition":null,"id":"1.258926623"}],"conflatems":null,"op":"mcm","id":3}
{"ct":null,"SegmentType":null,"clk":"AMJGAMBKAK1K","heartbeatms":null,"pt":1780839650600,"initialclk":null,"mc":[{"rc":[{"tv":null,"batb":null,"spb":null,"bdatl":null,"trd":null,"spf":null,"ltp":null,"atb":null,"spl":null,"spn":null,"atl":[[1000,1.1200000000000001]],"batl":null,"id":19924823,"hc":null,"bdatb":null}],"img":null,"tv":null,"con":null,"marketdefinition":null,"id":"1.258926623"}],"conflatems":null,"op":"mcm","id":3}
{"ct":null,"SegmentType":null,"clk":"AMxGAMhKALVK","heartbeatms":null,"pt":1780839650702,"initialclk":null,"mc":[{"rc":[{"tv":null,"batb":null,"spb":null,"bdatl":null,"trd":null,"spf":null,"ltp":null,"atb":[[1.0900000000000001,58970.449999999997]],"spl":null,"spn":null,"atl":null,"batl":null,"id":19924823,"hc":null,"bdatb":null}],"img":null,"tv":null,"con":null,"marketdefinition":null,"id":"1.258926623"}],"conflatems":null,"op":"mcm","id":3}
{"ct":null,"SegmentType":null,"clk":"ANpGANpKAM5K","heartbeatms":null,"pt":1780839650908,"initialclk":null,"mc":[{"rc":[{"tv":241576.34,"batb":null,"spb":null,"bdatl":null,"trd":[[9.4000000000000004,34.799999999999997],[9.1999999999999993,1551.51]],"spf":null,"ltp":9.1999999999999993,"atb":[[9.4000000000000004,0],[9.1999999999999993,34.170000000000002]],"spl":null,"spn":null,"atl":null,"batl":null,"id":16570658,"hc":null,"bdatb":null}],"img":null,"tv":2123858.2599999998,"con":null,"marketdefinition":null,"id":"1.258926623"}],"conflatems":null,"op":"mcm","id":3}
{"ct":null,"SegmentType":null,"clk":"AOFGAOVKANdK","heartbeatms":null,"pt":1780839651012,"initialclk":null,"mc":[{"rc":[{"tv":null,"batb":null,"spb":null,"bdatl":null,"trd":null,"spf":null,"ltp":null,"atb":null,"spl":null,"spn":null,"atl":[[1.1200000000000001,4720.7600000000002]],"batl":null,"id":19924823,"hc":null,"bdatb":null}],"img":null,"tv":null,"con":null,"marketdefinition":null,"id":"1.258926623"}],"conflatems":null,"op":"mcm","id":3}
{"ct":null,"SegmentType":null,"clk":"AOxGAPFKAN9K","heartbeatms":null,"pt":1780839651083,"initialclk":null,"mc":[{"rc":[{"tv":1882284.26,"batb":null,"spb":null,"bdatl":null,"trd":[[1.1100000000000001,2597.6999999999998]],"spf":null,"ltp":1.1100000000000001,"atb":[[1.1100000000000001,49725.25]],"spl":null,"spn":null,"atl":[[1000,0.88]],"batl":null,"id":19924823,"hc":null,"bdatb":null}],"img":null,"tv":2123860.6000000001,"con":null,"marketdefinition":null,"id":"1.258926623"}],"conflatems":null,"op":"mcm","id":3}
{"ct":null,"SegmentType":null,"clk":"APdGAPpKAONK","heartbeatms":null,"pt":1780839651182,"initialclk":null,"mc":[{"rc":[{"tv":1882296.8000000001,"batb":null,"spb":null,"bdatl":null,"trd":[[1.1200000000000001,23038.759999999998]],"spf":null,"ltp":1.1200000000000001,"atb":null,"spl":null,"spn":null,"atl":[[1.1200000000000001,4714.4899999999998]],"batl":null,"id":19924823,"hc":null,"bdatb":null}],"img":null,"tv":2123873.1400000001,"con":null,"marketdefinition":null,"id":"1.258926623"}],"conflatems":null,"op":"mcm","id":3}
{"ct":null,"SegmentType":null,"clk":"AKdHAKtLAJFL","heartbeatms":null,"pt":1780839651695,"initialclk":null,"mc":[{"rc":[{"tv":1882316.8100000001,"batb":null,"spb":null,"bdatl":null,"trd":[[1.1100000000000001,2617.71]],"spf":null,"ltp":1.1100000000000001,"atb":[[1.1100000000000001,49715.25]],"spl":null,"spn":null,"atl":null,"batl":null,"id":19924823,"hc":null,"bdatb":null}],"img":null,"tv":2123893.1499999999,"con":null,"marketdefinition":null,"id":"1.258926623"}],"conflatems":null,"op":"mcm","id":3}
{"ct":null,"SegmentType":null,"clk":"AptHAPZLAORL","heartbeatms":null,"pt":1780839652493,"initialclk":null,"mc":[{"rc":[{"tv":null,"batb":null,"spb":null,"bdatl":null,"trd":null,"spf":null,"ltp":null,"atb":[[9.4000000000000004,0.94999999999999996]],"spl":null,"spn":null,"atl":null,"batl":null,"id":16570658,"hc":null,"bdatb":null}],"img":null,"tv":null,"con":null,"marketdefinition":null,"id":"1.258926623"}],"conflatems":null,"op":"mcm","id":3}
{"ct":null,"SegmentType":null,"clk":"AJRIAidMAP1L","heartbeatms":null,"pt":1780839652701,"initialclk":null,"mc":[{"rc":[{"tv":1882369.5,"batb":null,"spb":null,"bdatl":null,"trd":[[1.1200000000000001,23091.450000000001]],"spf":null,"ltp":1.1200000000000001,"atb":null,"spl":null,"spn":null,"atl":[[1.1200000000000001,4688.1400000000003]],"batl":null,"id":19924823,"hc":null,"bdatb":null}],"img":null,"tv":2123945.8399999999,"con":null,"marketdefinition":null,"id":"1.258926623"}],"conflatems":null,"op":"mcm","id":3}
{"ct":null,"SegmentType":null,"clk":"ALhIALBMAKdM","heartbeatms":null,"pt":1780839653100,"initialclk":null,"mc":[{"rc":[{"tv":241578.34,"batb":null,"spb":null,"bdatl":null,"trd":[[9.5999999999999996,301.12]],"spf":null,"ltp":9.5999999999999996,"atb":[[9.5999999999999996,1.3500000000000001]],"spl":null,"spn":null,"atl":[[9.5999999999999996,0]],"batl":null,"id":16570658,"hc":null,"bdatb":null}],"img":null,"tv":2123947.8399999999,"con":null,"marketdefinition":null,"id":"1.258926623"}],"conflatems":null,"op":"mcm","id":3}
{"ct":null,"SegmentType":null,"clk":"AK1JAKxNAJBN","heartbeatms":null,"pt":1780839654100,"initialclk":null,"mc":[{"rc":[{"tv":241578.63000000001,"batb":null,"spb":null,"bdatl":null,"trd":[[9.5999999999999996,301.41000000000003]],"spf":null,"ltp":null,"atb":[[9.5999999999999996,1.2]],"spl":null,"spn":null,"atl":null,"batl":null,"id":16570658,"hc":null,"bdatb":null}],"img":null,"tv":2123948.1299999999,"con":null,"marketdefinition":null,"id":"1.258926623"}],"conflatems":null,"op":"mcm","id":3}
{"ct":null,"SegmentType":null,"clk":"ALdJALJNAJRN","heartbeatms":null,"pt":1780839654190,"initialclk":null,"mc":[{"rc":[{"tv":1882369.98,"batb":null,"spb":null,"bdatl":null,"trd":[[1.1100000000000001,2618.1900000000001]],"spf":null,"ltp":1.1100000000000001,"atb":[[1.1100000000000001,49715.010000000002]],"spl":null,"spn":null,"atl":null,"batl":null,"id":19924823,"hc":null,"bdatb":null}],"img":null,"tv":2123948.6099999999,"con":null,"marketdefinition":null,"id":"1.258926623"}],"conflatems":null,"op":"mcm","id":3}
{"ct":null,"SegmentType":null,"clk":"AMdJAMhNAKhN","heartbeatms":null,"pt":1780839654394,"initialclk":null,"mc":[{"rc":[{"tv":null,"batb":null,"spb":null,"bdatl":null,"trd":null,"spf":null,"ltp":null,"atb":null,"spl":null,"spn":null,"atl":[[12.5,106.26000000000001]],"batl":null,"id":16570658,"hc":null,"bdatb":null},{"tv":null,"batb":null,"spb":null,"bdatl":null,"trd":null,"spf":null,"ltp":null,"atb":[[1.0800000000000001,39143.739999999998]],"spl":null,"spn":null,"atl":null,"batl":null,"id":19924823,"hc":null,"bdatb":null}],"img":null,"tv":null,"con":null,"marketdefinition":null,"id":"1.258926623"}],"conflatems":null,"op":"mcm","id":3}
{"ct":null,"SegmentType":null,"clk":"AN5JAONNAMhN","heartbeatms":null,"pt":1780839654712,"initialclk":null,"mc":[{"rc":[{"tv":1911342.03,"batb":null,"spb":null,"bdatl":null,"trd":[[1.1100000000000001,31590.240000000002]],"spf":null,"ltp":null,"atb":[[1.1100000000000001,35228.980000000003]],"spl":null,"spn":null,"atl":null,"batl":null,"id":19924823,"hc":null,"bdatb":null}],"img":null,"tv":2152920.6600000001,"con":null,"marketdefinition":null,"id":"1.258926623"}],"conflatems":null,"op":"mcm","id":3}
{"ct":null,"SegmentType":null,"clk":"AOlJAopNANFN","heartbeatms":null,"pt":1780839654804,"initialclk":null,"mc":[{"rc":[{"tv":241597.48999999999,"batb":null,"spb":null,"bdatl":null,"trd":[[9.4000000000000004,36.700000000000003],[9.1999999999999993,1566.0699999999999],[9.5999999999999996,303.81]],"spf":null,"ltp":9.1999999999999993,"atb":[[9.4000000000000004,0],[9.1999999999999993,26.890000000000001],[9.5999999999999996,0]],"spl":null,"spn":null,"atl":null,"batl":null,"id":16570658,"hc":null,"bdatb":null}],"img":null,"tv":2152939.52,"con":null,"marketdefinition":null,"id":"1.258926623"}],"conflatems":null,"op":"mcm","id":3}
{"ct":null,"SegmentType":null,"clk":"APJJAPVNANtN","heartbeatms":null,"pt":1780839654906,"initialclk":null,"mc":[{"rc":[{"tv":null,"batb":null,"spb":null,"bdatl":null,"trd":null,"spf":null,"ltp":null,"atb":null,"spl":null,"spn":null,"atl":[[12.5,120.34]],"batl":null,"id":16570658,"hc":null,"bdatb":null},{"tv":null,"batb":null,"spb":null,"bdatl":null,"trd":null,"spf":null,"ltp":null,"atb":[[1.0800000000000001,39306.699999999997]],"spl":null,"spn":null,"atl":null,"batl":null,"id":19924823,"hc":null,"bdatb":null}],"img":null,"tv":null,"con":null,"marketdefinition":null,"id":"1.258926623"}],"conflatems":null,"op":"mcm","id":3}
{"ct":null,"SegmentType":null,"clk":"APxJAP5NAopN","heartbeatms":null,"pt":1780839655012,"initialclk":null,"mc":[{"rc":[{"tv":null,"batb":null,"spb":null,"bdatl":null,"trd":null,"spf":null,"ltp":null,"atb":[[7.4000000000000004,0]],"spl":null,"spn":null,"atl":[[12.5,134.41999999999999]],"batl":null,"id":16570658,"hc":null,"bdatb":null},{"tv":null,"batb":null,"spb":null,"bdatl":null,"trd":null,"spf":null,"ltp":null,"atb":[[1.0800000000000001,39469.660000000003]],"spl":null,"spn":null,"atl":null,"batl":null,"id":19924823,"hc":null,"bdatb":null}],"img":null,"tv":null,"con":null,"marketdefinition":null,"id":"1.258926623"}],"conflatems":null,"op":"mcm","id":3}
{"ct":null,"SegmentType":null,"clk":"AIRKAIhOAPNN","heartbeatms":null,"pt":1780839655115,"initialclk":null,"mc":[{"rc":[{"tv":null,"batb":null,"spb":null,"bdatl":null,"trd":null,"spf":null,"ltp":null,"atb":null,"spl":null,"spn":null,"atl":[[12.5,155.53999999999999]],"batl":null,"id":16570658,"hc":null,"bdatb":null},{"tv":null,"batb":null,"spb":null,"bdatl":null,"trd":null,"spf":null,"ltp":null,"atb":[[1.0800000000000001,39714.099999999999]],"spl":null,"spn":null,"atl":null,"batl":null,"id":19924823,"hc":null,"bdatb":null}],"img":null,"tv":null,"con":null,"marketdefinition":null,"id":"1.258926623"}],"conflatems":null,"op":"mcm","id":3}
{"ct":null,"SegmentType":null,"clk":"AI5KAJBOAPxN","heartbeatms":null,"pt":1780839655219,"initialclk":null,"mc":[{"rc":[{"tv":null,"batb":null,"spb":null,"bdatl":null,"trd":null,"spf":null,"ltp":null,"atb":null,"spl":null,"spn":null,"atl":[[12.5,169.62000000000001]],"batl":null,"id":16570658,"hc":null,"bdatb":null},{"tv":null,"batb":null,"spb":null,"bdatl":null,"trd":null,"spf":null,"ltp":null,"atb":[[1.0800000000000001,39877.059999999998]],"spl":null,"spn":null,"atl":null,"batl":null,"id":19924823,"hc":null,"bdatb":null}],"img":null,"tv":null,"con":null,"marketdefinition":null,"id":"1.258926623"}],"conflatems":null,"op":"mcm","id":3}
{"ct":null,"SegmentType":null,"clk":"AJhKAJtOAIZO","heartbeatms":null,"pt":1780839655326,"initialclk":null,"mc":[{"rc":[{"tv":null,"batb":null,"spb":null,"bdatl":null,"trd":null,"spf":null,"ltp":null,"atb":null,"spl":null,"spn":null,"atl":[[12.5,183.69999999999999]],"batl":null,"id":16570658,"hc":null,"bdatb":null},{"tv":null,"batb":null,"spb":null,"bdatl":null,"trd":null,"spf":null,"ltp":null,"atb":[[1.0800000000000001,40040.019999999997]],"spl":null,"spn":null,"atl":null,"batl":null,"id":19924823,"hc":null,"bdatb":null}],"img":null,"tv":null,"con":null,"marketdefinition":null,"id":"1.258926623"}],"conflatems":null,"op":"mcm","id":3}
{"ct":null,"SegmentType":null,"clk":"AJ5KAJ1OAItO","heartbeatms":null,"pt":1780839655387,"initialclk":null,"mc":[{"rc":[{"tv":null,"batb":null,"spb":null,"bdatl":null,"trd":null,"spf":null,"ltp":null,"atb":null,"spl":null,"spn":null,"atl":[[12.5,190.74000000000001]],"batl":null,"id":16570658,"hc":null,"bdatb":null},{"tv":null,"batb":null,"spb":null,"bdatl":null,"trd":null,"spf":null,"ltp":null,"atb":[[1.0800000000000001,40121.5]],"spl":null,"spn":null,"atl":null,"batl":null,"id":19924823,"hc":null,"bdatb":null}],"img":null,"tv":null,"con":null,"marketdefinition":null,"id":"1.258926623"}],"conflatems":null,"op":"mcm","id":3}
{"ct":null,"SegmentType":null,"clk":"AKVKAKZOAJVO","heartbeatms":null,"pt":1780839655494,"initialclk":null,"mc":[{"rc":[{"tv":null,"batb":null,"spb":null,"bdatl":null,"trd":null,"spf":null,"ltp":null,"atb":[[9.4000000000000004,4]],"spl":null,"spn":null,"atl":null,"batl":null,"id":16570658,"hc":null,"bdatb":null}],"img":null,"tv":null,"con":null,"marketdefinition":null,"id":"1.258926623"}],"conflatems":null,"op":"mcm","id":3}
{"ct":null,"SegmentType":null,"clk":"APdKAPZOAPxO","heartbeatms":null,"pt":1780839656515,"initialclk":null,"mc":[{"rc":[{"tv":1911380.6399999999,"batb":null,"spb":null,"bdatl":null,"trd":[[1.1200000000000001,23130.060000000001]],"spf":null,"ltp":1.1200000000000001,"atb":null,"spl":null,"spn":null,"atl":[[1.1200000000000001,4668.8400000000001]],"batl":null,"id":19924823,"hc":null,"bdatb":null}],"img":null,"tv":2152978.1299999999,"con":null,"marketdefinition":null,"id":"1.258926623"}],"conflatems":null,"op":"mcm","id":3}
{"ct":null,"SegmentType":null,"clk":"AP9KAIJPAIZP","heartbeatms":null,"pt":1780839656616,"initialclk":null,"mc":[{"rc":[{"tv":1911388.6399999999,"batb":null,"spb":null,"bdatl":null,"trd":[[1.1200000000000001,23138.060000000001]],"spf":null,"ltp":null,"atb":null,"spl":null,"spn":null,"atl":[[1.1200000000000001,4664.8400000000001]],"batl":null,"id":19924823,"hc":null,"bdatb":null}],"img":null,"tv":2152986.1299999999,"con":null,"marketdefinition":null,"id":"1.258926623"}],"conflatems":null,"op":"mcm","id":3}
{"ct":null,"SegmentType":null,"clk":"AI5LAJJPAJZP","heartbeatms":null,"pt":1780839656819,"initialclk":null,"mc":[{"rc":[{"tv":null,"batb":null,"spb":null,"bdatl":null,"trd":null,"spf":null,"ltp":null,"atb":null,"spl":null,"spn":null,"atl":[[9.8000000000000007,102.04000000000001],[10,0],[9.5999999999999996,164.62000000000001]],"batl":null,"id":16570658,"hc":null,"bdatb":null},{"tv":null,"batb":null,"spb":null,"bdatl":null,"trd":null,"spf":null,"ltp":null,"atb":null,"spl":null,"spn":null,"atl":[[1.1200000000000001,6846.0600000000004]],"batl":null,"id":19924823,"hc":null,"bdatb":null}],"img":null,"tv":null,"con":null,"marketdefinition":null,"id":"1.258926623"}],"conflatems":null,"op":"mcm","id":3}
{"ct":null,"SegmentType":null,"clk":"AJxLAKJPAKNP","heartbeatms":null,"pt":1780839656987,"initialclk":null,"mc":[{"rc":[{"tv":null,"batb":null,"spb":null,"bdatl":null,"trd":null,"spf":null,"ltp":null,"atb":[[9.4000000000000004,0]],"spl":null,"spn":null,"atl":[[9.4000000000000004,3280.0599999999999],[11,26.960000000000001],[10.5,2.1099999999999999]],"batl":null,"id":16570658,"hc":null,"bdatb":null},{"tv":null,"batb":null,"spb":null,"bdatl":null,"trd":null,"spf":null,"ltp":null,"atb":[[1.1000000000000001,49684.419999999998],[1.1100000000000001,35234.529999999999]],"spl":null,"spn":null,"atl":[[1.1299999999999999,17368.779999999999]],"batl":null,"id":19924823,"hc":null,"bdatb":null}],"img":null,"tv":null,"con":null,"marketdefinition":null,"id":"1.258926623"}],"conflatems":null,"op":"mcm","id":3}
{"ct":null,"SegmentType":null,"clk":"AKZLAK5PALFP","heartbeatms":null,"pt":1780839657091,"initialclk":null,"mc":[{"rc":[{"tv":null,"batb":null,"spb":null,"bdatl":null,"trd":null,"spf":null,"ltp":null,"atb":null,"spl":null,"spn":null,"atl":[[13,0],[12.5,189.88],[12,222.83000000000001]],"batl":null,"id":16570658,"hc":null,"bdatb":null},{"tv":null,"batb":null,"spb":null,"bdatl":null,"trd":null,"spf":null,"ltp":null,"atb":[[1.0700000000000001,39099.620000000003],[1.0800000000000001,40989.669999999998],[1.1100000000000001,35940.480000000003]],"spl":null,"spn":null,"atl":[[1.1399999999999999,20451.169999999998]],"batl":null,"id":19924823,"hc":null,"bdatb":null}],"img":null,"tv":null,"con":null,"marketdefinition":null,"id":"1.258926623"}],"conflatems":null,"op":"mcm","id":3}
{"ct":null,"SegmentType":null,"clk":"ALFLAMFPALhP","heartbeatms":null,"pt":1780839657196,"initialclk":null,"mc":[{"rc":[{"tv":null,"batb":null,"spb":null,"bdatl":null,"trd":null,"spf":null,"ltp":null,"atb":[[8.8000000000000007,157.77000000000001],[9.1999999999999993,0],[8.5999999999999996,561]],"spl":null,"spn":null,"atl":[[9.4000000000000004,220.16]],"batl":null,"id":16570658,"hc":null,"bdatb":null},{"tv":null,"batb":null,"spb":null,"bdatl":null,"trd":null,"spf":null,"ltp":null,"atb":[[1.1000000000000001,65059.129999999997]],"spl":null,"spn":null,"atl":[[1.1200000000000001,6427.2799999999997]],"batl":null,"id":19924823,"hc":null,"bdatb":null}],"img":null,"tv":null,"con":null,"marketdefinition":null,"id":"1.258926623"}],"conflatems":null,"op":"mcm","id":3}
{"ct":null,"SegmentType":null,"clk":"ALtLAMtPAMRP","heartbeatms":null,"pt":1780839657301,"initialclk":null,"mc":[{"rc":[{"tv":null,"batb":null,"spb":null,"bdatl":null,"trd":null,"spf":null,"ltp":null,"atb":[[9,25.91]],"spl":null,"spn":null,"atl":null,"batl":null,"id":16570658,"hc":null,"bdatb":null},{"tv":null,"batb":null,"spb":null,"bdatl":null,"trd":null,"spf":null,"ltp":null,"atb":[[1.1100000000000001,35947.980000000003]],"spl":null,"spn":null,"atl":null,"batl":null,"id":19924823,"hc":null,"bdatb":null}],"img":null,"tv":null,"con":null,"marketdefinition":null,"id":"1.258926623"}],"conflatems":null,"op":"mcm","id":3}
{"ct":null,"SegmentType":null,"clk":"AMNLANpPAM9P","heartbeatms":null,"pt":1780839657398,"initialclk":null,"mc":[{"rc":[{"tv":null,"batb":null,"spb":null,"bdatl":null,"trd":null,"spf":null,"ltp":null,"atb":null,"spl":null,"spn":null,"atl":[[12.5,183.80000000000001]],"batl":null,"id":16570658,"hc":null,"bdatb":null},{"tv":null,"batb":null,"spb":null,"bdatl":null,"trd":null,"spf":null,"ltp":null,"atb":[[1.1000000000000001,65725.899999999994],[1.1100000000000001,37573.769999999997]],"spl":null,"spn":null,"atl":[[1.1399999999999999,21337.490000000002]],"batl":null,"id":19924823,"hc":null,"bdatb":null}],"img":null,"tv":null,"con":null,"marketdefinition":null,"id":"1.258926623"}],"conflatems":null,"op":"mcm","id":3}
{"ct":null,"SegmentType":null,"clk":"AMxLAORPANVP","heartbeatms":null,"pt":1780839657503,"initialclk":null,"mc":[{"rc":[{"tv":null,"batb":null,"spb":null,"bdatl":null,"trd":null,"spf":null,"ltp":null,"atb":null,"spl":null,"spn":null,"atl":[[10,7.7699999999999996]],"batl":null,"id":16570658,"hc":null,"bdatb":null},{"tv":null,"batb":null,"spb":null,"bdatl":null,"trd":null,"spf":null,"ltp":null,"atb":[[1.0900000000000001,40109.940000000002],[1.03,88933.740000000005]],"spl":null,"spn":null,"atl":[[1.1299999999999999,17262.73],[1.1200000000000001,5964.0900000000001]],"batl":null,"id":19924823,"hc":null,"bdatb":null}],"img":null,"tv":null,"con":null,"marketdefinition":null,"id":"1.258926623"}],"conflatems":null,"op":"mcm","id":3}
{"ct":null,"SegmentType":null,"clk":"AN5LAPhPAOhP","heartbeatms":null,"pt":1780839657703,"initialclk":null,"mc":[{"rc":[{"tv":1952288.8700000001,"batb":null,"spb":null,"bdatl":null,"trd":[[1.1100000000000001,53398.480000000003],[1.1200000000000001,42230.050000000003]],"spf":null,"ltp":1.1100000000000001,"atb":[[1.1100000000000001,26669.650000000001],[1.1200000000000001,62]],"spl":null,"spn":null,"atl":[[1.1200000000000001,0]],"batl":null,"id":19924823,"hc":null,"bdatb":null}],"img":null,"tv":2193886.3599999999,"con":null,"marketdefinition":null,"id":"1.258926623"}],"conflatems":null,"op":"mcm","id":3}
{"ct":null,"SegmentType":null,"clk":"APBLAIZQAIFQ","heartbeatms":null,"pt":1780839657909,"initialclk":null,"mc":[{"rc":[{"tv":null,"batb":null,"spb":null,"bdatl":null,"trd":null,"spf":null,"ltp":null,"atb":[[8,685.52999999999997]],"spl":null,"spn":null,"atl":[[16.5,90.909999999999997]],"batl":null,"id":16570658,"hc":null,"bdatb":null},{"tv":null,"batb":null,"spb":null,"bdatl":null,"trd":null,"spf":null,"ltp":null,"atb":[[1.0900000000000001,40102.449999999997],[1.1100000000000001,28021]],"spl":null,"spn":null,"atl":[[1.1499999999999999,11529]],"batl":null,"id":19924823,"hc":null,"bdatb":null}],"img":null,"tv":null,"con":null,"marketdefinition":null,"id":"1.258926623"}],"conflatems":null,"op":"mcm","id":3}
{"ct":null,"SegmentType":null,"clk":"AIZMAKFQAKFQ","heartbeatms":null,"pt":1780839658218,"initialclk":null,"mc":[{"rc":[{"tv":null,"batb":null,"spb":null,"bdatl":null,"trd":null,"spf":null,"ltp":null,"atb":[[1.1100000000000001,27315.049999999999]],"spl":null,"spn":null,"atl":null,"batl":null,"id":19924823,"hc":null,"bdatb":null}],"img":null,"tv":null,"con":null,"marketdefinition":null,"id":"1.258926623"}],"conflatems":null,"op":"mcm","id":3}
{"ct":null,"SegmentType":null,"clk":"AI1MAKdQAKxQ","heartbeatms":null,"pt":1780839658318,"initialclk":null,"mc":[{"rc":[{"tv":null,"batb":null,"spb":null,"bdatl":null,"trd":null,"spf":null,"ltp":null,"atb":[[1.0800000000000001,39930.43]],"spl":null,"spn":null,"atl":null,"batl":null,"id":19924823,"hc":null,"bdatb":null}],"img":null,"tv":null,"con":null,"marketdefinition":null,"id":"1.258926623"}],"conflatems":null,"op":"mcm","id":3}
{"ct":null,"SegmentType":null,"clk":"AL5MANdQANNQ","heartbeatms":null,"pt":1780839658699,"initialclk":null,"mc":[{"rc":[{"tv":null,"batb":null,"spb":null,"bdatl":null,"trd":null,"spf":null,"ltp":null,"atb":[[1.1200000000000001,312]],"spl":null,"spn":null,"atl":null,"batl":null,"id":19924823,"hc":null,"bdatb":null}],"img":null,"tv":null,"con":null,"marketdefinition":null,"id":"1.258926623"}],"conflatems":null,"op":"mcm","id":3}
{"ct":null,"SegmentType":null,"clk":"ANhMAO9QAPBQ","heartbeatms":null,"pt":1780839659004,"initialclk":null,"mc":[{"rc":[{"tv":null,"batb":null,"spb":null,"bdatl":null,"trd":null,"spf":null,"ltp":null,"atb":null,"spl":null,"spn":null,"atl":[[12.5,92.280000000000001]],"batl":null,"id":16570658,"hc":null,"bdatb":null}],"img":null,"tv":null,"con":null,"marketdefinition":null,"id":"1.258926623"}],"conflatems":null,"op":"mcm","id":3}
{"ct":null,"SegmentType":null,"clk":"APRMAIRRAI1R","heartbeatms":null,"pt":1780839659307,"initialclk":null,"mc":[{"rc":[{"tv":null,"batb":null,"spb":null,"bdatl":null,"trd":null,"spf":null,"ltp":null,"atb":null,"spl":null,"spn":null,"atl":[[1.1299999999999999,18499.57]],"batl":null,"id":19924823,"hc":null,"bdatb":null}],"img":null,"tv":null,"con":null,"marketdefinition":null,"id":"1.258926623"}],"conflatems":null,"op":"mcm","id":3}
{"ct":null,"SegmentType":null,"clk":"AP5MAIxRAJlR","heartbeatms":null,"pt":1780839659415,"initialclk":null,"mc":[{"rc":[{"tv":null,"batb":null,"spb":null,"bdatl":null,"trd":null,"spf":null,"ltp":null,"atb":[[1.1200000000000001,312.29000000000002]],"spl":null,"spn":null,"atl":null,"batl":null,"id":19924823,"hc":null,"bdatb":null}],"img":null,"tv":null,"con":null,"marketdefinition":null,"id":"1.258926623"}],"conflatems":null,"op":"mcm","id":3}
{"ct":null,"SegmentType":null,"clk":"AKdNALVRANBR","heartbeatms":null,"pt":1780839659883,"initialclk":null,"mc":[{"rc":[{"tv":null,"batb":null,"spb":null,"bdatl":null,"trd":null,"spf":null,"ltp":null,"atb":[[1.1200000000000001,5326.9499999999998]],"spl":null,"spn":null,"atl":null,"batl":null,"id":19924823,"hc":null,"bdatb":null}],"img":null,"tv":null,"con":null,"marketdefinition":null,"id":"1.258926623"}],"conflatems":null,"op":"mcm","id":3}
{"ct":null,"SegmentType":null,"clk":"ALtNAMFRAOlR","heartbeatms":null,"pt":1780839660096,"initialclk":null,"mc":[{"rc":[{"tv":null,"batb":null,"spb":null,"bdatl":null,"trd":null,"spf":null,"ltp":null,"atb":[[8,502.81]],"spl":null,"spn":null,"atl":null,"batl":null,"id":16570658,"hc":null,"bdatb":null}],"img":null,"tv":null,"con":null,"marketdefinition":null,"id":"1.258926623"}],"conflatems":null,"op":"mcm","id":3}
{"ct":null,"SegmentType":null,"clk":"AM5NAMxRAPxR","heartbeatms":null,"pt":1780839660300,"initialclk":null,"mc":[{"rc":[{"tv":1981260.9299999999,"batb":null,"spb":null,"bdatl":null,"trd":[[1.1100000000000001,71716.649999999994],[1.1200000000000001,52883.940000000002]],"spf":null,"ltp":null,"atb":[[1.1100000000000001,18155.959999999999],[1.1200000000000001,0]],"spl":null,"spn":null,"atl":null,"batl":null,"id":19924823,"hc":null,"bdatb":null}],"img":null,"tv":2222858.4199999999,"con":null,"marketdefinition":null,"id":"1.258926623"}],"conflatems":null,"op":"mcm","id":3}
{"ct":null,"SegmentType":null,"clk":"ANlNANVRAIJS","heartbeatms":null,"pt":1780839660407,"initialclk":null,"mc":[{"rc":[{"tv":null,"batb":null,"spb":null,"bdatl":null,"trd":null,"spf":null,"ltp":null,"atb":null,"spl":null,"spn":null,"atl":[[1.1200000000000001,777.39999999999998]],"batl":null,"id":19924823,"hc":null,"bdatb":null}],"img":null,"tv":null,"con":null,"marketdefinition":null,"id":"1.258926623"}],"conflatems":null,"op":"mcm","id":3}
{"ct":null,"SegmentType":null,"clk":"AONNANhRAI1S","heartbeatms":null,"pt":1780839660507,"initialclk":null,"mc":[{"rc":[{"tv":null,"batb":null,"spb":null,"bdatl":null,"trd":null,"spf":null,"ltp":null,"atb":[[1.1100000000000001,19408]],"spl":null,"spn":null,"atl":null,"batl":null,"id":19924823,"hc":null,"bdatb":null}],"img":null,"tv":null,"con":null,"marketdefinition":null,"id":"1.258926623"}],"conflatems":null,"op":"mcm","id":3}
{"ct":null,"SegmentType":null,"clk":"APlNAOZRAKhS","heartbeatms":null,"pt":1780839660712,"initialclk":null,"mc":[{"rc":[{"tv":241768.51000000001,"batb":null,"spb":null,"bdatl":null,"trd":[[9.4000000000000004,207.72]],"spf":null,"ltp":9.4000000000000004,"atb":null,"spl":null,"spn":null,"atl":[[9.4000000000000004,134.65000000000001]],"batl":null,"id":16570658,"hc":null,"bdatb":null}],"img":null,"tv":2223029.4399999999,"con":null,"marketdefinition":null,"id":"1.258926623"}],"conflatems":null,"op":"mcm","id":3}
{"ct":null,"SegmentType":null,"clk":"AIROAO5RALNS","heartbeatms":null,"pt":1780839660810,"initialclk":null,"mc":[{"rc":[{"tv":null,"batb":null,"spb":null,"bdatl":null,"trd":null,"spf":null,"ltp":null,"atb":null,"spl":null,"spn":null,"atl":[[1.1200000000000001,1207.3399999999999]],"batl":null,"id":19924823,"hc":null,"bdatb":null}],"img":null,"tv":null,"con":null,"marketdefinition":null,"id":"1.258926623"}],"conflatems":null,"op":"mcm","id":3}
{"ct":null,"SegmentType":null,"clk":"AIxOAPdRALtS","heartbeatms":null,"pt":1780839660914,"initialclk":null,"mc":[{"rc":[{"tv":null,"batb":null,"spb":null,"bdatl":null,"trd":null,"spf":null,"ltp":null,"atb":[[9.1999999999999993,133.37000000000001],[9,98.909999999999997],[8,272.76999999999998]],"spl":null,"spn":null,"atl":[[11.5,148.53],[9.5999999999999996,292.43000000000001]],"batl":null,"id":16570658,"hc":null,"bdatb":null},{"tv":null,"batb":null,"spb":null,"bdatl":null,"trd":null,"spf":null,"ltp":null,"atb":[[1.0900000000000001,42247.449999999997],[1.1100000000000001,20201.860000000001],[1.03,88934.009999999995]],"spl":null,"spn":null,"atl":[[1.1299999999999999,21444.41]],"batl":null,"id":19924823,"hc":null,"bdatb":null}],"img":null,"tv":null,"con":null,"marketdefinition":null,"id":"1.258926623"}],"conflatems":null,"op":"mcm","id":3}
{"ct":null,"SegmentType":null,"clk":"AJpOAIBSAMVS","heartbeatms":null,"pt":1780839661023,"initialclk":null,"mc":[{"rc":[{"tv":null,"batb":null,"spb":null,"bdatl":null,"trd":null,"spf":null,"ltp":null,"atb":[[9,328.95999999999998]],"spl":null,"spn":null,"atl":null,"batl":null,"id":16570658,"hc":null,"bdatb":null}],"img":null,"tv":null,"con":null,"marketdefinition":null,"id":"1.258926623"}],"conflatems":null,"op":"mcm","id":3}
{"ct":null,"SegmentType":null,"clk":"AKFOAINSAM5S","heartbeatms":null,"pt":1780839661125,"initialclk":null,"mc":[{"rc":[{"tv":null,"batb":null,"spb":null,"bdatl":null,"trd":null,"spf":null,"ltp":null,"atb":[[1.1100000000000001,18850.509999999998]],"spl":null,"spn":null,"atl":null,"batl":null,"id":19924823,"hc":null,"bdatb":null}],"img":null,"tv":null,"con":null,"marketdefinition":null,"id":"1.258926623"}],"conflatems":null,"op":"mcm","id":3}
{"ct":null,"SegmentType":null,"clk":"ALlOAJJSANtS","heartbeatms":null,"pt":1780839661293,"initialclk":null,"mc":[{"rc":[{"tv":null,"batb":null,"spb":null,"bdatl":null,"trd":null,"spf":null,"ltp":null,"atb":[[1.03,88933.740000000005]],"spl":null,"spn":null,"atl":null,"batl":null,"id":19924823,"hc":null,"bdatb":null}],"img":null,"tv":null,"con":null,"marketdefinition":null,"id":"1.258926623"}],"conflatems":null,"op":"mcm","id":3}
{"ct":null,"SegmentType":null,"clk":"AOhOAMhSAJFT","heartbeatms":null,"pt":1780839661718,"initialclk":null,"mc":[{"rc":[{"tv":null,"batb":null,"spb":null,"bdatl":null,"trd":null,"spf":null,"ltp":null,"atb":[[1.1100000000000001,27709.459999999999]],"spl":null,"spn":null,"atl":null,"batl":null,"id":19924823,"hc":null,"bdatb":null}],"img":null,"tv":null,"con":null,"marketdefinition":null,"id":"1.258926623"}],"conflatems":null,"op":"mcm","id":3}
{"ct":null,"SegmentType":null,"clk":"APFOAM9SAJpT","heartbeatms":null,"pt":1780839661813,"initialclk":null,"mc":[{"rc":[{"tv":null,"batb":null,"spb":null,"bdatl":null,"trd":null,"spf":null,"ltp":null,"atb":[[1.1000000000000001,65733.399999999994]],"spl":null,"spn":null,"atl":[[1.1299999999999999,21446.41],[1.1399999999999999,21344.98]],"batl":null,"id":19924823,"hc":null,"bdatb":null}],"img":null,"tv":null,"con":null,"marketdefinition":null,"id":"1.258926623"}],"conflatems":null,"op":"mcm","id":3}
{"ct":null,"SegmentType":null,"clk":"APhOANtSAKFT","heartbeatms":null,"pt":1780839661904,"initialclk":null,"mc":[{"rc":[{"tv":null,"batb":null,"spb":null,"bdatl":null,"trd":null,"spf":null,"ltp":null,"atb":[[1.1100000000000001,36868.400000000001]],"spl":null,"spn":null,"atl":null,"batl":null,"id":19924823,"hc":null,"bdatb":null}],"img":null,"tv":null,"con":null,"marketdefinition":null,"id":"1.258926623"}],"conflatems":null,"op":"mcm","id":3}
{"ct":null,"SegmentType":null,"clk":"AINPAOZSAKlT","heartbeatms":null,"pt":1780839662010,"initialclk":null,"mc":[{"rc":[{"tv":null,"batb":null,"spb":null,"bdatl":null,"trd":null,"spf":null,"ltp":null,"atb":[[1.1000000000000001,65814.350000000006]],"spl":null,"spn":null,"atl":[[1.1299999999999999,21522.66]],"batl":null,"id":19924823,"hc":null,"bdatb":null}],"img":null,"tv":null,"con":null,"marketdefinition":null,"id":"1.258926623"}],"conflatems":null,"op":"mcm","id":3}
{"ct":null,"SegmentType":null,"clk":"AJFPAPBSALFT","heartbeatms":null,"pt":1780839662115,"initialclk":null,"mc":[{"rc":[{"tv":null,"batb":null,"spb":null,"bdatl":null,"trd":null,"spf":null,"ltp":null,"atb":[[8.8000000000000007,170.59]],"spl":null,"spn":null,"atl":null,"batl":null,"id":16570658,"hc":null,"bdatb":null},{"tv":null,"batb":null,"spb":null,"bdatl":null,"trd":null,"spf":null,"ltp":null,"atb":[[1.1100000000000001,36788.18]],"spl":null,"spn":null,"atl":[[1.1399999999999999,21267.419999999998]],"batl":null,"id":19924823,"hc":null,"bdatb":null}],"img":null,"tv":null,"con":null,"marketdefinition":null,"id":"1.258926623"}],"conflatems":null,"op":"mcm","id":3}
{"ct":null,"SegmentType":null,"clk":"AJlPAPpSALxT","heartbeatms":null,"pt":1780839662212,"initialclk":null,"mc":[{"rc":[{"tv":null,"batb":null,"spb":null,"bdatl":null,"trd":null,"spf":null,"ltp":null,"atb":[[1.1100000000000001,37038.18]],"spl":null,"spn":null,"atl":null,"batl":null,"id":19924823,"hc":null,"bdatb":null}],"img":null,"tv":null,"con":null,"marketdefinition":null,"id":"1.258926623"}],"conflatems":null,"op":"mcm","id":3}
{"ct":null,"SegmentType":null,"clk":"AKNPAIRTAMZT","heartbeatms":null,"pt":1780839662315,"initialclk":null,"mc":[{"rc":[{"tv":null,"batb":null,"spb":null,"bdatl":null,"trd":null,"spf":null,"ltp":null,"atb":[[1.1100000000000001,37110.379999999997]],"spl":null,"spn":null,"atl":[[1.1299999999999999,21535.880000000001]],"batl":null,"id":19924823,"hc":null,"bdatb":null}],"img":null,"tv":null,"con":null,"marketdefinition":null,"id":"1.258926623"}],"conflatems":null,"op":"mcm","id":3}
{"ct":null,"SegmentType":null,"clk":"ALBPAI1TANFT","heartbeatms":null,"pt":1780839662420,"initialclk":null,"mc":[{"rc":[{"tv":null,"batb":null,"spb":null,"bdatl":null,"trd":null,"spf":null,"ltp":null,"atb":[[1.1100000000000001,37360.379999999997]],"spl":null,"spn":null,"atl":null,"batl":null,"id":19924823,"hc":null,"bdatb":null}],"img":null,"tv":null,"con":null,"marketdefinition":null,"id":"1.258926623"}],"conflatems":null,"op":"mcm","id":3}
{"ct":null,"SegmentType":null,"clk":"AL9PAJ9TAOdT","heartbeatms":null,"pt":1780839662586,"initialclk":null,"mc":[{"rc":[{"tv":null,"batb":null,"spb":null,"bdatl":null,"trd":null,"spf":null,"ltp":null,"atb":[[1.1100000000000001,37610.379999999997]],"spl":null,"spn":null,"atl":null,"batl":null,"id":19924823,"hc":null,"bdatb":null}],"img":null,"tv":null,"con":null,"marketdefinition":null,"id":"1.258926623"}],"conflatems":null,"op":"mcm","id":3}
{"ct":null,"SegmentType":null,"clk":"AMxPAKVTAO9T","heartbeatms":null,"pt":1780839662693,"initialclk":null,"mc":[{"rc":[{"tv":null,"batb":null,"spb":null,"bdatl":null,"trd":null,"spf":null,"ltp":null,"atb":[[1.1100000000000001,37910.379999999997]],"spl":null,"spn":null,"atl":null,"batl":null,"id":19924823,"hc":null,"bdatb":null}],"img":null,"tv":null,"con":null,"marketdefinition":null,"id":"1.258926623"}],"conflatems":null,"op":"mcm","id":3}
{"ct":null,"SegmentType":null,"clk":"ANNPAK1TAP5T","heartbeatms":null,"pt":1780839662796,"initialclk":null,"mc":[{"rc":[{"tv":2010232.98,"batb":null,"spb":null,"bdatl":null,"trd":[[1.1100000000000001,100688.7]],"spf":null,"ltp":null,"atb":[[1.1100000000000001,23424.349999999999]],"spl":null,"spn":null,"atl":null,"batl":null,"id":19924823,"hc":null,"bdatb":null}],"img":null,"tv":2252001.4900000002,"con":null,"marketdefinition":null,"id":"1.258926623"}],"conflatems":null,"op":"mcm","id":3}
{"ct":null,"SegmentType":null,"clk":"ANtPALdTAI1U","heartbeatms":null,"pt":1780839662902,"initialclk":null,"mc":[{"rc":[{"tv":null,"batb":null,"spb":null,"bdatl":null,"trd":null,"spf":null,"ltp":null,"atb":[[9.1999999999999993,134.37000000000001]],"spl":null,"spn":null,"atl":null,"batl":null,"id":16570658,"hc":null,"bdatb":null},{"tv":null,"batb":null,"spb":null,"bdatl":null,"trd":null,"spf":null,"ltp":null,"atb":[[1.1100000000000001,23724.349999999999]],"spl":null,"spn":null,"atl":[[1.1299999999999999,24062.529999999999]],"batl":null,"id":19924823,"hc":null,"bdatb":null}],"img":null,"tv":null,"con":null,"marketdefinition":null,"id":"1.258926623"}],"conflatems":null,"op":"mcm","id":3}
{"ct":null,"SegmentType":null,"clk":"APpPAM1TAKhU","heartbeatms":null,"pt":1780839663208,"initialclk":null,"mc":[{"rc":[{"tv":null,"batb":null,"spb":null,"bdatl":null,"trd":null,"spf":null,"ltp":null,"atb":[[1.1100000000000001,24024.349999999999]],"spl":null,"spn":null,"atl":null,"batl":null,"id":19924823,"hc":null,"bdatb":null}],"img":null,"tv":null,"con":null,"marketdefinition":null,"id":"1.258926623"}],"conflatems":null,"op":"mcm","id":3}
{"ct":null,"SegmentType":null,"clk":"AJFQAOVTALxU","heartbeatms":null,"pt":1780839663408,"initialclk":null,"mc":[{"rc":[{"tv":null,"batb":null,"spb":null,"bdatl":null,"trd":null,"spf":null,"ltp":null,"atb":[[1.1100000000000001,24324.349999999999]],"spl":null,"spn":null,"atl":null,"batl":null,"id":19924823,"hc":null,"bdatb":null}],"img":null,"tv":null,"con":null,"marketdefinition":null,"id":"1.258926623"}],"conflatems":null,"op":"mcm","id":3}
{"ct":null,"SegmentType":null,"clk":"AJlQAopTAMJU","heartbeatms":null,"pt":1780839663517,"initialclk":null,"mc":[{"rc":[{"tv":null,"batb":null,"spb":null,"bdatl":null,"trd":null,"spf":null,"ltp":null,"atb":[[1.1100000000000001,24624.349999999999]],"spl":null,"spn":null,"atl":null,"batl":null,"id":19924823,"hc":null,"bdatb":null}],"img":null,"tv":null,"con":null,"marketdefinition":null,"id":"1.258926623"}],"conflatems":null,"op":"mcm","id":3}
{"ct":null,"SegmentType":null,"clk":"ALZQAP1TANdU","heartbeatms":null,"pt":1780839663718,"initialclk":null,"mc":[{"rc":[{"tv":null,"batb":null,"spb":null,"bdatl":null,"trd":null,"spf":null,"ltp":null,"atb":null,"spl":null,"spn":null,"atl":[[1.1200000000000001,10066.290000000001]],"batl":null,"id":19924823,"hc":null,"bdatb":null}],"img":null,"tv":null,"con":null,"marketdefinition":null,"id":"1.258926623"}],"conflatems":null,"op":"mcm","id":3}
{"ct":null,"SegmentType":null,"clk":"AL5QAIVUAN9U","heartbeatms":null,"pt":1780839663821,"initialclk":null,"mc":[{"rc":[{"tv":null,"batb":null,"spb":null,"bdatl":null,"trd":null,"spf":null,"ltp":null,"atb":null,"spl":null,"spn":null,"atl":[[9.8000000000000007,232.16]],"batl":null,"id":16570658,"hc":null,"bdatb":null},{"tv":2010247.4199999999,"batb":null,"spb":null,"bdatl":null,"trd":[[1.1100000000000001,100703.14]],"spf":null,"ltp":null,"atb":[[1.1100000000000001,24617.130000000001]],"spl":null,"spn":null,"atl":[[1.1299999999999999,28953.25],[1.1200000000000001,20063.790000000001]],"batl":null,"id":19924823,"hc":null,"bdatb":null}],"img":null,"tv":2252015.9300000002,"con":null,"marketdefinition":null,"id":"1.258926623"}],"conflatems":null,"op":"mcm","id":3}
{"ct":null,"SegmentType":null,"clk":"AMpQAI9UAOxU","heartbeatms":null,"pt":1780839663928,"initialclk":null,"mc":[{"rc":[{"tv":null,"batb":null,"spb":null,"bdatl":null,"trd":null,"spf":null,"ltp":null,"atb":[[1.1100000000000001,24917.130000000001]],"spl":null,"spn":null,"atl":null,"batl":null,"id":19924823,"hc":null,"bdatb":null}],"img":null,"tv":null,"con":null,"marketdefinition":null,"id":"1.258926623"}],"conflatems":null,"op":"mcm","id":3}
{"ct":null,"SegmentType":null,"clk":"AOZQAKdUAP9U","heartbeatms":null,"pt":1780839664196,"initialclk":null,"mc":[{"rc":[{"tv":null,"batb":null,"spb":null,"bdatl":null,"trd":null,"spf":null,"ltp":null,"atb":[[1.1100000000000001,25217.130000000001]],"spl":null,"spn":null,"atl":null,"batl":null,"id":19924823,"hc":null,"bdatb":null}],"img":null,"tv":null,"con":null,"marketdefinition":null,"id":"1.258926623"}],"conflatems":null,"op":"mcm","id":3}
{"ct":null,"SegmentType":null,"clk":"APpQALlUAJBV","heartbeatms":null,"pt":1780839664400,"initialclk":null,"mc":[{"rc":[{"tv":null,"batb":null,"spb":null,"bdatl":null,"trd":null,"spf":null,"ltp":null,"atb":[[7.7999999999999998,79.609999999999999],[7.5999999999999996,12.59]],"spl":null,"spn":null,"atl":[[12.5,93.269999999999996],[12,223.69],[11,27.82]],"batl":null,"id":16570658,"hc":null,"bdatb":null},{"tv":2010247.98,"batb":null,"spb":null,"bdatl":null,"trd":[[1.1200000000000001,52884.5]],"spf":null,"ltp":1.1200000000000001,"atb":[[1.0800000000000001,39938.209999999999],[1.1000000000000001,65818.850000000006],[1.0900000000000001,42252.419999999998]],"spl":null,"spn":null,"atl":[[1.23,486.72000000000003],[1.1599999999999999,8940.2099999999991],[1.1499999999999999,11534.139999999999],[1.1200000000000001,20063.52]],"batl":null,"id":19924823,"hc":null,"bdatb":null}],"img":null,"tv":2252016.4900000002,"con":null,"marketdefinition":null,"id":"1.258926623"}],"conflatems":null,"op":"mcm","id":3}
{"ct":null,"SegmentType":null,"clk":"AIRRAMVUAJpV","heartbeatms":null,"pt":1780839664505,"initialclk":null,"mc":[{"rc":[{"tv":null,"batb":null,"spb":null,"bdatl":null,"trd":null,"spf":null,"ltp":null,"atb":[[7,11.66],[9,346.45999999999998],[7.2000000000000002,11.289999999999999]],"spl":null,"spn":null,"atl":[[13,5.8300000000000001],[12.5,99.349999999999994]],"batl":null,"id":16570658,"hc":null,"bdatb":null},{"tv":null,"batb":null,"spb":null,"bdatl":null,"trd":null,"spf":null,"ltp":null,"atb":null,"spl":null,"spn":null,"atl":[[1.1299999999999999,29153.25]],"batl":null,"id":19924823,"hc":null,"bdatb":null}],"img":null,"tv":null,"con":null,"marketdefinition":null,"id":"1.258926623"}],"conflatems":null,"op":"mcm","id":3}
{"ct":null,"SegmentType":null,"clk":"AI5RAMpUAKNV","heartbeatms":null,"pt":1780839664610,"initialclk":null,"mc":[{"rc":[{"tv":null,"batb":null,"spb":null,"bdatl":null,"trd":null,"spf":null,"ltp":null,"atb":[[1.1100000000000001,25517.130000000001]],"spl":null,"spn":null,"atl":[[1.1200000000000001,20313.52]],"batl":null,"id":19924823,"hc":null,"bdatb":null}],"img":null,"tv":null,"con":null,"marketdefinition":null,"id":"1.258926623"}],"conflatems":null,"op":"mcm","id":3}
{"ct":null,"SegmentType":null,"clk":"AJpRANBUAKpV","heartbeatms":null,"pt":1780839664701,"initialclk":null,"mc":[{"rc":[{"tv":null,"batb":null,"spb":null,"bdatl":null,"trd":null,"spf":null,"ltp":null,"atb":[[9.1999999999999993,134.40000000000001]],"spl":null,"spn":null,"atl":null,"batl":null,"id":16570658,"hc":null,"bdatb":null}],"img":null,"tv":null,"con":null,"marketdefinition":null,"id":"1.258926623"}],"conflatems":null,"op":"mcm","id":3}
{"ct":null,"SegmentType":null,"clk":"AKRRANlUALZV","heartbeatms":null,"pt":1780839664814,"initialclk":null,"mc":[{"rc":[{"tv":null,"batb":null,"spb":null,"bdatl":null,"trd":null,"spf":null,"ltp":null,"atb":null,"spl":null,"spn":null,"atl":[[12,217.33000000000001],[11.5,141.87000000000001]],"batl":null,"id":16570658,"hc":null,"bdatb":null},{"tv":null,"batb":null,"spb":null,"bdatl":null,"trd":null,"spf":null,"ltp":null,"atb":[[1.03,88932.990000000005]],"spl":null,"spn":null,"atl":null,"batl":null,"id":19924823,"hc":null,"bdatb":null}],"img":null,"tv":null,"con":null,"marketdefinition":null,"id":"1.258926623"}],"conflatems":null,"op":"mcm","id":3}
{"ct":null,"SegmentType":null,"clk":"ALRRAN9UAMBV","heartbeatms":null,"pt":1780839664906,"initialclk":null,"mc":[{"rc":[{"tv":null,"batb":null,"spb":null,"bdatl":null,"trd":null,"spf":null,"ltp":null,"atb":[[6.7999999999999998,24.52]],"spl":null,"spn":null,"atl":null,"batl":null,"id":16570658,"hc":null,"bdatb":null},{"tv":null,"batb":null,"spb":null,"bdatl":null,"trd":null,"spf":null,"ltp":null,"atb":null,"spl":null,"spn":null,"atl":[[1.22,9062.3500000000004],[1.21,9160.3500000000004]],"batl":null,"id":19924823,"hc":null,"bdatb":null}],"img":null,"tv":null,"con":null,"marketdefinition":null,"id":"1.258926623"}],"conflatems":null,"op":"mcm","id":3}
{"ct":null,"SegmentType":null,"clk":"AL1RAOVUAMhV","heartbeatms":null,"pt":1780839665010,"initialclk":null,"mc":[{"rc":[{"tv":null,"batb":null,"spb":null,"bdatl":null,"trd":null,"spf":null,"ltp":null,"atb":[[1.1100000000000001,25817.130000000001]],"spl":null,"spn":null,"atl":null,"batl":null,"id":19924823,"hc":null,"bdatb":null}],"img":null,"tv":null,"con":null,"marketdefinition":null,"id":"1.258926623"}],"conflatems":null,"op":"mcm","id":3}
{"ct":null,"SegmentType":null,"clk":"AMhRAPFUANNV","heartbeatms":null,"pt":1780839665115,"initialclk":null,"mc":[{"rc":[{"tv":null,"batb":null,"spb":null,"bdatl":null,"trd":null,"spf":null,"ltp":null,"atb":[[1.1100000000000001,26117.130000000001]],"spl":null,"spn":null,"atl":null,"batl":null,"id":19924823,"hc":null,"bdatb":null}],"img":null,"tv":null,"con":null,"marketdefinition":null,"id":"1.258926623"}],"conflatems":null,"op":"mcm","id":3}
{"ct":null,"SegmentType":null,"clk":"ANJRAPpUANhV","heartbeatms":null,"pt":1780839665216,"initialclk":null,"mc":[{"rc":[{"tv":null,"batb":null,"spb":null,"bdatl":null,"trd":null,"spf":null,"ltp":null,"atb":[[7.5999999999999996,1.99]],"spl":null,"spn":null,"atl":null,"batl":null,"id":16570658,"hc":null,"bdatb":null},{"tv":null,"batb":null,"spb":null,"bdatl":null,"trd":null,"spf":null,"ltp":null,"atb":null,"spl":null,"spn":null,"atl":[[1.1499999999999999,11334.139999999999]],"batl":null,"id":19924823,"hc":null,"bdatb":null}],"img":null,"tv":null,"con":null,"marketdefinition":null,"id":"1.258926623"}],"conflatems":null,"op":"mcm","id":3}
{"ct":null,"SegmentType":null,"clk":"APVRAJJVAPFV","heartbeatms":null,"pt":1780839665494,"initialclk":null,"mc":[{"rc":[{"tv":2010277.8000000001,"batb":null,"spb":null,"bdatl":null,"trd":[[1.1200000000000001,52914.32]],"spf":null,"ltp":null,"atb":[[1.1100000000000001,26417.130000000001]],"spl":null,"spn":null,"atl":[[1.1200000000000001,20298.610000000001]],"batl":null,"id":19924823,"hc":null,"bdatb":null}],"img":null,"tv":2252046.3100000001,"con":null,"marketdefinition":null,"id":"1.258926623"}],"conflatems":null,"op":"mcm","id":3}
{"ct":null,"SegmentType":null,"clk":"AJdSALFVAJJW","heartbeatms":null,"pt":1780839665900,"initialclk":null,"mc":[{"rc":[{"tv":null,"batb":null,"spb":null,"bdatl":null,"trd":null,"spf":null,"ltp":null,"atb":[[8.1999999999999993,191.96000000000001]],"spl":null,"spn":null,"atl":[[10.5,144.96000000000001]],"batl":null,"id":16570658,"hc":null,"bdatb":null},{"tv":null,"batb":null,"spb":null,"bdatl":null,"trd":null,"spf":null,"ltp":null,"atb":[[1.1000000000000001,67182.479999999996],[1.1100000000000001,26717.130000000001]],"spl":null,"spn":null,"atl":[[1.1399999999999999,22578.349999999999]],"batl":null,"id":19924823,"hc":null,"bdatb":null}],"img":null,"tv":null,"con":null,"marketdefinition":null,"id":"1.258926623"}],"conflatems":null,"op":"mcm","id":3}
{"ct":null,"SegmentType":null,"clk":"AKtSAMFVAKJW","heartbeatms":null,"pt":1780839666112,"initialclk":null,"mc":[{"rc":[{"tv":null,"batb":null,"spb":null,"bdatl":null,"trd":null,"spf":null,"ltp":null,"atb":[[1.1100000000000001,35576.080000000002]],"spl":null,"spn":null,"atl":null,"batl":null,"id":19924823,"hc":null,"bdatb":null}],"img":null,"tv":null,"con":null,"marketdefinition":null,"id":"1.258926623"}],"conflatems":null,"op":"mcm","id":3}
{"ct":null,"SegmentType":null,"clk":"ALZSANFVAKpW","heartbeatms":null,"pt":1780839666211,"initialclk":null,"mc":[{"rc":[{"tv":null,"batb":null,"spb":null,"bdatl":null,"trd":null,"spf":null,"ltp":null,"atb":[[1.1100000000000001,35876.080000000002]],"spl":null,"spn":null,"atl":null,"batl":null,"id":19924823,"hc":null,"bdatb":null}],"img":null,"tv":null,"con":null,"marketdefinition":null,"id":"1.258926623"}],"conflatems":null,"op":"mcm","id":3}
{"ct":null,"SegmentType":null,"clk":"AL1SANZVALBW","heartbeatms":null,"pt":1780839666321,"initialclk":null,"mc":[{"rc":[{"tv":null,"batb":null,"spb":null,"bdatl":null,"trd":null,"spf":null,"ltp":null,"atb":null,"spl":null,"spn":null,"atl":[[16.5,0]],"batl":null,"id":16570658,"hc":null,"bdatb":null},{"tv":2010280.6699999999,"batb":null,"spb":null,"bdatl":null,"trd":[[1.1200000000000001,52917.190000000002]],"spf":null,"ltp":null,"atb":null,"spl":null,"spn":null,"atl":[[1.1499999999999999,10063.02],[1.1200000000000001,20297.169999999998]],"batl":null,"id":19924823,"hc":null,"bdatb":null}],"img":null,"tv":2252049.1800000002,"con":null,"marketdefinition":null,"id":"1.258926623"}],"conflatems":null,"op":"mcm","id":3}
{"ct":null,"SegmentType":null,"clk":"ANxSAPhVAMhW","heartbeatms":null,"pt":1780839666625,"initialclk":null,"mc":[{"rc":[{"tv":null,"batb":null,"spb":null,"bdatl":null,"trd":null,"spf":null,"ltp":null,"atb":[[1.1100000000000001,36176.080000000002]],"spl":null,"spn":null,"atl":null,"batl":null,"id":19924823,"hc":null,"bdatb":null}],"img":null,"tv":null,"con":null,"marketdefinition":null,"id":"1.258926623"}],"conflatems":null,"op":"mcm","id":3}
{"ct":null,"SegmentType":null,"clk":"AO5SAI1WANNW","heartbeatms":null,"pt":1780839666794,"initialclk":null,"mc":[{"rc":[{"tv":242037.81,"batb":null,"spb":null,"bdatl":null,"trd":[[9.4000000000000004,477.01999999999998]],"spf":null,"ltp":null,"atb":[[9.4000000000000004,135.66]],"spl":null,"spn":null,"atl":[[9.4000000000000004,0]],"batl":null,"id":16570658,"hc":null,"bdatb":null}],"img":null,"tv":2252318.48,"con":null,"marketdefinition":null,"id":"1.258926623"}],"conflatems":null,"op":"mcm","id":3}
{"ct":null,"SegmentType":null,"clk":"APlSAJdWAN5W","heartbeatms":null,"pt":1780839666896,"initialclk":null,"mc":[{"rc":[{"tv":null,"batb":null,"spb":null,"bdatl":null,"trd":null,"spf":null,"ltp":null,"atb":null,"spl":null,"spn":null,"atl":[[9.8000000000000007,291.07999999999998],[10,65.239999999999995]],"batl":null,"id":16570658,"hc":null,"bdatb":null}],"img":null,"tv":null,"con":null,"marketdefinition":null,"id":"1.258926623"}],"conflatems":null,"op":"mcm","id":3}
{"ct":null,"SegmentType":null,"clk":"AIVTAKZWAOdW","heartbeatms":null,"pt":1780839667001,"initialclk":null,"mc":[{"rc":[{"tv":null,"batb":null,"spb":null,"bdatl":null,"trd":null,"spf":null,"ltp":null,"atb":[[1.1100000000000001,36476.080000000002]],"spl":null,"spn":null,"atl":null,"batl":null,"id":19924823,"hc":null,"bdatb":null}],"img":null,"tv":null,"con":null,"marketdefinition":null,"id":"1.258926623"}],"conflatems":null,"op":"mcm","id":3}
{"ct":null,"SegmentType":null,"clk":"AJFTALFWAPNW","heartbeatms":null,"pt":1780839667104,"initialclk":null,"mc":[{"rc":[{"tv":null,"batb":null,"spb":null,"bdatl":null,"trd":null,"spf":null,"ltp":null,"atb":[[7.7999999999999998,78.739999999999995],[7.5999999999999996,0.98999999999999999]],"spl":null,"spn":null,"atl":[[11,26.829999999999998],[10.5,144.09999999999999]],"batl":null,"id":16570658,"hc":null,"bdatb":null},{"tv":null,"batb":null,"spb":null,"bdatl":null,"trd":null,"spf":null,"ltp":null,"atb":[[1.1000000000000001,67174.960000000006],[1.1100000000000001,36470.519999999997]],"spl":null,"spn":null,"atl":[[1.1599999999999999,8934.6000000000004],[1.1499999999999999,10057.950000000001]],"batl":null,"id":19924823,"hc":null,"bdatb":null}],"img":null,"tv":null,"con":null,"marketdefinition":null,"id":"1.258926623"}],"conflatems":null,"op":"mcm","id":3}
{"ct":null,"SegmentType":null,"clk":"AMdTAPVWAK1X","heartbeatms":null,"pt":1780839668088,"initialclk":null,"mc":[{"rc":[{"tv":null,"batb":null,"spb":null,"bdatl":null,"trd":null,"spf":null,"ltp":null,"atb":[[8.1999999999999993,182.24000000000001]],"spl":null,"spn":null,"atl":null,"batl":null,"id":16570658,"hc":null,"bdatb":null}],"img":null,"tv":null,"con":null,"marketdefinition":null,"id":"1.258926623"}],"conflatems":null,"op":"mcm","id":3}
{"ct":null,"SegmentType":null,"clk":"ANNTAIVXALVX","heartbeatms":null,"pt":1780839668106,"initialclk":null,"mc":[{"rc":[{"tv":null,"batb":null,"spb":null,"bdatl":null,"trd":null,"spf":null,"ltp":null,"atb":null,"spl":null,"spn":null,"atl":[[1.76,456]],"batl":null,"id":19924823,"hc":null,"bdatb":null}],"img":null,"tv":null,"con":null,"marketdefinition":null,"id":"1.258926623"}],"conflatems":null,"op":"mcm","id":3}
{"ct":null,"SegmentType":null,"clk":"ANdTAidXALpX","heartbeatms":null,"pt":1780839668116,"initialclk":null,"mc":[{"rc":[{"tv":null,"batb":null,"spb":null,"bdatl":null,"trd":null,"spf":null,"ltp":null,"atb":null,"spl":null,"spn":null,"atl":[[13.5,5.5999999999999996]],"batl":null,"id":16570658,"hc":null,"bdatb":null}],"img":null,"tv":null,"con":null,"marketdefinition":null,"id":"1.258926623"}],"conflatems":null,"op":"mcm","id":3}
{"ct":null,"SegmentType":null,"clk":"AOhTAJhXAMJX","heartbeatms":null,"pt":1780839668137,"initialclk":null,"mc":[{"rc":[{"tv":null,"batb":null,"spb":null,"bdatl":null,"trd":null,"spf":null,"ltp":null,"atb":null,"spl":null,"spn":null,"atl":[[1.23,483.77999999999997]],"batl":null,"id":19924823,"hc":null,"bdatb":null}],"img":null,"tv":null,"con":null,"marketdefinition":null,"id":"1.258926623"}],"conflatems":null,"op":"mcm","id":3}
{"ct":null,"SegmentType":null,"clk":"ALFUAMpXAP1X","heartbeatms":null,"pt":1780839668702,"initialclk":null,"mc":[{"rc":[{"tv":null,"batb":null,"spb":null,"bdatl":null,"trd":null,"spf":null,"ltp":null,"atb":[[1.1100000000000001,36463.029999999999]],"spl":null,"spn":null,"atl":[[1.1299999999999999,29145.75],[1.23,683.77999999999997]],"batl":null,"id":19924823,"hc":null,"bdatb":null}],"img":null,"tv":null,"con":null,"marketdefinition":null,"id":"1.258926623"}],"conflatems":null,"op":"mcm","id":3}
{"ct":null,"SegmentType":null,"clk":"APhUAJRYAMtY","heartbeatms":null,"pt":1780839669424,"initialclk":null,"mc":[{"rc":[{"tv":null,"batb":null,"spb":null,"bdatl":null,"trd":null,"spf":null,"ltp":null,"atb":[[6.7999999999999998,0.40000000000000002]],"spl":null,"spn":null,"atl":[[11,28.289999999999999]],"batl":null,"id":16570658,"hc":null,"bdatb":null},{"tv":null,"batb":null,"spb":null,"bdatl":null,"trd":null,"spf":null,"ltp":null,"atb":null,"spl":null,"spn":null,"atl":[[1.22,8862.3500000000004]],"batl":null,"id":19924823,"hc":null,"bdatb":null}],"img":null,"tv":null,"con":null,"marketdefinition":null,"id":"1.258926623"}],"conflatems":null,"op":"mcm","id":3}
{"ct":null,"SegmentType":null,"clk":"AIRVAJ1YANVY","heartbeatms":null,"pt":1780839669524,"initialclk":null,"mc":[{"rc":[{"tv":null,"batb":null,"spb":null,"bdatl":null,"trd":null,"spf":null,"ltp":null,"atb":[[7.4000000000000004,21.859999999999999]],"spl":null,"spn":null,"atl":null,"batl":null,"id":16570658,"hc":null,"bdatb":null}],"img":null,"tv":null,"con":null,"marketdefinition":null,"id":"1.258926623"}],"conflatems":null,"op":"mcm","id":3}
{"ct":null,"SegmentType":null,"clk":"AJ1VALZYAO1Y","heartbeatms":null,"pt":1780839669831,"initialclk":null,"mc":[{"rc":[{"tv":2011144.45,"batb":null,"spb":null,"bdatl":null,"trd":[[1.1200000000000001,53780.970000000001]],"spf":null,"ltp":null,"atb":null,"spl":null,"spn":null,"atl":[[1.1200000000000001,19865.279999999999]],"batl":null,"id":19924823,"hc":null,"bdatb":null}],"img":null,"tv":2253182.2599999998,"con":null,"marketdefinition":null,"id":"1.258926623"}],"conflatems":null,"op":"mcm","id":3}
{"ct":null,"SegmentType":null,"clk":"AMRVAN5YAJRZ","heartbeatms":null,"pt":1780839670207,"initialclk":null,"mc":[{"rc":[{"tv":2012008.23,"batb":null,"spb":null,"bdatl":null,"trd":[[1.1200000000000001,54644.75]],"spf":null,"ltp":null,"atb":null,"spl":null,"spn":null,"atl":[[1.1200000000000001,19433.389999999999]],"batl":null,"id":19924823,"hc":null,"bdatb":null}],"img":null,"tv":2254046.04,"con":null,"marketdefinition":null,"id":"1.258926623"}],"conflatems":null,"op":"mcm","id":3}
{"ct":null,"SegmentType":null,"clk":"ANlVAOxYAKhZ","heartbeatms":null,"pt":1780839670420,"initialclk":null,"mc":[{"rc":[{"tv":null,"batb":null,"spb":null,"bdatl":null,"trd":null,"spf":null,"ltp":null,"atb":[[1.1100000000000001,53738.660000000003]],"spl":null,"spn":null,"atl":null,"batl":null,"id":19924823,"hc":null,"bdatb":null}],"img":null,"tv":null,"con":null,"marketdefinition":null,"id":"1.258926623"}],"conflatems":null,"op":"mcm","id":3}
{"ct":null,"SegmentType":null,"clk":"APdVAIFZAMdZ","heartbeatms":null,"pt":1780839670716,"initialclk":null,"mc":[{"rc":[{"tv":null,"batb":null,"spb":null,"bdatl":null,"trd":null,"spf":null,"ltp":null,"atb":null,"spl":null,"spn":null,"atl":[[1.1200000000000001,19434.790000000001]],"batl":null,"id":19924823,"hc":null,"bdatb":null}],"img":null,"tv":null,"con":null,"marketdefinition":null,"id":"1.258926623"}],"conflatems":null,"op":"mcm","id":3}
{"ct":null,"SegmentType":null,"clk":"AJtWAJpZAOhZ","heartbeatms":null,"pt":1780839671026,"initialclk":null,"mc":[{"rc":[{"tv":null,"batb":null,"spb":null,"bdatl":null,"trd":null,"spf":null,"ltp":null,"atb":null,"spl":null,"spn":null,"atl":[[1.1299999999999999,27908.91]],"batl":null,"id":19924823,"hc":null,"bdatb":null}],"img":null,"tv":null,"con":null,"marketdefinition":null,"id":"1.258926623"}],"conflatems":null,"op":"mcm","id":3}
{"ct":null,"SegmentType":null,"clk":"ALBWAKtZAptZ","heartbeatms":null,"pt":1780839671235,"initialclk":null,"mc":[{"rc":[{"tv":null,"batb":null,"spb":null,"bdatl":null,"trd":null,"spf":null,"ltp":null,"atb":[[1.1100000000000001,53810.849999999999]],"spl":null,"spn":null,"atl":null,"batl":null,"id":19924823,"hc":null,"bdatb":null}],"img":null,"tv":null,"con":null,"marketdefinition":null,"id":"1.258926623"}],"conflatems":null,"op":"mcm","id":3}
{"ct":null,"SegmentType":null,"clk":"ALZWALVZAINa","heartbeatms":null,"pt":1780839671306,"initialclk":null,"mc":[{"rc":[{"tv":null,"batb":null,"spb":null,"bdatl":null,"trd":null,"spf":null,"ltp":null,"atb":[[9.1999999999999993,234.40000000000001]],"spl":null,"spn":null,"atl":null,"batl":null,"id":16570658,"hc":null,"bdatb":null}],"img":null,"tv":null,"con":null,"marketdefinition":null,"id":"1.258926623"}],"conflatems":null,"op":"mcm","id":3}
{"ct":null,"SegmentType":null,"clk":"ANVWANFZAKNa","heartbeatms":null,"pt":1780839671613,"initialclk":null,"mc":[{"rc":[{"tv":null,"batb":null,"spb":null,"bdatl":null,"trd":null,"spf":null,"ltp":null,"atb":[[9.1999999999999993,334.39999999999998]],"spl":null,"spn":null,"atl":null,"batl":null,"id":16570658,"hc":null,"bdatb":null}],"img":null,"tv":null,"con":null,"marketdefinition":null,"id":"1.258926623"}],"conflatems":null,"op":"mcm","id":3}
{"ct":null,"SegmentType":null,"clk":"AO5WAPlZAMta","heartbeatms":null,"pt":1780839671934,"initialclk":null,"mc":[{"rc":[{"tv":null,"batb":null,"spb":null,"bdatl":null,"trd":null,"spf":null,"ltp":null,"atb":null,"spl":null,"spn":null,"atl":[[1.1200000000000001,19107.849999999999]],"batl":null,"id":19924823,"hc":null,"bdatb":null}],"img":null,"tv":null,"con":null,"marketdefinition":null,"id":"1.258926623"}],"conflatems":null,"op":"mcm","id":3}
{"ct":null,"SegmentType":null,"clk":"AptWAJJaANta","heartbeatms":null,"pt":1780839672121,"initialclk":null,"mc":[{"rc":[{"tv":242087.81,"batb":null,"spb":null,"bdatl":null,"trd":[[9.4000000000000004,527.01999999999998]],"spf":null,"ltp":null,"atb":[[9.4000000000000004,110.66],[7.4000000000000004,30.219999999999999]],"spl":null,"spn":null,"atl":null,"batl":null,"id":16570658,"hc":null,"bdatb":null}],"img":null,"tv":2254096.04,"con":null,"marketdefinition":null,"id":"1.258926623"}],"conflatems":null,"op":"mcm","id":3}
{"ct":null,"SegmentType":null,"clk":"AIZXAKFaAONa","heartbeatms":null,"pt":1780839672232,"initialclk":null,"mc":[{"rc":[{"tv":null,"batb":null,"spb":null,"bdatl":null,"trd":null,"spf":null,"ltp":null,"atb":[[1.1100000000000001,52558.809999999998]],"spl":null,"spn":null,"atl":null,"batl":null,"id":19924823,"hc":null,"bdatb":null}],"img":null,"tv":null,"con":null,"marketdefinition":null,"id":"1.258926623"}],"conflatems":null,"op":"mcm","id":3}
{"ct":null,"SegmentType":null,"clk":"AJpXALdaAP5a","heartbeatms":null,"pt":1780839672491,"initialclk":null,"mc":[{"rc":[{"tv":null,"batb":null,"spb":null,"bdatl":null,"trd":null,"spf":null,"ltp":null,"atb":[[9.1999999999999993,334.37]],"spl":null,"spn":null,"atl":null,"batl":null,"id":16570658,"hc":null,"bdatb":null},{"tv":null,"batb":null,"spb":null,"bdatl":null,"trd":null,"spf":null,"ltp":null,"atb":null,"spl":null,"spn":null,"atl":[[1.22,9062.3500000000004]],"batl":null,"id":19924823,"hc":null,"bdatb":null}],"img":null,"tv":null,"con":null,"marketdefinition":null,"id":"1.258926623"}],"conflatems":null,"op":"mcm","id":3}
{"ct":null,"SegmentType":null,"clk":"AMpXAOZaAKlb","heartbeatms":null,"pt":1780839673110,"initialclk":null,"mc":[{"rc":[{"tv":null,"batb":null,"spb":null,"bdatl":null,"trd":null,"spf":null,"ltp":null,"atb":null,"spl":null,"spn":null,"atl":[[1.21,8960.3500000000004]],"batl":null,"id":19924823,"hc":null,"bdatb":null}],"img":null,"tv":null,"con":null,"marketdefinition":null,"id":"1.258926623"}],"conflatems":null,"op":"mcm","id":3}
{"ct":null,"SegmentType":null,"clk":"AP9XAJRbAN9b","heartbeatms":null,"pt":1780839673724,"initialclk":null,"mc":[{"rc":[{"tv":242117.79999999999,"batb":null,"spb":null,"bdatl":null,"trd":[[9.4000000000000004,557.00999999999999]],"spf":null,"ltp":null,"atb":[[9.4000000000000004,95.670000000000002]],"spl":null,"spn":null,"atl":null,"batl":null,"id":16570658,"hc":null,"bdatb":null}],"img":null,"tv":2254126.0299999998,"con":null,"marketdefinition":null,"id":"1.258926623"}],"conflatems":null,"op":"mcm","id":3}
{"ct":null,"SegmentType":null,"clk":"AItYAJxbAopb","heartbeatms":null,"pt":1780839673828,"initialclk":null,"mc":[{"rc":[{"tv":null,"batb":null,"spb":null,"bdatl":null,"trd":null,"spf":null,"ltp":null,"atb":[[8.8000000000000007,168.38999999999999]],"spl":null,"spn":null,"atl":null,"batl":null,"id":16570658,"hc":null,"bdatb":null}],"img":null,"tv":null,"con":null,"marketdefinition":null,"id":"1.258926623"}],"conflatems":null,"op":"mcm","id":3}
{"ct":null,"SegmentType":null,"clk":"AJBYAKJbAPBb","heartbeatms":null,"pt":1780839673889,"initialclk":null,"mc":[{"rc":[{"tv":null,"batb":null,"spb":null,"bdatl":null,"trd":null,"spf":null,"ltp":null,"atb":[[8.8000000000000007,170.66]],"spl":null,"spn":null,"atl":null,"batl":null,"id":16570658,"hc":null,"bdatb":null}],"img":null,"tv":null,"con":null,"marketdefinition":null,"id":"1.258926623"}],"conflatems":null,"op":"mcm","id":3}
{"ct":null,"SegmentType":null,"clk":"AMhYANVbAKVc","heartbeatms":null,"pt":1780839674411,"initialclk":null,"mc":[{"rc":[{"tv":2012019.8300000001,"batb":null,"spb":null,"bdatl":null,"trd":[[1.1200000000000001,54656.349999999999]],"spf":null,"ltp":null,"atb":null,"spl":null,"spn":null,"atl":[[1.1200000000000001,19102.060000000001]],"batl":null,"id":19924823,"hc":null,"bdatb":null}],"img":null,"tv":2254137.6299999999,"con":null,"marketdefinition":null,"id":"1.258926623"}],"conflatems":null,"op":"mcm","id":3}
{"ct":null,"SegmentType":null,"clk":"AOFYAPJbAMJc","heartbeatms":null,"pt":1780839674620,"initialclk":null,"mc":[{"rc":[{"tv":null,"batb":null,"spb":null,"bdatl":null,"trd":null,"spf":null,"ltp":null,"atb":[[1.1100000000000001,52559.870000000003]],"spl":null,"spn":null,"atl":null,"batl":null,"id":19924823,"hc":null,"bdatb":null}],"img":null,"tv":null,"con":null,"marketdefinition":null,"id":"1.258926623"}],"conflatems":null,"op":"mcm","id":3}
{"ct":null,"SegmentType":null,"clk":"APFYAidcANNc","heartbeatms":null,"pt":1780839674814,"initialclk":null,"mc":[{"rc":[{"tv":242147.48000000001,"batb":null,"spb":null,"bdatl":null,"trd":[[9.4000000000000004,586.69000000000005]],"spf":null,"ltp":null,"atb":[[9.4000000000000004,80.829999999999998]],"spl":null,"spn":null,"atl":null,"batl":null,"id":16570658,"hc":null,"bdatb":null}],"img":null,"tv":2254167.3100000001,"con":null,"marketdefinition":null,"id":"1.258926623"}],"conflatems":null,"op":"mcm","id":3}
{"ct":null,"SegmentType":null,"clk":"AM1ZAOVcAMBd","heartbeatms":null,"pt":1780839676012,"initialclk":null,"mc":[{"rc":[{"tv":null,"batb":null,"spb":null,"bdatl":null,"trd":null,"spf":null,"ltp":null,"atb":[[1.0900000000000001,42255.830000000002],[1.1100000000000001,52854.629999999997]],"spl":null,"spn":null,"atl":null,"batl":null,"id":19924823,"hc":null,"bdatb":null}],"img":null,"tv":null,"con":null,"marketdefinition":null,"id":"1.258926623"}],"conflatems":null,"op":"mcm","id":3}
{"ct":null,"SegmentType":null,"clk":"AI1aAKBdAP5d","heartbeatms":null,"pt":1780839676725,"initialclk":null,"mc":[{"rc":[{"tv":null,"batb":null,"spb":null,"bdatl":null,"trd":null,"spf":null,"ltp":null,"atb":null,"spl":null,"spn":null,"atl":[[1.21,9160.3500000000004]],"batl":null,"id":19924823,"hc":null,"bdatb":null}],"img":null,"tv":null,"con":null,"marketdefinition":null,"id":"1.258926623"}],"conflatems":null,"op":"mcm","id":3}
{"ct":null,"SegmentType":null,"clk":"AKlaAL9dAKpe","heartbeatms":null,"pt":1780839677101,"initialclk":null,"mc":[{"rc":[{"tv":2012022.6100000001,"batb":null,"spb":null,"bdatl":null,"trd":[[1.1200000000000001,54659.129999999997]],"spf":null,"ltp":null,"atb":null,"spl":null,"spn":null,"atl":[[1.1200000000000001,19100.669999999998]],"batl":null,"id":19924823,"hc":null,"bdatb":null}],"img":null,"tv":2254170.0899999999,"con":null,"marketdefinition":null,"id":"1.258926623"}],"conflatems":null,"op":"mcm","id":3}
{"ct":null,"SegmentType":null,"clk":"ALxaAM5dALte","heartbeatms":null,"pt":1780839677306,"initialclk":null,"mc":[{"rc":[{"tv":null,"batb":null,"spb":null,"bdatl":null,"trd":null,"spf":null,"ltp":null,"atb":null,"spl":null,"spn":null,"atl":[[1.23,483.77999999999997]],"batl":null,"id":19924823,"hc":null,"bdatb":null}],"img":null,"tv":null,"con":null,"marketdefinition":null,"id":"1.258926623"}],"conflatems":null,"op":"mcm","id":3}
{"ct":null,"SegmentType":null,"clk":"AP5aAI9eAIRf","heartbeatms":null,"pt":1780839678029,"initialclk":null,"mc":[{"rc":[{"tv":242151.32000000001,"batb":null,"spb":null,"bdatl":null,"trd":[[9.4000000000000004,590.52999999999997]],"spf":null,"ltp":null,"atb":[[9.4000000000000004,78.909999999999997]],"spl":null,"spn":null,"atl":null,"batl":null,"id":16570658,"hc":null,"bdatb":null}],"img":null,"tv":2254173.9300000002,"con":null,"marketdefinition":null,"id":"1.258926623"}],"conflatems":null,"op":"mcm","id":3}
{"ct":null,"SegmentType":null,"clk":"AIVbAJNeAI1f","heartbeatms":null,"pt":1780839678143,"initialclk":null,"mc":[{"rc":[{"tv":2012026.74,"batb":null,"spb":null,"bdatl":null,"trd":[[1.1200000000000001,54663.260000000002]],"spf":null,"ltp":null,"atb":null,"spl":null,"spn":null,"atl":[[1.1200000000000001,19098.599999999999]],"batl":null,"id":19924823,"hc":null,"bdatb":null}],"img":null,"tv":2254178.0600000001,"con":null,"marketdefinition":null,"id":"1.258926623"}],"conflatems":null,"op":"mcm","id":3}
{"ct":null,"SegmentType":null,"clk":"AJtbAKxeAK5f","heartbeatms":null,"pt":1780839678397,"initialclk":null,"mc":[{"rc":[{"tv":null,"batb":null,"spb":null,"bdatl":null,"trd":null,"spf":null,"ltp":null,"atb":null,"spl":null,"spn":null,"atl":[[1.1499999999999999,10078.24]],"batl":null,"id":19924823,"hc":null,"bdatb":null}],"img":null,"tv":null,"con":null,"marketdefinition":null,"id":"1.258926623"}],"conflatems":null,"op":"mcm","id":3}
{"ct":null,"SegmentType":null,"clk":"AMdbANZeANxf","heartbeatms":null,"pt":1780839678712,"initialclk":null,"mc":[{"rc":[{"tv":242161.32000000001,"batb":null,"spb":null,"bdatl":null,"trd":[[9.4000000000000004,600.52999999999997]],"spf":null,"ltp":null,"atb":[[9.4000000000000004,73.909999999999997]],"spl":null,"spn":null,"atl":null,"batl":null,"id":16570658,"hc":null,"bdatb":null}],"img":null,"tv":2254188.0600000001,"con":null,"marketdefinition":null,"id":"1.258926623"}],"conflatems":null,"op":"mcm","id":3}
{"ct":null,"SegmentType":null,"clk":"APxbAPFeAIxg","heartbeatms":null,"pt":1780839679221,"initialclk":null,"mc":[{"rc":[{"tv":242237.34,"batb":null,"spb":null,"bdatl":null,"trd":[[9.5999999999999996,379.82999999999998]],"spf":null,"ltp":9.5999999999999996,"atb":null,"spl":null,"spn":null,"atl":[[9.5999999999999996,254.41999999999999]],"batl":null,"id":16570658,"hc":null,"bdatb":null}],"img":null,"tv":2254264.0800000001,"con":null,"marketdefinition":null,"id":"1.258926623"}],"conflatems":null,"op":"mcm","id":3}
{"ct":null,"SegmentType":null,"clk":"AJlcAItfAKlg","heartbeatms":null,"pt":1780839679533,"initialclk":null,"mc":[{"rc":[{"tv":null,"batb":null,"spb":null,"bdatl":null,"trd":null,"spf":null,"ltp":null,"atb":[[1.1100000000000001,52782.43]],"spl":null,"spn":null,"atl":null,"batl":null,"id":19924823,"hc":null,"bdatb":null}],"img":null,"tv":null,"con":null,"marketdefinition":null,"id":"1.258926623"}],"conflatems":null,"op":"mcm","id":3}
{"ct":null,"SegmentType":null,"clk":"AK5cAKJfAL1g","heartbeatms":null,"pt":1780839679734,"initialclk":null,"mc":[{"rc":[{"tv":null,"batb":null,"spb":null,"bdatl":null,"trd":null,"spf":null,"ltp":null,"atb":[[8.1999999999999993,0]],"spl":null,"spn":null,"atl":[[9.8000000000000007,189.03999999999999],[10.5,1.25],[10,57.469999999999999],[9.5999999999999996,188.25999999999999]],"batl":null,"id":16570658,"hc":null,"bdatb":null},{"tv":null,"batb":null,"spb":null,"bdatl":null,"trd":null,"spf":null,"ltp":null,"atb":[[1.1000000000000001,65811.330000000002]],"spl":null,"spn":null,"atl":[[1.1399999999999999,21622.669999999998],[1.1200000000000001,1389.97]],"batl":null,"id":19924823,"hc":null,"bdatb":null}],"img":null,"tv":null,"con":null,"marketdefinition":null,"id":"1.258926623"}],"conflatems":null,"op":"mcm","id":3}
{"ct":null,"SegmentType":null,"clk":"ALZcAKpfAMZg","heartbeatms":null,"pt":1780839679798,"initialclk":null,"mc":[{"rc":[{"tv":null,"batb":null,"spb":null,"bdatl":null,"trd":null,"spf":null,"ltp":null,"atb":[[7.7999999999999998,162.99000000000001],[9,273.45999999999998],[8,510.31]],"spl":null,"spn":null,"atl":[[12.5,196.52000000000001],[12,515.52999999999997],[11.5,52.869999999999997]],"batl":null,"id":16570658,"hc":null,"bdatb":null},{"tv":null,"batb":null,"spb":null,"bdatl":null,"trd":null,"spf":null,"ltp":null,"atb":[[1.0900000000000001,40110.830000000002]],"spl":null,"spn":null,"atl":[[1.1299999999999999,26049.91]],"batl":null,"id":19924823,"hc":null,"bdatb":null}],"img":null,"tv":null,"con":null,"marketdefinition":null,"id":"1.258926623"}],"conflatems":null,"op":"mcm","id":3}
{"ct":null,"SegmentType":null,"clk":"AMtcAL5fANxg","heartbeatms":null,"pt":1780839680023,"initialclk":null,"mc":[{"rc":[{"tv":null,"batb":null,"spb":null,"bdatl":null,"trd":null,"spf":null,"ltp":null,"atb":[[9.4000000000000004,0],[8.8000000000000007,15.09],[9.1999999999999993,201],[8,520.86000000000001]],"spl":null,"spn":null,"atl":[[9.8000000000000007,58.920000000000002],[12.5,198.52000000000001],[9.5999999999999996,60.450000000000003]],"batl":null,"id":16570658,"hc":null,"bdatb":null},{"tv":null,"batb":null,"spb":null,"bdatl":null,"trd":null,"spf":null,"ltp":null,"atb":[[1.1100000000000001,51988.57]],"spl":null,"spn":null,"atl":[[1.1299999999999999,24964.07],[1.1200000000000001,251.41]],"batl":null,"id":19924823,"hc":null,"bdatb":null}],"img":null,"tv":null,"con":null,"marketdefinition":null,"id":"1.258926623"}],"conflatems":null,"op":"mcm","id":3}
{"ct":null,"SegmentType":null,"clk":"ANZcAMhfAORg","heartbeatms":null,"pt":1780839680107,"initialclk":null,"mc":[{"rc":[{"tv":null,"batb":null,"spb":null,"bdatl":null,"trd":null,"spf":null,"ltp":null,"atb":[[7.7999999999999998,85.109999999999999],[8,258.38999999999999]],"spl":null,"spn":null,"atl":[[9.8000000000000007,0],[12.5,108.24],[12,299.06],[10,0],[9.5999999999999996,0]],"batl":null,"id":16570658,"hc":null,"bdatb":null},{"tv":null,"batb":null,"spb":null,"bdatl":null,"trd":null,"spf":null,"ltp":null,"atb":[[1.1000000000000001,65789.740000000005]],"spl":null,"spn":null,"atl":null,"batl":null,"id":19924823,"hc":null,"bdatb":null}],"img":null,"tv":null,"con":null,"marketdefinition":null,"id":"1.258926623"}],"conflatems":null,"op":"mcm","id":3}
{"ct":null,"SegmentType":null,"clk":"ANxcANJfAOdg","heartbeatms":null,"pt":1780839680209,"initialclk":null,"mc":[{"rc":[{"tv":null,"batb":null,"spb":null,"bdatl":null,"trd":null,"spf":null,"ltp":null,"atb":[[9,255.96000000000001]],"spl":null,"spn":null,"atl":null,"batl":null,"id":16570658,"hc":null,"bdatb":null}],"img":null,"tv":null,"con":null,"marketdefinition":null,"id":"1.258926623"}],"conflatems":null,"op":"mcm","id":3}
{"ct":null,"SegmentType":null,"clk":"AOZcANxfAPNg","heartbeatms":null,"pt":1780839680317,"initialclk":null,"mc":[{"rc":[{"tv":null,"batb":null,"spb":null,"bdatl":null,"trd":null,"spf":null,"ltp":null,"atb":[[9.4000000000000004,0.94999999999999996]],"spl":null,"spn":null,"atl":null,"batl":null,"id":16570658,"hc":null,"bdatb":null}],"img":null,"tv":null,"con":null,"marketdefinition":null,"id":"1.258926623"}],"conflatems":null,"op":"mcm","id":3}
{"ct":null,"SegmentType":null,"clk":"APdcAO1fAIph","heartbeatms":null,"pt":1780839680528,"initialclk":null,"mc":[{"rc":[{"tv":null,"batb":null,"spb":null,"bdatl":null,"trd":null,"spf":null,"ltp":null,"atb":[[9.4000000000000004,4.9500000000000002]],"spl":null,"spn":null,"atl":[[11,21.289999999999999]],"batl":null,"id":16570658,"hc":null,"bdatb":null},{"tv":null,"batb":null,"spb":null,"bdatl":null,"trd":null,"spf":null,"ltp":null,"atb":[[1.1000000000000001,67047.679999999993]],"spl":null,"spn":null,"atl":[[1.1399999999999999,22503.73]],"batl":null,"id":19924823,"hc":null,"bdatb":null}],"img":null,"tv":null,"con":null,"marketdefinition":null,"id":"1.258926623"}],"conflatems":null,"op":"mcm","id":3}
{"ct":null,"SegmentType":null,"clk":"AIBdAPVfAJNh","heartbeatms":null,"pt":1780839680629,"initialclk":null,"mc":[{"rc":[{"tv":null,"batb":null,"spb":null,"bdatl":null,"trd":null,"spf":null,"ltp":null,"atb":[[1.1100000000000001,50443]],"spl":null,"spn":null,"atl":[[1.1299999999999999,24075.209999999999]],"batl":null,"id":19924823,"hc":null,"bdatb":null}],"img":null,"tv":null,"con":null,"marketdefinition":null,"id":"1.258926623"}],"conflatems":null,"op":"mcm","id":3}
{"ct":null,"SegmentType":null,"clk":"ALddAKZgALxh","heartbeatms":null,"pt":1780839681103,"initialclk":null,"mc":[{"rc":[{"tv":2012029.99,"batb":null,"spb":null,"bdatl":null,"trd":[[1.1200000000000001,54666.510000000002]],"spf":null,"ltp":null,"atb":null,"spl":null,"spn":null,"atl":[[1.1200000000000001,249.78]],"batl":null,"id":19924823,"hc":null,"bdatb":null}],"img":null,"tv":2254267.3300000001,"con":null,"marketdefinition":null,"id":"1.258926623"}],"conflatems":null,"op":"mcm","id":3}
{"ct":null,"SegmentType":null,"clk":"ANFdAMlgANph","heartbeatms":null,"pt":1780839681408,"initialclk":null,"mc":[{"rc":[{"tv":null,"batb":null,"spb":null,"bdatl":null,"trd":null,"spf":null,"ltp":null,"atb":[[9.1999999999999993,1]],"spl":null,"spn":null,"atl":null,"batl":null,"id":16570658,"hc":null,"bdatb":null}],"img":null,"tv":null,"con":null,"marketdefinition":null,"id":"1.258926623"}],"conflatems":null,"op":"mcm","id":3}
{"ct":null,"SegmentType":null,"clk":"AKReAKBhALdi","heartbeatms":null,"pt":1780839682129,"initialclk":null,"mc":[{"rc":[{"tv":2012032.8700000001,"batb":null,"spb":null,"bdatl":null,"trd":[[1.1200000000000001,54669.389999999999]],"spf":null,"ltp":null,"atb":null,"spl":null,"spn":null,"atl":[[1.1200000000000001,248.34]],"batl":null,"id":19924823,"hc":null,"bdatb":null}],"img":null,"tv":2254270.21,"con":null,"marketdefinition":null,"id":"1.258926623"}],"conflatems":null,"op":"mcm","id":3}
{"ct":null,"SegmentType":null,"clk":"AL1eALNhAMZi","heartbeatms":null,"pt":1780839682332,"initialclk":null,"mc":[{"rc":[{"tv":null,"batb":null,"spb":null,"bdatl":null,"trd":null,"spf":null,"ltp":null,"atb":[[1.1100000000000001,50543]],"spl":null,"spn":null,"atl":null,"batl":null,"id":19924823,"hc":null,"bdatb":null}],"img":null,"tv":null,"con":null,"marketdefinition":null,"id":"1.258926623"}],"conflatems":null,"op":"mcm","id":3}
{"ct":null,"SegmentType":null,"clk":"ANdeAMphAOhi","heartbeatms":null,"pt":1780839682608,"initialclk":null,"mc":[{"rc":[{"tv":2012177.25,"batb":null,"spb":null,"bdatl":null,"trd":[[1.1200000000000001,54813.769999999997]],"spf":null,"ltp":null,"atb":null,"spl":null,"spn":null,"atl":[[1.1200000000000001,176.15000000000001]],"batl":null,"id":19924823,"hc":null,"bdatb":null}],"img":null,"tv":2254414.5899999999,"con":null,"marketdefinition":null,"id":"1.258926623"}],"conflatems":null,"op":"mcm","id":3}
{"ct":null,"SegmentType":null,"clk":"AIhfAPFhAJhj","heartbeatms":null,"pt":1780839683124,"initialclk":null,"mc":[{"rc":[{"tv":null,"batb":null,"spb":null,"bdatl":null,"trd":null,"spf":null,"ltp":null,"atb":[[8.1999999999999993,180.53]],"spl":null,"spn":null,"atl":[[11,157.65000000000001]],"batl":null,"id":16570658,"hc":null,"bdatb":null},{"tv":null,"batb":null,"spb":null,"bdatl":null,"trd":null,"spf":null,"ltp":null,"atb":[[1.1100000000000001,51894.349999999999]],"spl":null,"spn":null,"atl":[[1.1399999999999999,23802.32]],"batl":null,"id":19924823,"hc":null,"bdatb":null}],"img":null,"tv":null,"con":null,"marketdefinition":null,"id":"1.258926623"}],"conflatems":null,"op":"mcm","id":3}
{"ct":null,"SegmentType":null,"clk":"AJBfApthAKVj","heartbeatms":null,"pt":1780839683223,"initialclk":null,"mc":[{"rc":[{"tv":null,"batb":null,"spb":null,"bdatl":null,"trd":null,"spf":null,"ltp":null,"atb":null,"spl":null,"spn":null,"atl":[[10,0.94999999999999996]],"batl":null,"id":16570658,"hc":null,"bdatb":null}],"img":null,"tv":null,"con":null,"marketdefinition":null,"id":"1.258926623"}],"conflatems":null,"op":"mcm","id":3}
{"ct":null,"SegmentType":null,"clk":"ALNfAJZiAMVj","heartbeatms":null,"pt":1780839683532,"initialclk":null,"mc":[{"rc":[{"tv":242239.34,"batb":null,"spb":null,"bdatl":null,"trd":[[9.4000000000000004,602.52999999999997]],"spf":null,"ltp":9.4000000000000004,"atb":[[9.4000000000000004,3.9500000000000002]],"spl":null,"spn":null,"atl":null,"batl":null,"id":16570658,"hc":null,"bdatb":null}],"img":null,"tv":2254416.5899999999,"con":null,"marketdefinition":null,"id":"1.258926623"}],"conflatems":null,"op":"mcm","id":3}
{"ct":null,"SegmentType":null,"clk":"AM9fAK1iAOJj","heartbeatms":null,"pt":1780839683835,"initialclk":null,"mc":[{"rc":[{"tv":null,"batb":null,"spb":null,"bdatl":null,"trd":null,"spf":null,"ltp":null,"atb":null,"spl":null,"spn":null,"atl":[[11,156.78999999999999]],"batl":null,"id":16570658,"hc":null,"bdatb":null},{"tv":null,"batb":null,"spb":null,"bdatl":null,"trd":null,"spf":null,"ltp":null,"atb":[[1.1000000000000001,67043.179999999993]],"spl":null,"spn":null,"atl":[[1.1200000000000001,9035.0900000000001]],"batl":null,"id":19924823,"hc":null,"bdatb":null}],"img":null,"tv":null,"con":null,"marketdefinition":null,"id":"1.258926623"}],"conflatems":null,"op":"mcm","id":3}
{"ct":null,"SegmentType":null,"clk":"AOBfALtiAO9j","heartbeatms":null,"pt":1780839684004,"initialclk":null,"mc":[{"rc":[{"tv":null,"batb":null,"spb":null,"bdatl":null,"trd":null,"spf":null,"ltp":null,"atb":[[1.1100000000000001,50543]],"spl":null,"spn":null,"atl":null,"batl":null,"id":19924823,"hc":null,"bdatb":null}],"img":null,"tv":null,"con":null,"marketdefinition":null,"id":"1.258926623"}],"conflatems":null,"op":"mcm","id":3}
{"ct":null,"SegmentType":null,"clk":"AIVgAOliAI9k","heartbeatms":null,"pt":1780839684415,"initialclk":null,"mc":[{"rc":[{"tv":2012184.21,"batb":null,"spb":null,"bdatl":null,"trd":[[1.1200000000000001,54820.730000000003]],"spf":null,"ltp":null,"atb":null,"spl":null,"spn":null,"atl":[[1.1200000000000001,9031.6100000000006]],"batl":null,"id":19924823,"hc":null,"bdatb":null}],"img":null,"tv":2254423.5499999998,"con":null,"marketdefinition":null,"id":"1.258926623"}],"conflatems":null,"op":"mcm","id":3}
{"ct":null,"SegmentType":null,"clk":"AMxhAIJkAJll","heartbeatms":null,"pt":1780839686129,"initialclk":null,"mc":[{"rc":[{"tv":null,"batb":null,"spb":null,"bdatl":null,"trd":null,"spf":null,"ltp":null,"atb":null,"spl":null,"spn":null,"atl":[[1.1699999999999999,9377.6299999999992]],"batl":null,"id":19924823,"hc":null,"bdatb":null}],"img":null,"tv":null,"con":null,"marketdefinition":null,"id":"1.258926623"}],"conflatems":null,"op":"mcm","id":3}
{"ct":null,"SegmentType":null,"clk":"ANxhAJFkALJl","heartbeatms":null,"pt":1780839686329,"initialclk":null,"mc":[{"rc":[{"tv":2012198.71,"batb":null,"spb":null,"bdatl":null,"trd":[[1.1200000000000001,54835.230000000003]],"spf":null,"ltp":null,"atb":null,"spl":null,"spn":null,"atl":[[1.1200000000000001,9024.3600000000006]],"batl":null,"id":19924823,"hc":null,"bdatb":null}],"img":null,"tv":2254438.0499999998,"con":null,"marketdefinition":null,"id":"1.258926623"}],"conflatems":null,"op":"mcm","id":3}
{"ct":null,"SegmentType":null,"clk":"AOdhAJhkALpl","heartbeatms":null,"pt":1780839686429,"initialclk":null,"mc":[{"rc":[{"tv":null,"batb":null,"spb":null,"bdatl":null,"trd":null,"spf":null,"ltp":null,"atb":[[9.5999999999999996,131.43000000000001]],"spl":null,"spn":null,"atl":[[10,127.13]],"batl":null,"id":16570658,"hc":null,"bdatb":null},{"tv":null,"batb":null,"spb":null,"bdatl":null,"trd":null,"spf":null,"ltp":null,"atb":[[1.1100000000000001,51679.730000000003]],"spl":null,"spn":null,"atl":[[1.1299999999999999,25191.82]],"batl":null,"id":19924823,"hc":null,"bdatb":null}],"img":null,"tv":null,"con":null,"marketdefinition":null,"id":"1.258926623"}],"conflatems":null,"op":"mcm","id":3}
{"ct":null,"SegmentType":null,"clk":"AO5hAKFkAMJl","heartbeatms":null,"pt":1780839686532,"initialclk":null,"mc":[{"rc":[{"tv":null,"batb":null,"spb":null,"bdatl":null,"trd":null,"spf":null,"ltp":null,"atb":[[9.4000000000000004,135.47999999999999]],"spl":null,"spn":null,"atl":[[9.8000000000000007,126.16]],"batl":null,"id":16570658,"hc":null,"bdatb":null}],"img":null,"tv":null,"con":null,"marketdefinition":null,"id":"1.258926623"}],"conflatems":null,"op":"mcm","id":3}
{"ct":null,"SegmentType":null,"clk":"APNhALFkAMll","heartbeatms":null,"pt":1780839686640,"initialclk":null,"mc":[{"rc":[{"tv":null,"batb":null,"spb":null,"bdatl":null,"trd":null,"spf":null,"ltp":null,"atb":[[9.4000000000000004,131.53]],"spl":null,"spn":null,"atl":null,"batl":null,"id":16570658,"hc":null,"bdatb":null}],"img":null,"tv":null,"con":null,"marketdefinition":null,"id":"1.258926623"}],"conflatems":null,"op":"mcm","id":3}
{"ct":null,"SegmentType":null,"clk":"AP1hALRkAM9l","heartbeatms":null,"pt":1780839686742,"initialclk":null,"mc":[{"rc":[{"tv":2012208.71,"batb":null,"spb":null,"bdatl":null,"trd":[[1.1100000000000001,100713.14]],"spf":null,"ltp":1.1100000000000001,"atb":[[1.1100000000000001,51674.730000000003]],"spl":null,"spn":null,"atl":null,"batl":null,"id":19924823,"hc":null,"bdatb":null}],"img":null,"tv":2254448.0499999998,"con":null,"marketdefinition":null,"id":"1.258926623"}],"conflatems":null,"op":"mcm","id":3}
{"ct":null,"SegmentType":null,"clk":"AI9iAMNkAN5l","heartbeatms":null,"pt":1780839686945,"initialclk":null,"mc":[{"rc":[{"tv":242246.23999999999,"batb":null,"spb":null,"bdatl":null,"trd":[[9.5999999999999996,386.73000000000002]],"spf":null,"ltp":9.5999999999999996,"atb":[[9.5999999999999996,127.98]],"spl":null,"spn":null,"atl":null,"batl":null,"id":16570658,"hc":null,"bdatb":null}],"img":null,"tv":2254454.9500000002,"con":null,"marketdefinition":null,"id":"1.258926623"}],"conflatems":null,"op":"mcm","id":3}
{"ct":null,"SegmentType":null,"clk":"ALxjAM1lAO9m","heartbeatms":null,"pt":1780839688503,"initialclk":null,"mc":[{"rc":[{"tv":null,"batb":null,"spb":null,"bdatl":null,"trd":null,"spf":null,"ltp":null,"atb":null,"spl":null,"spn":null,"atl":[[1.1200000000000001,9414.3600000000006]],"batl":null,"id":19924823,"hc":null,"bdatb":null}],"img":null,"tv":null,"con":null,"marketdefinition":null,"id":"1.258926623"}],"conflatems":null,"op":"mcm","id":3}
{"ct":null,"SegmentType":null,"clk":"AM9jAONlAIRn","heartbeatms":null,"pt":1780839688709,"initialclk":null,"mc":[{"rc":[{"tv":null,"batb":null,"spb":null,"bdatl":null,"trd":null,"spf":null,"ltp":null,"atb":[[9.5999999999999996,0]],"spl":null,"spn":null,"atl":null,"batl":null,"id":16570658,"hc":null,"bdatb":null}],"img":null,"tv":null,"con":null,"marketdefinition":null,"id":"1.258926623"}],"conflatems":null,"op":"mcm","id":3}
{"ct":null,"SegmentType":null,"clk":"AN5kAO5mAIFo","heartbeatms":null,"pt":1780839690113,"initialclk":null,"mc":[{"rc":[{"tv":null,"batb":null,"spb":null,"bdatl":null,"trd":null,"spf":null,"ltp":null,"atb":null,"spl":null,"spn":null,"atl":[[10,212.63999999999999]],"batl":null,"id":16570658,"hc":null,"bdatb":null}],"img":null,"tv":null,"con":null,"marketdefinition":null,"id":"1.258926623"}],"conflatems":null,"op":"mcm","id":3}
{"ct":null,"SegmentType":null,"clk":"ALFlAMJnALxo","heartbeatms":null,"pt":1780839690934,"initialclk":null,"mc":[{"rc":[{"tv":null,"batb":null,"spb":null,"bdatl":null,"trd":null,"spf":null,"ltp":null,"atb":null,"spl":null,"spn":null,"atl":[[11,242.30000000000001]],"batl":null,"id":16570658,"hc":null,"bdatb":null}],"img":null,"tv":null,"con":null,"marketdefinition":null,"id":"1.258926623"}],"conflatems":null,"op":"mcm","id":3}
{"ct":null,"SegmentType":null,"clk":"AMtlANZnAMto","heartbeatms":null,"pt":1780839691144,"initialclk":null,"mc":[{"rc":[{"tv":null,"batb":null,"spb":null,"bdatl":null,"trd":null,"spf":null,"ltp":null,"atb":null,"spl":null,"spn":null,"atl":[[10.5,144.09999999999999]],"batl":null,"id":16570658,"hc":null,"bdatb":null},{"tv":null,"batb":null,"spb":null,"bdatl":null,"trd":null,"spf":null,"ltp":null,"atb":[[1.1000000000000001,68406.809999999998]],"spl":null,"spn":null,"atl":null,"batl":null,"id":19924823,"hc":null,"bdatb":null}],"img":null,"tv":null,"con":null,"marketdefinition":null,"id":"1.258926623"}],"conflatems":null,"op":"mcm","id":3}
{"ct":null,"SegmentType":null,"clk":"AP1lAIhoAOto","heartbeatms":null,"pt":1780839691613,"initialclk":null,"mc":[{"rc":[{"tv":null,"batb":null,"spb":null,"bdatl":null,"trd":null,"spf":null,"ltp":null,"atb":null,"spl":null,"spn":null,"atl":[[11,105.94]],"batl":null,"id":16570658,"hc":null,"bdatb":null}],"img":null,"tv":null,"con":null,"marketdefinition":null,"id":"1.258926623"}],"conflatems":null,"op":"mcm","id":3}
{"ct":null,"SegmentType":null,"clk":"AP5mAPpoANNp","heartbeatms":null,"pt":1780839692812,"initialclk":null,"mc":[{"rc":[{"tv":2012220.3100000001,"batb":null,"spb":null,"bdatl":null,"trd":[[1.1200000000000001,54846.830000000002]],"spf":null,"ltp":1.1200000000000001,"atb":null,"spl":null,"spn":null,"atl":[[1.1200000000000001,9408.5599999999995]],"batl":null,"id":19924823,"hc":null,"bdatb":null}],"img":null,"tv":2254466.5499999998,"con":null,"marketdefinition":null,"id":"1.258926623"}],"conflatems":null,"op":"mcm","id":3}
{"ct":null,"SegmentType":null,"clk":"AJ1nAJZpAOhp","heartbeatms":null,"pt":1780839693124,"initialclk":null,"mc":[{"rc":[{"tv":null,"batb":null,"spb":null,"bdatl":null,"trd":null,"spf":null,"ltp":null,"atb":null,"spl":null,"spn":null,"atl":[[1.1200000000000001,549.62]],"batl":null,"id":19924823,"hc":null,"bdatb":null}],"img":null,"tv":null,"con":null,"marketdefinition":null,"id":"1.258926623"}],"conflatems":null,"op":"mcm","id":3}
{"ct":null,"SegmentType":null,"clk":"AKNnAJ9pAOxp","heartbeatms":null,"pt":1780839693225,"initialclk":null,"mc":[{"rc":[{"tv":null,"batb":null,"spb":null,"bdatl":null,"trd":null,"spf":null,"ltp":null,"atb":[[9.1999999999999993,138.69999999999999]],"spl":null,"spn":null,"atl":null,"batl":null,"id":16570658,"hc":null,"bdatb":null}],"img":null,"tv":null,"con":null,"marketdefinition":null,"id":"1.258926623"}],"conflatems":null,"op":"mcm","id":3}
{"ct":null,"SegmentType":null,"clk":"AK1nAKdpAPNp","heartbeatms":null,"pt":1780839693326,"initialclk":null,"mc":[{"rc":[{"tv":null,"batb":null,"spb":null,"bdatl":null,"trd":null,"spf":null,"ltp":null,"atb":[[8.1999999999999993,0]],"spl":null,"spn":null,"atl":[[10.5,1.25]],"batl":null,"id":16570658,"hc":null,"bdatb":null},{"tv":null,"batb":null,"spb":null,"bdatl":null,"trd":null,"spf":null,"ltp":null,"atb":[[1.1000000000000001,67043.179999999993]],"spl":null,"spn":null,"atl":[[1.1399999999999999,22503.73]],"batl":null,"id":19924823,"hc":null,"bdatb":null}],"img":null,"tv":null,"con":null,"marketdefinition":null,"id":"1.258926623"}],"conflatems":null,"op":"mcm","id":3}
{"ct":null,"SegmentType":null,"clk":"AMVnALhpAItq","heartbeatms":null,"pt":1780839693535,"initialclk":null,"mc":[{"rc":[{"tv":null,"batb":null,"spb":null,"bdatl":null,"trd":null,"spf":null,"ltp":null,"atb":[[9.4000000000000004,0],[9.1999999999999993,1]],"spl":null,"spn":null,"atl":[[9.8000000000000007,0],[10,86.459999999999994]],"batl":null,"id":16570658,"hc":null,"bdatb":null},{"tv":2012222.24,"batb":null,"spb":null,"bdatl":null,"trd":[[1.1100000000000001,100715.07000000001]],"spf":null,"ltp":1.1100000000000001,"atb":[[1.1100000000000001,50537.029999999999]],"spl":null,"spn":null,"atl":[[1.1299999999999999,24075.209999999999]],"batl":null,"id":19924823,"hc":null,"bdatb":null}],"img":null,"tv":2254468.48,"con":null,"marketdefinition":null,"id":"1.258926623"}],"conflatems":null,"op":"mcm","id":3}
{"ct":null,"SegmentType":null,"clk":"ANhnAM5pAJlq","heartbeatms":null,"pt":1780839693749,"initialclk":null,"mc":[{"rc":[{"tv":null,"batb":null,"spb":null,"bdatl":null,"trd":null,"spf":null,"ltp":null,"atb":[[9.4000000000000004,0.94999999999999996]],"spl":null,"spn":null,"atl":null,"batl":null,"id":16570658,"hc":null,"bdatb":null},{"tv":2012233.8400000001,"batb":null,"spb":null,"bdatl":null,"trd":[[1.1200000000000001,54858.43]],"spf":null,"ltp":1.1200000000000001,"atb":null,"spl":null,"spn":null,"atl":[[1.1200000000000001,543.82000000000005]],"batl":null,"id":19924823,"hc":null,"bdatb":null}],"img":null,"tv":2254480.0800000001,"con":null,"marketdefinition":null,"id":"1.258926623"}],"conflatems":null,"op":"mcm","id":3}
{"ct":null,"SegmentType":null,"clk":"AptnAOVpALJq","heartbeatms":null,"pt":1780839694045,"initialclk":null,"mc":[{"rc":[{"tv":null,"batb":null,"spb":null,"bdatl":null,"trd":null,"spf":null,"ltp":null,"atb":[[1.1000000000000001,67097.240000000005]],"spl":null,"spn":null,"atl":null,"batl":null,"id":19924823,"hc":null,"bdatb":null}],"img":null,"tv":null,"con":null,"marketdefinition":null,"id":"1.258926623"}],"conflatems":null,"op":"mcm","id":3}
{"ct":null,"SegmentType":null,"clk":"AI1pAOhqAKpr","heartbeatms":null,"pt":1780839695547,"initialclk":null,"mc":[{"rc":[{"tv":null,"batb":null,"spb":null,"bdatl":null,"trd":null,"spf":null,"ltp":null,"atb":null,"spl":null,"spn":null,"atl":[[1.1200000000000001,1788.52]],"batl":null,"id":19924823,"hc":null,"bdatb":null}],"img":null,"tv":null,"con":null,"marketdefinition":null,"id":"1.258926623"}],"conflatems":null,"op":"mcm","id":3}
{"ct":null,"SegmentType":null,"clk":"AKFpAP9qALtr","heartbeatms":null,"pt":1780839695761,"initialclk":null,"mc":[{"rc":[{"tv":2012406.6000000001,"batb":null,"spb":null,"bdatl":null,"trd":[[1.1200000000000001,55031.190000000002]],"spf":null,"ltp":null,"atb":[[1.1000000000000001,67043.179999999993]],"spl":null,"spn":null,"atl":[[1.1200000000000001,1702.1400000000001]],"batl":null,"id":19924823,"hc":null,"bdatb":null}],"img":null,"tv":2254652.8399999999,"con":null,"marketdefinition":null,"id":"1.258926623"}],"conflatems":null,"op":"mcm","id":3}
{"ct":null,"SegmentType":null,"clk":"APZpAMprAP9r","heartbeatms":null,"pt":1780839696651,"initialclk":null,"mc":[{"rc":[{"tv":242247.62,"batb":null,"spb":null,"bdatl":null,"trd":[[9.4000000000000004,603.90999999999997]],"spf":null,"ltp":9.4000000000000004,"atb":[[9.4000000000000004,0.26000000000000001]],"spl":null,"spn":null,"atl":null,"batl":null,"id":16570658,"hc":null,"bdatb":null}],"img":null,"tv":2254654.2200000002,"con":null,"marketdefinition":null,"id":"1.258926623"}],"conflatems":null,"op":"mcm","id":3}
{"ct":null,"SegmentType":null,"clk":"AMJqAPdrAL9s","heartbeatms":null,"pt":1780839697323,"initialclk":null,"mc":[{"rc":[{"tv":2012456.6000000001,"batb":null,"spb":null,"bdatl":null,"trd":[[1.1100000000000001,100765.07000000001]],"spf":null,"ltp":1.1100000000000001,"atb":[[1.1100000000000001,50512.029999999999]],"spl":null,"spn":null,"atl":null,"batl":null,"id":19924823,"hc":null,"bdatb":null}],"img":null,"tv":2254704.2200000002,"con":null,"marketdefinition":null,"id":"1.258926623"}],"conflatems":null,"op":"mcm","id":3}
{"ct":null,"SegmentType":null,"clk":"AOhqAKJsAOBs","heartbeatms":null,"pt":1780839697840,"initialclk":null,"mc":[{"rc":[{"tv":2012567.3999999999,"batb":null,"spb":null,"bdatl":null,"trd":[[1.1100000000000001,100875.87]],"spf":null,"ltp":null,"atb":[[1.1100000000000001,50456.629999999997]],"spl":null,"spn":null,"atl":null,"batl":null,"id":19924823,"hc":null,"bdatb":null}],"img":null,"tv":2254815.02,"con":null,"marketdefinition":null,"id":"1.258926623"}],"conflatems":null,"op":"mcm","id":3}
{"ct":null,"SegmentType":null,"clk":"ALprAOFsAJ5t","heartbeatms":null,"pt":1780839698619,"initialclk":null,"mc":[{"rc":[{"tv":null,"batb":null,"spb":null,"bdatl":null,"trd":null,"spf":null,"ltp":null,"atb":[[4,101.12000000000001]],"spl":null,"spn":null,"atl":null,"batl":null,"id":16570658,"hc":null,"bdatb":null}],"img":null,"tv":null,"con":null,"marketdefinition":null,"id":"1.258926623"}],"conflatems":null,"op":"mcm","id":3}
{"ct":null,"SegmentType":null,"clk":"ANtrAPlsALNt","heartbeatms":null,"pt":1780839698922,"initialclk":null,"mc":[{"rc":[{"tv":null,"batb":null,"spb":null,"bdatl":null,"trd":null,"spf":null,"ltp":null,"atb":[[1.1000000000000001,67097.240000000005]],"spl":null,"spn":null,"atl":null,"batl":null,"id":19924823,"hc":null,"bdatb":null}],"img":null,"tv":null,"con":null,"marketdefinition":null,"id":"1.258926623"}],"conflatems":null,"op":"mcm","id":3}
{"ct":null,"SegmentType":null,"clk":"ANVsANxtAKdu","heartbeatms":null,"pt":1780839700219,"initialclk":null,"mc":[{"rc":[{"tv":2012613.8000000001,"batb":null,"spb":null,"bdatl":null,"trd":[[1.1200000000000001,55077.589999999997]],"spf":null,"ltp":1.1200000000000001,"atb":null,"spl":null,"spn":null,"atl":[[1.1200000000000001,1678.9400000000001]],"batl":null,"id":19924823,"hc":null,"bdatb":null}],"img":null,"tv":2254861.4199999999,"con":null,"marketdefinition":null,"id":"1.258926623"}],"conflatems":null,"op":"mcm","id":3}
{"ct":null,"SegmentType":null,"clk":"AIFuAIBvAKxv","heartbeatms":null,"pt":1780839701936,"initialclk":null,"mc":[{"rc":[{"tv":2012631.8999999999,"batb":null,"spb":null,"bdatl":null,"trd":[[1.1200000000000001,55095.690000000002]],"spf":null,"ltp":null,"atb":null,"spl":null,"spn":null,"atl":[[1.1200000000000001,1669.8900000000001]],"batl":null,"id":19924823,"hc":null,"bdatb":null}],"img":null,"tv":2254879.52,"con":null,"marketdefinition":null,"id":"1.258926623"}],"conflatems":null,"op":"mcm","id":3}
{"ct":null,"SegmentType":null,"clk":"AJRuAI9vALxv","heartbeatms":null,"pt":1780839702143,"initialclk":null,"mc":[{"rc":[{"tv":2012633.9399999999,"batb":null,"spb":null,"bdatl":null,"trd":[[1.1200000000000001,55097.730000000003]],"spf":null,"ltp":null,"atb":null,"spl":null,"spn":null,"atl":[[1.1200000000000001,1668.8699999999999]],"batl":null,"id":19924823,"hc":null,"bdatb":null}],"img":null,"tv":2254881.5600000001,"con":null,"marketdefinition":null,"id":"1.258926623"}],"conflatems":null,"op":"mcm","id":3}
{"ct":null,"SegmentType":null,"clk":"AMFuAK9vAN1v","heartbeatms":null,"pt":1780839702547,"initialclk":null,"mc":[{"rc":[{"tv":null,"batb":null,"spb":null,"bdatl":null,"trd":null,"spf":null,"ltp":null,"atb":null,"spl":null,"spn":null,"atl":[[1.1299999999999999,21548.560000000001]],"batl":null,"id":19924823,"hc":null,"bdatb":null}],"img":null,"tv":null,"con":null,"marketdefinition":null,"id":"1.258926623"}],"conflatems":null,"op":"mcm","id":3}
{"ct":null,"SegmentType":null,"clk":"AOluANVvAPNv","heartbeatms":null,"pt":1780839702921,"initialclk":null,"mc":[{"rc":[{"tv":2012635.8600000001,"batb":null,"spb":null,"bdatl":null,"trd":[[1.1200000000000001,55099.650000000001]],"spf":null,"ltp":null,"atb":null,"spl":null,"spn":null,"atl":[[1.1200000000000001,1667.9100000000001]],"batl":null,"id":19924823,"hc":null,"bdatb":null}],"img":null,"tv":2254883.48,"con":null,"marketdefinition":null,"id":"1.258926623"}],"conflatems":null,"op":"mcm","id":3}
{"ct":null,"SegmentType":null,"clk":"APFuAN9vAptv","heartbeatms":null,"pt":1780839703023,"initialclk":null,"mc":[{"rc":[{"tv":2013154.1000000001,"batb":null,"spb":null,"bdatl":null,"trd":[[1.1200000000000001,55617.889999999999]],"spf":null,"ltp":null,"atb":null,"spl":null,"spn":null,"atl":[[1.1200000000000001,1408.79]],"batl":null,"id":19924823,"hc":null,"bdatb":null}],"img":null,"tv":2255401.7200000002,"con":null,"marketdefinition":null,"id":"1.258926623"}],"conflatems":null,"op":"mcm","id":3}
{"ct":null,"SegmentType":null,"clk":"AJdvAIBwAJNw","heartbeatms":null,"pt":1780839703432,"initialclk":null,"mc":[{"rc":[{"tv":2013174.3999999999,"batb":null,"spb":null,"bdatl":null,"trd":[[1.1200000000000001,55638.190000000002]],"spf":null,"ltp":null,"atb":null,"spl":null,"spn":null,"atl":[[1.1200000000000001,1398.6400000000001]],"batl":null,"id":19924823,"hc":null,"bdatb":null}],"img":null,"tv":2255422.02,"con":null,"marketdefinition":null,"id":"1.258926623"}],"conflatems":null,"op":"mcm","id":3}
{"ct":null,"SegmentType":null,"clk":"AMFvAKJwALNw","heartbeatms":null,"pt":1780839703844,"initialclk":null,"mc":[{"rc":[{"tv":2013204.22,"batb":null,"spb":null,"bdatl":null,"trd":[[1.1200000000000001,55668.010000000002]],"spf":null,"ltp":null,"atb":null,"spl":null,"spn":null,"atl":[[1.1200000000000001,1383.73]],"batl":null,"id":19924823,"hc":null,"bdatb":null}],"img":null,"tv":2255451.8399999999,"con":null,"marketdefinition":null,"id":"1.258926623"}],"conflatems":null,"op":"mcm","id":3}
{"ct":null,"SegmentType":null,"clk":"AMdwAJVxAJhx","heartbeatms":null,"pt":1780839705050,"initialclk":null,"mc":[{"rc":[{"tv":2013434.1299999999,"batb":null,"spb":null,"bdatl":null,"trd":[[1.1100000000000001,101105.78]],"spf":null,"ltp":1.1100000000000001,"atb":[[1.1100000000000001,50341.68]],"spl":null,"spn":null,"atl":null,"batl":null,"id":19924823,"hc":null,"bdatb":null}],"img":null,"tv":2255681.75,"con":null,"marketdefinition":null,"id":"1.258926623"}],"conflatems":null,"op":"mcm","id":3}
{"ct":null,"SegmentType":null,"clk":"AJZxAOhxAMpx","heartbeatms":null,"pt":1780839705833,"initialclk":null,"mc":[{"rc":[{"tv":242256.23999999999,"batb":null,"spb":null,"bdatl":null,"trd":[[9.4000000000000004,604.42999999999995],[9.1999999999999993,1574.1700000000001]],"spf":null,"ltp":9.1999999999999993,"atb":[[9.4000000000000004,0],[9.1999999999999993,0]],"spl":null,"spn":null,"atl":[[9.4000000000000004,106.38],[9.5999999999999996,2604.1700000000001]],"batl":null,"id":16570658,"hc":null,"bdatb":null},{"tv":2013484.24,"batb":null,"spb":null,"bdatl":null,"trd":[[1.1200000000000001,55718.120000000003]],"spf":null,"ltp":1.1200000000000001,"atb":[[1.1100000000000001,52469.790000000001]],"spl":null,"spn":null,"atl":[[1.1200000000000001,1333.6199999999999]],"batl":null,"id":19924823,"hc":null,"bdatb":null}],"img":null,"tv":2255740.48,"con":null,"marketdefinition":null,"id":"1.258926623"}],"conflatems":null,"op":"mcm","id":3}
{"ct":null,"SegmentType":null,"clk":"AKFxAPJxANRx","heartbeatms":null,"pt":1780839705946,"initialclk":null,"mc":[{"rc":[{"tv":null,"batb":null,"spb":null,"bdatl":null,"trd":null,"spf":null,"ltp":null,"atb":null,"spl":null,"spn":null,"atl":[[9.4000000000000004,108.38],[10.5,2.2400000000000002],[10,87.329999999999998]],"batl":null,"id":16570658,"hc":null,"bdatb":null},{"tv":null,"batb":null,"spb":null,"bdatl":null,"trd":null,"spf":null,"ltp":null,"atb":[[1.1000000000000001,67102.809999999998],[1.1100000000000001,52474]],"spl":null,"spn":null,"atl":null,"batl":null,"id":19924823,"hc":null,"bdatb":null}],"img":null,"tv":null,"con":null,"marketdefinition":null,"id":"1.258926623"}],"conflatems":null,"op":"mcm","id":3}
{"ct":null,"SegmentType":null,"clk":"AK5xAptxANhx","heartbeatms":null,"pt":1780839706043,"initialclk":null,"mc":[{"rc":[{"tv":242278.35000000001,"batb":null,"spb":null,"bdatl":null,"trd":[[9.1999999999999993,1596.28]],"spf":null,"ltp":null,"atb":[[8.8000000000000007,2.27]],"spl":null,"spn":null,"atl":[[13.5,0],[12.5,107.25],[12,298.19999999999999],[10,86.379999999999995],[9.5999999999999996,0]],"batl":null,"id":16570658,"hc":null,"bdatb":null},{"tv":2013665.8300000001,"batb":null,"spb":null,"bdatl":null,"trd":[[1.1200000000000001,55899.709999999999]],"spf":null,"ltp":null,"atb":[[1.0800000000000001,39930.43],[1.0900000000000001,40105.849999999999],[1.1100000000000001,52830.309999999998]],"spl":null,"spn":null,"atl":[[1.1299999999999999,21348.560000000001],[1.1200000000000001,1152.03]],"batl":null,"id":19924823,"hc":null,"bdatb":null}],"img":null,"tv":2255944.1800000002,"con":null,"marketdefinition":null,"id":"1.258926623"}],"conflatems":null,"op":"mcm","id":3}
{"ct":null,"SegmentType":null,"clk":"ALVxAIZyAOJx","heartbeatms":null,"pt":1780839706155,"initialclk":null,"mc":[{"rc":[{"tv":null,"batb":null,"spb":null,"bdatl":null,"trd":null,"spf":null,"ltp":null,"atb":[[8.5999999999999996,550.50999999999999],[8,306.88999999999999]],"spl":null,"spn":null,"atl":[[11.5,59.530000000000001]],"batl":null,"id":16570658,"hc":null,"bdatb":null},{"tv":null,"batb":null,"spb":null,"bdatl":null,"trd":null,"spf":null,"ltp":null,"atb":[[1.1100000000000001,53078.309999999998]],"spl":null,"spn":null,"atl":[[1.1299999999999999,21000.060000000001],[1.1399999999999999,23085.73]],"batl":null,"id":19924823,"hc":null,"bdatb":null}],"img":null,"tv":null,"con":null,"marketdefinition":null,"id":"1.258926623"}],"conflatems":null,"op":"mcm","id":3}
{"ct":null,"SegmentType":null,"clk":"AMlxAJxyAPJx","heartbeatms":null,"pt":1780839706346,"initialclk":null,"mc":[{"rc":[{"tv":null,"batb":null,"spb":null,"bdatl":null,"trd":null,"spf":null,"ltp":null,"atb":[[8.4000000000000004,170.65000000000001],[8.1999999999999993,562.58000000000004]],"spl":null,"spn":null,"atl":null,"batl":null,"id":16570658,"hc":null,"bdatb":null},{"tv":null,"batb":null,"spb":null,"bdatl":null,"trd":null,"spf":null,"ltp":null,"atb":[[1.1100000000000001,57464.589999999997]],"spl":null,"spn":null,"atl":null,"batl":null,"id":19924823,"hc":null,"bdatb":null}],"img":null,"tv":null,"con":null,"marketdefinition":null,"id":"1.258926623"}],"conflatems":null,"op":"mcm","id":3}
{"ct":null,"SegmentType":null,"clk":"ANJxAKRyAptx","heartbeatms":null,"pt":1780839706451,"initialclk":null,"mc":[{"rc":[{"tv":null,"batb":null,"spb":null,"bdatl":null,"trd":null,"spf":null,"ltp":null,"atb":[[8.5999999999999996,211.91]],"spl":null,"spn":null,"atl":[[13,0]],"batl":null,"id":16570658,"hc":null,"bdatb":null},{"tv":null,"batb":null,"spb":null,"bdatl":null,"trd":null,"spf":null,"ltp":null,"atb":[[1.1000000000000001,65947.929999999993]],"spl":null,"spn":null,"atl":null,"batl":null,"id":19924823,"hc":null,"bdatb":null}],"img":null,"tv":null,"con":null,"marketdefinition":null,"id":"1.258926623"}],"conflatems":null,"op":"mcm","id":3}
{"ct":null,"SegmentType":null,"clk":"AOBxAK1yAIZy","heartbeatms":null,"pt":1780839706554,"initialclk":null,"mc":[{"rc":[{"tv":null,"batb":null,"spb":null,"bdatl":null,"trd":null,"spf":null,"ltp":null,"atb":null,"spl":null,"spn":null,"atl":[[10,94.150000000000006]],"batl":null,"id":16570658,"hc":null,"bdatb":null}],"img":null,"tv":null,"con":null,"marketdefinition":null,"id":"1.258926623"}],"conflatems":null,"op":"mcm","id":3}
{"ct":null,"SegmentType":null,"clk":"AOVxALNyAIxy","heartbeatms":null,"pt":1780839706659,"initialclk":null,"mc":[{"rc":[{"tv":null,"batb":null,"spb":null,"bdatl":null,"trd":null,"spf":null,"ltp":null,"atb":[[1.1100000000000001,59479.93]],"spl":null,"spn":null,"atl":[[1.1399999999999999,23160.150000000001]],"batl":null,"id":19924823,"hc":null,"bdatb":null}],"img":null,"tv":null,"con":null,"marketdefinition":null,"id":"1.258926623"}],"conflatems":null,"op":"mcm","id":3}
{"ct":null,"SegmentType":null,"clk":"APBxALxyAJNy","heartbeatms":null,"pt":1780839706768,"initialclk":null,"mc":[{"rc":[{"tv":null,"batb":null,"spb":null,"bdatl":null,"trd":null,"spf":null,"ltp":null,"atb":[[1.1000000000000001,63479.389999999999]],"spl":null,"spn":null,"atl":[[1.1299999999999999,20521.560000000001]],"batl":null,"id":19924823,"hc":null,"bdatb":null}],"img":null,"tv":null,"con":null,"marketdefinition":null,"id":"1.258926623"}],"conflatems":null,"op":"mcm","id":3}
{"ct":null,"SegmentType":null,"clk":"APdxAMNyAJdy","heartbeatms":null,"pt":1780839706828,"initialclk":null,"mc":[{"rc":[{"tv":null,"batb":null,"spb":null,"bdatl":null,"trd":null,"spf":null,"ltp":null,"atb":[[7.5999999999999996,189.78999999999999]],"spl":null,"spn":null,"atl":[[9.8000000000000007,153.06]],"batl":null,"id":16570658,"hc":null,"bdatb":null},{"tv":null,"batb":null,"spb":null,"bdatl":null,"trd":null,"spf":null,"ltp":null,"atb":[[1.1100000000000001,60831.269999999997]],"spl":null,"spn":null,"atl":[[1.1499999999999999,11325.969999999999]],"batl":null,"id":19924823,"hc":null,"bdatb":null}],"img":null,"tv":null,"con":null,"marketdefinition":null,"id":"1.258926623"}],"conflatems":null,"op":"mcm","id":3}
{"ct":null,"SegmentType":null,"clk":"AIByAM9yAJ1y","heartbeatms":null,"pt":1780839706928,"initialclk":null,"mc":[{"rc":[{"tv":null,"batb":null,"spb":null,"bdatl":null,"trd":null,"spf":null,"ltp":null,"atb":null,"spl":null,"spn":null,"atl":[[9.1999999999999993,135.87000000000001]],"batl":null,"id":16570658,"hc":null,"bdatb":null},{"tv":null,"batb":null,"spb":null,"bdatl":null,"trd":null,"spf":null,"ltp":null,"atb":[[1.1000000000000001,63471.900000000001],[1.1200000000000001,27116.830000000002]],"spl":null,"spn":null,"atl":[[1.1200000000000001,0]],"batl":null,"id":19924823,"hc":null,"bdatb":null}],"img":null,"tv":null,"con":null,"marketdefinition":null,"id":"1.258926623"}],"conflatems":null,"op":"mcm","id":3}
{"ct":null,"SegmentType":null,"clk":"AJJyAORyAK9y","heartbeatms":null,"pt":1780839707144,"initialclk":null,"mc":[{"rc":[{"tv":null,"batb":null,"spb":null,"bdatl":null,"trd":null,"spf":null,"ltp":null,"atb":[[7.5999999999999996,0.98999999999999999]],"spl":null,"spn":null,"atl":[[9.1999999999999993,108.7]],"batl":null,"id":16570658,"hc":null,"bdatb":null},{"tv":null,"batb":null,"spb":null,"bdatl":null,"trd":null,"spf":null,"ltp":null,"atb":[[1.1100000000000001,60474.959999999999],[1.1200000000000001,20512.630000000001]],"spl":null,"spn":null,"atl":[[1.1499999999999999,10078.24]],"batl":null,"id":19924823,"hc":null,"bdatb":null}],"img":null,"tv":null,"con":null,"marketdefinition":null,"id":"1.258926623"}],"conflatems":null,"op":"mcm","id":3}
{"ct":null,"SegmentType":null,"clk":"AJhyAO5yALRy","heartbeatms":null,"pt":1780839707232,"initialclk":null,"mc":[{"rc":[{"tv":null,"batb":null,"spb":null,"bdatl":null,"trd":null,"spf":null,"ltp":null,"atb":null,"spl":null,"spn":null,"atl":[[25,0]],"batl":null,"id":16570658,"hc":null,"bdatb":null}],"img":null,"tv":null,"con":null,"marketdefinition":null,"id":"1.258926623"}],"conflatems":null,"op":"mcm","id":3}
{"ct":null,"SegmentType":null,"clk":"AKdyAPVyAL5y","heartbeatms":null,"pt":1780839707348,"initialclk":null,"mc":[{"rc":[{"tv":242298.35000000001,"batb":null,"spb":null,"bdatl":null,"trd":[[9,167.88999999999999]],"spf":null,"ltp":9,"atb":[[9,245.94999999999999]],"spl":null,"spn":null,"atl":null,"batl":null,"id":16570658,"hc":null,"bdatb":null},{"tv":null,"batb":null,"spb":null,"bdatl":null,"trd":null,"spf":null,"ltp":null,"atb":[[1.1000000000000001,63417.839999999997]],"spl":null,"spn":null,"atl":null,"batl":null,"id":19924823,"hc":null,"bdatb":null}],"img":null,"tv":2255964.1800000002,"con":null,"marketdefinition":null,"id":"1.258926623"}],"conflatems":null,"op":"mcm","id":3}
{"ct":null,"SegmentType":null,"clk":"AMNyAJFzANRy","heartbeatms":null,"pt":1780839707657,"initialclk":null,"mc":[{"rc":[{"tv":null,"batb":null,"spb":null,"bdatl":null,"trd":null,"spf":null,"ltp":null,"atb":null,"spl":null,"spn":null,"atl":[[19.5,44.229999999999997]],"batl":null,"id":16570658,"hc":null,"bdatb":null}],"img":null,"tv":null,"con":null,"marketdefinition":null,"id":"1.258926623"}],"conflatems":null,"op":"mcm","id":3}
{"ct":null,"SegmentType":null,"clk":"AORyALBzAPNy","heartbeatms":null,"pt":1780839708053,"initialclk":null,"mc":[{"rc":[{"tv":null,"batb":null,"spb":null,"bdatl":null,"trd":null,"spf":null,"ltp":null,"atb":[[1.1200000000000001,30333.630000000001]],"spl":null,"spn":null,"atl":null,"batl":null,"id":19924823,"hc":null,"bdatb":null}],"img":null,"tv":null,"con":null,"marketdefinition":null,"id":"1.258926623"}],"conflatems":null,"op":"mcm","id":3}
{"ct":null,"SegmentType":null,"clk":"AKhzAPpzAK1z","heartbeatms":null,"pt":1780839708840,"initialclk":null,"mc":[{"rc":[{"tv":null,"batb":null,"spb":null,"bdatl":null,"trd":null,"spf":null,"ltp":null,"atb":[[1.1100000000000001,60523.040000000001],[1.1200000000000001,30583.630000000001]],"spl":null,"spn":null,"atl":null,"batl":null,"id":19924823,"hc":null,"bdatb":null}],"img":null,"tv":null,"con":null,"marketdefinition":null,"id":"1.258926623"}],"conflatems":null,"op":"mcm","id":3}
{"ct":null,"SegmentType":null,"clk":"ALBzAIh0ALVz","heartbeatms":null,"pt":1780839708949,"initialclk":null,"mc":[{"rc":[{"tv":null,"batb":null,"spb":null,"bdatl":null,"trd":null,"spf":null,"ltp":null,"atb":null,"spl":null,"spn":null,"atl":[[1.1299999999999999,21758.400000000001]],"batl":null,"id":19924823,"hc":null,"bdatb":null}],"img":null,"tv":null,"con":null,"marketdefinition":null,"id":"1.258926623"}],"conflatems":null,"op":"mcm","id":3}
{"ct":null,"SegmentType":null,"clk":"ALhzAJN0AMBz","heartbeatms":null,"pt":1780839709054,"initialclk":null,"mc":[{"rc":[{"tv":null,"batb":null,"spb":null,"bdatl":null,"trd":null,"spf":null,"ltp":null,"atb":[[1.1200000000000001,30833.630000000001]],"spl":null,"spn":null,"atl":null,"batl":null,"id":19924823,"hc":null,"bdatb":null}],"img":null,"tv":null,"con":null,"marketdefinition":null,"id":"1.258926623"}],"conflatems":null,"op":"mcm","id":3}
{"ct":null,"SegmentType":null,"clk":"ANJzAKt0ANlz","heartbeatms":null,"pt":1780839709347,"initialclk":null,"mc":[{"rc":[{"tv":null,"batb":null,"spb":null,"bdatl":null,"trd":null,"spf":null,"ltp":null,"atb":[[8.4000000000000004,240.65000000000001]],"spl":null,"spn":null,"atl":[[11.5,130.53]],"batl":null,"id":16570658,"hc":null,"bdatb":null},{"tv":null,"batb":null,"spb":null,"bdatl":null,"trd":null,"spf":null,"ltp":null,"atb":[[1.0900000000000001,41728.849999999999],[1.1200000000000001,30982.169999999998]],"spl":null,"spn":null,"atl":[[1.1399999999999999,24628.150000000001]],"batl":null,"id":19924823,"hc":null,"bdatb":null}],"img":null,"tv":null,"con":null,"marketdefinition":null,"id":"1.258926623"}],"conflatems":null,"op":"mcm","id":3}
{"ct":null,"SegmentType":null,"clk":"APhzANp0APxz","heartbeatms":null,"pt":1780839709836,"initialclk":null,"mc":[{"rc":[{"tv":null,"batb":null,"spb":null,"bdatl":null,"trd":null,"spf":null,"ltp":null,"atb":null,"spl":null,"spn":null,"atl":[[1.1299999999999999,22186.279999999999],[6,16.579999999999998]],"batl":null,"id":19924823,"hc":null,"bdatb":null}],"img":null,"tv":null,"con":null,"marketdefinition":null,"id":"1.258926623"}],"conflatems":null,"op":"mcm","id":3}
{"ct":null,"SegmentType":null,"clk":"AIB0AOV0AIB0","heartbeatms":null,"pt":1780839709934,"initialclk":null,"mc":[{"rc":[{"tv":null,"batb":null,"spb":null,"bdatl":null,"trd":null,"spf":null,"ltp":null,"atb":[[9,388.13999999999999]],"spl":null,"spn":null,"atl":[[9.1999999999999993,248.83000000000001]],"batl":null,"id":16570658,"hc":null,"bdatb":null},{"tv":null,"batb":null,"spb":null,"bdatl":null,"trd":null,"spf":null,"ltp":null,"atb":[[1.1200000000000001,32124.77]],"spl":null,"spn":null,"atl":[[1.1299999999999999,23318.77]],"batl":null,"id":19924823,"hc":null,"bdatb":null}],"img":null,"tv":null,"con":null,"marketdefinition":null,"id":"1.258926623"}],"conflatems":null,"op":"mcm","id":3}
{"ct":null,"SegmentType":null,"clk":"AIt0APB0AIh0","heartbeatms":null,"pt":1780839710043,"initialclk":null,"mc":[{"rc":[{"tv":null,"batb":null,"spb":null,"bdatl":null,"trd":null,"spf":null,"ltp":null,"atb":[[7,0]],"spl":null,"spn":null,"atl":null,"batl":null,"id":16570658,"hc":null,"bdatb":null},{"tv":null,"batb":null,"spb":null,"bdatl":null,"trd":null,"spf":null,"ltp":null,"atb":[[1.1100000000000001,60228.290000000001]],"spl":null,"spn":null,"atl":null,"batl":null,"id":19924823,"hc":null,"bdatb":null}],"img":null,"tv":null,"con":null,"marketdefinition":null,"id":"1.258926623"}],"conflatems":null,"op":"mcm","id":3}
{"ct":null,"SegmentType":null,"clk":"AJZ0AP10AI10","heartbeatms":null,"pt":1780839710141,"initialclk":null,"mc":[{"rc":[{"tv":null,"batb":null,"spb":null,"bdatl":null,"trd":null,"spf":null,"ltp":null,"atb":[[8.1999999999999993,582.01999999999998]],"spl":null,"spn":null,"atl":null,"batl":null,"id":16570658,"hc":null,"bdatb":null}],"img":null,"tv":null,"con":null,"marketdefinition":null,"id":"1.258926623"}],"conflatems":null,"op":"mcm","id":3}
{"ct":null,"SegmentType":null,"clk":"ALB0AKl1AKN0","heartbeatms":null,"pt":1780839710451,"initialclk":null,"mc":[{"rc":[{"tv":null,"batb":null,"spb":null,"bdatl":null,"trd":null,"spf":null,"ltp":null,"atb":[[1.1200000000000001,22303.77]],"spl":null,"spn":null,"atl":null,"batl":null,"id":19924823,"hc":null,"bdatb":null}],"img":null,"tv":null,"con":null,"marketdefinition":null,"id":"1.258926623"}],"conflatems":null,"op":"mcm","id":3}
{"ct":null,"SegmentType":null,"clk":"ANR0AMt1AL50","heartbeatms":null,"pt":1780839710854,"initialclk":null,"mc":[{"rc":[{"tv":null,"batb":null,"spb":null,"bdatl":null,"trd":null,"spf":null,"ltp":null,"atb":null,"spl":null,"spn":null,"atl":[[1.1399999999999999,24630.150000000001]],"batl":null,"id":19924823,"hc":null,"bdatb":null}],"img":null,"tv":null,"con":null,"marketdefinition":null,"id":"1.258926623"}],"conflatems":null,"op":"mcm","id":3}
{"ct":null,"SegmentType":null,"clk":"AOl0AON1AMx0","heartbeatms":null,"pt":1780839711062,"initialclk":null,"mc":[{"rc":[{"tv":null,"batb":null,"spb":null,"bdatl":null,"trd":null,"spf":null,"ltp":null,"atb":null,"spl":null,"spn":null,"atl":[[1.1399999999999999,24628.150000000001]],"batl":null,"id":19924823,"hc":null,"bdatb":null}],"img":null,"tv":null,"con":null,"marketdefinition":null,"id":"1.258926623"}],"conflatems":null,"op":"mcm","id":3}
{"ct":null,"SegmentType":null,"clk":"AO90AOx1ANB0","heartbeatms":null,"pt":1780839711126,"initialclk":null,"mc":[{"rc":[{"tv":null,"batb":null,"spb":null,"bdatl":null,"trd":null,"spf":null,"ltp":null,"atb":[[8.8000000000000007,15.09]],"spl":null,"spn":null,"atl":null,"batl":null,"id":16570658,"hc":null,"bdatb":null}],"img":null,"tv":null,"con":null,"marketdefinition":null,"id":"1.258926623"}],"conflatems":null,"op":"mcm","id":3}
{"ct":null,"SegmentType":null,"clk":"Aid1APx1AN50","heartbeatms":null,"pt":1780839711376,"initialclk":null,"mc":[{"rc":[{"tv":null,"batb":null,"spb":null,"bdatl":null,"trd":null,"spf":null,"ltp":null,"atb":[[1.1200000000000001,23548.48]],"spl":null,"spn":null,"atl":null,"batl":null,"id":19924823,"hc":null,"bdatb":null}],"img":null,"tv":null,"con":null,"marketdefinition":null,"id":"1.258926623"}],"conflatems":null,"op":"mcm","id":3}
{"ct":null,"SegmentType":null,"clk":"AI11AIl2AOJ0","heartbeatms":null,"pt":1780839711443,"initialclk":null,"mc":[{"rc":[{"tv":null,"batb":null,"spb":null,"bdatl":null,"trd":null,"spf":null,"ltp":null,"atb":null,"spl":null,"spn":null,"atl":[[12.5,101.17]],"batl":null,"id":16570658,"hc":null,"bdatb":null},{"tv":null,"batb":null,"spb":null,"bdatl":null,"trd":null,"spf":null,"ltp":null,"atb":[[1.05,74261.529999999999]],"spl":null,"spn":null,"atl":null,"batl":null,"id":19924823,"hc":null,"bdatb":null}],"img":null,"tv":null,"con":null,"marketdefinition":null,"id":"1.258926623"}],"conflatems":null,"op":"mcm","id":3}
{"ct":null,"SegmentType":null,"clk":"AJV1AJN2AOl0","heartbeatms":null,"pt":1780839711541,"initialclk":null,"mc":[{"rc":[{"tv":null,"batb":null,"spb":null,"bdatl":null,"trd":null,"spf":null,"ltp":null,"atb":null,"spl":null,"spn":null,"atl":[[9.1999999999999993,257.35000000000002]],"batl":null,"id":16570658,"hc":null,"bdatb":null},{"tv":null,"batb":null,"spb":null,"bdatl":null,"trd":null,"spf":null,"ltp":null,"atb":[[1.1100000000000001,60864.650000000001],[1.1200000000000001,24793.189999999999]],"spl":null,"spn":null,"atl":null,"batl":null,"id":19924823,"hc":null,"bdatb":null}],"img":null,"tv":null,"con":null,"marketdefinition":null,"id":"1.258926623"}],"conflatems":null,"op":"mcm","id":3}
{"ct":null,"SegmentType":null,"clk":"AKB1AJp2APB0","heartbeatms":null,"pt":1780839711638,"initialclk":null,"mc":[{"rc":[{"tv":null,"batb":null,"spb":null,"bdatl":null,"trd":null,"spf":null,"ltp":null,"atb":[[1.1200000000000001,26037.900000000001]],"spl":null,"spn":null,"atl":null,"batl":null,"id":19924823,"hc":null,"bdatb":null}],"img":null,"tv":null,"con":null,"marketdefinition":null,"id":"1.258926623"}],"conflatems":null,"op":"mcm","id":3}
{"ct":null,"SegmentType":null,"clk":"AMR1AMx2AJF1","heartbeatms":null,"pt":1780839712165,"initialclk":null,"mc":[{"rc":[{"tv":null,"batb":null,"spb":null,"bdatl":null,"trd":null,"spf":null,"ltp":null,"atb":null,"spl":null,"spn":null,"atl":[[9.1999999999999993,342.86000000000001]],"batl":null,"id":16570658,"hc":null,"bdatb":null}],"img":null,"tv":null,"con":null,"marketdefinition":null,"id":"1.258926623"}],"conflatems":null,"op":"mcm","id":3}
{"ct":null,"SegmentType":null,"clk":"APl1AIZ3ALl1","heartbeatms":null,"pt":1780839712732,"initialclk":null,"mc":[{"rc":[{"tv":null,"batb":null,"spb":null,"bdatl":null,"trd":null,"spf":null,"ltp":null,"atb":[[1.1100000000000001,62109.360000000001]],"spl":null,"spn":null,"atl":null,"batl":null,"id":19924823,"hc":null,"bdatb":null}],"img":null,"tv":null,"con":null,"marketdefinition":null,"id":"1.258926623"}],"conflatems":null,"op":"mcm","id":3}
{"ct":null,"SegmentType":null,"clk":"AJd2AKJ3AM91","heartbeatms":null,"pt":1780839713044,"initialclk":null,"mc":[{"rc":[{"tv":null,"batb":null,"spb":null,"bdatl":null,"trd":null,"spf":null,"ltp":null,"atb":[[1.1100000000000001,63354.07]],"spl":null,"spn":null,"atl":null,"batl":null,"id":19924823,"hc":null,"bdatb":null}],"img":null,"tv":null,"con":null,"marketdefinition":null,"id":"1.258926623"}],"conflatems":null,"op":"mcm","id":3}
{"ct":null,"SegmentType":null,"clk":"AK12ALR3AOJ1","heartbeatms":null,"pt":1780839713254,"initialclk":null,"mc":[{"rc":[{"tv":null,"batb":null,"spb":null,"bdatl":null,"trd":null,"spf":null,"ltp":null,"atb":null,"spl":null,"spn":null,"atl":[[12,304.56]],"batl":null,"id":16570658,"hc":null,"bdatb":null},{"tv":null,"batb":null,"spb":null,"bdatl":null,"trd":null,"spf":null,"ltp":null,"atb":null,"spl":null,"spn":null,"atl":[[1.24,205.93000000000001],[1.23,683.77999999999997]],"batl":null,"id":19924823,"hc":null,"bdatb":null}],"img":null,"tv":null,"con":null,"marketdefinition":null,"id":"1.258926623"}],"conflatems":null,"op":"mcm","id":3}
{"ct":null,"SegmentType":null,"clk":"ALl2AL93AOd1","heartbeatms":null,"pt":1780839713353,"initialclk":null,"mc":[{"rc":[{"tv":null,"batb":null,"spb":null,"bdatl":null,"trd":null,"spf":null,"ltp":null,"atb":[[7.4000000000000004,31.09],[7.2000000000000002,12.279999999999999]],"spl":null,"spn":null,"atl":[[11.5,131.53],[11,106.81],[10,95.010000000000005]],"batl":null,"id":16570658,"hc":null,"bdatb":null},{"tv":null,"batb":null,"spb":null,"bdatl":null,"trd":null,"spf":null,"ltp":null,"atb":[[1.1000000000000001,63424.139999999999],[1.0900000000000001,41735.68],[1.1100000000000001,63360.220000000001]],"spl":null,"spn":null,"atl":[[1.1699999999999999,9381.6299999999992],[1.1599999999999999,8938.7900000000009]],"batl":null,"id":19924823,"hc":null,"bdatb":null}],"img":null,"tv":null,"con":null,"marketdefinition":null,"id":"1.258926623"}],"conflatems":null,"op":"mcm","id":3}
{"ct":null,"SegmentType":null,"clk":"APF2APN3AJZ2","heartbeatms":null,"pt":1780839713961,"initialclk":null,"mc":[{"rc":[{"tv":null,"batb":null,"spb":null,"bdatl":null,"trd":null,"spf":null,"ltp":null,"atb":null,"spl":null,"spn":null,"atl":[[1.22,8862.3500000000004]],"batl":null,"id":19924823,"hc":null,"bdatb":null}],"img":null,"tv":null,"con":null,"marketdefinition":null,"id":"1.258926623"}],"conflatems":null,"op":"mcm","id":3}
{"ct":null,"SegmentType":null,"clk":"Aid3AIF4AKF2","heartbeatms":null,"pt":1780839714127,"initialclk":null,"mc":[{"rc":[{"tv":null,"batb":null,"spb":null,"bdatl":null,"trd":null,"spf":null,"ltp":null,"atb":[[9,388.19]],"spl":null,"spn":null,"atl":null,"batl":null,"id":16570658,"hc":null,"bdatb":null},{"tv":null,"batb":null,"spb":null,"bdatl":null,"trd":null,"spf":null,"ltp":null,"atb":[[1.1200000000000001,26237.900000000001]],"spl":null,"spn":null,"atl":null,"batl":null,"id":19924823,"hc":null,"bdatb":null}],"img":null,"tv":null,"con":null,"marketdefinition":null,"id":"1.258926623"}],"conflatems":null,"op":"mcm","id":3}
{"ct":null,"SegmentType":null,"clk":"AKJ3AJ94ALZ2","heartbeatms":null,"pt":1780839714442,"initialclk":null,"mc":[{"rc":[{"tv":null,"batb":null,"spb":null,"bdatl":null,"trd":null,"spf":null,"ltp":null,"atb":[[1.1200000000000001,22503.77]],"spl":null,"spn":null,"atl":null,"batl":null,"id":19924823,"hc":null,"bdatb":null}],"img":null,"tv":null,"con":null,"marketdefinition":null,"id":"1.258926623"}],"conflatems":null,"op":"mcm","id":3}
{"ct":null,"SegmentType":null,"clk":"AKx3AKl4ALx2","heartbeatms":null,"pt":1780839714544,"initialclk":null,"mc":[{"rc":[{"tv":null,"batb":null,"spb":null,"bdatl":null,"trd":null,"spf":null,"ltp":null,"atb":null,"spl":null,"spn":null,"atl":[[1000,1.04]],"batl":null,"id":19924823,"hc":null,"bdatb":null}],"img":null,"tv":null,"con":null,"marketdefinition":null,"id":"1.258926623"}],"conflatems":null,"op":"mcm","id":3}
{"ct":null,"SegmentType":null,"clk":"ALp3ALx4AM92","heartbeatms":null,"pt":1780839714744,"initialclk":null,"mc":[{"rc":[{"tv":242338.35000000001,"batb":null,"spb":null,"bdatl":null,"trd":[[9,207.88999999999999]],"spf":null,"ltp":null,"atb":[[9,368.19]],"spl":null,"spn":null,"atl":null,"batl":null,"id":16570658,"hc":null,"bdatb":null},{"tv":null,"batb":null,"spb":null,"bdatl":null,"trd":null,"spf":null,"ltp":null,"atb":[[1.1100000000000001,64604.93]],"spl":null,"spn":null,"atl":null,"batl":null,"id":19924823,"hc":null,"bdatb":null}],"img":null,"tv":2256004.1800000002,"con":null,"marketdefinition":null,"id":"1.258926623"}],"conflatems":null,"op":"mcm","id":3}
{"ct":null,"SegmentType":null,"clk":"AMJ3AM14ANp2","heartbeatms":null,"pt":1780839714853,"initialclk":null,"mc":[{"rc":[{"tv":null,"batb":null,"spb":null,"bdatl":null,"trd":null,"spf":null,"ltp":null,"atb":[[7.7999999999999998,271.20999999999998],[8.8000000000000007,152.68000000000001]],"spl":null,"spn":null,"atl":[[9.5999999999999996,156.25]],"batl":null,"id":16570658,"hc":null,"bdatb":null},{"tv":null,"batb":null,"spb":null,"bdatl":null,"trd":null,"spf":null,"ltp":null,"atb":[[1.1100000000000001,65849.630000000005]],"spl":null,"spn":null,"atl":[[1.1499999999999999,11340.540000000001]],"batl":null,"id":19924823,"hc":null,"bdatb":null}],"img":null,"tv":null,"con":null,"marketdefinition":null,"id":"1.258926623"}],"conflatems":null,"op":"mcm","id":3}
{"ct":null,"SegmentType":null,"clk":"AMh3ANN4AN92","heartbeatms":null,"pt":1780839714953,"initialclk":null,"mc":[{"rc":[{"tv":null,"batb":null,"spb":null,"bdatl":null,"trd":null,"spf":null,"ltp":null,"atb":null,"spl":null,"spn":null,"atl":[[1000,0.88]],"batl":null,"id":19924823,"hc":null,"bdatb":null}],"img":null,"tv":null,"con":null,"marketdefinition":null,"id":"1.258926623"}],"conflatems":null,"op":"mcm","id":3}
{"ct":null,"SegmentType":null,"clk":"ANR3AN14AOd2","heartbeatms":null,"pt":1780839715055,"initialclk":null,"mc":[{"rc":[{"tv":242339.79000000001,"batb":null,"spb":null,"bdatl":null,"trd":[[9,209.33000000000001]],"spf":null,"ltp":null,"atb":[[9,367.45999999999998]],"spl":null,"spn":null,"atl":null,"batl":null,"id":16570658,"hc":null,"bdatb":null}],"img":null,"tv":2256005.6200000001,"con":null,"marketdefinition":null,"id":"1.258926623"}],"conflatems":null,"op":"mcm","id":3}
{"ct":null,"SegmentType":null,"clk":"AN13AOR4AO12","heartbeatms":null,"pt":1780839715159,"initialclk":null,"mc":[{"rc":[{"tv":null,"batb":null,"spb":null,"bdatl":null,"trd":null,"spf":null,"ltp":null,"atb":null,"spl":null,"spn":null,"atl":[[9.8000000000000007,0]],"batl":null,"id":16570658,"hc":null,"bdatb":null},{"tv":null,"batb":null,"spb":null,"bdatl":null,"trd":null,"spf":null,"ltp":null,"atb":[[1.1100000000000001,67094.339999999997]],"spl":null,"spn":null,"atl":null,"batl":null,"id":19924823,"hc":null,"bdatb":null}],"img":null,"tv":null,"con":null,"marketdefinition":null,"id":"1.258926623"}],"conflatems":null,"op":"mcm","id":3}
{"ct":null,"SegmentType":null,"clk":"AKx4ALx5AJ93","heartbeatms":null,"pt":1780839716048,"initialclk":null,"mc":[{"rc":[{"tv":null,"batb":null,"spb":null,"bdatl":null,"trd":null,"spf":null,"ltp":null,"atb":[[7.7999999999999998,270.35000000000002],[7.5999999999999996,0]],"spl":null,"spn":null,"atl":[[10.5,1.25],[10,94.150000000000006]],"batl":null,"id":16570658,"hc":null,"bdatb":null},{"tv":null,"batb":null,"spb":null,"bdatl":null,"trd":null,"spf":null,"ltp":null,"atb":[[1.1000000000000001,63418.559999999998],[1.1100000000000001,67090.139999999999]],"spl":null,"spn":null,"atl":[[1.1599999999999999,8933.1100000000006],[1.1499999999999999,11335.4]],"batl":null,"id":19924823,"hc":null,"bdatb":null}],"img":null,"tv":null,"con":null,"marketdefinition":null,"id":"1.258926623"}],"conflatems":null,"op":"mcm","id":3}
{"ct":null,"SegmentType":null,"clk":"APp4AI56AON3","heartbeatms":null,"pt":1780839716970,"initialclk":null,"mc":[{"rc":[{"tv":2013672.51,"batb":null,"spb":null,"bdatl":null,"trd":[[1.1299999999999999,199817.59]],"spf":null,"ltp":1.1299999999999999,"atb":null,"spl":null,"spn":null,"atl":[[1.1299999999999999,23315.43]],"batl":null,"id":19924823,"hc":null,"bdatb":null}],"img":null,"tv":2256012.2999999998,"con":null,"marketdefinition":null,"id":"1.258926623"}],"conflatems":null,"op":"mcm","id":3}
{"ct":null,"SegmentType":null,"clk":"AI55AKd6APR3","heartbeatms":null,"pt":1780839717145,"initialclk":null,"mc":[{"rc":[{"tv":242339.87,"batb":null,"spb":null,"bdatl":null,"trd":[[9.1999999999999993,1596.3599999999999]],"spf":null,"ltp":9.1999999999999993,"atb":null,"spl":null,"spn":null,"atl":[[9.1999999999999993,342.81999999999999]],"batl":null,"id":16570658,"hc":null,"bdatb":null}],"img":null,"tv":2256012.3799999999,"con":null,"marketdefinition":null,"id":"1.258926623"}],"conflatems":null,"op":"mcm","id":3}
{"ct":null,"SegmentType":null,"clk":"AJp5ALR6AIB4","heartbeatms":null,"pt":1780839717252,"initialclk":null,"mc":[{"rc":[{"tv":null,"batb":null,"spb":null,"bdatl":null,"trd":null,"spf":null,"ltp":null,"atb":[[1.1100000000000001,67170.119999999995]],"spl":null,"spn":null,"atl":[[1.1299999999999999,23393.57]],"batl":null,"id":19924823,"hc":null,"bdatb":null}],"img":null,"tv":null,"con":null,"marketdefinition":null,"id":"1.258926623"}],"conflatems":null,"op":"mcm","id":3}
{"ct":null,"SegmentType":null,"clk":"AKN5AL56AIl4","heartbeatms":null,"pt":1780839717348,"initialclk":null,"mc":[{"rc":[{"tv":null,"batb":null,"spb":null,"bdatl":null,"trd":null,"spf":null,"ltp":null,"atb":[[1.1200000000000001,22424.509999999998]],"spl":null,"spn":null,"atl":null,"batl":null,"id":19924823,"hc":null,"bdatb":null}],"img":null,"tv":null,"con":null,"marketdefinition":null,"id":"1.258926623"}],"conflatems":null,"op":"mcm","id":3}
{"ct":null,"SegmentType":null,"clk":"ALV5ANJ6AJd4","heartbeatms":null,"pt":1780839717552,"initialclk":null,"mc":[{"rc":[{"tv":null,"batb":null,"spb":null,"bdatl":null,"trd":null,"spf":null,"ltp":null,"atb":null,"spl":null,"spn":null,"atl":[[1.22,9062.3500000000004]],"batl":null,"id":19924823,"hc":null,"bdatb":null}],"img":null,"tv":null,"con":null,"marketdefinition":null,"id":"1.258926623"}],"conflatems":null,"op":"mcm","id":3}
{"ct":null,"SegmentType":null,"clk":"AOl5AIp7ALF4","heartbeatms":null,"pt":1780839718072,"initialclk":null,"mc":[{"rc":[{"tv":2013672.8300000001,"batb":null,"spb":null,"bdatl":null,"trd":[[1.1200000000000001,55900.029999999999]],"spf":null,"ltp":1.1200000000000001,"atb":[[1.1200000000000001,22424.349999999999]],"spl":null,"spn":null,"atl":[[1.1399999999999999,27516.720000000001]],"batl":null,"id":19924823,"hc":null,"bdatb":null}],"img":null,"tv":2256012.7000000002,"con":null,"marketdefinition":null,"id":"1.258926623"}],"conflatems":null,"op":"mcm","id":3}
{"ct":null,"SegmentType":null,"clk":"APB5AJF7ALV4","heartbeatms":null,"pt":1780839718162,"initialclk":null,"mc":[{"rc":[{"tv":null,"batb":null,"spb":null,"bdatl":null,"trd":null,"spf":null,"ltp":null,"atb":null,"spl":null,"spn":null,"atl":[[1.1299999999999999,23394.57]],"batl":null,"id":19924823,"hc":null,"bdatb":null}],"img":null,"tv":null,"con":null,"marketdefinition":null,"id":"1.258926623"}],"conflatems":null,"op":"mcm","id":3}
{"ct":null,"SegmentType":null,"clk":"APl5AJl7ALp4","heartbeatms":null,"pt":1780839718266,"initialclk":null,"mc":[{"rc":[{"tv":null,"batb":null,"spb":null,"bdatl":null,"trd":null,"spf":null,"ltp":null,"atb":[[1.1200000000000001,22416.849999999999]],"spl":null,"spn":null,"atl":null,"batl":null,"id":19924823,"hc":null,"bdatb":null}],"img":null,"tv":null,"con":null,"marketdefinition":null,"id":"1.258926623"}],"conflatems":null,"op":"mcm","id":3}
{"ct":null,"SegmentType":null,"clk":"AIN6AKV7AMJ4","heartbeatms":null,"pt":1780839718367,"initialclk":null,"mc":[{"rc":[{"tv":null,"batb":null,"spb":null,"bdatl":null,"trd":null,"spf":null,"ltp":null,"atb":null,"spl":null,"spn":null,"atl":[[1.24,5.9299999999999997]],"batl":null,"id":19924823,"hc":null,"bdatb":null}],"img":null,"tv":null,"con":null,"marketdefinition":null,"id":"1.258926623"}],"conflatems":null,"op":"mcm","id":3}
{"ct":null,"SegmentType":null,"clk":"AJ16AMd7ANp4","heartbeatms":null,"pt":1780839718673,"initialclk":null,"mc":[{"rc":[{"tv":null,"batb":null,"spb":null,"bdatl":null,"trd":null,"spf":null,"ltp":null,"atb":[[1.1200000000000001,22216.849999999999]],"spl":null,"spn":null,"atl":null,"batl":null,"id":19924823,"hc":null,"bdatb":null}],"img":null,"tv":null,"con":null,"marketdefinition":null,"id":"1.258926623"}],"conflatems":null,"op":"mcm","id":3}
{"ct":null,"SegmentType":null,"clk":"AJR7AON8AMd5","heartbeatms":null,"pt":1780839720138,"initialclk":null,"mc":[{"rc":[{"tv":null,"batb":null,"spb":null,"bdatl":null,"trd":null,"spf":null,"ltp":null,"atb":[[1.1100000000000001,67223.699999999997]],"spl":null,"spn":null,"atl":null,"batl":null,"id":19924823,"hc":null,"bdatb":null}],"img":null,"tv":null,"con":null,"marketdefinition":null,"id":"1.258926623"}],"conflatems":null,"op":"mcm","id":3}
{"ct":null,"SegmentType":null,"clk":"AJt7AO18AMl5","heartbeatms":null,"pt":1780839720231,"initialclk":null,"mc":[{"rc":[{"tv":null,"batb":null,"spb":null,"bdatl":null,"trd":null,"spf":null,"ltp":null,"atb":[[7.5999999999999996,12.94]],"spl":null,"spn":null,"atl":[[10.5,3.25]],"batl":null,"id":16570658,"hc":null,"bdatb":null},{"tv":null,"batb":null,"spb":null,"bdatl":null,"trd":null,"spf":null,"ltp":null,"atb":[[1.1100000000000001,67225.699999999997]],"spl":null,"spn":null,"atl":[[1.1299999999999999,22966.689999999999],[1.1499999999999999,11646.9]],"batl":null,"id":19924823,"hc":null,"bdatb":null}],"img":null,"tv":null,"con":null,"marketdefinition":null,"id":"1.258926623"}],"conflatems":null,"op":"mcm","id":3}
{"ct":null,"SegmentType":null,"clk":"AKN7APp8ANF5","heartbeatms":null,"pt":1780839720345,"initialclk":null,"mc":[{"rc":[{"tv":null,"batb":null,"spb":null,"bdatl":null,"trd":null,"spf":null,"ltp":null,"atb":[[8.4000000000000004,170.65000000000001]],"spl":null,"spn":null,"atl":[[9.4000000000000004,0],[12.5,99.170000000000002],[11.5,60.530000000000001],[9.1999999999999993,224.61000000000001]],"batl":null,"id":16570658,"hc":null,"bdatb":null},{"tv":null,"batb":null,"spb":null,"bdatl":null,"trd":null,"spf":null,"ltp":null,"atb":[[1.0900000000000001,40112.68],[1.1200000000000001,22214.849999999999]],"spl":null,"spn":null,"atl":[[1.1399999999999999,26048.720000000001]],"batl":null,"id":19924823,"hc":null,"bdatb":null}],"img":null,"tv":null,"con":null,"marketdefinition":null,"id":"1.258926623"}],"conflatems":null,"op":"mcm","id":3}
{"ct":null,"SegmentType":null,"clk":"AKx7AP58ANV5","heartbeatms":null,"pt":1780839720439,"initialclk":null,"mc":[{"rc":[{"tv":null,"batb":null,"spb":null,"bdatl":null,"trd":null,"spf":null,"ltp":null,"atb":[[7.7999999999999998,84.25],[7.4000000000000004,307.41000000000003],[7.2000000000000002,112.15000000000001]],"spl":null,"spn":null,"atl":[[11,234.15000000000001],[10.5,278.31],[9.5999999999999996,0]],"batl":null,"id":16570658,"hc":null,"bdatb":null},{"tv":null,"batb":null,"spb":null,"bdatl":null,"trd":null,"spf":null,"ltp":null,"atb":[[1.1100000000000001,65874.360000000001]],"spl":null,"spn":null,"atl":[[1.1499999999999999,10384.6]],"batl":null,"id":19924823,"hc":null,"bdatb":null}],"img":null,"tv":null,"con":null,"marketdefinition":null,"id":"1.258926623"}],"conflatems":null,"op":"mcm","id":3}
{"ct":null,"SegmentType":null,"clk":"ALZ7AIl9AOJ5","heartbeatms":null,"pt":1780839720556,"initialclk":null,"mc":[{"rc":[{"tv":null,"batb":null,"spb":null,"bdatl":null,"trd":null,"spf":null,"ltp":null,"atb":[[8.8000000000000007,15.09],[9,225.27000000000001]],"spl":null,"spn":null,"atl":[[9.1999999999999993,85.510000000000005]],"batl":null,"id":16570658,"hc":null,"bdatb":null},{"tv":null,"batb":null,"spb":null,"bdatl":null,"trd":null,"spf":null,"ltp":null,"atb":[[1.1200000000000001,21072.25]],"spl":null,"spn":null,"atl":[[1.1299999999999999,21834.200000000001]],"batl":null,"id":19924823,"hc":null,"bdatb":null}],"img":null,"tv":null,"con":null,"marketdefinition":null,"id":"1.258926623"}],"conflatems":null,"op":"mcm","id":3}
{"ct":null,"SegmentType":null,"clk":"AMR7AJd9APB5","heartbeatms":null,"pt":1780839720673,"initialclk":null,"mc":[{"rc":[{"tv":null,"batb":null,"spb":null,"bdatl":null,"trd":null,"spf":null,"ltp":null,"atb":[[8.4000000000000004,1],[8.5999999999999996,42.609999999999999]],"spl":null,"spn":null,"atl":null,"batl":null,"id":16570658,"hc":null,"bdatb":null},{"tv":null,"batb":null,"spb":null,"bdatl":null,"trd":null,"spf":null,"ltp":null,"atb":[[1.1100000000000001,61488.07]],"spl":null,"spn":null,"atl":null,"batl":null,"id":19924823,"hc":null,"bdatb":null}],"img":null,"tv":null,"con":null,"marketdefinition":null,"id":"1.258926623"}],"conflatems":null,"op":"mcm","id":3}
{"ct":null,"SegmentType":null,"clk":"AM97AKF9AP55","heartbeatms":null,"pt":1780839720776,"initialclk":null,"mc":[{"rc":[{"tv":null,"batb":null,"spb":null,"bdatl":null,"trd":null,"spf":null,"ltp":null,"atb":[[7.7999999999999998,0],[8,59.049999999999997]],"spl":null,"spn":null,"atl":[[12.5,0],[12,6.3600000000000003]],"batl":null,"id":16570658,"hc":null,"bdatb":null},{"tv":null,"batb":null,"spb":null,"bdatl":null,"trd":null,"spf":null,"ltp":null,"atb":[[1.1100000000000001,59359.959999999999],[1.1200000000000001,19024.400000000001]],"spl":null,"spn":null,"atl":null,"batl":null,"id":19924823,"hc":null,"bdatb":null}],"img":null,"tv":null,"con":null,"marketdefinition":null,"id":"1.258926623"}],"conflatems":null,"op":"mcm","id":3}
{"ct":null,"SegmentType":null,"clk":"AIN8ANF9AKN6","heartbeatms":null,"pt":1780839721345,"initialclk":null,"mc":[{"rc":[{"tv":null,"batb":null,"spb":null,"bdatl":null,"trd":null,"spf":null,"ltp":null,"atb":[[9,225.22999999999999]],"spl":null,"spn":null,"atl":null,"batl":null,"id":16570658,"hc":null,"bdatb":null},{"tv":null,"batb":null,"spb":null,"bdatl":null,"trd":null,"spf":null,"ltp":null,"atb":[[1.04,73813.479999999996]],"spl":null,"spn":null,"atl":null,"batl":null,"id":19924823,"hc":null,"bdatb":null}],"img":null,"tv":null,"con":null,"marketdefinition":null,"id":"1.258926623"}],"conflatems":null,"op":"mcm","id":3}
{"ct":null,"SegmentType":null,"clk":"AJF8AON9ALB6","heartbeatms":null,"pt":1780839721553,"initialclk":null,"mc":[{"rc":[{"tv":null,"batb":null,"spb":null,"bdatl":null,"trd":null,"spf":null,"ltp":null,"atb":[[1.1100000000000001,59306.379999999997]],"spl":null,"spn":null,"atl":null,"batl":null,"id":19924823,"hc":null,"bdatb":null}],"img":null,"tv":null,"con":null,"marketdefinition":null,"id":"1.258926623"}],"conflatems":null,"op":"mcm","id":3}
{"ct":null,"SegmentType":null,"clk":"ALV8AMZ\u002BAMd6","heartbeatms":null,"pt":1780839721866,"initialclk":null,"mc":[{"rc":[{"tv":null,"batb":null,"spb":null,"bdatl":null,"trd":null,"spf":null,"ltp":null,"atb":[[1.1000000000000001,64423.690000000002]],"spl":null,"spn":null,"atl":[[1.1499999999999999,11277.81]],"batl":null,"id":19924823,"hc":null,"bdatb":null}],"img":null,"tv":null,"con":null,"marketdefinition":null,"id":"1.258926623"}],"conflatems":null,"op":"mcm","id":3}
{"ct":null,"SegmentType":null,"clk":"AMJ8ANN\u002BAM56","heartbeatms":null,"pt":1780839721982,"initialclk":null,"mc":[{"rc":[{"tv":2014272.8300000001,"batb":null,"spb":null,"bdatl":null,"trd":[[1.1200000000000001,56500.029999999999]],"spf":null,"ltp":null,"atb":[[1.1100000000000001,58960.239999999998],[1.1200000000000001,18080.259999999998]],"spl":null,"spn":null,"atl":[[1.1299999999999999,21242.66]],"batl":null,"id":19924823,"hc":null,"bdatb":null}],"img":null,"tv":2256612.7000000002,"con":null,"marketdefinition":null,"id":"1.258926623"}],"conflatems":null,"op":"mcm","id":3}
{"ct":null,"SegmentType":null,"clk":"ANF8AOZ\u002BAN56","heartbeatms":null,"pt":1780839722167,"initialclk":null,"mc":[{"rc":[{"tv":2014314.8300000001,"batb":null,"spb":null,"bdatl":null,"trd":[[1.1200000000000001,56542.029999999999]],"spf":null,"ltp":null,"atb":[[1.1200000000000001,18059.259999999998]],"spl":null,"spn":null,"atl":null,"batl":null,"id":19924823,"hc":null,"bdatb":null}],"img":null,"tv":2256654.7000000002,"con":null,"marketdefinition":null,"id":"1.258926623"}],"conflatems":null,"op":"mcm","id":3}
{"ct":null,"SegmentType":null,"clk":"AKh9ALd/AJp7","heartbeatms":null,"pt":1780839722945,"initialclk":null,"mc":[{"rc":[{"tv":2014331.3899999999,"batb":null,"spb":null,"bdatl":null,"trd":[[1.1299999999999999,199834.14999999999]],"spf":null,"ltp":1.1299999999999999,"atb":null,"spl":null,"spn":null,"atl":[[1.1299999999999999,21234.380000000001]],"batl":null,"id":19924823,"hc":null,"bdatb":null}],"img":null,"tv":2256671.2599999998,"con":null,"marketdefinition":null,"id":"1.258926623"}],"conflatems":null,"op":"mcm","id":3}
{"ct":null,"SegmentType":null,"clk":"ALN9AMF/AKN7","heartbeatms":null,"pt":1780839723051,"initialclk":null,"mc":[{"rc":[{"tv":2014494.6399999999,"batb":null,"spb":null,"bdatl":null,"trd":[[1.1299999999999999,199997.39999999999]],"spf":null,"ltp":null,"atb":null,"spl":null,"spn":null,"atl":[[1.1299999999999999,21152.759999999998],[1.25,30.899999999999999]],"batl":null,"id":19924823,"hc":null,"bdatb":null}],"img":null,"tv":2256834.5099999998,"con":null,"marketdefinition":null,"id":"1.258926623"}],"conflatems":null,"op":"mcm","id":3}
{"ct":null,"SegmentType":null,"clk":"AMt\u002BAMSAAQCBfA==","heartbeatms":null,"pt":1780839724349,"initialclk":null,"mc":[{"rc":[{"tv":null,"batb":null,"spb":null,"bdatl":null,"trd":null,"spf":null,"ltp":null,"atb":null,"spl":null,"spn":null,"atl":[[10,93.280000000000001]],"batl":null,"id":16570658,"hc":null,"bdatb":null},{"tv":null,"batb":null,"spb":null,"bdatl":null,"trd":null,"spf":null,"ltp":null,"atb":[[1.1100000000000001,58954.089999999997]],"spl":null,"spn":null,"atl":null,"batl":null,"id":19924823,"hc":null,"bdatb":null}],"img":null,"tv":null,"con":null,"marketdefinition":null,"id":"1.258926623"}],"conflatems":null,"op":"mcm","id":3}
{"ct":null,"SegmentType":null,"clk":"ANV\u002BANSAAQCKfA==","heartbeatms":null,"pt":1780839724448,"initialclk":null,"mc":[{"rc":[{"tv":242349.88000000001,"batb":null,"spb":null,"bdatl":null,"trd":[[9,219.34]],"spf":null,"ltp":9,"atb":[[9,220.22999999999999]],"spl":null,"spn":null,"atl":null,"batl":null,"id":16570658,"hc":null,"bdatb":null}],"img":null,"tv":2256844.52,"con":null,"marketdefinition":null,"id":"1.258926623"}],"conflatems":null,"op":"mcm","id":3}
{"ct":null,"SegmentType":null,"clk":"AN1\u002BANqAAQCRfA==","heartbeatms":null,"pt":1780839724547,"initialclk":null,"mc":[{"rc":[{"tv":2014652.72,"batb":null,"spb":null,"bdatl":null,"trd":[[1.1299999999999999,200155.48000000001]],"spf":null,"ltp":null,"atb":null,"spl":null,"spn":null,"atl":[[1.1299999999999999,21073.709999999999]],"batl":null,"id":19924823,"hc":null,"bdatb":null}],"img":null,"tv":2257002.6000000001,"con":null,"marketdefinition":null,"id":"1.258926623"}],"conflatems":null,"op":"mcm","id":3}
{"ct":null,"SegmentType":null,"clk":"AOV\u002BAOmAAQCafA==","heartbeatms":null,"pt":1780839724654,"initialclk":null,"mc":[{"rc":[{"tv":null,"batb":null,"spb":null,"bdatl":null,"trd":null,"spf":null,"ltp":null,"atb":[[1.04,73813.679999999993]],"spl":null,"spn":null,"atl":null,"batl":null,"id":19924823,"hc":null,"bdatb":null}],"img":null,"tv":null,"con":null,"marketdefinition":null,"id":"1.258926623"}],"conflatems":null,"op":"mcm","id":3}
{"ct":null,"SegmentType":null,"clk":"AOt\u002BAPOAAQCifA==","heartbeatms":null,"pt":1780839724756,"initialclk":null,"mc":[{"rc":[{"tv":null,"batb":null,"spb":null,"bdatl":null,"trd":null,"spf":null,"ltp":null,"atb":null,"spl":null,"spn":null,"atl":[[9.1999999999999993,0]],"batl":null,"id":16570658,"hc":null,"bdatb":null},{"tv":null,"batb":null,"spb":null,"bdatl":null,"trd":null,"spf":null,"ltp":null,"atb":null,"spl":null,"spn":null,"atl":[[1.1299999999999999,19559.52]],"batl":null,"id":19924823,"hc":null,"bdatb":null}],"img":null,"tv":null,"con":null,"marketdefinition":null,"id":"1.258926623"}],"conflatems":null,"op":"mcm","id":3}
{"ct":null,"SegmentType":null,"clk":"APN\u002BAICBAQCmfA==","heartbeatms":null,"pt":1780839724859,"initialclk":null,"mc":[{"rc":[{"tv":null,"batb":null,"spb":null,"bdatl":null,"trd":null,"spf":null,"ltp":null,"atb":null,"spl":null,"spn":null,"atl":[[1.1399999999999999,26127.330000000002]],"batl":null,"id":19924823,"hc":null,"bdatb":null}],"img":null,"tv":null,"con":null,"marketdefinition":null,"id":"1.258926623"}],"conflatems":null,"op":"mcm","id":3}
{"ct":null,"SegmentType":null,"clk":"AIV/AI\u002BBAQC2fA==","heartbeatms":null,"pt":1780839725063,"initialclk":null,"mc":[{"rc":[{"tv":null,"batb":null,"spb":null,"bdatl":null,"trd":null,"spf":null,"ltp":null,"atb":[[1.04,73813.479999999996]],"spl":null,"spn":null,"atl":null,"batl":null,"id":19924823,"hc":null,"bdatb":null}],"img":null,"tv":null,"con":null,"marketdefinition":null,"id":"1.258926623"}],"conflatems":null,"op":"mcm","id":3}
{"ct":null,"SegmentType":null,"clk":"ALh/AMOBAQDqfA==","heartbeatms":null,"pt":1780839725545,"initialclk":null,"mc":[{"rc":[{"tv":242349.92999999999,"batb":null,"spb":null,"bdatl":null,"trd":[[9,219.38999999999999]],"spf":null,"ltp":null,"atb":[[9,220.19999999999999]],"spl":null,"spn":null,"atl":null,"batl":null,"id":16570658,"hc":null,"bdatb":null}],"img":null,"tv":2257002.6499999999,"con":null,"marketdefinition":null,"id":"1.258926623"}],"conflatems":null,"op":"mcm","id":3}
{"ct":null,"SegmentType":null,"clk":"AM1/ANuBAQD\u002BfA==","heartbeatms":null,"pt":1780839725758,"initialclk":null,"mc":[{"rc":[{"tv":null,"batb":null,"spb":null,"bdatl":null,"trd":null,"spf":null,"ltp":null,"atb":[[1.1200000000000001,648.52999999999997]],"spl":null,"spn":null,"atl":null,"batl":null,"id":19924823,"hc":null,"bdatb":null}],"img":null,"tv":null,"con":null,"marketdefinition":null,"id":"1.258926623"}],"conflatems":null,"op":"mcm","id":3}
{"ct":null,"SegmentType":null,"clk":"APF/AIOCAQCdfQ==","heartbeatms":null,"pt":1780839726152,"initialclk":null,"mc":[{"rc":[{"tv":242373.73999999999,"batb":null,"spb":null,"bdatl":null,"trd":[[9,243.19999999999999]],"spf":null,"ltp":null,"atb":[[9,208.30000000000001]],"spl":null,"spn":null,"atl":null,"batl":null,"id":16570658,"hc":null,"bdatb":null}],"img":null,"tv":2257026.46,"con":null,"marketdefinition":null,"id":"1.258926623"}],"conflatems":null,"op":"mcm","id":3}
{"ct":null,"SegmentType":null,"clk":"AP5/AJCCAQCofQ==","heartbeatms":null,"pt":1780839726260,"initialclk":null,"mc":[{"rc":[{"tv":null,"batb":null,"spb":null,"bdatl":null,"trd":null,"spf":null,"ltp":null,"atb":null,"spl":null,"spn":null,"atl":[[1.1399999999999999,32506.450000000001]],"batl":null,"id":19924823,"hc":null,"bdatb":null}],"img":null,"tv":null,"con":null,"marketdefinition":null,"id":"1.258926623"}],"conflatems":null,"op":"mcm","id":3}
{"ct":null,"SegmentType":null,"clk":"AIqAAQCdggEArX0=","heartbeatms":null,"pt":1780839726366,"initialclk":null,"mc":[{"rc":[{"tv":null,"batb":null,"spb":null,"bdatl":null,"trd":null,"spf":null,"ltp":null,"atb":[[7.7999999999999998,0.85999999999999999]],"spl":null,"spn":null,"atl":null,"batl":null,"id":16570658,"hc":null,"bdatb":null},{"tv":null,"batb":null,"spb":null,"bdatl":null,"trd":null,"spf":null,"ltp":null,"atb":null,"spl":null,"spn":null,"atl":[[1.1399999999999999,26130.330000000002],[1.1499999999999999,11282.209999999999]],"batl":null,"id":19924823,"hc":null,"bdatb":null}],"img":null,"tv":null,"con":null,"marketdefinition":null,"id":"1.258926623"}],"conflatems":null,"op":"mcm","id":3}
{"ct":null,"SegmentType":null,"clk":"AJqAAQChggEAtX0=","heartbeatms":null,"pt":1780839726467,"initialclk":null,"mc":[{"rc":[{"tv":null,"batb":null,"spb":null,"bdatl":null,"trd":null,"spf":null,"ltp":null,"atb":[[8.8000000000000007,2.27]],"spl":null,"spn":null,"atl":null,"batl":null,"id":16570658,"hc":null,"bdatb":null}],"img":null,"tv":null,"con":null,"marketdefinition":null,"id":"1.258926623"}],"conflatems":null,"op":"mcm","id":3}
{"ct":null,"SegmentType":null,"clk":"ALCAAQCyggEAw30=","heartbeatms":null,"pt":1780839726670,"initialclk":null,"mc":[{"rc":[{"tv":null,"batb":null,"spb":null,"bdatl":null,"trd":null,"spf":null,"ltp":null,"atb":[[1.1000000000000001,63423.690000000002]],"spl":null,"spn":null,"atl":null,"batl":null,"id":19924823,"hc":null,"bdatb":null}],"img":null,"tv":null,"con":null,"marketdefinition":null,"id":"1.258926623"}],"conflatems":null,"op":"mcm","id":3}
{"ct":null,"SegmentType":null,"clk":"AN6AAQDXggEA230=","heartbeatms":null,"pt":1780839727038,"initialclk":null,"mc":[{"rc":[{"tv":2014654.6399999999,"batb":null,"spb":null,"bdatl":null,"trd":[[1.1299999999999999,200157.39999999999]],"spf":null,"ltp":null,"atb":null,"spl":null,"spn":null,"atl":[[1.1299999999999999,19558.560000000001]],"batl":null,"id":19924823,"hc":null,"bdatb":null}],"img":null,"tv":2257028.3799999999,"con":null,"marketdefinition":null,"id":"1.258926623"}],"conflatems":null,"op":"mcm","id":3}
{"ct":null,"SegmentType":null,"clk":"AICBAQDyggEA6X0=","heartbeatms":null,"pt":1780839727349,"initialclk":null,"mc":[{"rc":[{"tv":null,"batb":null,"spb":null,"bdatl":null,"trd":null,"spf":null,"ltp":null,"atb":[[8,242.53]],"spl":null,"spn":null,"atl":[[10,243.27000000000001]],"batl":null,"id":16570658,"hc":null,"bdatb":null},{"tv":null,"batb":null,"spb":null,"bdatl":null,"trd":null,"spf":null,"ltp":null,"atb":[[1.1100000000000001,60305.440000000002]],"spl":null,"spn":null,"atl":[[1.1499999999999999,12558.639999999999]],"batl":null,"id":19924823,"hc":null,"bdatb":null}],"img":null,"tv":null,"con":null,"marketdefinition":null,"id":"1.258926623"}],"conflatems":null,"op":"mcm","id":3}
{"ct":null,"SegmentType":null,"clk":"AL\u002BBAQC1gwEAk34=","heartbeatms":null,"pt":1780839728077,"initialclk":null,"mc":[{"rc":[{"tv":2014804.54,"batb":null,"spb":null,"bdatl":null,"trd":[[1.1299999999999999,200307.29999999999]],"spf":null,"ltp":null,"atb":null,"spl":null,"spn":null,"atl":[[1.1299999999999999,19483.610000000001]],"batl":null,"id":19924823,"hc":null,"bdatb":null}],"img":null,"tv":2257178.2799999998,"con":null,"marketdefinition":null,"id":"1.258926623"}],"conflatems":null,"op":"mcm","id":3}
{"ct":null,"SegmentType":null,"clk":"AMKBAQC8gwEAm34=","heartbeatms":null,"pt":1780839728172,"initialclk":null,"mc":[{"rc":[{"tv":2014804.9299999999,"batb":null,"spb":null,"bdatl":null,"trd":[[1.1299999999999999,200307.69]],"spf":null,"ltp":null,"atb":null,"spl":null,"spn":null,"atl":[[1.1299999999999999,19483.41]],"batl":null,"id":19924823,"hc":null,"bdatb":null}],"img":null,"tv":2257178.6699999999,"con":null,"marketdefinition":null,"id":"1.258926623"}],"conflatems":null,"op":"mcm","id":3}
{"ct":null,"SegmentType":null,"clk":"AOOBAQDWgwEAuH4=","heartbeatms":null,"pt":1780839728448,"initialclk":null,"mc":[{"rc":[{"tv":2015004.9299999999,"batb":null,"spb":null,"bdatl":null,"trd":[[1.1299999999999999,200507.69]],"spf":null,"ltp":null,"atb":null,"spl":null,"spn":null,"atl":[[1.1299999999999999,19383.41]],"batl":null,"id":19924823,"hc":null,"bdatb":null}],"img":null,"tv":2257378.6699999999,"con":null,"marketdefinition":null,"id":"1.258926623"}],"conflatems":null,"op":"mcm","id":3}
{"ct":null,"SegmentType":null,"clk":"AOyBAQDlgwEAwX4=","heartbeatms":null,"pt":1780839728592,"initialclk":null,"mc":[{"rc":[{"tv":242790.34,"batb":null,"spb":null,"bdatl":null,"trd":[[9,659.79999999999995]],"spf":null,"ltp":null,"atb":[[9,0]],"spl":null,"spn":null,"atl":[[9,56.07]],"batl":null,"id":16570658,"hc":null,"bdatb":null},{"tv":null,"batb":null,"spb":null,"bdatl":null,"trd":null,"spf":null,"ltp":null,"atb":[[1.04,73812.729999999996],[1.1000000000000001,62418.559999999998]],"spl":null,"spn":null,"atl":[[1.1499999999999999,11665.43]],"batl":null,"id":19924823,"hc":null,"bdatb":null}],"img":null,"tv":2257795.27,"con":null,"marketdefinition":null,"id":"1.258926623"}],"conflatems":null,"op":"mcm","id":3}
{"ct":null,"SegmentType":null,"clk":"AP\u002BBAQDzgwEAzX4=","heartbeatms":null,"pt":1780839728755,"initialclk":null,"mc":[{"rc":[{"tv":2015021.8999999999,"batb":null,"spb":null,"bdatl":null,"trd":[[1.1299999999999999,200524.66]],"spf":null,"ltp":null,"atb":null,"spl":null,"spn":null,"atl":[[1.1299999999999999,19374.93],[1.1399999999999999,26216.700000000001]],"batl":null,"id":19924823,"hc":null,"bdatb":null}],"img":null,"tv":2257812.2400000002,"con":null,"marketdefinition":null,"id":"1.258926623"}],"conflatems":null,"op":"mcm","id":3}
{"ct":null,"SegmentType":null,"clk":"AIuCAQD7gwEA1n4=","heartbeatms":null,"pt":1780839728851,"initialclk":null,"mc":[{"rc":[{"tv":null,"batb":null,"spb":null,"bdatl":null,"trd":null,"spf":null,"ltp":null,"atb":[[8,59.049999999999997]],"spl":null,"spn":null,"atl":null,"batl":null,"id":16570658,"hc":null,"bdatb":null}],"img":null,"tv":null,"con":null,"marketdefinition":null,"id":"1.258926623"}],"conflatems":null,"op":"mcm","id":3}
{"ct":null,"SegmentType":null,"clk":"AIqDAQDuhAEAu38=","heartbeatms":null,"pt":1780839730051,"initialclk":null,"mc":[{"rc":[{"tv":null,"batb":null,"spb":null,"bdatl":null,"trd":null,"spf":null,"ltp":null,"atb":[[8.5999999999999996,156.27000000000001]],"spl":null,"spn":null,"atl":null,"batl":null,"id":16570658,"hc":null,"bdatb":null}],"img":null,"tv":null,"con":null,"marketdefinition":null,"id":"1.258926623"}],"conflatems":null,"op":"mcm","id":3}
{"ct":null,"SegmentType":null,"clk":"AJ\u002BDAQD\u002BhAEAy38=","heartbeatms":null,"pt":1780839730251,"initialclk":null,"mc":[{"rc":[{"tv":null,"batb":null,"spb":null,"bdatl":null,"trd":null,"spf":null,"ltp":null,"atb":[[8.5999999999999996,269.92000000000002]],"spl":null,"spn":null,"atl":null,"batl":null,"id":16570658,"hc":null,"bdatb":null}],"img":null,"tv":null,"con":null,"marketdefinition":null,"id":"1.258926623"}],"conflatems":null,"op":"mcm","id":3}
{"ct":null,"SegmentType":null,"clk":"ALSDAQCZhQEA538=","heartbeatms":null,"pt":1780839730559,"initialclk":null,"mc":[{"rc":[{"tv":null,"batb":null,"spb":null,"bdatl":null,"trd":null,"spf":null,"ltp":null,"atb":[[1.1100000000000001,61215.949999999997]],"spl":null,"spn":null,"atl":[[1.1299999999999999,20317.82]],"batl":null,"id":19924823,"hc":null,"bdatb":null}],"img":null,"tv":null,"con":null,"marketdefinition":null,"id":"1.258926623"}],"conflatems":null,"op":"mcm","id":3}
{"ct":null,"SegmentType":null,"clk":"ALyDAQCghQEA738=","heartbeatms":null,"pt":1780839730660,"initialclk":null,"mc":[{"rc":[{"tv":null,"batb":null,"spb":null,"bdatl":null,"trd":null,"spf":null,"ltp":null,"atb":[[8.8000000000000007,141.19]],"spl":null,"spn":null,"atl":[[9.1999999999999993,132.88]],"batl":null,"id":16570658,"hc":null,"bdatb":null},{"tv":null,"batb":null,"spb":null,"bdatl":null,"trd":null,"spf":null,"ltp":null,"atb":[[1.1100000000000001,62317.269999999997]],"spl":null,"spn":null,"atl":[[1.1299999999999999,21399.650000000001]],"batl":null,"id":19924823,"hc":null,"bdatb":null}],"img":null,"tv":null,"con":null,"marketdefinition":null,"id":"1.258926623"}],"conflatems":null,"op":"mcm","id":3}
{"ct":null,"SegmentType":null,"clk":"AICEAQDphQEAmYAB","heartbeatms":null,"pt":1780839731338,"initialclk":null,"mc":[{"rc":[{"tv":null,"batb":null,"spb":null,"bdatl":null,"trd":null,"spf":null,"ltp":null,"atb":[[1.1200000000000001,148.53]],"spl":null,"spn":null,"atl":null,"batl":null,"id":19924823,"hc":null,"bdatb":null}],"img":null,"tv":null,"con":null,"marketdefinition":null,"id":"1.258926623"}],"conflatems":null,"op":"mcm","id":3}
{"ct":null,"SegmentType":null,"clk":"AIiEAQD1hQEAqIAB","heartbeatms":null,"pt":1780839731443,"initialclk":null,"mc":[{"rc":[{"tv":null,"batb":null,"spb":null,"bdatl":null,"trd":null,"spf":null,"ltp":null,"atb":null,"spl":null,"spn":null,"atl":[[1.1299999999999999,38675.279999999999]],"batl":null,"id":19924823,"hc":null,"bdatb":null}],"img":null,"tv":null,"con":null,"marketdefinition":null,"id":"1.258926623"}],"conflatems":null,"op":"mcm","id":3}
{"ct":null,"SegmentType":null,"clk":"AJOEAQCDhgEAr4AB","heartbeatms":null,"pt":1780839731548,"initialclk":null,"mc":[{"rc":[{"tv":null,"batb":null,"spb":null,"bdatl":null,"trd":null,"spf":null,"ltp":null,"atb":null,"spl":null,"spn":null,"atl":[[1.1299999999999999,38761.660000000003]],"batl":null,"id":19924823,"hc":null,"bdatb":null}],"img":null,"tv":null,"con":null,"marketdefinition":null,"id":"1.258926623"}],"conflatems":null,"op":"mcm","id":3}
{"ct":null,"SegmentType":null,"clk":"AP2EAQCKhwEAkYEB","heartbeatms":null,"pt":1780839732892,"initialclk":null,"mc":[{"rc":[{"tv":2015096.48,"batb":null,"spb":null,"bdatl":null,"trd":[[1.1299999999999999,200599.23999999999]],"spf":null,"ltp":null,"atb":null,"spl":null,"spn":null,"atl":[[1.1299999999999999,36562.449999999997]],"batl":null,"id":19924823,"hc":null,"bdatb":null}],"img":null,"tv":2257886.8199999998,"con":null,"marketdefinition":null,"id":"1.258926623"}],"conflatems":null,"op":"mcm","id":3}
{"ct":null,"SegmentType":null,"clk":"AJeFAQChhwEApoEB","heartbeatms":null,"pt":1780839733140,"initialclk":null,"mc":[{"rc":[{"tv":null,"batb":null,"spb":null,"bdatl":null,"trd":null,"spf":null,"ltp":null,"atb":null,"spl":null,"spn":null,"atl":[[10,93.280000000000001]],"batl":null,"id":16570658,"hc":null,"bdatb":null},{"tv":null,"batb":null,"spb":null,"bdatl":null,"trd":null,"spf":null,"ltp":null,"atb":[[1.1100000000000001,60965.919999999998]],"spl":null,"spn":null,"atl":[[1.1499999999999999,10389]],"batl":null,"id":19924823,"hc":null,"bdatb":null}],"img":null,"tv":null,"con":null,"marketdefinition":null,"id":"1.258926623"}],"conflatems":null,"op":"mcm","id":3}
{"ct":null,"SegmentType":null,"clk":"AKCFAQCnhwEAsoEB","heartbeatms":null,"pt":1780839733249,"initialclk":null,"mc":[{"rc":[{"tv":null,"batb":null,"spb":null,"bdatl":null,"trd":null,"spf":null,"ltp":null,"atb":[[7.7999999999999998,0]],"spl":null,"spn":null,"atl":null,"batl":null,"id":16570658,"hc":null,"bdatb":null},{"tv":null,"batb":null,"spb":null,"bdatl":null,"trd":null,"spf":null,"ltp":null,"atb":null,"spl":null,"spn":null,"atl":[[1.1499999999999999,10384.6]],"batl":null,"id":19924823,"hc":null,"bdatb":null}],"img":null,"tv":null,"con":null,"marketdefinition":null,"id":"1.258926623"}],"conflatems":null,"op":"mcm","id":3}
{"ct":null,"SegmentType":null,"clk":"AL\u002BFAQDFhwEAyIEB","heartbeatms":null,"pt":1780839733555,"initialclk":null,"mc":[{"rc":[{"tv":null,"batb":null,"spb":null,"bdatl":null,"trd":null,"spf":null,"ltp":null,"atb":[[8.8000000000000007,2.27]],"spl":null,"spn":null,"atl":[[9.1999999999999993,0]],"batl":null,"id":16570658,"hc":null,"bdatb":null},{"tv":null,"batb":null,"spb":null,"bdatl":null,"trd":null,"spf":null,"ltp":null,"atb":[[1.1100000000000001,59864.599999999999]],"spl":null,"spn":null,"atl":[[1.1299999999999999,35480.620000000003]],"batl":null,"id":19924823,"hc":null,"bdatb":null}],"img":null,"tv":null,"con":null,"marketdefinition":null,"id":"1.258926623"}],"conflatems":null,"op":"mcm","id":3}
{"ct":null,"SegmentType":null,"clk":"AMyFAQDOhwEAz4EB","heartbeatms":null,"pt":1780839733658,"initialclk":null,"mc":[{"rc":[{"tv":242902.47,"batb":null,"spb":null,"bdatl":null,"trd":[[9,771.92999999999995]],"spf":null,"ltp":null,"atb":[[9.1999999999999993,100],[9,29.449999999999999]],"spl":null,"spn":null,"atl":[[9,0]],"batl":null,"id":16570658,"hc":null,"bdatb":null}],"img":null,"tv":2257998.9500000002,"con":null,"marketdefinition":null,"id":"1.258926623"}],"conflatems":null,"op":"mcm","id":3}
{"ct":null,"SegmentType":null,"clk":"AOSFAQDshwEA4YEB","heartbeatms":null,"pt":1780839733872,"initialclk":null,"mc":[{"rc":[{"tv":null,"batb":null,"spb":null,"bdatl":null,"trd":null,"spf":null,"ltp":null,"atb":[[1.1000000000000001,63570.300000000003]],"spl":null,"spn":null,"atl":[[1.1399999999999999,26345.389999999999],[1.1499999999999999,11157.91]],"batl":null,"id":19924823,"hc":null,"bdatb":null}],"img":null,"tv":null,"con":null,"marketdefinition":null,"id":"1.258926623"}],"conflatems":null,"op":"mcm","id":3}
{"ct":null,"SegmentType":null,"clk":"AO6FAQD7hwEA6oEB","heartbeatms":null,"pt":1780839733977,"initialclk":null,"mc":[{"rc":[{"tv":null,"batb":null,"spb":null,"bdatl":null,"trd":null,"spf":null,"ltp":null,"atb":[[1.1100000000000001,58808.809999999998]],"spl":null,"spn":null,"atl":[[1.1299999999999999,34537.730000000003]],"batl":null,"id":19924823,"hc":null,"bdatb":null}],"img":null,"tv":null,"con":null,"marketdefinition":null,"id":"1.258926623"}],"conflatems":null,"op":"mcm","id":3}
{"ct":null,"SegmentType":null,"clk":"AJ6GAQC0iAEAmIIB","heartbeatms":null,"pt":1780839734481,"initialclk":null,"mc":[{"rc":[{"tv":2015098.49,"batb":null,"spb":null,"bdatl":null,"trd":[[1.1299999999999999,200601.25]],"spf":null,"ltp":null,"atb":null,"spl":null,"spn":null,"atl":[[1.1299999999999999,34536.730000000003]],"batl":null,"id":19924823,"hc":null,"bdatb":null}],"img":null,"tv":2258000.96,"con":null,"marketdefinition":null,"id":"1.258926623"}],"conflatems":null,"op":"mcm","id":3}
{"ct":null,"SegmentType":null,"clk":"AM2GAQDbiAEAyoIB","heartbeatms":null,"pt":1780839735052,"initialclk":null,"mc":[{"rc":[{"tv":null,"batb":null,"spb":null,"bdatl":null,"trd":null,"spf":null,"ltp":null,"atb":[[9,0]],"spl":null,"spn":null,"atl":null,"batl":null,"id":16570658,"hc":null,"bdatb":null},{"tv":null,"batb":null,"spb":null,"bdatl":null,"trd":null,"spf":null,"ltp":null,"atb":[[1.1200000000000001,443.29000000000002]],"spl":null,"spn":null,"atl":null,"batl":null,"id":19924823,"hc":null,"bdatb":null}],"img":null,"tv":null,"con":null,"marketdefinition":null,"id":"1.258926623"}],"conflatems":null,"op":"mcm","id":3}
{"ct":null,"SegmentType":null,"clk":"AO6GAQCRiQEA9IIB","heartbeatms":null,"pt":1780839735564,"initialclk":null,"mc":[{"rc":[{"tv":null,"batb":null,"spb":null,"bdatl":null,"trd":null,"spf":null,"ltp":null,"atb":[[9.1999999999999993,0]],"spl":null,"spn":null,"atl":null,"batl":null,"id":16570658,"hc":null,"bdatb":null}],"img":null,"tv":null,"con":null,"marketdefinition":null,"id":"1.258926623"}],"conflatems":null,"op":"mcm","id":3}
{"ct":null,"SegmentType":null,"clk":"APaGAQCbiQEA\u002BoIB","heartbeatms":null,"pt":1780839735665,"initialclk":null,"mc":[{"rc":[{"tv":null,"batb":null,"spb":null,"bdatl":null,"trd":null,"spf":null,"ltp":null,"atb":[[8.5999999999999996,369.92000000000002]],"spl":null,"spn":null,"atl":null,"batl":null,"id":16570658,"hc":null,"bdatb":null}],"img":null,"tv":null,"con":null,"marketdefinition":null,"id":"1.258926623"}],"conflatems":null,"op":"mcm","id":3}
{"ct":null,"SegmentType":null,"clk":"AIiHAQCviQEAiIMB","heartbeatms":null,"pt":1780839735869,"initialclk":null,"mc":[{"rc":[{"tv":null,"batb":null,"spb":null,"bdatl":null,"trd":null,"spf":null,"ltp":null,"atb":[[8.5999999999999996,469.92000000000002]],"spl":null,"spn":null,"atl":null,"batl":null,"id":16570658,"hc":null,"bdatb":null}],"img":null,"tv":null,"con":null,"marketdefinition":null,"id":"1.258926623"}],"conflatems":null,"op":"mcm","id":3}
{"ct":null,"SegmentType":null,"clk":"AJqHAQDFiQEAmYMB","heartbeatms":null,"pt":1780839736088,"initialclk":null,"mc":[{"rc":[{"tv":null,"batb":null,"spb":null,"bdatl":null,"trd":null,"spf":null,"ltp":null,"atb":[[8.5999999999999996,569.91999999999996]],"spl":null,"spn":null,"atl":null,"batl":null,"id":16570658,"hc":null,"bdatb":null}],"img":null,"tv":null,"con":null,"marketdefinition":null,"id":"1.258926623"}],"conflatems":null,"op":"mcm","id":3}
{"ct":null,"SegmentType":null,"clk":"AKWHAQDUiQEAqIMB","heartbeatms":null,"pt":1780839736236,"initialclk":null,"mc":[{"rc":[{"tv":null,"batb":null,"spb":null,"bdatl":null,"trd":null,"spf":null,"ltp":null,"atb":[[8.5999999999999996,669.91999999999996]],"spl":null,"spn":null,"atl":null,"batl":null,"id":16570658,"hc":null,"bdatb":null}],"img":null,"tv":null,"con":null,"marketdefinition":null,"id":"1.258926623"}],"conflatems":null,"op":"mcm","id":3}
{"ct":null,"SegmentType":null,"clk":"AOiHAQCTigEA44MB","heartbeatms":null,"pt":1780839736962,"initialclk":null,"mc":[{"rc":[{"tv":null,"batb":null,"spb":null,"bdatl":null,"trd":null,"spf":null,"ltp":null,"atb":null,"spl":null,"spn":null,"atl":[[1.1499999999999999,11158.91]],"batl":null,"id":19924823,"hc":null,"bdatb":null}],"img":null,"tv":null,"con":null,"marketdefinition":null,"id":"1.258926623"}],"conflatems":null,"op":"mcm","id":3}
{"ct":null,"SegmentType":null,"clk":"AO2HAQCfigEA6YMB","heartbeatms":null,"pt":1780839737061,"initialclk":null,"mc":[{"rc":[{"tv":null,"batb":null,"spb":null,"bdatl":null,"trd":null,"spf":null,"ltp":null,"atb":null,"spl":null,"spn":null,"atl":[[1.1399999999999999,28366.549999999999]],"batl":null,"id":19924823,"hc":null,"bdatb":null}],"img":null,"tv":null,"con":null,"marketdefinition":null,"id":"1.258926623"}],"conflatems":null,"op":"mcm","id":3}
{"ct":null,"SegmentType":null,"clk":"APmHAQctigEA9IMB","heartbeatms":null,"pt":1780839737175,"initialclk":null,"mc":[{"rc":[{"tv":null,"batb":null,"spb":null,"bdatl":null,"trd":null,"spf":null,"ltp":null,"atb":[[1.1000000000000001,62418.559999999998],[1.1100000000000001,57204.910000000003]],"spl":null,"spn":null,"atl":[[1.1399999999999999,26473.619999999999],[1.1499999999999999,10385.6]],"batl":null,"id":19924823,"hc":null,"bdatb":null}],"img":null,"tv":null,"con":null,"marketdefinition":null,"id":"1.258926623"}],"conflatems":null,"op":"mcm","id":3}
{"ct":null,"SegmentType":null,"clk":"AJCIAQDOigEAjoQB","heartbeatms":null,"pt":1780839737476,"initialclk":null,"mc":[{"rc":[{"tv":null,"batb":null,"spb":null,"bdatl":null,"trd":null,"spf":null,"ltp":null,"atb":null,"spl":null,"spn":null,"atl":[[1.1299999999999999,34636.730000000003]],"batl":null,"id":19924823,"hc":null,"bdatb":null}],"img":null,"tv":null,"con":null,"marketdefinition":null,"id":"1.258926623"}],"conflatems":null,"op":"mcm","id":3}
{"ct":null,"SegmentType":null,"clk":"AJmIAQDYigEAl4QB","heartbeatms":null,"pt":1780839737580,"initialclk":null,"mc":[{"rc":[{"tv":null,"batb":null,"spb":null,"bdatl":null,"trd":null,"spf":null,"ltp":null,"atb":[[8.5999999999999996,269.92000000000002]],"spl":null,"spn":null,"atl":null,"batl":null,"id":16570658,"hc":null,"bdatb":null}],"img":null,"tv":null,"con":null,"marketdefinition":null,"id":"1.258926623"}],"conflatems":null,"op":"mcm","id":3}
{"ct":null,"SegmentType":null,"clk":"AKOIAQDjigEAn4QB","heartbeatms":null,"pt":1780839737684,"initialclk":null,"mc":[{"rc":[{"tv":null,"batb":null,"spb":null,"bdatl":null,"trd":null,"spf":null,"ltp":null,"atb":[[8.8000000000000007,402.26999999999998]],"spl":null,"spn":null,"atl":null,"batl":null,"id":16570658,"hc":null,"bdatb":null}],"img":null,"tv":null,"con":null,"marketdefinition":null,"id":"1.258926623"}],"conflatems":null,"op":"mcm","id":3}
{"ct":null,"SegmentType":null,"clk":"ANGIAQDIiwEAwYQB","heartbeatms":null,"pt":1780839738149,"initialclk":null,"mc":[{"rc":[{"tv":null,"batb":null,"spb":null,"bdatl":null,"trd":null,"spf":null,"ltp":null,"atb":[[9,1]],"spl":null,"spn":null,"atl":null,"batl":null,"id":16570658,"hc":null,"bdatb":null}],"img":null,"tv":null,"con":null,"marketdefinition":null,"id":"1.258926623"}],"conflatems":null,"op":"mcm","id":3}
{"ct":null,"SegmentType":null,"clk":"APyIAQCFjAEA6oQB","heartbeatms":null,"pt":1780839738667,"initialclk":null,"mc":[{"rc":[{"tv":null,"batb":null,"spb":null,"bdatl":null,"trd":null,"spf":null,"ltp":null,"atb":null,"spl":null,"spn":null,"atl":[[1.1299999999999999,17361.099999999999]],"batl":null,"id":19924823,"hc":null,"bdatb":null}],"img":null,"tv":null,"con":null,"marketdefinition":null,"id":"1.258926623"}],"conflatems":null,"op":"mcm","id":3}
{"ct":null,"SegmentType":null,"clk":"AKSJAQDBjAEAk4UB","heartbeatms":null,"pt":1780839739078,"initialclk":null,"mc":[{"rc":[{"tv":null,"batb":null,"spb":null,"bdatl":null,"trd":null,"spf":null,"ltp":null,"atb":null,"spl":null,"spn":null,"atl":[[9.1999999999999993,8]],"batl":null,"id":16570658,"hc":null,"bdatb":null}],"img":null,"tv":null,"con":null,"marketdefinition":null,"id":"1.258926623"}],"conflatems":null,"op":"mcm","id":3}
{"ct":null,"SegmentType":null,"clk":"AKqJAQDNjAEAmoUB","heartbeatms":null,"pt":1780839739185,"initialclk":null,"mc":[{"rc":[{"tv":null,"batb":null,"spb":null,"bdatl":null,"trd":null,"spf":null,"ltp":null,"atb":null,"spl":null,"spn":null,"atl":[[9.1999999999999993,116.7]],"batl":null,"id":16570658,"hc":null,"bdatb":null},{"tv":2015100.4099999999,"batb":null,"spb":null,"bdatl":null,"trd":[[1.1299999999999999,200603.17000000001]],"spf":null,"ltp":null,"atb":[[1.1200000000000001,27020.119999999999]],"spl":null,"spn":null,"atl":[[1.1299999999999999,17360.139999999999]],"batl":null,"id":19924823,"hc":null,"bdatb":null}],"img":null,"tv":2258002.8799999999,"con":null,"marketdefinition":null,"id":"1.258926623"}],"conflatems":null,"op":"mcm","id":3}
{"ct":null,"SegmentType":null,"clk":"ALWJAQDUjAEApIUB","heartbeatms":null,"pt":1780839739296,"initialclk":null,"mc":[{"rc":[{"tv":null,"batb":null,"spb":null,"bdatl":null,"trd":null,"spf":null,"ltp":null,"atb":null,"spl":null,"spn":null,"atl":[[9.4000000000000004,2],[9.8000000000000007,0.98999999999999999],[12,0],[11.5,59.530000000000001],[11,233.28],[9.5999999999999996,0.85999999999999999]],"batl":null,"id":16570658,"hc":null,"bdatb":null},{"tv":null,"batb":null,"spb":null,"bdatl":null,"trd":null,"spf":null,"ltp":null,"atb":[[1.1000000000000001,63418.559999999998],[1.0900000000000001,40105.849999999999],[1.1100000000000001,57210.75],[1.1200000000000001,27022.119999999999]],"spl":null,"spn":null,"atl":null,"batl":null,"id":19924823,"hc":null,"bdatb":null}],"img":null,"tv":null,"con":null,"marketdefinition":null,"id":"1.258926623"}],"conflatems":null,"op":"mcm","id":3}
{"ct":null,"SegmentType":null,"clk":"ALyJAQDgjAEAqoUB","heartbeatms":null,"pt":1780839739345,"initialclk":null,"mc":[{"rc":[{"tv":null,"batb":null,"spb":null,"bdatl":null,"trd":null,"spf":null,"ltp":null,"atb":null,"spl":null,"spn":null,"atl":[[10.5,285.67000000000002]],"batl":null,"id":16570658,"hc":null,"bdatb":null}],"img":null,"tv":null,"con":null,"marketdefinition":null,"id":"1.258926623"}],"conflatems":null,"op":"mcm","id":3}
{"ct":null,"SegmentType":null,"clk":"AMaJAQDpjAEAroUB","heartbeatms":null,"pt":1780839739450,"initialclk":null,"mc":[{"rc":[{"tv":null,"batb":null,"spb":null,"bdatl":null,"trd":null,"spf":null,"ltp":null,"atb":[[1.1200000000000001,27447.880000000001]],"spl":null,"spn":null,"atl":null,"batl":null,"id":19924823,"hc":null,"bdatb":null}],"img":null,"tv":null,"con":null,"marketdefinition":null,"id":"1.258926623"}],"conflatems":null,"op":"mcm","id":3}
{"ct":null,"SegmentType":null,"clk":"ANCJAQD1jAEAuoUB","heartbeatms":null,"pt":1780839739549,"initialclk":null,"mc":[{"rc":[{"tv":null,"batb":null,"spb":null,"bdatl":null,"trd":null,"spf":null,"ltp":null,"atb":[[8.5999999999999996,228.31]],"spl":null,"spn":null,"atl":null,"batl":null,"id":16570658,"hc":null,"bdatb":null},{"tv":null,"batb":null,"spb":null,"bdatl":null,"trd":null,"spf":null,"ltp":null,"atb":null,"spl":null,"spn":null,"atl":[[1.1299999999999999,16814.139999999999]],"batl":null,"id":19924823,"hc":null,"bdatb":null}],"img":null,"tv":null,"con":null,"marketdefinition":null,"id":"1.258926623"}],"conflatems":null,"op":"mcm","id":3}
{"ct":null,"SegmentType":null,"clk":"ANiJAQD/jAEAv4UB","heartbeatms":null,"pt":1780839739657,"initialclk":null,"mc":[{"rc":[{"tv":null,"batb":null,"spb":null,"bdatl":null,"trd":null,"spf":null,"ltp":null,"atb":[[8,651.95000000000005]],"spl":null,"spn":null,"atl":null,"batl":null,"id":16570658,"hc":null,"bdatb":null},{"tv":null,"batb":null,"spb":null,"bdatl":null,"trd":null,"spf":null,"ltp":null,"atb":[[1.1100000000000001,70337.990000000005]],"spl":null,"spn":null,"atl":null,"batl":null,"id":19924823,"hc":null,"bdatb":null}],"img":null,"tv":null,"con":null,"marketdefinition":null,"id":"1.258926623"}],"conflatems":null,"op":"mcm","id":3}
{"ct":null,"SegmentType":null,"clk":"AOyJAQCTjQEA1oUB","heartbeatms":null,"pt":1780839739866,"initialclk":null,"mc":[{"rc":[{"tv":null,"batb":null,"spb":null,"bdatl":null,"trd":null,"spf":null,"ltp":null,"atb":[[8.1999999999999993,207.13999999999999]],"spl":null,"spn":null,"atl":null,"batl":null,"id":16570658,"hc":null,"bdatb":null},{"tv":null,"batb":null,"spb":null,"bdatl":null,"trd":null,"spf":null,"ltp":null,"atb":[[1.1000000000000001,49220.330000000002]],"spl":null,"spn":null,"atl":null,"batl":null,"id":19924823,"hc":null,"bdatb":null}],"img":null,"tv":null,"con":null,"marketdefinition":null,"id":"1.258926623"}],"conflatems":null,"op":"mcm","id":3}
{"ct":null,"SegmentType":null,"clk":"AJGKAQDIjQEA9oUB","heartbeatms":null,"pt":1780839740283,"initialclk":null,"mc":[{"rc":[{"tv":null,"batb":null,"spb":null,"bdatl":null,"trd":null,"spf":null,"ltp":null,"atb":[[8.8000000000000007,2.27],[7.5999999999999996,200.5]],"spl":null,"spn":null,"atl":[[9.1999999999999993,279.74000000000001]],"batl":null,"id":16570658,"hc":null,"bdatb":null},{"tv":null,"batb":null,"spb":null,"bdatl":null,"trd":null,"spf":null,"ltp":null,"atb":[[1.1200000000000001,28787.16]],"spl":null,"spn":null,"atl":[[1.1599999999999999,10161.950000000001]],"batl":null,"id":19924823,"hc":null,"bdatb":null}],"img":null,"tv":null,"con":null,"marketdefinition":null,"id":"1.258926623"}],"conflatems":null,"op":"mcm","id":3}
{"ct":null,"SegmentType":null,"clk":"AKWKAQDdjQEAhYYB","heartbeatms":null,"pt":1780839740485,"initialclk":null,"mc":[{"rc":[{"tv":2015115.3300000001,"batb":null,"spb":null,"bdatl":null,"trd":[[1.1299999999999999,200618.09]],"spf":null,"ltp":null,"atb":null,"spl":null,"spn":null,"atl":[[1.1299999999999999,16806.68]],"batl":null,"id":19924823,"hc":null,"bdatb":null}],"img":null,"tv":2258017.7999999998,"con":null,"marketdefinition":null,"id":"1.258926623"}],"conflatems":null,"op":"mcm","id":3}
{"ct":null,"SegmentType":null,"clk":"ALKKAQDljQEAjIYB","heartbeatms":null,"pt":1780839740590,"initialclk":null,"mc":[{"rc":[{"tv":null,"batb":null,"spb":null,"bdatl":null,"trd":null,"spf":null,"ltp":null,"atb":null,"spl":null,"spn":null,"atl":[[11.5,52.869999999999997]],"batl":null,"id":16570658,"hc":null,"bdatb":null}],"img":null,"tv":null,"con":null,"marketdefinition":null,"id":"1.258926623"}],"conflatems":null,"op":"mcm","id":3}
{"ct":null,"SegmentType":null,"clk":"AN1NALZIANoiAIRbAK1H","heartbeatms":null,"pt":1780839740647,"Oc":[{"Accountid":null,"Orc":[{"Mb":[[1.1299999999999999,5]],"Uo":[{"Side":0,"pt":0,"Ot":0,"Status":1,"Sv":0,"P":1.1299999999999999,"Sc":0,"rc":"REG_LGA","S":5,"Pd":1780839572000,"Rac":"","Md":1780839740000,"Sl":0,"Avp":1.1299999999999999,"Sm":5,"id":"431726698780","Bsp":null,"Sr":0,"Cd":null,"Rfo":"SL-Back-0","Rfs":"SL"}],"id":19924823,"hc":null,"FullImage":null,"Ml":null}],"Closed":null,"id":"1.258926623","FullImage":null}],"initialclk":null,"conflatems":null,"op":"ocm","id":2}
{"ct":null,"SegmentType":null,"clk":"AL6KAQDwjQEAlYYB","heartbeatms":null,"pt":1780839740648,"initialclk":null,"mc":[{"rc":[{"tv":null,"batb":null,"spb":null,"bdatl":null,"trd":null,"spf":null,"ltp":null,"atb":null,"spl":null,"spn":null,"atl":[[9.1999999999999993,288.25999999999999]],"batl":null,"id":16570658,"hc":null,"bdatb":null},{"tv":2033923.3300000001,"batb":null,"spb":null,"bdatl":null,"trd":[[1.1299999999999999,219426.09]],"spf":null,"ltp":null,"atb":null,"spl":null,"spn":null,"atl":[[1.1299999999999999,7402.6800000000003]],"batl":null,"id":19924823,"hc":null,"bdatb":null}],"img":null,"tv":2276825.7999999998,"con":null,"marketdefinition":null,"id":"1.258926623"}],"conflatems":null,"op":"mcm","id":3}
{"ct":null,"SegmentType":null,"clk":"AMiKAQD8jQEAmYYB","heartbeatms":null,"pt":1780839740749,"initialclk":null,"mc":[{"rc":[{"tv":null,"batb":null,"spb":null,"bdatl":null,"trd":null,"spf":null,"ltp":null,"atb":null,"spl":null,"spn":null,"atl":[[1.1299999999999999,4892.5699999999997]],"batl":null,"id":19924823,"hc":null,"bdatb":null}],"img":null,"tv":null,"con":null,"marketdefinition":null,"id":"1.258926623"}],"conflatems":null,"op":"mcm","id":3}
{"ct":null,"SegmentType":null,"clk":"ANOKAQCFjgEAnIYB","heartbeatms":null,"pt":1780839740847,"initialclk":null,"mc":[{"rc":[{"tv":null,"batb":null,"spb":null,"bdatl":null,"trd":null,"spf":null,"ltp":null,"atb":[[8.5999999999999996,328.31]],"spl":null,"spn":null,"atl":null,"batl":null,"id":16570658,"hc":null,"bdatb":null}],"img":null,"tv":null,"con":null,"marketdefinition":null,"id":"1.258926623"}],"conflatems":null,"op":"mcm","id":3}
{"ct":null,"SegmentType":null,"clk":"ANqKAQCOjgEAo4YB","heartbeatms":null,"pt":1780839740952,"initialclk":null,"mc":[{"rc":[{"tv":null,"batb":null,"spb":null,"bdatl":null,"trd":null,"spf":null,"ltp":null,"atb":[[1.1100000000000001,71164.410000000003],[1.1200000000000001,30688.869999999999]],"spl":null,"spn":null,"atl":[[1.1399999999999999,27739.400000000001],[1.1499999999999999,11780.610000000001]],"batl":null,"id":19924823,"hc":null,"bdatb":null}],"img":null,"tv":null,"con":null,"marketdefinition":null,"id":"1.258926623"}],"conflatems":null,"op":"mcm","id":3}
{"ct":null,"SegmentType":null,"clk":"AOWKAQCYjgEAqYYB","heartbeatms":null,"pt":1780839741060,"initialclk":null,"mc":[{"rc":[{"tv":null,"batb":null,"spb":null,"bdatl":null,"trd":null,"spf":null,"ltp":null,"atb":[[8.5999999999999996,428.31]],"spl":null,"spn":null,"atl":null,"batl":null,"id":16570658,"hc":null,"bdatb":null}],"img":null,"tv":null,"con":null,"marketdefinition":null,"id":"1.258926623"}],"conflatems":null,"op":"mcm","id":3}
{"ct":null,"SegmentType":null,"clk":"APeKAQCojgEAtIYB","heartbeatms":null,"pt":1780839741264,"initialclk":null,"mc":[{"rc":[{"tv":null,"batb":null,"spb":null,"bdatl":null,"trd":null,"spf":null,"ltp":null,"atb":[[8.5999999999999996,528.30999999999995]],"spl":null,"spn":null,"atl":null,"batl":null,"id":16570658,"hc":null,"bdatb":null},{"tv":null,"batb":null,"spb":null,"bdatl":null,"trd":null,"spf":null,"ltp":null,"atb":null,"spl":null,"spn":null,"atl":[[1.1399999999999999,39565.389999999999]],"batl":null,"id":19924823,"hc":null,"bdatb":null}],"img":null,"tv":null,"con":null,"marketdefinition":null,"id":"1.258926623"}],"conflatems":null,"op":"mcm","id":3}
{"ct":null,"SegmentType":null,"clk":"AIGLAQCvjgEAu4YB","heartbeatms":null,"pt":1780839741365,"initialclk":null,"mc":[{"rc":[{"tv":null,"batb":null,"spb":null,"bdatl":null,"trd":null,"spf":null,"ltp":null,"atb":[[1.0800000000000001,39933.199999999997]],"spl":null,"spn":null,"atl":null,"batl":null,"id":19924823,"hc":null,"bdatb":null}],"img":null,"tv":null,"con":null,"marketdefinition":null,"id":"1.258926623"}],"conflatems":null,"op":"mcm","id":3}
{"ct":null,"SegmentType":null,"clk":"AIJOANVIAOMiAKpbAMdH","heartbeatms":null,"pt":1780839741371,"Oc":[{"Accountid":null,"Orc":[{"Mb":null,"Uo":[{"Side":1,"pt":0,"Ot":0,"Status":0,"Sv":0,"P":1.0800000000000001,"Sc":0,"rc":"REG_LGA","S":5.2300000000000004,"Pd":1780839741000,"Rac":"","Md":null,"Sl":0,"Avp":null,"Sm":0,"id":"431727017523","Bsp":null,"Sr":5.2300000000000004,"Cd":null,"Rfo":"SL-Lay-1","Rfs":"SL"}],"id":19924823,"hc":null,"FullImage":null,"Ml":null}],"Closed":null,"id":"1.258926623","FullImage":null}],"initialclk":null,"conflatems":null,"op":"ocm","id":2}
{"ct":null,"SegmentType":null,"clk":"AI2LAQC7jgEAwoYB","heartbeatms":null,"pt":1780839741471,"initialclk":null,"mc":[{"rc":[{"tv":null,"batb":null,"spb":null,"bdatl":null,"trd":null,"spf":null,"ltp":null,"atb":[[8.5999999999999996,628.30999999999995]],"spl":null,"spn":null,"atl":null,"batl":null,"id":16570658,"hc":null,"bdatb":null}],"img":null,"tv":null,"con":null,"marketdefinition":null,"id":"1.258926623"}],"conflatems":null,"op":"mcm","id":3}
{"ct":null,"SegmentType":null,"clk":"AJqLAQDIjgEAx4YB","heartbeatms":null,"pt":1780839741578,"initialclk":null,"mc":[{"rc":[{"tv":2033929.1899999999,"batb":null,"spb":null,"bdatl":null,"trd":[[1.1299999999999999,219431.95000000001]],"spf":null,"ltp":null,"atb":null,"spl":null,"spn":null,"atl":[[1.1299999999999999,3652.79]],"batl":null,"id":19924823,"hc":null,"bdatb":null}],"img":null,"tv":2276831.6600000001,"con":null,"marketdefinition":null,"id":"1.258926623"}],"conflatems":null,"op":"mcm","id":3}
{"ct":null,"SegmentType":null,"clk":"AKKLAQDWjgEAzIYB","heartbeatms":null,"pt":1780839741688,"initialclk":null,"mc":[{"rc":[{"tv":null,"batb":null,"spb":null,"bdatl":null,"trd":null,"spf":null,"ltp":null,"atb":null,"spl":null,"spn":null,"atl":[[1.1299999999999999,197.66999999999999]],"batl":null,"id":19924823,"hc":null,"bdatb":null}],"img":null,"tv":null,"con":null,"marketdefinition":null,"id":"1.258926623"}],"conflatems":null,"op":"mcm","id":3}
{"ct":null,"SegmentType":null,"clk":"AKqLAQDgjgEA0YYB","heartbeatms":null,"pt":1780839741786,"initialclk":null,"mc":[{"rc":[{"tv":null,"batb":null,"spb":null,"bdatl":null,"trd":null,"spf":null,"ltp":null,"atb":[[8.5999999999999996,728.30999999999995]],"spl":null,"spn":null,"atl":null,"batl":null,"id":16570658,"hc":null,"bdatb":null},{"tv":null,"batb":null,"spb":null,"bdatl":null,"trd":null,"spf":null,"ltp":null,"atb":[[1.1100000000000001,71217.990000000005]],"spl":null,"spn":null,"atl":null,"batl":null,"id":19924823,"hc":null,"bdatb":null}],"img":null,"tv":null,"con":null,"marketdefinition":null,"id":"1.258926623"}],"conflatems":null,"op":"mcm","id":3}
{"ct":null,"SegmentType":null,"clk":"AMSLAQCFjwEA64YB","heartbeatms":null,"pt":1780839742092,"initialclk":null,"mc":[{"rc":[{"tv":2033963.99,"batb":null,"spb":null,"bdatl":null,"trd":[[1.1200000000000001,56576.830000000002]],"spf":null,"ltp":1.1200000000000001,"atb":[[1.1200000000000001,30671.470000000001]],"spl":null,"spn":null,"atl":null,"batl":null,"id":19924823,"hc":null,"bdatb":null}],"img":null,"tv":2276866.46,"con":null,"marketdefinition":null,"id":"1.258926623"}],"conflatems":null,"op":"mcm","id":3}
{"ct":null,"SegmentType":null,"clk":"ANCLAQCRjwEA8YYB","heartbeatms":null,"pt":1780839742150,"initialclk":null,"mc":[{"rc":[{"tv":243407.69,"batb":null,"spb":null,"bdatl":null,"trd":[[8.8000000000000007,1153.54],[9,772.92999999999995],[8.5999999999999996,1720.9400000000001]],"spf":null,"ltp":8.5999999999999996,"atb":[[8.8000000000000007,0],[9,0],[8.5999999999999996,477.33999999999998]],"spl":null,"spn":null,"atl":[[8.8000000000000007,77.760000000000005],[9,138.88999999999999]],"batl":null,"id":16570658,"hc":null,"bdatb":null},{"tv":2034384.97,"batb":null,"spb":null,"bdatl":null,"trd":[[1.1299999999999999,219852.92999999999]],"spf":null,"ltp":1.1299999999999999,"atb":[[1.1299999999999999,5053.6300000000001]],"spl":null,"spn":null,"atl":[[1.1299999999999999,0]],"batl":null,"id":19924823,"hc":null,"bdatb":null}],"img":null,"tv":2277792.6600000001,"con":null,"marketdefinition":null,"id":"1.258926623"}],"conflatems":null,"op":"mcm","id":3}
{"ct":null,"SegmentType":null,"clk":"ANqLAQCajwEA\u002B4YB","heartbeatms":null,"pt":1780839742254,"initialclk":null,"mc":[{"rc":[{"tv":null,"batb":null,"spb":null,"bdatl":null,"trd":null,"spf":null,"ltp":null,"atb":null,"spl":null,"spn":null,"atl":[[9.1999999999999993,361.75999999999999],[9,214.46000000000001]],"batl":null,"id":16570658,"hc":null,"bdatb":null}],"img":null,"tv":null,"con":null,"marketdefinition":null,"id":"1.258926623"}],"conflatems":null,"op":"mcm","id":3}
{"ct":null,"SegmentType":null,"clk":"AOOLAQCkjwEA/4YB","heartbeatms":null,"pt":1780839742356,"initialclk":null,"mc":[{"rc":[{"tv":null,"batb":null,"spb":null,"bdatl":null,"trd":null,"spf":null,"ltp":null,"atb":[[7.5999999999999996,12.94]],"spl":null,"spn":null,"atl":[[9,186.68000000000001]],"batl":null,"id":16570658,"hc":null,"bdatb":null},{"tv":null,"batb":null,"spb":null,"bdatl":null,"trd":null,"spf":null,"ltp":null,"atb":[[1.1299999999999999,191.75999999999999],[1.1100000000000001,71164.410000000003]],"spl":null,"spn":null,"atl":null,"batl":null,"id":19924823,"hc":null,"bdatb":null}],"img":null,"tv":null,"con":null,"marketdefinition":null,"id":"1.258926623"}],"conflatems":null,"op":"mcm","id":3}
