{"ct":0,"SegmentType":null,"clk":"AAAAAAAA","heartbeatms":5000,"pt":1780840078014,"initialclk":"KoOJnfkJK/KF7PIJK/jD8ecJ","mc":[{"rc":[{"tv":249606.14999999999,"batb":null,"spb":null,"bdatl":null,"trd":[[8.4000000000000004,2828.0999999999999],[8.5999999999999996,2915.6900000000001],[9.1999999999999993,1757.6400000000001],[8.8000000000000007,2199.1100000000001],[9,1087.5799999999999],[9.4000000000000004,761.47000000000003],[8.1999999999999993,1722.4000000000001],[8,3816.0799999999999],[9.5999999999999996,386.73000000000002],[10,272.47000000000003],[9.8000000000000007,871.63],[7.7999999999999998,732.79999999999995],[7.5999999999999996,1586.5899999999999],[7,5.0499999999999998],[7.4000000000000004,1],[7.2000000000000002,1],[6.7999999999999998,634.39999999999998],[6.5999999999999996,819.97000000000003],[6.4000000000000004,795.78999999999996],[6.2000000000000002,3410.3600000000001],[5.7999999999999998,25054.669999999998],[5.7000000000000002,9564.7099999999991],[5.9000000000000004,702.05999999999995],[6,686.34000000000003],[5.5,21583.27],[5.5999999999999996,4770.9899999999998],[5.4000000000000004,42199.519999999997],[5.2999999999999998,22117.549999999999],[5.2000000000000002,3639.98],[5.0999999999999996,13755.219999999999],[5,17746.360000000001],[4.9000000000000004,9609.3899999999994],[4.7999999999999998,4883.1499999999996],[4.7000000000000002,2994.5799999999999],[4.5999999999999996,15402.610000000001],[4.5,23562.869999999999],[4.4000000000000004,3387.9299999999998],[4.2000000000000002,392.72000000000003],[4.2999999999999998,878.37],[3.8999999999999999,48],[4.0999999999999996,20]],"spf":null,"ltp":8.4000000000000004,"atb":[[8.1999999999999993,68.959999999999994],[7.7999999999999998,505.00999999999999],[6.5999999999999996,25.989999999999998],[6.7999999999999998,25.379999999999999],[7.4000000000000004,403.13],[7.2000000000000002,13.529999999999999],[8,728.04999999999995],[7,760.03999999999996],[7.5999999999999996,151.05000000000001],[1.01,18490.740000000002],[1.55,3.1600000000000001],[5,18.059999999999999],[4,101.12000000000001],[4.4000000000000004,8.6400000000000006],[1.1000000000000001,6768.2200000000003],[1.69,24.190000000000001],[2.2599999999999998,13.82],[2.7799999999999998,10.369999999999999],[3.3500000000000001,6.71],[3,38.210000000000001],[4.0999999999999996,8.6400000000000006],[3.8999999999999999,17.280000000000001],[4.2000000000000002,8.6400000000000006],[4.2999999999999998,38.869999999999997],[1.04,11387.200000000001],[4.5,52.829999999999998],[3.7999999999999998,14.68],[4.9000000000000004,4.5999999999999996],[4.7999999999999998,43.189999999999998],[4.7000000000000002,2.6699999999999999],[1.02,16541.880000000001],[1.1100000000000001,3003.8699999999999],[2.1200000000000001,105.75],[1.1200000000000001,117.38],[3.0499999999999998,12.09],[3.3999999999999999,7.7699999999999996],[1.5,5],[2.3599999999999999,202.19999999999999],[2.6800000000000002,52.869999999999997],[1.03,11277.290000000001],[1.05,8477.8700000000008],[1.1499999999999999,10],[1.2,21],[1.25,130],[1.3,10],[1.3500000000000001,10],[1.52,63.979999999999997],[1.75,11.630000000000001],[2.1000000000000001,7.9299999999999997],[2.3999999999999999,8.9900000000000002],[1.3200000000000001,59.219999999999999],[1.71,28.550000000000001],[1.8300000000000001,34.899999999999999],[2.2200000000000002,59.219999999999999],[1.0700000000000001,2999.6500000000001],[1.0600000000000001,4498.6800000000003],[1.0800000000000001,2999.6500000000001],[1.0900000000000001,2999.6500000000001]],"spl":null,"spn":null,"atl":[[8.4000000000000004,0.070000000000000007],[10,146.30000000000001],[8.8000000000000007,137.75],[8.5999999999999996,151.87000000000001],[9.4000000000000004,74.730000000000004],[9.5999999999999996,20],[10.5,359.33999999999997],[13,5.8300000000000001],[12.5,6.0800000000000001],[12,6.3600000000000003],[9.1999999999999993,321.38],[9,167.72],[11,239.16999999999999],[11.5,58.649999999999999],[13.5,65.200000000000003],[14.5,1.5],[100,4.5300000000000002],[200,1],[20,1.2],[1000,0.87],[30,0.56999999999999995],[55,0.28999999999999998],[50,67.5],[60,10.57],[34,10.57],[180,1],[150,1],[75,1],[40,1]],"batl":null,"id":16570658,"hc":null,"bdatb":null},{"tv":2141223.04,"batb":null,"spb":null,"bdatl":null,"trd":[[1.1299999999999999,272802.42999999999],[1.1399999999999999,172592.48999999999],[1.1200000000000001,70861.479999999996],[1.1100000000000001,101105.78],[1.1499999999999999,11637.32],[1.1599999999999999,3525.6199999999999],[1.1699999999999999,36180.339999999997],[1.1799999999999999,46182.110000000001],[1.19,10436.32],[1.2,42764.610000000001],[1.21,229366.76000000001],[1.22,236468.92999999999],[1.23,312970.45000000001],[1.24,101828.94],[1.25,206182.45999999999],[1.26,28136.310000000001],[1.27,63542.400000000001],[1.28,130279.96000000001],[1.29,48226.879999999997],[1.3,14804.200000000001],[1.3100000000000001,1248.97],[1.3200000000000001,78.280000000000001]],"spf":null,"ltp":1.1299999999999999,"atb":[[1.1299999999999999,11322.690000000001],[1.04,73842.729999999996],[1.1200000000000001,36361.620000000003],[1.1100000000000001,54829.839999999997],[1.03,88980.389999999999],[1.02,90735.919999999998],[1.0700000000000001,38885.129999999997],[1.1000000000000001,63298.290000000001],[1.0800000000000001,40769.5],[1.05,74308.929999999993],[1.0900000000000001,40185.099999999999],[1.0600000000000001,63326.940000000002],[1.01,93593.869999999995]],"spl":null,"spn":null,"atl":[[1.1399999999999999,26801.700000000001],[1.1599999999999999,27818.450000000001],[1.3999999999999999,1097.6400000000001],[1.1699999999999999,8884.6900000000005],[1.24,205.93000000000001],[1.23,681.25999999999999],[1.19,8880.4099999999999],[1.1799999999999999,8877.4599999999991],[1.1499999999999999,31024.830000000002],[1000,0.88],[1.21,8960.3500000000004],[1.22,9089.1000000000004],[1.2,9101.0499999999993],[1.4199999999999999,2.3900000000000001],[100,3],[2,22.18],[1.25,30.899999999999999],[6,16.579999999999998],[1.76,456],[1.3,894.33000000000004],[1.51,228],[1.26,2252.5100000000002],[1.29,473.61000000000001],[1.3200000000000001,80.640000000000001],[1.27,10],[1.28,20.289999999999999],[1.4099999999999999,17.280000000000001],[1.3100000000000001,61.509999999999998],[1.3799999999999999,561.15999999999997],[1.44,35.719999999999999],[1.3500000000000001,150.83000000000001],[1.3400000000000001,28.809999999999999],[1.3300000000000001,18.640000000000001],[1.3700000000000001,1552.6300000000001],[1.3600000000000001,17.289999999999999],[1.3899999999999999,8.6400000000000006],[1.8,3.5099999999999998],[1.5,129.47999999999999],[1.6699999999999999,20],[1.53,7.9299999999999997],[1.8200000000000001,210.53999999999999],[1.45,1.3200000000000001],[1.8799999999999999,1],[50,66.439999999999998],[1.6000000000000001,0.83999999999999997],[7,5.29],[1.6499999999999999,4.3200000000000003],[2.96,2.0600000000000001],[2.6000000000000001,0.029999999999999999],[21,10.57],[1.7,1018],[1.49,2.23],[1.6200000000000001,77.739999999999995],[4.7999999999999998,20.239999999999998],[2.2200000000000002,9],[2.98,105.75],[2.04,12.109999999999999],[1.6100000000000001,33.119999999999997],[2.1400000000000001,10],[1.94,10],[1.8400000000000001,10],[1.74,10],[1.5600000000000001,2.46],[75,1],[40,1]],"batl":null,"id":19924823,"hc":null,"bdatb":null}],"img":true,"tv":2390829.1899999999,"con":null,"marketdefinition":null,"id":"1.258926623"}],"conflatems":0,"op":"mcm","id":4}
{"ct":null,"SegmentType":null,"clk":"AAUABgAC","heartbeatms":null,"pt":1780840078065,"initialclk":null,"mc":[{"rc":[{"tv":2141224.6699999999,"batb":null,"spb":null,"bdatl":null,"trd":[[1.1399999999999999,172594.12]],"spf":null,"ltp":1.1399999999999999,"atb":null,"spl":null,"spn":null,"atl":[[1.1399999999999999,26800.889999999999]],"batl":null,"id":19924823,"hc":null,"bdatb":null}],"img":null,"tv":2390830.8199999998,"con":null,"marketdefinition":null,"id":"1.258926623"}],"conflatems":null,"op":"mcm","id":4}
{"ct":null,"SegmentType":null,"clk":"AJoBAK0BAHA=","heartbeatms":null,"pt":1780840079448,"initialclk":null,"mc":[{"rc":[{"tv":null,"batb":null,"spb":null,"bdatl":null,"trd":null,"spf":null,"ltp":null,"atb":null,"spl":null,"spn":null,"atl":[[8.5999999999999996,147.94999999999999]],"batl":null,"id":16570658,"hc":null,"bdatb":null},{"tv":2141253.6699999999,"batb":null,"spb":null,"bdatl":null,"trd":[[1.1399999999999999,172623.12]],"spf":null,"ltp":null,"atb":null,"spl":null,"spn":null,"atl":[[1.1399999999999999,26786.389999999999]],"batl":null,"id":19924823,"hc":null,"bdatb":null}],"img":null,"tv":2390859.8199999998,"con":null,"marketdefinition":null,"id":"1.258926623"}],"conflatems":null,"op":"mcm","id":4}
{"ct":null,"SegmentType":null,"clk":"AKIBALkBAHU=","heartbeatms":null,"pt":1780840079551,"initialclk":null,"mc":[{"rc":[{"tv":null,"batb":null,"spb":null,"bdatl":null,"trd":null,"spf":null,"ltp":null,"atb":null,"spl":null,"spn":null,"atl":[[8.4000000000000004,3.9900000000000002]],"batl":null,"id":16570658,"hc":null,"bdatb":null}],"img":null,"tv":null,"con":null,"marketdefinition":null,"id":"1.258926623"}],"conflatems":null,"op":"mcm","id":4}
{"ct":null,"SegmentType":null,"clk":"ALIBAmcBAH4=","heartbeatms":null,"pt":1780840079657,"initialclk":null,"mc":[{"rc":[{"tv":null,"batb":null,"spb":null,"bdatl":null,"trd":null,"spf":null,"ltp":null,"atb":null,"spl":null,"spn":null,"atl":[[8.5999999999999996,0]],"batl":null,"id":16570658,"hc":null,"bdatb":null},{"tv":2141262.8399999999,"batb":null,"spb":null,"bdatl":null,"trd":[[1.1399999999999999,172632.29000000001]],"spf":null,"ltp":null,"atb":null,"spl":null,"spn":null,"atl":[[1.1399999999999999,26781.799999999999]],"batl":null,"id":19924823,"hc":null,"bdatb":null}],"img":null,"tv":2390868.9900000002,"con":null,"marketdefinition":null,"id":"1.258926623"}],"conflatems":null,"op":"mcm","id":4}
{"ct":null,"SegmentType":null,"clk":"AMABANMBAIkB","heartbeatms":null,"pt":1780840079769,"initialclk":null,"mc":[{"rc":[{"tv":null,"batb":null,"spb":null,"bdatl":null,"trd":null,"spf":null,"ltp":null,"atb":null,"spl":null,"spn":null,"atl":[[8.5999999999999996,144.47999999999999]],"batl":null,"id":16570658,"hc":null,"bdatb":null},{"tv":null,"batb":null,"spb":null,"bdatl":null,"trd":null,"spf":null,"ltp":null,"atb":[[1.1200000000000001,36359.620000000003]],"spl":null,"spn":null,"atl":null,"batl":null,"id":19924823,"hc":null,"bdatb":null}],"img":null,"tv":null,"con":null,"marketdefinition":null,"id":"1.258926623"}],"conflatems":null,"op":"mcm","id":4}
{"ct":null,"SegmentType":null,"clk":"AOABAPIBAJwB","heartbeatms":null,"pt":1780840080082,"initialclk":null,"mc":[{"rc":[{"tv":null,"batb":null,"spb":null,"bdatl":null,"trd":null,"spf":null,"ltp":null,"atb":null,"spl":null,"spn":null,"atl":[[9.4000000000000004,76.730000000000004]],"batl":null,"id":16570658,"hc":null,"bdatb":null},{"tv":null,"batb":null,"spb":null,"bdatl":null,"trd":null,"spf":null,"ltp":null,"atb":[[1.1200000000000001,36365.019999999997]],"spl":null,"spn":null,"atl":null,"batl":null,"id":19924823,"hc":null,"bdatb":null}],"img":null,"tv":null,"con":null,"marketdefinition":null,"id":"1.258926623"}],"conflatems":null,"op":"mcm","id":4}
{"ct":null,"SegmentType":null,"clk":"AOcBAPoBAKQB","heartbeatms":null,"pt":1780840080174,"initialclk":null,"mc":[{"rc":[{"tv":null,"batb":null,"spb":null,"bdatl":null,"trd":null,"spf":null,"ltp":null,"atb":[[7,1088.8800000000001],[6.7999999999999998,145.91],[7.4000000000000004,211.34999999999999],[8,625.5]],"spl":null,"spn":null,"atl":[[9.8000000000000007,263.63],[10.5,270.33999999999997],[10,210.21000000000001],[9,1.0600000000000001]],"batl":null,"id":16570658,"hc":null,"bdatb":null},{"tv":null,"batb":null,"spb":null,"bdatl":null,"trd":null,"spf":null,"ltp":null,"atb":[[1.1299999999999999,2002.02],[1.1000000000000001,61572.290000000001],[1.1200000000000001,34132.879999999997]],"spl":null,"spn":null,"atl":[[1.1399999999999999,8480.1599999999999],[1.1599999999999999,26595.009999999998],[1.1499999999999999,29373.830000000002]],"batl":null,"id":19924823,"hc":null,"bdatb":null}],"img":null,"tv":null,"con":null,"marketdefinition":null,"id":"1.258926623"}],"conflatems":null,"op":"mcm","id":4}
{"ct":null,"SegmentType":null,"clk":"AIYCAJsCAMAB","heartbeatms":null,"pt":1780840080474,"initialclk":null,"mc":[{"rc":[{"tv":null,"batb":null,"spb":null,"bdatl":null,"trd":null,"spf":null,"ltp":null,"atb":[[7.7999999999999998,217.53],[7.5999999999999996,55.979999999999997]],"spl":null,"spn":null,"atl":[[9.4000000000000004,3.73],[11,103.94],[10.5,4.2400000000000002],[9.1999999999999993,30.140000000000001]],"batl":null,"id":16570658,"hc":null,"bdatb":null}],"img":null,"tv":null,"con":null,"marketdefinition":null,"id":"1.258926623"}],"conflatems":null,"op":"mcm","id":4}
{"ct":null,"SegmentType":null,"clk":"AJMCAKgCAMUB","heartbeatms":null,"pt":1780840080579,"initialclk":null,"mc":[{"rc":[{"tv":null,"batb":null,"spb":null,"bdatl":null,"trd":null,"spf":null,"ltp":null,"atb":[[7.7999999999999998,14.710000000000001],[7.4000000000000004,8.3599999999999994],[8.1999999999999993,8.4199999999999999]],"spl":null,"spn":null,"atl":[[8.8000000000000007,0],[8.5999999999999996,0]],"batl":null,"id":16570658,"hc":null,"bdatb":null},{"tv":null,"batb":null,"spb":null,"bdatl":null,"trd":null,"spf":null,"ltp":null,"atb":[[1.1299999999999999,901.33000000000004],[1.1200000000000001,33050.540000000001]],"spl":null,"spn":null,"atl":[[1.1399999999999999,7544.9499999999998]],"batl":null,"id":19924823,"hc":null,"bdatb":null}],"img":null,"tv":null,"con":null,"marketdefinition":null,"id":"1.258926623"}],"conflatems":null,"op":"mcm","id":4}
{"ct":null,"SegmentType":null,"clk":"AMMCAN0CAO4B","heartbeatms":null,"pt":1780840081058,"initialclk":null,"mc":[{"rc":[{"tv":null,"batb":null,"spb":null,"bdatl":null,"trd":null,"spf":null,"ltp":null,"atb":[[1.1299999999999999,449.86000000000001],[1.1100000000000001,56233.019999999997],[1.1200000000000001,32186.779999999999]],"spl":null,"spn":null,"atl":[[1.1699999999999999,10131.02],[1.1399999999999999,6894.3699999999999],[1.1599999999999999,27964.860000000001],[1.1499999999999999,27712.740000000002]],"batl":null,"id":19924823,"hc":null,"bdatb":null}],"img":null,"tv":null,"con":null,"marketdefinition":null,"id":"1.258926623"}],"conflatems":null,"op":"mcm","id":4}
{"ct":null,"SegmentType":null,"clk":"AM0CAOgCAPcB","heartbeatms":null,"pt":1780840081162,"initialclk":null,"mc":[{"rc":[{"tv":null,"batb":null,"spb":null,"bdatl":null,"trd":null,"spf":null,"ltp":null,"atb":[[1.1100000000000001,56392.849999999999]],"spl":null,"spn":null,"atl":null,"batl":null,"id":19924823,"hc":null,"bdatb":null}],"img":null,"tv":null,"con":null,"marketdefinition":null,"id":"1.258926623"}],"conflatems":null,"op":"mcm","id":4}
{"ct":null,"SegmentType":null,"clk":"ANsCAP0CAIoC","heartbeatms":null,"pt":1780840081362,"initialclk":null,"mc":[{"rc":[{"tv":2141266.1499999999,"batb":null,"spb":null,"bdatl":null,"trd":[[1.1399999999999999,172635.60000000001]],"spf":null,"ltp":null,"atb":null,"spl":null,"spn":null,"atl":[[1.1399999999999999,6892.7200000000003]],"batl":null,"id":19924823,"hc":null,"bdatb":null}],"img":null,"tv":2390872.2999999998,"con":null,"marketdefinition":null,"id":"1.258926623"}],"conflatems":null,"op":"mcm","id":4}
{"ct":null,"SegmentType":null,"clk":"AJ0DAMkDAMQC","heartbeatms":null,"pt":1780840082076,"initialclk":null,"mc":[{"rc":[{"tv":2141410.54,"batb":null,"spb":null,"bdatl":null,"trd":[[1.1299999999999999,272946.82000000001]],"spf":null,"ltp":1.1299999999999999,"atb":[[1.1299999999999999,22.140000000000001]],"spl":null,"spn":null,"atl":null,"batl":null,"id":19924823,"hc":null,"bdatb":null}],"img":null,"tv":2391016.6899999999,"con":null,"marketdefinition":null,"id":"1.258926623"}],"conflatems":null,"op":"mcm","id":4}
{"ct":null,"SegmentType":null,"clk":"AKIDANQDAMYC","heartbeatms":null,"pt":1780840082139,"initialclk":null,"mc":[{"rc":[{"tv":null,"batb":null,"spb":null,"bdatl":null,"trd":null,"spf":null,"ltp":null,"atb":[[8.1999999999999993,0]],"spl":null,"spn":null,"atl":null,"batl":null,"id":16570658,"hc":null,"bdatb":null}],"img":null,"tv":null,"con":null,"marketdefinition":null,"id":"1.258926623"}],"conflatems":null,"op":"mcm","id":4}
{"ct":null,"SegmentType":null,"clk":"AMsDAPcDANkC","heartbeatms":null,"pt":1780840082447,"initialclk":null,"mc":[{"rc":[{"tv":null,"batb":null,"spb":null,"bdatl":null,"trd":null,"spf":null,"ltp":null,"atb":null,"spl":null,"spn":null,"atl":[[8.1999999999999993,7.04]],"batl":null,"id":16570658,"hc":null,"bdatb":null}],"img":null,"tv":null,"con":null,"marketdefinition":null,"id":"1.258926623"}],"conflatems":null,"op":"mcm","id":4}
{"ct":null,"SegmentType":null,"clk":"ANwDAIUEAOIC","heartbeatms":null,"pt":1780840082554,"initialclk":null,"mc":[{"rc":[{"tv":null,"batb":null,"spb":null,"bdatl":null,"trd":null,"spf":null,"ltp":null,"atb":[[1.1200000000000001,32239.880000000001]],"spl":null,"spn":null,"atl":null,"batl":null,"id":19924823,"hc":null,"bdatb":null}],"img":null,"tv":null,"con":null,"marketdefinition":null,"id":"1.258926623"}],"conflatems":null,"op":"mcm","id":4}
{"ct":null,"SegmentType":null,"clk":"APwDAKcEAIAD","heartbeatms":null,"pt":1780840082862,"initialclk":null,"mc":[{"rc":[{"tv":249617.17999999999,"batb":null,"spb":null,"bdatl":null,"trd":[[8.4000000000000004,2832.0900000000001],[8.1999999999999993,1729.4400000000001]],"spf":null,"ltp":null,"atb":null,"spl":null,"spn":null,"atl":[[8.4000000000000004,0],[8.1999999999999993,0]],"batl":null,"id":16570658,"hc":null,"bdatb":null},{"tv":2141535.6000000001,"batb":null,"spb":null,"bdatl":null,"trd":[[1.1299999999999999,273071.88]],"spf":null,"ltp":null,"atb":[[1.1299999999999999,0]],"spl":null,"spn":null,"atl":[[1.1299999999999999,410.13]],"batl":null,"id":19924823,"hc":null,"bdatb":null}],"img":null,"tv":2391152.7799999998,"con":null,"marketdefinition":null,"id":"1.258926623"}],"conflatems":null,"op":"mcm","id":4}
{"ct":null,"SegmentType":null,"clk":"AI4EALwEAIsD","heartbeatms":null,"pt":1780840083058,"initialclk":null,"mc":[{"rc":[{"tv":249627.17999999999,"batb":null,"spb":null,"bdatl":null,"trd":[[8.5999999999999996,2925.6900000000001]],"spf":null,"ltp":8.5999999999999996,"atb":null,"spl":null,"spn":null,"atl":null,"batl":null,"id":16570658,"hc":null,"bdatb":null},{"tv":2141611.71,"batb":null,"spb":null,"bdatl":null,"trd":[[1.1299999999999999,273147.98999999999]],"spf":null,"ltp":null,"atb":null,"spl":null,"spn":null,"atl":[[1.1299999999999999,334.01999999999998]],"batl":null,"id":19924823,"hc":null,"bdatb":null}],"img":null,"tv":2391238.8900000001,"con":null,"marketdefinition":null,"id":"1.258926623"}],"conflatems":null,"op":"mcm","id":4}
{"ct":null,"SegmentType":null,"clk":"AMwEAIAFAMkD","heartbeatms":null,"pt":1780840083638,"initialclk":null,"mc":[{"rc":[{"tv":null,"batb":null,"spb":null,"bdatl":null,"trd":null,"spf":null,"ltp":null,"atb":[[1.1200000000000001,32312.080000000002]],"spl":null,"spn":null,"atl":null,"batl":null,"id":19924823,"hc":null,"bdatb":null}],"img":null,"tv":null,"con":null,"marketdefinition":null,"id":"1.258926623"}],"conflatems":null,"op":"mcm","id":4}
{"ct":null,"SegmentType":null,"clk":"ANUEAIkFANAD","heartbeatms":null,"pt":1780840083738,"initialclk":null,"mc":[{"rc":[{"tv":null,"batb":null,"spb":null,"bdatl":null,"trd":null,"spf":null,"ltp":null,"atb":[[8.1999999999999993,4]],"spl":null,"spn":null,"atl":null,"batl":null,"id":16570658,"hc":null,"bdatb":null}],"img":null,"tv":null,"con":null,"marketdefinition":null,"id":"1.258926623"}],"conflatems":null,"op":"mcm","id":4}
{"ct":null,"SegmentType":null,"clk":"AN4EAJUFANYD","heartbeatms":null,"pt":1780840083849,"initialclk":null,"mc":[{"rc":[{"tv":null,"batb":null,"spb":null,"bdatl":null,"trd":null,"spf":null,"ltp":null,"atb":[[1.1200000000000001,32258.98]],"spl":null,"spn":null,"atl":null,"batl":null,"id":19924823,"hc":null,"bdatb":null}],"img":null,"tv":null,"con":null,"marketdefinition":null,"id":"1.258926623"}],"conflatems":null,"op":"mcm","id":4}
{"ct":null,"SegmentType":null,"clk":"APwEALoFAOgD","heartbeatms":null,"pt":1780840084150,"initialclk":null,"mc":[{"rc":[{"tv":null,"batb":null,"spb":null,"bdatl":null,"trd":null,"spf":null,"ltp":null,"atb":[[7.2000000000000002,12.67]],"spl":null,"spn":null,"atl":null,"batl":null,"id":16570658,"hc":null,"bdatb":null},{"tv":null,"batb":null,"spb":null,"bdatl":null,"trd":null,"spf":null,"ltp":null,"atb":null,"spl":null,"spn":null,"atl":[[1.1599999999999999,27960.02]],"batl":null,"id":19924823,"hc":null,"bdatb":null}],"img":null,"tv":null,"con":null,"marketdefinition":null,"id":"1.258926623"}],"conflatems":null,"op":"mcm","id":4}
{"ct":null,"SegmentType":null,"clk":"ANsFAKoGAKsE","heartbeatms":null,"pt":1780840085072,"initialclk":null,"mc":[{"rc":[{"tv":null,"batb":null,"spb":null,"bdatl":null,"trd":null,"spf":null,"ltp":null,"atb":[[7.7999999999999998,23.129999999999999]],"spl":null,"spn":null,"atl":null,"batl":null,"id":16570658,"hc":null,"bdatb":null}],"img":null,"tv":null,"con":null,"marketdefinition":null,"id":"1.258926623"}],"conflatems":null,"op":"mcm","id":4}
{"ct":null,"SegmentType":null,"clk":"ANMGALAHAI4F","heartbeatms":null,"pt":1780840086268,"initialclk":null,"mc":[{"rc":[{"tv":249628.16,"batb":null,"spb":null,"bdatl":null,"trd":[[8.5999999999999996,2926.6700000000001]],"spf":null,"ltp":null,"atb":null,"spl":null,"spn":null,"atl":null,"batl":null,"id":16570658,"hc":null,"bdatb":null},{"tv":2141619.1899999999,"batb":null,"spb":null,"bdatl":null,"trd":[[1.1299999999999999,273155.46999999997]],"spf":null,"ltp":null,"atb":null,"spl":null,"spn":null,"atl":[[1.1299999999999999,326.54000000000002]],"batl":null,"id":19924823,"hc":null,"bdatb":null}],"img":null,"tv":2391247.3500000001,"con":null,"marketdefinition":null,"id":"1.258926623"}],"conflatems":null,"op":"mcm","id":4}
{"ct":null,"SegmentType":null,"clk":"AOUGAL4HAJoF","heartbeatms":null,"pt":1780840086462,"initialclk":null,"mc":[{"rc":[{"tv":null,"batb":null,"spb":null,"bdatl":null,"trd":null,"spf":null,"ltp":null,"atb":[[1.1200000000000001,32388.540000000001]],"spl":null,"spn":null,"atl":null,"batl":null,"id":19924823,"hc":null,"bdatb":null}],"img":null,"tv":null,"con":null,"marketdefinition":null,"id":"1.258926623"}],"conflatems":null,"op":"mcm","id":4}
{"ct":null,"SegmentType":null,"clk":"AO4GAMYHAKEF","heartbeatms":null,"pt":1780840086562,"initialclk":null,"mc":[{"rc":[{"tv":null,"batb":null,"spb":null,"bdatl":null,"trd":null,"spf":null,"ltp":null,"atb":[[1.1200000000000001,32518.110000000001]],"spl":null,"spn":null,"atl":null,"batl":null,"id":19924823,"hc":null,"bdatb":null}],"img":null,"tv":null,"con":null,"marketdefinition":null,"id":"1.258926623"}],"conflatems":null,"op":"mcm","id":4}
{"ct":null,"SegmentType":null,"clk":"AOkHAMYIAIEG","heartbeatms":null,"pt":1780840087966,"initialclk":null,"mc":[{"rc":[{"tv":null,"batb":null,"spb":null,"bdatl":null,"trd":null,"spf":null,"ltp":null,"atb":null,"spl":null,"spn":null,"atl":[[1.1399999999999999,3892.7199999999998]],"batl":null,"id":19924823,"hc":null,"bdatb":null}],"img":null,"tv":null,"con":null,"marketdefinition":null,"id":"1.258926623"}],"conflatems":null,"op":"mcm","id":4}
{"ct":null,"SegmentType":null,"clk":"ANAIAKQJAN0G","heartbeatms":null,"pt":1780840088978,"initialclk":null,"mc":[{"rc":[{"tv":null,"batb":null,"spb":null,"bdatl":null,"trd":null,"spf":null,"ltp":null,"atb":null,"spl":null,"spn":null,"atl":[[1.1399999999999999,2648.0100000000002]],"batl":null,"id":19924823,"hc":null,"bdatb":null}],"img":null,"tv":null,"con":null,"marketdefinition":null,"id":"1.258926623"}],"conflatems":null,"op":"mcm","id":4}
{"ct":null,"SegmentType":null,"clk":"AN4IALYJAPMG","heartbeatms":null,"pt":1780840089143,"initialclk":null,"mc":[{"rc":[{"tv":null,"batb":null,"spb":null,"bdatl":null,"trd":null,"spf":null,"ltp":null,"atb":[[8,25.5]],"spl":null,"spn":null,"atl":null,"batl":null,"id":16570658,"hc":null,"bdatb":null}],"img":null,"tv":null,"con":null,"marketdefinition":null,"id":"1.258926623"}],"conflatems":null,"op":"mcm","id":4}
{"ct":null,"SegmentType":null,"clk":"AP0IAN8JAJcH","heartbeatms":null,"pt":1780840089556,"initialclk":null,"mc":[{"rc":[{"tv":2141619.7599999998,"batb":null,"spb":null,"bdatl":null,"trd":[[1.1299999999999999,273156.03999999998]],"spf":null,"ltp":null,"atb":null,"spl":null,"spn":null,"atl":[[1.1299999999999999,326.25],[1.1399999999999999,2503.6199999999999]],"batl":null,"id":19924823,"hc":null,"bdatb":null}],"img":null,"tv":2391247.9199999999,"con":null,"marketdefinition":null,"id":"1.258926623"}],"conflatems":null,"op":"mcm","id":4}
{"ct":null,"SegmentType":null,"clk":"AM4JALQKAM8H","heartbeatms":null,"pt":1780840090477,"initialclk":null,"mc":[{"rc":[{"tv":2141642.96,"batb":null,"spb":null,"bdatl":null,"trd":[[1.1299999999999999,273179.23999999999]],"spf":null,"ltp":null,"atb":null,"spl":null,"spn":null,"atl":[[1.1299999999999999,314.64999999999998]],"batl":null,"id":19924823,"hc":null,"bdatb":null}],"img":null,"tv":2391271.1200000001,"con":null,"marketdefinition":null,"id":"1.258926623"}],"conflatems":null,"op":"mcm","id":4}
{"ct":null,"SegmentType":null,"clk":"AOkJAM4KAOUH","heartbeatms":null,"pt":1780840090749,"initialclk":null,"mc":[{"rc":[{"tv":2142272.2599999998,"batb":null,"spb":null,"bdatl":null,"trd":[[1.1299999999999999,273808.53999999998]],"spf":null,"ltp":null,"atb":[[1.1299999999999999,8957.3500000000004]],"spl":null,"spn":null,"atl":[[1.1299999999999999,0]],"batl":null,"id":19924823,"hc":null,"bdatb":null}],"img":null,"tv":2391900.4199999999,"con":null,"marketdefinition":null,"id":"1.258926623"}],"conflatems":null,"op":"mcm","id":4}
{"ct":null,"SegmentType":null,"clk":"AIkKAPAKAPwH","heartbeatms":null,"pt":1780840091061,"initialclk":null,"mc":[{"rc":[{"tv":null,"batb":null,"spb":null,"bdatl":null,"trd":null,"spf":null,"ltp":null,"atb":[[1.1299999999999999,0]],"spl":null,"spn":null,"atl":null,"batl":null,"id":19924823,"hc":null,"bdatb":null}],"img":null,"tv":null,"con":null,"marketdefinition":null,"id":"1.258926623"}],"conflatems":null,"op":"mcm","id":4}
{"ct":null,"SegmentType":null,"clk":"AIgLALcLAMkI","heartbeatms":null,"pt":1780840091874,"initialclk":null,"mc":[{"rc":[{"tv":null,"batb":null,"spb":null,"bdatl":null,"trd":null,"spf":null,"ltp":null,"atb":null,"spl":null,"spn":null,"atl":[[8.5999999999999996,1]],"batl":null,"id":16570658,"hc":null,"bdatb":null}],"img":null,"tv":null,"con":null,"marketdefinition":null,"id":"1.258926623"}],"conflatems":null,"op":"mcm","id":4}
