{"ct":null,"SegmentType":null,"clk":"ALPhAQDq4QEAtdAB","heartbeatms":null,"pt":1780839855504,"initialclk":null,"mc":[{"rc":[{"tv":null,"batb":null,"spb":null,"bdatl":null,"trd":null,"spf":null,"ltp":null,"atb":null,"spl":null,"spn":null,"atl":[[100,3.5299999999999998]],"batl":null,"id":16570658,"hc":null,"bdatb":null},{"tv":null,"batb":null,"spb":null,"bdatl":null,"trd":null,"spf":null,"ltp":null,"atb":[[1.1200000000000001,44588.839999999997]],"spl":null,"spn":null,"atl":null,"batl":null,"id":19924823,"hc":null,"bdatb":null}],"img":null,"tv":null,"con":null,"marketdefinition":null,"id":"1.258926623"}],"conflatems":null,"op":"mcm","id":3}
{"ct":null,"SegmentType":null,"clk":"AI/iAQC\u002B4gEAjNEB","heartbeatms":null,"pt":1780839856494,"initialclk":null,"mc":[{"rc":[{"tv":2090828.8300000001,"batb":null,"spb":null,"bdatl":null,"trd":[[1.1299999999999999,238817.39999999999]],"spf":null,"ltp":null,"atb":null,"spl":null,"spn":null,"atl":[[1.1299999999999999,8.75]],"batl":null,"id":19924823,"hc":null,"bdatb":null}],"img":null,"tv":2337581.4500000002,"con":null,"marketdefinition":null,"id":"1.258926623"}],"conflatems":null,"op":"mcm","id":3}
{"ct":null,"SegmentType":null,"clk":"AJTiAQDH4gEAj9EB","heartbeatms":null,"pt":1780839856595,"initialclk":null,"mc":[{"rc":[{"tv":null,"batb":null,"spb":null,"bdatl":null,"trd":null,"spf":null,"ltp":null,"atb":[[1.1200000000000001,45175.650000000001]],"spl":null,"spn":null,"atl":[[1.1499999999999999,32140.880000000001]],"batl":null,"id":19924823,"hc":null,"bdatb":null}],"img":null,"tv":null,"con":null,"marketdefinition":null,"id":"1.258926623"}],"conflatems":null,"op":"mcm","id":3}
{"ct":null,"SegmentType":null,"clk":"AMDiAQDs4gEAsNEB","heartbeatms":null,"pt":1780839857011,"initialclk":null,"mc":[{"rc":[{"tv":null,"batb":null,"spb":null,"bdatl":null,"trd":null,"spf":null,"ltp":null,"atb":null,"spl":null,"spn":null,"atl":[[9.8000000000000007,153.91999999999999]],"batl":null,"id":16570658,"hc":null,"bdatb":null}],"img":null,"tv":null,"con":null,"marketdefinition":null,"id":"1.258926623"}],"conflatems":null,"op":"mcm","id":3}
{"ct":null,"SegmentType":null,"clk":"ANLiAQCH4wEAxNEB","heartbeatms":null,"pt":1780839857266,"initialclk":null,"mc":[{"rc":[{"tv":2090846.3300000001,"batb":null,"spb":null,"bdatl":null,"trd":[[1.1299999999999999,238834.89999999999]],"spf":null,"ltp":null,"atb":[[1.1299999999999999,792.01999999999998]],"spl":null,"spn":null,"atl":[[1.1299999999999999,0]],"batl":null,"id":19924823,"hc":null,"bdatb":null}],"img":null,"tv":2337598.9500000002,"con":null,"marketdefinition":null,"id":"1.258926623"}],"conflatems":null,"op":"mcm","id":3}
{"ct":null,"SegmentType":null,"clk":"AN/iAQCR4wEAy9EB","heartbeatms":null,"pt":1780839857370,"initialclk":null,"mc":[{"rc":[{"tv":null,"batb":null,"spb":null,"bdatl":null,"trd":null,"spf":null,"ltp":null,"atb":null,"spl":null,"spn":null,"atl":[[1.1399999999999999,21616.389999999999]],"batl":null,"id":19924823,"hc":null,"bdatb":null}],"img":null,"tv":null,"con":null,"marketdefinition":null,"id":"1.258926623"}],"conflatems":null,"op":"mcm","id":3}
{"ct":null,"SegmentType":null,"clk":"AOTiAQCd4wEAz9EB","heartbeatms":null,"pt":1780839857469,"initialclk":null,"mc":[{"rc":[{"tv":null,"batb":null,"spb":null,"bdatl":null,"trd":null,"spf":null,"ltp":null,"atb":[[8,369.17000000000002]],"spl":null,"spn":null,"atl":null,"batl":null,"id":16570658,"hc":null,"bdatb":null},{"tv":null,"batb":null,"spb":null,"bdatl":null,"trd":null,"spf":null,"ltp":null,"atb":[[1.1299999999999999,774.80999999999995]],"spl":null,"spn":null,"atl":null,"batl":null,"id":19924823,"hc":null,"bdatb":null}],"img":null,"tv":null,"con":null,"marketdefinition":null,"id":"1.258926623"}],"conflatems":null,"op":"mcm","id":3}
{"ct":null,"SegmentType":null,"clk":"APviAQC44wEA7tEB","heartbeatms":null,"pt":1780839857780,"initialclk":null,"mc":[{"rc":[{"tv":null,"batb":null,"spb":null,"bdatl":null,"trd":null,"spf":null,"ltp":null,"atb":[[1.1299999999999999,839.45000000000005]],"spl":null,"spn":null,"atl":null,"batl":null,"id":19924823,"hc":null,"bdatb":null}],"img":null,"tv":null,"con":null,"marketdefinition":null,"id":"1.258926623"}],"conflatems":null,"op":"mcm","id":3}
{"ct":null,"SegmentType":null,"clk":"AP7iAQDC4wEA\u002B9EB","heartbeatms":null,"pt":1780839857886,"initialclk":null,"mc":[{"rc":[{"tv":247020.62,"batb":null,"spb":null,"bdatl":null,"trd":[[8.4000000000000004,2014.26]],"spf":null,"ltp":8.4000000000000004,"atb":[[8.4000000000000004,182.91999999999999]],"spl":null,"spn":null,"atl":null,"batl":null,"id":16570658,"hc":null,"bdatb":null}],"img":null,"tv":2337866.9500000002,"con":null,"marketdefinition":null,"id":"1.258926623"}],"conflatems":null,"op":"mcm","id":3}
{"ct":null,"SegmentType":null,"clk":"AJLjAQDV4wEAldIB","heartbeatms":null,"pt":1780839858091,"initialclk":null,"mc":[{"rc":[{"tv":null,"batb":null,"spb":null,"bdatl":null,"trd":null,"spf":null,"ltp":null,"atb":null,"spl":null,"spn":null,"atl":[[13,0]],"batl":null,"id":16570658,"hc":null,"bdatb":null},{"tv":null,"batb":null,"spb":null,"bdatl":null,"trd":null,"spf":null,"ltp":null,"atb":null,"spl":null,"spn":null,"atl":[[1.1399999999999999,21417.689999999999]],"batl":null,"id":19924823,"hc":null,"bdatb":null}],"img":null,"tv":null,"con":null,"marketdefinition":null,"id":"1.258926623"}],"conflatems":null,"op":"mcm","id":3}
{"ct":null,"SegmentType":null,"clk":"ALDjAQD44wEAs9IB","heartbeatms":null,"pt":1780839858404,"initialclk":null,"mc":[{"rc":[{"tv":null,"batb":null,"spb":null,"bdatl":null,"trd":null,"spf":null,"ltp":null,"atb":[[8.4000000000000004,324.68000000000001]],"spl":null,"spn":null,"atl":null,"batl":null,"id":16570658,"hc":null,"bdatb":null}],"img":null,"tv":null,"con":null,"marketdefinition":null,"id":"1.258926623"}],"conflatems":null,"op":"mcm","id":3}
{"ct":null,"SegmentType":null,"clk":"AMPjAQCR5AEAwdIB","heartbeatms":null,"pt":1780839858609,"initialclk":null,"mc":[{"rc":[{"tv":null,"batb":null,"spb":null,"bdatl":null,"trd":null,"spf":null,"ltp":null,"atb":null,"spl":null,"spn":null,"atl":[[1.1399999999999999,21430.91]],"batl":null,"id":19924823,"hc":null,"bdatb":null}],"img":null,"tv":null,"con":null,"marketdefinition":null,"id":"1.258926623"}],"conflatems":null,"op":"mcm","id":3}
{"ct":null,"SegmentType":null,"clk":"ANfjAQCj5AEA3dIB","heartbeatms":null,"pt":1780839858808,"initialclk":null,"mc":[{"rc":[{"tv":null,"batb":null,"spb":null,"bdatl":null,"trd":null,"spf":null,"ltp":null,"atb":[[8.1999999999999993,140.65000000000001],[6.4000000000000004,26.780000000000001]],"spl":null,"spn":null,"atl":null,"batl":null,"id":16570658,"hc":null,"bdatb":null}],"img":null,"tv":null,"con":null,"marketdefinition":null,"id":"1.258926623"}],"conflatems":null,"op":"mcm","id":3}
{"ct":null,"SegmentType":null,"clk":"AJbkAQDW5AEAidMB","heartbeatms":null,"pt":1780839859279,"initialclk":null,"mc":[{"rc":[{"tv":null,"batb":null,"spb":null,"bdatl":null,"trd":null,"spf":null,"ltp":null,"atb":[[1.1100000000000001,62863.129999999997]],"spl":null,"spn":null,"atl":null,"batl":null,"id":19924823,"hc":null,"bdatb":null}],"img":null,"tv":null,"con":null,"marketdefinition":null,"id":"1.258926623"}],"conflatems":null,"op":"mcm","id":3}
{"ct":null,"SegmentType":null,"clk":"ALHkAQDx5AEAqdMB","heartbeatms":null,"pt":1780839859589,"initialclk":null,"mc":[{"rc":[{"tv":2090951.71,"batb":null,"spb":null,"bdatl":null,"trd":[[1.1399999999999999,170573.34]],"spf":null,"ltp":1.1399999999999999,"atb":null,"spl":null,"spn":null,"atl":[[1.1399999999999999,21378.220000000001]],"batl":null,"id":19924823,"hc":null,"bdatb":null}],"img":null,"tv":2337972.3300000001,"con":null,"marketdefinition":null,"id":"1.258926623"}],"conflatems":null,"op":"mcm","id":3}
{"ct":null,"SegmentType":null,"clk":"ANLkAQCX5QEAwNMB","heartbeatms":null,"pt":1780839859907,"initialclk":null,"mc":[{"rc":[{"tv":null,"batb":null,"spb":null,"bdatl":null,"trd":null,"spf":null,"ltp":null,"atb":null,"spl":null,"spn":null,"atl":[[8.5999999999999996,13.84]],"batl":null,"id":16570658,"hc":null,"bdatb":null}],"img":null,"tv":null,"con":null,"marketdefinition":null,"id":"1.258926623"}],"conflatems":null,"op":"mcm","id":3}
{"ct":null,"SegmentType":null,"clk":"ANnkAQCb5QEAxdMB","heartbeatms":null,"pt":1780839860008,"initialclk":null,"mc":[{"rc":[{"tv":null,"batb":null,"spb":null,"bdatl":null,"trd":null,"spf":null,"ltp":null,"atb":[[1.1299999999999999,939.45000000000005]],"spl":null,"spn":null,"atl":null,"batl":null,"id":19924823,"hc":null,"bdatb":null}],"img":null,"tv":null,"con":null,"marketdefinition":null,"id":"1.258926623"}],"conflatems":null,"op":"mcm","id":3}
{"ct":null,"SegmentType":null,"clk":"APfkAQC55QEA3tMB","heartbeatms":null,"pt":1780839860263,"initialclk":null,"mc":[{"rc":[{"tv":null,"batb":null,"spb":null,"bdatl":null,"trd":null,"spf":null,"ltp":null,"atb":null,"spl":null,"spn":null,"atl":[[100,4.5300000000000002]],"batl":null,"id":16570658,"hc":null,"bdatb":null}],"img":null,"tv":null,"con":null,"marketdefinition":null,"id":"1.258926623"}],"conflatems":null,"op":"mcm","id":3}
{"ct":null,"SegmentType":null,"clk":"ALTlAQD05QEAitQB","heartbeatms":null,"pt":1780839860881,"initialclk":null,"mc":[{"rc":[{"tv":null,"batb":null,"spb":null,"bdatl":null,"trd":null,"spf":null,"ltp":null,"atb":[[8,122.37000000000001]],"spl":null,"spn":null,"atl":null,"batl":null,"id":16570658,"hc":null,"bdatb":null}],"img":null,"tv":null,"con":null,"marketdefinition":null,"id":"1.258926623"}],"conflatems":null,"op":"mcm","id":3}
{"ct":null,"SegmentType":null,"clk":"AOPlAQCY5gEArdQB","heartbeatms":null,"pt":1780839861194,"initialclk":null,"mc":[{"rc":[{"tv":2090957.5500000001,"batb":null,"spb":null,"bdatl":null,"trd":[[1.1399999999999999,170579.17999999999]],"spf":null,"ltp":null,"atb":null,"spl":null,"spn":null,"atl":[[1.1399999999999999,21375.299999999999]],"batl":null,"id":19924823,"hc":null,"bdatb":null}],"img":null,"tv":2337978.1699999999,"con":null,"marketdefinition":null,"id":"1.258926623"}],"conflatems":null,"op":"mcm","id":3}
{"ct":null,"SegmentType":null,"clk":"AO7lAQCi5gEAtNQB","heartbeatms":null,"pt":1780839861298,"initialclk":null,"mc":[{"rc":[{"tv":null,"batb":null,"spb":null,"bdatl":null,"trd":null,"spf":null,"ltp":null,"atb":null,"spl":null,"spn":null,"atl":[[1.1499999999999999,30853.959999999999]],"batl":null,"id":19924823,"hc":null,"bdatb":null}],"img":null,"tv":null,"con":null,"marketdefinition":null,"id":"1.258926623"}],"conflatems":null,"op":"mcm","id":3}
{"ct":null,"SegmentType":null,"clk":"ANHmAQD05gEA8tQB","heartbeatms":null,"pt":1780839862168,"initialclk":null,"mc":[{"rc":[{"tv":null,"batb":null,"spb":null,"bdatl":null,"trd":null,"spf":null,"ltp":null,"atb":[[1.1299999999999999,948.23000000000002]],"spl":null,"spn":null,"atl":null,"batl":null,"id":19924823,"hc":null,"bdatb":null}],"img":null,"tv":null,"con":null,"marketdefinition":null,"id":"1.258926623"}],"conflatems":null,"op":"mcm","id":3}
{"ct":null,"SegmentType":null,"clk":"AOPmAQCJ5wEAhdUB","heartbeatms":null,"pt":1780839862389,"initialclk":null,"mc":[{"rc":[{"tv":null,"batb":null,"spb":null,"bdatl":null,"trd":null,"spf":null,"ltp":null,"atb":[[7.4000000000000004,505.72000000000003]],"spl":null,"spn":null,"atl":null,"batl":null,"id":16570658,"hc":null,"bdatb":null},{"tv":null,"batb":null,"spb":null,"bdatl":null,"trd":null,"spf":null,"ltp":null,"atb":[[1.1200000000000001,46514.93]],"spl":null,"spn":null,"atl":[[1.1599999999999999,11983.9]],"batl":null,"id":19924823,"hc":null,"bdatb":null}],"img":null,"tv":null,"con":null,"marketdefinition":null,"id":"1.258926623"}],"conflatems":null,"op":"mcm","id":3}
{"ct":null,"SegmentType":null,"clk":"AJjnAQC95wEAt9UB","heartbeatms":null,"pt":1780839862999,"initialclk":null,"mc":[{"rc":[{"tv":null,"batb":null,"spb":null,"bdatl":null,"trd":null,"spf":null,"ltp":null,"atb":null,"spl":null,"spn":null,"atl":[[1.1399999999999999,21346.419999999998]],"batl":null,"id":19924823,"hc":null,"bdatb":null}],"img":null,"tv":null,"con":null,"marketdefinition":null,"id":"1.258926623"}],"conflatems":null,"op":"mcm","id":3}
{"ct":null,"SegmentType":null,"clk":"ALTnAQDf5wEA2NUB","heartbeatms":null,"pt":1780839863098,"initialclk":null,"mc":[{"rc":[{"tv":null,"batb":null,"spb":null,"bdatl":null,"trd":null,"spf":null,"ltp":null,"atb":null,"spl":null,"spn":null,"atl":[[1.1399999999999999,21349.66]],"batl":null,"id":19924823,"hc":null,"bdatb":null}],"img":null,"tv":null,"con":null,"marketdefinition":null,"id":"1.258926623"}],"conflatems":null,"op":"mcm","id":3}
{"ct":null,"SegmentType":null,"clk":"AO3nAQCH6AEA/NUB","heartbeatms":null,"pt":1780839863563,"initialclk":null,"mc":[{"rc":[{"tv":null,"batb":null,"spb":null,"bdatl":null,"trd":null,"spf":null,"ltp":null,"atb":null,"spl":null,"spn":null,"atl":[[9.8000000000000007,173.91999999999999]],"batl":null,"id":16570658,"hc":null,"bdatb":null}],"img":null,"tv":null,"con":null,"marketdefinition":null,"id":"1.258926623"}],"conflatems":null,"op":"mcm","id":3}
{"ct":null,"SegmentType":null,"clk":"ALLoAQCy6AEAo9YB","heartbeatms":null,"pt":1780839864092,"initialclk":null,"mc":[{"rc":[{"tv":null,"batb":null,"spb":null,"bdatl":null,"trd":null,"spf":null,"ltp":null,"atb":[[8.4000000000000004,222.13]],"spl":null,"spn":null,"atl":null,"batl":null,"id":16570658,"hc":null,"bdatb":null}],"img":null,"tv":null,"con":null,"marketdefinition":null,"id":"1.258926623"}],"conflatems":null,"op":"mcm","id":3}
{"ct":null,"SegmentType":null,"clk":"ALzoAQC/6AEAp9YB","heartbeatms":null,"pt":1780839864194,"initialclk":null,"mc":[{"rc":[{"tv":null,"batb":null,"spb":null,"bdatl":null,"trd":null,"spf":null,"ltp":null,"atb":null,"spl":null,"spn":null,"atl":[[8.5999999999999996,158.36000000000001]],"batl":null,"id":16570658,"hc":null,"bdatb":null}],"img":null,"tv":null,"con":null,"marketdefinition":null,"id":"1.258926623"}],"conflatems":null,"op":"mcm","id":3}
{"ct":null,"SegmentType":null,"clk":"AN3oAQDc6AEAvNYB","heartbeatms":null,"pt":1780839864497,"initialclk":null,"mc":[{"rc":[{"tv":2091157.5500000001,"batb":null,"spb":null,"bdatl":null,"trd":[[1.1299999999999999,239034.89999999999]],"spf":null,"ltp":1.1299999999999999,"atb":[[1.1299999999999999,848.23000000000002]],"spl":null,"spn":null,"atl":null,"batl":null,"id":19924823,"hc":null,"bdatb":null}],"img":null,"tv":2338178.1699999999,"con":null,"marketdefinition":null,"id":"1.258926623"}],"conflatems":null,"op":"mcm","id":3}
{"ct":null,"SegmentType":null,"clk":"AJXpAQCS6QEA\u002BNYB","heartbeatms":null,"pt":1780839865069,"initialclk":null,"mc":[{"rc":[{"tv":null,"batb":null,"spb":null,"bdatl":null,"trd":null,"spf":null,"ltp":null,"atb":null,"spl":null,"spn":null,"atl":[[9.1999999999999993,182.41]],"batl":null,"id":16570658,"hc":null,"bdatb":null}],"img":null,"tv":null,"con":null,"marketdefinition":null,"id":"1.258926623"}],"conflatems":null,"op":"mcm","id":3}
{"ct":null,"SegmentType":null,"clk":"AKXpAQCl6QEAiNcB","heartbeatms":null,"pt":1780839865274,"initialclk":null,"mc":[{"rc":[{"tv":null,"batb":null,"spb":null,"bdatl":null,"trd":null,"spf":null,"ltp":null,"atb":[[1.1299999999999999,922.57000000000005]],"spl":null,"spn":null,"atl":null,"batl":null,"id":19924823,"hc":null,"bdatb":null}],"img":null,"tv":null,"con":null,"marketdefinition":null,"id":"1.258926623"}],"conflatems":null,"op":"mcm","id":3}
{"ct":null,"SegmentType":null,"clk":"ALzpAQCx6QEAkdcB","heartbeatms":null,"pt":1780839865479,"initialclk":null,"mc":[{"rc":[{"tv":null,"batb":null,"spb":null,"bdatl":null,"trd":null,"spf":null,"ltp":null,"atb":null,"spl":null,"spn":null,"atl":[[9.8000000000000007,20.859999999999999]],"batl":null,"id":16570658,"hc":null,"bdatb":null},{"tv":null,"batb":null,"spb":null,"bdatl":null,"trd":null,"spf":null,"ltp":null,"atb":null,"spl":null,"spn":null,"atl":[[1000,1.1499999999999999]],"batl":null,"id":19924823,"hc":null,"bdatb":null}],"img":null,"tv":null,"con":null,"marketdefinition":null,"id":"1.258926623"}],"conflatems":null,"op":"mcm","id":3}
{"ct":null,"SegmentType":null,"clk":"AMXpAQC76QEAl9cB","heartbeatms":null,"pt":1780839865583,"initialclk":null,"mc":[{"rc":[{"tv":null,"batb":null,"spb":null,"bdatl":null,"trd":null,"spf":null,"ltp":null,"atb":null,"spl":null,"spn":null,"atl":[[1.1399999999999999,19622.099999999999]],"batl":null,"id":19924823,"hc":null,"bdatb":null}],"img":null,"tv":null,"con":null,"marketdefinition":null,"id":"1.258926623"}],"conflatems":null,"op":"mcm","id":3}
{"ct":null,"SegmentType":null,"clk":"AODpAQDY6QEAstcB","heartbeatms":null,"pt":1780839865889,"initialclk":null,"mc":[{"rc":[{"tv":null,"batb":null,"spb":null,"bdatl":null,"trd":null,"spf":null,"ltp":null,"atb":null,"spl":null,"spn":null,"atl":[[1000,0.88]],"batl":null,"id":19924823,"hc":null,"bdatb":null}],"img":null,"tv":null,"con":null,"marketdefinition":null,"id":"1.258926623"}],"conflatems":null,"op":"mcm","id":3}
{"ct":null,"SegmentType":null,"clk":"APzpAQD76QEAxtcB","heartbeatms":null,"pt":1780839866196,"initialclk":null,"mc":[{"rc":[{"tv":2091162.73,"batb":null,"spb":null,"bdatl":null,"trd":[[1.1299999999999999,239040.07999999999]],"spf":null,"ltp":null,"atb":[[1.1299999999999999,919.98000000000002]],"spl":null,"spn":null,"atl":null,"batl":null,"id":19924823,"hc":null,"bdatb":null}],"img":null,"tv":2338183.3500000001,"con":null,"marketdefinition":null,"id":"1.258926623"}],"conflatems":null,"op":"mcm","id":3}
{"ct":null,"SegmentType":null,"clk":"AJPqAQCR6gEA1dcB","heartbeatms":null,"pt":1780839866406,"initialclk":null,"mc":[{"rc":[{"tv":247178.98000000001,"batb":null,"spb":null,"bdatl":null,"trd":[[8.5999999999999996,2667.04]],"spf":null,"ltp":8.5999999999999996,"atb":[[8.5999999999999996,14.74]],"spl":null,"spn":null,"atl":[[8.5999999999999996,0]],"batl":null,"id":16570658,"hc":null,"bdatb":null},{"tv":2100105.2400000002,"batb":null,"spb":null,"bdatl":null,"trd":[[1.1299999999999999,242085.25],[1.1200000000000001,62474.169999999998]],"spf":null,"ltp":1.1200000000000001,"atb":[[1.1299999999999999,0],[1.1200000000000001,43566.260000000002]],"spl":null,"spn":null,"atl":[[1.1299999999999999,5.9000000000000004]],"batl":null,"id":19924823,"hc":null,"bdatb":null}],"img":null,"tv":2347284.2200000002,"con":null,"marketdefinition":null,"id":"1.258926623"}],"conflatems":null,"op":"mcm","id":3}
{"ct":null,"SegmentType":null,"clk":"AJvqAQCc6gEA2NcB","heartbeatms":null,"pt":1780839866499,"initialclk":null,"mc":[{"rc":[{"tv":null,"batb":null,"spb":null,"bdatl":null,"trd":null,"spf":null,"ltp":null,"atb":null,"spl":null,"spn":null,"atl":[[100,3]],"batl":null,"id":19924823,"hc":null,"bdatb":null}],"img":null,"tv":null,"con":null,"marketdefinition":null,"id":"1.258926623"}],"conflatems":null,"op":"mcm","id":3}
{"ct":null,"SegmentType":null,"clk":"AKbqAQCr6gEA4NcB","heartbeatms":null,"pt":1780839866608,"initialclk":null,"mc":[{"rc":[{"tv":null,"batb":null,"spb":null,"bdatl":null,"trd":null,"spf":null,"ltp":null,"atb":null,"spl":null,"spn":null,"atl":[[1.1399999999999999,19191.849999999999]],"batl":null,"id":19924823,"hc":null,"bdatb":null}],"img":null,"tv":null,"con":null,"marketdefinition":null,"id":"1.258926623"}],"conflatems":null,"op":"mcm","id":3}
{"ct":null,"SegmentType":null,"clk":"AMLqAQDL6gEA9tcB","heartbeatms":null,"pt":1780839866865,"initialclk":null,"mc":[{"rc":[{"tv":null,"batb":null,"spb":null,"bdatl":null,"trd":null,"spf":null,"ltp":null,"atb":null,"spl":null,"spn":null,"atl":[[1.1399999999999999,18391.849999999999]],"batl":null,"id":19924823,"hc":null,"bdatb":null}],"img":null,"tv":null,"con":null,"marketdefinition":null,"id":"1.258926623"}],"conflatems":null,"op":"mcm","id":3}
{"ct":null,"SegmentType":null,"clk":"AOPqAQDp6gEAidgB","heartbeatms":null,"pt":1780839867177,"initialclk":null,"mc":[{"rc":[{"tv":null,"batb":null,"spb":null,"bdatl":null,"trd":null,"spf":null,"ltp":null,"atb":[[6.4000000000000004,0.85999999999999999]],"spl":null,"spn":null,"atl":null,"batl":null,"id":16570658,"hc":null,"bdatb":null}],"img":null,"tv":null,"con":null,"marketdefinition":null,"id":"1.258926623"}],"conflatems":null,"op":"mcm","id":3}
{"ct":null,"SegmentType":null,"clk":"AILrAQCE6wEAntgB","heartbeatms":null,"pt":1780839867482,"initialclk":null,"mc":[{"rc":[{"tv":null,"batb":null,"spb":null,"bdatl":null,"trd":null,"spf":null,"ltp":null,"atb":[[1.0900000000000001,40176.459999999999]],"spl":null,"spn":null,"atl":null,"batl":null,"id":19924823,"hc":null,"bdatb":null}],"img":null,"tv":null,"con":null,"marketdefinition":null,"id":"1.258926623"}],"conflatems":null,"op":"mcm","id":3}
{"ct":null,"SegmentType":null,"clk":"AKjrAQCY6wEAttgB","heartbeatms":null,"pt":1780839867795,"initialclk":null,"mc":[{"rc":[{"tv":null,"batb":null,"spb":null,"bdatl":null,"trd":null,"spf":null,"ltp":null,"atb":[[1.1200000000000001,43832.629999999997]],"spl":null,"spn":null,"atl":[[1.1399999999999999,19039.619999999999]],"batl":null,"id":19924823,"hc":null,"bdatb":null}],"img":null,"tv":null,"con":null,"marketdefinition":null,"id":"1.258926623"}],"conflatems":null,"op":"mcm","id":3}
{"ct":null,"SegmentType":null,"clk":"ALTrAQCg6wEAwtgB","heartbeatms":null,"pt":1780839867901,"initialclk":null,"mc":[{"rc":[{"tv":null,"batb":null,"spb":null,"bdatl":null,"trd":null,"spf":null,"ltp":null,"atb":[[7,760.55999999999995],[7.4000000000000004,312.75],[7.2000000000000002,67.340000000000003]],"spl":null,"spn":null,"atl":[[9.4000000000000004,12],[11,103.94],[9.1999999999999993,10]],"batl":null,"id":16570658,"hc":null,"bdatb":null},{"tv":null,"batb":null,"spb":null,"bdatl":null,"trd":null,"spf":null,"ltp":null,"atb":[[1.1000000000000001,70778.229999999996],[1.1100000000000001,62857.910000000003],[1.1200000000000001,42487.739999999998]],"spl":null,"spn":null,"atl":[[1.1699999999999999,8883.6900000000005],[1.1399999999999999,18441.950000000001],[1.1599999999999999,10382.76],[1.1499999999999999,30537.41]],"batl":null,"id":19924823,"hc":null,"bdatb":null}],"img":null,"tv":null,"con":null,"marketdefinition":null,"id":"1.258926623"}],"conflatems":null,"op":"mcm","id":3}
{"ct":null,"SegmentType":null,"clk":"ALvrAQCp6wEAyNgB","heartbeatms":null,"pt":1780839868003,"initialclk":null,"mc":[{"rc":[{"tv":null,"batb":null,"spb":null,"bdatl":null,"trd":null,"spf":null,"ltp":null,"atb":[[6.5999999999999996,155.61000000000001],[6.7999999999999998,325.13999999999999]],"spl":null,"spn":null,"atl":[[9.8000000000000007,87.689999999999998],[9.5999999999999996,248.68000000000001]],"batl":null,"id":16570658,"hc":null,"bdatb":null}],"img":null,"tv":null,"con":null,"marketdefinition":null,"id":"1.258926623"}],"conflatems":null,"op":"mcm","id":3}
{"ct":null,"SegmentType":null,"clk":"ANLrAQDE6wEA1tgB","heartbeatms":null,"pt":1780839868108,"initialclk":null,"mc":[{"rc":[{"tv":null,"batb":null,"spb":null,"bdatl":null,"trd":null,"spf":null,"ltp":null,"atb":[[8.4000000000000004,80.370000000000005],[8.1999999999999993,19.440000000000001],[8,40.369999999999997]],"spl":null,"spn":null,"atl":[[8.8000000000000007,242.06999999999999],[10.5,3.25]],"batl":null,"id":16570658,"hc":null,"bdatb":null},{"tv":null,"batb":null,"spb":null,"bdatl":null,"trd":null,"spf":null,"ltp":null,"atb":[[1.1000000000000001,69103.229999999996],[1.1200000000000001,40630.949999999997]],"spl":null,"spn":null,"atl":[[1.1299999999999999,21.66],[1.1399999999999999,17379.790000000001],[1.1499999999999999,29076.41]],"batl":null,"id":19924823,"hc":null,"bdatb":null}],"img":null,"tv":null,"con":null,"marketdefinition":null,"id":"1.258926623"}],"conflatems":null,"op":"mcm","id":3}
{"ct":null,"SegmentType":null,"clk":"AObrAQDU6wEA5NgB","heartbeatms":null,"pt":1780839868214,"initialclk":null,"mc":[{"rc":[{"tv":null,"batb":null,"spb":null,"bdatl":null,"trd":null,"spf":null,"ltp":null,"atb":[[7.7999999999999998,0],[7.4000000000000004,109.33]],"spl":null,"spn":null,"atl":null,"batl":null,"id":16570658,"hc":null,"bdatb":null}],"img":null,"tv":null,"con":null,"marketdefinition":null,"id":"1.258926623"}],"conflatems":null,"op":"mcm","id":3}
{"ct":null,"SegmentType":null,"clk":"AOnrAQDX6wEA6tgB","heartbeatms":null,"pt":1780839868312,"initialclk":null,"mc":[{"rc":[{"tv":null,"batb":null,"spb":null,"bdatl":null,"trd":null,"spf":null,"ltp":null,"atb":[[7.2000000000000002,803.79999999999995]],"spl":null,"spn":null,"atl":null,"batl":null,"id":16570658,"hc":null,"bdatb":null},{"tv":null,"batb":null,"spb":null,"bdatl":null,"trd":null,"spf":null,"ltp":null,"atb":[[1.1100000000000001,75635.830000000002]],"spl":null,"spn":null,"atl":null,"batl":null,"id":19924823,"hc":null,"bdatb":null}],"img":null,"tv":null,"con":null,"marketdefinition":null,"id":"1.258926623"}],"conflatems":null,"op":"mcm","id":3}
{"ct":null,"SegmentType":null,"clk":"APTrAQDc6wEA\u002BNgB","heartbeatms":null,"pt":1780839868409,"initialclk":null,"mc":[{"rc":[{"tv":null,"batb":null,"spb":null,"bdatl":null,"trd":null,"spf":null,"ltp":null,"atb":[[7,0],[7.5999999999999996,12.94],[7.4000000000000004,8.3599999999999994]],"spl":null,"spn":null,"atl":[[8.8000000000000007,20],[9,10]],"batl":null,"id":16570658,"hc":null,"bdatb":null},{"tv":null,"batb":null,"spb":null,"bdatl":null,"trd":null,"spf":null,"ltp":null,"atb":[[1.1000000000000001,66571.919999999998],[1.1100000000000001,73340.130000000005],[1.1200000000000001,28037.189999999999]],"spl":null,"spn":null,"atl":[[1.1399999999999999,5553.8000000000002]],"batl":null,"id":19924823,"hc":null,"bdatb":null}],"img":null,"tv":null,"con":null,"marketdefinition":null,"id":"1.258926623"}],"conflatems":null,"op":"mcm","id":3}
{"ct":null,"SegmentType":null,"clk":"ALbsAQCT7AEAs9kB","heartbeatms":null,"pt":1780839868984,"initialclk":null,"mc":[{"rc":[{"tv":null,"batb":null,"spb":null,"bdatl":null,"trd":null,"spf":null,"ltp":null,"atb":null,"spl":null,"spn":null,"atl":[[1.1299999999999999,21.93]],"batl":null,"id":19924823,"hc":null,"bdatb":null}],"img":null,"tv":null,"con":null,"marketdefinition":null,"id":"1.258926623"}],"conflatems":null,"op":"mcm","id":3}
{"ct":null,"SegmentType":null,"clk":"AOrsAQC57AEA39kB","heartbeatms":null,"pt":1780839869507,"initialclk":null,"mc":[{"rc":[{"tv":247208,"batb":null,"spb":null,"bdatl":null,"trd":[[8.5999999999999996,2696.0599999999999]],"spf":null,"ltp":null,"atb":[[8.5999999999999996,0.23000000000000001]],"spl":null,"spn":null,"atl":null,"batl":null,"id":16570658,"hc":null,"bdatb":null}],"img":null,"tv":2347313.2400000002,"con":null,"marketdefinition":null,"id":"1.258926623"}],"conflatems":null,"op":"mcm","id":3}
{"ct":null,"SegmentType":null,"clk":"AITtAQDN7AEA9NkB","heartbeatms":null,"pt":1780839869716,"initialclk":null,"mc":[{"rc":[{"tv":null,"batb":null,"spb":null,"bdatl":null,"trd":null,"spf":null,"ltp":null,"atb":[[1.1200000000000001,27212.720000000001]],"spl":null,"spn":null,"atl":[[1.1399999999999999,4906.0299999999997],[1.1499999999999999,27424.060000000001]],"batl":null,"id":19924823,"hc":null,"bdatb":null}],"img":null,"tv":null,"con":null,"marketdefinition":null,"id":"1.258926623"}],"conflatems":null,"op":"mcm","id":3}
{"ct":null,"SegmentType":null,"clk":"AOXtAQCc7QEAwtoB","heartbeatms":null,"pt":1780839870590,"initialclk":null,"mc":[{"rc":[{"tv":2100119.73,"batb":null,"spb":null,"bdatl":null,"trd":[[1.1299999999999999,242099.73999999999]],"spf":null,"ltp":1.1299999999999999,"atb":null,"spl":null,"spn":null,"atl":[[1.1299999999999999,14.68]],"batl":null,"id":19924823,"hc":null,"bdatb":null}],"img":null,"tv":2347327.73,"con":null,"marketdefinition":null,"id":"1.258926623"}],"conflatems":null,"op":"mcm","id":3}
{"ct":null,"SegmentType":null,"clk":"APTtAQCw7QEA0doB","heartbeatms":null,"pt":1780839870795,"initialclk":null,"mc":[{"rc":[{"tv":2100149.0899999999,"batb":null,"spb":null,"bdatl":null,"trd":[[1.1299999999999999,242129.10000000001]],"spf":null,"ltp":null,"atb":[[1.1299999999999999,1128.8599999999999]],"spl":null,"spn":null,"atl":[[1.1299999999999999,0]],"batl":null,"id":19924823,"hc":null,"bdatb":null}],"img":null,"tv":2347357.0899999999,"con":null,"marketdefinition":null,"id":"1.258926623"}],"conflatems":null,"op":"mcm","id":3}
{"ct":null,"SegmentType":null,"clk":"AP3tAQC57QEA2toB","heartbeatms":null,"pt":1780839870901,"initialclk":null,"mc":[{"rc":[{"tv":2100181.4500000002,"batb":null,"spb":null,"bdatl":null,"trd":[[1.1399999999999999,170611.54000000001]],"spf":null,"ltp":1.1399999999999999,"atb":null,"spl":null,"spn":null,"atl":[[1.1399999999999999,4889.8500000000004]],"batl":null,"id":19924823,"hc":null,"bdatb":null}],"img":null,"tv":2347389.4500000002,"con":null,"marketdefinition":null,"id":"1.258926623"}],"conflatems":null,"op":"mcm","id":3}
{"ct":null,"SegmentType":null,"clk":"AILuAQDC7QEA49oB","heartbeatms":null,"pt":1780839870999,"initialclk":null,"mc":[{"rc":[{"tv":null,"batb":null,"spb":null,"bdatl":null,"trd":null,"spf":null,"ltp":null,"atb":[[1.1299999999999999,700]],"spl":null,"spn":null,"atl":null,"batl":null,"id":19924823,"hc":null,"bdatb":null}],"img":null,"tv":null,"con":null,"marketdefinition":null,"id":"1.258926623"}],"conflatems":null,"op":"mcm","id":3}
{"ct":null,"SegmentType":null,"clk":"AJ7uAQDg7QEA\u002B9oB","heartbeatms":null,"pt":1780839871307,"initialclk":null,"mc":[{"rc":[{"tv":2101183.4500000002,"batb":null,"spb":null,"bdatl":null,"trd":[[1.1399999999999999,171613.54000000001]],"spf":null,"ltp":null,"atb":null,"spl":null,"spn":null,"atl":[[1.1399999999999999,4388.8500000000004]],"batl":null,"id":19924823,"hc":null,"bdatb":null}],"img":null,"tv":2348391.4500000002,"con":null,"marketdefinition":null,"id":"1.258926623"}],"conflatems":null,"op":"mcm","id":3}
{"ct":null,"SegmentType":null,"clk":"AOfuAQCV7gEAyNsB","heartbeatms":null,"pt":1780839871983,"initialclk":null,"mc":[{"rc":[{"tv":null,"batb":null,"spb":null,"bdatl":null,"trd":null,"spf":null,"ltp":null,"atb":[[7.2000000000000002,802.94000000000005]],"spl":null,"spn":null,"atl":null,"batl":null,"id":16570658,"hc":null,"bdatb":null},{"tv":null,"batb":null,"spb":null,"bdatl":null,"trd":null,"spf":null,"ltp":null,"atb":null,"spl":null,"spn":null,"atl":[[1.1599999999999999,10377.68]],"batl":null,"id":19924823,"hc":null,"bdatb":null}],"img":null,"tv":null,"con":null,"marketdefinition":null,"id":"1.258926623"}],"conflatems":null,"op":"mcm","id":3}
{"ct":null,"SegmentType":null,"clk":"AL3vAQDX7gEAhtwB","heartbeatms":null,"pt":1780839872706,"initialclk":null,"mc":[{"rc":[{"tv":2101216.79,"batb":null,"spb":null,"bdatl":null,"trd":[[1.1399999999999999,171646.88000000001]],"spf":null,"ltp":null,"atb":null,"spl":null,"spn":null,"atl":[[1.1399999999999999,4372.1800000000003]],"batl":null,"id":19924823,"hc":null,"bdatb":null}],"img":null,"tv":2348424.79,"con":null,"marketdefinition":null,"id":"1.258926623"}],"conflatems":null,"op":"mcm","id":3}
{"ct":null,"SegmentType":null,"clk":"ALjwAQCz7wEA59wB","heartbeatms":null,"pt":1780839873800,"initialclk":null,"mc":[{"rc":[{"tv":247208.45999999999,"batb":null,"spb":null,"bdatl":null,"trd":[[8.5999999999999996,2696.52]],"spf":null,"ltp":null,"atb":[[8.5999999999999996,0]],"spl":null,"spn":null,"atl":[[8.5999999999999996,10.84]],"batl":null,"id":16570658,"hc":null,"bdatb":null},{"tv":null,"batb":null,"spb":null,"bdatl":null,"trd":null,"spf":null,"ltp":null,"atb":[[1.1100000000000001,74701.059999999998]],"spl":null,"spn":null,"atl":[[1.1699999999999999,10119.280000000001],[1.1599999999999999,11758.370000000001]],"batl":null,"id":19924823,"hc":null,"bdatb":null}],"img":null,"tv":2348425.25,"con":null,"marketdefinition":null,"id":"1.258926623"}],"conflatems":null,"op":"mcm","id":3}
{"ct":null,"SegmentType":null,"clk":"APDwAQDp7wEAkN0B","heartbeatms":null,"pt":1780839874279,"initialclk":null,"mc":[{"rc":[{"tv":2101232.79,"batb":null,"spb":null,"bdatl":null,"trd":[[1.1399999999999999,171662.88000000001]],"spf":null,"ltp":null,"atb":null,"spl":null,"spn":null,"atl":[[1.1399999999999999,4364.1800000000003]],"batl":null,"id":19924823,"hc":null,"bdatb":null}],"img":null,"tv":2348441.25,"con":null,"marketdefinition":null,"id":"1.258926623"}],"conflatems":null,"op":"mcm","id":3}
{"ct":null,"SegmentType":null,"clk":"AI/xAQCE8AEArt0B","heartbeatms":null,"pt":1780839874582,"initialclk":null,"mc":[{"rc":[{"tv":247228.45000000001,"batb":null,"spb":null,"bdatl":null,"trd":[[8.4000000000000004,2034.25]],"spf":null,"ltp":8.4000000000000004,"atb":[[8.4000000000000004,70.370000000000005]],"spl":null,"spn":null,"atl":null,"batl":null,"id":16570658,"hc":null,"bdatb":null}],"img":null,"tv":2348461.2400000002,"con":null,"marketdefinition":null,"id":"1.258926623"}],"conflatems":null,"op":"mcm","id":3}
{"ct":null,"SegmentType":null,"clk":"AJ3xAQCM8AEAuN0B","heartbeatms":null,"pt":1780839874690,"initialclk":null,"mc":[{"rc":[{"tv":2101239.5699999998,"batb":null,"spb":null,"bdatl":null,"trd":[[1.1399999999999999,171669.66]],"spf":null,"ltp":null,"atb":[[1.1200000000000001,27215.310000000001]],"spl":null,"spn":null,"atl":[[1.1399999999999999,4360.79]],"batl":null,"id":19924823,"hc":null,"bdatb":null}],"img":null,"tv":2348468.02,"con":null,"marketdefinition":null,"id":"1.258926623"}],"conflatems":null,"op":"mcm","id":3}
{"ct":null,"SegmentType":null,"clk":"AMjxAQCq8AEA3N0B","heartbeatms":null,"pt":1780839875096,"initialclk":null,"mc":[{"rc":[{"tv":null,"batb":null,"spb":null,"bdatl":null,"trd":null,"spf":null,"ltp":null,"atb":[[1.03,88975.339999999997]],"spl":null,"spn":null,"atl":null,"batl":null,"id":19924823,"hc":null,"bdatb":null}],"img":null,"tv":null,"con":null,"marketdefinition":null,"id":"1.258926623"}],"conflatems":null,"op":"mcm","id":3}
{"ct":null,"SegmentType":null,"clk":"APnxAQDM8AEAgN4B","heartbeatms":null,"pt":1780839875508,"initialclk":null,"mc":[{"rc":[{"tv":null,"batb":null,"spb":null,"bdatl":null,"trd":null,"spf":null,"ltp":null,"atb":null,"spl":null,"spn":null,"atl":[[9.8000000000000007,67.689999999999998]],"batl":null,"id":16570658,"hc":null,"bdatb":null}],"img":null,"tv":null,"con":null,"marketdefinition":null,"id":"1.258926623"}],"conflatems":null,"op":"mcm","id":3}
{"ct":null,"SegmentType":null,"clk":"AILyAQDU8AEAh94B","heartbeatms":null,"pt":1780839875611,"initialclk":null,"mc":[{"rc":[{"tv":null,"batb":null,"spb":null,"bdatl":null,"trd":null,"spf":null,"ltp":null,"atb":null,"spl":null,"spn":null,"atl":[[9.5999999999999996,268.68000000000001]],"batl":null,"id":16570658,"hc":null,"bdatb":null}],"img":null,"tv":null,"con":null,"marketdefinition":null,"id":"1.258926623"}],"conflatems":null,"op":"mcm","id":3}
{"ct":null,"SegmentType":null,"clk":"AJXyAQDf8AEAj94B","heartbeatms":null,"pt":1780839875679,"initialclk":null,"mc":[{"rc":[{"tv":null,"batb":null,"spb":null,"bdatl":null,"trd":null,"spf":null,"ltp":null,"atb":[[1.55,3.1600000000000001]],"spl":null,"spn":null,"atl":null,"batl":null,"id":16570658,"hc":null,"bdatb":null}],"img":null,"tv":null,"con":null,"marketdefinition":null,"id":"1.258926623"}],"conflatems":null,"op":"mcm","id":3}
{"ct":null,"SegmentType":null,"clk":"ALPyAQD68AEArN4B","heartbeatms":null,"pt":1780839875983,"initialclk":null,"mc":[{"rc":[{"tv":2101639.5699999998,"batb":null,"spb":null,"bdatl":null,"trd":[[1.1299999999999999,242529.10000000001]],"spf":null,"ltp":1.1299999999999999,"atb":[[1.1299999999999999,500]],"spl":null,"spn":null,"atl":null,"batl":null,"id":19924823,"hc":null,"bdatb":null}],"img":null,"tv":2348868.02,"con":null,"marketdefinition":null,"id":"1.258926623"}],"conflatems":null,"op":"mcm","id":3}
{"ct":null,"SegmentType":null,"clk":"AM3yAQCQ8QEAvd4B","heartbeatms":null,"pt":1780839876191,"initialclk":null,"mc":[{"rc":[{"tv":null,"batb":null,"spb":null,"bdatl":null,"trd":null,"spf":null,"ltp":null,"atb":[[8.4000000000000004,219.18000000000001],[8.1999999999999993,421.86000000000001],[8,126.17]],"spl":null,"spn":null,"atl":null,"batl":null,"id":16570658,"hc":null,"bdatb":null},{"tv":null,"batb":null,"spb":null,"bdatl":null,"trd":null,"spf":null,"ltp":null,"atb":null,"spl":null,"spn":null,"atl":[[1.1399999999999999,26860.790000000001]],"batl":null,"id":19924823,"hc":null,"bdatb":null}],"img":null,"tv":null,"con":null,"marketdefinition":null,"id":"1.258926623"}],"conflatems":null,"op":"mcm","id":3}
{"ct":null,"SegmentType":null,"clk":"ANbyAQCY8QEAyd4B","heartbeatms":null,"pt":1780839876298,"initialclk":null,"mc":[{"rc":[{"tv":null,"batb":null,"spb":null,"bdatl":null,"trd":null,"spf":null,"ltp":null,"atb":[[1.1000000000000001,66573.919999999998]],"spl":null,"spn":null,"atl":[[1.1399999999999999,44578.68]],"batl":null,"id":19924823,"hc":null,"bdatb":null}],"img":null,"tv":null,"con":null,"marketdefinition":null,"id":"1.258926623"}],"conflatems":null,"op":"mcm","id":3}
{"ct":null,"SegmentType":null,"clk":"AN/yAQCi8QEAzd4B","heartbeatms":null,"pt":1780839876406,"initialclk":null,"mc":[{"rc":[{"tv":null,"batb":null,"spb":null,"bdatl":null,"trd":null,"spf":null,"ltp":null,"atb":[[8.4000000000000004,189.41999999999999],[7.5999999999999996,13.800000000000001],[7.4000000000000004,9.3599999999999994],[6.2000000000000002,0],[6.4000000000000004,0]],"spl":null,"spn":null,"atl":null,"batl":null,"id":16570658,"hc":null,"bdatb":null},{"tv":null,"batb":null,"spb":null,"bdatl":null,"trd":null,"spf":null,"ltp":null,"atb":[[1.04,73840.729999999996],[1.05,74301.130000000005],[1.0700000000000001,38868.489999999998],[1.0800000000000001,39693.57],[1.0900000000000001,40174.459999999999],[1.0600000000000001,63324.940000000002],[1.02,90733.919999999998],[1.03,88973.339999999997],[1.01,93463.490000000005]],"spl":null,"spn":null,"atl":[[1.24,5.9299999999999997],[1.1699999999999999,10123.530000000001],[1.1399999999999999,22078.68],[1.19,8875.6399999999994],[1.1599999999999999,11762.49],[1.1799999999999999,8873.2000000000007]],"batl":null,"id":19924823,"hc":null,"bdatb":null}],"img":null,"tv":null,"con":null,"marketdefinition":null,"id":"1.258926623"}],"conflatems":null,"op":"mcm","id":3}
{"ct":null,"SegmentType":null,"clk":"AOzyAQCu8QEA094B","heartbeatms":null,"pt":1780839876504,"initialclk":null,"mc":[{"rc":[{"tv":null,"batb":null,"spb":null,"bdatl":null,"trd":null,"spf":null,"ltp":null,"atb":[[1.1000000000000001,66571.919999999998]],"spl":null,"spn":null,"atl":[[1.1699999999999999,10116.040000000001]],"batl":null,"id":19924823,"hc":null,"bdatb":null}],"img":null,"tv":null,"con":null,"marketdefinition":null,"id":"1.258926623"}],"conflatems":null,"op":"mcm","id":3}
{"ct":null,"SegmentType":null,"clk":"APXyAQC78QEA3N4B","heartbeatms":null,"pt":1780839876606,"initialclk":null,"mc":[{"rc":[{"tv":null,"batb":null,"spb":null,"bdatl":null,"trd":null,"spf":null,"ltp":null,"atb":[[8.4000000000000004,367.54000000000002],[7.5999999999999996,681.79999999999995],[8,304.27999999999997]],"spl":null,"spn":null,"atl":null,"batl":null,"id":16570658,"hc":null,"bdatb":null},{"tv":null,"batb":null,"spb":null,"bdatl":null,"trd":null,"spf":null,"ltp":null,"atb":null,"spl":null,"spn":null,"atl":[[1.1499999999999999,27624.060000000001]],"batl":null,"id":19924823,"hc":null,"bdatb":null}],"img":null,"tv":null,"con":null,"marketdefinition":null,"id":"1.258926623"}],"conflatems":null,"op":"mcm","id":3}
{"ct":null,"SegmentType":null,"clk":"AITzAQDF8QEA494B","heartbeatms":null,"pt":1780839876711,"initialclk":null,"mc":[{"rc":[{"tv":null,"batb":null,"spb":null,"bdatl":null,"trd":null,"spf":null,"ltp":null,"atb":[[7.2000000000000002,749.98000000000002]],"spl":null,"spn":null,"atl":null,"batl":null,"id":16570658,"hc":null,"bdatb":null},{"tv":null,"batb":null,"spb":null,"bdatl":null,"trd":null,"spf":null,"ltp":null,"atb":null,"spl":null,"spn":null,"atl":[[1.1599999999999999,11190.49]],"batl":null,"id":19924823,"hc":null,"bdatb":null}],"img":null,"tv":null,"con":null,"marketdefinition":null,"id":"1.258926623"}],"conflatems":null,"op":"mcm","id":3}
{"ct":null,"SegmentType":null,"clk":"AJHzAQDP8QEA7d4B","heartbeatms":null,"pt":1780839876816,"initialclk":null,"mc":[{"rc":[{"tv":null,"batb":null,"spb":null,"bdatl":null,"trd":null,"spf":null,"ltp":null,"atb":[[6.5999999999999996,130.61000000000001]],"spl":null,"spn":null,"atl":null,"batl":null,"id":16570658,"hc":null,"bdatb":null},{"tv":null,"batb":null,"spb":null,"bdatl":null,"trd":null,"spf":null,"ltp":null,"atb":[[1.1000000000000001,65571.919999999998]],"spl":null,"spn":null,"atl":[[1.23,481.25999999999999]],"batl":null,"id":19924823,"hc":null,"bdatb":null}],"img":null,"tv":null,"con":null,"marketdefinition":null,"id":"1.258926623"}],"conflatems":null,"op":"mcm","id":3}
{"ct":null,"SegmentType":null,"clk":"AJnzAQDY8QEA9t4B","heartbeatms":null,"pt":1780839876871,"initialclk":null,"mc":[{"rc":[{"tv":null,"batb":null,"spb":null,"bdatl":null,"trd":null,"spf":null,"ltp":null,"atb":null,"spl":null,"spn":null,"atl":[[1.1399999999999999,22278.68]],"batl":null,"id":19924823,"hc":null,"bdatb":null}],"img":null,"tv":null,"con":null,"marketdefinition":null,"id":"1.258926623"}],"conflatems":null,"op":"mcm","id":3}
{"ct":null,"SegmentType":null,"clk":"AKjzAQDi8QEAgd8B","heartbeatms":null,"pt":1780839876973,"initialclk":null,"mc":[{"rc":[{"tv":null,"batb":null,"spb":null,"bdatl":null,"trd":null,"spf":null,"ltp":null,"atb":[[1.1100000000000001,74708.550000000003]],"spl":null,"spn":null,"atl":[[1.1399999999999999,22286.18]],"batl":null,"id":19924823,"hc":null,"bdatb":null}],"img":null,"tv":null,"con":null,"marketdefinition":null,"id":"1.258926623"}],"conflatems":null,"op":"mcm","id":3}
{"ct":null,"SegmentType":null,"clk":"AO3zAQDw8QEAh98B","heartbeatms":null,"pt":1780839877128,"initialclk":null,"mc":[{"rc":[{"tv":null,"batb":null,"spb":null,"bdatl":null,"trd":null,"spf":null,"ltp":null,"atb":[[1.1100000000000001,74955]],"spl":null,"spn":null,"atl":[[1.1399999999999999,24267.790000000001],[1.1499999999999999,28309.459999999999]],"batl":null,"id":19924823,"hc":null,"bdatb":null}],"img":null,"tv":null,"con":null,"marketdefinition":null,"id":"1.258926623"}],"conflatems":null,"op":"mcm","id":3}
{"ct":null,"SegmentType":null,"clk":"APbzAQD68QEAkN8B","heartbeatms":null,"pt":1780839877181,"initialclk":null,"mc":[{"rc":[{"tv":null,"batb":null,"spb":null,"bdatl":null,"trd":null,"spf":null,"ltp":null,"atb":[[1.1200000000000001,26962.099999999999]],"spl":null,"spn":null,"atl":[[1.1699999999999999,8880.4500000000007],[1.1599999999999999,9809.7999999999993]],"batl":null,"id":19924823,"hc":null,"bdatb":null}],"img":null,"tv":null,"con":null,"marketdefinition":null,"id":"1.258926623"}],"conflatems":null,"op":"mcm","id":3}
{"ct":null,"SegmentType":null,"clk":"AIP0AQCI8gEAmt8B","heartbeatms":null,"pt":1780839877285,"initialclk":null,"mc":[{"rc":[{"tv":null,"batb":null,"spb":null,"bdatl":null,"trd":null,"spf":null,"ltp":null,"atb":[[7.5999999999999996,871.71000000000004]],"spl":null,"spn":null,"atl":[[14.5,104.94]],"batl":null,"id":16570658,"hc":null,"bdatb":null},{"tv":null,"batb":null,"spb":null,"bdatl":null,"trd":null,"spf":null,"ltp":null,"atb":[[1.1200000000000001,28301.380000000001]],"spl":null,"spn":null,"atl":[[1.1499999999999999,29564.549999999999]],"batl":null,"id":19924823,"hc":null,"bdatb":null}],"img":null,"tv":null,"con":null,"marketdefinition":null,"id":"1.258926623"}],"conflatems":null,"op":"mcm","id":3}
{"ct":null,"SegmentType":null,"clk":"AI70AQCQ8gEAoN8B","heartbeatms":null,"pt":1780839877387,"initialclk":null,"mc":[{"rc":[{"tv":247239.29000000001,"batb":null,"spb":null,"bdatl":null,"trd":[[8.5999999999999996,2707.3600000000001]],"spf":null,"ltp":8.5999999999999996,"atb":[[8.5999999999999996,11.4]],"spl":null,"spn":null,"atl":[[8.5999999999999996,0]],"batl":null,"id":16570658,"hc":null,"bdatb":null},{"tv":2102722.0800000001,"batb":null,"spb":null,"bdatl":null,"trd":[[1.1299999999999999,243611.60999999999]],"spf":null,"ltp":null,"atb":[[1.1299999999999999,0]],"spl":null,"spn":null,"atl":[[1.1299999999999999,43203.830000000002]],"batl":null,"id":19924823,"hc":null,"bdatb":null}],"img":null,"tv":2349961.3700000001,"con":null,"marketdefinition":null,"id":"1.258926623"}],"conflatems":null,"op":"mcm","id":3}
{"ct":null,"SegmentType":null,"clk":"AKD0AQCl8gEArt8B","heartbeatms":null,"pt":1780839877593,"initialclk":null,"mc":[{"rc":[{"tv":2102725.02,"batb":null,"spb":null,"bdatl":null,"trd":[[1.1299999999999999,243614.54999999999]],"spf":null,"ltp":null,"atb":[[1.1200000000000001,26962.099999999999]],"spl":null,"spn":null,"atl":[[1.1299999999999999,43202.360000000001]],"batl":null,"id":19924823,"hc":null,"bdatb":null}],"img":null,"tv":2349964.3100000001,"con":null,"marketdefinition":null,"id":"1.258926623"}],"conflatems":null,"op":"mcm","id":3}
{"ct":null,"SegmentType":null,"clk":"AOn0AQDu8gEA6t8B","heartbeatms":null,"pt":1780839878414,"initialclk":null,"mc":[{"rc":[{"tv":null,"batb":null,"spb":null,"bdatl":null,"trd":null,"spf":null,"ltp":null,"atb":[[1.03,88973.630000000005]],"spl":null,"spn":null,"atl":null,"batl":null,"id":19924823,"hc":null,"bdatb":null}],"img":null,"tv":null,"con":null,"marketdefinition":null,"id":"1.258926623"}],"conflatems":null,"op":"mcm","id":3}
{"ct":null,"SegmentType":null,"clk":"AP/0AQCI8wEA\u002B98B","heartbeatms":null,"pt":1780839878578,"initialclk":null,"mc":[{"rc":[{"tv":null,"batb":null,"spb":null,"bdatl":null,"trd":null,"spf":null,"ltp":null,"atb":null,"spl":null,"spn":null,"atl":[[1.1299999999999999,26510.700000000001]],"batl":null,"id":19924823,"hc":null,"bdatb":null}],"img":null,"tv":null,"con":null,"marketdefinition":null,"id":"1.258926623"}],"conflatems":null,"op":"mcm","id":3}
{"ct":null,"SegmentType":null,"clk":"AJH1AQCi8wEAjOAB","heartbeatms":null,"pt":1780839878783,"initialclk":null,"mc":[{"rc":[{"tv":null,"batb":null,"spb":null,"bdatl":null,"trd":null,"spf":null,"ltp":null,"atb":[[1.03,88973.339999999997]],"spl":null,"spn":null,"atl":[[1.1299999999999999,27755.41]],"batl":null,"id":19924823,"hc":null,"bdatb":null}],"img":null,"tv":null,"con":null,"marketdefinition":null,"id":"1.258926623"}],"conflatems":null,"op":"mcm","id":3}
{"ct":null,"SegmentType":null,"clk":"AKb1AQC08wEAoeAB","heartbeatms":null,"pt":1780839878995,"initialclk":null,"mc":[{"rc":[{"tv":null,"batb":null,"spb":null,"bdatl":null,"trd":null,"spf":null,"ltp":null,"atb":null,"spl":null,"spn":null,"atl":[[1.1299999999999999,29000.119999999999]],"batl":null,"id":19924823,"hc":null,"bdatb":null}],"img":null,"tv":null,"con":null,"marketdefinition":null,"id":"1.258926623"}],"conflatems":null,"op":"mcm","id":3}
{"ct":null,"SegmentType":null,"clk":"AK71AQC98wEAqeAB","heartbeatms":null,"pt":1780839879095,"initialclk":null,"mc":[{"rc":[{"tv":null,"batb":null,"spb":null,"bdatl":null,"trd":null,"spf":null,"ltp":null,"atb":null,"spl":null,"spn":null,"atl":[[1.1299999999999999,30244.830000000002]],"batl":null,"id":19924823,"hc":null,"bdatb":null}],"img":null,"tv":null,"con":null,"marketdefinition":null,"id":"1.258926623"}],"conflatems":null,"op":"mcm","id":3}
{"ct":null,"SegmentType":null,"clk":"ANX1AQDn8wEAyuAB","heartbeatms":null,"pt":1780839879509,"initialclk":null,"mc":[{"rc":[{"tv":2102739.52,"batb":null,"spb":null,"bdatl":null,"trd":[[1.1299999999999999,243629.04999999999]],"spf":null,"ltp":null,"atb":null,"spl":null,"spn":null,"atl":[[1.1299999999999999,30237.580000000002]],"batl":null,"id":19924823,"hc":null,"bdatb":null}],"img":null,"tv":2349978.8100000001,"con":null,"marketdefinition":null,"id":"1.258926623"}],"conflatems":null,"op":"mcm","id":3}
{"ct":null,"SegmentType":null,"clk":"AOT1AQD58wEA1uAB","heartbeatms":null,"pt":1780839879709,"initialclk":null,"mc":[{"rc":[{"tv":null,"batb":null,"spb":null,"bdatl":null,"trd":null,"spf":null,"ltp":null,"atb":[[1.1200000000000001,26902.099999999999]],"spl":null,"spn":null,"atl":null,"batl":null,"id":19924823,"hc":null,"bdatb":null}],"img":null,"tv":null,"con":null,"marketdefinition":null,"id":"1.258926623"}],"conflatems":null,"op":"mcm","id":3}
{"ct":null,"SegmentType":null,"clk":"APP1AQCO9AEA6OAB","heartbeatms":null,"pt":1780839879913,"initialclk":null,"mc":[{"rc":[{"tv":null,"batb":null,"spb":null,"bdatl":null,"trd":null,"spf":null,"ltp":null,"atb":[[8.4000000000000004,459.54000000000002]],"spl":null,"spn":null,"atl":[[10.5,114.25]],"batl":null,"id":16570658,"hc":null,"bdatb":null},{"tv":null,"batb":null,"spb":null,"bdatl":null,"trd":null,"spf":null,"ltp":null,"atb":[[1.1000000000000001,67668.919999999998]],"spl":null,"spn":null,"atl":[[1.1399999999999999,26215.790000000001]],"batl":null,"id":19924823,"hc":null,"bdatb":null}],"img":null,"tv":null,"con":null,"marketdefinition":null,"id":"1.258926623"}],"conflatems":null,"op":"mcm","id":3}
{"ct":null,"SegmentType":null,"clk":"APj1AQCc9AEA7\u002BAB","heartbeatms":null,"pt":1780839879973,"initialclk":null,"mc":[{"rc":[{"tv":null,"batb":null,"spb":null,"bdatl":null,"trd":null,"spf":null,"ltp":null,"atb":null,"spl":null,"spn":null,"atl":[[1.1299999999999999,30261.16]],"batl":null,"id":19924823,"hc":null,"bdatb":null}],"img":null,"tv":null,"con":null,"marketdefinition":null,"id":"1.258926623"}],"conflatems":null,"op":"mcm","id":3}
{"ct":null,"SegmentType":null,"clk":"AIj2AQCy9AEAg\u002BEB","heartbeatms":null,"pt":1780839880180,"initialclk":null,"mc":[{"rc":[{"tv":null,"batb":null,"spb":null,"bdatl":null,"trd":null,"spf":null,"ltp":null,"atb":null,"spl":null,"spn":null,"atl":[[1.1299999999999999,30693.509999999998]],"batl":null,"id":19924823,"hc":null,"bdatb":null}],"img":null,"tv":null,"con":null,"marketdefinition":null,"id":"1.258926623"}],"conflatems":null,"op":"mcm","id":3}
{"ct":null,"SegmentType":null,"clk":"AJX2AQDG9AEAleEB","heartbeatms":null,"pt":1780839880382,"initialclk":null,"mc":[{"rc":[{"tv":null,"batb":null,"spb":null,"bdatl":null,"trd":null,"spf":null,"ltp":null,"atb":null,"spl":null,"spn":null,"atl":[[13.5,0]],"batl":null,"id":16570658,"hc":null,"bdatb":null}],"img":null,"tv":null,"con":null,"marketdefinition":null,"id":"1.258926623"}],"conflatems":null,"op":"mcm","id":3}
{"ct":null,"SegmentType":null,"clk":"AJz2AQDP9AEAnuEB","heartbeatms":null,"pt":1780839880482,"initialclk":null,"mc":[{"rc":[{"tv":null,"batb":null,"spb":null,"bdatl":null,"trd":null,"spf":null,"ltp":null,"atb":[[8.5999999999999996,158.61000000000001]],"spl":null,"spn":null,"atl":[[10,95.239999999999995],[9,150.66999999999999]],"batl":null,"id":16570658,"hc":null,"bdatb":null},{"tv":null,"batb":null,"spb":null,"bdatl":null,"trd":null,"spf":null,"ltp":null,"atb":[[1.1200000000000001,28032.450000000001]],"spl":null,"spn":null,"atl":[[1.1299999999999999,31813.849999999999]],"batl":null,"id":19924823,"hc":null,"bdatb":null}],"img":null,"tv":null,"con":null,"marketdefinition":null,"id":"1.258926623"}],"conflatems":null,"op":"mcm","id":3}
{"ct":null,"SegmentType":null,"clk":"AMT2AQD59AEAv\u002BEB","heartbeatms":null,"pt":1780839880896,"initialclk":null,"mc":[{"rc":[{"tv":null,"batb":null,"spb":null,"bdatl":null,"trd":null,"spf":null,"ltp":null,"atb":null,"spl":null,"spn":null,"atl":[[1.1599999999999999,9817.2999999999993]],"batl":null,"id":19924823,"hc":null,"bdatb":null}],"img":null,"tv":null,"con":null,"marketdefinition":null,"id":"1.258926623"}],"conflatems":null,"op":"mcm","id":3}
{"ct":null,"SegmentType":null,"clk":"AMz2AQCA9QEAxOEB","heartbeatms":null,"pt":1780839881002,"initialclk":null,"mc":[{"rc":[{"tv":247239.35999999999,"batb":null,"spb":null,"bdatl":null,"trd":[[8.5999999999999996,2707.4299999999998]],"spf":null,"ltp":null,"atb":[[8.5999999999999996,158.56999999999999]],"spl":null,"spn":null,"atl":null,"batl":null,"id":16570658,"hc":null,"bdatb":null}],"img":null,"tv":2349978.8799999999,"con":null,"marketdefinition":null,"id":"1.258926623"}],"conflatems":null,"op":"mcm","id":3}
{"ct":null,"SegmentType":null,"clk":"ANP2AQCH9QEAzOEB","heartbeatms":null,"pt":1780839881103,"initialclk":null,"mc":[{"rc":[{"tv":null,"batb":null,"spb":null,"bdatl":null,"trd":null,"spf":null,"ltp":null,"atb":[[1.1000000000000001,68668.919999999998]],"spl":null,"spn":null,"atl":null,"batl":null,"id":19924823,"hc":null,"bdatb":null}],"img":null,"tv":null,"con":null,"marketdefinition":null,"id":"1.258926623"}],"conflatems":null,"op":"mcm","id":3}
{"ct":null,"SegmentType":null,"clk":"AOX2AQCZ9QEA3OEB","heartbeatms":null,"pt":1780839881311,"initialclk":null,"mc":[{"rc":[{"tv":null,"batb":null,"spb":null,"bdatl":null,"trd":null,"spf":null,"ltp":null,"atb":null,"spl":null,"spn":null,"atl":[[1.1499999999999999,29566.549999999999]],"batl":null,"id":19924823,"hc":null,"bdatb":null}],"img":null,"tv":null,"con":null,"marketdefinition":null,"id":"1.258926623"}],"conflatems":null,"op":"mcm","id":3}
{"ct":null,"SegmentType":null,"clk":"APP2AQCw9QEA8\u002BEB","heartbeatms":null,"pt":1780839881510,"initialclk":null,"mc":[{"rc":[{"tv":null,"batb":null,"spb":null,"bdatl":null,"trd":null,"spf":null,"ltp":null,"atb":null,"spl":null,"spn":null,"atl":[[1.1499999999999999,29564.549999999999]],"batl":null,"id":19924823,"hc":null,"bdatb":null}],"img":null,"tv":null,"con":null,"marketdefinition":null,"id":"1.258926623"}],"conflatems":null,"op":"mcm","id":3}
{"ct":null,"SegmentType":null,"clk":"AJH3AQDQ9QEAkuIB","heartbeatms":null,"pt":1780839881876,"initialclk":null,"mc":[{"rc":[{"tv":2102740.1000000001,"batb":null,"spb":null,"bdatl":null,"trd":[[1.1299999999999999,243629.63000000001]],"spf":null,"ltp":null,"atb":null,"spl":null,"spn":null,"atl":[[1.1299999999999999,31813.560000000001]],"batl":null,"id":19924823,"hc":null,"bdatb":null}],"img":null,"tv":2349979.46,"con":null,"marketdefinition":null,"id":"1.258926623"}],"conflatems":null,"op":"mcm","id":3}
{"ct":null,"SegmentType":null,"clk":"AJz3AQDc9QEAmuIB","heartbeatms":null,"pt":1780839881979,"initialclk":null,"mc":[{"rc":[{"tv":2102791.77,"batb":null,"spb":null,"bdatl":null,"trd":[[1.1299999999999999,243681.29999999999]],"spf":null,"ltp":null,"atb":null,"spl":null,"spn":null,"atl":[[1.1299999999999999,31787.73]],"batl":null,"id":19924823,"hc":null,"bdatb":null}],"img":null,"tv":2350031.1299999999,"con":null,"marketdefinition":null,"id":"1.258926623"}],"conflatems":null,"op":"mcm","id":3}
{"ct":null,"SegmentType":null,"clk":"ALX3AQCG9gEAteIB","heartbeatms":null,"pt":1780839882291,"initialclk":null,"mc":[{"rc":[{"tv":null,"batb":null,"spb":null,"bdatl":null,"trd":null,"spf":null,"ltp":null,"atb":[[1.03,88972.589999999997]],"spl":null,"spn":null,"atl":null,"batl":null,"id":19924823,"hc":null,"bdatb":null}],"img":null,"tv":null,"con":null,"marketdefinition":null,"id":"1.258926623"}],"conflatems":null,"op":"mcm","id":3}
{"ct":null,"SegmentType":null,"clk":"ALv3AQCR9gEAwOIB","heartbeatms":null,"pt":1780839882391,"initialclk":null,"mc":[{"rc":[{"tv":null,"batb":null,"spb":null,"bdatl":null,"trd":null,"spf":null,"ltp":null,"atb":[[1.04,73842.729999999996],[1.05,74303.130000000005],[1.0700000000000001,38870.489999999998],[1.0800000000000001,39695.57],[1.1000000000000001,68670.919999999998],[1.0900000000000001,40176.459999999999],[1.0600000000000001,63326.940000000002],[1.02,90735.919999999998],[1.03,88974.589999999997],[1.01,93465.490000000005]],"spl":null,"spn":null,"atl":null,"batl":null,"id":19924823,"hc":null,"bdatb":null}],"img":null,"tv":null,"con":null,"marketdefinition":null,"id":"1.258926623"}],"conflatems":null,"op":"mcm","id":3}
{"ct":null,"SegmentType":null,"clk":"AOf3AQDN9gEA5uIB","heartbeatms":null,"pt":1780839882905,"initialclk":null,"mc":[{"rc":[{"tv":2102801.77,"batb":null,"spb":null,"bdatl":null,"trd":[[1.1299999999999999,243691.29999999999]],"spf":null,"ltp":null,"atb":null,"spl":null,"spn":null,"atl":[[1.1299999999999999,31782.73]],"batl":null,"id":19924823,"hc":null,"bdatb":null}],"img":null,"tv":2350041.1299999999,"con":null,"marketdefinition":null,"id":"1.258926623"}],"conflatems":null,"op":"mcm","id":3}
{"ct":null,"SegmentType":null,"clk":"APL3AQDV9gEA6uIB","heartbeatms":null,"pt":1780839883005,"initialclk":null,"mc":[{"rc":[{"tv":null,"batb":null,"spb":null,"bdatl":null,"trd":null,"spf":null,"ltp":null,"atb":null,"spl":null,"spn":null,"atl":[[8.8000000000000007,56.630000000000003]],"batl":null,"id":16570658,"hc":null,"bdatb":null},{"tv":null,"batb":null,"spb":null,"bdatl":null,"trd":null,"spf":null,"ltp":null,"atb":[[1.1200000000000001,29945.490000000002]],"spl":null,"spn":null,"atl":[[1.1299999999999999,31781.919999999998]],"batl":null,"id":19924823,"hc":null,"bdatb":null}],"img":null,"tv":null,"con":null,"marketdefinition":null,"id":"1.258926623"}],"conflatems":null,"op":"mcm","id":3}
{"ct":null,"SegmentType":null,"clk":"AJn4AQCA9wEAjuMB","heartbeatms":null,"pt":1780839883517,"initialclk":null,"mc":[{"rc":[{"tv":247352.62,"batb":null,"spb":null,"bdatl":null,"trd":[[8.8000000000000007,1580.6600000000001]],"spf":null,"ltp":8.8000000000000007,"atb":[[8.8000000000000007,70.609999999999999]],"spl":null,"spn":null,"atl":[[8.8000000000000007,0]],"batl":null,"id":16570658,"hc":null,"bdatb":null}],"img":null,"tv":2350154.3900000001,"con":null,"marketdefinition":null,"id":"1.258926623"}],"conflatems":null,"op":"mcm","id":3}
{"ct":null,"SegmentType":null,"clk":"AKL4AQCK9wEAl\u002BMB","heartbeatms":null,"pt":1780839883579,"initialclk":null,"mc":[{"rc":[{"tv":null,"batb":null,"spb":null,"bdatl":null,"trd":null,"spf":null,"ltp":null,"atb":null,"spl":null,"spn":null,"atl":[[1.1299999999999999,28047.790000000001],[1.1399999999999999,24488.23]],"batl":null,"id":19924823,"hc":null,"bdatb":null}],"img":null,"tv":null,"con":null,"marketdefinition":null,"id":"1.258926623"}],"conflatems":null,"op":"mcm","id":3}
{"ct":null,"SegmentType":null,"clk":"AKr4AQCT9wEAn\u002BMB","heartbeatms":null,"pt":1780839883677,"initialclk":null,"mc":[{"rc":[{"tv":null,"batb":null,"spb":null,"bdatl":null,"trd":null,"spf":null,"ltp":null,"atb":[[7,0.98999999999999999],[7.5999999999999996,872.58000000000004],[7.2000000000000002,750.84000000000003]],"spl":null,"spn":null,"atl":[[11,104.94],[10.5,115.11]],"batl":null,"id":16570658,"hc":null,"bdatb":null},{"tv":null,"batb":null,"spb":null,"bdatl":null,"trd":null,"spf":null,"ltp":null,"atb":[[1.1000000000000001,68675.630000000005],[1.0900000000000001,40184.019999999997]],"spl":null,"spn":null,"atl":[[1.1699999999999999,8885.4500000000007],[1.1499999999999999,29569.73],[1.1799999999999999,8877.2099999999991]],"batl":null,"id":19924823,"hc":null,"bdatb":null}],"img":null,"tv":null,"con":null,"marketdefinition":null,"id":"1.258926623"}],"conflatems":null,"op":"mcm","id":3}
{"ct":null,"SegmentType":null,"clk":"AMz4AQC69wEAv\u002BMB","heartbeatms":null,"pt":1780839884090,"initialclk":null,"mc":[{"rc":[{"tv":null,"batb":null,"spb":null,"bdatl":null,"trd":null,"spf":null,"ltp":null,"atb":null,"spl":null,"spn":null,"atl":[[1.2,9101.0499999999993]],"batl":null,"id":19924823,"hc":null,"bdatb":null}],"img":null,"tv":null,"con":null,"marketdefinition":null,"id":"1.258926623"}],"conflatems":null,"op":"mcm","id":3}
{"ct":null,"SegmentType":null,"clk":"AP/4AQDx9wEA6uMB","heartbeatms":null,"pt":1780839884604,"initialclk":null,"mc":[{"rc":[{"tv":null,"batb":null,"spb":null,"bdatl":null,"trd":null,"spf":null,"ltp":null,"atb":null,"spl":null,"spn":null,"atl":[[1.22,8862.3500000000004]],"batl":null,"id":19924823,"hc":null,"bdatb":null}],"img":null,"tv":null,"con":null,"marketdefinition":null,"id":"1.258926623"}],"conflatems":null,"op":"mcm","id":3}
{"ct":null,"SegmentType":null,"clk":"AIn5AQD99wEA7uMB","heartbeatms":null,"pt":1780839884706,"initialclk":null,"mc":[{"rc":[{"tv":null,"batb":null,"spb":null,"bdatl":null,"trd":null,"spf":null,"ltp":null,"atb":[[8.8000000000000007,70.670000000000002]],"spl":null,"spn":null,"atl":null,"batl":null,"id":16570658,"hc":null,"bdatb":null}],"img":null,"tv":null,"con":null,"marketdefinition":null,"id":"1.258926623"}],"conflatems":null,"op":"mcm","id":3}
{"ct":null,"SegmentType":null,"clk":"AMn5AQDG\u002BAEAquQB","heartbeatms":null,"pt":1780839885379,"initialclk":null,"mc":[{"rc":[{"tv":null,"batb":null,"spb":null,"bdatl":null,"trd":null,"spf":null,"ltp":null,"atb":[[7.7999999999999998,187.30000000000001]],"spl":null,"spn":null,"atl":[[9.5999999999999996,424.93000000000001]],"batl":null,"id":16570658,"hc":null,"bdatb":null},{"tv":null,"batb":null,"spb":null,"bdatl":null,"trd":null,"spf":null,"ltp":null,"atb":[[1.1100000000000001,76306.350000000006]],"spl":null,"spn":null,"atl":null,"batl":null,"id":19924823,"hc":null,"bdatb":null}],"img":null,"tv":null,"con":null,"marketdefinition":null,"id":"1.258926623"}],"conflatems":null,"op":"mcm","id":3}
{"ct":null,"SegmentType":null,"clk":"ANr5AQDc\u002BAEAuuQB","heartbeatms":null,"pt":1780839885584,"initialclk":null,"mc":[{"rc":[{"tv":null,"batb":null,"spb":null,"bdatl":null,"trd":null,"spf":null,"ltp":null,"atb":null,"spl":null,"spn":null,"atl":[[9.5999999999999996,268.68000000000001]],"batl":null,"id":16570658,"hc":null,"bdatb":null}],"img":null,"tv":null,"con":null,"marketdefinition":null,"id":"1.258926623"}],"conflatems":null,"op":"mcm","id":3}
{"ct":null,"SegmentType":null,"clk":"AOT5AQDg\u002BAEAv\u002BQB","heartbeatms":null,"pt":1780839885683,"initialclk":null,"mc":[{"rc":[{"tv":null,"batb":null,"spb":null,"bdatl":null,"trd":null,"spf":null,"ltp":null,"atb":[[7.5999999999999996,682.66999999999996]],"spl":null,"spn":null,"atl":null,"batl":null,"id":16570658,"hc":null,"bdatb":null}],"img":null,"tv":null,"con":null,"marketdefinition":null,"id":"1.258926623"}],"conflatems":null,"op":"mcm","id":3}
{"ct":null,"SegmentType":null,"clk":"AJb6AQCO\u002BQEA6OQB","heartbeatms":null,"pt":1780839886202,"initialclk":null,"mc":[{"rc":[{"tv":null,"batb":null,"spb":null,"bdatl":null,"trd":null,"spf":null,"ltp":null,"atb":[[1.01,18490.740000000002]],"spl":null,"spn":null,"atl":null,"batl":null,"id":16570658,"hc":null,"bdatb":null},{"tv":null,"batb":null,"spb":null,"bdatl":null,"trd":null,"spf":null,"ltp":null,"atb":[[1.01,93593.869999999995]],"spl":null,"spn":null,"atl":null,"batl":null,"id":19924823,"hc":null,"bdatb":null}],"img":null,"tv":null,"con":null,"marketdefinition":null,"id":"1.258926623"}],"conflatems":null,"op":"mcm","id":3}
{"ct":null,"SegmentType":null,"clk":"ALn6AQCp\u002BQEAgOUB","heartbeatms":null,"pt":1780839886509,"initialclk":null,"mc":[{"rc":[{"tv":null,"batb":null,"spb":null,"bdatl":null,"trd":null,"spf":null,"ltp":null,"atb":[[7.5999999999999996,681.79999999999995],[7.4000000000000004,8.3599999999999994]],"spl":null,"spn":null,"atl":[[9.8000000000000007,66.829999999999998],[10,94.25]],"batl":null,"id":16570658,"hc":null,"bdatb":null},{"tv":2102802.0899999999,"batb":null,"spb":null,"bdatl":null,"trd":[[1.1299999999999999,243691.62]],"spf":null,"ltp":null,"atb":[[1.1000000000000001,68668.809999999998],[1.1100000000000001,76301.869999999995]],"spl":null,"spn":null,"atl":[[1.1699999999999999,8881.2000000000007],[1.1299999999999999,28047.630000000001],[1.1599999999999999,9813.1800000000003]],"batl":null,"id":19924823,"hc":null,"bdatb":null}],"img":null,"tv":2350154.71,"con":null,"marketdefinition":null,"id":"1.258926623"}],"conflatems":null,"op":"mcm","id":3}
{"ct":null,"SegmentType":null,"clk":"AO76AQDw\u002BQEAo\u002BUB","heartbeatms":null,"pt":1780839887082,"initialclk":null,"mc":[{"rc":[{"tv":null,"batb":null,"spb":null,"bdatl":null,"trd":null,"spf":null,"ltp":null,"atb":null,"spl":null,"spn":null,"atl":[[1.1299999999999999,28076.509999999998]],"batl":null,"id":19924823,"hc":null,"bdatb":null}],"img":null,"tv":null,"con":null,"marketdefinition":null,"id":"1.258926623"}],"conflatems":null,"op":"mcm","id":3}
{"ct":null,"SegmentType":null,"clk":"ALL7AQC7\u002BgEA1eUB","heartbeatms":null,"pt":1780839887700,"initialclk":null,"mc":[{"rc":[{"tv":247352.73999999999,"batb":null,"spb":null,"bdatl":null,"trd":[[9,773.04999999999995]],"spf":null,"ltp":9,"atb":null,"spl":null,"spn":null,"atl":[[9,150.61000000000001]],"batl":null,"id":16570658,"hc":null,"bdatb":null}],"img":null,"tv":2350154.8300000001,"con":null,"marketdefinition":null,"id":"1.258926623"}],"conflatems":null,"op":"mcm","id":3}
{"ct":null,"SegmentType":null,"clk":"AMP7AQDO\u002BgEA5eUB","heartbeatms":null,"pt":1780839887910,"initialclk":null,"mc":[{"rc":[{"tv":null,"batb":null,"spb":null,"bdatl":null,"trd":null,"spf":null,"ltp":null,"atb":null,"spl":null,"spn":null,"atl":[[1.22,9062.3500000000004]],"batl":null,"id":19924823,"hc":null,"bdatb":null}],"img":null,"tv":null,"con":null,"marketdefinition":null,"id":"1.258926623"}],"conflatems":null,"op":"mcm","id":3}
{"ct":null,"SegmentType":null,"clk":"AOT7AQDt\u002BgEA/OUB","heartbeatms":null,"pt":1780839888315,"initialclk":null,"mc":[{"rc":[{"tv":null,"batb":null,"spb":null,"bdatl":null,"trd":null,"spf":null,"ltp":null,"atb":null,"spl":null,"spn":null,"atl":[[1.1399999999999999,24480.73]],"batl":null,"id":19924823,"hc":null,"bdatb":null}],"img":null,"tv":null,"con":null,"marketdefinition":null,"id":"1.258926623"}],"conflatems":null,"op":"mcm","id":3}
{"ct":null,"SegmentType":null,"clk":"AJb8AQCc\u002BwEAquYB","heartbeatms":null,"pt":1780839888787,"initialclk":null,"mc":[{"rc":[{"tv":null,"batb":null,"spb":null,"bdatl":null,"trd":null,"spf":null,"ltp":null,"atb":null,"spl":null,"spn":null,"atl":[[1.21,8960.3500000000004]],"batl":null,"id":19924823,"hc":null,"bdatb":null}],"img":null,"tv":null,"con":null,"marketdefinition":null,"id":"1.258926623"}],"conflatems":null,"op":"mcm","id":3}
{"ct":null,"SegmentType":null,"clk":"AKv8AQCs\u002BwEAu\u002BYB","heartbeatms":null,"pt":1780839888992,"initialclk":null,"mc":[{"rc":[{"tv":2103026.4100000001,"batb":null,"spb":null,"bdatl":null,"trd":[[1.1299999999999999,243915.94]],"spf":null,"ltp":null,"atb":null,"spl":null,"spn":null,"atl":[[1.1299999999999999,27964.349999999999]],"batl":null,"id":19924823,"hc":null,"bdatb":null}],"img":null,"tv":2350379.1499999999,"con":null,"marketdefinition":null,"id":"1.258926623"}],"conflatems":null,"op":"mcm","id":3}
{"ct":null,"SegmentType":null,"clk":"AMb8AQC/\u002BwEAyuYB","heartbeatms":null,"pt":1780839889202,"initialclk":null,"mc":[{"rc":[{"tv":2103028.4100000001,"batb":null,"spb":null,"bdatl":null,"trd":[[1.1200000000000001,62476.169999999998]],"spf":null,"ltp":1.1200000000000001,"atb":[[1.1200000000000001,29944.490000000002]],"spl":null,"spn":null,"atl":null,"batl":null,"id":19924823,"hc":null,"bdatb":null}],"img":null,"tv":2350381.1499999999,"con":null,"marketdefinition":null,"id":"1.258926623"}],"conflatems":null,"op":"mcm","id":3}
{"ct":null,"SegmentType":null,"clk":"AJ/9AQCm/AEAo\u002BcB","heartbeatms":null,"pt":1780839890185,"initialclk":null,"mc":[{"rc":[{"tv":247653.95999999999,"batb":null,"spb":null,"bdatl":null,"trd":[[9,1074.27]],"spf":null,"ltp":null,"atb":[[9,4.8700000000000001]],"spl":null,"spn":null,"atl":[[9,0]],"batl":null,"id":16570658,"hc":null,"bdatb":null}],"img":null,"tv":2350682.3700000001,"con":null,"marketdefinition":null,"id":"1.258926623"}],"conflatems":null,"op":"mcm","id":3}
{"ct":null,"SegmentType":null,"clk":"AKP9AQCx/AEAsucB","heartbeatms":null,"pt":1780839890289,"initialclk":null,"mc":[{"rc":[{"tv":null,"batb":null,"spb":null,"bdatl":null,"trd":null,"spf":null,"ltp":null,"atb":null,"spl":null,"spn":null,"atl":[[9.1999999999999993,144.86000000000001]],"batl":null,"id":16570658,"hc":null,"bdatb":null}],"img":null,"tv":null,"con":null,"marketdefinition":null,"id":"1.258926623"}],"conflatems":null,"op":"mcm","id":3}
{"ct":null,"SegmentType":null,"clk":"AK39AQC7/AEAuucB","heartbeatms":null,"pt":1780839890393,"initialclk":null,"mc":[{"rc":[{"tv":null,"batb":null,"spb":null,"bdatl":null,"trd":null,"spf":null,"ltp":null,"atb":[[8,289.99000000000001]],"spl":null,"spn":null,"atl":null,"batl":null,"id":16570658,"hc":null,"bdatb":null},{"tv":null,"batb":null,"spb":null,"bdatl":null,"trd":null,"spf":null,"ltp":null,"atb":[[1.1200000000000001,28031.450000000001]],"spl":null,"spn":null,"atl":null,"batl":null,"id":19924823,"hc":null,"bdatb":null}],"img":null,"tv":null,"con":null,"marketdefinition":null,"id":"1.258926623"}],"conflatems":null,"op":"mcm","id":3}
{"ct":null,"SegmentType":null,"clk":"ALn9AQDF/AEAv\u002BcB","heartbeatms":null,"pt":1780839890494,"initialclk":null,"mc":[{"rc":[{"tv":247665.12,"batb":null,"spb":null,"bdatl":null,"trd":[[8.8000000000000007,1582.0799999999999],[9,1084.01]],"spf":null,"ltp":8.8000000000000007,"atb":[[8.8000000000000007,69.959999999999994],[9,0]],"spl":null,"spn":null,"atl":null,"batl":null,"id":16570658,"hc":null,"bdatb":null}],"img":null,"tv":2350693.5299999998,"con":null,"marketdefinition":null,"id":"1.258926623"}],"conflatems":null,"op":"mcm","id":3}
{"ct":null,"SegmentType":null,"clk":"AMH9AQDS/AEAyecB","heartbeatms":null,"pt":1780839890604,"initialclk":null,"mc":[{"rc":[{"tv":null,"batb":null,"spb":null,"bdatl":null,"trd":null,"spf":null,"ltp":null,"atb":[[8.5999999999999996,171.72999999999999]],"spl":null,"spn":null,"atl":null,"batl":null,"id":16570658,"hc":null,"bdatb":null}],"img":null,"tv":null,"con":null,"marketdefinition":null,"id":"1.258926623"}],"conflatems":null,"op":"mcm","id":3}
{"ct":null,"SegmentType":null,"clk":"ANT9AQDm/AEA3\u002BcB","heartbeatms":null,"pt":1780839890801,"initialclk":null,"mc":[{"rc":[{"tv":null,"batb":null,"spb":null,"bdatl":null,"trd":null,"spf":null,"ltp":null,"atb":[[1.1200000000000001,28028.860000000001]],"spl":null,"spn":null,"atl":null,"batl":null,"id":19924823,"hc":null,"bdatb":null}],"img":null,"tv":null,"con":null,"marketdefinition":null,"id":"1.258926623"}],"conflatems":null,"op":"mcm","id":3}
{"ct":null,"SegmentType":null,"clk":"APT9AQD\u002B/AEA/OcB","heartbeatms":null,"pt":1780839891111,"initialclk":null,"mc":[{"rc":[{"tv":null,"batb":null,"spb":null,"bdatl":null,"trd":null,"spf":null,"ltp":null,"atb":null,"spl":null,"spn":null,"atl":[[1.1499999999999999,29568.73]],"batl":null,"id":19924823,"hc":null,"bdatb":null}],"img":null,"tv":null,"con":null,"marketdefinition":null,"id":"1.258926623"}],"conflatems":null,"op":"mcm","id":3}
{"ct":null,"SegmentType":null,"clk":"APz9AQCH/QEAiOgB","heartbeatms":null,"pt":1780839891212,"initialclk":null,"mc":[{"rc":[{"tv":null,"batb":null,"spb":null,"bdatl":null,"trd":null,"spf":null,"ltp":null,"atb":null,"spl":null,"spn":null,"atl":[[1.1699999999999999,8882.2000000000007]],"batl":null,"id":19924823,"hc":null,"bdatb":null}],"img":null,"tv":null,"con":null,"marketdefinition":null,"id":"1.258926623"}],"conflatems":null,"op":"mcm","id":3}
{"ct":null,"SegmentType":null,"clk":"AIn\u002BAQCT/QEAkegB","heartbeatms":null,"pt":1780839891319,"initialclk":null,"mc":[{"rc":[{"tv":null,"batb":null,"spb":null,"bdatl":null,"trd":null,"spf":null,"ltp":null,"atb":null,"spl":null,"spn":null,"atl":[[1.1299999999999999,27532]],"batl":null,"id":19924823,"hc":null,"bdatb":null}],"img":null,"tv":null,"con":null,"marketdefinition":null,"id":"1.258926623"}],"conflatems":null,"op":"mcm","id":3}
{"ct":null,"SegmentType":null,"clk":"AK7\u002BAQDB/QEAr\u002BgB","heartbeatms":null,"pt":1780839891779,"initialclk":null,"mc":[{"rc":[{"tv":null,"batb":null,"spb":null,"bdatl":null,"trd":null,"spf":null,"ltp":null,"atb":null,"spl":null,"spn":null,"atl":[[1.21,9160.3500000000004]],"batl":null,"id":19924823,"hc":null,"bdatb":null}],"img":null,"tv":null,"con":null,"marketdefinition":null,"id":"1.258926623"}],"conflatems":null,"op":"mcm","id":3}
{"ct":null,"SegmentType":null,"clk":"AO/\u002BAQCI/gEA3\u002BgB","heartbeatms":null,"pt":1780839892407,"initialclk":null,"mc":[{"rc":[{"tv":null,"batb":null,"spb":null,"bdatl":null,"trd":null,"spf":null,"ltp":null,"atb":[[8.8000000000000007,69.900000000000006]],"spl":null,"spn":null,"atl":null,"batl":null,"id":16570658,"hc":null,"bdatb":null}],"img":null,"tv":null,"con":null,"marketdefinition":null,"id":"1.258926623"}],"conflatems":null,"op":"mcm","id":3}
{"ct":null,"SegmentType":null,"clk":"AKX/AQDA/gEAh\u002BkB","heartbeatms":null,"pt":1780839893018,"initialclk":null,"mc":[{"rc":[{"tv":247672.79999999999,"batb":null,"spb":null,"bdatl":null,"trd":[[8.8000000000000007,1589.76]],"spf":null,"ltp":null,"atb":[[8.8000000000000007,66.060000000000002]],"spl":null,"spn":null,"atl":null,"batl":null,"id":16570658,"hc":null,"bdatb":null}],"img":null,"tv":2350701.21,"con":null,"marketdefinition":null,"id":"1.258926623"}],"conflatems":null,"op":"mcm","id":3}
{"ct":null,"SegmentType":null,"clk":"ALL/AQDJ/gEAkOkB","heartbeatms":null,"pt":1780839893120,"initialclk":null,"mc":[{"rc":[{"tv":null,"batb":null,"spb":null,"bdatl":null,"trd":null,"spf":null,"ltp":null,"atb":null,"spl":null,"spn":null,"atl":[[9,134.30000000000001]],"batl":null,"id":16570658,"hc":null,"bdatb":null},{"tv":null,"batb":null,"spb":null,"bdatl":null,"trd":null,"spf":null,"ltp":null,"atb":null,"spl":null,"spn":null,"atl":[[1.22,8862.3500000000004]],"batl":null,"id":19924823,"hc":null,"bdatb":null}],"img":null,"tv":null,"con":null,"marketdefinition":null,"id":"1.258926623"}],"conflatems":null,"op":"mcm","id":3}
{"ct":null,"SegmentType":null,"clk":"AM//AQDp/gEAtekB","heartbeatms":null,"pt":1780839893479,"initialclk":null,"mc":[{"rc":[{"tv":null,"batb":null,"spb":null,"bdatl":null,"trd":null,"spf":null,"ltp":null,"atb":null,"spl":null,"spn":null,"atl":[[9.5999999999999996,424.92000000000002]],"batl":null,"id":16570658,"hc":null,"bdatb":null}],"img":null,"tv":null,"con":null,"marketdefinition":null,"id":"1.258926623"}],"conflatems":null,"op":"mcm","id":3}
{"ct":null,"SegmentType":null,"clk":"APb/AQCT/wEA1OkB","heartbeatms":null,"pt":1780839893996,"initialclk":null,"mc":[{"rc":[{"tv":null,"batb":null,"spb":null,"bdatl":null,"trd":null,"spf":null,"ltp":null,"atb":null,"spl":null,"spn":null,"atl":[[14.5,1.5]],"batl":null,"id":16570658,"hc":null,"bdatb":null}],"img":null,"tv":null,"con":null,"marketdefinition":null,"id":"1.258926623"}],"conflatems":null,"op":"mcm","id":3}
{"ct":null,"SegmentType":null,"clk":"AMKAAgDi/wEAn\u002BoB","heartbeatms":null,"pt":1780839894922,"initialclk":null,"mc":[{"rc":[{"tv":247675.04000000001,"batb":null,"spb":null,"bdatl":null,"trd":[[8.8000000000000007,1592]],"spf":null,"ltp":null,"atb":[[8.8000000000000007,64.939999999999998]],"spl":null,"spn":null,"atl":null,"batl":null,"id":16570658,"hc":null,"bdatb":null}],"img":null,"tv":2350703.4500000002,"con":null,"marketdefinition":null,"id":"1.258926623"}],"conflatems":null,"op":"mcm","id":3}
{"ct":null,"SegmentType":null,"clk":"AKOBAgDbgAIAjOsB","heartbeatms":null,"pt":1780839896018,"initialclk":null,"mc":[{"rc":[{"tv":2103038.4300000002,"batb":null,"spb":null,"bdatl":null,"trd":[[1.1200000000000001,62486.190000000002]],"spf":null,"ltp":null,"atb":[[1.1200000000000001,28023.849999999999]],"spl":null,"spn":null,"atl":null,"batl":null,"id":19924823,"hc":null,"bdatb":null}],"img":null,"tv":2350713.4700000002,"con":null,"marketdefinition":null,"id":"1.258926623"}],"conflatems":null,"op":"mcm","id":3}
{"ct":null,"SegmentType":null,"clk":"ALuBAgCEgQIApesB","heartbeatms":null,"pt":1780839896321,"initialclk":null,"mc":[{"rc":[{"tv":2103039.0899999999,"batb":null,"spb":null,"bdatl":null,"trd":[[1.1299999999999999,243916.60000000001]],"spf":null,"ltp":1.1299999999999999,"atb":null,"spl":null,"spn":null,"atl":[[1.1299999999999999,27531.669999999998]],"batl":null,"id":19924823,"hc":null,"bdatb":null}],"img":null,"tv":2350714.1299999999,"con":null,"marketdefinition":null,"id":"1.258926623"}],"conflatems":null,"op":"mcm","id":3}
{"ct":null,"SegmentType":null,"clk":"ANmBAgCkgQIAwusB","heartbeatms":null,"pt":1780839896585,"initialclk":null,"mc":[{"rc":[{"tv":null,"batb":null,"spb":null,"bdatl":null,"trd":null,"spf":null,"ltp":null,"atb":null,"spl":null,"spn":null,"atl":[[1.22,9062.3500000000004]],"batl":null,"id":19924823,"hc":null,"bdatb":null}],"img":null,"tv":null,"con":null,"marketdefinition":null,"id":"1.258926623"}],"conflatems":null,"op":"mcm","id":3}
{"ct":null,"SegmentType":null,"clk":"APWBAgDJgQIA3OsB","heartbeatms":null,"pt":1780839896898,"initialclk":null,"mc":[{"rc":[{"tv":2103076.3700000001,"batb":null,"spb":null,"bdatl":null,"trd":[[1.1299999999999999,243953.88000000001]],"spf":null,"ltp":null,"atb":null,"spl":null,"spn":null,"atl":[[1.1299999999999999,27513.029999999999]],"batl":null,"id":19924823,"hc":null,"bdatb":null}],"img":null,"tv":2350751.4100000001,"con":null,"marketdefinition":null,"id":"1.258926623"}],"conflatems":null,"op":"mcm","id":3}
{"ct":null,"SegmentType":null,"clk":"AJmCAgD8gQIA\u002BesB","heartbeatms":null,"pt":1780839897311,"initialclk":null,"mc":[{"rc":[{"tv":2103078.6499999999,"batb":null,"spb":null,"bdatl":null,"trd":[[1.1200000000000001,62488.470000000001]],"spf":null,"ltp":1.1200000000000001,"atb":[[1.1200000000000001,28022.709999999999]],"spl":null,"spn":null,"atl":null,"batl":null,"id":19924823,"hc":null,"bdatb":null}],"img":null,"tv":2350753.6899999999,"con":null,"marketdefinition":null,"id":"1.258926623"}],"conflatems":null,"op":"mcm","id":3}
{"ct":null,"SegmentType":null,"clk":"AMGCAgCzggIAoewB","heartbeatms":null,"pt":1780839897721,"initialclk":null,"mc":[{"rc":[{"tv":2103081.3599999999,"batb":null,"spb":null,"bdatl":null,"trd":[[1.1299999999999999,243956.59]],"spf":null,"ltp":1.1299999999999999,"atb":null,"spl":null,"spn":null,"atl":[[1.1299999999999999,27511.669999999998],[1.21,8960.3500000000004]],"batl":null,"id":19924823,"hc":null,"bdatb":null}],"img":null,"tv":2350756.3999999999,"con":null,"marketdefinition":null,"id":"1.258926623"}],"conflatems":null,"op":"mcm","id":3}
{"ct":null,"SegmentType":null,"clk":"AM\u002BCAgDIggIAt\u002BwB","heartbeatms":null,"pt":1780839897922,"initialclk":null,"mc":[{"rc":[{"tv":2104334.8999999999,"batb":null,"spb":null,"bdatl":null,"trd":[[1.1200000000000001,63742.010000000002]],"spf":null,"ltp":1.1200000000000001,"atb":[[1.1200000000000001,27395.939999999999]],"spl":null,"spn":null,"atl":null,"batl":null,"id":19924823,"hc":null,"bdatb":null}],"img":null,"tv":2352009.9399999999,"con":null,"marketdefinition":null,"id":"1.258926623"}],"conflatems":null,"op":"mcm","id":3}
{"ct":null,"SegmentType":null,"clk":"ANmCAgDQggIAv\u002BwB","heartbeatms":null,"pt":1780839898025,"initialclk":null,"mc":[{"rc":[{"tv":null,"batb":null,"spb":null,"bdatl":null,"trd":null,"spf":null,"ltp":null,"atb":[[8,300.87]],"spl":null,"spn":null,"atl":null,"batl":null,"id":16570658,"hc":null,"bdatb":null},{"tv":null,"batb":null,"spb":null,"bdatl":null,"trd":null,"spf":null,"ltp":null,"atb":null,"spl":null,"spn":null,"atl":[[1.1399999999999999,24844.98]],"batl":null,"id":19924823,"hc":null,"bdatb":null}],"img":null,"tv":null,"con":null,"marketdefinition":null,"id":"1.258926623"}],"conflatems":null,"op":"mcm","id":3}
{"ct":null,"SegmentType":null,"clk":"AOGCAgDbggIAxuwB","heartbeatms":null,"pt":1780839898128,"initialclk":null,"mc":[{"rc":[{"tv":null,"batb":null,"spb":null,"bdatl":null,"trd":null,"spf":null,"ltp":null,"atb":[[8.4000000000000004,340.49000000000001],[8.1999999999999993,299.91000000000003]],"spl":null,"spn":null,"atl":null,"batl":null,"id":16570658,"hc":null,"bdatb":null}],"img":null,"tv":null,"con":null,"marketdefinition":null,"id":"1.258926623"}],"conflatems":null,"op":"mcm","id":3}
{"ct":null,"SegmentType":null,"clk":"AOuCAgDmggIA0uwB","heartbeatms":null,"pt":1780839898186,"initialclk":null,"mc":[{"rc":[{"tv":null,"batb":null,"spb":null,"bdatl":null,"trd":null,"spf":null,"ltp":null,"atb":[[8.4000000000000004,248.49000000000001],[7.7999999999999998,0],[7.4000000000000004,301.63],[7.2000000000000002,858.74000000000001]],"spl":null,"spn":null,"atl":[[11,242.44],[10.5,302.77999999999997],[9.5999999999999996,268.68000000000001]],"batl":null,"id":16570658,"hc":null,"bdatb":null},{"tv":null,"batb":null,"spb":null,"bdatl":null,"trd":null,"spf":null,"ltp":null,"atb":[[1.1000000000000001,66571.809999999998],[1.1100000000000001,74950.520000000004]],"spl":null,"spn":null,"atl":[[1.1299999999999999,9793.7800000000007],[1.1399999999999999,22896.98],[1.1499999999999999,28313.639999999999]],"batl":null,"id":19924823,"hc":null,"bdatb":null}],"img":null,"tv":null,"con":null,"marketdefinition":null,"id":"1.258926623"}],"conflatems":null,"op":"mcm","id":3}
{"ct":null,"SegmentType":null,"clk":"APmCAgDvggIA3ewB","heartbeatms":null,"pt":1780839898294,"initialclk":null,"mc":[{"rc":[{"tv":null,"batb":null,"spb":null,"bdatl":null,"trd":null,"spf":null,"ltp":null,"atb":[[8.1999999999999993,280.47000000000003]],"spl":null,"spn":null,"atl":null,"batl":null,"id":16570658,"hc":null,"bdatb":null}],"img":null,"tv":null,"con":null,"marketdefinition":null,"id":"1.258926623"}],"conflatems":null,"op":"mcm","id":3}
{"ct":null,"SegmentType":null,"clk":"AIyDAgCFgwIA8OwB","heartbeatms":null,"pt":1780839898498,"initialclk":null,"mc":[{"rc":[{"tv":null,"batb":null,"spb":null,"bdatl":null,"trd":null,"spf":null,"ltp":null,"atb":[[8.4000000000000004,70.370000000000005],[6.5999999999999996,0],[8.8000000000000007,0],[6.7999999999999998,24.52],[8.1999999999999993,0],[8.5999999999999996,24.52],[7.2000000000000002,122.28],[8,36.960000000000001]],"spl":null,"spn":null,"atl":[[9.8000000000000007,0],[9.1999999999999993,10],[9,0],[9.5999999999999996,20]],"batl":null,"id":16570658,"hc":null,"bdatb":null},{"tv":null,"batb":null,"spb":null,"bdatl":null,"trd":null,"spf":null,"ltp":null,"atb":[[1.1200000000000001,26265.59]],"spl":null,"spn":null,"atl":[[1.1299999999999999,8673.4400000000005]],"batl":null,"id":19924823,"hc":null,"bdatb":null}],"img":null,"tv":null,"con":null,"marketdefinition":null,"id":"1.258926623"}],"conflatems":null,"op":"mcm","id":3}
{"ct":null,"SegmentType":null,"clk":"AJaDAgCSgwIA\u002BewB","heartbeatms":null,"pt":1780839898600,"initialclk":null,"mc":[{"rc":[{"tv":null,"batb":null,"spb":null,"bdatl":null,"trd":null,"spf":null,"ltp":null,"atb":[[8,16.960000000000001]],"spl":null,"spn":null,"atl":null,"batl":null,"id":16570658,"hc":null,"bdatb":null}],"img":null,"tv":null,"con":null,"marketdefinition":null,"id":"1.258926623"}],"conflatems":null,"op":"mcm","id":3}
{"ct":null,"SegmentType":null,"clk":"AKKDAgChgwIAg\u002B0B","heartbeatms":null,"pt":1780839898706,"initialclk":null,"mc":[{"rc":[{"tv":null,"batb":null,"spb":null,"bdatl":null,"trd":null,"spf":null,"ltp":null,"atb":null,"spl":null,"spn":null,"atl":[[1.1299999999999999,9918.1499999999996]],"batl":null,"id":19924823,"hc":null,"bdatb":null}],"img":null,"tv":null,"con":null,"marketdefinition":null,"id":"1.258926623"}],"conflatems":null,"op":"mcm","id":3}
{"ct":null,"SegmentType":null,"clk":"ALGDAgC2gwIAk\u002B0B","heartbeatms":null,"pt":1780839898905,"initialclk":null,"mc":[{"rc":[{"tv":null,"batb":null,"spb":null,"bdatl":null,"trd":null,"spf":null,"ltp":null,"atb":[[1.1100000000000001,76024.919999999998]],"spl":null,"spn":null,"atl":[[1.1599999999999999,10513.530000000001],[1.1499999999999999,29571.580000000002]],"batl":null,"id":19924823,"hc":null,"bdatb":null}],"img":null,"tv":null,"con":null,"marketdefinition":null,"id":"1.258926623"}],"conflatems":null,"op":"mcm","id":3}
{"ct":null,"SegmentType":null,"clk":"ALiDAgC\u002BgwIAn\u002B0B","heartbeatms":null,"pt":1780839899016,"initialclk":null,"mc":[{"rc":[{"tv":null,"batb":null,"spb":null,"bdatl":null,"trd":null,"spf":null,"ltp":null,"atb":[[1.1200000000000001,25137.869999999999]],"spl":null,"spn":null,"atl":[[1.1399999999999999,20915.369999999999]],"batl":null,"id":19924823,"hc":null,"bdatb":null}],"img":null,"tv":null,"con":null,"marketdefinition":null,"id":"1.258926623"}],"conflatems":null,"op":"mcm","id":3}
{"ct":null,"SegmentType":null,"clk":"AMSDAgDLgwIAq\u002B0B","heartbeatms":null,"pt":1780839899119,"initialclk":null,"mc":[{"rc":[{"tv":2104336.52,"batb":null,"spb":null,"bdatl":null,"trd":[[1.1299999999999999,243958.20999999999]],"spf":null,"ltp":1.1299999999999999,"atb":null,"spl":null,"spn":null,"atl":[[1.1299999999999999,9917.3400000000001]],"batl":null,"id":19924823,"hc":null,"bdatb":null}],"img":null,"tv":2352011.5600000001,"con":null,"marketdefinition":null,"id":"1.258926623"}],"conflatems":null,"op":"mcm","id":3}
{"ct":null,"SegmentType":null,"clk":"ANeDAgDigwIAvO0B","heartbeatms":null,"pt":1780839899318,"initialclk":null,"mc":[{"rc":[{"tv":null,"batb":null,"spb":null,"bdatl":null,"trd":null,"spf":null,"ltp":null,"atb":null,"spl":null,"spn":null,"atl":[[9.8000000000000007,724.29999999999995]],"batl":null,"id":16570658,"hc":null,"bdatb":null}],"img":null,"tv":null,"con":null,"marketdefinition":null,"id":"1.258926623"}],"conflatems":null,"op":"mcm","id":3}
{"ct":null,"SegmentType":null,"clk":"AN6DAgDvgwIAxu0B","heartbeatms":null,"pt":1780839899423,"initialclk":null,"mc":[{"rc":[{"tv":null,"batb":null,"spb":null,"bdatl":null,"trd":null,"spf":null,"ltp":null,"atb":null,"spl":null,"spn":null,"atl":[[9.8000000000000007,0.85999999999999999]],"batl":null,"id":16570658,"hc":null,"bdatb":null},{"tv":null,"batb":null,"spb":null,"bdatl":null,"trd":null,"spf":null,"ltp":null,"atb":[[1.1100000000000001,76029.449999999997]],"spl":null,"spn":null,"atl":null,"batl":null,"id":19924823,"hc":null,"bdatb":null}],"img":null,"tv":null,"con":null,"marketdefinition":null,"id":"1.258926623"}],"conflatems":null,"op":"mcm","id":3}
{"ct":null,"SegmentType":null,"clk":"AOmDAgD4gwIA0O0B","heartbeatms":null,"pt":1780839899521,"initialclk":null,"mc":[{"rc":[{"tv":null,"batb":null,"spb":null,"bdatl":null,"trd":null,"spf":null,"ltp":null,"atb":[[8.5999999999999996,11.359999999999999]],"spl":null,"spn":null,"atl":null,"batl":null,"id":16570658,"hc":null,"bdatb":null}],"img":null,"tv":null,"con":null,"marketdefinition":null,"id":"1.258926623"}],"conflatems":null,"op":"mcm","id":3}
{"ct":null,"SegmentType":null,"clk":"AIaEAgCYhAIA7O0B","heartbeatms":null,"pt":1780839899784,"initialclk":null,"mc":[{"rc":[{"tv":null,"batb":null,"spb":null,"bdatl":null,"trd":null,"spf":null,"ltp":null,"atb":[[1.1000000000000001,65571.809999999998]],"spl":null,"spn":null,"atl":null,"batl":null,"id":19924823,"hc":null,"bdatb":null}],"img":null,"tv":null,"con":null,"marketdefinition":null,"id":"1.258926623"}],"conflatems":null,"op":"mcm","id":3}
{"ct":null,"SegmentType":null,"clk":"AM\u002BEAgDLhAIArO4B","heartbeatms":null,"pt":1780839900411,"initialclk":null,"mc":[{"rc":[{"tv":null,"batb":null,"spb":null,"bdatl":null,"trd":null,"spf":null,"ltp":null,"atb":[[7.7999999999999998,186.31999999999999]],"spl":null,"spn":null,"atl":null,"batl":null,"id":16570658,"hc":null,"bdatb":null},{"tv":null,"batb":null,"spb":null,"bdatl":null,"trd":null,"spf":null,"ltp":null,"atb":[[1.1100000000000001,77380.800000000003]],"spl":null,"spn":null,"atl":[[1.1499999999999999,30835.330000000002]],"batl":null,"id":19924823,"hc":null,"bdatb":null}],"img":null,"tv":null,"con":null,"marketdefinition":null,"id":"1.258926623"}],"conflatems":null,"op":"mcm","id":3}
{"ct":null,"SegmentType":null,"clk":"AOeEAgDnhAIAve4B","heartbeatms":null,"pt":1780839900620,"initialclk":null,"mc":[{"rc":[{"tv":null,"batb":null,"spb":null,"bdatl":null,"trd":null,"spf":null,"ltp":null,"atb":[[1.1100000000000001,71157.25]],"spl":null,"spn":null,"atl":null,"batl":null,"id":19924823,"hc":null,"bdatb":null}],"img":null,"tv":null,"con":null,"marketdefinition":null,"id":"1.258926623"}],"conflatems":null,"op":"mcm","id":3}
{"ct":null,"SegmentType":null,"clk":"AIOFAgD8hAIA1\u002B4B","heartbeatms":null,"pt":1780839900818,"initialclk":null,"mc":[{"rc":[{"tv":null,"batb":null,"spb":null,"bdatl":null,"trd":null,"spf":null,"ltp":null,"atb":null,"spl":null,"spn":null,"atl":[[1.1299999999999999,1444.1700000000001]],"batl":null,"id":19924823,"hc":null,"bdatb":null}],"img":null,"tv":null,"con":null,"marketdefinition":null,"id":"1.258926623"}],"conflatems":null,"op":"mcm","id":3}
{"ct":null,"SegmentType":null,"clk":"AKWFAgCbhQIA8e4B","heartbeatms":null,"pt":1780839901031,"initialclk":null,"mc":[{"rc":[{"tv":null,"batb":null,"spb":null,"bdatl":null,"trd":null,"spf":null,"ltp":null,"atb":null,"spl":null,"spn":null,"atl":[[17,0]],"batl":null,"id":16570658,"hc":null,"bdatb":null}],"img":null,"tv":null,"con":null,"marketdefinition":null,"id":"1.258926623"}],"conflatems":null,"op":"mcm","id":3}
{"ct":null,"SegmentType":null,"clk":"ALeFAgC3hQIAgu8B","heartbeatms":null,"pt":1780839901235,"initialclk":null,"mc":[{"rc":[{"tv":null,"batb":null,"spb":null,"bdatl":null,"trd":null,"spf":null,"ltp":null,"atb":[[1.1100000000000001,69547.889999999999]],"spl":null,"spn":null,"atl":[[1.1599999999999999,9813.1800000000003],[1.1499999999999999,30036.529999999999]],"batl":null,"id":19924823,"hc":null,"bdatb":null}],"img":null,"tv":null,"con":null,"marketdefinition":null,"id":"1.258926623"}],"conflatems":null,"op":"mcm","id":3}
{"ct":null,"SegmentType":null,"clk":"AOCFAgDhhQIAre8B","heartbeatms":null,"pt":1780839901604,"initialclk":null,"mc":[{"rc":[{"tv":null,"batb":null,"spb":null,"bdatl":null,"trd":null,"spf":null,"ltp":null,"atb":null,"spl":null,"spn":null,"atl":[[15,100]],"batl":null,"id":16570658,"hc":null,"bdatb":null}],"img":null,"tv":null,"con":null,"marketdefinition":null,"id":"1.258926623"}],"conflatems":null,"op":"mcm","id":3}
{"ct":null,"SegmentType":null,"clk":"AKWGAgCkhgIA6u8B","heartbeatms":null,"pt":1780839902226,"initialclk":null,"mc":[{"rc":[{"tv":2104348.1200000001,"batb":null,"spb":null,"bdatl":null,"trd":[[1.1299999999999999,243969.81]],"spf":null,"ltp":null,"atb":null,"spl":null,"spn":null,"atl":[[1.1299999999999999,1438.3699999999999]],"batl":null,"id":19924823,"hc":null,"bdatb":null}],"img":null,"tv":2352023.1600000001,"con":null,"marketdefinition":null,"id":"1.258926623"}],"conflatems":null,"op":"mcm","id":3}
{"ct":null,"SegmentType":null,"clk":"AL6GAgDMhgIAhPAB","heartbeatms":null,"pt":1780839902526,"initialclk":null,"mc":[{"rc":[{"tv":null,"batb":null,"spb":null,"bdatl":null,"trd":null,"spf":null,"ltp":null,"atb":[[7.7999999999999998,0]],"spl":null,"spn":null,"atl":null,"batl":null,"id":16570658,"hc":null,"bdatb":null},{"tv":null,"batb":null,"spb":null,"bdatl":null,"trd":null,"spf":null,"ltp":null,"atb":null,"spl":null,"spn":null,"atl":[[1000,0.98999999999999999]],"batl":null,"id":19924823,"hc":null,"bdatb":null}],"img":null,"tv":null,"con":null,"marketdefinition":null,"id":"1.258926623"}],"conflatems":null,"op":"mcm","id":3}
{"ct":null,"SegmentType":null,"clk":"AN\u002BGAgDrhgIAnfAB","heartbeatms":null,"pt":1780839902794,"initialclk":null,"mc":[{"rc":[{"tv":2104351.02,"batb":null,"spb":null,"bdatl":null,"trd":[[1.1299999999999999,243972.70999999999]],"spf":null,"ltp":null,"atb":null,"spl":null,"spn":null,"atl":[[1.1299999999999999,1436.9200000000001]],"batl":null,"id":19924823,"hc":null,"bdatb":null}],"img":null,"tv":2352026.0600000001,"con":null,"marketdefinition":null,"id":"1.258926623"}],"conflatems":null,"op":"mcm","id":3}
{"ct":null,"SegmentType":null,"clk":"APeGAgCChwIAtPAB","heartbeatms":null,"pt":1780839902998,"initialclk":null,"mc":[{"rc":[{"tv":null,"batb":null,"spb":null,"bdatl":null,"trd":null,"spf":null,"ltp":null,"atb":null,"spl":null,"spn":null,"atl":[[1000,0.88]],"batl":null,"id":19924823,"hc":null,"bdatb":null}],"img":null,"tv":null,"con":null,"marketdefinition":null,"id":"1.258926623"}],"conflatems":null,"op":"mcm","id":3}
{"ct":null,"SegmentType":null,"clk":"AKqHAgCkhwIA3vAB","heartbeatms":null,"pt":1780839903412,"initialclk":null,"mc":[{"rc":[{"tv":null,"batb":null,"spb":null,"bdatl":null,"trd":null,"spf":null,"ltp":null,"atb":[[8.5999999999999996,159.58000000000001]],"spl":null,"spn":null,"atl":[[9,141.63999999999999]],"batl":null,"id":16570658,"hc":null,"bdatb":null},{"tv":null,"batb":null,"spb":null,"bdatl":null,"trd":null,"spf":null,"ltp":null,"atb":[[1.1200000000000001,26276.02]],"spl":null,"spn":null,"atl":[[1.1399999999999999,22033.560000000001]],"batl":null,"id":19924823,"hc":null,"bdatb":null}],"img":null,"tv":null,"con":null,"marketdefinition":null,"id":"1.258926623"}],"conflatems":null,"op":"mcm","id":3}
{"ct":null,"SegmentType":null,"clk":"ALWHAgCvhwIA5vAB","heartbeatms":null,"pt":1780839903511,"initialclk":null,"mc":[{"rc":[{"tv":2104352.8599999999,"batb":null,"spb":null,"bdatl":null,"trd":[[1.1299999999999999,243974.54999999999]],"spf":null,"ltp":null,"atb":null,"spl":null,"spn":null,"atl":[[1.1299999999999999,1436]],"batl":null,"id":19924823,"hc":null,"bdatb":null}],"img":null,"tv":2352027.8999999999,"con":null,"marketdefinition":null,"id":"1.258926623"}],"conflatems":null,"op":"mcm","id":3}
{"ct":null,"SegmentType":null,"clk":"AMOHAgC9hwIA7fAB","heartbeatms":null,"pt":1780839903622,"initialclk":null,"mc":[{"rc":[{"tv":2107224.8599999999,"batb":null,"spb":null,"bdatl":null,"trd":[[1.1299999999999999,246846.54999999999]],"spf":null,"ltp":null,"atb":[[1.1299999999999999,13232.190000000001]],"spl":null,"spn":null,"atl":[[1.1299999999999999,0]],"batl":null,"id":19924823,"hc":null,"bdatb":null}],"img":null,"tv":2354899.8999999999,"con":null,"marketdefinition":null,"id":"1.258926623"}],"conflatems":null,"op":"mcm","id":3}
{"ct":null,"SegmentType":null,"clk":"AMyHAgDEhwIA9fAB","heartbeatms":null,"pt":1780839903722,"initialclk":null,"mc":[{"rc":[{"tv":null,"batb":null,"spb":null,"bdatl":null,"trd":null,"spf":null,"ltp":null,"atb":[[8.4000000000000004,223.22999999999999]],"spl":null,"spn":null,"atl":null,"batl":null,"id":16570658,"hc":null,"bdatb":null},{"tv":null,"batb":null,"spb":null,"bdatl":null,"trd":null,"spf":null,"ltp":null,"atb":[[1.1299999999999999,14368.469999999999]],"spl":null,"spn":null,"atl":null,"batl":null,"id":19924823,"hc":null,"bdatb":null}],"img":null,"tv":null,"con":null,"marketdefinition":null,"id":"1.258926623"}],"conflatems":null,"op":"mcm","id":3}
{"ct":null,"SegmentType":null,"clk":"ANuHAgDShwIA//AB","heartbeatms":null,"pt":1780839903830,"initialclk":null,"mc":[{"rc":[{"tv":null,"batb":null,"spb":null,"bdatl":null,"trd":null,"spf":null,"ltp":null,"atb":[[8.5999999999999996,11.359999999999999]],"spl":null,"spn":null,"atl":null,"batl":null,"id":16570658,"hc":null,"bdatb":null},{"tv":null,"batb":null,"spb":null,"bdatl":null,"trd":null,"spf":null,"ltp":null,"atb":null,"spl":null,"spn":null,"atl":[[1.1499999999999999,28772.779999999999]],"batl":null,"id":19924823,"hc":null,"bdatb":null}],"img":null,"tv":null,"con":null,"marketdefinition":null,"id":"1.258926623"}],"conflatems":null,"op":"mcm","id":3}
{"ct":null,"SegmentType":null,"clk":"AOmHAgDbhwIAhfEB","heartbeatms":null,"pt":1780839903923,"initialclk":null,"mc":[{"rc":[{"tv":null,"batb":null,"spb":null,"bdatl":null,"trd":null,"spf":null,"ltp":null,"atb":[[1.1299999999999999,14404.66]],"spl":null,"spn":null,"atl":null,"batl":null,"id":19924823,"hc":null,"bdatb":null}],"img":null,"tv":null,"con":null,"marketdefinition":null,"id":"1.258926623"}],"conflatems":null,"op":"mcm","id":3}
{"ct":null,"SegmentType":null,"clk":"APSHAgDshwIAkfEB","heartbeatms":null,"pt":1780839904034,"initialclk":null,"mc":[{"rc":[{"tv":null,"batb":null,"spb":null,"bdatl":null,"trd":null,"spf":null,"ltp":null,"atb":[[1.1200000000000001,27933.93]],"spl":null,"spn":null,"atl":[[1.1399999999999999,23551.990000000002]],"batl":null,"id":19924823,"hc":null,"bdatb":null}],"img":null,"tv":null,"con":null,"marketdefinition":null,"id":"1.258926623"}],"conflatems":null,"op":"mcm","id":3}
{"ct":null,"SegmentType":null,"clk":"AKmIAgCYiAIAv/EB","heartbeatms":null,"pt":1780839904410,"initialclk":null,"mc":[{"rc":[{"tv":null,"batb":null,"spb":null,"bdatl":null,"trd":null,"spf":null,"ltp":null,"atb":[[8.1999999999999993,99]],"spl":null,"spn":null,"atl":[[10.5,418.77999999999997]],"batl":null,"id":16570658,"hc":null,"bdatb":null},{"tv":null,"batb":null,"spb":null,"bdatl":null,"trd":null,"spf":null,"ltp":null,"atb":[[1.1000000000000001,67742.809999999998]],"spl":null,"spn":null,"atl":[[1.1399999999999999,25357.990000000002]],"batl":null,"id":19924823,"hc":null,"bdatb":null}],"img":null,"tv":null,"con":null,"marketdefinition":null,"id":"1.258926623"}],"conflatems":null,"op":"mcm","id":3}
{"ct":null,"SegmentType":null,"clk":"ALyIAgCkiAIAyPEB","heartbeatms":null,"pt":1780839904516,"initialclk":null,"mc":[{"rc":[{"tv":null,"batb":null,"spb":null,"bdatl":null,"trd":null,"spf":null,"ltp":null,"atb":[[1.1100000000000001,68196.539999999994]],"spl":null,"spn":null,"atl":null,"batl":null,"id":19924823,"hc":null,"bdatb":null}],"img":null,"tv":null,"con":null,"marketdefinition":null,"id":"1.258926623"}],"conflatems":null,"op":"mcm","id":3}
{"ct":null,"SegmentType":null,"clk":"AIuKAgC/iQIA3fIB","heartbeatms":null,"pt":1780839906023,"initialclk":null,"mc":[{"rc":[{"tv":null,"batb":null,"spb":null,"bdatl":null,"trd":null,"spf":null,"ltp":null,"atb":[[1.1000000000000001,67748.610000000001]],"spl":null,"spn":null,"atl":null,"batl":null,"id":19924823,"hc":null,"bdatb":null}],"img":null,"tv":null,"con":null,"marketdefinition":null,"id":"1.258926623"}],"conflatems":null,"op":"mcm","id":3}
{"ct":null,"SegmentType":null,"clk":"AJuKAgDLiQIA6fIB","heartbeatms":null,"pt":1780839906121,"initialclk":null,"mc":[{"rc":[{"tv":2107225.0699999998,"batb":null,"spb":null,"bdatl":null,"trd":[[1.1299999999999999,246846.76000000001]],"spf":null,"ltp":null,"atb":[[1.1299999999999999,14404.56]],"spl":null,"spn":null,"atl":null,"batl":null,"id":19924823,"hc":null,"bdatb":null}],"img":null,"tv":2354900.1099999999,"con":null,"marketdefinition":null,"id":"1.258926623"}],"conflatems":null,"op":"mcm","id":3}
{"ct":null,"SegmentType":null,"clk":"AN6LAgCUiwIAnvQB","heartbeatms":null,"pt":1780839908131,"initialclk":null,"mc":[{"rc":[{"tv":null,"batb":null,"spb":null,"bdatl":null,"trd":null,"spf":null,"ltp":null,"atb":null,"spl":null,"spn":null,"atl":[[1.1399999999999999,37013.660000000003]],"batl":null,"id":19924823,"hc":null,"bdatb":null}],"img":null,"tv":null,"con":null,"marketdefinition":null,"id":"1.258926623"}],"conflatems":null,"op":"mcm","id":3}
{"ct":null,"SegmentType":null,"clk":"AICMAgC6iwIAxvQB","heartbeatms":null,"pt":1780839908493,"initialclk":null,"mc":[{"rc":[{"tv":null,"batb":null,"spb":null,"bdatl":null,"trd":null,"spf":null,"ltp":null,"atb":[[7.4000000000000004,494.43000000000001]],"spl":null,"spn":null,"atl":null,"batl":null,"id":16570658,"hc":null,"bdatb":null},{"tv":null,"batb":null,"spb":null,"bdatl":null,"trd":null,"spf":null,"ltp":null,"atb":[[1.1200000000000001,29273.209999999999]],"spl":null,"spn":null,"atl":[[1.1599999999999999,11043.120000000001]],"batl":null,"id":19924823,"hc":null,"bdatb":null}],"img":null,"tv":null,"con":null,"marketdefinition":null,"id":"1.258926623"}],"conflatems":null,"op":"mcm","id":3}
{"ct":null,"SegmentType":null,"clk":"ALmMAgCCjAIA9fQB","heartbeatms":null,"pt":1780839909113,"initialclk":null,"mc":[{"rc":[{"tv":247697.76000000001,"batb":null,"spb":null,"bdatl":null,"trd":[[8.5999999999999996,2730.1500000000001]],"spf":null,"ltp":8.5999999999999996,"atb":[[8.5999999999999996,0]],"spl":null,"spn":null,"atl":[[8.5999999999999996,144.90000000000001]],"batl":null,"id":16570658,"hc":null,"bdatb":null}],"img":null,"tv":2354922.8300000001,"con":null,"marketdefinition":null,"id":"1.258926623"}],"conflatems":null,"op":"mcm","id":3}
{"ct":null,"SegmentType":null,"clk":"AOSMAgCxjAIAmfUB","heartbeatms":null,"pt":1780839909533,"initialclk":null,"mc":[{"rc":[{"tv":null,"batb":null,"spb":null,"bdatl":null,"trd":null,"spf":null,"ltp":null,"atb":[[1.0600000000000001,63327.690000000002]],"spl":null,"spn":null,"atl":null,"batl":null,"id":19924823,"hc":null,"bdatb":null}],"img":null,"tv":null,"con":null,"marketdefinition":null,"id":"1.258926623"}],"conflatems":null,"op":"mcm","id":3}
{"ct":null,"SegmentType":null,"clk":"AO6MAgC8jAIAoPUB","heartbeatms":null,"pt":1780839909627,"initialclk":null,"mc":[{"rc":[{"tv":null,"batb":null,"spb":null,"bdatl":null,"trd":null,"spf":null,"ltp":null,"atb":null,"spl":null,"spn":null,"atl":[[9,308.30000000000001]],"batl":null,"id":16570658,"hc":null,"bdatb":null}],"img":null,"tv":null,"con":null,"marketdefinition":null,"id":"1.258926623"}],"conflatems":null,"op":"mcm","id":3}
{"ct":null,"SegmentType":null,"clk":"AI\u002BNAgDmjAIAuvUB","heartbeatms":null,"pt":1780839909895,"initialclk":null,"mc":[{"rc":[{"tv":null,"batb":null,"spb":null,"bdatl":null,"trd":null,"spf":null,"ltp":null,"atb":null,"spl":null,"spn":null,"atl":[[15,0],[8.8000000000000007,139]],"batl":null,"id":16570658,"hc":null,"bdatb":null}],"img":null,"tv":null,"con":null,"marketdefinition":null,"id":"1.258926623"}],"conflatems":null,"op":"mcm","id":3}
{"ct":null,"SegmentType":null,"clk":"AKeNAgD7jAIAxfUB","heartbeatms":null,"pt":1780839910099,"initialclk":null,"mc":[{"rc":[{"tv":2107245.0699999998,"batb":null,"spb":null,"bdatl":null,"trd":[[1.1299999999999999,246866.76000000001]],"spf":null,"ltp":null,"atb":[[1.1299999999999999,14394.56]],"spl":null,"spn":null,"atl":null,"batl":null,"id":19924823,"hc":null,"bdatb":null}],"img":null,"tv":2354942.8300000001,"con":null,"marketdefinition":null,"id":"1.258926623"}],"conflatems":null,"op":"mcm","id":3}
{"ct":null,"SegmentType":null,"clk":"AMKNAgCXjQIA1/UB","heartbeatms":null,"pt":1780839910312,"initialclk":null,"mc":[{"rc":[{"tv":null,"batb":null,"spb":null,"bdatl":null,"trd":null,"spf":null,"ltp":null,"atb":[[1.1100000000000001,67124.119999999995],[1.1200000000000001,27615.299999999999]],"spl":null,"spn":null,"atl":[[1.1399999999999999,35495.230000000003],[1.1499999999999999,27628.240000000002]],"batl":null,"id":19924823,"hc":null,"bdatb":null}],"img":null,"tv":null,"con":null,"marketdefinition":null,"id":"1.258926623"}],"conflatems":null,"op":"mcm","id":3}
{"ct":null,"SegmentType":null,"clk":"AN2NAgC3jQIA7fUB","heartbeatms":null,"pt":1780839910619,"initialclk":null,"mc":[{"rc":[{"tv":null,"batb":null,"spb":null,"bdatl":null,"trd":null,"spf":null,"ltp":null,"atb":null,"spl":null,"spn":null,"atl":[[1.1399999999999999,23839.560000000001]],"batl":null,"id":19924823,"hc":null,"bdatb":null}],"img":null,"tv":null,"con":null,"marketdefinition":null,"id":"1.258926623"}],"conflatems":null,"op":"mcm","id":3}
{"ct":null,"SegmentType":null,"clk":"AP2NAgDVjQIAgvYB","heartbeatms":null,"pt":1780839910933,"initialclk":null,"mc":[{"rc":[{"tv":null,"batb":null,"spb":null,"bdatl":null,"trd":null,"spf":null,"ltp":null,"atb":null,"spl":null,"spn":null,"atl":[[1.1399999999999999,24839.560000000001]],"batl":null,"id":19924823,"hc":null,"bdatb":null}],"img":null,"tv":null,"con":null,"marketdefinition":null,"id":"1.258926623"}],"conflatems":null,"op":"mcm","id":3}
{"ct":null,"SegmentType":null,"clk":"AJGOAgDnjQIAj/YB","heartbeatms":null,"pt":1780839911133,"initialclk":null,"mc":[{"rc":[{"tv":null,"batb":null,"spb":null,"bdatl":null,"trd":null,"spf":null,"ltp":null,"atb":null,"spl":null,"spn":null,"atl":[[1.1399999999999999,25839.560000000001]],"batl":null,"id":19924823,"hc":null,"bdatb":null}],"img":null,"tv":null,"con":null,"marketdefinition":null,"id":"1.258926623"}],"conflatems":null,"op":"mcm","id":3}
{"ct":null,"SegmentType":null,"clk":"AKWOAgD6jQIAmfYB","heartbeatms":null,"pt":1780839911252,"initialclk":null,"mc":[{"rc":[{"tv":null,"batb":null,"spb":null,"bdatl":null,"trd":null,"spf":null,"ltp":null,"atb":null,"spl":null,"spn":null,"atl":[[1.1399999999999999,26839.560000000001]],"batl":null,"id":19924823,"hc":null,"bdatb":null}],"img":null,"tv":null,"con":null,"marketdefinition":null,"id":"1.258926623"}],"conflatems":null,"op":"mcm","id":3}
{"ct":null,"SegmentType":null,"clk":"ALGOAgCDjgIAnfYB","heartbeatms":null,"pt":1780839911343,"initialclk":null,"mc":[{"rc":[{"tv":null,"batb":null,"spb":null,"bdatl":null,"trd":null,"spf":null,"ltp":null,"atb":null,"spl":null,"spn":null,"atl":[[8.5999999999999996,0]],"batl":null,"id":16570658,"hc":null,"bdatb":null}],"img":null,"tv":null,"con":null,"marketdefinition":null,"id":"1.258926623"}],"conflatems":null,"op":"mcm","id":3}
{"ct":null,"SegmentType":null,"clk":"AMWPAgCUjwIAsvcB","heartbeatms":null,"pt":1780839912712,"initialclk":null,"mc":[{"rc":[{"tv":null,"batb":null,"spb":null,"bdatl":null,"trd":null,"spf":null,"ltp":null,"atb":null,"spl":null,"spn":null,"atl":[[9,141.63999999999999]],"batl":null,"id":16570658,"hc":null,"bdatb":null},{"tv":null,"batb":null,"spb":null,"bdatl":null,"trd":null,"spf":null,"ltp":null,"atb":[[1.1100000000000001,69437.729999999996],[1.1200000000000001,28043.099999999999]],"spl":null,"spn":null,"atl":[[1.1599999999999999,11881.1],[1.1499999999999999,29432.740000000002]],"batl":null,"id":19924823,"hc":null,"bdatb":null}],"img":null,"tv":null,"con":null,"marketdefinition":null,"id":"1.258926623"}],"conflatems":null,"op":"mcm","id":3}
{"ct":null,"SegmentType":null,"clk":"ANePAgctjwIAyfcB","heartbeatms":null,"pt":1780839912923,"initialclk":null,"mc":[{"rc":[{"tv":null,"batb":null,"spb":null,"bdatl":null,"trd":null,"spf":null,"ltp":null,"atb":null,"spl":null,"spn":null,"atl":[[8.8000000000000007,0]],"batl":null,"id":16570658,"hc":null,"bdatb":null},{"tv":null,"batb":null,"spb":null,"bdatl":null,"trd":null,"spf":null,"ltp":null,"atb":[[1.0600000000000001,63327.809999999998]],"spl":null,"spn":null,"atl":null,"batl":null,"id":19924823,"hc":null,"bdatb":null}],"img":null,"tv":null,"con":null,"marketdefinition":null,"id":"1.258926623"}],"conflatems":null,"op":"mcm","id":3}
{"ct":null,"SegmentType":null,"clk":"AOCPAgC6jwIA1fcB","heartbeatms":null,"pt":1780839913028,"initialclk":null,"mc":[{"rc":[{"tv":null,"batb":null,"spb":null,"bdatl":null,"trd":null,"spf":null,"ltp":null,"atb":null,"spl":null,"spn":null,"atl":[[1.1399999999999999,26846.720000000001]],"batl":null,"id":19924823,"hc":null,"bdatb":null}],"img":null,"tv":null,"con":null,"marketdefinition":null,"id":"1.258926623"}],"conflatems":null,"op":"mcm","id":3}
{"ct":null,"SegmentType":null,"clk":"AJSQAgDmjwIA\u002B/cB","heartbeatms":null,"pt":1780839913442,"initialclk":null,"mc":[{"rc":[{"tv":null,"batb":null,"spb":null,"bdatl":null,"trd":null,"spf":null,"ltp":null,"atb":[[1.0700000000000001,38876.290000000001],[1.0600000000000001,63327.690000000002]],"spl":null,"spn":null,"atl":null,"batl":null,"id":19924823,"hc":null,"bdatb":null}],"img":null,"tv":null,"con":null,"marketdefinition":null,"id":"1.258926623"}],"conflatems":null,"op":"mcm","id":3}
{"ct":null,"SegmentType":null,"clk":"AKGQAgDwjwIAh/gB","heartbeatms":null,"pt":1780839913501,"initialclk":null,"mc":[{"rc":[{"tv":null,"batb":null,"spb":null,"bdatl":null,"trd":null,"spf":null,"ltp":null,"atb":[[1.1200000000000001,28073.099999999999]],"spl":null,"spn":null,"atl":null,"batl":null,"id":19924823,"hc":null,"bdatb":null}],"img":null,"tv":null,"con":null,"marketdefinition":null,"id":"1.258926623"}],"conflatems":null,"op":"mcm","id":3}
{"ct":null,"SegmentType":null,"clk":"AMCRAgCYkQIAoPkB","heartbeatms":null,"pt":1780839915204,"initialclk":null,"mc":[{"rc":[{"tv":null,"batb":null,"spb":null,"bdatl":null,"trd":null,"spf":null,"ltp":null,"atb":[[1.1100000000000001,69558.75]],"spl":null,"spn":null,"atl":null,"batl":null,"id":19924823,"hc":null,"bdatb":null}],"img":null,"tv":null,"con":null,"marketdefinition":null,"id":"1.258926623"}],"conflatems":null,"op":"mcm","id":3}
{"ct":null,"SegmentType":null,"clk":"AMeSAgCNkgIAofoB","heartbeatms":null,"pt":1780839916548,"initialclk":null,"mc":[{"rc":[{"tv":null,"batb":null,"spb":null,"bdatl":null,"trd":null,"spf":null,"ltp":null,"atb":[[8.4000000000000004,70.370000000000005],[7.4000000000000004,301.63]],"spl":null,"spn":null,"atl":[[9,0]],"batl":null,"id":16570658,"hc":null,"bdatb":null},{"tv":2107245.3300000001,"batb":null,"spb":null,"bdatl":null,"trd":[[1.1399999999999999,171669.92000000001]],"spf":null,"ltp":1.1399999999999999,"atb":[[1.1299999999999999,13258.280000000001],[1.1200000000000001,25595.669999999998]],"spl":null,"spn":null,"atl":[[1.1399999999999999,25728.400000000001],[1.1599999999999999,10651.16]],"batl":null,"id":19924823,"hc":null,"bdatb":null}],"img":null,"tv":2354943.0899999999,"con":null,"marketdefinition":null,"id":"1.258926623"}],"conflatems":null,"op":"mcm","id":3}
{"ct":null,"SegmentType":null,"clk":"ANGSAgCakgIApvoB","heartbeatms":null,"pt":1780839916643,"initialclk":null,"mc":[{"rc":[{"tv":null,"batb":null,"spb":null,"bdatl":null,"trd":null,"spf":null,"ltp":null,"atb":[[7.5999999999999996,680.94000000000005],[8.1999999999999993,0]],"spl":null,"spn":null,"atl":[[9.8000000000000007,0],[10.5,302.77999999999997]],"batl":null,"id":16570658,"hc":null,"bdatb":null},{"tv":null,"batb":null,"spb":null,"bdatl":null,"trd":null,"spf":null,"ltp":null,"atb":[[1.1000000000000001,65577.610000000001],[1.1100000000000001,69554.220000000001]],"spl":null,"spn":null,"atl":[[1.1399999999999999,23922.400000000001],[1.1499999999999999,29427.560000000001]],"batl":null,"id":19924823,"hc":null,"bdatb":null}],"img":null,"tv":null,"con":null,"marketdefinition":null,"id":"1.258926623"}],"conflatems":null,"op":"mcm","id":3}
{"ct":null,"SegmentType":null,"clk":"AOqSAgCwkgIAxvoB","heartbeatms":null,"pt":1780839916903,"initialclk":null,"mc":[{"rc":[{"tv":2107845.3300000001,"batb":null,"spb":null,"bdatl":null,"trd":[[1.1399999999999999,172269.92000000001]],"spf":null,"ltp":null,"atb":null,"spl":null,"spn":null,"atl":[[1.1399999999999999,23622.400000000001]],"batl":null,"id":19924823,"hc":null,"bdatb":null}],"img":null,"tv":2355543.0899999999,"con":null,"marketdefinition":null,"id":"1.258926623"}],"conflatems":null,"op":"mcm","id":3}
{"ct":null,"SegmentType":null,"clk":"APSSAgC1kgIA0foB","heartbeatms":null,"pt":1780839917008,"initialclk":null,"mc":[{"rc":[{"tv":null,"batb":null,"spb":null,"bdatl":null,"trd":null,"spf":null,"ltp":null,"atb":[[1.0600000000000001,63326.940000000002]],"spl":null,"spn":null,"atl":null,"batl":null,"id":19924823,"hc":null,"bdatb":null}],"img":null,"tv":null,"con":null,"marketdefinition":null,"id":"1.258926623"}],"conflatems":null,"op":"mcm","id":3}
{"ct":null,"SegmentType":null,"clk":"AJSTAgDVkgIA7voB","heartbeatms":null,"pt":1780839917316,"initialclk":null,"mc":[{"rc":[{"tv":2107855.3300000001,"batb":null,"spb":null,"bdatl":null,"trd":[[1.1399999999999999,172279.92000000001]],"spf":null,"ltp":null,"atb":null,"spl":null,"spn":null,"atl":[[1.1399999999999999,23617.400000000001]],"batl":null,"id":19924823,"hc":null,"bdatb":null}],"img":null,"tv":2355553.0899999999,"con":null,"marketdefinition":null,"id":"1.258926623"}],"conflatems":null,"op":"mcm","id":3}
{"ct":null,"SegmentType":null,"clk":"AKqUAgD\u002BkwIA\u002BPsB","heartbeatms":null,"pt":1780839918817,"initialclk":null,"mc":[{"rc":[{"tv":null,"batb":null,"spb":null,"bdatl":null,"trd":null,"spf":null,"ltp":null,"atb":[[1.1299999999999999,13406.81]],"spl":null,"spn":null,"atl":null,"batl":null,"id":19924823,"hc":null,"bdatb":null}],"img":null,"tv":null,"con":null,"marketdefinition":null,"id":"1.258926623"}],"conflatems":null,"op":"mcm","id":3}
{"ct":null,"SegmentType":null,"clk":"APqUAgDKlAIAtPwB","heartbeatms":null,"pt":1780839919641,"initialclk":null,"mc":[{"rc":[{"tv":247838.51000000001,"batb":null,"spb":null,"bdatl":null,"trd":[[8.4000000000000004,2175]],"spf":null,"ltp":8.4000000000000004,"atb":[[8.4000000000000004,0]],"spl":null,"spn":null,"atl":[[8.4000000000000004,74.010000000000005]],"batl":null,"id":16570658,"hc":null,"bdatb":null}],"img":null,"tv":2355693.8399999999,"con":null,"marketdefinition":null,"id":"1.258926623"}],"conflatems":null,"op":"mcm","id":3}
{"ct":null,"SegmentType":null,"clk":"AI2VAgDclAIAwfwB","heartbeatms":null,"pt":1780839919821,"initialclk":null,"mc":[{"rc":[{"tv":248016.19,"batb":null,"spb":null,"bdatl":null,"trd":[[8.4000000000000004,2323.04],[8.8000000000000007,1621.6400000000001]],"spf":null,"ltp":8.8000000000000007,"atb":null,"spl":null,"spn":null,"atl":[[8.4000000000000004,0]],"batl":null,"id":16570658,"hc":null,"bdatb":null},{"tv":2108086.1299999999,"batb":null,"spb":null,"bdatl":null,"trd":[[1.1299999999999999,247097.56]],"spf":null,"ltp":1.1299999999999999,"atb":[[1.1299999999999999,13176.02],[1.1200000000000001,25625.669999999998]],"spl":null,"spn":null,"atl":null,"batl":null,"id":19924823,"hc":null,"bdatb":null}],"img":null,"tv":2356102.3199999998,"con":null,"marketdefinition":null,"id":"1.258926623"}],"conflatems":null,"op":"mcm","id":3}
{"ct":null,"SegmentType":null,"clk":"AKaVAgDqlAIAzvwB","heartbeatms":null,"pt":1780839920018,"initialclk":null,"mc":[{"rc":[{"tv":null,"batb":null,"spb":null,"bdatl":null,"trd":null,"spf":null,"ltp":null,"atb":[[8.1999999999999993,0.94999999999999996]],"spl":null,"spn":null,"atl":null,"batl":null,"id":16570658,"hc":null,"bdatb":null}],"img":null,"tv":null,"con":null,"marketdefinition":null,"id":"1.258926623"}],"conflatems":null,"op":"mcm","id":3}
{"ct":null,"SegmentType":null,"clk":"AK2VAgDxlAIA1/wB","heartbeatms":null,"pt":1780839920111,"initialclk":null,"mc":[{"rc":[{"tv":null,"batb":null,"spb":null,"bdatl":null,"trd":null,"spf":null,"ltp":null,"atb":null,"spl":null,"spn":null,"atl":[[8.8000000000000007,60]],"batl":null,"id":16570658,"hc":null,"bdatb":null},{"tv":null,"batb":null,"spb":null,"bdatl":null,"trd":null,"spf":null,"ltp":null,"atb":[[1.1299999999999999,487.60000000000002]],"spl":null,"spn":null,"atl":null,"batl":null,"id":19924823,"hc":null,"bdatb":null}],"img":null,"tv":null,"con":null,"marketdefinition":null,"id":"1.258926623"}],"conflatems":null,"op":"mcm","id":3}
{"ct":null,"SegmentType":null,"clk":"ALaVAgD5lAIA3vwB","heartbeatms":null,"pt":1780839920211,"initialclk":null,"mc":[{"rc":[{"tv":null,"batb":null,"spb":null,"bdatl":null,"trd":null,"spf":null,"ltp":null,"atb":[[1.05,74308.929999999993]],"spl":null,"spn":null,"atl":null,"batl":null,"id":19924823,"hc":null,"bdatb":null}],"img":null,"tv":null,"con":null,"marketdefinition":null,"id":"1.258926623"}],"conflatems":null,"op":"mcm","id":3}
{"ct":null,"SegmentType":null,"clk":"AMCVAgCDlQIA6PwB","heartbeatms":null,"pt":1780839920320,"initialclk":null,"mc":[{"rc":[{"tv":2108100.8900000001,"batb":null,"spb":null,"bdatl":null,"trd":[[1.1399999999999999,172294.67999999999]],"spf":null,"ltp":1.1399999999999999,"atb":null,"spl":null,"spn":null,"atl":[[1.1399999999999999,23610.02]],"batl":null,"id":19924823,"hc":null,"bdatb":null}],"img":null,"tv":2356117.0800000001,"con":null,"marketdefinition":null,"id":"1.258926623"}],"conflatems":null,"op":"mcm","id":3}
{"ct":null,"SegmentType":null,"clk":"AN6VAgCilQIAiv0B","heartbeatms":null,"pt":1780839920634,"initialclk":null,"mc":[{"rc":[{"tv":null,"batb":null,"spb":null,"bdatl":null,"trd":null,"spf":null,"ltp":null,"atb":null,"spl":null,"spn":null,"atl":[[13.5,6.5199999999999996]],"batl":null,"id":16570658,"hc":null,"bdatb":null},{"tv":null,"batb":null,"spb":null,"bdatl":null,"trd":null,"spf":null,"ltp":null,"atb":[[1.0800000000000001,39777.050000000003]],"spl":null,"spn":null,"atl":null,"batl":null,"id":19924823,"hc":null,"bdatb":null}],"img":null,"tv":null,"con":null,"marketdefinition":null,"id":"1.258926623"}],"conflatems":null,"op":"mcm","id":3}
{"ct":null,"SegmentType":null,"clk":"AIuWAgDPlQIAwf0B","heartbeatms":null,"pt":1780839921152,"initialclk":null,"mc":[{"rc":[{"tv":null,"batb":null,"spb":null,"bdatl":null,"trd":null,"spf":null,"ltp":null,"atb":null,"spl":null,"spn":null,"atl":[[13.5,26.079999999999998]],"batl":null,"id":16570658,"hc":null,"bdatb":null},{"tv":null,"batb":null,"spb":null,"bdatl":null,"trd":null,"spf":null,"ltp":null,"atb":[[1.0800000000000001,40021.489999999998]],"spl":null,"spn":null,"atl":null,"batl":null,"id":19924823,"hc":null,"bdatb":null}],"img":null,"tv":null,"con":null,"marketdefinition":null,"id":"1.258926623"}],"conflatems":null,"op":"mcm","id":3}
{"ct":null,"SegmentType":null,"clk":"AJaWAgDclQIAzf0B","heartbeatms":null,"pt":1780839921207,"initialclk":null,"mc":[{"rc":[{"tv":null,"batb":null,"spb":null,"bdatl":null,"trd":null,"spf":null,"ltp":null,"atb":null,"spl":null,"spn":null,"atl":[[13.5,39.119999999999997]],"batl":null,"id":16570658,"hc":null,"bdatb":null},{"tv":null,"batb":null,"spb":null,"bdatl":null,"trd":null,"spf":null,"ltp":null,"atb":[[1.0800000000000001,40184.449999999997]],"spl":null,"spn":null,"atl":null,"batl":null,"id":19924823,"hc":null,"bdatb":null}],"img":null,"tv":null,"con":null,"marketdefinition":null,"id":"1.258926623"}],"conflatems":null,"op":"mcm","id":3}
{"ct":null,"SegmentType":null,"clk":"AJ\u002BWAgDolQIA1f0B","heartbeatms":null,"pt":1780839921305,"initialclk":null,"mc":[{"rc":[{"tv":null,"batb":null,"spb":null,"bdatl":null,"trd":null,"spf":null,"ltp":null,"atb":null,"spl":null,"spn":null,"atl":[[13.5,58.68]],"batl":null,"id":16570658,"hc":null,"bdatb":null},{"tv":null,"batb":null,"spb":null,"bdatl":null,"trd":null,"spf":null,"ltp":null,"atb":[[1.0800000000000001,40428.889999999999]],"spl":null,"spn":null,"atl":null,"batl":null,"id":19924823,"hc":null,"bdatb":null}],"img":null,"tv":null,"con":null,"marketdefinition":null,"id":"1.258926623"}],"conflatems":null,"op":"mcm","id":3}
{"ct":null,"SegmentType":null,"clk":"AKmWAgDwlQIA3v0B","heartbeatms":null,"pt":1780839921413,"initialclk":null,"mc":[{"rc":[{"tv":null,"batb":null,"spb":null,"bdatl":null,"trd":null,"spf":null,"ltp":null,"atb":null,"spl":null,"spn":null,"atl":[[13.5,65.200000000000003]],"batl":null,"id":16570658,"hc":null,"bdatb":null},{"tv":null,"batb":null,"spb":null,"bdatl":null,"trd":null,"spf":null,"ltp":null,"atb":[[1.0800000000000001,40510.370000000003],[1.1299999999999999,490.82999999999998]],"spl":null,"spn":null,"atl":null,"batl":null,"id":19924823,"hc":null,"bdatb":null}],"img":null,"tv":null,"con":null,"marketdefinition":null,"id":"1.258926623"}],"conflatems":null,"op":"mcm","id":3}
{"ct":null,"SegmentType":null,"clk":"APuWAgCzlgIAuP4B","heartbeatms":null,"pt":1780839922238,"initialclk":null,"mc":[{"rc":[{"tv":null,"batb":null,"spb":null,"bdatl":null,"trd":null,"spf":null,"ltp":null,"atb":[[8.1999999999999993,100.95]],"spl":null,"spn":null,"atl":null,"batl":null,"id":16570658,"hc":null,"bdatb":null}],"img":null,"tv":null,"con":null,"marketdefinition":null,"id":"1.258926623"}],"conflatems":null,"op":"mcm","id":3}
{"ct":null,"SegmentType":null,"clk":"AI6XAgDKlgIAy/4B","heartbeatms":null,"pt":1780839922442,"initialclk":null,"mc":[{"rc":[{"tv":null,"batb":null,"spb":null,"bdatl":null,"trd":null,"spf":null,"ltp":null,"atb":null,"spl":null,"spn":null,"atl":[[9,1.73]],"batl":null,"id":16570658,"hc":null,"bdatb":null}],"img":null,"tv":null,"con":null,"marketdefinition":null,"id":"1.258926623"}],"conflatems":null,"op":"mcm","id":3}
{"ct":null,"SegmentType":null,"clk":"AMeXAgCRlwIAjf8B","heartbeatms":null,"pt":1780839923020,"initialclk":null,"mc":[{"rc":[{"tv":null,"batb":null,"spb":null,"bdatl":null,"trd":null,"spf":null,"ltp":null,"atb":null,"spl":null,"spn":null,"atl":[[8.5999999999999996,0.94999999999999996]],"batl":null,"id":16570658,"hc":null,"bdatb":null}],"img":null,"tv":null,"con":null,"marketdefinition":null,"id":"1.258926623"}],"conflatems":null,"op":"mcm","id":3}
{"ct":null,"SegmentType":null,"clk":"AP6XAgC8lwIAsf8B","heartbeatms":null,"pt":1780839923427,"initialclk":null,"mc":[{"rc":[{"tv":null,"batb":null,"spb":null,"bdatl":null,"trd":null,"spf":null,"ltp":null,"atb":[[8.1999999999999993,200.94999999999999]],"spl":null,"spn":null,"atl":null,"batl":null,"id":16570658,"hc":null,"bdatb":null}],"img":null,"tv":null,"con":null,"marketdefinition":null,"id":"1.258926623"}],"conflatems":null,"op":"mcm","id":3}
{"ct":null,"SegmentType":null,"clk":"AIyZAgDKmAIA0IAC","heartbeatms":null,"pt":1780839924833,"initialclk":null,"mc":[{"rc":[{"tv":null,"batb":null,"spb":null,"bdatl":null,"trd":null,"spf":null,"ltp":null,"atb":[[8.1999999999999993,0.94999999999999996]],"spl":null,"spn":null,"atl":null,"batl":null,"id":16570658,"hc":null,"bdatb":null}],"img":null,"tv":null,"con":null,"marketdefinition":null,"id":"1.258926623"}],"conflatems":null,"op":"mcm","id":3}
{"ct":null,"SegmentType":null,"clk":"AJOZAgDSmAIA14AC","heartbeatms":null,"pt":1780839924931,"initialclk":null,"mc":[{"rc":[{"tv":null,"batb":null,"spb":null,"bdatl":null,"trd":null,"spf":null,"ltp":null,"atb":[[7.7999999999999998,0.98999999999999999],[8.1999999999999993,14.84],[8,217.81999999999999]],"spl":null,"spn":null,"atl":null,"batl":null,"id":16570658,"hc":null,"bdatb":null},{"tv":null,"batb":null,"spb":null,"bdatl":null,"trd":null,"spf":null,"ltp":null,"atb":[[1.1200000000000001,2205.54]],"spl":null,"spn":null,"atl":[[1.1399999999999999,23615.560000000001],[1.1499999999999999,29432.02]],"batl":null,"id":19924823,"hc":null,"bdatb":null}],"img":null,"tv":null,"con":null,"marketdefinition":null,"id":"1.258926623"}],"conflatems":null,"op":"mcm","id":3}
{"ct":null,"SegmentType":null,"clk":"AJ6ZAgDamAIA4IAC","heartbeatms":null,"pt":1780839925036,"initialclk":null,"mc":[{"rc":[{"tv":null,"batb":null,"spb":null,"bdatl":null,"trd":null,"spf":null,"ltp":null,"atb":[[7,0],[7.2000000000000002,121.42]],"spl":null,"spn":null,"atl":null,"batl":null,"id":16570658,"hc":null,"bdatb":null},{"tv":null,"batb":null,"spb":null,"bdatl":null,"trd":null,"spf":null,"ltp":null,"atb":null,"spl":null,"spn":null,"atl":[[1.1699999999999999,8877.2000000000007],[1.1799999999999999,8873.2000000000007]],"batl":null,"id":19924823,"hc":null,"bdatb":null}],"img":null,"tv":null,"con":null,"marketdefinition":null,"id":"1.258926623"}],"conflatems":null,"op":"mcm","id":3}
{"ct":null,"SegmentType":null,"clk":"AKmZAgDjmAIA8YAC","heartbeatms":null,"pt":1780839925144,"initialclk":null,"mc":[{"rc":[{"tv":null,"batb":null,"spb":null,"bdatl":null,"trd":null,"spf":null,"ltp":null,"atb":[[7.2000000000000002,107.90000000000001],[8,257.24000000000001]],"spl":null,"spn":null,"atl":null,"batl":null,"id":16570658,"hc":null,"bdatb":null},{"tv":null,"batb":null,"spb":null,"bdatl":null,"trd":null,"spf":null,"ltp":null,"atb":[[1.04,73840.729999999996],[1.05,74306.929999999993],[1.0700000000000001,38874.290000000001],[1.0800000000000001,40508.370000000003],[1.1000000000000001,65575.610000000001],[1.0900000000000001,40182.019999999997],[1.0600000000000001,63324.940000000002],[1.02,90733.919999999998],[1.03,88972.589999999997],[1.01,93591.869999999995]],"spl":null,"spn":null,"atl":[[1.1399999999999999,23848.560000000001],[1.1599999999999999,10304.690000000001]],"batl":null,"id":19924823,"hc":null,"bdatb":null}],"img":null,"tv":null,"con":null,"marketdefinition":null,"id":"1.258926623"}],"conflatems":null,"op":"mcm","id":3}
{"ct":null,"SegmentType":null,"clk":"ALOZAgDumAIA/IAC","heartbeatms":null,"pt":1780839925244,"initialclk":null,"mc":[{"rc":[{"tv":null,"batb":null,"spb":null,"bdatl":null,"trd":null,"spf":null,"ltp":null,"atb":[[8,357.24000000000001]],"spl":null,"spn":null,"atl":null,"batl":null,"id":16570658,"hc":null,"bdatb":null},{"tv":null,"batb":null,"spb":null,"bdatl":null,"trd":null,"spf":null,"ltp":null,"atb":[[1.1200000000000001,1971.54]],"spl":null,"spn":null,"atl":null,"batl":null,"id":19924823,"hc":null,"bdatb":null}],"img":null,"tv":null,"con":null,"marketdefinition":null,"id":"1.258926623"}],"conflatems":null,"op":"mcm","id":3}
{"ct":null,"SegmentType":null,"clk":"AMSZAgCAmQIAj4EC","heartbeatms":null,"pt":1780839925447,"initialclk":null,"mc":[{"rc":[{"tv":null,"batb":null,"spb":null,"bdatl":null,"trd":null,"spf":null,"ltp":null,"atb":[[8.1999999999999993,179.22],[8,1026]],"spl":null,"spn":null,"atl":null,"batl":null,"id":16570658,"hc":null,"bdatb":null}],"img":null,"tv":null,"con":null,"marketdefinition":null,"id":"1.258926623"}],"conflatems":null,"op":"mcm","id":3}
{"ct":null,"SegmentType":null,"clk":"AOmZAgCkmQIAsoEC","heartbeatms":null,"pt":1780839925814,"initialclk":null,"mc":[{"rc":[{"tv":null,"batb":null,"spb":null,"bdatl":null,"trd":null,"spf":null,"ltp":null,"atb":[[8.1999999999999993,198.66]],"spl":null,"spn":null,"atl":null,"batl":null,"id":16570658,"hc":null,"bdatb":null}],"img":null,"tv":null,"con":null,"marketdefinition":null,"id":"1.258926623"}],"conflatems":null,"op":"mcm","id":3}
{"ct":null,"SegmentType":null,"clk":"APCZAgCrmQIAvIEC","heartbeatms":null,"pt":1780839925917,"initialclk":null,"mc":[{"rc":[{"tv":null,"batb":null,"spb":null,"bdatl":null,"trd":null,"spf":null,"ltp":null,"atb":[[8.1999999999999993,380.99000000000001]],"spl":null,"spn":null,"atl":[[10.5,445.63]],"batl":null,"id":16570658,"hc":null,"bdatb":null},{"tv":null,"batb":null,"spb":null,"bdatl":null,"trd":null,"spf":null,"ltp":null,"atb":[[1.1000000000000001,66939.240000000005],[1.1100000000000001,67240.610000000001],[1.1200000000000001,1543.74]],"spl":null,"spn":null,"atl":[[1.1399999999999999,25160.080000000002],[1.1599999999999999,9466.7099999999991],[1.1499999999999999,27627.52]],"batl":null,"id":19924823,"hc":null,"bdatb":null}],"img":null,"tv":null,"con":null,"marketdefinition":null,"id":"1.258926623"}],"conflatems":null,"op":"mcm","id":3}
{"ct":null,"SegmentType":null,"clk":"APiZAgC2mQIAyYEC","heartbeatms":null,"pt":1780839926027,"initialclk":null,"mc":[{"rc":[{"tv":null,"batb":null,"spb":null,"bdatl":null,"trd":null,"spf":null,"ltp":null,"atb":null,"spl":null,"spn":null,"atl":[[1.1399999999999999,27659.830000000002],[1.1599999999999999,9459.2099999999991]],"batl":null,"id":19924823,"hc":null,"bdatb":null}],"img":null,"tv":null,"con":null,"marketdefinition":null,"id":"1.258926623"}],"conflatems":null,"op":"mcm","id":3}
{"ct":null,"SegmentType":null,"clk":"AIGaAgDAmQIA0YEC","heartbeatms":null,"pt":1780839926124,"initialclk":null,"mc":[{"rc":[{"tv":null,"batb":null,"spb":null,"bdatl":null,"trd":null,"spf":null,"ltp":null,"atb":[[8.1999999999999993,198.66]],"spl":null,"spn":null,"atl":null,"batl":null,"id":16570658,"hc":null,"bdatb":null}],"img":null,"tv":null,"con":null,"marketdefinition":null,"id":"1.258926623"}],"conflatems":null,"op":"mcm","id":3}
{"ct":null,"SegmentType":null,"clk":"AIqaAgDImQIA2YEC","heartbeatms":null,"pt":1780839926231,"initialclk":null,"mc":[{"rc":[{"tv":null,"batb":null,"spb":null,"bdatl":null,"trd":null,"spf":null,"ltp":null,"atb":[[1.1200000000000001,1483.74]],"spl":null,"spn":null,"atl":null,"batl":null,"id":19924823,"hc":null,"bdatb":null}],"img":null,"tv":null,"con":null,"marketdefinition":null,"id":"1.258926623"}],"conflatems":null,"op":"mcm","id":3}
{"ct":null,"SegmentType":null,"clk":"AJWaAgDVmQIA4YEC","heartbeatms":null,"pt":1780839926333,"initialclk":null,"mc":[{"rc":[{"tv":null,"batb":null,"spb":null,"bdatl":null,"trd":null,"spf":null,"ltp":null,"atb":null,"spl":null,"spn":null,"atl":[[25,42.460000000000001]],"batl":null,"id":16570658,"hc":null,"bdatb":null}],"img":null,"tv":null,"con":null,"marketdefinition":null,"id":"1.258926623"}],"conflatems":null,"op":"mcm","id":3}
{"ct":null,"SegmentType":null,"clk":"AJ2aAgDhmQIA6YEC","heartbeatms":null,"pt":1780839926435,"initialclk":null,"mc":[{"rc":[{"tv":248017.14000000001,"batb":null,"spb":null,"bdatl":null,"trd":[[8.5999999999999996,2731.0999999999999]],"spf":null,"ltp":8.5999999999999996,"atb":[[8.5999999999999996,257.00999999999999]],"spl":null,"spn":null,"atl":[[8.5999999999999996,0]],"batl":null,"id":16570658,"hc":null,"bdatb":null},{"tv":2109089.7599999998,"batb":null,"spb":null,"bdatl":null,"trd":[[1.1299999999999999,248086.42999999999]],"spf":null,"ltp":1.1299999999999999,"atb":[[1.1299999999999999,0]],"spl":null,"spn":null,"atl":[[1.1299999999999999,54180.779999999999]],"batl":null,"id":19924823,"hc":null,"bdatb":null}],"img":null,"tv":2357106.8999999999,"con":null,"marketdefinition":null,"id":"1.258926623"}],"conflatems":null,"op":"mcm","id":3}
{"ct":null,"SegmentType":null,"clk":"AKaaAgDqmQIA8IEC","heartbeatms":null,"pt":1780839926537,"initialclk":null,"mc":[{"rc":[{"tv":null,"batb":null,"spb":null,"bdatl":null,"trd":null,"spf":null,"ltp":null,"atb":[[1.1200000000000001,983.74000000000001]],"spl":null,"spn":null,"atl":null,"batl":null,"id":19924823,"hc":null,"bdatb":null}],"img":null,"tv":null,"con":null,"marketdefinition":null,"id":"1.258926623"}],"conflatems":null,"op":"mcm","id":3}
{"ct":null,"SegmentType":null,"clk":"ALCaAgD3mQIA94EC","heartbeatms":null,"pt":1780839926643,"initialclk":null,"mc":[{"rc":[{"tv":null,"batb":null,"spb":null,"bdatl":null,"trd":null,"spf":null,"ltp":null,"atb":[[7.5999999999999996,34.140000000000001]],"spl":null,"spn":null,"atl":null,"batl":null,"id":16570658,"hc":null,"bdatb":null},{"tv":null,"batb":null,"spb":null,"bdatl":null,"trd":null,"spf":null,"ltp":null,"atb":null,"spl":null,"spn":null,"atl":[[1.1299999999999999,43408.970000000001]],"batl":null,"id":19924823,"hc":null,"bdatb":null}],"img":null,"tv":null,"con":null,"marketdefinition":null,"id":"1.258926623"}],"conflatems":null,"op":"mcm","id":3}
{"ct":null,"SegmentType":null,"clk":"AOiaAgCxmgIArIIC","heartbeatms":null,"pt":1780839927153,"initialclk":null,"mc":[{"rc":[{"tv":null,"batb":null,"spb":null,"bdatl":null,"trd":null,"spf":null,"ltp":null,"atb":null,"spl":null,"spn":null,"atl":[[1.1399999999999999,25160.080000000002]],"batl":null,"id":19924823,"hc":null,"bdatb":null}],"img":null,"tv":null,"con":null,"marketdefinition":null,"id":"1.258926623"}],"conflatems":null,"op":"mcm","id":3}
{"ct":null,"SegmentType":null,"clk":"ALGbAgCNmwIA54IC","heartbeatms":null,"pt":1780839927833,"initialclk":null,"mc":[{"rc":[{"tv":248140.60999999999,"batb":null,"spb":null,"bdatl":null,"trd":[[8.8000000000000007,1741.6400000000001],[9,1087.48]],"spf":null,"ltp":9,"atb":[[8.8000000000000007,324.92000000000002],[9,109.38]],"spl":null,"spn":null,"atl":[[8.8000000000000007,0],[9,0]],"batl":null,"id":16570658,"hc":null,"bdatb":null},{"tv":null,"batb":null,"spb":null,"bdatl":null,"trd":null,"spf":null,"ltp":null,"atb":[[1.1200000000000001,1233.74]],"spl":null,"spn":null,"atl":null,"batl":null,"id":19924823,"hc":null,"bdatb":null}],"img":null,"tv":2357230.3700000001,"con":null,"marketdefinition":null,"id":"1.258926623"}],"conflatems":null,"op":"mcm","id":3}
{"ct":null,"SegmentType":null,"clk":"AM2bAgC0mwIA/oIC","heartbeatms":null,"pt":1780839928146,"initialclk":null,"mc":[{"rc":[{"tv":null,"batb":null,"spb":null,"bdatl":null,"trd":null,"spf":null,"ltp":null,"atb":[[8.1999999999999993,197.71000000000001],[8,626]],"spl":null,"spn":null,"atl":null,"batl":null,"id":16570658,"hc":null,"bdatb":null}],"img":null,"tv":null,"con":null,"marketdefinition":null,"id":"1.258926623"}],"conflatems":null,"op":"mcm","id":3}
{"ct":null,"SegmentType":null,"clk":"ANibAgC\u002BmwIAiYMC","heartbeatms":null,"pt":1780839928247,"initialclk":null,"mc":[{"rc":[{"tv":null,"batb":null,"spb":null,"bdatl":null,"trd":null,"spf":null,"ltp":null,"atb":[[8.8000000000000007,724.91999999999996]],"spl":null,"spn":null,"atl":null,"batl":null,"id":16570658,"hc":null,"bdatb":null}],"img":null,"tv":null,"con":null,"marketdefinition":null,"id":"1.258926623"}],"conflatems":null,"op":"mcm","id":3}
{"ct":null,"SegmentType":null,"clk":"AOObAgDJmwIAj4MC","heartbeatms":null,"pt":1780839928352,"initialclk":null,"mc":[{"rc":[{"tv":null,"batb":null,"spb":null,"bdatl":null,"trd":null,"spf":null,"ltp":null,"atb":[[8.4000000000000004,70]],"spl":null,"spn":null,"atl":[[11.5,124.87000000000001]],"batl":null,"id":16570658,"hc":null,"bdatb":null},{"tv":null,"batb":null,"spb":null,"bdatl":null,"trd":null,"spf":null,"ltp":null,"atb":[[1.0900000000000001,41833.019999999997]],"spl":null,"spn":null,"atl":[[1.1399999999999999,26581.080000000002]],"batl":null,"id":19924823,"hc":null,"bdatb":null}],"img":null,"tv":null,"con":null,"marketdefinition":null,"id":"1.258926623"}],"conflatems":null,"op":"mcm","id":3}
{"ct":null,"SegmentType":null,"clk":"AOubAgDSmwIAnIMC","heartbeatms":null,"pt":1780839928421,"initialclk":null,"mc":[{"rc":[{"tv":2109095.6200000001,"batb":null,"spb":null,"bdatl":null,"trd":[[1.1299999999999999,248092.29000000001]],"spf":null,"ltp":null,"atb":null,"spl":null,"spn":null,"atl":[[1.1299999999999999,43406.040000000001]],"batl":null,"id":19924823,"hc":null,"bdatb":null}],"img":null,"tv":2357236.23,"con":null,"marketdefinition":null,"id":"1.258926623"}],"conflatems":null,"op":"mcm","id":3}
{"ct":null,"SegmentType":null,"clk":"AIicAgDvmwIAu4MC","heartbeatms":null,"pt":1780839928719,"initialclk":null,"mc":[{"rc":[{"tv":null,"batb":null,"spb":null,"bdatl":null,"trd":null,"spf":null,"ltp":null,"atb":[[1.1000000000000001,67419.339999999997],[1.1100000000000001,69510.100000000006]],"spl":null,"spn":null,"atl":[[1.1299999999999999,44738.330000000002],[1.1399999999999999,27933.490000000002]],"batl":null,"id":19924823,"hc":null,"bdatb":null}],"img":null,"tv":null,"con":null,"marketdefinition":null,"id":"1.258926623"}],"conflatems":null,"op":"mcm","id":3}
{"ct":null,"SegmentType":null,"clk":"AI6cAgD8mwIAyIMC","heartbeatms":null,"pt":1780839928821,"initialclk":null,"mc":[{"rc":[{"tv":null,"batb":null,"spb":null,"bdatl":null,"trd":null,"spf":null,"ltp":null,"atb":null,"spl":null,"spn":null,"atl":[[9.1999999999999993,37.469999999999999]],"batl":null,"id":16570658,"hc":null,"bdatb":null},{"tv":null,"batb":null,"spb":null,"bdatl":null,"trd":null,"spf":null,"ltp":null,"atb":null,"spl":null,"spn":null,"atl":[[1.1299999999999999,45170.68]],"batl":null,"id":19924823,"hc":null,"bdatb":null}],"img":null,"tv":null,"con":null,"marketdefinition":null,"id":"1.258926623"}],"conflatems":null,"op":"mcm","id":3}
{"ct":null,"SegmentType":null,"clk":"AJ\u002BcAgCLnAIA3IMC","heartbeatms":null,"pt":1780839929031,"initialclk":null,"mc":[{"rc":[{"tv":null,"batb":null,"spb":null,"bdatl":null,"trd":null,"spf":null,"ltp":null,"atb":null,"spl":null,"spn":null,"atl":[[12.5,0]],"batl":null,"id":16570658,"hc":null,"bdatb":null}],"img":null,"tv":null,"con":null,"marketdefinition":null,"id":"1.258926623"}],"conflatems":null,"op":"mcm","id":3}
{"ct":null,"SegmentType":null,"clk":"AKecAgCTnAIA5oMC","heartbeatms":null,"pt":1780839929131,"initialclk":null,"mc":[{"rc":[{"tv":null,"batb":null,"spb":null,"bdatl":null,"trd":null,"spf":null,"ltp":null,"atb":[[9,248.21000000000001]],"spl":null,"spn":null,"atl":[[9.4000000000000004,144.91999999999999],[10.5,452.99000000000001]],"batl":null,"id":16570658,"hc":null,"bdatb":null},{"tv":null,"batb":null,"spb":null,"bdatl":null,"trd":null,"spf":null,"ltp":null,"atb":[[1.1100000000000001,70635.75]],"spl":null,"spn":null,"atl":[[1.1299999999999999,46276.410000000003]],"batl":null,"id":19924823,"hc":null,"bdatb":null}],"img":null,"tv":null,"con":null,"marketdefinition":null,"id":"1.258926623"}],"conflatems":null,"op":"mcm","id":3}
{"ct":null,"SegmentType":null,"clk":"ALGcAgCcnAIA7IMC","heartbeatms":null,"pt":1780839929231,"initialclk":null,"mc":[{"rc":[{"tv":null,"batb":null,"spb":null,"bdatl":null,"trd":null,"spf":null,"ltp":null,"atb":[[1.1000000000000001,68419.339999999997]],"spl":null,"spn":null,"atl":null,"batl":null,"id":19924823,"hc":null,"bdatb":null}],"img":null,"tv":null,"con":null,"marketdefinition":null,"id":"1.258926623"}],"conflatems":null,"op":"mcm","id":3}
{"ct":null,"SegmentType":null,"clk":"AOecAgDanAIAnoQC","heartbeatms":null,"pt":1780839929852,"initialclk":null,"mc":[{"rc":[{"tv":null,"batb":null,"spb":null,"bdatl":null,"trd":null,"spf":null,"ltp":null,"atb":null,"spl":null,"spn":null,"atl":[[1.1399999999999999,27935.490000000002]],"batl":null,"id":19924823,"hc":null,"bdatb":null}],"img":null,"tv":null,"con":null,"marketdefinition":null,"id":"1.258926623"}],"conflatems":null,"op":"mcm","id":3}
{"ct":null,"SegmentType":null,"clk":"APOcAgDonAIApIQC","heartbeatms":null,"pt":1780839929953,"initialclk":null,"mc":[{"rc":[{"tv":null,"batb":null,"spb":null,"bdatl":null,"trd":null,"spf":null,"ltp":null,"atb":null,"spl":null,"spn":null,"atl":[[1.1499999999999999,27635.009999999998]],"batl":null,"id":19924823,"hc":null,"bdatb":null}],"img":null,"tv":null,"con":null,"marketdefinition":null,"id":"1.258926623"}],"conflatems":null,"op":"mcm","id":3}
{"ct":null,"SegmentType":null,"clk":"APucAgD4nAIAqYQC","heartbeatms":null,"pt":1780839930057,"initialclk":null,"mc":[{"rc":[{"tv":null,"batb":null,"spb":null,"bdatl":null,"trd":null,"spf":null,"ltp":null,"atb":null,"spl":null,"spn":null,"atl":[[1.1399999999999999,27933.490000000002]],"batl":null,"id":19924823,"hc":null,"bdatb":null}],"img":null,"tv":null,"con":null,"marketdefinition":null,"id":"1.258926623"}],"conflatems":null,"op":"mcm","id":3}
{"ct":null,"SegmentType":null,"clk":"AIWdAgCDnQIAr4QC","heartbeatms":null,"pt":1780839930112,"initialclk":null,"mc":[{"rc":[{"tv":null,"batb":null,"spb":null,"bdatl":null,"trd":null,"spf":null,"ltp":null,"atb":null,"spl":null,"spn":null,"atl":[[1.1399999999999999,28183.490000000002]],"batl":null,"id":19924823,"hc":null,"bdatb":null}],"img":null,"tv":null,"con":null,"marketdefinition":null,"id":"1.258926623"}],"conflatems":null,"op":"mcm","id":3}
{"ct":null,"SegmentType":null,"clk":"ALqdAgC5nQIA4YQC","heartbeatms":null,"pt":1780839930632,"initialclk":null,"mc":[{"rc":[{"tv":null,"batb":null,"spb":null,"bdatl":null,"trd":null,"spf":null,"ltp":null,"atb":[[8.8000000000000007,324.92000000000002]],"spl":null,"spn":null,"atl":null,"batl":null,"id":16570658,"hc":null,"bdatb":null}],"img":null,"tv":null,"con":null,"marketdefinition":null,"id":"1.258926623"}],"conflatems":null,"op":"mcm","id":3}
{"ct":null,"SegmentType":null,"clk":"APWdAgD0nQIAmoUC","heartbeatms":null,"pt":1780839931251,"initialclk":null,"mc":[{"rc":[{"tv":2109449.6000000001,"batb":null,"spb":null,"bdatl":null,"trd":[[1.1299999999999999,248446.26999999999]],"spf":null,"ltp":null,"atb":[[1.1000000000000001,67055.710000000006]],"spl":null,"spn":null,"atl":[[1.1299999999999999,46099.419999999998]],"batl":null,"id":19924823,"hc":null,"bdatb":null}],"img":null,"tv":2357590.21,"con":null,"marketdefinition":null,"id":"1.258926623"}],"conflatems":null,"op":"mcm","id":3}
{"ct":null,"SegmentType":null,"clk":"AJ\u002BeAgCvngIAxYUC","heartbeatms":null,"pt":1780839931821,"initialclk":null,"mc":[{"rc":[{"tv":null,"batb":null,"spb":null,"bdatl":null,"trd":null,"spf":null,"ltp":null,"atb":[[1.04,73842.729999999996],[1.05,74308.929999999993],[1.0700000000000001,38876.290000000001],[1.0800000000000001,40510.370000000003],[1.1000000000000001,67057.710000000006],[1.0900000000000001,41835.019999999997],[1.0600000000000001,63326.940000000002],[1.02,90735.919999999998],[1.03,88974.589999999997],[1.01,93593.869999999995]],"spl":null,"spn":null,"atl":null,"batl":null,"id":19924823,"hc":null,"bdatb":null}],"img":null,"tv":null,"con":null,"marketdefinition":null,"id":"1.258926623"}],"conflatems":null,"op":"mcm","id":3}
{"ct":null,"SegmentType":null,"clk":"ALqeAgDSngIA2oUC","heartbeatms":null,"pt":1780839932139,"initialclk":null,"mc":[{"rc":[{"tv":248215.54999999999,"batb":null,"spb":null,"bdatl":null,"trd":[[9.1999999999999993,1671.3]],"spf":null,"ltp":9.1999999999999993,"atb":[[9.1999999999999993,235.81]],"spl":null,"spn":null,"atl":[[9.1999999999999993,0]],"batl":null,"id":16570658,"hc":null,"bdatb":null}],"img":null,"tv":2357665.1499999999,"con":null,"marketdefinition":null,"id":"1.258926623"}],"conflatems":null,"op":"mcm","id":3}
{"ct":null,"SegmentType":null,"clk":"AL6eAgDdngIA4IUC","heartbeatms":null,"pt":1780839932238,"initialclk":null,"mc":[{"rc":[{"tv":null,"batb":null,"spb":null,"bdatl":null,"trd":null,"spf":null,"ltp":null,"atb":[[9.1999999999999993,672.36000000000001]],"spl":null,"spn":null,"atl":null,"batl":null,"id":16570658,"hc":null,"bdatb":null},{"tv":null,"batb":null,"spb":null,"bdatl":null,"trd":null,"spf":null,"ltp":null,"atb":null,"spl":null,"spn":null,"atl":[[1.1299999999999999,47146.919999999998]],"batl":null,"id":19924823,"hc":null,"bdatb":null}],"img":null,"tv":null,"con":null,"marketdefinition":null,"id":"1.258926623"}],"conflatems":null,"op":"mcm","id":3}
{"ct":null,"SegmentType":null,"clk":"AMaeAgDsngIA5IUC","heartbeatms":null,"pt":1780839932341,"initialclk":null,"mc":[{"rc":[{"tv":null,"batb":null,"spb":null,"bdatl":null,"trd":null,"spf":null,"ltp":null,"atb":[[7.7999999999999998,1.8600000000000001],[7.4000000000000004,302.5],[8.1999999999999993,183.81999999999999],[7.2000000000000002,108.89]],"spl":null,"spn":null,"atl":[[11,243.43000000000001],[10.5,453.86000000000001],[9.5999999999999996,144.80000000000001]],"batl":null,"id":16570658,"hc":null,"bdatb":null},{"tv":null,"batb":null,"spb":null,"bdatl":null,"trd":null,"spf":null,"ltp":null,"atb":[[1.1000000000000001,67063.050000000003],[1.0900000000000001,41841.860000000001]],"spl":null,"spn":null,"atl":[[1000,1.0900000000000001],[1.1699999999999999,8881.7700000000004],[1.1599999999999999,9463.8600000000006],[1.1499999999999999,27639.950000000001]],"batl":null,"id":19924823,"hc":null,"bdatb":null}],"img":null,"tv":null,"con":null,"marketdefinition":null,"id":"1.258926623"}],"conflatems":null,"op":"mcm","id":3}
{"ct":null,"SegmentType":null,"clk":"ANCeAgD1ngIA64UC","heartbeatms":null,"pt":1780839932445,"initialclk":null,"mc":[{"rc":[{"tv":null,"batb":null,"spb":null,"bdatl":null,"trd":null,"spf":null,"ltp":null,"atb":[[9,260.70999999999998]],"spl":null,"spn":null,"atl":null,"batl":null,"id":16570658,"hc":null,"bdatb":null}],"img":null,"tv":null,"con":null,"marketdefinition":null,"id":"1.258926623"}],"conflatems":null,"op":"mcm","id":3}
{"ct":null,"SegmentType":null,"clk":"AOKeAgCInwIA\u002B4UC","heartbeatms":null,"pt":1780839932652,"initialclk":null,"mc":[{"rc":[{"tv":null,"batb":null,"spb":null,"bdatl":null,"trd":null,"spf":null,"ltp":null,"atb":[[9.1999999999999993,672.44000000000005]],"spl":null,"spn":null,"atl":null,"batl":null,"id":16570658,"hc":null,"bdatb":null}],"img":null,"tv":null,"con":null,"marketdefinition":null,"id":"1.258926623"}],"conflatems":null,"op":"mcm","id":3}
{"ct":null,"SegmentType":null,"clk":"AOueAgCRnwIAhoYC","heartbeatms":null,"pt":1780839932756,"initialclk":null,"mc":[{"rc":[{"tv":248259.98999999999,"batb":null,"spb":null,"bdatl":null,"trd":[[9.1999999999999993,1715.74]],"spf":null,"ltp":null,"atb":[[9.1999999999999993,650.22000000000003]],"spl":null,"spn":null,"atl":null,"batl":null,"id":16570658,"hc":null,"bdatb":null}],"img":null,"tv":2357709.5899999999,"con":null,"marketdefinition":null,"id":"1.258926623"}],"conflatems":null,"op":"mcm","id":3}
{"ct":null,"SegmentType":null,"clk":"APaeAgCdnwIAioYC","heartbeatms":null,"pt":1780839932817,"initialclk":null,"mc":[{"rc":[{"tv":null,"batb":null,"spb":null,"bdatl":null,"trd":null,"spf":null,"ltp":null,"atb":null,"spl":null,"spn":null,"atl":[[1000,0.88]],"batl":null,"id":19924823,"hc":null,"bdatb":null}],"img":null,"tv":null,"con":null,"marketdefinition":null,"id":"1.258926623"}],"conflatems":null,"op":"mcm","id":3}
{"ct":null,"SegmentType":null,"clk":"AK\u002BfAgDXnwIA0oYC","heartbeatms":null,"pt":1780839933534,"initialclk":null,"mc":[{"rc":[{"tv":2109453.6600000001,"batb":null,"spb":null,"bdatl":null,"trd":[[1.1200000000000001,63746.07]],"spf":null,"ltp":1.1200000000000001,"atb":[[1.1200000000000001,1231.71]],"spl":null,"spn":null,"atl":null,"batl":null,"id":19924823,"hc":null,"bdatb":null}],"img":null,"tv":2357713.6499999999,"con":null,"marketdefinition":null,"id":"1.258926623"}],"conflatems":null,"op":"mcm","id":3}
{"ct":null,"SegmentType":null,"clk":"AMKfAgDmnwIA4YYC","heartbeatms":null,"pt":1780839933743,"initialclk":null,"mc":[{"rc":[{"tv":null,"batb":null,"spb":null,"bdatl":null,"trd":null,"spf":null,"ltp":null,"atb":null,"spl":null,"spn":null,"atl":[[9.4000000000000004,12]],"batl":null,"id":16570658,"hc":null,"bdatb":null}],"img":null,"tv":null,"con":null,"marketdefinition":null,"id":"1.258926623"}],"conflatems":null,"op":"mcm","id":3}
{"ct":null,"SegmentType":null,"clk":"ANGfAgD6nwIA8oYC","heartbeatms":null,"pt":1780839933947,"initialclk":null,"mc":[{"rc":[{"tv":null,"batb":null,"spb":null,"bdatl":null,"trd":null,"spf":null,"ltp":null,"atb":[[8.4000000000000004,248.56999999999999]],"spl":null,"spn":null,"atl":null,"batl":null,"id":16570658,"hc":null,"bdatb":null},{"tv":null,"batb":null,"spb":null,"bdatl":null,"trd":null,"spf":null,"ltp":null,"atb":[[1.1000000000000001,68426.679999999993]],"spl":null,"spn":null,"atl":null,"batl":null,"id":19924823,"hc":null,"bdatb":null}],"img":null,"tv":null,"con":null,"marketdefinition":null,"id":"1.258926623"}],"conflatems":null,"op":"mcm","id":3}
{"ct":null,"SegmentType":null,"clk":"AO\u002BfAgCloAIAjocC","heartbeatms":null,"pt":1780839934354,"initialclk":null,"mc":[{"rc":[{"tv":2109473.6699999999,"batb":null,"spb":null,"bdatl":null,"trd":[[1.1200000000000001,63766.080000000002]],"spf":null,"ltp":null,"atb":[[1.1200000000000001,1221.71]],"spl":null,"spn":null,"atl":null,"batl":null,"id":19924823,"hc":null,"bdatb":null}],"img":null,"tv":2357733.6600000001,"con":null,"marketdefinition":null,"id":"1.258926623"}],"conflatems":null,"op":"mcm","id":3}
{"ct":null,"SegmentType":null,"clk":"AIWgAgDDoAIAqYcC","heartbeatms":null,"pt":1780839934617,"initialclk":null,"mc":[{"rc":[{"tv":null,"batb":null,"spb":null,"bdatl":null,"trd":null,"spf":null,"ltp":null,"atb":[[9.1999999999999993,550.22000000000003]],"spl":null,"spn":null,"atl":null,"batl":null,"id":16570658,"hc":null,"bdatb":null}],"img":null,"tv":null,"con":null,"marketdefinition":null,"id":"1.258926623"}],"conflatems":null,"op":"mcm","id":3}
{"ct":null,"SegmentType":null,"clk":"AJygAgDhoAIAt4cC","heartbeatms":null,"pt":1780839934826,"initialclk":null,"mc":[{"rc":[{"tv":null,"batb":null,"spb":null,"bdatl":null,"trd":null,"spf":null,"ltp":null,"atb":[[8.4000000000000004,70]],"spl":null,"spn":null,"atl":null,"batl":null,"id":16570658,"hc":null,"bdatb":null}],"img":null,"tv":null,"con":null,"marketdefinition":null,"id":"1.258926623"}],"conflatems":null,"op":"mcm","id":3}
{"ct":null,"SegmentType":null,"clk":"AKagAgDxoAIAvocC","heartbeatms":null,"pt":1780839934928,"initialclk":null,"mc":[{"rc":[{"tv":null,"batb":null,"spb":null,"bdatl":null,"trd":null,"spf":null,"ltp":null,"atb":[[7.7999999999999998,0.85999999999999999],[8,625.13]],"spl":null,"spn":null,"atl":[[11,242.44],[10.5,452.99000000000001]],"batl":null,"id":16570658,"hc":null,"bdatb":null},{"tv":null,"batb":null,"spb":null,"bdatl":null,"trd":null,"spf":null,"ltp":null,"atb":[[1.1000000000000001,68421.979999999996],[1.0900000000000001,41834.300000000003]],"spl":null,"spn":null,"atl":[[1.1399999999999999,28177.950000000001],[1.1499999999999999,27635.490000000002]],"batl":null,"id":19924823,"hc":null,"bdatb":null}],"img":null,"tv":null,"con":null,"marketdefinition":null,"id":"1.258926623"}],"conflatems":null,"op":"mcm","id":3}
{"ct":null,"SegmentType":null,"clk":"AMCgAgCPoQIA0ocC","heartbeatms":null,"pt":1780839935233,"initialclk":null,"mc":[{"rc":[{"tv":null,"batb":null,"spb":null,"bdatl":null,"trd":null,"spf":null,"ltp":null,"atb":null,"spl":null,"spn":null,"atl":[[10,244.25]],"batl":null,"id":16570658,"hc":null,"bdatb":null}],"img":null,"tv":null,"con":null,"marketdefinition":null,"id":"1.258926623"}],"conflatems":null,"op":"mcm","id":3}
{"ct":null,"SegmentType":null,"clk":"ANegAgC3oQIA7YcC","heartbeatms":null,"pt":1780839935549,"initialclk":null,"mc":[{"rc":[{"tv":null,"batb":null,"spb":null,"bdatl":null,"trd":null,"spf":null,"ltp":null,"atb":null,"spl":null,"spn":null,"atl":[[10.5,310.13999999999999]],"batl":null,"id":16570658,"hc":null,"bdatb":null}],"img":null,"tv":null,"con":null,"marketdefinition":null,"id":"1.258926623"}],"conflatems":null,"op":"mcm","id":3}
{"ct":null,"SegmentType":null,"clk":"AOOgAgDDoQIA9YcC","heartbeatms":null,"pt":1780839935655,"initialclk":null,"mc":[{"rc":[{"tv":248260.16,"batb":null,"spb":null,"bdatl":null,"trd":[[9.4000000000000004,604.60000000000002]],"spf":null,"ltp":9.4000000000000004,"atb":null,"spl":null,"spn":null,"atl":[[9.4000000000000004,11.92]],"batl":null,"id":16570658,"hc":null,"bdatb":null}],"img":null,"tv":2357733.8300000001,"con":null,"marketdefinition":null,"id":"1.258926623"}],"conflatems":null,"op":"mcm","id":3}
{"ct":null,"SegmentType":null,"clk":"APKgAgDboQIAhogC","heartbeatms":null,"pt":1780839935856,"initialclk":null,"mc":[{"rc":[{"tv":null,"batb":null,"spb":null,"bdatl":null,"trd":null,"spf":null,"ltp":null,"atb":[[1.1100000000000001,70636.710000000006]],"spl":null,"spn":null,"atl":null,"batl":null,"id":19924823,"hc":null,"bdatb":null}],"img":null,"tv":null,"con":null,"marketdefinition":null,"id":"1.258926623"}],"conflatems":null,"op":"mcm","id":3}
{"ct":null,"SegmentType":null,"clk":"AP2gAgDnoQIAkIgC","heartbeatms":null,"pt":1780839935916,"initialclk":null,"mc":[{"rc":[{"tv":null,"batb":null,"spb":null,"bdatl":null,"trd":null,"spf":null,"ltp":null,"atb":null,"spl":null,"spn":null,"atl":[[1.1299999999999999,47147.129999999997]],"batl":null,"id":19924823,"hc":null,"bdatb":null}],"img":null,"tv":null,"con":null,"marketdefinition":null,"id":"1.258926623"}],"conflatems":null,"op":"mcm","id":3}
{"ct":null,"SegmentType":null,"clk":"AKahAgCVogIAtogC","heartbeatms":null,"pt":1780839936334,"initialclk":null,"mc":[{"rc":[{"tv":null,"batb":null,"spb":null,"bdatl":null,"trd":null,"spf":null,"ltp":null,"atb":[[1.1200000000000001,1236.71]],"spl":null,"spn":null,"atl":null,"batl":null,"id":19924823,"hc":null,"bdatb":null}],"img":null,"tv":null,"con":null,"marketdefinition":null,"id":"1.258926623"}],"conflatems":null,"op":"mcm","id":3}
{"ct":null,"SegmentType":null,"clk":"AN2hAgDPogIA34gC","heartbeatms":null,"pt":1780839936848,"initialclk":null,"mc":[{"rc":[{"tv":null,"batb":null,"spb":null,"bdatl":null,"trd":null,"spf":null,"ltp":null,"atb":null,"spl":null,"spn":null,"atl":[[1.1299999999999999,47139.629999999997]],"batl":null,"id":19924823,"hc":null,"bdatb":null}],"img":null,"tv":null,"con":null,"marketdefinition":null,"id":"1.258926623"}],"conflatems":null,"op":"mcm","id":3}
{"ct":null,"SegmentType":null,"clk":"AP6hAgCBowIA\u002B4gC","heartbeatms":null,"pt":1780839937258,"initialclk":null,"mc":[{"rc":[{"tv":2109475.5800000001,"batb":null,"spb":null,"bdatl":null,"trd":[[1.1299999999999999,248448.17999999999]],"spf":null,"ltp":1.1299999999999999,"atb":null,"spl":null,"spn":null,"atl":[[1.1299999999999999,47138.669999999998]],"batl":null,"id":19924823,"hc":null,"bdatb":null}],"img":null,"tv":2357735.7400000002,"con":null,"marketdefinition":null,"id":"1.258926623"}],"conflatems":null,"op":"mcm","id":3}
{"ct":null,"SegmentType":null,"clk":"ALGiAgDIowIAqYkC","heartbeatms":null,"pt":1780839937827,"initialclk":null,"mc":[{"rc":[{"tv":2110729.1099999999,"batb":null,"spb":null,"bdatl":null,"trd":[[1.1200000000000001,65019.610000000001]],"spf":null,"ltp":1.1200000000000001,"atb":[[1.1200000000000001,609.94000000000005]],"spl":null,"spn":null,"atl":null,"batl":null,"id":19924823,"hc":null,"bdatb":null}],"img":null,"tv":2358989.27,"con":null,"marketdefinition":null,"id":"1.258926623"}],"conflatems":null,"op":"mcm","id":3}
{"ct":null,"SegmentType":null,"clk":"ANqiAgDwowIA2IkC","heartbeatms":null,"pt":1780839938254,"initialclk":null,"mc":[{"rc":[{"tv":null,"batb":null,"spb":null,"bdatl":null,"trd":null,"spf":null,"ltp":null,"atb":null,"spl":null,"spn":null,"atl":[[9.4000000000000004,10]],"batl":null,"id":16570658,"hc":null,"bdatb":null}],"img":null,"tv":null,"con":null,"marketdefinition":null,"id":"1.258926623"}],"conflatems":null,"op":"mcm","id":3}
{"ct":null,"SegmentType":null,"clk":"ALejAgDKpAIAr4oC","heartbeatms":null,"pt":1780839939138,"initialclk":null,"mc":[{"rc":[{"tv":2110733.1800000002,"batb":null,"spb":null,"bdatl":null,"trd":[[1.1200000000000001,65023.68]],"spf":null,"ltp":null,"atb":[[1.1200000000000001,607.90999999999997]],"spl":null,"spn":null,"atl":null,"batl":null,"id":19924823,"hc":null,"bdatb":null}],"img":null,"tv":2358993.3399999999,"con":null,"marketdefinition":null,"id":"1.258926623"}],"conflatems":null,"op":"mcm","id":3}
{"ct":null,"SegmentType":null,"clk":"ANejAgDvpAIAyIoC","heartbeatms":null,"pt":1780839939451,"initialclk":null,"mc":[{"rc":[{"tv":null,"batb":null,"spb":null,"bdatl":null,"trd":null,"spf":null,"ltp":null,"atb":null,"spl":null,"spn":null,"atl":[[11.5,130.65000000000001]],"batl":null,"id":16570658,"hc":null,"bdatb":null}],"img":null,"tv":null,"con":null,"marketdefinition":null,"id":"1.258926623"}],"conflatems":null,"op":"mcm","id":3}
{"ct":null,"SegmentType":null,"clk":"AJCkAgCrpQIA7YoC","heartbeatms":null,"pt":1780839939918,"initialclk":null,"mc":[{"rc":[{"tv":null,"batb":null,"spb":null,"bdatl":null,"trd":null,"spf":null,"ltp":null,"atb":null,"spl":null,"spn":null,"atl":[[1.1299999999999999,46706.32]],"batl":null,"id":19924823,"hc":null,"bdatb":null}],"img":null,"tv":null,"con":null,"marketdefinition":null,"id":"1.258926623"}],"conflatems":null,"op":"mcm","id":3}
{"ct":null,"SegmentType":null,"clk":"ALCkAgDNpQIAi4sC","heartbeatms":null,"pt":1780839940229,"initialclk":null,"mc":[{"rc":[{"tv":2110735.1000000001,"batb":null,"spb":null,"bdatl":null,"trd":[[1.1299999999999999,248450.10000000001]],"spf":null,"ltp":1.1299999999999999,"atb":null,"spl":null,"spn":null,"atl":[[1.1299999999999999,46705.360000000001]],"batl":null,"id":19924823,"hc":null,"bdatb":null}],"img":null,"tv":2358995.2599999998,"con":null,"marketdefinition":null,"id":"1.258926623"}],"conflatems":null,"op":"mcm","id":3}
{"ct":null,"SegmentType":null,"clk":"ALukAgDZpQIAk4sC","heartbeatms":null,"pt":1780839940333,"initialclk":null,"mc":[{"rc":[{"tv":null,"batb":null,"spb":null,"bdatl":null,"trd":null,"spf":null,"ltp":null,"atb":[[9.1999999999999993,550.13999999999999]],"spl":null,"spn":null,"atl":null,"batl":null,"id":16570658,"hc":null,"bdatb":null}],"img":null,"tv":null,"con":null,"marketdefinition":null,"id":"1.258926623"}],"conflatems":null,"op":"mcm","id":3}
{"ct":null,"SegmentType":null,"clk":"APekAgCbpgIAyIsC","heartbeatms":null,"pt":1780839940950,"initialclk":null,"mc":[{"rc":[{"tv":248352.59,"batb":null,"spb":null,"bdatl":null,"trd":[[9.4000000000000004,697.02999999999997]],"spf":null,"ltp":null,"atb":[[9.4000000000000004,59.439999999999998]],"spl":null,"spn":null,"atl":[[9.4000000000000004,0]],"batl":null,"id":16570658,"hc":null,"bdatb":null},{"tv":2111343.0099999998,"batb":null,"spb":null,"bdatl":null,"trd":[[1.1200000000000001,65631.589999999997]],"spf":null,"ltp":1.1200000000000001,"atb":[[1.1200000000000001,0]],"spl":null,"spn":null,"atl":[[1.1200000000000001,0.95999999999999996]],"batl":null,"id":19924823,"hc":null,"bdatb":null}],"img":null,"tv":2359695.6000000001,"con":null,"marketdefinition":null,"id":"1.258926623"}],"conflatems":null,"op":"mcm","id":3}
{"ct":null,"SegmentType":null,"clk":"AIKlAgClpgIA04sC","heartbeatms":null,"pt":1780839941055,"initialclk":null,"mc":[{"rc":[{"tv":null,"batb":null,"spb":null,"bdatl":null,"trd":null,"spf":null,"ltp":null,"atb":null,"spl":null,"spn":null,"atl":[[9.8000000000000007,129.03]],"batl":null,"id":16570658,"hc":null,"bdatb":null}],"img":null,"tv":null,"con":null,"marketdefinition":null,"id":"1.258926623"}],"conflatems":null,"op":"mcm","id":3}
{"ct":null,"SegmentType":null,"clk":"AIelAgCrpgIA24sC","heartbeatms":null,"pt":1780839941160,"initialclk":null,"mc":[{"rc":[{"tv":248352.64999999999,"batb":null,"spb":null,"bdatl":null,"trd":[[9.4000000000000004,697.09000000000003]],"spf":null,"ltp":null,"atb":[[9.4000000000000004,59.380000000000003]],"spl":null,"spn":null,"atl":null,"batl":null,"id":16570658,"hc":null,"bdatb":null},{"tv":2111345.4199999999,"batb":null,"spb":null,"bdatl":null,"trd":[[1.1200000000000001,65634]],"spf":null,"ltp":null,"atb":null,"spl":null,"spn":null,"atl":[[1.1299999999999999,45657.860000000001],[1.1200000000000001,0]],"batl":null,"id":19924823,"hc":null,"bdatb":null}],"img":null,"tv":2359698.0699999998,"con":null,"marketdefinition":null,"id":"1.258926623"}],"conflatems":null,"op":"mcm","id":3}
{"ct":null,"SegmentType":null,"clk":"AKGlAgDHpgIAtIwC","heartbeatms":null,"pt":1780839941427,"initialclk":null,"mc":[{"rc":[{"tv":null,"batb":null,"spb":null,"bdatl":null,"trd":null,"spf":null,"ltp":null,"atb":null,"spl":null,"spn":null,"atl":[[1.1399999999999999,25177.950000000001]],"batl":null,"id":19924823,"hc":null,"bdatb":null}],"img":null,"tv":null,"con":null,"marketdefinition":null,"id":"1.258926623"}],"conflatems":null,"op":"mcm","id":3}
{"ct":null,"SegmentType":null,"clk":"AK2lAgDRpgIAuYwC","heartbeatms":null,"pt":1780839941527,"initialclk":null,"mc":[{"rc":[{"tv":null,"batb":null,"spb":null,"bdatl":null,"trd":null,"spf":null,"ltp":null,"atb":null,"spl":null,"spn":null,"atl":[[1.1299999999999999,45830.620000000003]],"batl":null,"id":19924823,"hc":null,"bdatb":null}],"img":null,"tv":null,"con":null,"marketdefinition":null,"id":"1.258926623"}],"conflatems":null,"op":"mcm","id":3}
{"ct":null,"SegmentType":null,"clk":"ALelAgDdpgIAwYwC","heartbeatms":null,"pt":1780839941633,"initialclk":null,"mc":[{"rc":[{"tv":null,"batb":null,"spb":null,"bdatl":null,"trd":null,"spf":null,"ltp":null,"atb":null,"spl":null,"spn":null,"atl":[[1.1299999999999999,45902.809999999998]],"batl":null,"id":19924823,"hc":null,"bdatb":null}],"img":null,"tv":null,"con":null,"marketdefinition":null,"id":"1.258926623"}],"conflatems":null,"op":"mcm","id":3}
{"ct":null,"SegmentType":null,"clk":"AM2lAgDvpgIA2YwC","heartbeatms":null,"pt":1780839941844,"initialclk":null,"mc":[{"rc":[{"tv":null,"batb":null,"spb":null,"bdatl":null,"trd":null,"spf":null,"ltp":null,"atb":null,"spl":null,"spn":null,"atl":[[1.1299999999999999,45910.029999999999]],"batl":null,"id":19924823,"hc":null,"bdatb":null}],"img":null,"tv":null,"con":null,"marketdefinition":null,"id":"1.258926623"}],"conflatems":null,"op":"mcm","id":3}
{"ct":null,"SegmentType":null,"clk":"ANmlAgD5pgIA44wC","heartbeatms":null,"pt":1780839941949,"initialclk":null,"mc":[{"rc":[{"tv":null,"batb":null,"spb":null,"bdatl":null,"trd":null,"spf":null,"ltp":null,"atb":[[8,811.07000000000005]],"spl":null,"spn":null,"atl":null,"batl":null,"id":16570658,"hc":null,"bdatb":null},{"tv":null,"batb":null,"spb":null,"bdatl":null,"trd":null,"spf":null,"ltp":null,"atb":[[1.1100000000000001,71988.059999999998]],"spl":null,"spn":null,"atl":[[1.1299999999999999,45909.82]],"batl":null,"id":19924823,"hc":null,"bdatb":null}],"img":null,"tv":null,"con":null,"marketdefinition":null,"id":"1.258926623"}],"conflatems":null,"op":"mcm","id":3}
{"ct":null,"SegmentType":null,"clk":"AOylAgCLpwIA\u002BIwC","heartbeatms":null,"pt":1780839942154,"initialclk":null,"mc":[{"rc":[{"tv":null,"batb":null,"spb":null,"bdatl":null,"trd":null,"spf":null,"ltp":null,"atb":null,"spl":null,"spn":null,"atl":[[1.22,9089.1000000000004]],"batl":null,"id":19924823,"hc":null,"bdatb":null}],"img":null,"tv":null,"con":null,"marketdefinition":null,"id":"1.258926623"}],"conflatems":null,"op":"mcm","id":3}
{"ct":null,"SegmentType":null,"clk":"AICmAgCepwIAi40C","heartbeatms":null,"pt":1780839942359,"initialclk":null,"mc":[{"rc":[{"tv":null,"batb":null,"spb":null,"bdatl":null,"trd":null,"spf":null,"ltp":null,"atb":[[1.1000000000000001,67058.350000000006]],"spl":null,"spn":null,"atl":null,"batl":null,"id":19924823,"hc":null,"bdatb":null}],"img":null,"tv":null,"con":null,"marketdefinition":null,"id":"1.258926623"}],"conflatems":null,"op":"mcm","id":3}
{"ct":null,"SegmentType":null,"clk":"AOOmAgCdqAIA6o0C","heartbeatms":null,"pt":1780839943448,"initialclk":null,"mc":[{"rc":[{"tv":null,"batb":null,"spb":null,"bdatl":null,"trd":null,"spf":null,"ltp":null,"atb":null,"spl":null,"spn":null,"atl":[[1.1299999999999999,45982.019999999997]],"batl":null,"id":19924823,"hc":null,"bdatb":null}],"img":null,"tv":null,"con":null,"marketdefinition":null,"id":"1.258926623"}],"conflatems":null,"op":"mcm","id":3}
{"ct":null,"SegmentType":null,"clk":"AIGnAgDAqAIAhI4C","heartbeatms":null,"pt":1780839943758,"initialclk":null,"mc":[{"rc":[{"tv":null,"batb":null,"spb":null,"bdatl":null,"trd":null,"spf":null,"ltp":null,"atb":null,"spl":null,"spn":null,"atl":[[1.1299999999999999,45996.459999999999]],"batl":null,"id":19924823,"hc":null,"bdatb":null}],"img":null,"tv":null,"con":null,"marketdefinition":null,"id":"1.258926623"}],"conflatems":null,"op":"mcm","id":3}
{"ct":null,"SegmentType":null,"clk":"AKKnAgDmqAIAqY4C","heartbeatms":null,"pt":1780839944125,"initialclk":null,"mc":[{"rc":[{"tv":null,"batb":null,"spb":null,"bdatl":null,"trd":null,"spf":null,"ltp":null,"atb":[[8.5999999999999996,258.74000000000001]],"spl":null,"spn":null,"atl":null,"batl":null,"id":16570658,"hc":null,"bdatb":null}],"img":null,"tv":null,"con":null,"marketdefinition":null,"id":"1.258926623"}],"conflatems":null,"op":"mcm","id":3}
{"ct":null,"SegmentType":null,"clk":"AM6nAgCkqQIA0Y4C","heartbeatms":null,"pt":1780839944642,"initialclk":null,"mc":[{"rc":[{"tv":248362.64999999999,"batb":null,"spb":null,"bdatl":null,"trd":[[9.4000000000000004,707.09000000000003]],"spf":null,"ltp":null,"atb":[[9.4000000000000004,54.380000000000003]],"spl":null,"spn":null,"atl":null,"batl":null,"id":16570658,"hc":null,"bdatb":null}],"img":null,"tv":2359708.0699999998,"con":null,"marketdefinition":null,"id":"1.258926623"}],"conflatems":null,"op":"mcm","id":3}
{"ct":null,"SegmentType":null,"clk":"ALaoAgCZqgIAsI8C","heartbeatms":null,"pt":1780839945733,"initialclk":null,"mc":[{"rc":[{"tv":248363.03,"batb":null,"spb":null,"bdatl":null,"trd":[[9.4000000000000004,707.47000000000003]],"spf":null,"ltp":null,"atb":[[9.4000000000000004,54]],"spl":null,"spn":null,"atl":null,"batl":null,"id":16570658,"hc":null,"bdatb":null},{"tv":2111348.6400000001,"batb":null,"spb":null,"bdatl":null,"trd":[[1.1200000000000001,65637.220000000001]],"spf":null,"ltp":null,"atb":null,"spl":null,"spn":null,"atl":null,"batl":null,"id":19924823,"hc":null,"bdatb":null}],"img":null,"tv":2359711.6699999999,"con":null,"marketdefinition":null,"id":"1.258926623"}],"conflatems":null,"op":"mcm","id":3}
{"ct":null,"SegmentType":null,"clk":"AIKpAgDtqgIA7o8C","heartbeatms":null,"pt":1780839946557,"initialclk":null,"mc":[{"rc":[{"tv":null,"batb":null,"spb":null,"bdatl":null,"trd":null,"spf":null,"ltp":null,"atb":null,"spl":null,"spn":null,"atl":[[1.1299999999999999,46003.959999999999]],"batl":null,"id":19924823,"hc":null,"bdatb":null}],"img":null,"tv":null,"con":null,"marketdefinition":null,"id":"1.258926623"}],"conflatems":null,"op":"mcm","id":3}
{"ct":null,"SegmentType":null,"clk":"ALCpAgCOqwIAkZAC","heartbeatms":null,"pt":1780839947069,"initialclk":null,"mc":[{"rc":[{"tv":248363.42000000001,"batb":null,"spb":null,"bdatl":null,"trd":[[9.4000000000000004,707.86000000000001]],"spf":null,"ltp":null,"atb":[[9.4000000000000004,53.609999999999999]],"spl":null,"spn":null,"atl":null,"batl":null,"id":16570658,"hc":null,"bdatb":null},{"tv":2111351.8799999999,"batb":null,"spb":null,"bdatl":null,"trd":[[1.1200000000000001,65640.460000000006]],"spf":null,"ltp":null,"atb":null,"spl":null,"spn":null,"atl":null,"batl":null,"id":19924823,"hc":null,"bdatb":null}],"img":null,"tv":2359715.2999999998,"con":null,"marketdefinition":null,"id":"1.258926623"}],"conflatems":null,"op":"mcm","id":3}
{"ct":null,"SegmentType":null,"clk":"APCpAgDMqwIAzpAC","heartbeatms":null,"pt":1780839947643,"initialclk":null,"mc":[{"rc":[{"tv":248417.03,"batb":null,"spb":null,"bdatl":null,"trd":[[9.4000000000000004,761.47000000000003]],"spf":null,"ltp":null,"atb":[[9.4000000000000004,0]],"spl":null,"spn":null,"atl":null,"batl":null,"id":16570658,"hc":null,"bdatb":null},{"tv":2111801.8199999998,"batb":null,"spb":null,"bdatl":null,"trd":[[1.1200000000000001,66090.399999999994]],"spf":null,"ltp":null,"atb":[[1.1200000000000001,1126.0999999999999]],"spl":null,"spn":null,"atl":null,"batl":null,"id":19924823,"hc":null,"bdatb":null}],"img":null,"tv":2360218.8500000001,"con":null,"marketdefinition":null,"id":"1.258926623"}],"conflatems":null,"op":"mcm","id":3}
{"ct":null,"SegmentType":null,"clk":"APypAgDWqwIA1pAC","heartbeatms":null,"pt":1780839947745,"initialclk":null,"mc":[{"rc":[{"tv":null,"batb":null,"spb":null,"bdatl":null,"trd":null,"spf":null,"ltp":null,"atb":null,"spl":null,"spn":null,"atl":[[1.1299999999999999,47582.459999999999]],"batl":null,"id":19924823,"hc":null,"bdatb":null}],"img":null,"tv":null,"con":null,"marketdefinition":null,"id":"1.258926623"}],"conflatems":null,"op":"mcm","id":3}
{"ct":null,"SegmentType":null,"clk":"AI2qAgDjqwIA5JAC","heartbeatms":null,"pt":1780839947854,"initialclk":null,"mc":[{"rc":[{"tv":2112201.8199999998,"batb":null,"spb":null,"bdatl":null,"trd":[[1.1299999999999999,248850.10000000001]],"spf":null,"ltp":1.1299999999999999,"atb":null,"spl":null,"spn":null,"atl":[[1.1299999999999999,47382.459999999999]],"batl":null,"id":19924823,"hc":null,"bdatb":null}],"img":null,"tv":2360618.8500000001,"con":null,"marketdefinition":null,"id":"1.258926623"}],"conflatems":null,"op":"mcm","id":3}
{"ct":null,"SegmentType":null,"clk":"AMyqAgClrAIAlpEC","heartbeatms":null,"pt":1780839948569,"initialclk":null,"mc":[{"rc":[{"tv":null,"batb":null,"spb":null,"bdatl":null,"trd":null,"spf":null,"ltp":null,"atb":[[1.1000000000000001,67078.75]],"spl":null,"spn":null,"atl":null,"batl":null,"id":19924823,"hc":null,"bdatb":null}],"img":null,"tv":null,"con":null,"marketdefinition":null,"id":"1.258926623"}],"conflatems":null,"op":"mcm","id":3}
{"ct":null,"SegmentType":null,"clk":"ANyqAgC6rAIAqpEC","heartbeatms":null,"pt":1780839948727,"initialclk":null,"mc":[{"rc":[{"tv":null,"batb":null,"spb":null,"bdatl":null,"trd":null,"spf":null,"ltp":null,"atb":null,"spl":null,"spn":null,"atl":[[1000,1.1200000000000001]],"batl":null,"id":19924823,"hc":null,"bdatb":null}],"img":null,"tv":null,"con":null,"marketdefinition":null,"id":"1.258926623"}],"conflatems":null,"op":"mcm","id":3}
{"ct":null,"SegmentType":null,"clk":"APOqAgDSrAIAupEC","heartbeatms":null,"pt":1780839948947,"initialclk":null,"mc":[{"rc":[{"tv":null,"batb":null,"spb":null,"bdatl":null,"trd":null,"spf":null,"ltp":null,"atb":null,"spl":null,"spn":null,"atl":[[1.1299999999999999,45803.959999999999]],"batl":null,"id":19924823,"hc":null,"bdatb":null}],"img":null,"tv":null,"con":null,"marketdefinition":null,"id":"1.258926623"}],"conflatems":null,"op":"mcm","id":3}
{"ct":null,"SegmentType":null,"clk":"AP6qAgDjrAIAzZEC","heartbeatms":null,"pt":1780839949139,"initialclk":null,"mc":[{"rc":[{"tv":null,"batb":null,"spb":null,"bdatl":null,"trd":null,"spf":null,"ltp":null,"atb":null,"spl":null,"spn":null,"atl":[[1000,0.88],[1.1399999999999999,25164.73]],"batl":null,"id":19924823,"hc":null,"bdatb":null}],"img":null,"tv":null,"con":null,"marketdefinition":null,"id":"1.258926623"}],"conflatems":null,"op":"mcm","id":3}
{"ct":null,"SegmentType":null,"clk":"ANOrAgCwrQIAjZIC","heartbeatms":null,"pt":1780839949963,"initialclk":null,"mc":[{"rc":[{"tv":null,"batb":null,"spb":null,"bdatl":null,"trd":null,"spf":null,"ltp":null,"atb":null,"spl":null,"spn":null,"atl":[[1.1399999999999999,25165.73]],"batl":null,"id":19924823,"hc":null,"bdatb":null}],"img":null,"tv":null,"con":null,"marketdefinition":null,"id":"1.258926623"}],"conflatems":null,"op":"mcm","id":3}
{"ct":null,"SegmentType":null,"clk":"ANurAgC8rQIAlpIC","heartbeatms":null,"pt":1780839950065,"initialclk":null,"mc":[{"rc":[{"tv":null,"batb":null,"spb":null,"bdatl":null,"trd":null,"spf":null,"ltp":null,"atb":null,"spl":null,"spn":null,"atl":[[1.1299999999999999,48071.459999999999]],"batl":null,"id":19924823,"hc":null,"bdatb":null}],"img":null,"tv":null,"con":null,"marketdefinition":null,"id":"1.258926623"}],"conflatems":null,"op":"mcm","id":3}
{"ct":null,"SegmentType":null,"clk":"AKWsAgD4rQIAyZIC","heartbeatms":null,"pt":1780839950747,"initialclk":null,"mc":[{"rc":[{"tv":2112777.2400000002,"batb":null,"spb":null,"bdatl":null,"trd":[[1.1200000000000001,66665.820000000007]],"spf":null,"ltp":1.1200000000000001,"atb":[[1.1200000000000001,838.38999999999999]],"spl":null,"spn":null,"atl":null,"batl":null,"id":19924823,"hc":null,"bdatb":null}],"img":null,"tv":2361194.27,"con":null,"marketdefinition":null,"id":"1.258926623"}],"conflatems":null,"op":"mcm","id":3}
{"ct":null,"SegmentType":null,"clk":"AP6sAgDRrgIAipMC","heartbeatms":null,"pt":1780839951728,"initialclk":null,"mc":[{"rc":[{"tv":null,"batb":null,"spb":null,"bdatl":null,"trd":null,"spf":null,"ltp":null,"atb":[[1.1200000000000001,839.21000000000004]],"spl":null,"spn":null,"atl":null,"batl":null,"id":19924823,"hc":null,"bdatb":null}],"img":null,"tv":null,"con":null,"marketdefinition":null,"id":"1.258926623"}],"conflatems":null,"op":"mcm","id":3}
{"ct":null,"SegmentType":null,"clk":"AKytAgD4rgIArJMC","heartbeatms":null,"pt":1780839952242,"initialclk":null,"mc":[{"rc":[{"tv":2112777.7200000002,"batb":null,"spb":null,"bdatl":null,"trd":[[1.1200000000000001,66666.300000000003]],"spf":null,"ltp":null,"atb":[[1.1200000000000001,838.97000000000003]],"spl":null,"spn":null,"atl":[[1.1299999999999999,48146.029999999999]],"batl":null,"id":19924823,"hc":null,"bdatb":null}],"img":null,"tv":2361194.75,"con":null,"marketdefinition":null,"id":"1.258926623"}],"conflatems":null,"op":"mcm","id":3}
{"ct":null,"SegmentType":null,"clk":"AP2tAgDQrwIA6ZMC","heartbeatms":null,"pt":1780839953069,"initialclk":null,"mc":[{"rc":[{"tv":null,"batb":null,"spb":null,"bdatl":null,"trd":null,"spf":null,"ltp":null,"atb":[[8.4000000000000004,0],[8.8000000000000007,211.28],[9,151.33000000000001],[8.5999999999999996,269.27999999999997],[8,625.13]],"spl":null,"spn":null,"atl":[[11.5,58.649999999999999],[11,244.44],[10,94.25]],"batl":null,"id":16570658,"hc":null,"bdatb":null},{"tv":null,"batb":null,"spb":null,"bdatl":null,"trd":null,"spf":null,"ltp":null,"atb":[[1.0900000000000001,40183.300000000003],[1.1100000000000001,70636.710000000006]],"spl":null,"spn":null,"atl":[[1.1299999999999999,48553.529999999999],[1.1399999999999999,22433.209999999999]],"batl":null,"id":19924823,"hc":null,"bdatb":null}],"img":null,"tv":null,"con":null,"marketdefinition":null,"id":"1.258926623"}],"conflatems":null,"op":"mcm","id":3}
{"ct":null,"SegmentType":null,"clk":"AIWuAgDerwIA85MC","heartbeatms":null,"pt":1780839953176,"initialclk":null,"mc":[{"rc":[{"tv":null,"batb":null,"spb":null,"bdatl":null,"trd":null,"spf":null,"ltp":null,"atb":[[7.7999999999999998,341.89999999999998],[7.5999999999999996,128]],"spl":null,"spn":null,"atl":null,"batl":null,"id":16570658,"hc":null,"bdatb":null},{"tv":null,"batb":null,"spb":null,"bdatl":null,"trd":null,"spf":null,"ltp":null,"atb":[[1.1000000000000001,70148.220000000001],[1.0900000000000001,43101.089999999997]],"spl":null,"spn":null,"atl":null,"batl":null,"id":19924823,"hc":null,"bdatb":null}],"img":null,"tv":null,"con":null,"marketdefinition":null,"id":"1.258926623"}],"conflatems":null,"op":"mcm","id":3}
{"ct":null,"SegmentType":null,"clk":"AI6uAgDprwIA\u002BpMC","heartbeatms":null,"pt":1780839953276,"initialclk":null,"mc":[{"rc":[{"tv":null,"batb":null,"spb":null,"bdatl":null,"trd":null,"spf":null,"ltp":null,"atb":null,"spl":null,"spn":null,"atl":[[1.1299999999999999,46286.029999999999]],"batl":null,"id":19924823,"hc":null,"bdatb":null}],"img":null,"tv":null,"con":null,"marketdefinition":null,"id":"1.258926623"}],"conflatems":null,"op":"mcm","id":3}
{"ct":null,"SegmentType":null,"clk":"AKGuAgD5rwIAjZQC","heartbeatms":null,"pt":1780839953437,"initialclk":null,"mc":[{"rc":[{"tv":null,"batb":null,"spb":null,"bdatl":null,"trd":null,"spf":null,"ltp":null,"atb":[[8.8000000000000007,0],[7.4000000000000004,9.2300000000000004],[8.1999999999999993,19.440000000000001],[8.5999999999999996,30.949999999999999],[7.2000000000000002,0.98999999999999999],[8,619.95000000000005]],"spl":null,"spn":null,"atl":[[11,106.94],[10.5,11.470000000000001]],"batl":null,"id":16570658,"hc":null,"bdatb":null}],"img":null,"tv":null,"con":null,"marketdefinition":null,"id":"1.258926623"}],"conflatems":null,"op":"mcm","id":3}
{"ct":null,"SegmentType":null,"clk":"AKeuAgCEsAIAl5QC","heartbeatms":null,"pt":1780839953541,"initialclk":null,"mc":[{"rc":[{"tv":null,"batb":null,"spb":null,"bdatl":null,"trd":null,"spf":null,"ltp":null,"atb":[[9.1999999999999993,436.55000000000001],[9,12.5]],"spl":null,"spn":null,"atl":[[9.8000000000000007,0],[9.5999999999999996,20]],"batl":null,"id":16570658,"hc":null,"bdatb":null},{"tv":null,"batb":null,"spb":null,"bdatl":null,"trd":null,"spf":null,"ltp":null,"atb":[[1.1100000000000001,69511.059999999998]],"spl":null,"spn":null,"atl":[[1.1299999999999999,45180.300000000003]],"batl":null,"id":19924823,"hc":null,"bdatb":null}],"img":null,"tv":null,"con":null,"marketdefinition":null,"id":"1.258926623"}],"conflatems":null,"op":"mcm","id":3}
{"ct":null,"SegmentType":null,"clk":"ALmuAgCasAIAo5QC","heartbeatms":null,"pt":1780839953745,"initialclk":null,"mc":[{"rc":[{"tv":null,"batb":null,"spb":null,"bdatl":null,"trd":null,"spf":null,"ltp":null,"atb":null,"spl":null,"spn":null,"atl":[[9.4000000000000004,5]],"batl":null,"id":16570658,"hc":null,"bdatb":null},{"tv":null,"batb":null,"spb":null,"bdatl":null,"trd":null,"spf":null,"ltp":null,"atb":[[1.1000000000000001,70625.320000000007]],"spl":null,"spn":null,"atl":[[1.1399999999999999,23270.669999999998],[1.1499999999999999,28114.43]],"batl":null,"id":19924823,"hc":null,"bdatb":null}],"img":null,"tv":null,"con":null,"marketdefinition":null,"id":"1.258926623"}],"conflatems":null,"op":"mcm","id":3}
{"ct":null,"SegmentType":null,"clk":"AMWuAgCqsAIAp5QC","heartbeatms":null,"pt":1780839953850,"initialclk":null,"mc":[{"rc":[{"tv":null,"batb":null,"spb":null,"bdatl":null,"trd":null,"spf":null,"ltp":null,"atb":[[1.1100000000000001,69038.25]],"spl":null,"spn":null,"atl":[[1.1299999999999999,43848.010000000002]],"batl":null,"id":19924823,"hc":null,"bdatb":null}],"img":null,"tv":null,"con":null,"marketdefinition":null,"id":"1.258926623"}],"conflatems":null,"op":"mcm","id":3}
{"ct":null,"SegmentType":null,"clk":"AMyuAgCzsAIArpQC","heartbeatms":null,"pt":1780839953952,"initialclk":null,"mc":[{"rc":[{"tv":248427.03,"batb":null,"spb":null,"bdatl":null,"trd":[[9.1999999999999993,1725.74]],"spf":null,"ltp":9.1999999999999993,"atb":[[9.1999999999999993,431.55000000000001]],"spl":null,"spn":null,"atl":null,"batl":null,"id":16570658,"hc":null,"bdatb":null}],"img":null,"tv":2361204.75,"con":null,"marketdefinition":null,"id":"1.258926623"}],"conflatems":null,"op":"mcm","id":3}
{"ct":null,"SegmentType":null,"clk":"AOKuAgDMsAIAw5QC","heartbeatms":null,"pt":1780839954159,"initialclk":null,"mc":[{"rc":[{"tv":2112786.3399999999,"batb":null,"spb":null,"bdatl":null,"trd":[[1.1299999999999999,248858.72]],"spf":null,"ltp":1.1299999999999999,"atb":null,"spl":null,"spn":null,"atl":[[1.1299999999999999,43843.699999999997]],"batl":null,"id":19924823,"hc":null,"bdatb":null}],"img":null,"tv":2361213.3700000001,"con":null,"marketdefinition":null,"id":"1.258926623"}],"conflatems":null,"op":"mcm","id":3}
{"ct":null,"SegmentType":null,"clk":"AMCvAgCssQIAmZUC","heartbeatms":null,"pt":1780839955143,"initialclk":null,"mc":[{"rc":[{"tv":2112831.5,"batb":null,"spb":null,"bdatl":null,"trd":[[1.1200000000000001,66711.460000000006]],"spf":null,"ltp":1.1200000000000001,"atb":[[1.1200000000000001,816.38999999999999]],"spl":null,"spn":null,"atl":null,"batl":null,"id":19924823,"hc":null,"bdatb":null}],"img":null,"tv":2361258.5299999998,"con":null,"marketdefinition":null,"id":"1.258926623"}],"conflatems":null,"op":"mcm","id":3}
{"ct":null,"SegmentType":null,"clk":"APOvAgDTsQIAvpUC","heartbeatms":null,"pt":1780839955560,"initialclk":null,"mc":[{"rc":[{"tv":null,"batb":null,"spb":null,"bdatl":null,"trd":null,"spf":null,"ltp":null,"atb":[[1.03,88975.339999999997]],"spl":null,"spn":null,"atl":null,"batl":null,"id":19924823,"hc":null,"bdatb":null}],"img":null,"tv":null,"con":null,"marketdefinition":null,"id":"1.258926623"}],"conflatems":null,"op":"mcm","id":3}
{"ct":null,"SegmentType":null,"clk":"AJ2wAgD1sQIA55UC","heartbeatms":null,"pt":1780839955972,"initialclk":null,"mc":[{"rc":[{"tv":2112831.6600000001,"batb":null,"spb":null,"bdatl":null,"trd":[[1.1299999999999999,248858.88000000001]],"spf":null,"ltp":1.1299999999999999,"atb":null,"spl":null,"spn":null,"atl":[[1.1299999999999999,43843.620000000003]],"batl":null,"id":19924823,"hc":null,"bdatb":null}],"img":null,"tv":2361258.6899999999,"con":null,"marketdefinition":null,"id":"1.258926623"}],"conflatems":null,"op":"mcm","id":3}
{"ct":null,"SegmentType":null,"clk":"AKKwAgCAsgIA8pUC","heartbeatms":null,"pt":1780839956069,"initialclk":null,"mc":[{"rc":[{"tv":null,"batb":null,"spb":null,"bdatl":null,"trd":null,"spf":null,"ltp":null,"atb":[[1.1100000000000001,69041.5]],"spl":null,"spn":null,"atl":null,"batl":null,"id":19924823,"hc":null,"bdatb":null}],"img":null,"tv":null,"con":null,"marketdefinition":null,"id":"1.258926623"}],"conflatems":null,"op":"mcm","id":3}
{"ct":null,"SegmentType":null,"clk":"AM6wAgCosgIAlJYC","heartbeatms":null,"pt":1780839956435,"initialclk":null,"mc":[{"rc":[{"tv":2112851.6600000001,"batb":null,"spb":null,"bdatl":null,"trd":[[1.1200000000000001,66731.460000000006]],"spf":null,"ltp":1.1200000000000001,"atb":[[1.1200000000000001,806.38999999999999]],"spl":null,"spn":null,"atl":null,"batl":null,"id":19924823,"hc":null,"bdatb":null}],"img":null,"tv":2361278.6899999999,"con":null,"marketdefinition":null,"id":"1.258926623"}],"conflatems":null,"op":"mcm","id":3}
{"ct":null,"SegmentType":null,"clk":"AJ2xAgDxsgIA1JYC","heartbeatms":null,"pt":1780839957164,"initialclk":null,"mc":[{"rc":[{"tv":null,"batb":null,"spb":null,"bdatl":null,"trd":null,"spf":null,"ltp":null,"atb":[[7.7999999999999998,341.04000000000002]],"spl":null,"spn":null,"atl":null,"batl":null,"id":16570658,"hc":null,"bdatb":null},{"tv":null,"batb":null,"spb":null,"bdatl":null,"trd":null,"spf":null,"ltp":null,"atb":null,"spl":null,"spn":null,"atl":[[1.1499999999999999,28109.490000000002]],"batl":null,"id":19924823,"hc":null,"bdatb":null}],"img":null,"tv":null,"con":null,"marketdefinition":null,"id":"1.258926623"}],"conflatems":null,"op":"mcm","id":3}
{"ct":null,"SegmentType":null,"clk":"AJyyAgD5swIAy5cC","heartbeatms":null,"pt":1780839958452,"initialclk":null,"mc":[{"rc":[{"tv":null,"batb":null,"spb":null,"bdatl":null,"trd":null,"spf":null,"ltp":null,"atb":null,"spl":null,"spn":null,"atl":[[1.4199999999999999,2.3900000000000001]],"batl":null,"id":19924823,"hc":null,"bdatb":null}],"img":null,"tv":null,"con":null,"marketdefinition":null,"id":"1.258926623"}],"conflatems":null,"op":"mcm","id":3}
{"ct":null,"SegmentType":null,"clk":"ALmyAgCXtAIA4ZcC","heartbeatms":null,"pt":1780839958760,"initialclk":null,"mc":[{"rc":[{"tv":null,"batb":null,"spb":null,"bdatl":null,"trd":null,"spf":null,"ltp":null,"atb":null,"spl":null,"spn":null,"atl":[[9.8000000000000007,0.34999999999999998]],"batl":null,"id":16570658,"hc":null,"bdatb":null}],"img":null,"tv":null,"con":null,"marketdefinition":null,"id":"1.258926623"}],"conflatems":null,"op":"mcm","id":3}
{"ct":null,"SegmentType":null,"clk":"AMKyAgCftAIA6pcC","heartbeatms":null,"pt":1780839958860,"initialclk":null,"mc":[{"rc":[{"tv":null,"batb":null,"spb":null,"bdatl":null,"trd":null,"spf":null,"ltp":null,"atb":[[1.03,88975.589999999997]],"spl":null,"spn":null,"atl":null,"batl":null,"id":19924823,"hc":null,"bdatb":null}],"img":null,"tv":null,"con":null,"marketdefinition":null,"id":"1.258926623"}],"conflatems":null,"op":"mcm","id":3}
{"ct":null,"SegmentType":null,"clk":"AO\u002ByAgDctAIAh5gC","heartbeatms":null,"pt":1780839959275,"initialclk":null,"mc":[{"rc":[{"tv":null,"batb":null,"spb":null,"bdatl":null,"trd":null,"spf":null,"ltp":null,"atb":[[1.03,88975.339999999997]],"spl":null,"spn":null,"atl":null,"batl":null,"id":19924823,"hc":null,"bdatb":null}],"img":null,"tv":null,"con":null,"marketdefinition":null,"id":"1.258926623"}],"conflatems":null,"op":"mcm","id":3}
{"ct":null,"SegmentType":null,"clk":"ALmzAgD6tAIAuJgC","heartbeatms":null,"pt":1780839959955,"initialclk":null,"mc":[{"rc":[{"tv":null,"batb":null,"spb":null,"bdatl":null,"trd":null,"spf":null,"ltp":null,"atb":[[9.1999999999999993,0]],"spl":null,"spn":null,"atl":null,"batl":null,"id":16570658,"hc":null,"bdatb":null}],"img":null,"tv":null,"con":null,"marketdefinition":null,"id":"1.258926623"}],"conflatems":null,"op":"mcm","id":3}
{"ct":null,"SegmentType":null,"clk":"AOOzAgCutQIA3pgC","heartbeatms":null,"pt":1780839960465,"initialclk":null,"mc":[{"rc":[{"tv":2112882.5699999998,"batb":null,"spb":null,"bdatl":null,"trd":[[1.1299999999999999,248889.79000000001]],"spf":null,"ltp":1.1299999999999999,"atb":null,"spl":null,"spn":null,"atl":[[1.1299999999999999,43828.160000000003]],"batl":null,"id":19924823,"hc":null,"bdatb":null}],"img":null,"tv":2361309.6000000001,"con":null,"marketdefinition":null,"id":"1.258926623"}],"conflatems":null,"op":"mcm","id":3}
{"ct":null,"SegmentType":null,"clk":"AIK0AgDLtQIAgZkC","heartbeatms":null,"pt":1780839960775,"initialclk":null,"mc":[{"rc":[{"tv":null,"batb":null,"spb":null,"bdatl":null,"trd":null,"spf":null,"ltp":null,"atb":null,"spl":null,"spn":null,"atl":[[9.1999999999999993,50]],"batl":null,"id":16570658,"hc":null,"bdatb":null}],"img":null,"tv":null,"con":null,"marketdefinition":null,"id":"1.258926623"}],"conflatems":null,"op":"mcm","id":3}
{"ct":null,"SegmentType":null,"clk":"AJO0AgDjtQIAl5kC","heartbeatms":null,"pt":1780839960933,"initialclk":null,"mc":[{"rc":[{"tv":null,"batb":null,"spb":null,"bdatl":null,"trd":null,"spf":null,"ltp":null,"atb":[[9,0]],"spl":null,"spn":null,"atl":null,"batl":null,"id":16570658,"hc":null,"bdatb":null}],"img":null,"tv":null,"con":null,"marketdefinition":null,"id":"1.258926623"}],"conflatems":null,"op":"mcm","id":3}
{"ct":null,"SegmentType":null,"clk":"ANe0AgCltgIA45kC","heartbeatms":null,"pt":1780839961563,"initialclk":null,"mc":[{"rc":[{"tv":2112884.4900000002,"batb":null,"spb":null,"bdatl":null,"trd":[[1.1299999999999999,248891.70999999999]],"spf":null,"ltp":null,"atb":null,"spl":null,"spn":null,"atl":[[1.1299999999999999,43827.199999999997]],"batl":null,"id":19924823,"hc":null,"bdatb":null}],"img":null,"tv":2361311.52,"con":null,"marketdefinition":null,"id":"1.258926623"}],"conflatems":null,"op":"mcm","id":3}
{"ct":null,"SegmentType":null,"clk":"AO20AgC9tgIAh5oC","heartbeatms":null,"pt":1780839961865,"initialclk":null,"mc":[{"rc":[{"tv":2112885.0699999998,"batb":null,"spb":null,"bdatl":null,"trd":[[1.1299999999999999,248892.29000000001]],"spf":null,"ltp":null,"atb":null,"spl":null,"spn":null,"atl":[[1.1299999999999999,43826.910000000003]],"batl":null,"id":19924823,"hc":null,"bdatb":null}],"img":null,"tv":2361312.1000000001,"con":null,"marketdefinition":null,"id":"1.258926623"}],"conflatems":null,"op":"mcm","id":3}
{"ct":null,"SegmentType":null,"clk":"AKO1AgDwtgIAvpoC","heartbeatms":null,"pt":1780839962335,"initialclk":null,"mc":[{"rc":[{"tv":2112885.5800000001,"batb":null,"spb":null,"bdatl":null,"trd":[[1.1299999999999999,248892.79999999999]],"spf":null,"ltp":null,"atb":null,"spl":null,"spn":null,"atl":[[1.1299999999999999,43826.660000000003]],"batl":null,"id":19924823,"hc":null,"bdatb":null}],"img":null,"tv":2361312.6099999999,"con":null,"marketdefinition":null,"id":"1.258926623"}],"conflatems":null,"op":"mcm","id":3}
{"ct":null,"SegmentType":null,"clk":"ANa1AgCftwIA\u002B5oC","heartbeatms":null,"pt":1780839962853,"initialclk":null,"mc":[{"rc":[{"tv":null,"batb":null,"spb":null,"bdatl":null,"trd":null,"spf":null,"ltp":null,"atb":[[1.03,88974.589999999997]],"spl":null,"spn":null,"atl":null,"batl":null,"id":19924823,"hc":null,"bdatb":null}],"img":null,"tv":null,"con":null,"marketdefinition":null,"id":"1.258926623"}],"conflatems":null,"op":"mcm","id":3}
{"ct":null,"SegmentType":null,"clk":"AJC3AgDzuAIA3JwC","heartbeatms":null,"pt":1780839964970,"initialclk":null,"mc":[{"rc":[{"tv":null,"batb":null,"spb":null,"bdatl":null,"trd":null,"spf":null,"ltp":null,"atb":null,"spl":null,"spn":null,"atl":[[1.1299999999999999,26551.02]],"batl":null,"id":19924823,"hc":null,"bdatb":null}],"img":null,"tv":null,"con":null,"marketdefinition":null,"id":"1.258926623"}],"conflatems":null,"op":"mcm","id":3}
{"ct":null,"SegmentType":null,"clk":"AJ63AgCDuQIA7JwC","heartbeatms":null,"pt":1780839965169,"initialclk":null,"mc":[{"rc":[{"tv":null,"batb":null,"spb":null,"bdatl":null,"trd":null,"spf":null,"ltp":null,"atb":[[1.1000000000000001,70577.880000000005]],"spl":null,"spn":null,"atl":null,"batl":null,"id":19924823,"hc":null,"bdatb":null}],"img":null,"tv":null,"con":null,"marketdefinition":null,"id":"1.258926623"}],"conflatems":null,"op":"mcm","id":3}
{"ct":null,"SegmentType":null,"clk":"ALu3AgCZuQIAkJ0C","heartbeatms":null,"pt":1780839965483,"initialclk":null,"mc":[{"rc":[{"tv":null,"batb":null,"spb":null,"bdatl":null,"trd":null,"spf":null,"ltp":null,"atb":[[1.1200000000000001,805.57000000000005]],"spl":null,"spn":null,"atl":null,"batl":null,"id":19924823,"hc":null,"bdatb":null}],"img":null,"tv":null,"con":null,"marketdefinition":null,"id":"1.258926623"}],"conflatems":null,"op":"mcm","id":3}
{"ct":null,"SegmentType":null,"clk":"AIW5AgDcugIAtZ4C","heartbeatms":null,"pt":1780839967354,"initialclk":null,"mc":[{"rc":[{"tv":2112887.5,"batb":null,"spb":null,"bdatl":null,"trd":[[1.1299999999999999,248894.72]],"spf":null,"ltp":null,"atb":null,"spl":null,"spn":null,"atl":[[1.1299999999999999,18787.259999999998]],"batl":null,"id":19924823,"hc":null,"bdatb":null}],"img":null,"tv":2361314.5299999998,"con":null,"marketdefinition":null,"id":"1.258926623"}],"conflatems":null,"op":"mcm","id":3}
{"ct":null,"SegmentType":null,"clk":"AJ26AgDluwIAzJ8C","heartbeatms":null,"pt":1780839968554,"initialclk":null,"mc":[{"rc":[{"tv":null,"batb":null,"spb":null,"bdatl":null,"trd":null,"spf":null,"ltp":null,"atb":[[1.1200000000000001,18523.459999999999]],"spl":null,"spn":null,"atl":null,"batl":null,"id":19924823,"hc":null,"bdatb":null}],"img":null,"tv":null,"con":null,"marketdefinition":null,"id":"1.258926623"}],"conflatems":null,"op":"mcm","id":3}
{"ct":null,"SegmentType":null,"clk":"AMC6AgD/uwIA5Z8C","heartbeatms":null,"pt":1780839968870,"initialclk":null,"mc":[{"rc":[{"tv":null,"batb":null,"spb":null,"bdatl":null,"trd":null,"spf":null,"ltp":null,"atb":[[8.5999999999999996,130.94999999999999]],"spl":null,"spn":null,"atl":null,"batl":null,"id":16570658,"hc":null,"bdatb":null}],"img":null,"tv":null,"con":null,"marketdefinition":null,"id":"1.258926623"}],"conflatems":null,"op":"mcm","id":3}
{"ct":null,"SegmentType":null,"clk":"AMy6AgCGvAIA758C","heartbeatms":null,"pt":1780839968975,"initialclk":null,"mc":[{"rc":[{"tv":null,"batb":null,"spb":null,"bdatl":null,"trd":null,"spf":null,"ltp":null,"atb":[[8.5999999999999996,230.94999999999999]],"spl":null,"spn":null,"atl":null,"batl":null,"id":16570658,"hc":null,"bdatb":null}],"img":null,"tv":null,"con":null,"marketdefinition":null,"id":"1.258926623"}],"conflatems":null,"op":"mcm","id":3}
{"ct":null,"SegmentType":null,"clk":"AOS6AgCgvAIAhKAC","heartbeatms":null,"pt":1780839969179,"initialclk":null,"mc":[{"rc":[{"tv":null,"batb":null,"spb":null,"bdatl":null,"trd":null,"spf":null,"ltp":null,"atb":[[8.5999999999999996,330.94999999999999]],"spl":null,"spn":null,"atl":null,"batl":null,"id":16570658,"hc":null,"bdatb":null}],"img":null,"tv":null,"con":null,"marketdefinition":null,"id":"1.258926623"}],"conflatems":null,"op":"mcm","id":3}
{"ct":null,"SegmentType":null,"clk":"APS6AgCuvAIAi6AC","heartbeatms":null,"pt":1780839969282,"initialclk":null,"mc":[{"rc":[{"tv":null,"batb":null,"spb":null,"bdatl":null,"trd":null,"spf":null,"ltp":null,"atb":[[8.5999999999999996,430.94999999999999]],"spl":null,"spn":null,"atl":null,"batl":null,"id":16570658,"hc":null,"bdatb":null}],"img":null,"tv":null,"con":null,"marketdefinition":null,"id":"1.258926623"}],"conflatems":null,"op":"mcm","id":3}
{"ct":null,"SegmentType":null,"clk":"AJa7AgDJvAIAoKAC","heartbeatms":null,"pt":1780839969544,"initialclk":null,"mc":[{"rc":[{"tv":null,"batb":null,"spb":null,"bdatl":null,"trd":null,"spf":null,"ltp":null,"atb":[[1.1200000000000001,18773.459999999999]],"spl":null,"spn":null,"atl":[[1.1299999999999999,9928.3199999999997]],"batl":null,"id":19924823,"hc":null,"bdatb":null}],"img":null,"tv":null,"con":null,"marketdefinition":null,"id":"1.258926623"}],"conflatems":null,"op":"mcm","id":3}
{"ct":null,"SegmentType":null,"clk":"AKC7AgDtvAIAp6AC","heartbeatms":null,"pt":1780839969650,"initialclk":null,"mc":[{"rc":[{"tv":null,"batb":null,"spb":null,"bdatl":null,"trd":null,"spf":null,"ltp":null,"atb":[[8.5999999999999996,530.95000000000005]],"spl":null,"spn":null,"atl":null,"batl":null,"id":16570658,"hc":null,"bdatb":null}],"img":null,"tv":null,"con":null,"marketdefinition":null,"id":"1.258926623"}],"conflatems":null,"op":"mcm","id":3}
{"ct":null,"SegmentType":null,"clk":"AKq7AgDevAIArKAC","heartbeatms":null,"pt":1780839969753,"initialclk":null,"mc":[{"rc":[{"tv":null,"batb":null,"spb":null,"bdatl":null,"trd":null,"spf":null,"ltp":null,"atb":[[1.1200000000000001,19023.459999999999]],"spl":null,"spn":null,"atl":null,"batl":null,"id":19924823,"hc":null,"bdatb":null}],"img":null,"tv":null,"con":null,"marketdefinition":null,"id":"1.258926623"}],"conflatems":null,"op":"mcm","id":3}
{"ct":null,"SegmentType":null,"clk":"AL\u002B7AgD1vAIAu6AC","heartbeatms":null,"pt":1780839969967,"initialclk":null,"mc":[{"rc":[{"tv":null,"batb":null,"spb":null,"bdatl":null,"trd":null,"spf":null,"ltp":null,"atb":[[1.1200000000000001,19273.459999999999]],"spl":null,"spn":null,"atl":[[1.1299999999999999,1069.3699999999999]],"batl":null,"id":19924823,"hc":null,"bdatb":null}],"img":null,"tv":null,"con":null,"marketdefinition":null,"id":"1.258926623"}],"conflatems":null,"op":"mcm","id":3}
{"ct":null,"SegmentType":null,"clk":"AOG7AgCjvQIA16AC","heartbeatms":null,"pt":1780839970383,"initialclk":null,"mc":[{"rc":[{"tv":null,"batb":null,"spb":null,"bdatl":null,"trd":null,"spf":null,"ltp":null,"atb":null,"spl":null,"spn":null,"atl":[[9.1999999999999993,158.69999999999999],[9,138.88999999999999]],"batl":null,"id":16570658,"hc":null,"bdatb":null},{"tv":null,"batb":null,"spb":null,"bdatl":null,"trd":null,"spf":null,"ltp":null,"atb":[[1.1100000000000001,71329.899999999994],[1.1200000000000001,24144.790000000001]],"spl":null,"spn":null,"atl":null,"batl":null,"id":19924823,"hc":null,"bdatb":null}],"img":null,"tv":null,"con":null,"marketdefinition":null,"id":"1.258926623"}],"conflatems":null,"op":"mcm","id":3}
{"ct":null,"SegmentType":null,"clk":"AOy7AgCqvQIA3aAC","heartbeatms":null,"pt":1780839970476,"initialclk":null,"mc":[{"rc":[{"tv":null,"batb":null,"spb":null,"bdatl":null,"trd":null,"spf":null,"ltp":null,"atb":null,"spl":null,"spn":null,"atl":[[9.4000000000000004,7.8600000000000003],[9.5999999999999996,20.989999999999998]],"batl":null,"id":16570658,"hc":null,"bdatb":null},{"tv":null,"batb":null,"spb":null,"bdatl":null,"trd":null,"spf":null,"ltp":null,"atb":[[1.1100000000000001,71335.490000000005],[1.1200000000000001,24500.080000000002]],"spl":null,"spn":null,"atl":[[1.1299999999999999,924.98000000000002]],"batl":null,"id":19924823,"hc":null,"bdatb":null}],"img":null,"tv":null,"con":null,"marketdefinition":null,"id":"1.258926623"}],"conflatems":null,"op":"mcm","id":3}
{"ct":null,"SegmentType":null,"clk":"APm7AgC1vQIA5aAC","heartbeatms":null,"pt":1780839970587,"initialclk":null,"mc":[{"rc":[{"tv":null,"batb":null,"spb":null,"bdatl":null,"trd":null,"spf":null,"ltp":null,"atb":[[8.5999999999999996,520.40999999999997]],"spl":null,"spn":null,"atl":[[11,105.94],[10.5,10.609999999999999],[9,111.11]],"batl":null,"id":16570658,"hc":null,"bdatb":null},{"tv":null,"batb":null,"spb":null,"bdatl":null,"trd":null,"spf":null,"ltp":null,"atb":[[1.04,73840.729999999996],[1.05,74306.929999999993],[1.0700000000000001,38874.290000000001],[1.0800000000000001,40508.370000000003],[1.0900000000000001,43092.25],[1.0600000000000001,63324.940000000002],[1.02,90733.919999999998],[1.03,88972.589999999997],[1.01,93591.869999999995],[1.1200000000000001,21995.279999999999]],"spl":null,"spn":null,"atl":[[1.1299999999999999,517.48000000000002]],"batl":null,"id":19924823,"hc":null,"bdatb":null}],"img":null,"tv":null,"con":null,"marketdefinition":null,"id":"1.258926623"}],"conflatems":null,"op":"mcm","id":3}
{"ct":null,"SegmentType":null,"clk":"AIK8AgDBvQIA8aAC","heartbeatms":null,"pt":1780839970684,"initialclk":null,"mc":[{"rc":[{"tv":null,"batb":null,"spb":null,"bdatl":null,"trd":null,"spf":null,"ltp":null,"atb":[[7.5999999999999996,148.44]],"spl":null,"spn":null,"atl":null,"batl":null,"id":16570658,"hc":null,"bdatb":null},{"tv":2112891.7000000002,"batb":null,"spb":null,"bdatl":null,"trd":[[1.1299999999999999,248898.92000000001]],"spf":null,"ltp":null,"atb":[[1.1200000000000001,22254.279999999999]],"spl":null,"spn":null,"atl":[[1.1299999999999999,515.38],[1.1499999999999999,28342.490000000002]],"batl":null,"id":19924823,"hc":null,"bdatb":null}],"img":null,"tv":2361318.73,"con":null,"marketdefinition":null,"id":"1.258926623"}],"conflatems":null,"op":"mcm","id":3}
{"ct":null,"SegmentType":null,"clk":"AI28AgDNvQIA\u002BqAC","heartbeatms":null,"pt":1780839970789,"initialclk":null,"mc":[{"rc":[{"tv":null,"batb":null,"spb":null,"bdatl":null,"trd":null,"spf":null,"ltp":null,"atb":[[7.5999999999999996,342.88],[7.4000000000000004,708.63],[8.5999999999999996,501.73000000000002]],"spl":null,"spn":null,"atl":[[12,0]],"batl":null,"id":16570658,"hc":null,"bdatb":null},{"tv":null,"batb":null,"spb":null,"bdatl":null,"trd":null,"spf":null,"ltp":null,"atb":[[1.1200000000000001,26293.759999999998]],"spl":null,"spn":null,"atl":[[1.1299999999999999,276.48000000000002]],"batl":null,"id":19924823,"hc":null,"bdatb":null}],"img":null,"tv":null,"con":null,"marketdefinition":null,"id":"1.258926623"}],"conflatems":null,"op":"mcm","id":3}
{"ct":null,"SegmentType":null,"clk":"AJe8AgDtvQIAgaEC","heartbeatms":null,"pt":1780839970848,"initialclk":null,"mc":[{"rc":[{"tv":null,"batb":null,"spb":null,"bdatl":null,"trd":null,"spf":null,"ltp":null,"atb":[[8.5999999999999996,1.73]],"spl":null,"spn":null,"atl":[[9.1999999999999993,167.22]],"batl":null,"id":16570658,"hc":null,"bdatb":null}],"img":null,"tv":null,"con":null,"marketdefinition":null,"id":"1.258926623"}],"conflatems":null,"op":"mcm","id":3}
{"ct":null,"SegmentType":null,"clk":"AKS8AgDcvQIAiaEC","heartbeatms":null,"pt":1780839970953,"initialclk":null,"mc":[{"rc":[{"tv":null,"batb":null,"spb":null,"bdatl":null,"trd":null,"spf":null,"ltp":null,"atb":[[8,231.25]],"spl":null,"spn":null,"atl":null,"batl":null,"id":16570658,"hc":null,"bdatb":null}],"img":null,"tv":null,"con":null,"marketdefinition":null,"id":"1.258926623"}],"conflatems":null,"op":"mcm","id":3}
{"ct":null,"SegmentType":null,"clk":"AKu8AgDnvQIAkaEC","heartbeatms":null,"pt":1780839971054,"initialclk":null,"mc":[{"rc":[{"tv":null,"batb":null,"spb":null,"bdatl":null,"trd":null,"spf":null,"ltp":null,"atb":[[1.1200000000000001,26296.709999999999]],"spl":null,"spn":null,"atl":null,"batl":null,"id":19924823,"hc":null,"bdatb":null}],"img":null,"tv":null,"con":null,"marketdefinition":null,"id":"1.258926623"}],"conflatems":null,"op":"mcm","id":3}
{"ct":null,"SegmentType":null,"clk":"ALy8AgDyvQIAmKEC","heartbeatms":null,"pt":1780839971163,"initialclk":null,"mc":[{"rc":[{"tv":null,"batb":null,"spb":null,"bdatl":null,"trd":null,"spf":null,"ltp":null,"atb":[[1.1200000000000001,28400.860000000001]],"spl":null,"spn":null,"atl":[[1.1499999999999999,29393.959999999999]],"batl":null,"id":19924823,"hc":null,"bdatb":null}],"img":null,"tv":null,"con":null,"marketdefinition":null,"id":"1.258926623"}],"conflatems":null,"op":"mcm","id":3}
{"ct":null,"SegmentType":null,"clk":"AMq8AgD8vQIAoaEC","heartbeatms":null,"pt":1780839971261,"initialclk":null,"mc":[{"rc":[{"tv":null,"batb":null,"spb":null,"bdatl":null,"trd":null,"spf":null,"ltp":null,"atb":[[1.1000000000000001,69620.679999999993],[1.1100000000000001,70160.970000000001]],"spl":null,"spn":null,"atl":[[1.1399999999999999,22209.98]],"batl":null,"id":19924823,"hc":null,"bdatb":null}],"img":null,"tv":null,"con":null,"marketdefinition":null,"id":"1.258926623"}],"conflatems":null,"op":"mcm","id":3}
{"ct":null,"SegmentType":null,"clk":"AM\u002B8AgCEvgIAraEC","heartbeatms":null,"pt":1780839971366,"initialclk":null,"mc":[{"rc":[{"tv":null,"batb":null,"spb":null,"bdatl":null,"trd":null,"spf":null,"ltp":null,"atb":[[7.4000000000000004,899.57000000000005]],"spl":null,"spn":null,"atl":[[9,277.76999999999998]],"batl":null,"id":16570658,"hc":null,"bdatb":null},{"tv":null,"batb":null,"spb":null,"bdatl":null,"trd":null,"spf":null,"ltp":null,"atb":[[1.1100000000000001,70153.470000000001],[1.1200000000000001,29740.139999999999]],"spl":null,"spn":null,"atl":[[1.1599999999999999,10681.959999999999]],"batl":null,"id":19924823,"hc":null,"bdatb":null}],"img":null,"tv":null,"con":null,"marketdefinition":null,"id":"1.258926623"}],"conflatems":null,"op":"mcm","id":3}
{"ct":null,"SegmentType":null,"clk":"AIO9AgctvgIA3qEC","heartbeatms":null,"pt":1780839971876,"initialclk":null,"mc":[{"rc":[{"tv":null,"batb":null,"spb":null,"bdatl":null,"trd":null,"spf":null,"ltp":null,"atb":null,"spl":null,"spn":null,"atl":[[25,0]],"batl":null,"id":16570658,"hc":null,"bdatb":null}],"img":null,"tv":null,"con":null,"marketdefinition":null,"id":"1.258926623"}],"conflatems":null,"op":"mcm","id":3}
{"ct":null,"SegmentType":null,"clk":"AMS9AgCBvwIAnaIC","heartbeatms":null,"pt":1780839972346,"initialclk":null,"mc":[{"rc":[{"tv":null,"batb":null,"spb":null,"bdatl":null,"trd":null,"spf":null,"ltp":null,"atb":null,"spl":null,"spn":null,"atl":[[19.5,44.229999999999997]],"batl":null,"id":16570658,"hc":null,"bdatb":null}],"img":null,"tv":null,"con":null,"marketdefinition":null,"id":"1.258926623"}],"conflatems":null,"op":"mcm","id":3}
{"ct":null,"SegmentType":null,"clk":"AJe\u002BAgDrvwIA7qIC","heartbeatms":null,"pt":1780839973181,"initialclk":null,"mc":[{"rc":[{"tv":null,"batb":null,"spb":null,"bdatl":null,"trd":null,"spf":null,"ltp":null,"atb":null,"spl":null,"spn":null,"atl":[[9.8000000000000007,0]],"batl":null,"id":16570658,"hc":null,"bdatb":null},{"tv":null,"batb":null,"spb":null,"bdatl":null,"trd":null,"spf":null,"ltp":null,"atb":null,"spl":null,"spn":null,"atl":[[1.1399999999999999,23209.98]],"batl":null,"id":19924823,"hc":null,"bdatb":null}],"img":null,"tv":null,"con":null,"marketdefinition":null,"id":"1.258926623"}],"conflatems":null,"op":"mcm","id":3}
{"ct":null,"SegmentType":null,"clk":"AKi\u002BAgD5vwIA9qIC","heartbeatms":null,"pt":1780839973284,"initialclk":null,"mc":[{"rc":[{"tv":null,"batb":null,"spb":null,"bdatl":null,"trd":null,"spf":null,"ltp":null,"atb":null,"spl":null,"spn":null,"atl":[[1.1399999999999999,24209.98]],"batl":null,"id":19924823,"hc":null,"bdatb":null}],"img":null,"tv":null,"con":null,"marketdefinition":null,"id":"1.258926623"}],"conflatems":null,"op":"mcm","id":3}
{"ct":null,"SegmentType":null,"clk":"AKu\u002BAgCCwAIA/qIC","heartbeatms":null,"pt":1780839973379,"initialclk":null,"mc":[{"rc":[{"tv":null,"batb":null,"spb":null,"bdatl":null,"trd":null,"spf":null,"ltp":null,"atb":[[8,331.25]],"spl":null,"spn":null,"atl":null,"batl":null,"id":16570658,"hc":null,"bdatb":null}],"img":null,"tv":null,"con":null,"marketdefinition":null,"id":"1.258926623"}],"conflatems":null,"op":"mcm","id":3}
{"ct":null,"SegmentType":null,"clk":"AMK\u002BAgCrwAIAnqMC","heartbeatms":null,"pt":1780839973689,"initialclk":null,"mc":[{"rc":[{"tv":null,"batb":null,"spb":null,"bdatl":null,"trd":null,"spf":null,"ltp":null,"atb":[[8,431.25]],"spl":null,"spn":null,"atl":null,"batl":null,"id":16570658,"hc":null,"bdatb":null}],"img":null,"tv":null,"con":null,"marketdefinition":null,"id":"1.258926623"}],"conflatems":null,"op":"mcm","id":3}
{"ct":null,"SegmentType":null,"clk":"AM6\u002BAgC6wAIArKMC","heartbeatms":null,"pt":1780839973755,"initialclk":null,"mc":[{"rc":[{"tv":2112906.6899999999,"batb":null,"spb":null,"bdatl":null,"trd":[[1.1299999999999999,248913.91]],"spf":null,"ltp":null,"atb":null,"spl":null,"spn":null,"atl":[[1.1299999999999999,268.99000000000001]],"batl":null,"id":19924823,"hc":null,"bdatb":null}],"img":null,"tv":2361333.7200000002,"con":null,"marketdefinition":null,"id":"1.258926623"}],"conflatems":null,"op":"mcm","id":3}
{"ct":null,"SegmentType":null,"clk":"ANm\u002BAgDIwAIAtqMC","heartbeatms":null,"pt":1780839973848,"initialclk":null,"mc":[{"rc":[{"tv":null,"batb":null,"spb":null,"bdatl":null,"trd":null,"spf":null,"ltp":null,"atb":[[8,519.25]],"spl":null,"spn":null,"atl":[[10.5,98.609999999999999]],"batl":null,"id":16570658,"hc":null,"bdatb":null},{"tv":null,"batb":null,"spb":null,"bdatl":null,"trd":null,"spf":null,"ltp":null,"atb":[[1.1000000000000001,71350.679999999993]],"spl":null,"spn":null,"atl":[[1.1499999999999999,30931.959999999999]],"batl":null,"id":19924823,"hc":null,"bdatb":null}],"img":null,"tv":null,"con":null,"marketdefinition":null,"id":"1.258926623"}],"conflatems":null,"op":"mcm","id":3}
{"ct":null,"SegmentType":null,"clk":"AOS\u002BAgDWwAIAvKMC","heartbeatms":null,"pt":1780839973951,"initialclk":null,"mc":[{"rc":[{"tv":null,"batb":null,"spb":null,"bdatl":null,"trd":null,"spf":null,"ltp":null,"atb":null,"spl":null,"spn":null,"atl":[[9,111.11]],"batl":null,"id":16570658,"hc":null,"bdatb":null}],"img":null,"tv":null,"con":null,"marketdefinition":null,"id":"1.258926623"}],"conflatems":null,"op":"mcm","id":3}
{"ct":null,"SegmentType":null,"clk":"APW\u002BAgDxwAIAyqMC","heartbeatms":null,"pt":1780839974157,"initialclk":null,"mc":[{"rc":[{"tv":null,"batb":null,"spb":null,"bdatl":null,"trd":null,"spf":null,"ltp":null,"atb":null,"spl":null,"spn":null,"atl":[[1.1599999999999999,9463.8600000000006]],"batl":null,"id":19924823,"hc":null,"bdatb":null}],"img":null,"tv":null,"con":null,"marketdefinition":null,"id":"1.258926623"}],"conflatems":null,"op":"mcm","id":3}
{"ct":null,"SegmentType":null,"clk":"AIu/AgCWwQIA26MC","heartbeatms":null,"pt":1780839974364,"initialclk":null,"mc":[{"rc":[{"tv":null,"batb":null,"spb":null,"bdatl":null,"trd":null,"spf":null,"ltp":null,"atb":null,"spl":null,"spn":null,"atl":[[1.1299999999999999,701.34000000000003]],"batl":null,"id":19924823,"hc":null,"bdatb":null}],"img":null,"tv":null,"con":null,"marketdefinition":null,"id":"1.258926623"}],"conflatems":null,"op":"mcm","id":3}
{"ct":null,"SegmentType":null,"clk":"AJK/AgCmwQIA5aMC","heartbeatms":null,"pt":1780839974467,"initialclk":null,"mc":[{"rc":[{"tv":null,"batb":null,"spb":null,"bdatl":null,"trd":null,"spf":null,"ltp":null,"atb":[[8.5999999999999996,46.719999999999999]],"spl":null,"spn":null,"atl":[[9,249.84]],"batl":null,"id":16570658,"hc":null,"bdatb":null},{"tv":null,"batb":null,"spb":null,"bdatl":null,"trd":null,"spf":null,"ltp":null,"atb":[[1.1200000000000001,30854.93]],"spl":null,"spn":null,"atl":[[1.1399999999999999,25305.220000000001]],"batl":null,"id":19924823,"hc":null,"bdatb":null}],"img":null,"tv":null,"con":null,"marketdefinition":null,"id":"1.258926623"}],"conflatems":null,"op":"mcm","id":3}
