{"ct":null,"SegmentType":null,"clk":"AJu/AgCzwQIA9KMC","heartbeatms":null,"pt":1780839974572,"initialclk":null,"mc":[{"rc":[{"tv":null,"batb":null,"spb":null,"bdatl":null,"trd":null,"spf":null,"ltp":null,"atb":[[6.7999999999999998,0.40000000000000002]],"spl":null,"spn":null,"atl":null,"batl":null,"id":16570658,"hc":null,"bdatb":null}],"img":null,"tv":null,"con":null,"marketdefinition":null,"id":"1.258926623"}],"conflatems":null,"op":"mcm","id":3}
{"ct":null,"SegmentType":null,"clk":"AKO/AgDBwQIA\u002B6MC","heartbeatms":null,"pt":1780839974673,"initialclk":null,"mc":[{"rc":[{"tv":null,"batb":null,"spb":null,"bdatl":null,"trd":null,"spf":null,"ltp":null,"atb":[[8,539.25]],"spl":null,"spn":null,"atl":null,"batl":null,"id":16570658,"hc":null,"bdatb":null}],"img":null,"tv":null,"con":null,"marketdefinition":null,"id":"1.258926623"}],"conflatems":null,"op":"mcm","id":3}
{"ct":null,"SegmentType":null,"clk":"AMa/AgDkwQIAoKQC","heartbeatms":null,"pt":1780839975081,"initialclk":null,"mc":[{"rc":[{"tv":null,"batb":null,"spb":null,"bdatl":null,"trd":null,"spf":null,"ltp":null,"atb":[[8,339.25]],"spl":null,"spn":null,"atl":null,"batl":null,"id":16570658,"hc":null,"bdatb":null}],"img":null,"tv":null,"con":null,"marketdefinition":null,"id":"1.258926623"}],"conflatems":null,"op":"mcm","id":3}
{"ct":null,"SegmentType":null,"clk":"ANG/AgDxwQIApqQC","heartbeatms":null,"pt":1780839975187,"initialclk":null,"mc":[{"rc":[{"tv":null,"batb":null,"spb":null,"bdatl":null,"trd":null,"spf":null,"ltp":null,"atb":[[8.1999999999999993,219.44]],"spl":null,"spn":null,"atl":null,"batl":null,"id":16570658,"hc":null,"bdatb":null}],"img":null,"tv":null,"con":null,"marketdefinition":null,"id":"1.258926623"}],"conflatems":null,"op":"mcm","id":3}
{"ct":null,"SegmentType":null,"clk":"ANe/AgD6wQIAraQC","heartbeatms":null,"pt":1780839975289,"initialclk":null,"mc":[{"rc":[{"tv":null,"batb":null,"spb":null,"bdatl":null,"trd":null,"spf":null,"ltp":null,"atb":null,"spl":null,"spn":null,"atl":[[1.1699999999999999,8889.2600000000002]],"batl":null,"id":19924823,"hc":null,"bdatb":null}],"img":null,"tv":null,"con":null,"marketdefinition":null,"id":"1.258926623"}],"conflatems":null,"op":"mcm","id":3}
{"ct":null,"SegmentType":null,"clk":"AOG/AgCCwgIAt6QC","heartbeatms":null,"pt":1780839975344,"initialclk":null,"mc":[{"rc":[{"tv":null,"batb":null,"spb":null,"bdatl":null,"trd":null,"spf":null,"ltp":null,"atb":null,"spl":null,"spn":null,"atl":[[1.1499999999999999,30933.959999999999]],"batl":null,"id":19924823,"hc":null,"bdatb":null}],"img":null,"tv":null,"con":null,"marketdefinition":null,"id":"1.258926623"}],"conflatems":null,"op":"mcm","id":3}
{"ct":null,"SegmentType":null,"clk":"APG/AgCZwgIAxqQC","heartbeatms":null,"pt":1780839975551,"initialclk":null,"mc":[{"rc":[{"tv":null,"batb":null,"spb":null,"bdatl":null,"trd":null,"spf":null,"ltp":null,"atb":null,"spl":null,"spn":null,"atl":[[1.1499999999999999,30931.959999999999]],"batl":null,"id":19924823,"hc":null,"bdatb":null}],"img":null,"tv":null,"con":null,"marketdefinition":null,"id":"1.258926623"}],"conflatems":null,"op":"mcm","id":3}
{"ct":null,"SegmentType":null,"clk":"APy/AgCwwgIA06QC","heartbeatms":null,"pt":1780839975756,"initialclk":null,"mc":[{"rc":[{"tv":null,"batb":null,"spb":null,"bdatl":null,"trd":null,"spf":null,"ltp":null,"atb":[[8.4000000000000004,13.51]],"spl":null,"spn":null,"atl":null,"batl":null,"id":16570658,"hc":null,"bdatb":null}],"img":null,"tv":null,"con":null,"marketdefinition":null,"id":"1.258926623"}],"conflatems":null,"op":"mcm","id":3}
{"ct":null,"SegmentType":null,"clk":"AJHAAgDEwgIA46QC","heartbeatms":null,"pt":1780839975966,"initialclk":null,"mc":[{"rc":[{"tv":null,"batb":null,"spb":null,"bdatl":null,"trd":null,"spf":null,"ltp":null,"atb":[[1.1200000000000001,29515.650000000001]],"spl":null,"spn":null,"atl":null,"batl":null,"id":19924823,"hc":null,"bdatb":null}],"img":null,"tv":null,"con":null,"marketdefinition":null,"id":"1.258926623"}],"conflatems":null,"op":"mcm","id":3}
{"ct":null,"SegmentType":null,"clk":"AJ7AAgDQwgIA7qQC","heartbeatms":null,"pt":1780839976068,"initialclk":null,"mc":[{"rc":[{"tv":null,"batb":null,"spb":null,"bdatl":null,"trd":null,"spf":null,"ltp":null,"atb":null,"spl":null,"spn":null,"atl":[[1.1599999999999999,26739.490000000002]],"batl":null,"id":19924823,"hc":null,"bdatb":null}],"img":null,"tv":null,"con":null,"marketdefinition":null,"id":"1.258926623"}],"conflatems":null,"op":"mcm","id":3}
{"ct":null,"SegmentType":null,"clk":"AMHAAgD1wgIAlKUC","heartbeatms":null,"pt":1780839976479,"initialclk":null,"mc":[{"rc":[{"tv":null,"batb":null,"spb":null,"bdatl":null,"trd":null,"spf":null,"ltp":null,"atb":null,"spl":null,"spn":null,"atl":[[1.1399999999999999,26305.220000000001]],"batl":null,"id":19924823,"hc":null,"bdatb":null}],"img":null,"tv":null,"con":null,"marketdefinition":null,"id":"1.258926623"}],"conflatems":null,"op":"mcm","id":3}
{"ct":null,"SegmentType":null,"clk":"AOfAAgCcwwIAuaUC","heartbeatms":null,"pt":1780839976891,"initialclk":null,"mc":[{"rc":[{"tv":2113066.02,"batb":null,"spb":null,"bdatl":null,"trd":[[1.1299999999999999,249073.23999999999]],"spf":null,"ltp":null,"atb":null,"spl":null,"spn":null,"atl":[[1.1299999999999999,621.66999999999996]],"batl":null,"id":19924823,"hc":null,"bdatb":null}],"img":null,"tv":2361493.0499999998,"con":null,"marketdefinition":null,"id":"1.258926623"}],"conflatems":null,"op":"mcm","id":3}
{"ct":null,"SegmentType":null,"clk":"APzAAgCswwIA0qUC","heartbeatms":null,"pt":1780839977053,"initialclk":null,"mc":[{"rc":[{"tv":null,"batb":null,"spb":null,"bdatl":null,"trd":null,"spf":null,"ltp":null,"atb":[[1.04,73842.729999999996],[1.05,74308.929999999993],[1.0700000000000001,38876.290000000001],[1.0800000000000001,40510.370000000003],[1.0900000000000001,43094.25],[1.0600000000000001,63326.940000000002],[1.02,90735.919999999998],[1.03,88974.589999999997],[1.01,93593.869999999995]],"spl":null,"spn":null,"atl":null,"batl":null,"id":19924823,"hc":null,"bdatb":null}],"img":null,"tv":null,"con":null,"marketdefinition":null,"id":"1.258926623"}],"conflatems":null,"op":"mcm","id":3}
{"ct":null,"SegmentType":null,"clk":"AIPBAgC0wwIA3KUC","heartbeatms":null,"pt":1780839977156,"initialclk":null,"mc":[{"rc":[{"tv":null,"batb":null,"spb":null,"bdatl":null,"trd":null,"spf":null,"ltp":null,"atb":[[8.1999999999999993,319.44]],"spl":null,"spn":null,"atl":null,"batl":null,"id":16570658,"hc":null,"bdatb":null}],"img":null,"tv":null,"con":null,"marketdefinition":null,"id":"1.258926623"}],"conflatems":null,"op":"mcm","id":3}
{"ct":null,"SegmentType":null,"clk":"AJnBAgDWwwIAhqYC","heartbeatms":null,"pt":1780839977463,"initialclk":null,"mc":[{"rc":[{"tv":null,"batb":null,"spb":null,"bdatl":null,"trd":null,"spf":null,"ltp":null,"atb":[[8.1999999999999993,419.44]],"spl":null,"spn":null,"atl":null,"batl":null,"id":16570658,"hc":null,"bdatb":null},{"tv":2114309.3599999999,"batb":null,"spb":null,"bdatl":null,"trd":[[1.1299999999999999,250316.57999999999]],"spf":null,"ltp":null,"atb":[[1.1299999999999999,623.03999999999996]],"spl":null,"spn":null,"atl":[[1.1299999999999999,0]],"batl":null,"id":19924823,"hc":null,"bdatb":null}],"img":null,"tv":2362736.3900000001,"con":null,"marketdefinition":null,"id":"1.258926623"}],"conflatems":null,"op":"mcm","id":3}
{"ct":null,"SegmentType":null,"clk":"AKjBAgDiwwIAlKYC","heartbeatms":null,"pt":1780839977568,"initialclk":null,"mc":[{"rc":[{"tv":null,"batb":null,"spb":null,"bdatl":null,"trd":null,"spf":null,"ltp":null,"atb":null,"spl":null,"spn":null,"atl":[[8.8000000000000007,138.62000000000001]],"batl":null,"id":16570658,"hc":null,"bdatb":null},{"tv":null,"batb":null,"spb":null,"bdatl":null,"trd":null,"spf":null,"ltp":null,"atb":null,"spl":null,"spn":null,"atl":[[1.1399999999999999,28569.470000000001]],"batl":null,"id":19924823,"hc":null,"bdatb":null}],"img":null,"tv":null,"con":null,"marketdefinition":null,"id":"1.258926623"}],"conflatems":null,"op":"mcm","id":3}
{"ct":null,"SegmentType":null,"clk":"ALLBAgDwwwIAn6YC","heartbeatms":null,"pt":1780839977671,"initialclk":null,"mc":[{"rc":[{"tv":null,"batb":null,"spb":null,"bdatl":null,"trd":null,"spf":null,"ltp":null,"atb":[[1.1200000000000001,29162.360000000001]],"spl":null,"spn":null,"atl":null,"batl":null,"id":19924823,"hc":null,"bdatb":null}],"img":null,"tv":null,"con":null,"marketdefinition":null,"id":"1.258926623"}],"conflatems":null,"op":"mcm","id":3}
{"ct":null,"SegmentType":null,"clk":"AMfBAgCDxAIAtKYC","heartbeatms":null,"pt":1780839977874,"initialclk":null,"mc":[{"rc":[{"tv":248642.97,"batb":null,"spb":null,"bdatl":null,"trd":[[8.8000000000000007,1957.5799999999999]],"spf":null,"ltp":8.8000000000000007,"atb":[[6.5999999999999996,0.98999999999999999],[6.7999999999999998,1.26],[7.4000000000000004,900.42999999999995]],"spl":null,"spn":null,"atl":[[8.8000000000000007,30.649999999999999],[10.5,99.599999999999994],[10,95.109999999999999]],"batl":null,"id":16570658,"hc":null,"bdatb":null},{"tv":null,"batb":null,"spb":null,"bdatl":null,"trd":null,"spf":null,"ltp":null,"atb":[[1.1000000000000001,71357.259999999995],[1.1100000000000001,70159]],"spl":null,"spn":null,"atl":[[1.19,8879.5200000000004],[1.1599999999999999,26743.75],[1.1799999999999999,8877.8999999999996]],"batl":null,"id":19924823,"hc":null,"bdatb":null}],"img":null,"tv":2362952.3300000001,"con":null,"marketdefinition":null,"id":"1.258926623"}],"conflatems":null,"op":"mcm","id":3}
{"ct":null,"SegmentType":null,"clk":"ANTBAgCQxAIAvaYC","heartbeatms":null,"pt":1780839977981,"initialclk":null,"mc":[{"rc":[{"tv":null,"batb":null,"spb":null,"bdatl":null,"trd":null,"spf":null,"ltp":null,"atb":[[8.4000000000000004,147.19]],"spl":null,"spn":null,"atl":null,"batl":null,"id":16570658,"hc":null,"bdatb":null}],"img":null,"tv":null,"con":null,"marketdefinition":null,"id":"1.258926623"}],"conflatems":null,"op":"mcm","id":3}
{"ct":null,"SegmentType":null,"clk":"AOHBAgCaxAIAxKYC","heartbeatms":null,"pt":1780839978083,"initialclk":null,"mc":[{"rc":[{"tv":null,"batb":null,"spb":null,"bdatl":null,"trd":null,"spf":null,"ltp":null,"atb":[[1.1200000000000001,29176.790000000001]],"spl":null,"spn":null,"atl":null,"batl":null,"id":19924823,"hc":null,"bdatb":null}],"img":null,"tv":null,"con":null,"marketdefinition":null,"id":"1.258926623"}],"conflatems":null,"op":"mcm","id":3}
{"ct":null,"SegmentType":null,"clk":"APvBAgC6xAIA26YC","heartbeatms":null,"pt":1780839978386,"initialclk":null,"mc":[{"rc":[{"tv":null,"batb":null,"spb":null,"bdatl":null,"trd":null,"spf":null,"ltp":null,"atb":null,"spl":null,"spn":null,"atl":[[9.1999999999999993,158.69999999999999]],"batl":null,"id":16570658,"hc":null,"bdatb":null},{"tv":null,"batb":null,"spb":null,"bdatl":null,"trd":null,"spf":null,"ltp":null,"atb":[[1.1299999999999999,623.15999999999997]],"spl":null,"spn":null,"atl":null,"batl":null,"id":19924823,"hc":null,"bdatb":null}],"img":null,"tv":null,"con":null,"marketdefinition":null,"id":"1.258926623"}],"conflatems":null,"op":"mcm","id":3}
{"ct":null,"SegmentType":null,"clk":"AIjCAgDDxAIA46YC","heartbeatms":null,"pt":1780839978494,"initialclk":null,"mc":[{"rc":[{"tv":null,"batb":null,"spb":null,"bdatl":null,"trd":null,"spf":null,"ltp":null,"atb":[[7,23.32],[7.2000000000000002,23.57]],"spl":null,"spn":null,"atl":null,"batl":null,"id":16570658,"hc":null,"bdatb":null},{"tv":null,"batb":null,"spb":null,"bdatl":null,"trd":null,"spf":null,"ltp":null,"atb":[[1.1299999999999999,0.12]],"spl":null,"spn":null,"atl":[[1.23,681.25999999999999],[1.21,9160.3500000000004]],"batl":null,"id":19924823,"hc":null,"bdatb":null}],"img":null,"tv":null,"con":null,"marketdefinition":null,"id":"1.258926623"}],"conflatems":null,"op":"mcm","id":3}
{"ct":null,"SegmentType":null,"clk":"AKDCAgDlxAIA\u002BaYC","heartbeatms":null,"pt":1780839978759,"initialclk":null,"mc":[{"rc":[{"tv":null,"batb":null,"spb":null,"bdatl":null,"trd":null,"spf":null,"ltp":null,"atb":[[8.5999999999999996,46.789999999999999]],"spl":null,"spn":null,"atl":null,"batl":null,"id":16570658,"hc":null,"bdatb":null},{"tv":null,"batb":null,"spb":null,"bdatl":null,"trd":null,"spf":null,"ltp":null,"atb":[[1.1299999999999999,2.1200000000000001]],"spl":null,"spn":null,"atl":null,"batl":null,"id":19924823,"hc":null,"bdatb":null}],"img":null,"tv":null,"con":null,"marketdefinition":null,"id":"1.258926623"}],"conflatems":null,"op":"mcm","id":3}
{"ct":null,"SegmentType":null,"clk":"AKfCAgDvxAIAgacC","heartbeatms":null,"pt":1780839978861,"initialclk":null,"mc":[{"rc":[{"tv":null,"batb":null,"spb":null,"bdatl":null,"trd":null,"spf":null,"ltp":null,"atb":null,"spl":null,"spn":null,"atl":[[1.22,8889.1000000000004]],"batl":null,"id":19924823,"hc":null,"bdatb":null}],"img":null,"tv":null,"con":null,"marketdefinition":null,"id":"1.258926623"}],"conflatems":null,"op":"mcm","id":3}
{"ct":null,"SegmentType":null,"clk":"AMfCAgCcxQIAp6cC","heartbeatms":null,"pt":1780839979272,"initialclk":null,"mc":[{"rc":[{"tv":248646.56,"batb":null,"spb":null,"bdatl":null,"trd":[[8.5999999999999996,2734.6900000000001]],"spf":null,"ltp":8.5999999999999996,"atb":[[8.5999999999999996,45]],"spl":null,"spn":null,"atl":null,"batl":null,"id":16570658,"hc":null,"bdatb":null}],"img":null,"tv":2362955.9199999999,"con":null,"marketdefinition":null,"id":"1.258926623"}],"conflatems":null,"op":"mcm","id":3}
{"ct":null,"SegmentType":null,"clk":"ANLCAgCqxQIAsacC","heartbeatms":null,"pt":1780839979380,"initialclk":null,"mc":[{"rc":[{"tv":248686.56,"batb":null,"spb":null,"bdatl":null,"trd":[[8.5999999999999996,2774.6900000000001]],"spf":null,"ltp":null,"atb":[[8.5999999999999996,25]],"spl":null,"spn":null,"atl":null,"batl":null,"id":16570658,"hc":null,"bdatb":null}],"img":null,"tv":2362995.9199999999,"con":null,"marketdefinition":null,"id":"1.258926623"}],"conflatems":null,"op":"mcm","id":3}
{"ct":null,"SegmentType":null,"clk":"ANrCAgC1xQIAuKcC","heartbeatms":null,"pt":1780839979480,"initialclk":null,"mc":[{"rc":[{"tv":null,"batb":null,"spb":null,"bdatl":null,"trd":null,"spf":null,"ltp":null,"atb":null,"spl":null,"spn":null,"atl":[[9.1999999999999993,321.74000000000001]],"batl":null,"id":16570658,"hc":null,"bdatb":null},{"tv":null,"batb":null,"spb":null,"bdatl":null,"trd":null,"spf":null,"ltp":null,"atb":[[1.1299999999999999,18.120000000000001],[1.1200000000000001,30516.07]],"spl":null,"spn":null,"atl":[[1.1599999999999999,27976.459999999999]],"batl":null,"id":19924823,"hc":null,"bdatb":null}],"img":null,"tv":null,"con":null,"marketdefinition":null,"id":"1.258926623"}],"conflatems":null,"op":"mcm","id":3}
{"ct":null,"SegmentType":null,"clk":"AJTDAgD7xQIA8acC","heartbeatms":null,"pt":1780839980055,"initialclk":null,"mc":[{"rc":[{"tv":null,"batb":null,"spb":null,"bdatl":null,"trd":null,"spf":null,"ltp":null,"atb":[[7.5999999999999996,531.42999999999995]],"spl":null,"spn":null,"atl":null,"batl":null,"id":16570658,"hc":null,"bdatb":null}],"img":null,"tv":null,"con":null,"marketdefinition":null,"id":"1.258926623"}],"conflatems":null,"op":"mcm","id":3}
{"ct":null,"SegmentType":null,"clk":"AKTDAgCSxgIAgKgC","heartbeatms":null,"pt":1780839980257,"initialclk":null,"mc":[{"rc":[{"tv":null,"batb":null,"spb":null,"bdatl":null,"trd":null,"spf":null,"ltp":null,"atb":[[1.1299999999999999,1262.8299999999999]],"spl":null,"spn":null,"atl":null,"batl":null,"id":19924823,"hc":null,"bdatb":null}],"img":null,"tv":null,"con":null,"marketdefinition":null,"id":"1.258926623"}],"conflatems":null,"op":"mcm","id":3}
{"ct":null,"SegmentType":null,"clk":"ALrDAgCmxgIAkKgC","heartbeatms":null,"pt":1780839980463,"initialclk":null,"mc":[{"rc":[{"tv":null,"batb":null,"spb":null,"bdatl":null,"trd":null,"spf":null,"ltp":null,"atb":[[7.5999999999999996,342.88],[8.5999999999999996,0.070000000000000007]],"spl":null,"spn":null,"atl":null,"batl":null,"id":16570658,"hc":null,"bdatb":null}],"img":null,"tv":null,"con":null,"marketdefinition":null,"id":"1.258926623"}],"conflatems":null,"op":"mcm","id":3}
{"ct":null,"SegmentType":null,"clk":"AMTDAgCwxgIAmKgC","heartbeatms":null,"pt":1780839980570,"initialclk":null,"mc":[{"rc":[{"tv":null,"batb":null,"spb":null,"bdatl":null,"trd":null,"spf":null,"ltp":null,"atb":[[7.4000000000000004,708.63],[7.2000000000000002,22.579999999999998]],"spl":null,"spn":null,"atl":[[9.4000000000000004,7],[9.5999999999999996,20]],"batl":null,"id":16570658,"hc":null,"bdatb":null},{"tv":null,"batb":null,"spb":null,"bdatl":null,"trd":null,"spf":null,"ltp":null,"atb":[[1.1000000000000001,71351.910000000003],[1.1100000000000001,70153.410000000003]],"spl":null,"spn":null,"atl":[[1.1699999999999999,8884.6900000000005],[1.1599999999999999,27971.810000000001]],"batl":null,"id":19924823,"hc":null,"bdatb":null}],"img":null,"tv":null,"con":null,"marketdefinition":null,"id":"1.258926623"}],"conflatems":null,"op":"mcm","id":3}
{"ct":null,"SegmentType":null,"clk":"AOPDAgDQxgIArKgC","heartbeatms":null,"pt":1780839980877,"initialclk":null,"mc":[{"rc":[{"tv":null,"batb":null,"spb":null,"bdatl":null,"trd":null,"spf":null,"ltp":null,"atb":null,"spl":null,"spn":null,"atl":[[1.1399999999999999,26305.220000000001]],"batl":null,"id":19924823,"hc":null,"bdatb":null}],"img":null,"tv":null,"con":null,"marketdefinition":null,"id":"1.258926623"}],"conflatems":null,"op":"mcm","id":3}
{"ct":null,"SegmentType":null,"clk":"APXDAgDixgIAuKgC","heartbeatms":null,"pt":1780839981078,"initialclk":null,"mc":[{"rc":[{"tv":null,"batb":null,"spb":null,"bdatl":null,"trd":null,"spf":null,"ltp":null,"atb":[[8.4000000000000004,176.66999999999999]],"spl":null,"spn":null,"atl":null,"batl":null,"id":16570658,"hc":null,"bdatb":null},{"tv":null,"batb":null,"spb":null,"bdatl":null,"trd":null,"spf":null,"ltp":null,"atb":null,"spl":null,"spn":null,"atl":[[1.1399999999999999,26377.419999999998]],"batl":null,"id":19924823,"hc":null,"bdatb":null}],"img":null,"tv":null,"con":null,"marketdefinition":null,"id":"1.258926623"}],"conflatems":null,"op":"mcm","id":3}
{"ct":null,"SegmentType":null,"clk":"AKjEAgCnxwIA8agC","heartbeatms":null,"pt":1780839981657,"initialclk":null,"mc":[{"rc":[{"tv":248692.09,"batb":null,"spb":null,"bdatl":null,"trd":[[8.8000000000000007,1963.1099999999999]],"spf":null,"ltp":8.8000000000000007,"atb":null,"spl":null,"spn":null,"atl":[[8.8000000000000007,27.890000000000001]],"batl":null,"id":16570658,"hc":null,"bdatb":null}],"img":null,"tv":2363001.4500000002,"con":null,"marketdefinition":null,"id":"1.258926623"}],"conflatems":null,"op":"mcm","id":3}
{"ct":null,"SegmentType":null,"clk":"ALHEAgCyxwIA\u002BKgC","heartbeatms":null,"pt":1780839981758,"initialclk":null,"mc":[{"rc":[{"tv":248692.22,"batb":null,"spb":null,"bdatl":null,"trd":[[8.8000000000000007,1963.24]],"spf":null,"ltp":null,"atb":null,"spl":null,"spn":null,"atl":[[8.8000000000000007,27.82]],"batl":null,"id":16570658,"hc":null,"bdatb":null},{"tv":null,"batb":null,"spb":null,"bdatl":null,"trd":null,"spf":null,"ltp":null,"atb":null,"spl":null,"spn":null,"atl":[[1.1399999999999999,26305.220000000001]],"batl":null,"id":19924823,"hc":null,"bdatb":null}],"img":null,"tv":2363001.5800000001,"con":null,"marketdefinition":null,"id":"1.258926623"}],"conflatems":null,"op":"mcm","id":3}
{"ct":null,"SegmentType":null,"clk":"ALrEAgC\u002BxwIAgakC","heartbeatms":null,"pt":1780839981869,"initialclk":null,"mc":[{"rc":[{"tv":null,"batb":null,"spb":null,"bdatl":null,"trd":null,"spf":null,"ltp":null,"atb":null,"spl":null,"spn":null,"atl":[[1.1399999999999999,26538.830000000002]],"batl":null,"id":19924823,"hc":null,"bdatb":null}],"img":null,"tv":null,"con":null,"marketdefinition":null,"id":"1.258926623"}],"conflatems":null,"op":"mcm","id":3}
{"ct":null,"SegmentType":null,"clk":"ANjEAgDYxwIAmKkC","heartbeatms":null,"pt":1780839982168,"initialclk":null,"mc":[{"rc":[{"tv":null,"batb":null,"spb":null,"bdatl":null,"trd":null,"spf":null,"ltp":null,"atb":null,"spl":null,"spn":null,"atl":[[1.22,9089.1000000000004],[1.1499999999999999,30924.470000000001]],"batl":null,"id":19924823,"hc":null,"bdatb":null}],"img":null,"tv":null,"con":null,"marketdefinition":null,"id":"1.258926623"}],"conflatems":null,"op":"mcm","id":3}
{"ct":null,"SegmentType":null,"clk":"AObEAgDixwIAqqkC","heartbeatms":null,"pt":1780839982270,"initialclk":null,"mc":[{"rc":[{"tv":null,"batb":null,"spb":null,"bdatl":null,"trd":null,"spf":null,"ltp":null,"atb":[[1.1299999999999999,1270.8299999999999]],"spl":null,"spn":null,"atl":null,"batl":null,"id":19924823,"hc":null,"bdatb":null}],"img":null,"tv":null,"con":null,"marketdefinition":null,"id":"1.258926623"}],"conflatems":null,"op":"mcm","id":3}
{"ct":null,"SegmentType":null,"clk":"AJDFAgCbyAIA2akC","heartbeatms":null,"pt":1780839982786,"initialclk":null,"mc":[{"rc":[{"tv":null,"batb":null,"spb":null,"bdatl":null,"trd":null,"spf":null,"ltp":null,"atb":null,"spl":null,"spn":null,"atl":[[1.2,8901.0499999999993]],"batl":null,"id":19924823,"hc":null,"bdatb":null}],"img":null,"tv":null,"con":null,"marketdefinition":null,"id":"1.258926623"}],"conflatems":null,"op":"mcm","id":3}
{"ct":null,"SegmentType":null,"clk":"ANfGAgD7yQIAwKsC","heartbeatms":null,"pt":1780839984960,"initialclk":null,"mc":[{"rc":[{"tv":2114453.75,"batb":null,"spb":null,"bdatl":null,"trd":[[1.1299999999999999,250460.97]],"spf":null,"ltp":null,"atb":[[1.1299999999999999,1198.6400000000001]],"spl":null,"spn":null,"atl":null,"batl":null,"id":19924823,"hc":null,"bdatb":null}],"img":null,"tv":2363145.9700000002,"con":null,"marketdefinition":null,"id":"1.258926623"}],"conflatems":null,"op":"mcm","id":3}
{"ct":null,"SegmentType":null,"clk":"AKrHAgDgygIAkKwC","heartbeatms":null,"pt":1780839985987,"initialclk":null,"mc":[{"rc":[{"tv":2114460.5600000001,"batb":null,"spb":null,"bdatl":null,"trd":[[1.1299999999999999,250467.78]],"spf":null,"ltp":null,"atb":[[1.1299999999999999,1195.23]],"spl":null,"spn":null,"atl":null,"batl":null,"id":19924823,"hc":null,"bdatb":null}],"img":null,"tv":2363152.7799999998,"con":null,"marketdefinition":null,"id":"1.258926623"}],"conflatems":null,"op":"mcm","id":3}
{"ct":null,"SegmentType":null,"clk":"AMTHAgCAywIAqKwC","heartbeatms":null,"pt":1780839986296,"initialclk":null,"mc":[{"rc":[{"tv":null,"batb":null,"spb":null,"bdatl":null,"trd":null,"spf":null,"ltp":null,"atb":[[8.5999999999999996,0]],"spl":null,"spn":null,"atl":null,"batl":null,"id":16570658,"hc":null,"bdatb":null}],"img":null,"tv":null,"con":null,"marketdefinition":null,"id":"1.258926623"}],"conflatems":null,"op":"mcm","id":3}
{"ct":null,"SegmentType":null,"clk":"AJTIAgDZywIA\u002BqwC","heartbeatms":null,"pt":1780839987172,"initialclk":null,"mc":[{"rc":[{"tv":null,"batb":null,"spb":null,"bdatl":null,"trd":null,"spf":null,"ltp":null,"atb":[[1.1200000000000001,30513.130000000001]],"spl":null,"spn":null,"atl":null,"batl":null,"id":19924823,"hc":null,"bdatb":null}],"img":null,"tv":null,"con":null,"marketdefinition":null,"id":"1.258926623"}],"conflatems":null,"op":"mcm","id":3}
{"ct":null,"SegmentType":null,"clk":"AJrIAgDnywIAha0C","heartbeatms":null,"pt":1780839987277,"initialclk":null,"mc":[{"rc":[{"tv":null,"batb":null,"spb":null,"bdatl":null,"trd":null,"spf":null,"ltp":null,"atb":[[1.0900000000000001,43102.889999999999]],"spl":null,"spn":null,"atl":null,"batl":null,"id":19924823,"hc":null,"bdatb":null}],"img":null,"tv":null,"con":null,"marketdefinition":null,"id":"1.258926623"}],"conflatems":null,"op":"mcm","id":3}
{"ct":null,"SegmentType":null,"clk":"AKXIAgD0ywIAka0C","heartbeatms":null,"pt":1780839987383,"initialclk":null,"mc":[{"rc":[{"tv":null,"batb":null,"spb":null,"bdatl":null,"trd":null,"spf":null,"ltp":null,"atb":[[6.7999999999999998,25.379999999999999]],"spl":null,"spn":null,"atl":null,"batl":null,"id":16570658,"hc":null,"bdatb":null}],"img":null,"tv":null,"con":null,"marketdefinition":null,"id":"1.258926623"}],"conflatems":null,"op":"mcm","id":3}
{"ct":null,"SegmentType":null,"clk":"ALXIAgCLzAIAoK0C","heartbeatms":null,"pt":1780839987586,"initialclk":null,"mc":[{"rc":[{"tv":2114460.6699999999,"batb":null,"spb":null,"bdatl":null,"trd":[[1.1299999999999999,250467.89000000001]],"spf":null,"ltp":null,"atb":[[1.1299999999999999,1195.1800000000001]],"spl":null,"spn":null,"atl":null,"batl":null,"id":19924823,"hc":null,"bdatb":null}],"img":null,"tv":2363152.8900000001,"con":null,"marketdefinition":null,"id":"1.258926623"}],"conflatems":null,"op":"mcm","id":3}
{"ct":null,"SegmentType":null,"clk":"AMPIAgCnzAIAsq0C","heartbeatms":null,"pt":1780839987889,"initialclk":null,"mc":[{"rc":[{"tv":null,"batb":null,"spb":null,"bdatl":null,"trd":null,"spf":null,"ltp":null,"atb":[[7,0]],"spl":null,"spn":null,"atl":null,"batl":null,"id":16570658,"hc":null,"bdatb":null}],"img":null,"tv":null,"con":null,"marketdefinition":null,"id":"1.258926623"}],"conflatems":null,"op":"mcm","id":3}
{"ct":null,"SegmentType":null,"clk":"ANfIAgC9zAIAxK0C","heartbeatms":null,"pt":1780839988096,"initialclk":null,"mc":[{"rc":[{"tv":null,"batb":null,"spb":null,"bdatl":null,"trd":null,"spf":null,"ltp":null,"atb":[[7.5999999999999996,531.45000000000005]],"spl":null,"spn":null,"atl":null,"batl":null,"id":16570658,"hc":null,"bdatb":null}],"img":null,"tv":null,"con":null,"marketdefinition":null,"id":"1.258926623"}],"conflatems":null,"op":"mcm","id":3}
{"ct":null,"SegmentType":null,"clk":"AOfIAgDSzAIA2a0C","heartbeatms":null,"pt":1780839988300,"initialclk":null,"mc":[{"rc":[{"tv":null,"batb":null,"spb":null,"bdatl":null,"trd":null,"spf":null,"ltp":null,"atb":[[1.1200000000000001,30528.130000000001]],"spl":null,"spn":null,"atl":null,"batl":null,"id":19924823,"hc":null,"bdatb":null}],"img":null,"tv":null,"con":null,"marketdefinition":null,"id":"1.258926623"}],"conflatems":null,"op":"mcm","id":3}
{"ct":null,"SegmentType":null,"clk":"AJ3JAgCZzQIAna4C","heartbeatms":null,"pt":1780839989080,"initialclk":null,"mc":[{"rc":[{"tv":null,"batb":null,"spb":null,"bdatl":null,"trd":null,"spf":null,"ltp":null,"atb":[[1.1299999999999999,8],[1.1000000000000001,66373.080000000002]],"spl":null,"spn":null,"atl":null,"batl":null,"id":19924823,"hc":null,"bdatb":null}],"img":null,"tv":null,"con":null,"marketdefinition":null,"id":"1.258926623"}],"conflatems":null,"op":"mcm","id":3}
{"ct":null,"SegmentType":null,"clk":"AK3JAgCrzQIAsK4C","heartbeatms":null,"pt":1780839989281,"initialclk":null,"mc":[{"rc":[{"tv":null,"batb":null,"spb":null,"bdatl":null,"trd":null,"spf":null,"ltp":null,"atb":null,"spl":null,"spn":null,"atl":[[1.1599999999999999,26739.099999999999]],"batl":null,"id":19924823,"hc":null,"bdatb":null}],"img":null,"tv":null,"con":null,"marketdefinition":null,"id":"1.258926623"}],"conflatems":null,"op":"mcm","id":3}
{"ct":null,"SegmentType":null,"clk":"AL3JAgDCzQIAwa4C","heartbeatms":null,"pt":1780839989489,"initialclk":null,"mc":[{"rc":[{"tv":2114474.23,"batb":null,"spb":null,"bdatl":null,"trd":[[1.1399999999999999,172308.23999999999]],"spf":null,"ltp":1.1399999999999999,"atb":null,"spl":null,"spn":null,"atl":[[1.1399999999999999,26532.049999999999]],"batl":null,"id":19924823,"hc":null,"bdatb":null}],"img":null,"tv":2363166.4500000002,"con":null,"marketdefinition":null,"id":"1.258926623"}],"conflatems":null,"op":"mcm","id":3}
{"ct":null,"SegmentType":null,"clk":"ANPJAgDizQIA5K4C","heartbeatms":null,"pt":1780839989793,"initialclk":null,"mc":[{"rc":[{"tv":null,"batb":null,"spb":null,"bdatl":null,"trd":null,"spf":null,"ltp":null,"atb":null,"spl":null,"spn":null,"atl":[[1.1599999999999999,27975.650000000001]],"batl":null,"id":19924823,"hc":null,"bdatb":null}],"img":null,"tv":null,"con":null,"marketdefinition":null,"id":"1.258926623"}],"conflatems":null,"op":"mcm","id":3}
{"ct":null,"SegmentType":null,"clk":"AOfJAgD3zQIA\u002Ba4C","heartbeatms":null,"pt":1780839989997,"initialclk":null,"mc":[{"rc":[{"tv":null,"batb":null,"spb":null,"bdatl":null,"trd":null,"spf":null,"ltp":null,"atb":[[1.1200000000000001,12810.24]],"spl":null,"spn":null,"atl":null,"batl":null,"id":19924823,"hc":null,"bdatb":null}],"img":null,"tv":null,"con":null,"marketdefinition":null,"id":"1.258926623"}],"conflatems":null,"op":"mcm","id":3}
{"ct":null,"SegmentType":null,"clk":"AO3JAgCFzgIAhK8C","heartbeatms":null,"pt":1780839990099,"initialclk":null,"mc":[{"rc":[{"tv":2114476.1400000001,"batb":null,"spb":null,"bdatl":null,"trd":[[1.1399999999999999,172310.14999999999]],"spf":null,"ltp":null,"atb":null,"spl":null,"spn":null,"atl":[[1.1399999999999999,26531.09]],"batl":null,"id":19924823,"hc":null,"bdatb":null}],"img":null,"tv":2363168.3599999999,"con":null,"marketdefinition":null,"id":"1.258926623"}],"conflatems":null,"op":"mcm","id":3}
{"ct":null,"SegmentType":null,"clk":"APnJAgCQzgIAja8C","heartbeatms":null,"pt":1780839990205,"initialclk":null,"mc":[{"rc":[{"tv":2114543.9500000002,"batb":null,"spb":null,"bdatl":null,"trd":[[1.1399999999999999,172377.95999999999]],"spf":null,"ltp":null,"atb":null,"spl":null,"spn":null,"atl":[[1.1399999999999999,26497.189999999999]],"batl":null,"id":19924823,"hc":null,"bdatb":null}],"img":null,"tv":2363236.1699999999,"con":null,"marketdefinition":null,"id":"1.258926623"}],"conflatems":null,"op":"mcm","id":3}
{"ct":null,"SegmentType":null,"clk":"AIXKAgCdzgIAmK8C","heartbeatms":null,"pt":1780839990264,"initialclk":null,"mc":[{"rc":[{"tv":null,"batb":null,"spb":null,"bdatl":null,"trd":null,"spf":null,"ltp":null,"atb":null,"spl":null,"spn":null,"atl":[[9.4000000000000004,2]],"batl":null,"id":16570658,"hc":null,"bdatb":null},{"tv":null,"batb":null,"spb":null,"bdatl":null,"trd":null,"spf":null,"ltp":null,"atb":[[1.1200000000000001,12813.190000000001]],"spl":null,"spn":null,"atl":null,"batl":null,"id":19924823,"hc":null,"bdatb":null}],"img":null,"tv":null,"con":null,"marketdefinition":null,"id":"1.258926623"}],"conflatems":null,"op":"mcm","id":3}
{"ct":null,"SegmentType":null,"clk":"AMLKAgDizgIA2a8C","heartbeatms":null,"pt":1780839990988,"initialclk":null,"mc":[{"rc":[{"tv":249045.54999999999,"batb":null,"spb":null,"bdatl":null,"trd":[[8.4000000000000004,2676.3699999999999]],"spf":null,"ltp":8.4000000000000004,"atb":[[8.4000000000000004,0]],"spl":null,"spn":null,"atl":[[8.4000000000000004,73.329999999999998]],"batl":null,"id":16570658,"hc":null,"bdatb":null}],"img":null,"tv":2363589.5,"con":null,"marketdefinition":null,"id":"1.258926623"}],"conflatems":null,"op":"mcm","id":3}
{"ct":null,"SegmentType":null,"clk":"AMfKAgDvzgIA4a8C","heartbeatms":null,"pt":1780839991089,"initialclk":null,"mc":[{"rc":[{"tv":null,"batb":null,"spb":null,"bdatl":null,"trd":null,"spf":null,"ltp":null,"atb":null,"spl":null,"spn":null,"atl":[[9,416.5],[8.5999999999999996,113.97]],"batl":null,"id":16570658,"hc":null,"bdatb":null}],"img":null,"tv":null,"con":null,"marketdefinition":null,"id":"1.258926623"}],"conflatems":null,"op":"mcm","id":3}
{"ct":null,"SegmentType":null,"clk":"AM/KAgD6zgIA668C","heartbeatms":null,"pt":1780839991195,"initialclk":null,"mc":[{"rc":[{"tv":null,"batb":null,"spb":null,"bdatl":null,"trd":null,"spf":null,"ltp":null,"atb":[[7.5999999999999996,342.88]],"spl":null,"spn":null,"atl":null,"batl":null,"id":16570658,"hc":null,"bdatb":null},{"tv":null,"batb":null,"spb":null,"bdatl":null,"trd":null,"spf":null,"ltp":null,"atb":null,"spl":null,"spn":null,"atl":[[1.1399999999999999,26263.580000000002]],"batl":null,"id":19924823,"hc":null,"bdatb":null}],"img":null,"tv":null,"con":null,"marketdefinition":null,"id":"1.258926623"}],"conflatems":null,"op":"mcm","id":3}
{"ct":null,"SegmentType":null,"clk":"AODKAgCRzwIA\u002B68C","heartbeatms":null,"pt":1780839991404,"initialclk":null,"mc":[{"rc":[{"tv":null,"batb":null,"spb":null,"bdatl":null,"trd":null,"spf":null,"ltp":null,"atb":null,"spl":null,"spn":null,"atl":[[9.1999999999999993,158.69999999999999]],"batl":null,"id":16570658,"hc":null,"bdatb":null}],"img":null,"tv":null,"con":null,"marketdefinition":null,"id":"1.258926623"}],"conflatems":null,"op":"mcm","id":3}
{"ct":null,"SegmentType":null,"clk":"AO7KAgCmzwIAjbAC","heartbeatms":null,"pt":1780839991566,"initialclk":null,"mc":[{"rc":[{"tv":null,"batb":null,"spb":null,"bdatl":null,"trd":null,"spf":null,"ltp":null,"atb":[[6.5999999999999996,25.989999999999998],[7,23.32]],"spl":null,"spn":null,"atl":[[9.1999999999999993,167.22]],"batl":null,"id":16570658,"hc":null,"bdatb":null},{"tv":null,"batb":null,"spb":null,"bdatl":null,"trd":null,"spf":null,"ltp":null,"atb":null,"spl":null,"spn":null,"atl":[[1.24,205.93000000000001]],"batl":null,"id":19924823,"hc":null,"bdatb":null}],"img":null,"tv":null,"con":null,"marketdefinition":null,"id":"1.258926623"}],"conflatems":null,"op":"mcm","id":3}
{"ct":null,"SegmentType":null,"clk":"APvKAgCxzwIAk7AC","heartbeatms":null,"pt":1780839991666,"initialclk":null,"mc":[{"rc":[{"tv":null,"batb":null,"spb":null,"bdatl":null,"trd":null,"spf":null,"ltp":null,"atb":null,"spl":null,"spn":null,"atl":[[9.4000000000000004,3.73]],"batl":null,"id":16570658,"hc":null,"bdatb":null}],"img":null,"tv":null,"con":null,"marketdefinition":null,"id":"1.258926623"}],"conflatems":null,"op":"mcm","id":3}
{"ct":null,"SegmentType":null,"clk":"AJrLAgDQzwIApbAC","heartbeatms":null,"pt":1780839991980,"initialclk":null,"mc":[{"rc":[{"tv":null,"batb":null,"spb":null,"bdatl":null,"trd":null,"spf":null,"ltp":null,"atb":[[1.1100000000000001,70253.410000000003]],"spl":null,"spn":null,"atl":null,"batl":null,"id":19924823,"hc":null,"bdatb":null}],"img":null,"tv":null,"con":null,"marketdefinition":null,"id":"1.258926623"}],"conflatems":null,"op":"mcm","id":3}
{"ct":null,"SegmentType":null,"clk":"AKvLAgDZzwIArrAC","heartbeatms":null,"pt":1780839992080,"initialclk":null,"mc":[{"rc":[{"tv":null,"batb":null,"spb":null,"bdatl":null,"trd":null,"spf":null,"ltp":null,"atb":[[7.2000000000000002,0]],"spl":null,"spn":null,"atl":null,"batl":null,"id":16570658,"hc":null,"bdatb":null}],"img":null,"tv":null,"con":null,"marketdefinition":null,"id":"1.258926623"}],"conflatems":null,"op":"mcm","id":3}
{"ct":null,"SegmentType":null,"clk":"ANXLAgCF0AIA07AC","heartbeatms":null,"pt":1780839992498,"initialclk":null,"mc":[{"rc":[{"tv":null,"batb":null,"spb":null,"bdatl":null,"trd":null,"spf":null,"ltp":null,"atb":[[8.1999999999999993,19.440000000000001]],"spl":null,"spn":null,"atl":null,"batl":null,"id":16570658,"hc":null,"bdatb":null}],"img":null,"tv":null,"con":null,"marketdefinition":null,"id":"1.258926623"}],"conflatems":null,"op":"mcm","id":3}
{"ct":null,"SegmentType":null,"clk":"AI7MAgC90AIAgrEC","heartbeatms":null,"pt":1780839993060,"initialclk":null,"mc":[{"rc":[{"tv":null,"batb":null,"spb":null,"bdatl":null,"trd":null,"spf":null,"ltp":null,"atb":[[1.1299999999999999,81.5]],"spl":null,"spn":null,"atl":null,"batl":null,"id":19924823,"hc":null,"bdatb":null}],"img":null,"tv":null,"con":null,"marketdefinition":null,"id":"1.258926623"}],"conflatems":null,"op":"mcm","id":3}
{"ct":null,"SegmentType":null,"clk":"AJTMAgDO0AIAiLEC","heartbeatms":null,"pt":1780839993159,"initialclk":null,"mc":[{"rc":[{"tv":null,"batb":null,"spb":null,"bdatl":null,"trd":null,"spf":null,"ltp":null,"atb":null,"spl":null,"spn":null,"atl":[[1.1499999999999999,30931.25]],"batl":null,"id":19924823,"hc":null,"bdatb":null}],"img":null,"tv":null,"con":null,"marketdefinition":null,"id":"1.258926623"}],"conflatems":null,"op":"mcm","id":3}
{"ct":null,"SegmentType":null,"clk":"AJ3MAgDW0AIAkLEC","heartbeatms":null,"pt":1780839993266,"initialclk":null,"mc":[{"rc":[{"tv":null,"batb":null,"spb":null,"bdatl":null,"trd":null,"spf":null,"ltp":null,"atb":null,"spl":null,"spn":null,"atl":[[8.4000000000000004,186.75]],"batl":null,"id":16570658,"hc":null,"bdatb":null}],"img":null,"tv":null,"con":null,"marketdefinition":null,"id":"1.258926623"}],"conflatems":null,"op":"mcm","id":3}
{"ct":null,"SegmentType":null,"clk":"AK7MAgDq0AIAp7EC","heartbeatms":null,"pt":1780839993467,"initialclk":null,"mc":[{"rc":[{"tv":null,"batb":null,"spb":null,"bdatl":null,"trd":null,"spf":null,"ltp":null,"atb":[[7.2000000000000002,12.67]],"spl":null,"spn":null,"atl":null,"batl":null,"id":16570658,"hc":null,"bdatb":null},{"tv":null,"batb":null,"spb":null,"bdatl":null,"trd":null,"spf":null,"ltp":null,"atb":null,"spl":null,"spn":null,"atl":[[1.1599999999999999,28272.869999999999]],"batl":null,"id":19924823,"hc":null,"bdatb":null}],"img":null,"tv":null,"con":null,"marketdefinition":null,"id":"1.258926623"}],"conflatems":null,"op":"mcm","id":3}
{"ct":null,"SegmentType":null,"clk":"ALrMAgD40AIAsbEC","heartbeatms":null,"pt":1780839993585,"initialclk":null,"mc":[{"rc":[{"tv":null,"batb":null,"spb":null,"bdatl":null,"trd":null,"spf":null,"ltp":null,"atb":[[8,328.37]],"spl":null,"spn":null,"atl":[[9.4000000000000004,1.73],[11,103.94],[9.1999999999999993,58.520000000000003],[9,138.72999999999999]],"batl":null,"id":16570658,"hc":null,"bdatb":null},{"tv":null,"batb":null,"spb":null,"bdatl":null,"trd":null,"spf":null,"ltp":null,"atb":[[1.1000000000000001,66371.080000000002],[1.1200000000000001,11471.91]],"spl":null,"spn":null,"atl":[[1.1399999999999999,25899.330000000002],[1.1599999999999999,27036.32]],"batl":null,"id":19924823,"hc":null,"bdatb":null}],"img":null,"tv":null,"con":null,"marketdefinition":null,"id":"1.258926623"}],"conflatems":null,"op":"mcm","id":3}
{"ct":null,"SegmentType":null,"clk":"AMTMAgCA0QIAvrEC","heartbeatms":null,"pt":1780839993678,"initialclk":null,"mc":[{"rc":[{"tv":null,"batb":null,"spb":null,"bdatl":null,"trd":null,"spf":null,"ltp":null,"atb":[[7,387.47000000000003],[6.7999999999999998,145.03],[8,240.37000000000001]],"spl":null,"spn":null,"atl":[[9.4000000000000004,3.73],[10.5,160.16],[10,357.08999999999997]],"batl":null,"id":16570658,"hc":null,"bdatb":null},{"tv":null,"batb":null,"spb":null,"bdatl":null,"trd":null,"spf":null,"ltp":null,"atb":[[1.1000000000000001,64641.080000000002],[1.1200000000000001,11473.91]],"spl":null,"spn":null,"atl":[[1.1499999999999999,29427.150000000001]],"batl":null,"id":19924823,"hc":null,"bdatb":null}],"img":null,"tv":null,"con":null,"marketdefinition":null,"id":"1.258926623"}],"conflatems":null,"op":"mcm","id":3}
{"ct":null,"SegmentType":null,"clk":"AMnMAgCI0QIAx7EC","heartbeatms":null,"pt":1780839993777,"initialclk":null,"mc":[{"rc":[{"tv":null,"batb":null,"spb":null,"bdatl":null,"trd":null,"spf":null,"ltp":null,"atb":[[8.1999999999999993,0],[8,220.37000000000001]],"spl":null,"spn":null,"atl":null,"batl":null,"id":16570658,"hc":null,"bdatb":null},{"tv":null,"batb":null,"spb":null,"bdatl":null,"trd":null,"spf":null,"ltp":null,"atb":null,"spl":null,"spn":null,"atl":[[1.1399999999999999,25699.330000000002],[1.1499999999999999,29227.150000000001]],"batl":null,"id":19924823,"hc":null,"bdatb":null}],"img":null,"tv":null,"con":null,"marketdefinition":null,"id":"1.258926623"}],"conflatems":null,"op":"mcm","id":3}
{"ct":null,"SegmentType":null,"clk":"ANrMAgCZ0QIA3LEC","heartbeatms":null,"pt":1780839993986,"initialclk":null,"mc":[{"rc":[{"tv":null,"batb":null,"spb":null,"bdatl":null,"trd":null,"spf":null,"ltp":null,"atb":[[7.7999999999999998,0],[7.5999999999999996,54.579999999999998],[8,25.5]],"spl":null,"spn":null,"atl":[[9.1999999999999993,50]],"batl":null,"id":16570658,"hc":null,"bdatb":null},{"tv":null,"batb":null,"spb":null,"bdatl":null,"trd":null,"spf":null,"ltp":null,"atb":[[1.1000000000000001,61571.610000000001],[1.0900000000000001,40185.099999999999],[1.1100000000000001,67965.009999999995],[1.1200000000000001,5067.8999999999996]],"spl":null,"spn":null,"atl":null,"batl":null,"id":19924823,"hc":null,"bdatb":null}],"img":null,"tv":null,"con":null,"marketdefinition":null,"id":"1.258926623"}],"conflatems":null,"op":"mcm","id":3}
{"ct":null,"SegmentType":null,"clk":"AOLMAgCj0QIA67EC","heartbeatms":null,"pt":1780839994085,"initialclk":null,"mc":[{"rc":[{"tv":null,"batb":null,"spb":null,"bdatl":null,"trd":null,"spf":null,"ltp":null,"atb":null,"spl":null,"spn":null,"atl":[[8.4000000000000004,73.329999999999998],[8.8000000000000007,0],[9,0],[8.5999999999999996,0]],"batl":null,"id":16570658,"hc":null,"bdatb":null},{"tv":null,"batb":null,"spb":null,"bdatl":null,"trd":null,"spf":null,"ltp":null,"atb":[[1.1200000000000001,3953.1100000000001]],"spl":null,"spn":null,"atl":[[1.1399999999999999,24604.09]],"batl":null,"id":19924823,"hc":null,"bdatb":null}],"img":null,"tv":null,"con":null,"marketdefinition":null,"id":"1.258926623"}],"conflatems":null,"op":"mcm","id":3}
{"ct":null,"SegmentType":null,"clk":"APbMAgC10QIAhbIC","heartbeatms":null,"pt":1780839994295,"initialclk":null,"mc":[{"rc":[{"tv":249191.76999999999,"batb":null,"spb":null,"bdatl":null,"trd":[[8.4000000000000004,2822.5900000000001]],"spf":null,"ltp":null,"atb":null,"spl":null,"spn":null,"atl":[[8.4000000000000004,0.22]],"batl":null,"id":16570658,"hc":null,"bdatb":null}],"img":null,"tv":2363735.7200000002,"con":null,"marketdefinition":null,"id":"1.258926623"}],"conflatems":null,"op":"mcm","id":3}
{"ct":null,"SegmentType":null,"clk":"AILNAgC/0QIAlrIC","heartbeatms":null,"pt":1780839994398,"initialclk":null,"mc":[{"rc":[{"tv":null,"batb":null,"spb":null,"bdatl":null,"trd":null,"spf":null,"ltp":null,"atb":[[1.1100000000000001,69163]],"spl":null,"spn":null,"atl":[[1.1599999999999999,28576.830000000002]],"batl":null,"id":19924823,"hc":null,"bdatb":null}],"img":null,"tv":null,"con":null,"marketdefinition":null,"id":"1.258926623"}],"conflatems":null,"op":"mcm","id":3}
{"ct":null,"SegmentType":null,"clk":"AIrNAgDL0QIAn7IC","heartbeatms":null,"pt":1780839994498,"initialclk":null,"mc":[{"rc":[{"tv":null,"batb":null,"spb":null,"bdatl":null,"trd":null,"spf":null,"ltp":null,"atb":[[8.1999999999999993,0.94999999999999996]],"spl":null,"spn":null,"atl":null,"batl":null,"id":16570658,"hc":null,"bdatb":null},{"tv":2114546.29,"batb":null,"spb":null,"bdatl":null,"trd":[[1.1399999999999999,172380.29999999999]],"spf":null,"ltp":null,"atb":[[1.1200000000000001,2765.8099999999999]],"spl":null,"spn":null,"atl":[[1.1399999999999999,23473.740000000002],[1.1499999999999999,28277.48]],"batl":null,"id":19924823,"hc":null,"bdatb":null}],"img":null,"tv":2363738.0600000001,"con":null,"marketdefinition":null,"id":"1.258926623"}],"conflatems":null,"op":"mcm","id":3}
{"ct":null,"SegmentType":null,"clk":"AIvOAgDg0gIAibMC","heartbeatms":null,"pt":1780839995784,"initialclk":null,"mc":[{"rc":[{"tv":null,"batb":null,"spb":null,"bdatl":null,"trd":null,"spf":null,"ltp":null,"atb":[[1.1200000000000001,2015.81]],"spl":null,"spn":null,"atl":null,"batl":null,"id":19924823,"hc":null,"bdatb":null}],"img":null,"tv":null,"con":null,"marketdefinition":null,"id":"1.258926623"}],"conflatems":null,"op":"mcm","id":3}
{"ct":null,"SegmentType":null,"clk":"AJbOAgDn0gIAkrMC","heartbeatms":null,"pt":1780839995889,"initialclk":null,"mc":[{"rc":[{"tv":249192.20999999999,"batb":null,"spb":null,"bdatl":null,"trd":[[8.4000000000000004,2823.0300000000002]],"spf":null,"ltp":null,"atb":[[8.4000000000000004,199.78]],"spl":null,"spn":null,"atl":[[8.4000000000000004,0]],"batl":null,"id":16570658,"hc":null,"bdatb":null}],"img":null,"tv":2363738.5,"con":null,"marketdefinition":null,"id":"1.258926623"}],"conflatems":null,"op":"mcm","id":3}
{"ct":null,"SegmentType":null,"clk":"AK7OAgCB0wIArbMC","heartbeatms":null,"pt":1780839996192,"initialclk":null,"mc":[{"rc":[{"tv":null,"batb":null,"spb":null,"bdatl":null,"trd":null,"spf":null,"ltp":null,"atb":[[1.1299999999999999,155.84999999999999]],"spl":null,"spn":null,"atl":null,"batl":null,"id":19924823,"hc":null,"bdatb":null}],"img":null,"tv":null,"con":null,"marketdefinition":null,"id":"1.258926623"}],"conflatems":null,"op":"mcm","id":3}
{"ct":null,"SegmentType":null,"clk":"AMDOAgCW0wIAvrMC","heartbeatms":null,"pt":1780839996398,"initialclk":null,"mc":[{"rc":[{"tv":null,"batb":null,"spb":null,"bdatl":null,"trd":null,"spf":null,"ltp":null,"atb":null,"spl":null,"spn":null,"atl":[[1.1399999999999999,14614.790000000001]],"batl":null,"id":19924823,"hc":null,"bdatb":null}],"img":null,"tv":null,"con":null,"marketdefinition":null,"id":"1.258926623"}],"conflatems":null,"op":"mcm","id":3}
{"ct":null,"SegmentType":null,"clk":"AN/OAgC\u002B0wIA2rMC","heartbeatms":null,"pt":1780839996764,"initialclk":null,"mc":[{"rc":[{"tv":null,"batb":null,"spb":null,"bdatl":null,"trd":null,"spf":null,"ltp":null,"atb":[[1.1200000000000001,2000.81]],"spl":null,"spn":null,"atl":[[1.1399999999999999,5755.8500000000004]],"batl":null,"id":19924823,"hc":null,"bdatb":null}],"img":null,"tv":null,"con":null,"marketdefinition":null,"id":"1.258926623"}],"conflatems":null,"op":"mcm","id":3}
{"ct":null,"SegmentType":null,"clk":"AObOAgDG0wIA4rMC","heartbeatms":null,"pt":1780839996863,"initialclk":null,"mc":[{"rc":[{"tv":2114575.29,"batb":null,"spb":null,"bdatl":null,"trd":[[1.1299999999999999,250496.89000000001]],"spf":null,"ltp":1.1299999999999999,"atb":[[1.1299999999999999,141.34999999999999]],"spl":null,"spn":null,"atl":null,"batl":null,"id":19924823,"hc":null,"bdatb":null}],"img":null,"tv":2363767.5,"con":null,"marketdefinition":null,"id":"1.258926623"}],"conflatems":null,"op":"mcm","id":3}
{"ct":null,"SegmentType":null,"clk":"ALHPAgCF1AIAn7QC","heartbeatms":null,"pt":1780839997586,"initialclk":null,"mc":[{"rc":[{"tv":null,"batb":null,"spb":null,"bdatl":null,"trd":null,"spf":null,"ltp":null,"atb":[[7.4000000000000004,707.76999999999998]],"spl":null,"spn":null,"atl":null,"batl":null,"id":16570658,"hc":null,"bdatb":null},{"tv":null,"batb":null,"spb":null,"bdatl":null,"trd":null,"spf":null,"ltp":null,"atb":null,"spl":null,"spn":null,"atl":[[1.1599999999999999,28572.57]],"batl":null,"id":19924823,"hc":null,"bdatb":null}],"img":null,"tv":null,"con":null,"marketdefinition":null,"id":"1.258926623"}],"conflatems":null,"op":"mcm","id":3}
{"ct":null,"SegmentType":null,"clk":"ALbPAgCO1AIApbQC","heartbeatms":null,"pt":1780839997689,"initialclk":null,"mc":[{"rc":[{"tv":null,"batb":null,"spb":null,"bdatl":null,"trd":null,"spf":null,"ltp":null,"atb":[[1.1100000000000001,67342.850000000006],[1.1200000000000001,1083.96]],"spl":null,"spn":null,"atl":[[1.1599999999999999,27032.060000000001],[1.1499999999999999,27696.740000000002]],"batl":null,"id":19924823,"hc":null,"bdatb":null}],"img":null,"tv":null,"con":null,"marketdefinition":null,"id":"1.258926623"}],"conflatems":null,"op":"mcm","id":3}
{"ct":null,"SegmentType":null,"clk":"AM/PAgCr1AIAvbQC","heartbeatms":null,"pt":1780839997994,"initialclk":null,"mc":[{"rc":[{"tv":2114576.9199999999,"batb":null,"spb":null,"bdatl":null,"trd":[[1.1399999999999999,172381.92999999999]],"spf":null,"ltp":1.1399999999999999,"atb":null,"spl":null,"spn":null,"atl":[[1.1399999999999999,5755.04]],"batl":null,"id":19924823,"hc":null,"bdatb":null}],"img":null,"tv":2363769.1299999999,"con":null,"marketdefinition":null,"id":"1.258926623"}],"conflatems":null,"op":"mcm","id":3}
{"ct":null,"SegmentType":null,"clk":"AOjPAgDH1AIA2bQC","heartbeatms":null,"pt":1780839998297,"initialclk":null,"mc":[{"rc":[{"tv":null,"batb":null,"spb":null,"bdatl":null,"trd":null,"spf":null,"ltp":null,"atb":[[8.4000000000000004,0]],"spl":null,"spn":null,"atl":null,"batl":null,"id":16570658,"hc":null,"bdatb":null}],"img":null,"tv":null,"con":null,"marketdefinition":null,"id":"1.258926623"}],"conflatems":null,"op":"mcm","id":3}
{"ct":null,"SegmentType":null,"clk":"AJvQAgCH1QIAjLUC","heartbeatms":null,"pt":1780839998868,"initialclk":null,"mc":[{"rc":[{"tv":2114578.0600000001,"batb":null,"spb":null,"bdatl":null,"trd":[[1.1399999999999999,172383.07000000001]],"spf":null,"ltp":null,"atb":null,"spl":null,"spn":null,"atl":[[1.1399999999999999,5754.4700000000003]],"batl":null,"id":19924823,"hc":null,"bdatb":null}],"img":null,"tv":2363770.27,"con":null,"marketdefinition":null,"id":"1.258926623"}],"conflatems":null,"op":"mcm","id":3}
{"ct":null,"SegmentType":null,"clk":"ALTQAgCd1QIApLUC","heartbeatms":null,"pt":1780839999182,"initialclk":null,"mc":[{"rc":[{"tv":null,"batb":null,"spb":null,"bdatl":null,"trd":null,"spf":null,"ltp":null,"atb":[[1.1100000000000001,69162.889999999999],[1.1200000000000001,2000.9200000000001]],"spl":null,"spn":null,"atl":[[1.1599999999999999,28572.57],[1.1499999999999999,28277.360000000001]],"batl":null,"id":19924823,"hc":null,"bdatb":null}],"img":null,"tv":null,"con":null,"marketdefinition":null,"id":"1.258926623"}],"conflatems":null,"op":"mcm","id":3}
{"ct":null,"SegmentType":null,"clk":"AMrQAgCv1QIAuLUC","heartbeatms":null,"pt":1780839999387,"initialclk":null,"mc":[{"rc":[{"tv":null,"batb":null,"spb":null,"bdatl":null,"trd":null,"spf":null,"ltp":null,"atb":[[8,125.5]],"spl":null,"spn":null,"atl":null,"batl":null,"id":16570658,"hc":null,"bdatb":null}],"img":null,"tv":null,"con":null,"marketdefinition":null,"id":"1.258926623"}],"conflatems":null,"op":"mcm","id":3}
{"ct":null,"SegmentType":null,"clk":"AN7QAgDB1QIAyLUC","heartbeatms":null,"pt":1780839999590,"initialclk":null,"mc":[{"rc":[{"tv":null,"batb":null,"spb":null,"bdatl":null,"trd":null,"spf":null,"ltp":null,"atb":[[8,225.5]],"spl":null,"spn":null,"atl":null,"batl":null,"id":16570658,"hc":null,"bdatb":null}],"img":null,"tv":null,"con":null,"marketdefinition":null,"id":"1.258926623"}],"conflatems":null,"op":"mcm","id":3}
{"ct":null,"SegmentType":null,"clk":"AI3RAgDZ1QIA57UC","heartbeatms":null,"pt":1780839999997,"initialclk":null,"mc":[{"rc":[{"tv":null,"batb":null,"spb":null,"bdatl":null,"trd":null,"spf":null,"ltp":null,"atb":[[8,325.5]],"spl":null,"spn":null,"atl":null,"batl":null,"id":16570658,"hc":null,"bdatb":null}],"img":null,"tv":null,"con":null,"marketdefinition":null,"id":"1.258926623"}],"conflatems":null,"op":"mcm","id":3}
{"ct":null,"SegmentType":null,"clk":"AO7SAgCz1wIAobcC","heartbeatms":null,"pt":1780840002369,"initialclk":null,"mc":[{"rc":[{"tv":null,"batb":null,"spb":null,"bdatl":null,"trd":null,"spf":null,"ltp":null,"atb":[[1.1299999999999999,215.71000000000001]],"spl":null,"spn":null,"atl":null,"batl":null,"id":19924823,"hc":null,"bdatb":null}],"img":null,"tv":null,"con":null,"marketdefinition":null,"id":"1.258926623"}],"conflatems":null,"op":"mcm","id":3}
{"ct":null,"SegmentType":null,"clk":"AKHTAgDk1wIA1rcC","heartbeatms":null,"pt":1780840002883,"initialclk":null,"mc":[{"rc":[{"tv":2114778.0699999998,"batb":null,"spb":null,"bdatl":null,"trd":[[1.1299999999999999,250696.89999999999]],"spf":null,"ltp":1.1299999999999999,"atb":[[1.1299999999999999,115.7]],"spl":null,"spn":null,"atl":null,"batl":null,"id":19924823,"hc":null,"bdatb":null}],"img":null,"tv":2363970.2799999998,"con":null,"marketdefinition":null,"id":"1.258926623"}],"conflatems":null,"op":"mcm","id":3}
{"ct":null,"SegmentType":null,"clk":"AL/TAgCK2AIA\u002B7cC","heartbeatms":null,"pt":1780840003191,"initialclk":null,"mc":[{"rc":[{"tv":null,"batb":null,"spb":null,"bdatl":null,"trd":null,"spf":null,"ltp":null,"atb":[[2.3799999999999999,0]],"spl":null,"spn":null,"atl":null,"batl":null,"id":16570658,"hc":null,"bdatb":null}],"img":null,"tv":null,"con":null,"marketdefinition":null,"id":"1.258926623"}],"conflatems":null,"op":"mcm","id":3}
{"ct":null,"SegmentType":null,"clk":"AInUAgD32AIAyrgC","heartbeatms":null,"pt":1780840003967,"initialclk":null,"mc":[{"rc":[{"tv":null,"batb":null,"spb":null,"bdatl":null,"trd":null,"spf":null,"ltp":null,"atb":[[7.7999999999999998,8.4199999999999999]],"spl":null,"spn":null,"atl":null,"batl":null,"id":16570658,"hc":null,"bdatb":null},{"tv":null,"batb":null,"spb":null,"bdatl":null,"trd":null,"spf":null,"ltp":null,"atb":[[1.1200000000000001,2008.0799999999999]],"spl":null,"spn":null,"atl":null,"batl":null,"id":19924823,"hc":null,"bdatb":null}],"img":null,"tv":null,"con":null,"marketdefinition":null,"id":"1.258926623"}],"conflatems":null,"op":"mcm","id":3}
{"ct":null,"SegmentType":null,"clk":"AMLVAgC62gIA5bkC","heartbeatms":null,"pt":1780840005975,"initialclk":null,"mc":[{"rc":[{"tv":null,"batb":null,"spb":null,"bdatl":null,"trd":null,"spf":null,"ltp":null,"atb":[[1.1299999999999999,334.81]],"spl":null,"spn":null,"atl":null,"batl":null,"id":19924823,"hc":null,"bdatb":null}],"img":null,"tv":null,"con":null,"marketdefinition":null,"id":"1.258926623"}],"conflatems":null,"op":"mcm","id":3}
{"ct":null,"SegmentType":null,"clk":"ANHVAgDN2gIA\u002BrkC","heartbeatms":null,"pt":1780840006179,"initialclk":null,"mc":[{"rc":[{"tv":null,"batb":null,"spb":null,"bdatl":null,"trd":null,"spf":null,"ltp":null,"atb":[[8.4000000000000004,446.97000000000003],[8.1999999999999993,203.09]],"spl":null,"spn":null,"atl":null,"batl":null,"id":16570658,"hc":null,"bdatb":null}],"img":null,"tv":null,"con":null,"marketdefinition":null,"id":"1.258926623"}],"conflatems":null,"op":"mcm","id":3}
{"ct":null,"SegmentType":null,"clk":"ANvVAgDa2gIAhroC","heartbeatms":null,"pt":1780840006284,"initialclk":null,"mc":[{"rc":[{"tv":null,"batb":null,"spb":null,"bdatl":null,"trd":null,"spf":null,"ltp":null,"atb":[[7.7999999999999998,9.2899999999999991],[7.5999999999999996,55.57]],"spl":null,"spn":null,"atl":null,"batl":null,"id":16570658,"hc":null,"bdatb":null},{"tv":null,"batb":null,"spb":null,"bdatl":null,"trd":null,"spf":null,"ltp":null,"atb":[[1.1000000000000001,61573.610000000001]],"spl":null,"spn":null,"atl":[[1.1399999999999999,23472.360000000001],[1.1599999999999999,28577.259999999998],[1.1499999999999999,28282.599999999999]],"batl":null,"id":19924823,"hc":null,"bdatb":null}],"img":null,"tv":null,"con":null,"marketdefinition":null,"id":"1.258926623"}],"conflatems":null,"op":"mcm","id":3}
{"ct":null,"SegmentType":null,"clk":"AODVAgDl2gIAkLoC","heartbeatms":null,"pt":1780840006384,"initialclk":null,"mc":[{"rc":[{"tv":null,"batb":null,"spb":null,"bdatl":null,"trd":null,"spf":null,"ltp":null,"atb":[[8.4000000000000004,417.20999999999998],[6.5999999999999996,25],[6.7999999999999998,144.16999999999999]],"spl":null,"spn":null,"atl":null,"batl":null,"id":16570658,"hc":null,"bdatb":null},{"tv":null,"batb":null,"spb":null,"bdatl":null,"trd":null,"spf":null,"ltp":null,"atb":[[1.1000000000000001,60573.610000000001]],"spl":null,"spn":null,"atl":[[1.19,8875.6399999999994],[1.1799999999999999,8873.2000000000007]],"batl":null,"id":19924823,"hc":null,"bdatb":null}],"img":null,"tv":null,"con":null,"marketdefinition":null,"id":"1.258926623"}],"conflatems":null,"op":"mcm","id":3}
{"ct":null,"SegmentType":null,"clk":"AOfVAgDw2gIAmroC","heartbeatms":null,"pt":1780840006483,"initialclk":null,"mc":[{"rc":[{"tv":null,"batb":null,"spb":null,"bdatl":null,"trd":null,"spf":null,"ltp":null,"atb":[[8.1999999999999993,216.97999999999999]],"spl":null,"spn":null,"atl":null,"batl":null,"id":16570658,"hc":null,"bdatb":null},{"tv":null,"batb":null,"spb":null,"bdatl":null,"trd":null,"spf":null,"ltp":null,"atb":[[1.04,73840.729999999996],[1.05,74306.929999999993],[1.0700000000000001,38874.290000000001],[1.0800000000000001,40508.370000000003],[1.0900000000000001,40183.099999999999],[1.0600000000000001,63324.940000000002],[1.02,90733.919999999998],[1.03,88972.589999999997],[1.01,93591.869999999995]],"spl":null,"spn":null,"atl":[[1.24,5.9299999999999997],[1.1399999999999999,24167.110000000001]],"batl":null,"id":19924823,"hc":null,"bdatb":null}],"img":null,"tv":null,"con":null,"marketdefinition":null,"id":"1.258926623"}],"conflatems":null,"op":"mcm","id":3}
{"ct":null,"SegmentType":null,"clk":"APjVAgD\u002B2gIAoroC","heartbeatms":null,"pt":1780840006593,"initialclk":null,"mc":[{"rc":[{"tv":null,"batb":null,"spb":null,"bdatl":null,"trd":null,"spf":null,"ltp":null,"atb":[[8.4000000000000004,591.42999999999995],[7.7999999999999998,614.62],[7.5999999999999996,35.130000000000003],[8,499.72000000000003]],"spl":null,"spn":null,"atl":null,"batl":null,"id":16570658,"hc":null,"bdatb":null},{"tv":null,"batb":null,"spb":null,"bdatl":null,"trd":null,"spf":null,"ltp":null,"atb":[[1.1000000000000001,60571.610000000001],[1.1200000000000001,1749.0799999999999]],"spl":null,"spn":null,"atl":[[1.1499999999999999,28249.599999999999]],"batl":null,"id":19924823,"hc":null,"bdatb":null}],"img":null,"tv":null,"con":null,"marketdefinition":null,"id":"1.258926623"}],"conflatems":null,"op":"mcm","id":3}
{"ct":null,"SegmentType":null,"clk":"AIzWAgCU2wIArboC","heartbeatms":null,"pt":1780840006793,"initialclk":null,"mc":[{"rc":[{"tv":null,"batb":null,"spb":null,"bdatl":null,"trd":null,"spf":null,"ltp":null,"atb":[[7.4000000000000004,8.3599999999999994]],"spl":null,"spn":null,"atl":null,"batl":null,"id":16570658,"hc":null,"bdatb":null}],"img":null,"tv":null,"con":null,"marketdefinition":null,"id":"1.258926623"}],"conflatems":null,"op":"mcm","id":3}
{"ct":null,"SegmentType":null,"clk":"AJfWAgCf2wIAtLoC","heartbeatms":null,"pt":1780840006902,"initialclk":null,"mc":[{"rc":[{"tv":null,"batb":null,"spb":null,"bdatl":null,"trd":null,"spf":null,"ltp":null,"atb":[[1.1100000000000001,69466.039999999994],[1.1200000000000001,1448.6400000000001]],"spl":null,"spn":null,"atl":[[1.1399999999999999,25954.779999999999],[1.1599999999999999,27036.75],[1.1499999999999999,27668.98]],"batl":null,"id":19924823,"hc":null,"bdatb":null}],"img":null,"tv":null,"con":null,"marketdefinition":null,"id":"1.258926623"}],"conflatems":null,"op":"mcm","id":3}
{"ct":null,"SegmentType":null,"clk":"AKPWAgCv2wIAzboC","heartbeatms":null,"pt":1780840007105,"initialclk":null,"mc":[{"rc":[{"tv":null,"batb":null,"spb":null,"bdatl":null,"trd":null,"spf":null,"ltp":null,"atb":null,"spl":null,"spn":null,"atl":[[1.1699999999999999,8877.2000000000007]],"batl":null,"id":19924823,"hc":null,"bdatb":null}],"img":null,"tv":null,"con":null,"marketdefinition":null,"id":"1.258926623"}],"conflatems":null,"op":"mcm","id":3}
{"ct":null,"SegmentType":null,"clk":"ALbWAgC\u002B2wIA5LoC","heartbeatms":null,"pt":1780840007308,"initialclk":null,"mc":[{"rc":[{"tv":null,"batb":null,"spb":null,"bdatl":null,"trd":null,"spf":null,"ltp":null,"atb":[[8,683.50999999999999]],"spl":null,"spn":null,"atl":[[9.8000000000000007,153.06]],"batl":null,"id":16570658,"hc":null,"bdatb":null},{"tv":null,"batb":null,"spb":null,"bdatl":null,"trd":null,"spf":null,"ltp":null,"atb":[[1.1100000000000001,70817.389999999999]],"spl":null,"spn":null,"atl":[[1.1499999999999999,28947.560000000001]],"batl":null,"id":19924823,"hc":null,"bdatb":null}],"img":null,"tv":null,"con":null,"marketdefinition":null,"id":"1.258926623"}],"conflatems":null,"op":"mcm","id":3}
{"ct":null,"SegmentType":null,"clk":"AMfWAgDN2wIA9roC","heartbeatms":null,"pt":1780840007509,"initialclk":null,"mc":[{"rc":[{"tv":null,"batb":null,"spb":null,"bdatl":null,"trd":null,"spf":null,"ltp":null,"atb":null,"spl":null,"spn":null,"atl":[[9.8000000000000007,0]],"batl":null,"id":16570658,"hc":null,"bdatb":null}],"img":null,"tv":null,"con":null,"marketdefinition":null,"id":"1.258926623"}],"conflatems":null,"op":"mcm","id":3}
{"ct":null,"SegmentType":null,"clk":"ANvWAgDa2wIAhrsC","heartbeatms":null,"pt":1780840007713,"initialclk":null,"mc":[{"rc":[{"tv":null,"batb":null,"spb":null,"bdatl":null,"trd":null,"spf":null,"ltp":null,"atb":[[1.1100000000000001,70824.880000000005]],"spl":null,"spn":null,"atl":null,"batl":null,"id":19924823,"hc":null,"bdatb":null}],"img":null,"tv":null,"con":null,"marketdefinition":null,"id":"1.258926623"}],"conflatems":null,"op":"mcm","id":3}
{"ct":null,"SegmentType":null,"clk":"APnWAgD52wIApLsC","heartbeatms":null,"pt":1780840008075,"initialclk":null,"mc":[{"rc":[{"tv":null,"batb":null,"spb":null,"bdatl":null,"trd":null,"spf":null,"ltp":null,"atb":[[8.8000000000000007,9.0099999999999998]],"spl":null,"spn":null,"atl":null,"batl":null,"id":16570658,"hc":null,"bdatb":null},{"tv":2115447.6899999999,"batb":null,"spb":null,"bdatl":null,"trd":[[1.1299999999999999,251366.51999999999]],"spf":null,"ltp":null,"atb":[[1.1299999999999999,0]],"spl":null,"spn":null,"atl":[[1.1299999999999999,43408.389999999999]],"batl":null,"id":19924823,"hc":null,"bdatb":null}],"img":null,"tv":2364639.8999999999,"con":null,"marketdefinition":null,"id":"1.258926623"}],"conflatems":null,"op":"mcm","id":3}
{"ct":null,"SegmentType":null,"clk":"AI3XAgCJ3AIAt7sC","heartbeatms":null,"pt":1780840008287,"initialclk":null,"mc":[{"rc":[{"tv":null,"batb":null,"spb":null,"bdatl":null,"trd":null,"spf":null,"ltp":null,"atb":[[8.1999999999999993,216.03]],"spl":null,"spn":null,"atl":null,"batl":null,"id":16570658,"hc":null,"bdatb":null},{"tv":null,"batb":null,"spb":null,"bdatl":null,"trd":null,"spf":null,"ltp":null,"atb":[[1.1100000000000001,69473.529999999999]],"spl":null,"spn":null,"atl":[[1.1299999999999999,35320.690000000002],[1.1399999999999999,25260.029999999999]],"batl":null,"id":19924823,"hc":null,"bdatb":null}],"img":null,"tv":null,"con":null,"marketdefinition":null,"id":"1.258926623"}],"conflatems":null,"op":"mcm","id":3}
{"ct":null,"SegmentType":null,"clk":"AMXXAgDb3AIA\u002BrsC","heartbeatms":null,"pt":1780840009100,"initialclk":null,"mc":[{"rc":[{"tv":249194.06,"batb":null,"spb":null,"bdatl":null,"trd":[[8.8000000000000007,1965.0899999999999]],"spf":null,"ltp":8.8000000000000007,"atb":[[8.8000000000000007,8.0899999999999999]],"spl":null,"spn":null,"atl":null,"batl":null,"id":16570658,"hc":null,"bdatb":null}],"img":null,"tv":2364641.75,"con":null,"marketdefinition":null,"id":"1.258926623"}],"conflatems":null,"op":"mcm","id":3}
{"ct":null,"SegmentType":null,"clk":"AIfYAgCZ3QIAvbwC","heartbeatms":null,"pt":1780840009778,"initialclk":null,"mc":[{"rc":[{"tv":2115845.04,"batb":null,"spb":null,"bdatl":null,"trd":[[1.1200000000000001,67128.809999999998]],"spf":null,"ltp":1.1200000000000001,"atb":[[1.1200000000000001,1249.96]],"spl":null,"spn":null,"atl":null,"batl":null,"id":19924823,"hc":null,"bdatb":null}],"img":null,"tv":2365039.1000000001,"con":null,"marketdefinition":null,"id":"1.258926623"}],"conflatems":null,"op":"mcm","id":3}
{"ct":null,"SegmentType":null,"clk":"AKrYAgDA3QIA37wC","heartbeatms":null,"pt":1780840010194,"initialclk":null,"mc":[{"rc":[{"tv":null,"batb":null,"spb":null,"bdatl":null,"trd":null,"spf":null,"ltp":null,"atb":null,"spl":null,"spn":null,"atl":[[1.1299999999999999,36989.099999999999]],"batl":null,"id":19924823,"hc":null,"bdatb":null}],"img":null,"tv":null,"con":null,"marketdefinition":null,"id":"1.258926623"}],"conflatems":null,"op":"mcm","id":3}
{"ct":null,"SegmentType":null,"clk":"AMXYAgDR3QIA9LwC","heartbeatms":null,"pt":1780840010398,"initialclk":null,"mc":[{"rc":[{"tv":null,"batb":null,"spb":null,"bdatl":null,"trd":null,"spf":null,"ltp":null,"atb":[[8.4000000000000004,660.42999999999995]],"spl":null,"spn":null,"atl":[[11,180.94]],"batl":null,"id":16570658,"hc":null,"bdatb":null},{"tv":null,"batb":null,"spb":null,"bdatl":null,"trd":null,"spf":null,"ltp":null,"atb":[[1.1000000000000001,62283.610000000001]],"spl":null,"spn":null,"atl":[[1.1399999999999999,26681.029999999999]],"batl":null,"id":19924823,"hc":null,"bdatb":null}],"img":null,"tv":null,"con":null,"marketdefinition":null,"id":"1.258926623"}],"conflatems":null,"op":"mcm","id":3}
{"ct":null,"SegmentType":null,"clk":"AM7YAgDZ3QIA\u002B7wC","heartbeatms":null,"pt":1780840010500,"initialclk":null,"mc":[{"rc":[{"tv":null,"batb":null,"spb":null,"bdatl":null,"trd":null,"spf":null,"ltp":null,"atb":[[6.5999999999999996,0]],"spl":null,"spn":null,"atl":[[9.1999999999999993,157.44999999999999]],"batl":null,"id":16570658,"hc":null,"bdatb":null},{"tv":null,"batb":null,"spb":null,"bdatl":null,"trd":null,"spf":null,"ltp":null,"atb":[[1.1100000000000001,70594.669999999998]],"spl":null,"spn":null,"atl":[[1.1299999999999999,37932.589999999997],[1.23,481.25999999999999]],"batl":null,"id":19924823,"hc":null,"bdatb":null}],"img":null,"tv":null,"con":null,"marketdefinition":null,"id":"1.258926623"}],"conflatems":null,"op":"mcm","id":3}
{"ct":null,"SegmentType":null,"clk":"ANbYAgDh3QIAhL0C","heartbeatms":null,"pt":1780840010603,"initialclk":null,"mc":[{"rc":[{"tv":null,"batb":null,"spb":null,"bdatl":null,"trd":null,"spf":null,"ltp":null,"atb":[[8.1999999999999993,235.47]],"spl":null,"spn":null,"atl":null,"batl":null,"id":16570658,"hc":null,"bdatb":null},{"tv":null,"batb":null,"spb":null,"bdatl":null,"trd":null,"spf":null,"ltp":null,"atb":null,"spl":null,"spn":null,"atl":[[1.1399999999999999,26881.029999999999]],"batl":null,"id":19924823,"hc":null,"bdatb":null}],"img":null,"tv":null,"con":null,"marketdefinition":null,"id":"1.258926623"}],"conflatems":null,"op":"mcm","id":3}
{"ct":null,"SegmentType":null,"clk":"AIzZAgCc3gIAv70C","heartbeatms":null,"pt":1780840011171,"initialclk":null,"mc":[{"rc":[{"tv":null,"batb":null,"spb":null,"bdatl":null,"trd":null,"spf":null,"ltp":null,"atb":[[8,383.50999999999999]],"spl":null,"spn":null,"atl":null,"batl":null,"id":16570658,"hc":null,"bdatb":null},{"tv":null,"batb":null,"spb":null,"bdatl":null,"trd":null,"spf":null,"ltp":null,"atb":null,"spl":null,"spn":null,"atl":[[1.1399999999999999,26883.029999999999]],"batl":null,"id":19924823,"hc":null,"bdatb":null}],"img":null,"tv":null,"con":null,"marketdefinition":null,"id":"1.258926623"}],"conflatems":null,"op":"mcm","id":3}
{"ct":null,"SegmentType":null,"clk":"AJPZAgCm3gIAyr0C","heartbeatms":null,"pt":1780840011276,"initialclk":null,"mc":[{"rc":[{"tv":null,"batb":null,"spb":null,"bdatl":null,"trd":null,"spf":null,"ltp":null,"atb":[[8.8000000000000007,308.08999999999997]],"spl":null,"spn":null,"atl":null,"batl":null,"id":16570658,"hc":null,"bdatb":null},{"tv":null,"batb":null,"spb":null,"bdatl":null,"trd":null,"spf":null,"ltp":null,"atb":[[1.1000000000000001,63283.610000000001]],"spl":null,"spn":null,"atl":null,"batl":null,"id":19924823,"hc":null,"bdatb":null}],"img":null,"tv":null,"con":null,"marketdefinition":null,"id":"1.258926623"}],"conflatems":null,"op":"mcm","id":3}
{"ct":null,"SegmentType":null,"clk":"ALDZAgC93gIA370C","heartbeatms":null,"pt":1780840011381,"initialclk":null,"mc":[{"rc":[{"tv":null,"batb":null,"spb":null,"bdatl":null,"trd":null,"spf":null,"ltp":null,"atb":null,"spl":null,"spn":null,"atl":[[1.1399999999999999,26881.029999999999]],"batl":null,"id":19924823,"hc":null,"bdatb":null}],"img":null,"tv":null,"con":null,"marketdefinition":null,"id":"1.258926623"}],"conflatems":null,"op":"mcm","id":3}
{"ct":null,"SegmentType":null,"clk":"ALzZAgDL3gIA6L0C","heartbeatms":null,"pt":1780840011480,"initialclk":null,"mc":[{"rc":[{"tv":2115898.27,"batb":null,"spb":null,"bdatl":null,"trd":[[1.1299999999999999,251419.75]],"spf":null,"ltp":1.1299999999999999,"atb":null,"spl":null,"spn":null,"atl":[[1.1299999999999999,37905.970000000001],[1.1599999999999999,27044.240000000002]],"batl":null,"id":19924823,"hc":null,"bdatb":null}],"img":null,"tv":2365092.3300000001,"con":null,"marketdefinition":null,"id":"1.258926623"}],"conflatems":null,"op":"mcm","id":3}
{"ct":null,"SegmentType":null,"clk":"ANvZAgD23gIAgr4C","heartbeatms":null,"pt":1780840011895,"initialclk":null,"mc":[{"rc":[{"tv":null,"batb":null,"spb":null,"bdatl":null,"trd":null,"spf":null,"ltp":null,"atb":null,"spl":null,"spn":null,"atl":[[1000,1.0900000000000001]],"batl":null,"id":19924823,"hc":null,"bdatb":null}],"img":null,"tv":null,"con":null,"marketdefinition":null,"id":"1.258926623"}],"conflatems":null,"op":"mcm","id":3}
{"ct":null,"SegmentType":null,"clk":"AOHZAgCB3wIAjr4C","heartbeatms":null,"pt":1780840011991,"initialclk":null,"mc":[{"rc":[{"tv":null,"batb":null,"spb":null,"bdatl":null,"trd":null,"spf":null,"ltp":null,"atb":null,"spl":null,"spn":null,"atl":[[10,416.05000000000001]],"batl":null,"id":16570658,"hc":null,"bdatb":null}],"img":null,"tv":null,"con":null,"marketdefinition":null,"id":"1.258926623"}],"conflatems":null,"op":"mcm","id":3}
{"ct":null,"SegmentType":null,"clk":"APnZAgCg3wIAq74C","heartbeatms":null,"pt":1780840012303,"initialclk":null,"mc":[{"rc":[{"tv":null,"batb":null,"spb":null,"bdatl":null,"trd":null,"spf":null,"ltp":null,"atb":null,"spl":null,"spn":null,"atl":[[1000,0.88]],"batl":null,"id":19924823,"hc":null,"bdatb":null}],"img":null,"tv":null,"con":null,"marketdefinition":null,"id":"1.258926623"}],"conflatems":null,"op":"mcm","id":3}
{"ct":null,"SegmentType":null,"clk":"APfaAgC34AIAmr8C","heartbeatms":null,"pt":1780840013699,"initialclk":null,"mc":[{"rc":[{"tv":null,"batb":null,"spb":null,"bdatl":null,"trd":null,"spf":null,"ltp":null,"atb":[[7.7999999999999998,615.49000000000001],[7.4000000000000004,9.2300000000000004],[7.2000000000000002,13.66]],"spl":null,"spn":null,"atl":[[11,181.94],[10.5,161.03]],"batl":null,"id":16570658,"hc":null,"bdatb":null},{"tv":null,"batb":null,"spb":null,"bdatl":null,"trd":null,"spf":null,"ltp":null,"atb":[[1.1000000000000001,63289.919999999998],[1.0900000000000001,40189.459999999999]],"spl":null,"spn":null,"atl":[[1.1699999999999999,8881.3700000000008],[1.1599999999999999,27049.18],[1.1499999999999999,28951.990000000002]],"batl":null,"id":19924823,"hc":null,"bdatb":null}],"img":null,"tv":null,"con":null,"marketdefinition":null,"id":"1.258926623"}],"conflatems":null,"op":"mcm","id":3}
{"ct":null,"SegmentType":null,"clk":"APzaAgDD4AIAob8C","heartbeatms":null,"pt":1780840013798,"initialclk":null,"mc":[{"rc":[{"tv":null,"batb":null,"spb":null,"bdatl":null,"trd":null,"spf":null,"ltp":null,"atb":[[1.04,73842.729999999996],[1.05,74308.929999999993],[1.0700000000000001,38876.290000000001],[1.0800000000000001,40510.370000000003],[1.1000000000000001,63291.919999999998],[1.0900000000000001,40191.459999999999],[1.0600000000000001,63326.940000000002],[1.02,90735.919999999998],[1.03,88974.589999999997],[1.01,93593.869999999995]],"spl":null,"spn":null,"atl":null,"batl":null,"id":19924823,"hc":null,"bdatb":null}],"img":null,"tv":null,"con":null,"marketdefinition":null,"id":"1.258926623"}],"conflatems":null,"op":"mcm","id":3}
{"ct":null,"SegmentType":null,"clk":"AKbbAgD/4AIAyr8C","heartbeatms":null,"pt":1780840014314,"initialclk":null,"mc":[{"rc":[{"tv":null,"batb":null,"spb":null,"bdatl":null,"trd":null,"spf":null,"ltp":null,"atb":null,"spl":null,"spn":null,"atl":[[1.2,9101.0499999999993]],"batl":null,"id":19924823,"hc":null,"bdatb":null}],"img":null,"tv":null,"con":null,"marketdefinition":null,"id":"1.258926623"}],"conflatems":null,"op":"mcm","id":3}
{"ct":null,"SegmentType":null,"clk":"AM7bAgCs4QIA3r8C","heartbeatms":null,"pt":1780840014681,"initialclk":null,"mc":[{"rc":[{"tv":null,"batb":null,"spb":null,"bdatl":null,"trd":null,"spf":null,"ltp":null,"atb":null,"spl":null,"spn":null,"atl":[[1.22,8889.1000000000004]],"batl":null,"id":19924823,"hc":null,"bdatb":null}],"img":null,"tv":null,"con":null,"marketdefinition":null,"id":"1.258926623"}],"conflatems":null,"op":"mcm","id":3}
{"ct":null,"SegmentType":null,"clk":"ANbbAgC34QIA6b8C","heartbeatms":null,"pt":1780840014788,"initialclk":null,"mc":[{"rc":[{"tv":null,"batb":null,"spb":null,"bdatl":null,"trd":null,"spf":null,"ltp":null,"atb":[[9,0.050000000000000003]],"spl":null,"spn":null,"atl":null,"batl":null,"id":16570658,"hc":null,"bdatb":null}],"img":null,"tv":null,"con":null,"marketdefinition":null,"id":"1.258926623"}],"conflatems":null,"op":"mcm","id":3}
{"ct":null,"SegmentType":null,"clk":"AKPcAgD14QIAocAC","heartbeatms":null,"pt":1780840015408,"initialclk":null,"mc":[{"rc":[{"tv":null,"batb":null,"spb":null,"bdatl":null,"trd":null,"spf":null,"ltp":null,"atb":[[8.8000000000000007,408.08999999999998]],"spl":null,"spn":null,"atl":[[9.8000000000000007,153.06]],"batl":null,"id":16570658,"hc":null,"bdatb":null},{"tv":null,"batb":null,"spb":null,"bdatl":null,"trd":null,"spf":null,"ltp":null,"atb":[[1.1100000000000001,71946.020000000004]],"spl":null,"spn":null,"atl":[[1.1299999999999999,37906.18]],"batl":null,"id":19924823,"hc":null,"bdatb":null}],"img":null,"tv":null,"con":null,"marketdefinition":null,"id":"1.258926623"}],"conflatems":null,"op":"mcm","id":3}
{"ct":null,"SegmentType":null,"clk":"AMncAgCN4gIAvsAC","heartbeatms":null,"pt":1780840015712,"initialclk":null,"mc":[{"rc":[{"tv":249204.07000000001,"batb":null,"spb":null,"bdatl":null,"trd":[[8.8000000000000007,1975],[9,1087.5799999999999]],"spf":null,"ltp":null,"atb":[[8.8000000000000007,403.13999999999999],[9,0]],"spl":null,"spn":null,"atl":null,"batl":null,"id":16570658,"hc":null,"bdatb":null}],"img":null,"tv":2365102.3399999999,"con":null,"marketdefinition":null,"id":"1.258926623"}],"conflatems":null,"op":"mcm","id":3}
{"ct":null,"SegmentType":null,"clk":"AIXdAgDI4gIA7MAC","heartbeatms":null,"pt":1780840016179,"initialclk":null,"mc":[{"rc":[{"tv":null,"batb":null,"spb":null,"bdatl":null,"trd":null,"spf":null,"ltp":null,"atb":[[8.8000000000000007,400]],"spl":null,"spn":null,"atl":null,"batl":null,"id":16570658,"hc":null,"bdatb":null}],"img":null,"tv":null,"con":null,"marketdefinition":null,"id":"1.258926623"}],"conflatems":null,"op":"mcm","id":3}
{"ct":null,"SegmentType":null,"clk":"AJPdAgDh4gIAgsEC","heartbeatms":null,"pt":1780840016393,"initialclk":null,"mc":[{"rc":[{"tv":249206.70999999999,"batb":null,"spb":null,"bdatl":null,"trd":[[8.8000000000000007,1977.6400000000001]],"spf":null,"ltp":null,"atb":[[7.7999999999999998,614.62],[8.8000000000000007,398.68000000000001],[7.5999999999999996,34.140000000000001]],"spl":null,"spn":null,"atl":[[10.5,160.03],[10,415.18000000000001]],"batl":null,"id":16570658,"hc":null,"bdatb":null},{"tv":null,"batb":null,"spb":null,"bdatl":null,"trd":null,"spf":null,"ltp":null,"atb":[[1.1000000000000001,63285.339999999997],[1.1100000000000001,71940.5]],"spl":null,"spn":null,"atl":[[1.1599999999999999,27044.5],[1.1499999999999999,28946.75]],"batl":null,"id":19924823,"hc":null,"bdatb":null}],"img":null,"tv":2365104.98,"con":null,"marketdefinition":null,"id":"1.258926623"}],"conflatems":null,"op":"mcm","id":3}
{"ct":null,"SegmentType":null,"clk":"AIneAgDV4wIA78EC","heartbeatms":null,"pt":1780840017778,"initialclk":null,"mc":[{"rc":[{"tv":249206.81,"batb":null,"spb":null,"bdatl":null,"trd":[[9.1999999999999993,1725.8399999999999]],"spf":null,"ltp":9.1999999999999993,"atb":null,"spl":null,"spn":null,"atl":[[9.1999999999999993,157.40000000000001]],"batl":null,"id":16570658,"hc":null,"bdatb":null}],"img":null,"tv":2365105.0800000001,"con":null,"marketdefinition":null,"id":"1.258926623"}],"conflatems":null,"op":"mcm","id":3}
{"ct":null,"SegmentType":null,"clk":"AJneAgDo4wIA/MEC","heartbeatms":null,"pt":1780840017987,"initialclk":null,"mc":[{"rc":[{"tv":2115900,"batb":null,"spb":null,"bdatl":null,"trd":[[1.1200000000000001,67130.539999999994]],"spf":null,"ltp":1.1200000000000001,"atb":[[1.1200000000000001,1249.0999999999999]],"spl":null,"spn":null,"atl":null,"batl":null,"id":19924823,"hc":null,"bdatb":null}],"img":null,"tv":2365106.8100000001,"con":null,"marketdefinition":null,"id":"1.258926623"}],"conflatems":null,"op":"mcm","id":3}
{"ct":null,"SegmentType":null,"clk":"AK7eAgCH5AIAlMIC","heartbeatms":null,"pt":1780840018290,"initialclk":null,"mc":[{"rc":[{"tv":null,"batb":null,"spb":null,"bdatl":null,"trd":null,"spf":null,"ltp":null,"atb":null,"spl":null,"spn":null,"atl":[[1.22,9089.1000000000004]],"batl":null,"id":19924823,"hc":null,"bdatb":null}],"img":null,"tv":null,"con":null,"marketdefinition":null,"id":"1.258926623"}],"conflatems":null,"op":"mcm","id":3}
{"ct":null,"SegmentType":null,"clk":"ALbeAgCS5AIAnMIC","heartbeatms":null,"pt":1780840018392,"initialclk":null,"mc":[{"rc":[{"tv":null,"batb":null,"spb":null,"bdatl":null,"trd":null,"spf":null,"ltp":null,"atb":null,"spl":null,"spn":null,"atl":[[1.1299999999999999,37898.690000000002]],"batl":null,"id":19924823,"hc":null,"bdatb":null}],"img":null,"tv":null,"con":null,"marketdefinition":null,"id":"1.258926623"}],"conflatems":null,"op":"mcm","id":3}
{"ct":null,"SegmentType":null,"clk":"ANneAgDI5AIAu8IC","heartbeatms":null,"pt":1780840018805,"initialclk":null,"mc":[{"rc":[{"tv":2115917.3900000001,"batb":null,"spb":null,"bdatl":null,"trd":[[1.1299999999999999,251437.14000000001]],"spf":null,"ltp":1.1299999999999999,"atb":null,"spl":null,"spn":null,"atl":[[1.1299999999999999,37889.989999999998]],"batl":null,"id":19924823,"hc":null,"bdatb":null}],"img":null,"tv":2365124.2000000002,"con":null,"marketdefinition":null,"id":"1.258926623"}],"conflatems":null,"op":"mcm","id":3}
{"ct":null,"SegmentType":null,"clk":"AOPeAgDR5AIAv8IC","heartbeatms":null,"pt":1780840018906,"initialclk":null,"mc":[{"rc":[{"tv":null,"batb":null,"spb":null,"bdatl":null,"trd":null,"spf":null,"ltp":null,"atb":[[8.8000000000000007,0]],"spl":null,"spn":null,"atl":null,"batl":null,"id":16570658,"hc":null,"bdatb":null}],"img":null,"tv":null,"con":null,"marketdefinition":null,"id":"1.258926623"}],"conflatems":null,"op":"mcm","id":3}
{"ct":null,"SegmentType":null,"clk":"AOzeAgDb5AIAy8IC","heartbeatms":null,"pt":1780840019013,"initialclk":null,"mc":[{"rc":[{"tv":null,"batb":null,"spb":null,"bdatl":null,"trd":null,"spf":null,"ltp":null,"atb":[[8.5999999999999996,398.68000000000001]],"spl":null,"spn":null,"atl":null,"batl":null,"id":16570658,"hc":null,"bdatb":null},{"tv":null,"batb":null,"spb":null,"bdatl":null,"trd":null,"spf":null,"ltp":null,"atb":null,"spl":null,"spn":null,"atl":[[1.21,8960.3500000000004]],"batl":null,"id":19924823,"hc":null,"bdatb":null}],"img":null,"tv":null,"con":null,"marketdefinition":null,"id":"1.258926623"}],"conflatems":null,"op":"mcm","id":3}
{"ct":null,"SegmentType":null,"clk":"AIHfAgDw5AIA1MIC","heartbeatms":null,"pt":1780840019213,"initialclk":null,"mc":[{"rc":[{"tv":null,"batb":null,"spb":null,"bdatl":null,"trd":null,"spf":null,"ltp":null,"atb":null,"spl":null,"spn":null,"atl":[[1.1299999999999999,37962.190000000002]],"batl":null,"id":19924823,"hc":null,"bdatb":null}],"img":null,"tv":null,"con":null,"marketdefinition":null,"id":"1.258926623"}],"conflatems":null,"op":"mcm","id":3}
{"ct":null,"SegmentType":null,"clk":"AOjfAgDe5QIAvcMC","heartbeatms":null,"pt":1780840020203,"initialclk":null,"mc":[{"rc":[{"tv":null,"batb":null,"spb":null,"bdatl":null,"trd":null,"spf":null,"ltp":null,"atb":[[8.8000000000000007,55.369999999999997]],"spl":null,"spn":null,"atl":null,"batl":null,"id":16570658,"hc":null,"bdatb":null}],"img":null,"tv":null,"con":null,"marketdefinition":null,"id":"1.258926623"}],"conflatems":null,"op":"mcm","id":3}
{"ct":null,"SegmentType":null,"clk":"AJTgAgCK5gIA2cMC","heartbeatms":null,"pt":1780840020612,"initialclk":null,"mc":[{"rc":[{"tv":null,"batb":null,"spb":null,"bdatl":null,"trd":null,"spf":null,"ltp":null,"atb":null,"spl":null,"spn":null,"atl":[[1.1299999999999999,38034.379999999997]],"batl":null,"id":19924823,"hc":null,"bdatb":null}],"img":null,"tv":null,"con":null,"marketdefinition":null,"id":"1.258926623"}],"conflatems":null,"op":"mcm","id":3}
{"ct":null,"SegmentType":null,"clk":"AKjgAgCa5gIA8sMC","heartbeatms":null,"pt":1780840020818,"initialclk":null,"mc":[{"rc":[{"tv":null,"batb":null,"spb":null,"bdatl":null,"trd":null,"spf":null,"ltp":null,"atb":[[8.8000000000000007,110.74]],"spl":null,"spn":null,"atl":null,"batl":null,"id":16570658,"hc":null,"bdatb":null}],"img":null,"tv":null,"con":null,"marketdefinition":null,"id":"1.258926623"}],"conflatems":null,"op":"mcm","id":3}
{"ct":null,"SegmentType":null,"clk":"AOzgAgDc5gIApMQC","heartbeatms":null,"pt":1780840021294,"initialclk":null,"mc":[{"rc":[{"tv":null,"batb":null,"spb":null,"bdatl":null,"trd":null,"spf":null,"ltp":null,"atb":null,"spl":null,"spn":null,"atl":[[1.1299999999999999,37610.470000000001]],"batl":null,"id":19924823,"hc":null,"bdatb":null}],"img":null,"tv":null,"con":null,"marketdefinition":null,"id":"1.258926623"}],"conflatems":null,"op":"mcm","id":3}
{"ct":null,"SegmentType":null,"clk":"ALzhAgCs5wIA5sQC","heartbeatms":null,"pt":1780840022018,"initialclk":null,"mc":[{"rc":[{"tv":null,"batb":null,"spb":null,"bdatl":null,"trd":null,"spf":null,"ltp":null,"atb":null,"spl":null,"spn":null,"atl":[[10,501.56]],"batl":null,"id":16570658,"hc":null,"bdatb":null},{"tv":2116117.3900000001,"batb":null,"spb":null,"bdatl":null,"trd":[[1.1200000000000001,67330.539999999994]],"spf":null,"ltp":1.1200000000000001,"atb":[[1.1200000000000001,1149.0999999999999]],"spl":null,"spn":null,"atl":null,"batl":null,"id":19924823,"hc":null,"bdatb":null}],"img":null,"tv":2365324.2000000002,"con":null,"marketdefinition":null,"id":"1.258926623"}],"conflatems":null,"op":"mcm","id":3}
{"ct":null,"SegmentType":null,"clk":"AOjhAgDZ5wIAjcUC","heartbeatms":null,"pt":1780840022431,"initialclk":null,"mc":[{"rc":[{"tv":2116317.3900000001,"batb":null,"spb":null,"bdatl":null,"trd":[[1.1200000000000001,67530.539999999994]],"spf":null,"ltp":null,"atb":[[1.1200000000000001,1049.0999999999999]],"spl":null,"spn":null,"atl":null,"batl":null,"id":19924823,"hc":null,"bdatb":null}],"img":null,"tv":2365524.2000000002,"con":null,"marketdefinition":null,"id":"1.258926623"}],"conflatems":null,"op":"mcm","id":3}
{"ct":null,"SegmentType":null,"clk":"AP/hAgDy5wIAoMUC","heartbeatms":null,"pt":1780840022634,"initialclk":null,"mc":[{"rc":[{"tv":null,"batb":null,"spb":null,"bdatl":null,"trd":null,"spf":null,"ltp":null,"atb":null,"spl":null,"spn":null,"atl":[[1.21,9160.3500000000004]],"batl":null,"id":19924823,"hc":null,"bdatb":null}],"img":null,"tv":null,"con":null,"marketdefinition":null,"id":"1.258926623"}],"conflatems":null,"op":"mcm","id":3}
{"ct":null,"SegmentType":null,"clk":"AIXiAgCB6AIAq8UC","heartbeatms":null,"pt":1780840022689,"initialclk":null,"mc":[{"rc":[{"tv":null,"batb":null,"spb":null,"bdatl":null,"trd":null,"spf":null,"ltp":null,"atb":null,"spl":null,"spn":null,"atl":[[9.8000000000000007,0]],"batl":null,"id":16570658,"hc":null,"bdatb":null},{"tv":2116517.3900000001,"batb":null,"spb":null,"bdatl":null,"trd":[[1.1200000000000001,67730.539999999994]],"spf":null,"ltp":null,"atb":[[1.1200000000000001,949.10000000000002]],"spl":null,"spn":null,"atl":null,"batl":null,"id":19924823,"hc":null,"bdatb":null}],"img":null,"tv":2365724.2000000002,"con":null,"marketdefinition":null,"id":"1.258926623"}],"conflatems":null,"op":"mcm","id":3}
{"ct":null,"SegmentType":null,"clk":"AJHiAgCO6AIAusUC","heartbeatms":null,"pt":1780840022795,"initialclk":null,"mc":[{"rc":[{"tv":null,"batb":null,"spb":null,"bdatl":null,"trd":null,"spf":null,"ltp":null,"atb":null,"spl":null,"spn":null,"atl":[[9.4000000000000004,125.03]],"batl":null,"id":16570658,"hc":null,"bdatb":null}],"img":null,"tv":null,"con":null,"marketdefinition":null,"id":"1.258926623"}],"conflatems":null,"op":"mcm","id":3}
{"ct":null,"SegmentType":null,"clk":"ALbiAgCw6AIA0sUC","heartbeatms":null,"pt":1780840023105,"initialclk":null,"mc":[{"rc":[{"tv":null,"batb":null,"spb":null,"bdatl":null,"trd":null,"spf":null,"ltp":null,"atb":[[7.7999999999999998,801.44000000000005]],"spl":null,"spn":null,"atl":null,"batl":null,"id":16570658,"hc":null,"bdatb":null}],"img":null,"tv":null,"con":null,"marketdefinition":null,"id":"1.258926623"}],"conflatems":null,"op":"mcm","id":3}
{"ct":null,"SegmentType":null,"clk":"AMPiAgC86AIA3MUC","heartbeatms":null,"pt":1780840023206,"initialclk":null,"mc":[{"rc":[{"tv":null,"batb":null,"spb":null,"bdatl":null,"trd":null,"spf":null,"ltp":null,"atb":[[8,199.72]],"spl":null,"spn":null,"atl":null,"batl":null,"id":16570658,"hc":null,"bdatb":null}],"img":null,"tv":null,"con":null,"marketdefinition":null,"id":"1.258926623"}],"conflatems":null,"op":"mcm","id":3}
{"ct":null,"SegmentType":null,"clk":"AMbiAgDH6AIA4cUC","heartbeatms":null,"pt":1780840023308,"initialclk":null,"mc":[{"rc":[{"tv":null,"batb":null,"spb":null,"bdatl":null,"trd":null,"spf":null,"ltp":null,"atb":null,"spl":null,"spn":null,"atl":[[1.22,8889.1000000000004]],"batl":null,"id":19924823,"hc":null,"bdatb":null}],"img":null,"tv":null,"con":null,"marketdefinition":null,"id":"1.258926623"}],"conflatems":null,"op":"mcm","id":3}
{"ct":null,"SegmentType":null,"clk":"ANbiAgDR6AIA6sUC","heartbeatms":null,"pt":1780840023413,"initialclk":null,"mc":[{"rc":[{"tv":null,"batb":null,"spb":null,"bdatl":null,"trd":null,"spf":null,"ltp":null,"atb":null,"spl":null,"spn":null,"atl":[[9.5999999999999996,176.25]],"batl":null,"id":16570658,"hc":null,"bdatb":null}],"img":null,"tv":null,"con":null,"marketdefinition":null,"id":"1.258926623"}],"conflatems":null,"op":"mcm","id":3}
{"ct":null,"SegmentType":null,"clk":"ALjjAgCp6QIAssYC","heartbeatms":null,"pt":1780840024293,"initialclk":null,"mc":[{"rc":[{"tv":2116544.52,"batb":null,"spb":null,"bdatl":null,"trd":[[1.1299999999999999,251464.26999999999]],"spf":null,"ltp":1.1299999999999999,"atb":null,"spl":null,"spn":null,"atl":[[1.1299999999999999,37596.910000000003]],"batl":null,"id":19924823,"hc":null,"bdatb":null}],"img":null,"tv":2365751.3300000001,"con":null,"marketdefinition":null,"id":"1.258926623"}],"conflatems":null,"op":"mcm","id":3}
{"ct":null,"SegmentType":null,"clk":"AP3jAgDv6QIA\u002B8YC","heartbeatms":null,"pt":1780840025016,"initialclk":null,"mc":[{"rc":[{"tv":2116571.6400000001,"batb":null,"spb":null,"bdatl":null,"trd":[[1.1299999999999999,251491.39000000001]],"spf":null,"ltp":null,"atb":null,"spl":null,"spn":null,"atl":[[1.1299999999999999,37583.349999999999]],"batl":null,"id":19924823,"hc":null,"bdatb":null}],"img":null,"tv":2365778.4500000002,"con":null,"marketdefinition":null,"id":"1.258926623"}],"conflatems":null,"op":"mcm","id":3}
{"ct":null,"SegmentType":null,"clk":"AJHkAgCJ6gIAjccC","heartbeatms":null,"pt":1780840025219,"initialclk":null,"mc":[{"rc":[{"tv":null,"batb":null,"spb":null,"bdatl":null,"trd":null,"spf":null,"ltp":null,"atb":[[1.1100000000000001,72041.399999999994]],"spl":null,"spn":null,"atl":null,"batl":null,"id":19924823,"hc":null,"bdatb":null}],"img":null,"tv":null,"con":null,"marketdefinition":null,"id":"1.258926623"}],"conflatems":null,"op":"mcm","id":3}
{"ct":null,"SegmentType":null,"clk":"AKTkAgCg6gIAoccC","heartbeatms":null,"pt":1780840025426,"initialclk":null,"mc":[{"rc":[{"tv":2116671.6400000001,"batb":null,"spb":null,"bdatl":null,"trd":[[1.1200000000000001,67830.539999999994]],"spf":null,"ltp":1.1200000000000001,"atb":[[1.1200000000000001,899.10000000000002]],"spl":null,"spn":null,"atl":null,"batl":null,"id":19924823,"hc":null,"bdatb":null}],"img":null,"tv":2365878.4500000002,"con":null,"marketdefinition":null,"id":"1.258926623"}],"conflatems":null,"op":"mcm","id":3}
{"ct":null,"SegmentType":null,"clk":"AMbkAgDI6gIAxccC","heartbeatms":null,"pt":1780840025699,"initialclk":null,"mc":[{"rc":[{"tv":2116698.7599999998,"batb":null,"spb":null,"bdatl":null,"trd":[[1.1299999999999999,251518.51000000001]],"spf":null,"ltp":1.1299999999999999,"atb":[[1.1100000000000001,72142.300000000003]],"spl":null,"spn":null,"atl":[[1.1299999999999999,37569.790000000001]],"batl":null,"id":19924823,"hc":null,"bdatb":null}],"img":null,"tv":2365905.5699999998,"con":null,"marketdefinition":null,"id":"1.258926623"}],"conflatems":null,"op":"mcm","id":3}
{"ct":null,"SegmentType":null,"clk":"AOrkAgDp6gIA3ccC","heartbeatms":null,"pt":1780840026001,"initialclk":null,"mc":[{"rc":[{"tv":2116725.8900000001,"batb":null,"spb":null,"bdatl":null,"trd":[[1.1299999999999999,251545.64000000001]],"spf":null,"ltp":null,"atb":[[1.1100000000000001,72243.199999999997]],"spl":null,"spn":null,"atl":[[1.1299999999999999,37556.220000000001]],"batl":null,"id":19924823,"hc":null,"bdatb":null}],"img":null,"tv":2365932.7000000002,"con":null,"marketdefinition":null,"id":"1.258926623"}],"conflatems":null,"op":"mcm","id":3}
{"ct":null,"SegmentType":null,"clk":"AILlAgCB6wIA7scC","heartbeatms":null,"pt":1780840026208,"initialclk":null,"mc":[{"rc":[{"tv":2116753.0099999998,"batb":null,"spb":null,"bdatl":null,"trd":[[1.1299999999999999,251572.76000000001]],"spf":null,"ltp":null,"atb":null,"spl":null,"spn":null,"atl":[[1.1299999999999999,37542.660000000003]],"batl":null,"id":19924823,"hc":null,"bdatb":null}],"img":null,"tv":2365959.8199999998,"con":null,"marketdefinition":null,"id":"1.258926623"}],"conflatems":null,"op":"mcm","id":3}
{"ct":null,"SegmentType":null,"clk":"AIjlAgCN6wIA9scC","heartbeatms":null,"pt":1780840026304,"initialclk":null,"mc":[{"rc":[{"tv":null,"batb":null,"spb":null,"bdatl":null,"trd":null,"spf":null,"ltp":null,"atb":null,"spl":null,"spn":null,"atl":[[1.22,9089.1000000000004]],"batl":null,"id":19924823,"hc":null,"bdatb":null}],"img":null,"tv":null,"con":null,"marketdefinition":null,"id":"1.258926623"}],"conflatems":null,"op":"mcm","id":3}
{"ct":null,"SegmentType":null,"clk":"AMjlAgDh6wIAvsgC","heartbeatms":null,"pt":1780840027030,"initialclk":null,"mc":[{"rc":[{"tv":null,"batb":null,"spb":null,"bdatl":null,"trd":null,"spf":null,"ltp":null,"atb":null,"spl":null,"spn":null,"atl":[[1.2,8901.0499999999993]],"batl":null,"id":19924823,"hc":null,"bdatb":null}],"img":null,"tv":null,"con":null,"marketdefinition":null,"id":"1.258926623"}],"conflatems":null,"op":"mcm","id":3}
{"ct":null,"SegmentType":null,"clk":"AIrmAgCs7AIA\u002BMgC","heartbeatms":null,"pt":1780840027706,"initialclk":null,"mc":[{"rc":[{"tv":null,"batb":null,"spb":null,"bdatl":null,"trd":null,"spf":null,"ltp":null,"atb":null,"spl":null,"spn":null,"atl":[[1.1399999999999999,26894.59]],"batl":null,"id":19924823,"hc":null,"bdatb":null}],"img":null,"tv":null,"con":null,"marketdefinition":null,"id":"1.258926623"}],"conflatems":null,"op":"mcm","id":3}
{"ct":null,"SegmentType":null,"clk":"AL7mAgDp7AIAsMkC","heartbeatms":null,"pt":1780840028236,"initialclk":null,"mc":[{"rc":[{"tv":null,"batb":null,"spb":null,"bdatl":null,"trd":null,"spf":null,"ltp":null,"atb":null,"spl":null,"spn":null,"atl":[[1.1399999999999999,26908.150000000001]],"batl":null,"id":19924823,"hc":null,"bdatb":null}],"img":null,"tv":null,"con":null,"marketdefinition":null,"id":"1.258926623"}],"conflatems":null,"op":"mcm","id":3}
{"ct":null,"SegmentType":null,"clk":"AITnAgCd7QIA6ckC","heartbeatms":null,"pt":1780840028700,"initialclk":null,"mc":[{"rc":[{"tv":null,"batb":null,"spb":null,"bdatl":null,"trd":null,"spf":null,"ltp":null,"atb":null,"spl":null,"spn":null,"atl":[[9.5999999999999996,20]],"batl":null,"id":16570658,"hc":null,"bdatb":null}],"img":null,"tv":null,"con":null,"marketdefinition":null,"id":"1.258926623"}],"conflatems":null,"op":"mcm","id":3}
{"ct":null,"SegmentType":null,"clk":"AKTnAgC17QIA\u002B8kC","heartbeatms":null,"pt":1780840028908,"initialclk":null,"mc":[{"rc":[{"tv":2117038.5299999998,"batb":null,"spb":null,"bdatl":null,"trd":[[1.1200000000000001,68116.059999999998]],"spf":null,"ltp":1.1200000000000001,"atb":[[1.1200000000000001,756.34000000000003]],"spl":null,"spn":null,"atl":null,"batl":null,"id":19924823,"hc":null,"bdatb":null}],"img":null,"tv":2366245.3399999999,"con":null,"marketdefinition":null,"id":"1.258926623"}],"conflatems":null,"op":"mcm","id":3}
{"ct":null,"SegmentType":null,"clk":"AMnnAgDY7QIAj8oC","heartbeatms":null,"pt":1780840029218,"initialclk":null,"mc":[{"rc":[{"tv":null,"batb":null,"spb":null,"bdatl":null,"trd":null,"spf":null,"ltp":null,"atb":null,"spl":null,"spn":null,"atl":[[1.1399999999999999,26935.27]],"batl":null,"id":19924823,"hc":null,"bdatb":null}],"img":null,"tv":null,"con":null,"marketdefinition":null,"id":"1.258926623"}],"conflatems":null,"op":"mcm","id":3}
{"ct":null,"SegmentType":null,"clk":"AIHoAgCl7gIAvMoC","heartbeatms":null,"pt":1780840029730,"initialclk":null,"mc":[{"rc":[{"tv":null,"batb":null,"spb":null,"bdatl":null,"trd":null,"spf":null,"ltp":null,"atb":null,"spl":null,"spn":null,"atl":[[1.1399999999999999,26948.830000000002]],"batl":null,"id":19924823,"hc":null,"bdatb":null}],"img":null,"tv":null,"con":null,"marketdefinition":null,"id":"1.258926623"}],"conflatems":null,"op":"mcm","id":3}
{"ct":null,"SegmentType":null,"clk":"AJvoAgDD7gIA2soC","heartbeatms":null,"pt":1780840030030,"initialclk":null,"mc":[{"rc":[{"tv":249216.81,"batb":null,"spb":null,"bdatl":null,"trd":[[8.8000000000000007,1987.6400000000001]],"spf":null,"ltp":8.8000000000000007,"atb":[[8.8000000000000007,105.74]],"spl":null,"spn":null,"atl":null,"batl":null,"id":16570658,"hc":null,"bdatb":null}],"img":null,"tv":2366255.3399999999,"con":null,"marketdefinition":null,"id":"1.258926623"}],"conflatems":null,"op":"mcm","id":3}
{"ct":null,"SegmentType":null,"clk":"ALHoAgDf7gIA8soC","heartbeatms":null,"pt":1780840030296,"initialclk":null,"mc":[{"rc":[{"tv":null,"batb":null,"spb":null,"bdatl":null,"trd":null,"spf":null,"ltp":null,"atb":null,"spl":null,"spn":null,"atl":[[1.2,9101.0499999999993]],"batl":null,"id":19924823,"hc":null,"bdatb":null}],"img":null,"tv":null,"con":null,"marketdefinition":null,"id":"1.258926623"}],"conflatems":null,"op":"mcm","id":3}
{"ct":null,"SegmentType":null,"clk":"AIvpAgC87wIAxssC","heartbeatms":null,"pt":1780840031226,"initialclk":null,"mc":[{"rc":[{"tv":null,"batb":null,"spb":null,"bdatl":null,"trd":null,"spf":null,"ltp":null,"atb":[[8,383.75]],"spl":null,"spn":null,"atl":null,"batl":null,"id":16570658,"hc":null,"bdatb":null}],"img":null,"tv":null,"con":null,"marketdefinition":null,"id":"1.258926623"}],"conflatems":null,"op":"mcm","id":3}
{"ct":null,"SegmentType":null,"clk":"AK/pAgDd7wIA3MsC","heartbeatms":null,"pt":1780840031530,"initialclk":null,"mc":[{"rc":[{"tv":null,"batb":null,"spb":null,"bdatl":null,"trd":null,"spf":null,"ltp":null,"atb":null,"spl":null,"spn":null,"atl":[[9.8000000000000007,153.06]],"batl":null,"id":16570658,"hc":null,"bdatb":null}],"img":null,"tv":null,"con":null,"marketdefinition":null,"id":"1.258926623"}],"conflatems":null,"op":"mcm","id":3}
{"ct":null,"SegmentType":null,"clk":"ALfpAgDn7wIA5MsC","heartbeatms":null,"pt":1780840031631,"initialclk":null,"mc":[{"rc":[{"tv":null,"batb":null,"spb":null,"bdatl":null,"trd":null,"spf":null,"ltp":null,"atb":[[7.7999999999999998,614.62]],"spl":null,"spn":null,"atl":null,"batl":null,"id":16570658,"hc":null,"bdatb":null}],"img":null,"tv":null,"con":null,"marketdefinition":null,"id":"1.258926623"}],"conflatems":null,"op":"mcm","id":3}
{"ct":null,"SegmentType":null,"clk":"ANDpAgCH8AIA\u002BssC","heartbeatms":null,"pt":1780840031896,"initialclk":null,"mc":[{"rc":[{"tv":null,"batb":null,"spb":null,"bdatl":null,"trd":null,"spf":null,"ltp":null,"atb":null,"spl":null,"spn":null,"atl":[[1.22,8889.1000000000004]],"batl":null,"id":19924823,"hc":null,"bdatb":null}],"img":null,"tv":null,"con":null,"marketdefinition":null,"id":"1.258926623"}],"conflatems":null,"op":"mcm","id":3}
{"ct":null,"SegmentType":null,"clk":"AL/rAgC/8gIA5M0C","heartbeatms":null,"pt":1780840034424,"initialclk":null,"mc":[{"rc":[{"tv":null,"batb":null,"spb":null,"bdatl":null,"trd":null,"spf":null,"ltp":null,"atb":null,"spl":null,"spn":null,"atl":[[1.1599999999999999,27115.66]],"batl":null,"id":19924823,"hc":null,"bdatb":null}],"img":null,"tv":null,"con":null,"marketdefinition":null,"id":"1.258926623"}],"conflatems":null,"op":"mcm","id":3}
{"ct":null,"SegmentType":null,"clk":"AI3sAgCJ8wIAnc4C","heartbeatms":null,"pt":1780840035144,"initialclk":null,"mc":[{"rc":[{"tv":null,"batb":null,"spb":null,"bdatl":null,"trd":null,"spf":null,"ltp":null,"atb":null,"spl":null,"spn":null,"atl":[[1.22,9089.1000000000004]],"batl":null,"id":19924823,"hc":null,"bdatb":null}],"img":null,"tv":null,"con":null,"marketdefinition":null,"id":"1.258926623"}],"conflatems":null,"op":"mcm","id":3}
{"ct":null,"SegmentType":null,"clk":"APjsAgD\u002B8wIA9M4C","heartbeatms":null,"pt":1780840036228,"initialclk":null,"mc":[{"rc":[{"tv":null,"batb":null,"spb":null,"bdatl":null,"trd":null,"spf":null,"ltp":null,"atb":[[1.1200000000000001,885.89999999999998]],"spl":null,"spn":null,"atl":null,"batl":null,"id":19924823,"hc":null,"bdatb":null}],"img":null,"tv":null,"con":null,"marketdefinition":null,"id":"1.258926623"}],"conflatems":null,"op":"mcm","id":3}
{"ct":null,"SegmentType":null,"clk":"AMbtAgDV9AIAsc8C","heartbeatms":null,"pt":1780840037039,"initialclk":null,"mc":[{"rc":[{"tv":2117041.8300000001,"batb":null,"spb":null,"bdatl":null,"trd":[[1.1299999999999999,251576.06]],"spf":null,"ltp":1.1299999999999999,"atb":null,"spl":null,"spn":null,"atl":[[1.1299999999999999,37541.010000000002],[1.21,8960.3500000000004]],"batl":null,"id":19924823,"hc":null,"bdatb":null}],"img":null,"tv":2366258.6400000001,"con":null,"marketdefinition":null,"id":"1.258926623"}],"conflatems":null,"op":"mcm","id":3}
{"ct":null,"SegmentType":null,"clk":"AO3tAgD59AIAys8C","heartbeatms":null,"pt":1780840037406,"initialclk":null,"mc":[{"rc":[{"tv":249569.12,"batb":null,"spb":null,"bdatl":null,"trd":[[8.8000000000000007,2199.1100000000001],[8.5999999999999996,2915.5300000000002]],"spf":null,"ltp":8.5999999999999996,"atb":[[8.8000000000000007,0],[8.5999999999999996,328.25999999999999]],"spl":null,"spn":null,"atl":null,"batl":null,"id":16570658,"hc":null,"bdatb":null}],"img":null,"tv":2366610.9500000002,"con":null,"marketdefinition":null,"id":"1.258926623"}],"conflatems":null,"op":"mcm","id":3}
{"ct":null,"SegmentType":null,"clk":"AJvuAgCy9QIA988C","heartbeatms":null,"pt":1780840038021,"initialclk":null,"mc":[{"rc":[{"tv":2117273.8300000001,"batb":null,"spb":null,"bdatl":null,"trd":[[1.1299999999999999,251808.06]],"spf":null,"ltp":null,"atb":null,"spl":null,"spn":null,"atl":[[1.1299999999999999,37425.019999999997]],"batl":null,"id":19924823,"hc":null,"bdatb":null}],"img":null,"tv":2366842.9500000002,"con":null,"marketdefinition":null,"id":"1.258926623"}],"conflatems":null,"op":"mcm","id":3}
{"ct":null,"SegmentType":null,"clk":"AMLuAgDd9QIAndAC","heartbeatms":null,"pt":1780840038437,"initialclk":null,"mc":[{"rc":[{"tv":2118073.8300000001,"batb":null,"spb":null,"bdatl":null,"trd":[[1.1299999999999999,252608.06]],"spf":null,"ltp":null,"atb":null,"spl":null,"spn":null,"atl":[[1.1299999999999999,37025.019999999997]],"batl":null,"id":19924823,"hc":null,"bdatb":null}],"img":null,"tv":2367642.9500000002,"con":null,"marketdefinition":null,"id":"1.258926623"}],"conflatems":null,"op":"mcm","id":3}
{"ct":null,"SegmentType":null,"clk":"AN3vAgD89gIAlNEC","heartbeatms":null,"pt":1780840039929,"initialclk":null,"mc":[{"rc":[{"tv":null,"batb":null,"spb":null,"bdatl":null,"trd":null,"spf":null,"ltp":null,"atb":[[8.4000000000000004,541.38],[8.1999999999999993,113.52],[8,395.30000000000001]],"spl":null,"spn":null,"atl":null,"batl":null,"id":16570658,"hc":null,"bdatb":null},{"tv":null,"batb":null,"spb":null,"bdatl":null,"trd":null,"spf":null,"ltp":null,"atb":null,"spl":null,"spn":null,"atl":[[1.1399999999999999,27332.580000000002]],"batl":null,"id":19924823,"hc":null,"bdatb":null}],"img":null,"tv":null,"con":null,"marketdefinition":null,"id":"1.258926623"}],"conflatems":null,"op":"mcm","id":3}
{"ct":null,"SegmentType":null,"clk":"AOLvAgCF9wIAltEC","heartbeatms":null,"pt":1780840040029,"initialclk":null,"mc":[{"rc":[{"tv":null,"batb":null,"spb":null,"bdatl":null,"trd":null,"spf":null,"ltp":null,"atb":[[8.4000000000000004,472.38],[7.7999999999999998,902.10000000000002],[7.5999999999999996,129.21000000000001],[8,211.27000000000001]],"spl":null,"spn":null,"atl":[[9.8000000000000007,0],[11,240.16999999999999],[10.5,426.13]],"batl":null,"id":16570658,"hc":null,"bdatb":null},{"tv":null,"batb":null,"spb":null,"bdatl":null,"trd":null,"spf":null,"ltp":null,"atb":[[1.1000000000000001,61573.339999999997],[1.1100000000000001,70891.850000000006]],"spl":null,"spn":null,"atl":[[1.1399999999999999,25911.580000000002],[1.1499999999999999,27668.169999999998]],"batl":null,"id":19924823,"hc":null,"bdatb":null}],"img":null,"tv":null,"con":null,"marketdefinition":null,"id":"1.258926623"}],"conflatems":null,"op":"mcm","id":3}
{"ct":null,"SegmentType":null,"clk":"AO7vAgCN9wIAntEC","heartbeatms":null,"pt":1780840040138,"initialclk":null,"mc":[{"rc":[{"tv":null,"batb":null,"spb":null,"bdatl":null,"trd":null,"spf":null,"ltp":null,"atb":[[1.1100000000000001,70941.039999999994]],"spl":null,"spn":null,"atl":null,"batl":null,"id":19924823,"hc":null,"bdatb":null}],"img":null,"tv":null,"con":null,"marketdefinition":null,"id":"1.258926623"}],"conflatems":null,"op":"mcm","id":3}
{"ct":null,"SegmentType":null,"clk":"APvvAgCX9wIAptEC","heartbeatms":null,"pt":1780840040233,"initialclk":null,"mc":[{"rc":[{"tv":null,"batb":null,"spb":null,"bdatl":null,"trd":null,"spf":null,"ltp":null,"atb":[[8.4000000000000004,298.16000000000003],[8,37.049999999999997]],"spl":null,"spn":null,"atl":null,"batl":null,"id":16570658,"hc":null,"bdatb":null}],"img":null,"tv":null,"con":null,"marketdefinition":null,"id":"1.258926623"}],"conflatems":null,"op":"mcm","id":3}
{"ct":null,"SegmentType":null,"clk":"AIXwAgCm9wIArNEC","heartbeatms":null,"pt":1780840040336,"initialclk":null,"mc":[{"rc":[{"tv":null,"batb":null,"spb":null,"bdatl":null,"trd":null,"spf":null,"ltp":null,"atb":[[8.4000000000000004,0],[7,23.32],[6.7999999999999998,24.52],[8.1999999999999993,33.329999999999998]],"spl":null,"spn":null,"atl":[[10.5,277.56999999999999],[10,239.58000000000001]],"batl":null,"id":16570658,"hc":null,"bdatb":null},{"tv":2118819.5499999998,"batb":null,"spb":null,"bdatl":null,"trd":[[1.1299999999999999,253353.78]],"spf":null,"ltp":null,"atb":null,"spl":null,"spn":null,"atl":[[1.1299999999999999,36652.160000000003]],"batl":null,"id":19924823,"hc":null,"bdatb":null}],"img":null,"tv":2368388.6699999999,"con":null,"marketdefinition":null,"id":"1.258926623"}],"conflatems":null,"op":"mcm","id":3}
{"ct":null,"SegmentType":null,"clk":"AJDwAgCw9wIAtdEC","heartbeatms":null,"pt":1780840040437,"initialclk":null,"mc":[{"rc":[{"tv":2118872.1699999999,"batb":null,"spb":null,"bdatl":null,"trd":[[1.1200000000000001,68168.679999999993]],"spf":null,"ltp":1.1200000000000001,"atb":[[1.1200000000000001,859.59000000000003]],"spl":null,"spn":null,"atl":null,"batl":null,"id":19924823,"hc":null,"bdatb":null}],"img":null,"tv":2368441.29,"con":null,"marketdefinition":null,"id":"1.258926623"}],"conflatems":null,"op":"mcm","id":3}
{"ct":null,"SegmentType":null,"clk":"AJvwAgC89wIAvtEC","heartbeatms":null,"pt":1780840040543,"initialclk":null,"mc":[{"rc":[{"tv":null,"batb":null,"spb":null,"bdatl":null,"trd":null,"spf":null,"ltp":null,"atb":[[1.1200000000000001,1412.3399999999999]],"spl":null,"spn":null,"atl":null,"batl":null,"id":19924823,"hc":null,"bdatb":null}],"img":null,"tv":null,"con":null,"marketdefinition":null,"id":"1.258926623"}],"conflatems":null,"op":"mcm","id":3}
{"ct":null,"SegmentType":null,"clk":"AKXwAgDD9wIAx9EC","heartbeatms":null,"pt":1780840040614,"initialclk":null,"mc":[{"rc":[{"tv":null,"batb":null,"spb":null,"bdatl":null,"trd":null,"spf":null,"ltp":null,"atb":null,"spl":null,"spn":null,"atl":[[9.4000000000000004,3.73],[9.1999999999999993,49.950000000000003]],"batl":null,"id":16570658,"hc":null,"bdatb":null},{"tv":null,"batb":null,"spb":null,"bdatl":null,"trd":null,"spf":null,"ltp":null,"atb":[[1.1100000000000001,69819.899999999994]],"spl":null,"spn":null,"atl":[[1.1299999999999999,35708.669999999998]],"batl":null,"id":19924823,"hc":null,"bdatb":null}],"img":null,"tv":null,"con":null,"marketdefinition":null,"id":"1.258926623"}],"conflatems":null,"op":"mcm","id":3}
{"ct":null,"SegmentType":null,"clk":"AK7wAgDS9wIA0dEC","heartbeatms":null,"pt":1780840040722,"initialclk":null,"mc":[{"rc":[{"tv":2118954.9500000002,"batb":null,"spb":null,"bdatl":null,"trd":[[1.1299999999999999,253436.56]],"spf":null,"ltp":1.1299999999999999,"atb":[[1.1100000000000001,70334.679999999993]],"spl":null,"spn":null,"atl":[[1.1299999999999999,35667.269999999997],[1.1499999999999999,28717.150000000001]],"batl":null,"id":19924823,"hc":null,"bdatb":null}],"img":null,"tv":2368524.0699999998,"con":null,"marketdefinition":null,"id":"1.258926623"}],"conflatems":null,"op":"mcm","id":3}
{"ct":null,"SegmentType":null,"clk":"ALjwAgDf9wIA1tEC","heartbeatms":null,"pt":1780840040826,"initialclk":null,"mc":[{"rc":[{"tv":null,"batb":null,"spb":null,"bdatl":null,"trd":null,"spf":null,"ltp":null,"atb":[[1.1200000000000001,795.82000000000005]],"spl":null,"spn":null,"atl":[[1.1299999999999999,35020.730000000003],[1.1399999999999999,25738.75]],"batl":null,"id":19924823,"hc":null,"bdatb":null}],"img":null,"tv":null,"con":null,"marketdefinition":null,"id":"1.258926623"}],"conflatems":null,"op":"mcm","id":3}
{"ct":null,"SegmentType":null,"clk":"AKHxAgDN\u002BAIAwNIC","heartbeatms":null,"pt":1780840042008,"initialclk":null,"mc":[{"rc":[{"tv":2118994.9500000002,"batb":null,"spb":null,"bdatl":null,"trd":[[1.1299999999999999,253476.56]],"spf":null,"ltp":null,"atb":null,"spl":null,"spn":null,"atl":[[1.1299999999999999,35000.739999999998]],"batl":null,"id":19924823,"hc":null,"bdatb":null}],"img":null,"tv":2368564.0699999998,"con":null,"marketdefinition":null,"id":"1.258926623"}],"conflatems":null,"op":"mcm","id":3}
{"ct":null,"SegmentType":null,"clk":"AK/xAgDV\u002BAIAxtIC","heartbeatms":null,"pt":1780840042115,"initialclk":null,"mc":[{"rc":[{"tv":249576.06,"batb":null,"spb":null,"bdatl":null,"trd":[[9.1999999999999993,1732.78]],"spf":null,"ltp":9.1999999999999993,"atb":null,"spl":null,"spn":null,"atl":[[9.1999999999999993,46.479999999999997]],"batl":null,"id":16570658,"hc":null,"bdatb":null}],"img":null,"tv":2368571.0099999998,"con":null,"marketdefinition":null,"id":"1.258926623"}],"conflatems":null,"op":"mcm","id":3}
{"ct":null,"SegmentType":null,"clk":"AOTxAgCL\u002BQIA6NIC","heartbeatms":null,"pt":1780840042630,"initialclk":null,"mc":[{"rc":[{"tv":249600.92000000001,"batb":null,"spb":null,"bdatl":null,"trd":[[9.1999999999999993,1757.6400000000001]],"spf":null,"ltp":null,"atb":null,"spl":null,"spn":null,"atl":[[9.1999999999999993,21.620000000000001],[19.5,0]],"batl":null,"id":16570658,"hc":null,"bdatb":null},{"tv":2120790.7799999998,"batb":null,"spb":null,"bdatl":null,"trd":[[1.1200000000000001,69964.509999999995]],"spf":null,"ltp":1.1200000000000001,"atb":[[1.1200000000000001,0]],"spl":null,"spn":null,"atl":null,"batl":null,"id":19924823,"hc":null,"bdatb":null}],"img":null,"tv":2370391.7000000002,"con":null,"marketdefinition":null,"id":"1.258926623"}],"conflatems":null,"op":"mcm","id":3}
{"ct":null,"SegmentType":null,"clk":"APXxAgCf\u002BQIA89IC","heartbeatms":null,"pt":1780840042833,"initialclk":null,"mc":[{"rc":[{"tv":null,"batb":null,"spb":null,"bdatl":null,"trd":null,"spf":null,"ltp":null,"atb":[[1.1200000000000001,2]],"spl":null,"spn":null,"atl":null,"batl":null,"id":19924823,"hc":null,"bdatb":null}],"img":null,"tv":null,"con":null,"marketdefinition":null,"id":"1.258926623"}],"conflatems":null,"op":"mcm","id":3}
{"ct":null,"SegmentType":null,"clk":"AIPyAgCn\u002BQIA\u002BtIC","heartbeatms":null,"pt":1780840042936,"initialclk":null,"mc":[{"rc":[{"tv":null,"batb":null,"spb":null,"bdatl":null,"trd":null,"spf":null,"ltp":null,"atb":null,"spl":null,"spn":null,"atl":[[9.4000000000000004,1.73]],"batl":null,"id":16570658,"hc":null,"bdatb":null}],"img":null,"tv":null,"con":null,"marketdefinition":null,"id":"1.258926623"}],"conflatems":null,"op":"mcm","id":3}
{"ct":null,"SegmentType":null,"clk":"AIvyAgCx\u002BQIAhNMC","heartbeatms":null,"pt":1780840043031,"initialclk":null,"mc":[{"rc":[{"tv":null,"batb":null,"spb":null,"bdatl":null,"trd":null,"spf":null,"ltp":null,"atb":null,"spl":null,"spn":null,"atl":[[9.4000000000000004,3.73]],"batl":null,"id":16570658,"hc":null,"bdatb":null}],"img":null,"tv":null,"con":null,"marketdefinition":null,"id":"1.258926623"}],"conflatems":null,"op":"mcm","id":3}
{"ct":null,"SegmentType":null,"clk":"AJPyAgC9\u002BQIAitMC","heartbeatms":null,"pt":1780840043142,"initialclk":null,"mc":[{"rc":[{"tv":null,"batb":null,"spb":null,"bdatl":null,"trd":null,"spf":null,"ltp":null,"atb":[[1.1200000000000001,0]],"spl":null,"spn":null,"atl":null,"batl":null,"id":19924823,"hc":null,"bdatb":null}],"img":null,"tv":null,"con":null,"marketdefinition":null,"id":"1.258926623"}],"conflatems":null,"op":"mcm","id":3}
{"ct":null,"SegmentType":null,"clk":"AJ7yAgDJ\u002BQIAmNMC","heartbeatms":null,"pt":1780840043238,"initialclk":null,"mc":[{"rc":[{"tv":null,"batb":null,"spb":null,"bdatl":null,"trd":null,"spf":null,"ltp":null,"atb":null,"spl":null,"spn":null,"atl":[[9.4000000000000004,1.73]],"batl":null,"id":16570658,"hc":null,"bdatb":null}],"img":null,"tv":null,"con":null,"marketdefinition":null,"id":"1.258926623"}],"conflatems":null,"op":"mcm","id":3}
{"ct":null,"SegmentType":null,"clk":"AKbyAgDU\u002BQIAn9MC","heartbeatms":null,"pt":1780840043341,"initialclk":null,"mc":[{"rc":[{"tv":null,"batb":null,"spb":null,"bdatl":null,"trd":null,"spf":null,"ltp":null,"atb":null,"spl":null,"spn":null,"atl":[[9.4000000000000004,3.73]],"batl":null,"id":16570658,"hc":null,"bdatb":null}],"img":null,"tv":null,"con":null,"marketdefinition":null,"id":"1.258926623"}],"conflatems":null,"op":"mcm","id":3}
{"ct":null,"SegmentType":null,"clk":"AL3yAgDt\u002BQIAsdMC","heartbeatms":null,"pt":1780840043547,"initialclk":null,"mc":[{"rc":[{"tv":null,"batb":null,"spb":null,"bdatl":null,"trd":null,"spf":null,"ltp":null,"atb":null,"spl":null,"spn":null,"atl":[[9.4000000000000004,1.73]],"batl":null,"id":16570658,"hc":null,"bdatb":null},{"tv":null,"batb":null,"spb":null,"bdatl":null,"trd":null,"spf":null,"ltp":null,"atb":[[1.1200000000000001,870.05999999999995]],"spl":null,"spn":null,"atl":null,"batl":null,"id":19924823,"hc":null,"bdatb":null}],"img":null,"tv":null,"con":null,"marketdefinition":null,"id":"1.258926623"}],"conflatems":null,"op":"mcm","id":3}
{"ct":null,"SegmentType":null,"clk":"ANDyAgCG\u002BgIAxNMC","heartbeatms":null,"pt":1780840043717,"initialclk":null,"mc":[{"rc":[{"tv":null,"batb":null,"spb":null,"bdatl":null,"trd":null,"spf":null,"ltp":null,"atb":null,"spl":null,"spn":null,"atl":[[9.4000000000000004,3.73]],"batl":null,"id":16570658,"hc":null,"bdatb":null}],"img":null,"tv":null,"con":null,"marketdefinition":null,"id":"1.258926623"}],"conflatems":null,"op":"mcm","id":3}
{"ct":null,"SegmentType":null,"clk":"ANjyAgCR\u002BgIAydMC","heartbeatms":null,"pt":1780840043817,"initialclk":null,"mc":[{"rc":[{"tv":2120793.75,"batb":null,"spb":null,"bdatl":null,"trd":[[1.1200000000000001,69967.479999999996]],"spf":null,"ltp":null,"atb":[[1.1200000000000001,868.58000000000004]],"spl":null,"spn":null,"atl":null,"batl":null,"id":19924823,"hc":null,"bdatb":null}],"img":null,"tv":2370394.6699999999,"con":null,"marketdefinition":null,"id":"1.258926623"}],"conflatems":null,"op":"mcm","id":3}
{"ct":null,"SegmentType":null,"clk":"AOPyAgCp\u002BgIA2dMC","heartbeatms":null,"pt":1780840044022,"initialclk":null,"mc":[{"rc":[{"tv":null,"batb":null,"spb":null,"bdatl":null,"trd":null,"spf":null,"ltp":null,"atb":[[7.7999999999999998,901.24000000000001]],"spl":null,"spn":null,"atl":[[9.4000000000000004,1.73]],"batl":null,"id":16570658,"hc":null,"bdatb":null},{"tv":null,"batb":null,"spb":null,"bdatl":null,"trd":null,"spf":null,"ltp":null,"atb":null,"spl":null,"spn":null,"atl":[[1.1499999999999999,28712.720000000001]],"batl":null,"id":19924823,"hc":null,"bdatb":null}],"img":null,"tv":null,"con":null,"marketdefinition":null,"id":"1.258926623"}],"conflatems":null,"op":"mcm","id":3}
{"ct":null,"SegmentType":null,"clk":"APnyAgC/\u002BgIA6NMC","heartbeatms":null,"pt":1780840044225,"initialclk":null,"mc":[{"rc":[{"tv":null,"batb":null,"spb":null,"bdatl":null,"trd":null,"spf":null,"ltp":null,"atb":null,"spl":null,"spn":null,"atl":[[9.4000000000000004,3.73]],"batl":null,"id":16570658,"hc":null,"bdatb":null}],"img":null,"tv":null,"con":null,"marketdefinition":null,"id":"1.258926623"}],"conflatems":null,"op":"mcm","id":3}
{"ct":null,"SegmentType":null,"clk":"AJjzAgDl\u002BgIA/tMC","heartbeatms":null,"pt":1780840044535,"initialclk":null,"mc":[{"rc":[{"tv":null,"batb":null,"spb":null,"bdatl":null,"trd":null,"spf":null,"ltp":null,"atb":null,"spl":null,"spn":null,"atl":[[9.4000000000000004,1.73]],"batl":null,"id":16570658,"hc":null,"bdatb":null}],"img":null,"tv":null,"con":null,"marketdefinition":null,"id":"1.258926623"}],"conflatems":null,"op":"mcm","id":3}
{"ct":null,"SegmentType":null,"clk":"AKjzAgD0\u002BgIAgtQC","heartbeatms":null,"pt":1780840044637,"initialclk":null,"mc":[{"rc":[{"tv":null,"batb":null,"spb":null,"bdatl":null,"trd":null,"spf":null,"ltp":null,"atb":null,"spl":null,"spn":null,"atl":[[9.4000000000000004,3.73]],"batl":null,"id":16570658,"hc":null,"bdatb":null}],"img":null,"tv":null,"con":null,"marketdefinition":null,"id":"1.258926623"}],"conflatems":null,"op":"mcm","id":3}
{"ct":null,"SegmentType":null,"clk":"ALzzAgCI\u002BwIAj9QC","heartbeatms":null,"pt":1780840044838,"initialclk":null,"mc":[{"rc":[{"tv":null,"batb":null,"spb":null,"bdatl":null,"trd":null,"spf":null,"ltp":null,"atb":null,"spl":null,"spn":null,"atl":[[9.4000000000000004,1.73]],"batl":null,"id":16570658,"hc":null,"bdatb":null}],"img":null,"tv":null,"con":null,"marketdefinition":null,"id":"1.258926623"}],"conflatems":null,"op":"mcm","id":3}
{"ct":null,"SegmentType":null,"clk":"AMrzAgCR\u002BwIAltQC","heartbeatms":null,"pt":1780840044937,"initialclk":null,"mc":[{"rc":[{"tv":null,"batb":null,"spb":null,"bdatl":null,"trd":null,"spf":null,"ltp":null,"atb":null,"spl":null,"spn":null,"atl":[[9.4000000000000004,3.73]],"batl":null,"id":16570658,"hc":null,"bdatb":null}],"img":null,"tv":null,"con":null,"marketdefinition":null,"id":"1.258926623"}],"conflatems":null,"op":"mcm","id":3}
{"ct":null,"SegmentType":null,"clk":"ANTzAgCe\u002BwIAnNQC","heartbeatms":null,"pt":1780840045046,"initialclk":null,"mc":[{"rc":[{"tv":null,"batb":null,"spb":null,"bdatl":null,"trd":null,"spf":null,"ltp":null,"atb":[[1.1200000000000001,872.88]],"spl":null,"spn":null,"atl":[[1000,1.04]],"batl":null,"id":19924823,"hc":null,"bdatb":null}],"img":null,"tv":null,"con":null,"marketdefinition":null,"id":"1.258926623"}],"conflatems":null,"op":"mcm","id":3}
{"ct":null,"SegmentType":null,"clk":"AODzAgCk\u002BwIAp9QC","heartbeatms":null,"pt":1780840045107,"initialclk":null,"mc":[{"rc":[{"tv":null,"batb":null,"spb":null,"bdatl":null,"trd":null,"spf":null,"ltp":null,"atb":[[8.5999999999999996,428.25999999999999]],"spl":null,"spn":null,"atl":null,"batl":null,"id":16570658,"hc":null,"bdatb":null}],"img":null,"tv":null,"con":null,"marketdefinition":null,"id":"1.258926623"}],"conflatems":null,"op":"mcm","id":3}
{"ct":null,"SegmentType":null,"clk":"AOnzAgCu\u002BwIAr9QC","heartbeatms":null,"pt":1780840045209,"initialclk":null,"mc":[{"rc":[{"tv":null,"batb":null,"spb":null,"bdatl":null,"trd":null,"spf":null,"ltp":null,"atb":null,"spl":null,"spn":null,"atl":[[9.4000000000000004,1.73]],"batl":null,"id":16570658,"hc":null,"bdatb":null}],"img":null,"tv":null,"con":null,"marketdefinition":null,"id":"1.258926623"}],"conflatems":null,"op":"mcm","id":3}
{"ct":null,"SegmentType":null,"clk":"APvzAgDE\u002BwIAutQC","heartbeatms":null,"pt":1780840045419,"initialclk":null,"mc":[{"rc":[{"tv":null,"batb":null,"spb":null,"bdatl":null,"trd":null,"spf":null,"ltp":null,"atb":null,"spl":null,"spn":null,"atl":[[9.4000000000000004,3.73]],"batl":null,"id":16570658,"hc":null,"bdatb":null},{"tv":null,"batb":null,"spb":null,"bdatl":null,"trd":null,"spf":null,"ltp":null,"atb":null,"spl":null,"spn":null,"atl":[[1000,0.88],[1.1399999999999999,25974.400000000001]],"batl":null,"id":19924823,"hc":null,"bdatb":null}],"img":null,"tv":null,"con":null,"marketdefinition":null,"id":"1.258926623"}],"conflatems":null,"op":"mcm","id":3}
{"ct":null,"SegmentType":null,"clk":"AI/0AgDb\u002BwIAyNQC","heartbeatms":null,"pt":1780840045625,"initialclk":null,"mc":[{"rc":[{"tv":null,"batb":null,"spb":null,"bdatl":null,"trd":null,"spf":null,"ltp":null,"atb":null,"spl":null,"spn":null,"atl":[[9.4000000000000004,1.73]],"batl":null,"id":16570658,"hc":null,"bdatb":null}],"img":null,"tv":null,"con":null,"marketdefinition":null,"id":"1.258926623"}],"conflatems":null,"op":"mcm","id":3}
{"ct":null,"SegmentType":null,"clk":"AKL0AgDw\u002BwIA3tQC","heartbeatms":null,"pt":1780840045827,"initialclk":null,"mc":[{"rc":[{"tv":null,"batb":null,"spb":null,"bdatl":null,"trd":null,"spf":null,"ltp":null,"atb":null,"spl":null,"spn":null,"atl":[[9.4000000000000004,3.73]],"batl":null,"id":16570658,"hc":null,"bdatb":null}],"img":null,"tv":null,"con":null,"marketdefinition":null,"id":"1.258926623"}],"conflatems":null,"op":"mcm","id":3}
{"ct":null,"SegmentType":null,"clk":"AKn0AgCA/AIA69QC","heartbeatms":null,"pt":1780840045936,"initialclk":null,"mc":[{"rc":[{"tv":null,"batb":null,"spb":null,"bdatl":null,"trd":null,"spf":null,"ltp":null,"atb":[[1.02,90741.720000000001]],"spl":null,"spn":null,"atl":null,"batl":null,"id":19924823,"hc":null,"bdatb":null}],"img":null,"tv":null,"con":null,"marketdefinition":null,"id":"1.258926623"}],"conflatems":null,"op":"mcm","id":3}
{"ct":null,"SegmentType":null,"clk":"AL30AgCS/AIA/NQC","heartbeatms":null,"pt":1780840046141,"initialclk":null,"mc":[{"rc":[{"tv":null,"batb":null,"spb":null,"bdatl":null,"trd":null,"spf":null,"ltp":null,"atb":null,"spl":null,"spn":null,"atl":[[9.4000000000000004,1.73]],"batl":null,"id":16570658,"hc":null,"bdatb":null}],"img":null,"tv":null,"con":null,"marketdefinition":null,"id":"1.258926623"}],"conflatems":null,"op":"mcm","id":3}
{"ct":null,"SegmentType":null,"clk":"AM70AgCl/AIAjdUC","heartbeatms":null,"pt":1780840046336,"initialclk":null,"mc":[{"rc":[{"tv":null,"batb":null,"spb":null,"bdatl":null,"trd":null,"spf":null,"ltp":null,"atb":null,"spl":null,"spn":null,"atl":[[9.4000000000000004,3.73]],"batl":null,"id":16570658,"hc":null,"bdatb":null}],"img":null,"tv":null,"con":null,"marketdefinition":null,"id":"1.258926623"}],"conflatems":null,"op":"mcm","id":3}
{"ct":null,"SegmentType":null,"clk":"AO30AgDC/AIAqdUC","heartbeatms":null,"pt":1780840046646,"initialclk":null,"mc":[{"rc":[{"tv":null,"batb":null,"spb":null,"bdatl":null,"trd":null,"spf":null,"ltp":null,"atb":null,"spl":null,"spn":null,"atl":[[9.4000000000000004,1.73]],"batl":null,"id":16570658,"hc":null,"bdatb":null}],"img":null,"tv":null,"con":null,"marketdefinition":null,"id":"1.258926623"}],"conflatems":null,"op":"mcm","id":3}
{"ct":null,"SegmentType":null,"clk":"APL0AgDN/AIAsNUC","heartbeatms":null,"pt":1780840046710,"initialclk":null,"mc":[{"rc":[{"tv":2121493.75,"batb":null,"spb":null,"bdatl":null,"trd":[[1.1200000000000001,70667.479999999996]],"spf":null,"ltp":null,"atb":[[1.1200000000000001,522.88]],"spl":null,"spn":null,"atl":null,"batl":null,"id":19924823,"hc":null,"bdatb":null}],"img":null,"tv":2371094.6699999999,"con":null,"marketdefinition":null,"id":"1.258926623"}],"conflatems":null,"op":"mcm","id":3}
{"ct":null,"SegmentType":null,"clk":"APn0AgDY/AIAttUC","heartbeatms":null,"pt":1780840046812,"initialclk":null,"mc":[{"rc":[{"tv":null,"batb":null,"spb":null,"bdatl":null,"trd":null,"spf":null,"ltp":null,"atb":null,"spl":null,"spn":null,"atl":[[9.4000000000000004,3.73],[8.8000000000000007,1.23]],"batl":null,"id":16570658,"hc":null,"bdatb":null}],"img":null,"tv":null,"con":null,"marketdefinition":null,"id":"1.258926623"}],"conflatems":null,"op":"mcm","id":3}
{"ct":null,"SegmentType":null,"clk":"AIf1AgDw/AIAy9UC","heartbeatms":null,"pt":1780840047019,"initialclk":null,"mc":[{"rc":[{"tv":2121511.4399999999,"batb":null,"spb":null,"bdatl":null,"trd":[[1.1200000000000001,70685.169999999998]],"spf":null,"ltp":null,"atb":[[1.1200000000000001,514.02999999999997]],"spl":null,"spn":null,"atl":null,"batl":null,"id":19924823,"hc":null,"bdatb":null}],"img":null,"tv":2371112.3599999999,"con":null,"marketdefinition":null,"id":"1.258926623"}],"conflatems":null,"op":"mcm","id":3}
{"ct":null,"SegmentType":null,"clk":"AJD1AgD2/AIA09UC","heartbeatms":null,"pt":1780840047122,"initialclk":null,"mc":[{"rc":[{"tv":null,"batb":null,"spb":null,"bdatl":null,"trd":null,"spf":null,"ltp":null,"atb":null,"spl":null,"spn":null,"atl":[[9.4000000000000004,1.73]],"batl":null,"id":16570658,"hc":null,"bdatb":null}],"img":null,"tv":null,"con":null,"marketdefinition":null,"id":"1.258926623"}],"conflatems":null,"op":"mcm","id":3}
{"ct":null,"SegmentType":null,"clk":"AJn1AgCB/QIA3tUC","heartbeatms":null,"pt":1780840047226,"initialclk":null,"mc":[{"rc":[{"tv":null,"batb":null,"spb":null,"bdatl":null,"trd":null,"spf":null,"ltp":null,"atb":null,"spl":null,"spn":null,"atl":[[9.4000000000000004,3.73]],"batl":null,"id":16570658,"hc":null,"bdatb":null}],"img":null,"tv":null,"con":null,"marketdefinition":null,"id":"1.258926623"}],"conflatems":null,"op":"mcm","id":3}
{"ct":null,"SegmentType":null,"clk":"ALT1AgCo/QIA9tUC","heartbeatms":null,"pt":1780840047533,"initialclk":null,"mc":[{"rc":[{"tv":null,"batb":null,"spb":null,"bdatl":null,"trd":null,"spf":null,"ltp":null,"atb":null,"spl":null,"spn":null,"atl":[[9.4000000000000004,1.73]],"batl":null,"id":16570658,"hc":null,"bdatb":null}],"img":null,"tv":null,"con":null,"marketdefinition":null,"id":"1.258926623"}],"conflatems":null,"op":"mcm","id":3}
{"ct":null,"SegmentType":null,"clk":"AMX1AgC7/QIAgdYC","heartbeatms":null,"pt":1780840047733,"initialclk":null,"mc":[{"rc":[{"tv":null,"batb":null,"spb":null,"bdatl":null,"trd":null,"spf":null,"ltp":null,"atb":null,"spl":null,"spn":null,"atl":[[9.4000000000000004,3.73]],"batl":null,"id":16570658,"hc":null,"bdatb":null},{"tv":null,"batb":null,"spb":null,"bdatl":null,"trd":null,"spf":null,"ltp":null,"atb":null,"spl":null,"spn":null,"atl":[[1.1399999999999999,22974.400000000001]],"batl":null,"id":19924823,"hc":null,"bdatb":null}],"img":null,"tv":null,"con":null,"marketdefinition":null,"id":"1.258926623"}],"conflatems":null,"op":"mcm","id":3}
{"ct":null,"SegmentType":null,"clk":"ANf1AgDP/QIAj9YC","heartbeatms":null,"pt":1780840047941,"initialclk":null,"mc":[{"rc":[{"tv":null,"batb":null,"spb":null,"bdatl":null,"trd":null,"spf":null,"ltp":null,"atb":null,"spl":null,"spn":null,"atl":[[9.4000000000000004,1.73]],"batl":null,"id":16570658,"hc":null,"bdatb":null}],"img":null,"tv":null,"con":null,"marketdefinition":null,"id":"1.258926623"}],"conflatems":null,"op":"mcm","id":3}
{"ct":null,"SegmentType":null,"clk":"AO/1AgDg/QIAodYC","heartbeatms":null,"pt":1780840048142,"initialclk":null,"mc":[{"rc":[{"tv":null,"batb":null,"spb":null,"bdatl":null,"trd":null,"spf":null,"ltp":null,"atb":null,"spl":null,"spn":null,"atl":[[9.4000000000000004,3.73]],"batl":null,"id":16570658,"hc":null,"bdatb":null},{"tv":2121687.4399999999,"batb":null,"spb":null,"bdatl":null,"trd":[[1.1200000000000001,70861.169999999998]],"spf":null,"ltp":null,"atb":[[1.1200000000000001,426.02999999999997]],"spl":null,"spn":null,"atl":null,"batl":null,"id":19924823,"hc":null,"bdatb":null}],"img":null,"tv":2371288.3599999999,"con":null,"marketdefinition":null,"id":"1.258926623"}],"conflatems":null,"op":"mcm","id":3}
{"ct":null,"SegmentType":null,"clk":"AIb2AgD9/QIAtNYC","heartbeatms":null,"pt":1780840048415,"initialclk":null,"mc":[{"rc":[{"tv":null,"batb":null,"spb":null,"bdatl":null,"trd":null,"spf":null,"ltp":null,"atb":null,"spl":null,"spn":null,"atl":[[9.4000000000000004,1.73]],"batl":null,"id":16570658,"hc":null,"bdatb":null}],"img":null,"tv":null,"con":null,"marketdefinition":null,"id":"1.258926623"}],"conflatems":null,"op":"mcm","id":3}
{"ct":null,"SegmentType":null,"clk":"AJH2AgCK/gIAv9YC","heartbeatms":null,"pt":1780840048513,"initialclk":null,"mc":[{"rc":[{"tv":null,"batb":null,"spb":null,"bdatl":null,"trd":null,"spf":null,"ltp":null,"atb":null,"spl":null,"spn":null,"atl":[[9.4000000000000004,3.73]],"batl":null,"id":16570658,"hc":null,"bdatb":null},{"tv":2121687.75,"batb":null,"spb":null,"bdatl":null,"trd":[[1.1200000000000001,70861.479999999996]],"spf":null,"ltp":null,"atb":[[1.1200000000000001,425.87]],"spl":null,"spn":null,"atl":null,"batl":null,"id":19924823,"hc":null,"bdatb":null}],"img":null,"tv":2371288.6699999999,"con":null,"marketdefinition":null,"id":"1.258926623"}],"conflatems":null,"op":"mcm","id":3}
{"ct":null,"SegmentType":null,"clk":"AKH2AgCh/gIAz9YC","heartbeatms":null,"pt":1780840048728,"initialclk":null,"mc":[{"rc":[{"tv":null,"batb":null,"spb":null,"bdatl":null,"trd":null,"spf":null,"ltp":null,"atb":null,"spl":null,"spn":null,"atl":[[1.1299999999999999,19114.93]],"batl":null,"id":19924823,"hc":null,"bdatb":null}],"img":null,"tv":null,"con":null,"marketdefinition":null,"id":"1.258926623"}],"conflatems":null,"op":"mcm","id":3}
{"ct":null,"SegmentType":null,"clk":"ALv2AgDB/gIA5NYC","heartbeatms":null,"pt":1780840049028,"initialclk":null,"mc":[{"rc":[{"tv":null,"batb":null,"spb":null,"bdatl":null,"trd":null,"spf":null,"ltp":null,"atb":null,"spl":null,"spn":null,"atl":[[9.4000000000000004,1.73],[9,2777.7800000000002]],"batl":null,"id":16570658,"hc":null,"bdatb":null}],"img":null,"tv":null,"con":null,"marketdefinition":null,"id":"1.258926623"}],"conflatems":null,"op":"mcm","id":3}
{"ct":null,"SegmentType":null,"clk":"AMH2AgDM/gIA6dYC","heartbeatms":null,"pt":1780840049128,"initialclk":null,"mc":[{"rc":[{"tv":null,"batb":null,"spb":null,"bdatl":null,"trd":null,"spf":null,"ltp":null,"atb":null,"spl":null,"spn":null,"atl":[[9.4000000000000004,75.599999999999994],[9.1999999999999993,312.86000000000001],[9.5999999999999996,20.989999999999998]],"batl":null,"id":16570658,"hc":null,"bdatb":null},{"tv":null,"batb":null,"spb":null,"bdatl":null,"trd":null,"spf":null,"ltp":null,"atb":[[1.1100000000000001,70339.940000000002],[1.1200000000000001,27895.57]],"spl":null,"spn":null,"atl":null,"batl":null,"id":19924823,"hc":null,"bdatb":null}],"img":null,"tv":null,"con":null,"marketdefinition":null,"id":"1.258926623"}],"conflatems":null,"op":"mcm","id":3}
{"ct":null,"SegmentType":null,"clk":"AMv2AgDX/gIA9NYC","heartbeatms":null,"pt":1780840049236,"initialclk":null,"mc":[{"rc":[{"tv":null,"batb":null,"spb":null,"bdatl":null,"trd":null,"spf":null,"ltp":null,"atb":[[7,0],[8.1999999999999993,19.440000000000001]],"spl":null,"spn":null,"atl":[[11,239.16999999999999],[10.5,276.70999999999998],[9,0]],"batl":null,"id":16570658,"hc":null,"bdatb":null},{"tv":null,"batb":null,"spb":null,"bdatl":null,"trd":null,"spf":null,"ltp":null,"atb":[[1.0900000000000001,40185.099999999999],[1.1200000000000001,28656.110000000001]],"spl":null,"spn":null,"atl":null,"batl":null,"id":19924823,"hc":null,"bdatb":null}],"img":null,"tv":null,"con":null,"marketdefinition":null,"id":"1.258926623"}],"conflatems":null,"op":"mcm","id":3}
{"ct":null,"SegmentType":null,"clk":"AN32AgDn/gIA/tYC","heartbeatms":null,"pt":1780840049341,"initialclk":null,"mc":[{"rc":[{"tv":null,"batb":null,"spb":null,"bdatl":null,"trd":null,"spf":null,"ltp":null,"atb":[[1.04,73840.729999999996],[1.05,74306.929999999993],[1.0700000000000001,38874.290000000001],[1.0800000000000001,40508.370000000003],[1.1000000000000001,61571.339999999997],[1.0900000000000001,40183.099999999999],[1.0600000000000001,63324.940000000002],[1.02,90739.720000000001],[1.03,88972.589999999997],[1.01,93591.869999999995]],"spl":null,"spn":null,"atl":null,"batl":null,"id":19924823,"hc":null,"bdatb":null}],"img":null,"tv":null,"con":null,"marketdefinition":null,"id":"1.258926623"}],"conflatems":null,"op":"mcm","id":3}
{"ct":null,"SegmentType":null,"clk":"AOH2AgD5/gIAiNcC","heartbeatms":null,"pt":1780840049434,"initialclk":null,"mc":[{"rc":[{"tv":null,"batb":null,"spb":null,"bdatl":null,"trd":null,"spf":null,"ltp":null,"atb":[[7.5999999999999996,151.05000000000001]],"spl":null,"spn":null,"atl":null,"batl":null,"id":16570658,"hc":null,"bdatb":null},{"tv":null,"batb":null,"spb":null,"bdatl":null,"trd":null,"spf":null,"ltp":null,"atb":[[1.1100000000000001,70332.449999999997],[1.1200000000000001,28933.110000000001]],"spl":null,"spn":null,"atl":[[1.1499999999999999,28961.720000000001]],"batl":null,"id":19924823,"hc":null,"bdatb":null}],"img":null,"tv":null,"con":null,"marketdefinition":null,"id":"1.258926623"}],"conflatems":null,"op":"mcm","id":3}
{"ct":null,"SegmentType":null,"clk":"APH2AgCK/wIAkNcC","heartbeatms":null,"pt":1780840049549,"initialclk":null,"mc":[{"rc":[{"tv":null,"batb":null,"spb":null,"bdatl":null,"trd":null,"spf":null,"ltp":null,"atb":[[7,760.03999999999996],[7.4000000000000004,212.21000000000001]],"spl":null,"spn":null,"atl":[[9.1999999999999993,321.38]],"batl":null,"id":16570658,"hc":null,"bdatb":null},{"tv":null,"batb":null,"spb":null,"bdatl":null,"trd":null,"spf":null,"ltp":null,"atb":[[1.1200000000000001,41530.669999999998]],"spl":null,"spn":null,"atl":null,"batl":null,"id":19924823,"hc":null,"bdatb":null}],"img":null,"tv":null,"con":null,"marketdefinition":null,"id":"1.258926623"}],"conflatems":null,"op":"mcm","id":3}
{"ct":null,"SegmentType":null,"clk":"APb2AgCT/wIAl9cC","heartbeatms":null,"pt":1780840049646,"initialclk":null,"mc":[{"rc":[{"tv":2121690.6499999999,"batb":null,"spb":null,"bdatl":null,"trd":[[1.1299999999999999,253479.45999999999]],"spf":null,"ltp":1.1299999999999999,"atb":null,"spl":null,"spn":null,"atl":[[1.1299999999999999,19113.48]],"batl":null,"id":19924823,"hc":null,"bdatb":null}],"img":null,"tv":2371291.5699999998,"con":null,"marketdefinition":null,"id":"1.258926623"}],"conflatems":null,"op":"mcm","id":3}
{"ct":null,"SegmentType":null,"clk":"AIf3AgCg/wIAndcC","heartbeatms":null,"pt":1780840049740,"initialclk":null,"mc":[{"rc":[{"tv":null,"batb":null,"spb":null,"bdatl":null,"trd":null,"spf":null,"ltp":null,"atb":[[7.7999999999999998,498.72000000000003]],"spl":null,"spn":null,"atl":null,"batl":null,"id":16570658,"hc":null,"bdatb":null},{"tv":null,"batb":null,"spb":null,"bdatl":null,"trd":null,"spf":null,"ltp":null,"atb":[[1.1100000000000001,57554.519999999997],[1.1200000000000001,43649.379999999997]],"spl":null,"spn":null,"atl":[[1.1499999999999999,29573.830000000002]],"batl":null,"id":19924823,"hc":null,"bdatb":null}],"img":null,"tv":null,"con":null,"marketdefinition":null,"id":"1.258926623"}],"conflatems":null,"op":"mcm","id":3}
{"ct":null,"SegmentType":null,"clk":"AI/3AgCo/wIAqtcC","heartbeatms":null,"pt":1780840049844,"initialclk":null,"mc":[{"rc":[{"tv":null,"batb":null,"spb":null,"bdatl":null,"trd":null,"spf":null,"ltp":null,"atb":null,"spl":null,"spn":null,"atl":[[9.1999999999999993,312.86000000000001]],"batl":null,"id":16570658,"hc":null,"bdatb":null},{"tv":null,"batb":null,"spb":null,"bdatl":null,"trd":null,"spf":null,"ltp":null,"atb":[[1.1100000000000001,54916.550000000003]],"spl":null,"spn":null,"atl":[[1.1399999999999999,22865.490000000002]],"batl":null,"id":19924823,"hc":null,"bdatb":null}],"img":null,"tv":null,"con":null,"marketdefinition":null,"id":"1.258926623"}],"conflatems":null,"op":"mcm","id":3}
{"ct":null,"SegmentType":null,"clk":"AKX3AgC9/wIAvdcC","heartbeatms":null,"pt":1780840050021,"initialclk":null,"mc":[{"rc":[{"tv":null,"batb":null,"spb":null,"bdatl":null,"trd":null,"spf":null,"ltp":null,"atb":null,"spl":null,"spn":null,"atl":[[1.1399999999999999,23865.490000000002]],"batl":null,"id":19924823,"hc":null,"bdatb":null}],"img":null,"tv":null,"con":null,"marketdefinition":null,"id":"1.258926623"}],"conflatems":null,"op":"mcm","id":3}
{"ct":null,"SegmentType":null,"clk":"ALH3AgDG/wIAytcC","heartbeatms":null,"pt":1780840050125,"initialclk":null,"mc":[{"rc":[{"tv":null,"batb":null,"spb":null,"bdatl":null,"trd":null,"spf":null,"ltp":null,"atb":null,"spl":null,"spn":null,"atl":[[1.1399999999999999,24865.490000000002]],"batl":null,"id":19924823,"hc":null,"bdatb":null}],"img":null,"tv":null,"con":null,"marketdefinition":null,"id":"1.258926623"}],"conflatems":null,"op":"mcm","id":3}
{"ct":null,"SegmentType":null,"clk":"AMT3AgDP/wIA0tcC","heartbeatms":null,"pt":1780840050233,"initialclk":null,"mc":[{"rc":[{"tv":null,"batb":null,"spb":null,"bdatl":null,"trd":null,"spf":null,"ltp":null,"atb":[[7.2000000000000002,208.66999999999999]],"spl":null,"spn":null,"atl":[[9,166.66]],"batl":null,"id":16570658,"hc":null,"bdatb":null},{"tv":null,"batb":null,"spb":null,"bdatl":null,"trd":null,"spf":null,"ltp":null,"atb":[[1.1200000000000001,44988.660000000003]],"spl":null,"spn":null,"atl":[[1.1599999999999999,28326.060000000001]],"batl":null,"id":19924823,"hc":null,"bdatb":null}],"img":null,"tv":null,"con":null,"marketdefinition":null,"id":"1.258926623"}],"conflatems":null,"op":"mcm","id":3}
{"ct":null,"SegmentType":null,"clk":"AM73AgDe/wIA4NcC","heartbeatms":null,"pt":1780840050338,"initialclk":null,"mc":[{"rc":[{"tv":null,"batb":null,"spb":null,"bdatl":null,"trd":null,"spf":null,"ltp":null,"atb":[[1.1200000000000001,44230.120000000003]],"spl":null,"spn":null,"atl":null,"batl":null,"id":19924823,"hc":null,"bdatb":null}],"img":null,"tv":null,"con":null,"marketdefinition":null,"id":"1.258926623"}],"conflatems":null,"op":"mcm","id":3}
{"ct":null,"SegmentType":null,"clk":"AOD3AgDy/wIA9NcC","heartbeatms":null,"pt":1780840050526,"initialclk":null,"mc":[{"rc":[{"tv":null,"batb":null,"spb":null,"bdatl":null,"trd":null,"spf":null,"ltp":null,"atb":null,"spl":null,"spn":null,"atl":[[9.1999999999999993,321.38],[9,167.72]],"batl":null,"id":16570658,"hc":null,"bdatb":null},{"tv":null,"batb":null,"spb":null,"bdatl":null,"trd":null,"spf":null,"ltp":null,"atb":[[1.1200000000000001,61505.75]],"spl":null,"spn":null,"atl":[[1.1299999999999999,17868.77]],"batl":null,"id":19924823,"hc":null,"bdatb":null}],"img":null,"tv":null,"con":null,"marketdefinition":null,"id":"1.258926623"}],"conflatems":null,"op":"mcm","id":3}
{"ct":null,"SegmentType":null,"clk":"AO73AgD8/wIA/tcC","heartbeatms":null,"pt":1780840050647,"initialclk":null,"mc":[{"rc":[{"tv":2139782.6600000001,"batb":null,"spb":null,"bdatl":null,"trd":[[1.1299999999999999,271571.46999999997]],"spf":null,"ltp":null,"atb":null,"spl":null,"spn":null,"atl":[[1.1299999999999999,152.33000000000001]],"batl":null,"id":19924823,"hc":null,"bdatb":null}],"img":null,"tv":2389383.5800000001,"con":null,"marketdefinition":null,"id":"1.258926623"}],"conflatems":null,"op":"mcm","id":3}
{"ct":null,"SegmentType":null,"clk":"AJP4AgCqgAMAptgC","heartbeatms":null,"pt":1780840051046,"initialclk":null,"mc":[{"rc":[{"tv":2140087.3199999998,"batb":null,"spb":null,"bdatl":null,"trd":[[1.1299999999999999,271876.13]],"spf":null,"ltp":null,"atb":[[1.1299999999999999,8598.4200000000001]],"spl":null,"spn":null,"atl":[[1.1299999999999999,0]],"batl":null,"id":19924823,"hc":null,"bdatb":null}],"img":null,"tv":2389688.2400000002,"con":null,"marketdefinition":null,"id":"1.258926623"}],"conflatems":null,"op":"mcm","id":3}
{"ct":null,"SegmentType":null,"clk":"AKX4AgDBgAMAuNgC","heartbeatms":null,"pt":1780840051243,"initialclk":null,"mc":[{"rc":[{"tv":null,"batb":null,"spb":null,"bdatl":null,"trd":null,"spf":null,"ltp":null,"atb":null,"spl":null,"spn":null,"atl":[[8.8000000000000007,45.950000000000003]],"batl":null,"id":16570658,"hc":null,"bdatb":null},{"tv":null,"batb":null,"spb":null,"bdatl":null,"trd":null,"spf":null,"ltp":null,"atb":[[1.1299999999999999,1529.0899999999999]],"spl":null,"spn":null,"atl":[[1.1599999999999999,27115.66]],"batl":null,"id":19924823,"hc":null,"bdatb":null}],"img":null,"tv":null,"con":null,"marketdefinition":null,"id":"1.258926623"}],"conflatems":null,"op":"mcm","id":3}
{"ct":null,"SegmentType":null,"clk":"AK/4AgDNgAMAxNgC","heartbeatms":null,"pt":1780840051345,"initialclk":null,"mc":[{"rc":[{"tv":null,"batb":null,"spb":null,"bdatl":null,"trd":null,"spf":null,"ltp":null,"atb":[[1.1299999999999999,1629.0899999999999]],"spl":null,"spn":null,"atl":null,"batl":null,"id":19924823,"hc":null,"bdatb":null}],"img":null,"tv":null,"con":null,"marketdefinition":null,"id":"1.258926623"}],"conflatems":null,"op":"mcm","id":3}
{"ct":null,"SegmentType":null,"clk":"ALf4AgDYgAMA1dgC","heartbeatms":null,"pt":1780840051447,"initialclk":null,"mc":[{"rc":[{"tv":null,"batb":null,"spb":null,"bdatl":null,"trd":null,"spf":null,"ltp":null,"atb":[[1.1200000000000001,61650.139999999999]],"spl":null,"spn":null,"atl":null,"batl":null,"id":19924823,"hc":null,"bdatb":null}],"img":null,"tv":null,"con":null,"marketdefinition":null,"id":"1.258926623"}],"conflatems":null,"op":"mcm","id":3}
{"ct":null,"SegmentType":null,"clk":"AM74AgDtgAMA6dgC","heartbeatms":null,"pt":1780840051622,"initialclk":null,"mc":[{"rc":[{"tv":null,"batb":null,"spb":null,"bdatl":null,"trd":null,"spf":null,"ltp":null,"atb":[[1.1299999999999999,1638.98]],"spl":null,"spn":null,"atl":null,"batl":null,"id":19924823,"hc":null,"bdatb":null}],"img":null,"tv":null,"con":null,"marketdefinition":null,"id":"1.258926623"}],"conflatems":null,"op":"mcm","id":3}
{"ct":null,"SegmentType":null,"clk":"AOb4AgCLgQMA9dgC","heartbeatms":null,"pt":1780840051836,"initialclk":null,"mc":[{"rc":[{"tv":null,"batb":null,"spb":null,"bdatl":null,"trd":null,"spf":null,"ltp":null,"atb":[[8.5999999999999996,0]],"spl":null,"spn":null,"atl":[[8.5999999999999996,29.07]],"batl":null,"id":16570658,"hc":null,"bdatb":null}],"img":null,"tv":null,"con":null,"marketdefinition":null,"id":"1.258926623"}],"conflatems":null,"op":"mcm","id":3}
{"ct":null,"SegmentType":null,"clk":"AO74AgCVgQMA/dgC","heartbeatms":null,"pt":1780840051926,"initialclk":null,"mc":[{"rc":[{"tv":null,"batb":null,"spb":null,"bdatl":null,"trd":null,"spf":null,"ltp":null,"atb":[[1.04,73841.479999999996]],"spl":null,"spn":null,"atl":null,"batl":null,"id":19924823,"hc":null,"bdatb":null}],"img":null,"tv":null,"con":null,"marketdefinition":null,"id":"1.258926623"}],"conflatems":null,"op":"mcm","id":3}
{"ct":null,"SegmentType":null,"clk":"APb4AgCggQMAg9kC","heartbeatms":null,"pt":1780840052031,"initialclk":null,"mc":[{"rc":[{"tv":null,"batb":null,"spb":null,"bdatl":null,"trd":null,"spf":null,"ltp":null,"atb":null,"spl":null,"spn":null,"atl":[[8.5999999999999996,0]],"batl":null,"id":16570658,"hc":null,"bdatb":null}],"img":null,"tv":null,"con":null,"marketdefinition":null,"id":"1.258926623"}],"conflatems":null,"op":"mcm","id":3}
{"ct":null,"SegmentType":null,"clk":"AJH5AgDAgQMAmtkC","heartbeatms":null,"pt":1780840052337,"initialclk":null,"mc":[{"rc":[{"tv":null,"batb":null,"spb":null,"bdatl":null,"trd":null,"spf":null,"ltp":null,"atb":[[8,128.05000000000001]],"spl":null,"spn":null,"atl":[[10.5,365.70999999999998]],"batl":null,"id":16570658,"hc":null,"bdatb":null},{"tv":null,"batb":null,"spb":null,"bdatl":null,"trd":null,"spf":null,"ltp":null,"atb":[[1.1000000000000001,63297.339999999997]],"spl":null,"spn":null,"atl":[[1.1499999999999999,31024.830000000002]],"batl":null,"id":19924823,"hc":null,"bdatb":null}],"img":null,"tv":null,"con":null,"marketdefinition":null,"id":"1.258926623"}],"conflatems":null,"op":"mcm","id":3}
{"ct":null,"SegmentType":null,"clk":"AKL5AgDUgQMAo9kC","heartbeatms":null,"pt":1780840052447,"initialclk":null,"mc":[{"rc":[{"tv":null,"batb":null,"spb":null,"bdatl":null,"trd":null,"spf":null,"ltp":null,"atb":null,"spl":null,"spn":null,"atl":[[1.1399999999999999,26110.200000000001]],"batl":null,"id":19924823,"hc":null,"bdatb":null}],"img":null,"tv":null,"con":null,"marketdefinition":null,"id":"1.258926623"}],"conflatems":null,"op":"mcm","id":3}
{"ct":null,"SegmentType":null,"clk":"AKb5AgDbgQMAsNkC","heartbeatms":null,"pt":1780840052545,"initialclk":null,"mc":[{"rc":[{"tv":null,"batb":null,"spb":null,"bdatl":null,"trd":null,"spf":null,"ltp":null,"atb":[[8,228.05000000000001]],"spl":null,"spn":null,"atl":null,"batl":null,"id":16570658,"hc":null,"bdatb":null}],"img":null,"tv":null,"con":null,"marketdefinition":null,"id":"1.258926623"}],"conflatems":null,"op":"mcm","id":3}
{"ct":null,"SegmentType":null,"clk":"AL35AgDrgQMAv9kC","heartbeatms":null,"pt":1780840052743,"initialclk":null,"mc":[{"rc":[{"tv":null,"batb":null,"spb":null,"bdatl":null,"trd":null,"spf":null,"ltp":null,"atb":[[8,328.05000000000001]],"spl":null,"spn":null,"atl":null,"batl":null,"id":16570658,"hc":null,"bdatb":null}],"img":null,"tv":null,"con":null,"marketdefinition":null,"id":"1.258926623"}],"conflatems":null,"op":"mcm","id":3}
{"ct":null,"SegmentType":null,"clk":"AMj5AgD1gQMAxtkC","heartbeatms":null,"pt":1780840052842,"initialclk":null,"mc":[{"rc":[{"tv":null,"batb":null,"spb":null,"bdatl":null,"trd":null,"spf":null,"ltp":null,"atb":[[8,428.05000000000001]],"spl":null,"spn":null,"atl":null,"batl":null,"id":16570658,"hc":null,"bdatb":null}],"img":null,"tv":null,"con":null,"marketdefinition":null,"id":"1.258926623"}],"conflatems":null,"op":"mcm","id":3}
{"ct":null,"SegmentType":null,"clk":"AN35AgCKggMA29kC","heartbeatms":null,"pt":1780840053050,"initialclk":null,"mc":[{"rc":[{"tv":null,"batb":null,"spb":null,"bdatl":null,"trd":null,"spf":null,"ltp":null,"atb":[[8,528.04999999999995]],"spl":null,"spn":null,"atl":null,"batl":null,"id":16570658,"hc":null,"bdatb":null}],"img":null,"tv":null,"con":null,"marketdefinition":null,"id":"1.258926623"}],"conflatems":null,"op":"mcm","id":3}
{"ct":null,"SegmentType":null,"clk":"AOj5AgCUggMA49kC","heartbeatms":null,"pt":1780840053130,"initialclk":null,"mc":[{"rc":[{"tv":null,"batb":null,"spb":null,"bdatl":null,"trd":null,"spf":null,"ltp":null,"atb":null,"spl":null,"spn":null,"atl":[[1.1399999999999999,26533.900000000001]],"batl":null,"id":19924823,"hc":null,"bdatb":null}],"img":null,"tv":null,"con":null,"marketdefinition":null,"id":"1.258926623"}],"conflatems":null,"op":"mcm","id":3}
{"ct":null,"SegmentType":null,"clk":"APD5AgCcggMA7tkC","heartbeatms":null,"pt":1780840053219,"initialclk":null,"mc":[{"rc":[{"tv":null,"batb":null,"spb":null,"bdatl":null,"trd":null,"spf":null,"ltp":null,"atb":[[6.7999999999999998,0.40000000000000002],[8,628.04999999999995]],"spl":null,"spn":null,"atl":null,"batl":null,"id":16570658,"hc":null,"bdatb":null}],"img":null,"tv":null,"con":null,"marketdefinition":null,"id":"1.258926623"}],"conflatems":null,"op":"mcm","id":3}
{"ct":null,"SegmentType":null,"clk":"APz5AgCmggMA9dkC","heartbeatms":null,"pt":1780840053319,"initialclk":null,"mc":[{"rc":[{"tv":null,"batb":null,"spb":null,"bdatl":null,"trd":null,"spf":null,"ltp":null,"atb":[[8,648.04999999999995]],"spl":null,"spn":null,"atl":null,"batl":null,"id":16570658,"hc":null,"bdatb":null}],"img":null,"tv":null,"con":null,"marketdefinition":null,"id":"1.258926623"}],"conflatems":null,"op":"mcm","id":3}
{"ct":null,"SegmentType":null,"clk":"AJj6AgC7ggMAhtoC","heartbeatms":null,"pt":1780840053528,"initialclk":null,"mc":[{"rc":[{"tv":null,"batb":null,"spb":null,"bdatl":null,"trd":null,"spf":null,"ltp":null,"atb":[[8,748.04999999999995]],"spl":null,"spn":null,"atl":null,"batl":null,"id":16570658,"hc":null,"bdatb":null}],"img":null,"tv":null,"con":null,"marketdefinition":null,"id":"1.258926623"}],"conflatems":null,"op":"mcm","id":3}
{"ct":null,"SegmentType":null,"clk":"AKP6AgDJggMAktoC","heartbeatms":null,"pt":1780840053637,"initialclk":null,"mc":[{"rc":[{"tv":null,"batb":null,"spb":null,"bdatl":null,"trd":null,"spf":null,"ltp":null,"atb":null,"spl":null,"spn":null,"atl":[[8.8000000000000007,183.69999999999999]],"batl":null,"id":16570658,"hc":null,"bdatb":null},{"tv":null,"batb":null,"spb":null,"bdatl":null,"trd":null,"spf":null,"ltp":null,"atb":[[1.1200000000000001,62732.480000000003]],"spl":null,"spn":null,"atl":[[1.1399999999999999,27469.110000000001]],"batl":null,"id":19924823,"hc":null,"bdatb":null}],"img":null,"tv":null,"con":null,"marketdefinition":null,"id":"1.258926623"}],"conflatems":null,"op":"mcm","id":3}
{"ct":null,"SegmentType":null,"clk":"AK76AgDMggMAl9oC","heartbeatms":null,"pt":1780840053733,"initialclk":null,"mc":[{"rc":[{"tv":null,"batb":null,"spb":null,"bdatl":null,"trd":null,"spf":null,"ltp":null,"atb":[[1.1200000000000001,62807.629999999997]],"spl":null,"spn":null,"atl":[[1.1399999999999999,27543.32]],"batl":null,"id":19924823,"hc":null,"bdatb":null}],"img":null,"tv":null,"con":null,"marketdefinition":null,"id":"1.258926623"}],"conflatems":null,"op":"mcm","id":3}
{"ct":null,"SegmentType":null,"clk":"ALf6AgDYggMAodoC","heartbeatms":null,"pt":1780840053838,"initialclk":null,"mc":[{"rc":[{"tv":null,"batb":null,"spb":null,"bdatl":null,"trd":null,"spf":null,"ltp":null,"atb":[[1.1299999999999999,1564.49]],"spl":null,"spn":null,"atl":null,"batl":null,"id":19924823,"hc":null,"bdatb":null}],"img":null,"tv":null,"con":null,"marketdefinition":null,"id":"1.258926623"}],"conflatems":null,"op":"mcm","id":3}
{"ct":null,"SegmentType":null,"clk":"ANH6AgDtggMAtdoC","heartbeatms":null,"pt":1780840054043,"initialclk":null,"mc":[{"rc":[{"tv":null,"batb":null,"spb":null,"bdatl":null,"trd":null,"spf":null,"ltp":null,"atb":[[1.1200000000000001,62837.629999999997]],"spl":null,"spn":null,"atl":null,"batl":null,"id":19924823,"hc":null,"bdatb":null}],"img":null,"tv":null,"con":null,"marketdefinition":null,"id":"1.258926623"}],"conflatems":null,"op":"mcm","id":3}
{"ct":null,"SegmentType":null,"clk":"AN76AgD4ggMAvdoC","heartbeatms":null,"pt":1780840054149,"initialclk":null,"mc":[{"rc":[{"tv":null,"batb":null,"spb":null,"bdatl":null,"trd":null,"spf":null,"ltp":null,"atb":null,"spl":null,"spn":null,"atl":[[1.1499999999999999,31026.830000000002]],"batl":null,"id":19924823,"hc":null,"bdatb":null}],"img":null,"tv":null,"con":null,"marketdefinition":null,"id":"1.258926623"}],"conflatems":null,"op":"mcm","id":3}
{"ct":null,"SegmentType":null,"clk":"AOb6AgCCgwMAwdoC","heartbeatms":null,"pt":1780840054240,"initialclk":null,"mc":[{"rc":[{"tv":null,"batb":null,"spb":null,"bdatl":null,"trd":null,"spf":null,"ltp":null,"atb":[[7.7999999999999998,513.42999999999995]],"spl":null,"spn":null,"atl":null,"batl":null,"id":16570658,"hc":null,"bdatb":null},{"tv":2140116.2000000002,"batb":null,"spb":null,"bdatl":null,"trd":[[1.1299999999999999,271905.01000000001]],"spf":null,"ltp":null,"atb":[[1.1299999999999999,1550.05]],"spl":null,"spn":null,"atl":null,"batl":null,"id":19924823,"hc":null,"bdatb":null}],"img":null,"tv":2389717.1200000001,"con":null,"marketdefinition":null,"id":"1.258926623"}],"conflatems":null,"op":"mcm","id":3}
{"ct":null,"SegmentType":null,"clk":"APD6AgCMgwMAyNoC","heartbeatms":null,"pt":1780840054342,"initialclk":null,"mc":[{"rc":[{"tv":null,"batb":null,"spb":null,"bdatl":null,"trd":null,"spf":null,"ltp":null,"atb":null,"spl":null,"spn":null,"atl":[[1.1499999999999999,31024.830000000002]],"batl":null,"id":19924823,"hc":null,"bdatb":null}],"img":null,"tv":null,"con":null,"marketdefinition":null,"id":"1.258926623"}],"conflatems":null,"op":"mcm","id":3}
{"ct":null,"SegmentType":null,"clk":"AIb7AgCggwMA19oC","heartbeatms":null,"pt":1780840054509,"initialclk":null,"mc":[{"rc":[{"tv":null,"batb":null,"spb":null,"bdatl":null,"trd":null,"spf":null,"ltp":null,"atb":null,"spl":null,"spn":null,"atl":[[8.5999999999999996,4]],"batl":null,"id":16570658,"hc":null,"bdatb":null}],"img":null,"tv":null,"con":null,"marketdefinition":null,"id":"1.258926623"}],"conflatems":null,"op":"mcm","id":3}
{"ct":null,"SegmentType":null,"clk":"AJT7AgCvgwMA3doC","heartbeatms":null,"pt":1780840054618,"initialclk":null,"mc":[{"rc":[{"tv":null,"batb":null,"spb":null,"bdatl":null,"trd":null,"spf":null,"ltp":null,"atb":null,"spl":null,"spn":null,"atl":[[8.5999999999999996,151.94999999999999]],"batl":null,"id":16570658,"hc":null,"bdatb":null},{"tv":null,"batb":null,"spb":null,"bdatl":null,"trd":null,"spf":null,"ltp":null,"atb":[[1.1200000000000001,62852.07]],"spl":null,"spn":null,"atl":null,"batl":null,"id":19924823,"hc":null,"bdatb":null}],"img":null,"tv":null,"con":null,"marketdefinition":null,"id":"1.258926623"}],"conflatems":null,"op":"mcm","id":3}
{"ct":null,"SegmentType":null,"clk":"AJ37AgC7gwMA4doC","heartbeatms":null,"pt":1780840054714,"initialclk":null,"mc":[{"rc":[{"tv":null,"batb":null,"spb":null,"bdatl":null,"trd":null,"spf":null,"ltp":null,"atb":null,"spl":null,"spn":null,"atl":[[8.8000000000000007,138.97999999999999]],"batl":null,"id":16570658,"hc":null,"bdatb":null},{"tv":2140516.1899999999,"batb":null,"spb":null,"bdatl":null,"trd":[[1.1299999999999999,272305]],"spf":null,"ltp":null,"atb":[[1.1299999999999999,1350.05]],"spl":null,"spn":null,"atl":null,"batl":null,"id":19924823,"hc":null,"bdatb":null}],"img":null,"tv":2390117.1099999999,"con":null,"marketdefinition":null,"id":"1.258926623"}],"conflatems":null,"op":"mcm","id":3}
{"ct":null,"SegmentType":null,"clk":"ANX7AgDwgwMAgtsC","heartbeatms":null,"pt":1780840055232,"initialclk":null,"mc":[{"rc":[{"tv":null,"batb":null,"spb":null,"bdatl":null,"trd":null,"spf":null,"ltp":null,"atb":[[1.04,73841.679999999993]],"spl":null,"spn":null,"atl":null,"batl":null,"id":19924823,"hc":null,"bdatb":null}],"img":null,"tv":null,"con":null,"marketdefinition":null,"id":"1.258926623"}],"conflatems":null,"op":"mcm","id":3}
{"ct":null,"SegmentType":null,"clk":"AOf7AgCKhAMAjtsC","heartbeatms":null,"pt":1780840055435,"initialclk":null,"mc":[{"rc":[{"tv":null,"batb":null,"spb":null,"bdatl":null,"trd":null,"spf":null,"ltp":null,"atb":null,"spl":null,"spn":null,"atl":[[1.1699999999999999,8888.8600000000006]],"batl":null,"id":19924823,"hc":null,"bdatb":null}],"img":null,"tv":null,"con":null,"marketdefinition":null,"id":"1.258926623"}],"conflatems":null,"op":"mcm","id":3}
{"ct":null,"SegmentType":null,"clk":"APv7AgCghAMAntsC","heartbeatms":null,"pt":1780840055648,"initialclk":null,"mc":[{"rc":[{"tv":null,"batb":null,"spb":null,"bdatl":null,"trd":null,"spf":null,"ltp":null,"atb":[[1.04,73841.479999999996]],"spl":null,"spn":null,"atl":null,"batl":null,"id":19924823,"hc":null,"bdatb":null}],"img":null,"tv":null,"con":null,"marketdefinition":null,"id":"1.258926623"}],"conflatems":null,"op":"mcm","id":3}
{"ct":null,"SegmentType":null,"clk":"AIT8AgC0hAMAp9sC","heartbeatms":null,"pt":1780840055758,"initialclk":null,"mc":[{"rc":[{"tv":null,"batb":null,"spb":null,"bdatl":null,"trd":null,"spf":null,"ltp":null,"atb":[[8.4000000000000004,2.5299999999999998]],"spl":null,"spn":null,"atl":null,"batl":null,"id":16570658,"hc":null,"bdatb":null},{"tv":null,"batb":null,"spb":null,"bdatl":null,"trd":null,"spf":null,"ltp":null,"atb":[[1.04,73843.479999999996],[1.05,74308.929999999993],[1.0700000000000001,38876.290000000001],[1.0800000000000001,40510.370000000003],[1.1000000000000001,63299.339999999997],[1.0900000000000001,40185.099999999999],[1.0600000000000001,63326.940000000002],[1.02,90741.720000000001],[1.03,88974.589999999997],[1.01,93593.869999999995]],"spl":null,"spn":null,"atl":null,"batl":null,"id":19924823,"hc":null,"bdatb":null}],"img":null,"tv":null,"con":null,"marketdefinition":null,"id":"1.258926623"}],"conflatems":null,"op":"mcm","id":3}
{"ct":null,"SegmentType":null,"clk":"AMH8AgCOhQMA7NsC","heartbeatms":null,"pt":1780840056521,"initialclk":null,"mc":[{"rc":[{"tv":null,"batb":null,"spb":null,"bdatl":null,"trd":null,"spf":null,"ltp":null,"atb":[[8.1999999999999993,0],[8,728.04999999999995]],"spl":null,"spn":null,"atl":null,"batl":null,"id":16570658,"hc":null,"bdatb":null}],"img":null,"tv":null,"con":null,"marketdefinition":null,"id":"1.258926623"}],"conflatems":null,"op":"mcm","id":3}
{"ct":null,"SegmentType":null,"clk":"AMn8AgCahQMA9NsC","heartbeatms":null,"pt":1780840056625,"initialclk":null,"mc":[{"rc":[{"tv":null,"batb":null,"spb":null,"bdatl":null,"trd":null,"spf":null,"ltp":null,"atb":[[6.5999999999999996,0.98999999999999999],[6.7999999999999998,1.26],[7.2000000000000002,209.53999999999999]],"spl":null,"spn":null,"atl":[[10.5,366.69999999999999],[10,240.44]],"batl":null,"id":16570658,"hc":null,"bdatb":null},{"tv":null,"batb":null,"spb":null,"bdatl":null,"trd":null,"spf":null,"ltp":null,"atb":[[1.1000000000000001,63304.599999999999],[1.1100000000000001,54921.480000000003]],"spl":null,"spn":null,"atl":[[1.19,8880.4099999999999],[1.1599999999999999,27120.490000000002],[1.1799999999999999,8877.4599999999991]],"batl":null,"id":19924823,"hc":null,"bdatb":null}],"img":null,"tv":null,"con":null,"marketdefinition":null,"id":"1.258926623"}],"conflatems":null,"op":"mcm","id":3}
{"ct":null,"SegmentType":null,"clk":"APX8AgDMhQMAmdwC","heartbeatms":null,"pt":1780840057134,"initialclk":null,"mc":[{"rc":[{"tv":null,"batb":null,"spb":null,"bdatl":null,"trd":null,"spf":null,"ltp":null,"atb":null,"spl":null,"spn":null,"atl":[[13,5.8300000000000001],[12.5,6.0800000000000001],[12,6.3600000000000003]],"batl":null,"id":16570658,"hc":null,"bdatb":null},{"tv":null,"batb":null,"spb":null,"bdatl":null,"trd":null,"spf":null,"ltp":null,"atb":null,"spl":null,"spn":null,"atl":[[1.24,205.93000000000001],[1.23,681.25999999999999]],"batl":null,"id":19924823,"hc":null,"bdatb":null}],"img":null,"tv":null,"con":null,"marketdefinition":null,"id":"1.258926623"}],"conflatems":null,"op":"mcm","id":3}
{"ct":null,"SegmentType":null,"clk":"AIL9AgDXhQMAodwC","heartbeatms":null,"pt":1780840057241,"initialclk":null,"mc":[{"rc":[{"tv":null,"batb":null,"spb":null,"bdatl":null,"trd":null,"spf":null,"ltp":null,"atb":[[8.4000000000000004,2.6099999999999999]],"spl":null,"spn":null,"atl":null,"batl":null,"id":16570658,"hc":null,"bdatb":null},{"tv":null,"batb":null,"spb":null,"bdatl":null,"trd":null,"spf":null,"ltp":null,"atb":[[1.0800000000000001,40596.739999999998]],"spl":null,"spn":null,"atl":null,"batl":null,"id":19924823,"hc":null,"bdatb":null}],"img":null,"tv":null,"con":null,"marketdefinition":null,"id":"1.258926623"}],"conflatems":null,"op":"mcm","id":3}
{"ct":null,"SegmentType":null,"clk":"AIz9AgDkhQMAqtwC","heartbeatms":null,"pt":1780840057343,"initialclk":null,"mc":[{"rc":[{"tv":2140522.8799999999,"batb":null,"spb":null,"bdatl":null,"trd":[[1.1299999999999999,272311.69]],"spf":null,"ltp":null,"atb":[[1.1299999999999999,1346.71]],"spl":null,"spn":null,"atl":null,"batl":null,"id":19924823,"hc":null,"bdatb":null}],"img":null,"tv":2390123.7999999998,"con":null,"marketdefinition":null,"id":"1.258926623"}],"conflatems":null,"op":"mcm","id":3}
{"ct":null,"SegmentType":null,"clk":"AJb9AgDvhQMAr9wC","heartbeatms":null,"pt":1780840057445,"initialclk":null,"mc":[{"rc":[{"tv":null,"batb":null,"spb":null,"bdatl":null,"trd":null,"spf":null,"ltp":null,"atb":[[1.0800000000000001,40683.120000000003]],"spl":null,"spn":null,"atl":null,"batl":null,"id":19924823,"hc":null,"bdatb":null}],"img":null,"tv":null,"con":null,"marketdefinition":null,"id":"1.258926623"}],"conflatems":null,"op":"mcm","id":3}
{"ct":null,"SegmentType":null,"clk":"AL79AgCghgMAxdwC","heartbeatms":null,"pt":1780840057752,"initialclk":null,"mc":[{"rc":[{"tv":null,"batb":null,"spb":null,"bdatl":null,"trd":null,"spf":null,"ltp":null,"atb":[[1.0800000000000001,40769.5],[1.1299999999999999,1246.71]],"spl":null,"spn":null,"atl":null,"batl":null,"id":19924823,"hc":null,"bdatb":null}],"img":null,"tv":null,"con":null,"marketdefinition":null,"id":"1.258926623"}],"conflatems":null,"op":"mcm","id":3}
{"ct":null,"SegmentType":null,"clk":"AMb9AgCohgMAzNwC","heartbeatms":null,"pt":1780840057817,"initialclk":null,"mc":[{"rc":[{"tv":null,"batb":null,"spb":null,"bdatl":null,"trd":null,"spf":null,"ltp":null,"atb":[[1.1299999999999999,1664.55]],"spl":null,"spn":null,"atl":null,"batl":null,"id":19924823,"hc":null,"bdatb":null}],"img":null,"tv":null,"con":null,"marketdefinition":null,"id":"1.258926623"}],"conflatems":null,"op":"mcm","id":3}
{"ct":null,"SegmentType":null,"clk":"AM/9AgC2hgMA0dwC","heartbeatms":null,"pt":1780840057917,"initialclk":null,"mc":[{"rc":[{"tv":null,"batb":null,"spb":null,"bdatl":null,"trd":null,"spf":null,"ltp":null,"atb":null,"spl":null,"spn":null,"atl":[[10.5,359.33999999999997],[10,232.66999999999999]],"batl":null,"id":16570658,"hc":null,"bdatb":null}],"img":null,"tv":null,"con":null,"marketdefinition":null,"id":"1.258926623"}],"conflatems":null,"op":"mcm","id":3}
{"ct":null,"SegmentType":null,"clk":"AOT9AgDOhgMA39wC","heartbeatms":null,"pt":1780840058125,"initialclk":null,"mc":[{"rc":[{"tv":null,"batb":null,"spb":null,"bdatl":null,"trd":null,"spf":null,"ltp":null,"atb":[[7.4000000000000004,403.99000000000001]],"spl":null,"spn":null,"atl":null,"batl":null,"id":16570658,"hc":null,"bdatb":null},{"tv":null,"batb":null,"spb":null,"bdatl":null,"trd":null,"spf":null,"ltp":null,"atb":null,"spl":null,"spn":null,"atl":[[1.1599999999999999,28343.93]],"batl":null,"id":19924823,"hc":null,"bdatb":null}],"img":null,"tv":null,"con":null,"marketdefinition":null,"id":"1.258926623"}],"conflatems":null,"op":"mcm","id":3}
{"ct":null,"SegmentType":null,"clk":"AIj\u002BAgD/hgMAgt0C","heartbeatms":null,"pt":1780840058541,"initialclk":null,"mc":[{"rc":[{"tv":null,"batb":null,"spb":null,"bdatl":null,"trd":null,"spf":null,"ltp":null,"atb":[[7.2000000000000002,14.529999999999999]],"spl":null,"spn":null,"atl":null,"batl":null,"id":16570658,"hc":null,"bdatb":null}],"img":null,"tv":null,"con":null,"marketdefinition":null,"id":"1.258926623"}],"conflatems":null,"op":"mcm","id":3}
{"ct":null,"SegmentType":null,"clk":"AJX\u002BAgCWhwMAj90C","heartbeatms":null,"pt":1780840058741,"initialclk":null,"mc":[{"rc":[{"tv":null,"batb":null,"spb":null,"bdatl":null,"trd":null,"spf":null,"ltp":null,"atb":[[1.1299999999999999,1664.74]],"spl":null,"spn":null,"atl":null,"batl":null,"id":19924823,"hc":null,"bdatb":null}],"img":null,"tv":null,"con":null,"marketdefinition":null,"id":"1.258926623"}],"conflatems":null,"op":"mcm","id":3}
{"ct":null,"SegmentType":null,"clk":"ANH\u002BAgDNhwMAu90C","heartbeatms":null,"pt":1780840059252,"initialclk":null,"mc":[{"rc":[{"tv":null,"batb":null,"spb":null,"bdatl":null,"trd":null,"spf":null,"ltp":null,"atb":[[7.4000000000000004,403.13],[7.2000000000000002,13.529999999999999]],"spl":null,"spn":null,"atl":[[9.4000000000000004,74.730000000000004],[9.5999999999999996,20]],"batl":null,"id":16570658,"hc":null,"bdatb":null},{"tv":null,"batb":null,"spb":null,"bdatl":null,"trd":null,"spf":null,"ltp":null,"atb":[[1.1000000000000001,63298.290000000001],[1.1100000000000001,54916.220000000001]],"spl":null,"spn":null,"atl":[[1.1699999999999999,8884.6900000000005],[1.1599999999999999,28338.990000000002]],"batl":null,"id":19924823,"hc":null,"bdatb":null}],"img":null,"tv":null,"con":null,"marketdefinition":null,"id":"1.258926623"}],"conflatems":null,"op":"mcm","id":3}
{"ct":null,"SegmentType":null,"clk":"AOX\u002BAgDqhwMAyd0C","heartbeatms":null,"pt":1780840059459,"initialclk":null,"mc":[{"rc":[{"tv":2140524.98,"batb":null,"spb":null,"bdatl":null,"trd":[[1.1299999999999999,272313.78999999998]],"spf":null,"ltp":null,"atb":[[1.1299999999999999,1663.6900000000001]],"spl":null,"spn":null,"atl":null,"batl":null,"id":19924823,"hc":null,"bdatb":null}],"img":null,"tv":2390125.8999999999,"con":null,"marketdefinition":null,"id":"1.258926623"}],"conflatems":null,"op":"mcm","id":3}
{"ct":null,"SegmentType":null,"clk":"AIX/AgCIiAMA290C","heartbeatms":null,"pt":1780840059736,"initialclk":null,"mc":[{"rc":[{"tv":null,"batb":null,"spb":null,"bdatl":null,"trd":null,"spf":null,"ltp":null,"atb":null,"spl":null,"spn":null,"atl":[[1.1399999999999999,27293.32]],"batl":null,"id":19924823,"hc":null,"bdatb":null}],"img":null,"tv":null,"con":null,"marketdefinition":null,"id":"1.258926623"}],"conflatems":null,"op":"mcm","id":3}
{"ct":null,"SegmentType":null,"clk":"AKD/AgCriAMA7t0C","heartbeatms":null,"pt":1780840060038,"initialclk":null,"mc":[{"rc":[{"tv":null,"batb":null,"spb":null,"bdatl":null,"trd":null,"spf":null,"ltp":null,"atb":null,"spl":null,"spn":null,"atl":[[1.3999999999999999,1097.6400000000001]],"batl":null,"id":19924823,"hc":null,"bdatb":null}],"img":null,"tv":null,"con":null,"marketdefinition":null,"id":"1.258926623"}],"conflatems":null,"op":"mcm","id":3}
{"ct":null,"SegmentType":null,"clk":"ALD/AgDAiAMA\u002Bt0C","heartbeatms":null,"pt":1780840060234,"initialclk":null,"mc":[{"rc":[{"tv":249601.07999999999,"batb":null,"spb":null,"bdatl":null,"trd":[[8.5999999999999996,2915.6900000000001]],"spf":null,"ltp":8.5999999999999996,"atb":null,"spl":null,"spn":null,"atl":[[8.5999999999999996,151.87000000000001]],"batl":null,"id":16570658,"hc":null,"bdatb":null}],"img":null,"tv":2390126.0600000001,"con":null,"marketdefinition":null,"id":"1.258926623"}],"conflatems":null,"op":"mcm","id":3}
{"ct":null,"SegmentType":null,"clk":"AOz/AgCGiQMAq94C","heartbeatms":null,"pt":1780840060851,"initialclk":null,"mc":[{"rc":[{"tv":2140724.98,"batb":null,"spb":null,"bdatl":null,"trd":[[1.1399999999999999,172583.07000000001]],"spf":null,"ltp":1.1399999999999999,"atb":null,"spl":null,"spn":null,"atl":[[1.1399999999999999,27193.32]],"batl":null,"id":19924823,"hc":null,"bdatb":null}],"img":null,"tv":2390326.0600000001,"con":null,"marketdefinition":null,"id":"1.258926623"}],"conflatems":null,"op":"mcm","id":3}
{"ct":null,"SegmentType":null,"clk":"AP7/AgCdiQMAwN4C","heartbeatms":null,"pt":1780840061022,"initialclk":null,"mc":[{"rc":[{"tv":null,"batb":null,"spb":null,"bdatl":null,"trd":null,"spf":null,"ltp":null,"atb":[[1.1299999999999999,1656.2000000000001]],"spl":null,"spn":null,"atl":[[1.1599999999999999,28331.5]],"batl":null,"id":19924823,"hc":null,"bdatb":null}],"img":null,"tv":null,"con":null,"marketdefinition":null,"id":"1.258926623"}],"conflatems":null,"op":"mcm","id":3}
{"ct":null,"SegmentType":null,"clk":"AIqBAwC3igMAyt8C","heartbeatms":null,"pt":1780840062521,"initialclk":null,"mc":[{"rc":[{"tv":249602.98000000001,"batb":null,"spb":null,"bdatl":null,"trd":[[8.4000000000000004,2824.9299999999998]],"spf":null,"ltp":8.4000000000000004,"atb":[[8.4000000000000004,1.6599999999999999]],"spl":null,"spn":null,"atl":[[8.8000000000000007,137.75]],"batl":null,"id":16570658,"hc":null,"bdatb":null},{"tv":null,"batb":null,"spb":null,"bdatl":null,"trd":null,"spf":null,"ltp":null,"atb":[[1.1299999999999999,10515.139999999999]],"spl":null,"spn":null,"atl":null,"batl":null,"id":19924823,"hc":null,"bdatb":null}],"img":null,"tv":2390327.96,"con":null,"marketdefinition":null,"id":"1.258926623"}],"conflatems":null,"op":"mcm","id":3}
{"ct":null,"SegmentType":null,"clk":"AJeBAwDDigMA1N8C","heartbeatms":null,"pt":1780840062622,"initialclk":null,"mc":[{"rc":[{"tv":null,"batb":null,"spb":null,"bdatl":null,"trd":null,"spf":null,"ltp":null,"atb":[[1.1299999999999999,11615.83]],"spl":null,"spn":null,"atl":null,"batl":null,"id":19924823,"hc":null,"bdatb":null}],"img":null,"tv":null,"con":null,"marketdefinition":null,"id":"1.258926623"}],"conflatems":null,"op":"mcm","id":3}
{"ct":null,"SegmentType":null,"clk":"ALOBAwDZigMA6N8C","heartbeatms":null,"pt":1780840062831,"initialclk":null,"mc":[{"rc":[{"tv":null,"batb":null,"spb":null,"bdatl":null,"trd":null,"spf":null,"ltp":null,"atb":null,"spl":null,"spn":null,"atl":[[1.1399999999999999,27145.240000000002]],"batl":null,"id":19924823,"hc":null,"bdatb":null}],"img":null,"tv":null,"con":null,"marketdefinition":null,"id":"1.258926623"}],"conflatems":null,"op":"mcm","id":3}
{"ct":null,"SegmentType":null,"clk":"AImCAwCxiwMAs\u002BAC","heartbeatms":null,"pt":1780840063753,"initialclk":null,"mc":[{"rc":[{"tv":2140727.02,"batb":null,"spb":null,"bdatl":null,"trd":[[1.1399999999999999,172585.10999999999]],"spf":null,"ltp":null,"atb":null,"spl":null,"spn":null,"atl":[[1.1399999999999999,27144.220000000001]],"batl":null,"id":19924823,"hc":null,"bdatb":null}],"img":null,"tv":2390330,"con":null,"marketdefinition":null,"id":"1.258926623"}],"conflatems":null,"op":"mcm","id":3}
{"ct":null,"SegmentType":null,"clk":"AKeCAwDNiwMAzOAC","heartbeatms":null,"pt":1780840064052,"initialclk":null,"mc":[{"rc":[{"tv":null,"batb":null,"spb":null,"bdatl":null,"trd":null,"spf":null,"ltp":null,"atb":null,"spl":null,"spn":null,"atl":[[1.1399999999999999,27158.66]],"batl":null,"id":19924823,"hc":null,"bdatb":null}],"img":null,"tv":null,"con":null,"marketdefinition":null,"id":"1.258926623"}],"conflatems":null,"op":"mcm","id":3}
{"ct":null,"SegmentType":null,"clk":"ALCCAwDciwMA0OAC","heartbeatms":null,"pt":1780840064119,"initialclk":null,"mc":[{"rc":[{"tv":null,"batb":null,"spb":null,"bdatl":null,"trd":null,"spf":null,"ltp":null,"atb":null,"spl":null,"spn":null,"atl":[[1.1399999999999999,26734.959999999999]],"batl":null,"id":19924823,"hc":null,"bdatb":null}],"img":null,"tv":null,"con":null,"marketdefinition":null,"id":"1.258926623"}],"conflatems":null,"op":"mcm","id":3}
{"ct":null,"SegmentType":null,"clk":"ALyCAwDoiwMA1eAC","heartbeatms":null,"pt":1780840064220,"initialclk":null,"mc":[{"rc":[{"tv":null,"batb":null,"spb":null,"bdatl":null,"trd":null,"spf":null,"ltp":null,"atb":[[8.4000000000000004,1.5800000000000001]],"spl":null,"spn":null,"atl":null,"batl":null,"id":16570658,"hc":null,"bdatb":null}],"img":null,"tv":null,"con":null,"marketdefinition":null,"id":"1.258926623"}],"conflatems":null,"op":"mcm","id":3}
{"ct":null,"SegmentType":null,"clk":"AOOCAwCVjAMA9eAC","heartbeatms":null,"pt":1780840064641,"initialclk":null,"mc":[{"rc":[{"tv":2141127.02,"batb":null,"spb":null,"bdatl":null,"trd":[[1.1299999999999999,272713.78999999998]],"spf":null,"ltp":1.1299999999999999,"atb":[[1.1299999999999999,11415.83]],"spl":null,"spn":null,"atl":null,"batl":null,"id":19924823,"hc":null,"bdatb":null}],"img":null,"tv":2390730,"con":null,"marketdefinition":null,"id":"1.258926623"}],"conflatems":null,"op":"mcm","id":3}
{"ct":null,"SegmentType":null,"clk":"AO\u002BCAwCfjAMA\u002B\u002BAC","heartbeatms":null,"pt":1780840064736,"initialclk":null,"mc":[{"rc":[{"tv":2141149.7200000002,"batb":null,"spb":null,"bdatl":null,"trd":[[1.1299999999999999,272736.48999999999]],"spf":null,"ltp":null,"atb":[[1.1299999999999999,11404.48]],"spl":null,"spn":null,"atl":null,"batl":null,"id":19924823,"hc":null,"bdatb":null}],"img":null,"tv":2390752.7000000002,"con":null,"marketdefinition":null,"id":"1.258926623"}],"conflatems":null,"op":"mcm","id":3}
{"ct":null,"SegmentType":null,"clk":"AIaDAwC/jAMAkeEC","heartbeatms":null,"pt":1780840065042,"initialclk":null,"mc":[{"rc":[{"tv":null,"batb":null,"spb":null,"bdatl":null,"trd":null,"spf":null,"ltp":null,"atb":[[8.1999999999999993,8.4199999999999999]],"spl":null,"spn":null,"atl":null,"batl":null,"id":16570658,"hc":null,"bdatb":null},{"tv":null,"batb":null,"spb":null,"bdatl":null,"trd":null,"spf":null,"ltp":null,"atb":[[1.0700000000000001,38885.129999999997]],"spl":null,"spn":null,"atl":null,"batl":null,"id":19924823,"hc":null,"bdatb":null}],"img":null,"tv":null,"con":null,"marketdefinition":null,"id":"1.258926623"}],"conflatems":null,"op":"mcm","id":3}
{"ct":null,"SegmentType":null,"clk":"AMqEAwCOjgMAiOIC","heartbeatms":null,"pt":1780840066858,"initialclk":null,"mc":[{"rc":[{"tv":249606.14999999999,"batb":null,"spb":null,"bdatl":null,"trd":[[8.4000000000000004,2828.0999999999999]],"spf":null,"ltp":null,"atb":[[8.4000000000000004,0]],"spl":null,"spn":null,"atl":[[8.4000000000000004,0.070000000000000007]],"batl":null,"id":16570658,"hc":null,"bdatb":null}],"img":null,"tv":2390755.8700000001,"con":null,"marketdefinition":null,"id":"1.258926623"}],"conflatems":null,"op":"mcm","id":3}
{"ct":null,"SegmentType":null,"clk":"AP6EAwC8jgMAsOIC","heartbeatms":null,"pt":1780840067358,"initialclk":null,"mc":[{"rc":[{"tv":null,"batb":null,"spb":null,"bdatl":null,"trd":null,"spf":null,"ltp":null,"atb":null,"spl":null,"spn":null,"atl":[[1.1399999999999999,26805.400000000001]],"batl":null,"id":19924823,"hc":null,"bdatb":null}],"img":null,"tv":null,"con":null,"marketdefinition":null,"id":"1.258926623"}],"conflatems":null,"op":"mcm","id":3}
{"ct":null,"SegmentType":null,"clk":"AIeFAwDHjgMAtuIC","heartbeatms":null,"pt":1780840067416,"initialclk":null,"mc":[{"rc":[{"tv":null,"batb":null,"spb":null,"bdatl":null,"trd":null,"spf":null,"ltp":null,"atb":[[6.5999999999999996,25.989999999999998],[6.7999999999999998,25.379999999999999]],"spl":null,"spn":null,"atl":null,"batl":null,"id":16570658,"hc":null,"bdatb":null},{"tv":null,"batb":null,"spb":null,"bdatl":null,"trd":null,"spf":null,"ltp":null,"atb":[[1.1299999999999999,11333.719999999999]],"spl":null,"spn":null,"atl":null,"batl":null,"id":19924823,"hc":null,"bdatb":null}],"img":null,"tv":null,"con":null,"marketdefinition":null,"id":"1.258926623"}],"conflatems":null,"op":"mcm","id":3}
{"ct":null,"SegmentType":null,"clk":"AMyFAwCEjwMA6OIC","heartbeatms":null,"pt":1780840068039,"initialclk":null,"mc":[{"rc":[{"tv":null,"batb":null,"spb":null,"bdatl":null,"trd":null,"spf":null,"ltp":null,"atb":[[7.7999999999999998,505.00999999999999]],"spl":null,"spn":null,"atl":null,"batl":null,"id":16570658,"hc":null,"bdatb":null}],"img":null,"tv":null,"con":null,"marketdefinition":null,"id":"1.258926623"}],"conflatems":null,"op":"mcm","id":3}
{"ct":null,"SegmentType":null,"clk":"AOCFAwCPjwMA7uIC","heartbeatms":null,"pt":1780840068152,"initialclk":null,"mc":[{"rc":[{"tv":null,"batb":null,"spb":null,"bdatl":null,"trd":null,"spf":null,"ltp":null,"atb":[[1.1299999999999999,11355.860000000001]],"spl":null,"spn":null,"atl":null,"batl":null,"id":19924823,"hc":null,"bdatb":null}],"img":null,"tv":null,"con":null,"marketdefinition":null,"id":"1.258926623"}],"conflatems":null,"op":"mcm","id":3}
{"ct":null,"SegmentType":null,"clk":"AMKGAwD2jwMAreMC","heartbeatms":null,"pt":1780840069065,"initialclk":null,"mc":[{"rc":[{"tv":null,"batb":null,"spb":null,"bdatl":null,"trd":null,"spf":null,"ltp":null,"atb":[[1.02,90735.919999999998]],"spl":null,"spn":null,"atl":null,"batl":null,"id":19924823,"hc":null,"bdatb":null}],"img":null,"tv":null,"con":null,"marketdefinition":null,"id":"1.258926623"}],"conflatems":null,"op":"mcm","id":3}
{"ct":null,"SegmentType":null,"clk":"AMqGAwD/jwMAs\u002BMC","heartbeatms":null,"pt":1780840069123,"initialclk":null,"mc":[{"rc":[{"tv":null,"batb":null,"spb":null,"bdatl":null,"trd":null,"spf":null,"ltp":null,"atb":[[1.03,88980.389999999999]],"spl":null,"spn":null,"atl":null,"batl":null,"id":19924823,"hc":null,"bdatb":null}],"img":null,"tv":null,"con":null,"marketdefinition":null,"id":"1.258926623"}],"conflatems":null,"op":"mcm","id":3}
{"ct":null,"SegmentType":null,"clk":"AIGHAwC6kAMA1uMC","heartbeatms":null,"pt":1780840069642,"initialclk":null,"mc":[{"rc":[{"tv":null,"batb":null,"spb":null,"bdatl":null,"trd":null,"spf":null,"ltp":null,"atb":[[1.1299999999999999,11355.66]],"spl":null,"spn":null,"atl":null,"batl":null,"id":19924823,"hc":null,"bdatb":null}],"img":null,"tv":null,"con":null,"marketdefinition":null,"id":"1.258926623"}],"conflatems":null,"op":"mcm","id":3}
{"ct":null,"SegmentType":null,"clk":"ALuHAwDokAMA\u002BOMC","heartbeatms":null,"pt":1780840070148,"initialclk":null,"mc":[{"rc":[{"tv":null,"batb":null,"spb":null,"bdatl":null,"trd":null,"spf":null,"ltp":null,"atb":[[1.1200000000000001,36275.239999999998]],"spl":null,"spn":null,"atl":null,"batl":null,"id":19924823,"hc":null,"bdatb":null}],"img":null,"tv":null,"con":null,"marketdefinition":null,"id":"1.258926623"}],"conflatems":null,"op":"mcm","id":3}
{"ct":null,"SegmentType":null,"clk":"ANqHAwD7kAMAj\u002BQC","heartbeatms":null,"pt":1780840070351,"initialclk":null,"mc":[{"rc":[{"tv":null,"batb":null,"spb":null,"bdatl":null,"trd":null,"spf":null,"ltp":null,"atb":null,"spl":null,"spn":null,"atl":[[8.4000000000000004,1.0600000000000001]],"batl":null,"id":16570658,"hc":null,"bdatb":null}],"img":null,"tv":null,"con":null,"marketdefinition":null,"id":"1.258926623"}],"conflatems":null,"op":"mcm","id":3}
{"ct":null,"SegmentType":null,"clk":"AIOJAwCWkgMAmeUC","heartbeatms":null,"pt":1780840072061,"initialclk":null,"mc":[{"rc":[{"tv":2141156.7400000002,"batb":null,"spb":null,"bdatl":null,"trd":[[1.1399999999999999,172592.13000000001]],"spf":null,"ltp":1.1399999999999999,"atb":null,"spl":null,"spn":null,"atl":[[1.1399999999999999,26801.880000000001]],"batl":null,"id":19924823,"hc":null,"bdatb":null}],"img":null,"tv":2390762.8900000001,"con":null,"marketdefinition":null,"id":"1.258926623"}],"conflatems":null,"op":"mcm","id":3}
{"ct":null,"SegmentType":null,"clk":"APqJAwCAkwMA9uUC","heartbeatms":null,"pt":1780840073156,"initialclk":null,"mc":[{"rc":[{"tv":null,"batb":null,"spb":null,"bdatl":null,"trd":null,"spf":null,"ltp":null,"atb":[[1.04,73843.660000000003]],"spl":null,"spn":null,"atl":null,"batl":null,"id":19924823,"hc":null,"bdatb":null}],"img":null,"tv":null,"con":null,"marketdefinition":null,"id":"1.258926623"}],"conflatems":null,"op":"mcm","id":3}
{"ct":null,"SegmentType":null,"clk":"AIyKAwCWkwMAgeYC","heartbeatms":null,"pt":1780840073354,"initialclk":null,"mc":[{"rc":[{"tv":null,"batb":null,"spb":null,"bdatl":null,"trd":null,"spf":null,"ltp":null,"atb":null,"spl":null,"spn":null,"atl":[[10,146.30000000000001]],"batl":null,"id":16570658,"hc":null,"bdatb":null}],"img":null,"tv":null,"con":null,"marketdefinition":null,"id":"1.258926623"}],"conflatems":null,"op":"mcm","id":3}
{"ct":null,"SegmentType":null,"clk":"AKSKAwCxkwMAkOYC","heartbeatms":null,"pt":1780840073555,"initialclk":null,"mc":[{"rc":[{"tv":null,"batb":null,"spb":null,"bdatl":null,"trd":null,"spf":null,"ltp":null,"atb":[[1.04,73843.479999999996]],"spl":null,"spn":null,"atl":null,"batl":null,"id":19924823,"hc":null,"bdatb":null}],"img":null,"tv":null,"con":null,"marketdefinition":null,"id":"1.258926623"}],"conflatems":null,"op":"mcm","id":3}
{"ct":null,"SegmentType":null,"clk":"AM2KAwDZkwMAs\u002BYC","heartbeatms":null,"pt":1780840073929,"initialclk":null,"mc":[{"rc":[{"tv":2141172.7400000002,"batb":null,"spb":null,"bdatl":null,"trd":[[1.1299999999999999,272752.48999999999]],"spf":null,"ltp":1.1299999999999999,"atb":[[1.1299999999999999,11347.66]],"spl":null,"spn":null,"atl":null,"batl":null,"id":19924823,"hc":null,"bdatb":null}],"img":null,"tv":2390778.8900000001,"con":null,"marketdefinition":null,"id":"1.258926623"}],"conflatems":null,"op":"mcm","id":3}
{"ct":null,"SegmentType":null,"clk":"AJ6LAwCslAMA9uYC","heartbeatms":null,"pt":1780840074653,"initialclk":null,"mc":[{"rc":[{"tv":null,"batb":null,"spb":null,"bdatl":null,"trd":null,"spf":null,"ltp":null,"atb":[[1.1100000000000001,54829.839999999997]],"spl":null,"spn":null,"atl":null,"batl":null,"id":19924823,"hc":null,"bdatb":null}],"img":null,"tv":null,"con":null,"marketdefinition":null,"id":"1.258926623"}],"conflatems":null,"op":"mcm","id":3}
{"ct":null,"SegmentType":null,"clk":"AKWLAwC5lAMA/\u002BYC","heartbeatms":null,"pt":1780840074767,"initialclk":null,"mc":[{"rc":[{"tv":null,"batb":null,"spb":null,"bdatl":null,"trd":null,"spf":null,"ltp":null,"atb":[[1.1200000000000001,36361.620000000003]],"spl":null,"spn":null,"atl":null,"batl":null,"id":19924823,"hc":null,"bdatb":null}],"img":null,"tv":null,"con":null,"marketdefinition":null,"id":"1.258926623"}],"conflatems":null,"op":"mcm","id":3}
{"ct":null,"SegmentType":null,"clk":"APKLAwCVlQMAx\u002BcC","heartbeatms":null,"pt":1780840075551,"initialclk":null,"mc":[{"rc":[{"tv":null,"batb":null,"spb":null,"bdatl":null,"trd":null,"spf":null,"ltp":null,"atb":null,"spl":null,"spn":null,"atl":[[1.1599999999999999,27818.450000000001]],"batl":null,"id":19924823,"hc":null,"bdatb":null}],"img":null,"tv":null,"con":null,"marketdefinition":null,"id":"1.258926623"}],"conflatems":null,"op":"mcm","id":3}
{"ct":null,"SegmentType":null,"clk":"ANuMAwD7lQMAuOgC","heartbeatms":null,"pt":1780840076666,"initialclk":null,"mc":[{"rc":[{"tv":2141173.1000000001,"batb":null,"spb":null,"bdatl":null,"trd":[[1.1399999999999999,172592.48999999999]],"spf":null,"ltp":1.1399999999999999,"atb":null,"spl":null,"spn":null,"atl":[[1.1399999999999999,26801.700000000001]],"batl":null,"id":19924823,"hc":null,"bdatb":null}],"img":null,"tv":2390779.25,"con":null,"marketdefinition":null,"id":"1.258926623"}],"conflatems":null,"op":"mcm","id":3}
{"ct":null,"SegmentType":null,"clk":"AIGNAwCelgMA3ugC","heartbeatms":null,"pt":1780840077064,"initialclk":null,"mc":[{"rc":[{"tv":null,"batb":null,"spb":null,"bdatl":null,"trd":null,"spf":null,"ltp":null,"atb":[[1.04,73842.729999999996]],"spl":null,"spn":null,"atl":null,"batl":null,"id":19924823,"hc":null,"bdatb":null}],"img":null,"tv":null,"con":null,"marketdefinition":null,"id":"1.258926623"}],"conflatems":null,"op":"mcm","id":3}
{"ct":null,"SegmentType":null,"clk":"AJeNAwCylgMA8OgC","heartbeatms":null,"pt":1780840077230,"initialclk":null,"mc":[{"rc":[{"tv":null,"batb":null,"spb":null,"bdatl":null,"trd":null,"spf":null,"ltp":null,"atb":null,"spl":null,"spn":null,"atl":[[8.4000000000000004,0.070000000000000007]],"batl":null,"id":16570658,"hc":null,"bdatb":null}],"img":null,"tv":null,"con":null,"marketdefinition":null,"id":"1.258926623"}],"conflatems":null,"op":"mcm","id":3}
{"ct":null,"SegmentType":null,"clk":"AJ\u002BNAwC/lgMA9\u002BgC","heartbeatms":null,"pt":1780840077330,"initialclk":null,"mc":[{"rc":[{"tv":null,"batb":null,"spb":null,"bdatl":null,"trd":null,"spf":null,"ltp":null,"atb":[[8.1999999999999993,68.959999999999994]],"spl":null,"spn":null,"atl":null,"batl":null,"id":16570658,"hc":null,"bdatb":null}],"img":null,"tv":null,"con":null,"marketdefinition":null,"id":"1.258926623"}],"conflatems":null,"op":"mcm","id":3}
{"ct":null,"SegmentType":null,"clk":"ALWNAwDVlgMAhekC","heartbeatms":null,"pt":1780840077541,"initialclk":null,"mc":[{"rc":[{"tv":2141223.04,"batb":null,"spb":null,"bdatl":null,"trd":[[1.1299999999999999,272802.42999999999]],"spf":null,"ltp":1.1299999999999999,"atb":[[1.1299999999999999,11322.690000000001]],"spl":null,"spn":null,"atl":null,"batl":null,"id":19924823,"hc":null,"bdatb":null}],"img":null,"tv":2390829.1899999999,"con":null,"marketdefinition":null,"id":"1.258926623"}],"conflatems":null,"op":"mcm","id":3}
