{"ct":0,"SegmentType":null,"clk":"AAAAAAAA","heartbeatms":5000,"pt":1780839550398,"initialclk":"KqH7mfkJK/Hu6PIJK9ba7ucJ","mc":[{"rc":[{"tv":238310.32000000001,"batb":null,"spb":null,"bdatl":null,"trd":[[8.5999999999999996,1192.1900000000001],[8.8000000000000007,1089.47],[8.4000000000000004,149.56999999999999],[8,3729.2399999999998],[8.1999999999999993,1162.5999999999999],[7.7999999999999998,732.79999999999995],[7.5999999999999996,1586.5899999999999],[7,5.0499999999999998],[7.4000000000000004,1],[7.2000000000000002,1],[6.7999999999999998,634.39999999999998],[6.5999999999999996,819.97000000000003],[6.4000000000000004,795.78999999999996],[6.2000000000000002,3410.3600000000001],[5.7999999999999998,25054.669999999998],[5.7000000000000002,9564.7099999999991],[5.9000000000000004,702.05999999999995],[6,686.34000000000003],[5.5,21583.27],[5.5999999999999996,4770.9899999999998],[5.4000000000000004,42199.519999999997],[5.2999999999999998,22117.549999999999],[5.2000000000000002,3639.98],[5.0999999999999996,13755.219999999999],[5,17746.360000000001],[4.9000000000000004,9609.3899999999994],[4.7999999999999998,4883.1499999999996],[4.7000000000000002,2994.5799999999999],[4.5999999999999996,15402.610000000001],[4.5,23562.869999999999],[4.4000000000000004,3387.9299999999998],[4.2000000000000002,392.72000000000003],[4.2999999999999998,878.37],[3.8999999999999999,48],[4.0999999999999996,20]],"spf":null,"ltp":8.5999999999999996,"atb":[[7.5999999999999996,666.59000000000003],[8.1999999999999993,257.95999999999998],[8.5999999999999996,370.68000000000001],[8,1065],[7,367.38999999999999],[6.7999999999999998,114.61],[7.2000000000000002,11.289999999999999],[7.7999999999999998,0.98999999999999999],[8.4000000000000004,295.42000000000002],[7.4000000000000004,218.24000000000001],[2.3799999999999999,570],[1.69,24.190000000000001],[2.2599999999999998,13.82],[2.7799999999999998,10.369999999999999],[3.3500000000000001,6.71],[3,38.210000000000001],[4,100.20999999999999],[4.0999999999999996,8.6400000000000006],[3.8999999999999999,17.280000000000001],[4.2000000000000002,8.6400000000000006],[4.2999999999999998,38.869999999999997],[1.04,11387.200000000001],[4.4000000000000004,308.63999999999999],[5,286.10000000000002],[5.2000000000000002,287.63999999999999],[4.5,52.829999999999998],[3.7999999999999998,14.68],[4.9000000000000004,4.5999999999999996],[4.7999999999999998,43.189999999999998],[4.7000000000000002,2.6699999999999999],[1.01,18362.360000000001],[1.1000000000000001,6768.2200000000003],[1.02,16541.880000000001],[1.1100000000000001,3003.8699999999999],[2.1200000000000001,105.75],[1.1200000000000001,117.38],[3.0499999999999998,12.09],[3.3999999999999999,7.7699999999999996],[1.5,5],[2.3599999999999999,202.19999999999999],[2.6800000000000002,52.869999999999997],[1.03,11277.290000000001],[1.05,8477.8700000000008],[1.1499999999999999,10],[1.2,21],[1.25,130],[1.3,10],[1.3500000000000001,10],[1.52,63.979999999999997],[1.75,11.630000000000001],[2.1000000000000001,7.9299999999999997],[2.3999999999999999,8.9900000000000002],[1.3200000000000001,59.219999999999999],[1.71,28.550000000000001],[1.8300000000000001,34.899999999999999],[2.2200000000000002,59.219999999999999],[1.0700000000000001,2999.6500000000001],[1.0600000000000001,4498.6800000000003],[1.0800000000000001,2999.6500000000001],[1.0900000000000001,2999.6500000000001]],"spl":null,"spn":null,"atl":[[1000,1.0700000000000001],[9.1999999999999993,0.94999999999999996],[8.8000000000000007,2.8900000000000001],[9.8000000000000007,85.510000000000005],[9.4000000000000004,208.13999999999999],[10,558.03999999999996],[9.5999999999999996,1.01],[11,103.47],[10.5,145.36000000000001],[13.5,5.5999999999999996],[12.5,6.0800000000000001],[11.5,59.530000000000001],[100,2.5299999999999998],[30,0.56999999999999995],[55,0.28999999999999998],[50,67.5],[60,10.57],[34,10.57],[180,1],[150,1],[20,1.0600000000000001],[75,1],[40,1]],"batl":null,"id":16570658,"hc":null,"bdatb":null},{"tv":1814333.47,"batb":null,"spb":null,"bdatl":null,"trd":[[1.1299999999999999,151827.81],[1.1399999999999999,132988.57000000001],[1.1200000000000001,5656.2299999999996],[1.1499999999999999,11637.32],[1.1599999999999999,3525.6199999999999],[1.1699999999999999,36180.339999999997],[1.1799999999999999,46182.110000000001],[1.19,10436.32],[1.2,42764.610000000001],[1.21,229366.76000000001],[1.22,236468.92999999999],[1.23,312970.45000000001],[1.24,101828.94],[1.25,206182.45999999999],[1.26,28136.310000000001],[1.27,63542.400000000001],[1.28,130279.96000000001],[1.29,48226.879999999997],[1.3,14804.200000000001],[1.3100000000000001,1248.97],[1.3200000000000001,78.280000000000001]],"spf":null,"ltp":1.1299999999999999,"atb":[[1.03,88900.990000000005],[1.1200000000000001,46104.82],[1.1100000000000001,50345.07],[1.0800000000000001,38937.550000000003],[1.1000000000000001,43001.339999999997],[1.0900000000000001,39618.040000000001],[1.05,75629.529999999999],[1.02,90673.919999999998],[1.0600000000000001,63264.940000000002],[1.0700000000000001,39091.82],[1.04,73780.729999999996],[1.01,93203.490000000005]],"spl":null,"spn":null,"atl":[[1.1499999999999999,10870.799999999999],[1.1299999999999999,27254.389999999999],[1.1699999999999999,9574.9899999999998],[1.19,8875.6399999999994],[1.1599999999999999,10133.76],[1.1799999999999999,9058.9400000000005],[1.1399999999999999,25434.209999999999],[1000,0.88],[1.21,8960.3500000000004],[1.26,2252.5100000000002],[1.22,8862.3500000000004],[1.23,9345.6700000000001],[1.2,8901.0499999999993],[1.24,1212.4200000000001],[1.25,1014.76],[1.29,473.61000000000001],[1.3,1909.6800000000001],[1.3200000000000001,80.640000000000001],[1.27,10],[1.28,20.289999999999999],[1.3999999999999999,1089.6400000000001],[1.4099999999999999,17.280000000000001],[1.3100000000000001,61.509999999999998],[1.3799999999999999,561.15999999999997],[100,2],[1.44,35.719999999999999],[1.3500000000000001,150.83000000000001],[1.3400000000000001,28.809999999999999],[1.3300000000000001,18.640000000000001],[1.3700000000000001,1552.6300000000001],[1.3600000000000001,17.289999999999999],[1.3899999999999999,8.6400000000000006],[2.2000000000000002,5.2699999999999996],[1.8,3.5099999999999998],[1.5,129.47999999999999],[1.6699999999999999,20],[2,16.91],[1.53,7.9299999999999997],[1.8200000000000001,210.53999999999999],[1.45,1.3200000000000001],[1.8799999999999999,1],[50,66.439999999999998],[1.4199999999999999,0.93999999999999995],[1.6000000000000001,0.83999999999999997],[7,5.29],[1.6499999999999999,4.3200000000000003],[2.96,2.0600000000000001],[2.6000000000000001,0.029999999999999999],[21,10.57],[6,15.859999999999999],[1.7,1018],[1.49,2.23],[1.6200000000000001,77.739999999999995],[4.7999999999999998,20.239999999999998],[2.2200000000000002,9],[2.98,105.75],[2.04,12.109999999999999],[1.6100000000000001,33.119999999999997],[2.1400000000000001,10],[1.94,10],[1.8400000000000001,10],[1.74,10],[1.5600000000000001,2.46],[75,1],[40,1]],"batl":null,"id":19924823,"hc":null,"bdatb":null}],"img":true,"tv":2052643.79,"con":null,"marketdefinition":null,"id":"1.258926623"}],"conflatems":0,"op":"mcm","id":3}
{"ct":null,"SegmentType":null,"clk":"AAQAAwAD","heartbeatms":null,"pt":1780839550423,"initialclk":null,"mc":[{"rc":[{"tv":null,"batb":null,"spb":null,"bdatl":null,"trd":null,"spf":null,"ltp":null,"atb":[[7.5999999999999996,21.09]],"spl":null,"spn":null,"atl":[[1000,0.87]],"batl":null,"id":16570658,"hc":null,"bdatb":null}],"img":null,"tv":null,"con":null,"marketdefinition":null,"id":"1.258926623"}],"conflatems":null,"op":"mcm","id":3}
{"ct":null,"SegmentType":null,"clk":"ABYAIgAS","heartbeatms":null,"pt":1780839550633,"initialclk":null,"mc":[{"rc":[{"tv":null,"batb":null,"spb":null,"bdatl":null,"trd":null,"spf":null,"ltp":null,"atb":[[1.1100000000000001,50688.5]],"spl":null,"spn":null,"atl":[[1.1299999999999999,27652.650000000001],[1.1399999999999999,26834.299999999999]],"batl":null,"id":19924823,"hc":null,"bdatb":null}],"img":null,"tv":null,"con":null,"marketdefinition":null,"id":"1.258926623"}],"conflatems":null,"op":"mcm","id":3}
{"ct":null,"SegmentType":null,"clk":"AB4AKgAb","heartbeatms":null,"pt":1780839550733,"initialclk":null,"mc":[{"rc":[{"tv":null,"batb":null,"spb":null,"bdatl":null,"trd":null,"spf":null,"ltp":null,"atb":[[1.1200000000000001,45764.449999999997]],"spl":null,"spn":null,"atl":[[1.1599999999999999,8926.1000000000004],[1.1499999999999999,10287]],"batl":null,"id":19924823,"hc":null,"bdatb":null}],"img":null,"tv":null,"con":null,"marketdefinition":null,"id":"1.258926623"}],"conflatems":null,"op":"mcm","id":3}
{"ct":null,"SegmentType":null,"clk":"ACQANQAh","heartbeatms":null,"pt":1780839550840,"initialclk":null,"mc":[{"rc":[{"tv":null,"batb":null,"spb":null,"bdatl":null,"trd":null,"spf":null,"ltp":null,"atb":[[8,1222.2000000000001]],"spl":null,"spn":null,"atl":[[10.5,288.20999999999998]],"batl":null,"id":16570658,"hc":null,"bdatb":null},{"tv":null,"batb":null,"spb":null,"bdatl":null,"trd":null,"spf":null,"ltp":null,"atb":[[1.1100000000000001,52039.849999999999]],"spl":null,"spn":null,"atl":[[1.1399999999999999,27937.52]],"batl":null,"id":19924823,"hc":null,"bdatb":null}],"img":null,"tv":null,"con":null,"marketdefinition":null,"id":"1.258926623"}],"conflatems":null,"op":"mcm","id":3}
{"ct":null,"SegmentType":null,"clk":"AC8AQwAq","heartbeatms":null,"pt":1780839550945,"initialclk":null,"mc":[{"rc":[{"tv":238310.89999999999,"batb":null,"spb":null,"bdatl":null,"trd":[[8.5999999999999996,1192.77]],"spf":null,"ltp":null,"atb":[[8.5999999999999996,370.38999999999999]],"spl":null,"spn":null,"atl":null,"batl":null,"id":16570658,"hc":null,"bdatb":null},{"tv":null,"batb":null,"spb":null,"bdatl":null,"trd":null,"spf":null,"ltp":null,"atb":[[1.1200000000000001,42030.330000000002]],"spl":null,"spn":null,"atl":null,"batl":null,"id":19924823,"hc":null,"bdatb":null}],"img":null,"tv":2052644.3700000001,"con":null,"marketdefinition":null,"id":"1.258926623"}],"conflatems":null,"op":"mcm","id":3}
{"ct":null,"SegmentType":null,"clk":"AFAAYwBG","heartbeatms":null,"pt":1780839551206,"initialclk":null,"mc":[{"rc":[{"tv":null,"batb":null,"spb":null,"bdatl":null,"trd":null,"spf":null,"ltp":null,"atb":[[8,1022.2000000000001]],"spl":null,"spn":null,"atl":null,"batl":null,"id":16570658,"hc":null,"bdatb":null},{"tv":null,"batb":null,"spb":null,"bdatl":null,"trd":null,"spf":null,"ltp":null,"atb":null,"spl":null,"spn":null,"atl":[[1.1299999999999999,27660.150000000001]],"batl":null,"id":19924823,"hc":null,"bdatb":null}],"img":null,"tv":null,"con":null,"marketdefinition":null,"id":"1.258926623"}],"conflatems":null,"op":"mcm","id":3}
{"ct":null,"SegmentType":null,"clk":"AFoAbABP","heartbeatms":null,"pt":1780839551312,"initialclk":null,"mc":[{"rc":[{"tv":null,"batb":null,"spb":null,"bdatl":null,"trd":null,"spf":null,"ltp":null,"atb":[[8.5999999999999996,570.38999999999999]],"spl":null,"spn":null,"atl":null,"batl":null,"id":16570658,"hc":null,"bdatb":null},{"tv":1814359.3700000001,"batb":null,"spb":null,"bdatl":null,"trd":[[1.1299999999999999,151853.70999999999]],"spf":null,"ltp":null,"atb":null,"spl":null,"spn":null,"atl":[[1.1299999999999999,27647.200000000001]],"batl":null,"id":19924823,"hc":null,"bdatb":null}],"img":null,"tv":2052670.27,"con":null,"marketdefinition":null,"id":"1.258926623"}],"conflatems":null,"op":"mcm","id":3}
{"ct":null,"SegmentType":null,"clk":"AF8AdQBX","heartbeatms":null,"pt":1780839551406,"initialclk":null,"mc":[{"rc":[{"tv":null,"batb":null,"spb":null,"bdatl":null,"trd":null,"spf":null,"ltp":null,"atb":[[7.2000000000000002,0]],"spl":null,"spn":null,"atl":null,"batl":null,"id":16570658,"hc":null,"bdatb":null},{"tv":null,"batb":null,"spb":null,"bdatl":null,"trd":null,"spf":null,"ltp":null,"atb":null,"spl":null,"spn":null,"atl":[[1.1299999999999999,28510.119999999999],[1.1799999999999999,8858.9400000000005]],"batl":null,"id":19924823,"hc":null,"bdatb":null}],"img":null,"tv":null,"con":null,"marketdefinition":null,"id":"1.258926623"}],"conflatems":null,"op":"mcm","id":3}
{"ct":null,"SegmentType":null,"clk":"AGgAfwBh","heartbeatms":null,"pt":1780839551512,"initialclk":null,"mc":[{"rc":[{"tv":238335.67000000001,"batb":null,"spb":null,"bdatl":null,"trd":[[8.5999999999999996,1217.54]],"spf":null,"ltp":null,"atb":[[8.1999999999999993,267.68000000000001],[8.5999999999999996,558]],"spl":null,"spn":null,"atl":null,"batl":null,"id":16570658,"hc":null,"bdatb":null},{"tv":null,"batb":null,"spb":null,"bdatl":null,"trd":null,"spf":null,"ltp":null,"atb":null,"spl":null,"spn":null,"atl":[[1.1399999999999999,28137.52]],"batl":null,"id":19924823,"hc":null,"bdatb":null}],"img":null,"tv":2052695.04,"con":null,"marketdefinition":null,"id":"1.258926623"}],"conflatems":null,"op":"mcm","id":3}
{"ct":null,"SegmentType":null,"clk":"AhcAjwEAbw==","heartbeatms":null,"pt":1780839551718,"initialclk":null,"mc":[{"rc":[{"tv":null,"batb":null,"spb":null,"bdatl":null,"trd":null,"spf":null,"ltp":null,"atb":[[8.5999999999999996,671.64999999999998]],"spl":null,"spn":null,"atl":[[9.1999999999999993,13.949999999999999]],"batl":null,"id":16570658,"hc":null,"bdatb":null},{"tv":null,"batb":null,"spb":null,"bdatl":null,"trd":null,"spf":null,"ltp":null,"atb":null,"spl":null,"spn":null,"atl":[[1.1399999999999999,22786.52]],"batl":null,"id":19924823,"hc":null,"bdatb":null}],"img":null,"tv":null,"con":null,"marketdefinition":null,"id":"1.258926623"}],"conflatems":null,"op":"mcm","id":3}
{"ct":null,"SegmentType":null,"clk":"AIUBAJ4BAHU=","heartbeatms":null,"pt":1780839551825,"initialclk":null,"mc":[{"rc":[{"tv":null,"batb":null,"spb":null,"bdatl":null,"trd":null,"spf":null,"ltp":null,"atb":[[8.1999999999999993,257.95999999999998]],"spl":null,"spn":null,"atl":null,"batl":null,"id":16570658,"hc":null,"bdatb":null}],"img":null,"tv":null,"con":null,"marketdefinition":null,"id":"1.258926623"}],"conflatems":null,"op":"mcm","id":3}
{"ct":null,"SegmentType":null,"clk":"AI8BAKQBAHk=","heartbeatms":null,"pt":1780839551929,"initialclk":null,"mc":[{"rc":[{"tv":null,"batb":null,"spb":null,"bdatl":null,"trd":null,"spf":null,"ltp":null,"atb":[[8.5999999999999996,785.30999999999995]],"spl":null,"spn":null,"atl":null,"batl":null,"id":16570658,"hc":null,"bdatb":null},{"tv":1814363.3899999999,"batb":null,"spb":null,"bdatl":null,"trd":[[1.1299999999999999,151857.73000000001]],"spf":null,"ltp":null,"atb":null,"spl":null,"spn":null,"atl":[[1.1299999999999999,28508.110000000001],[1.1399999999999999,21683.299999999999]],"batl":null,"id":19924823,"hc":null,"bdatb":null}],"img":null,"tv":2052699.0600000001,"con":null,"marketdefinition":null,"id":"1.258926623"}],"conflatems":null,"op":"mcm","id":3}
{"ct":null,"SegmentType":null,"clk":"AJoBAK8BAIAB","heartbeatms":null,"pt":1780839552031,"initialclk":null,"mc":[{"rc":[{"tv":null,"batb":null,"spb":null,"bdatl":null,"trd":null,"spf":null,"ltp":null,"atb":null,"spl":null,"spn":null,"atl":[[1.1299999999999999,28758.110000000001]],"batl":null,"id":19924823,"hc":null,"bdatb":null}],"img":null,"tv":null,"con":null,"marketdefinition":null,"id":"1.258926623"}],"conflatems":null,"op":"mcm","id":3}
{"ct":null,"SegmentType":null,"clk":"AKYBALgBAIkB","heartbeatms":null,"pt":1780839552133,"initialclk":null,"mc":[{"rc":[{"tv":null,"batb":null,"spb":null,"bdatl":null,"trd":null,"spf":null,"ltp":null,"atb":[[8.5999999999999996,898.97000000000003]],"spl":null,"spn":null,"atl":null,"batl":null,"id":16570658,"hc":null,"bdatb":null}],"img":null,"tv":null,"con":null,"marketdefinition":null,"id":"1.258926623"}],"conflatems":null,"op":"mcm","id":3}
{"ct":null,"SegmentType":null,"clk":"AK0BAMQBAJEB","heartbeatms":null,"pt":1780839552235,"initialclk":null,"mc":[{"rc":[{"tv":null,"batb":null,"spb":null,"bdatl":null,"trd":null,"spf":null,"ltp":null,"atb":null,"spl":null,"spn":null,"atl":[[1.1299999999999999,29008.110000000001]],"batl":null,"id":19924823,"hc":null,"bdatb":null}],"img":null,"tv":null,"con":null,"marketdefinition":null,"id":"1.258926623"}],"conflatems":null,"op":"mcm","id":3}
{"ct":null,"SegmentType":null,"clk":"AOIBAO4BAL0B","heartbeatms":null,"pt":1780839552807,"initialclk":null,"mc":[{"rc":[{"tv":238341.45000000001,"batb":null,"spb":null,"bdatl":null,"trd":[[8.8000000000000007,1095.25]],"spf":null,"ltp":8.8000000000000007,"atb":[[8.8000000000000007,139.16]],"spl":null,"spn":null,"atl":[[8.8000000000000007,0]],"batl":null,"id":16570658,"hc":null,"bdatb":null}],"img":null,"tv":2052704.8400000001,"con":null,"marketdefinition":null,"id":"1.258926623"}],"conflatems":null,"op":"mcm","id":3}
{"ct":null,"SegmentType":null,"clk":"APIBAIECANEB","heartbeatms":null,"pt":1780839553009,"initialclk":null,"mc":[{"rc":[{"tv":null,"batb":null,"spb":null,"bdatl":null,"trd":null,"spf":null,"ltp":null,"atb":[[8.8000000000000007,113.64],[8.1999999999999993,257.00999999999999],[8.5999999999999996,853.17999999999995]],"spl":null,"spn":null,"atl":null,"batl":null,"id":16570658,"hc":null,"bdatb":null}],"img":null,"tv":null,"con":null,"marketdefinition":null,"id":"1.258926623"}],"conflatems":null,"op":"mcm","id":3}
{"ct":null,"SegmentType":null,"clk":"AKICALoCAIUC","heartbeatms":null,"pt":1780839553524,"initialclk":null,"mc":[{"rc":[{"tv":238341.85000000001,"batb":null,"spb":null,"bdatl":null,"trd":[[8.8000000000000007,1095.6500000000001]],"spf":null,"ltp":null,"atb":[[8.8000000000000007,113.44]],"spl":null,"spn":null,"atl":null,"batl":null,"id":16570658,"hc":null,"bdatb":null}],"img":null,"tv":2052705.24,"con":null,"marketdefinition":null,"id":"1.258926623"}],"conflatems":null,"op":"mcm","id":3}
{"ct":null,"SegmentType":null,"clk":"AK4CAMUCAJAC","heartbeatms":null,"pt":1780839553631,"initialclk":null,"mc":[{"rc":[{"tv":null,"batb":null,"spb":null,"bdatl":null,"trd":null,"spf":null,"ltp":null,"atb":[[1.1000000000000001,6769.2200000000003]],"spl":null,"spn":null,"atl":null,"batl":null,"id":16570658,"hc":null,"bdatb":null}],"img":null,"tv":null,"con":null,"marketdefinition":null,"id":"1.258926623"}],"conflatems":null,"op":"mcm","id":3}
{"ct":null,"SegmentType":null,"clk":"AMMCANkCAKQC","heartbeatms":null,"pt":1780839553839,"initialclk":null,"mc":[{"rc":[{"tv":null,"batb":null,"spb":null,"bdatl":null,"trd":null,"spf":null,"ltp":null,"atb":[[1.1000000000000001,6768.4200000000001]],"spl":null,"spn":null,"atl":[[9.1999999999999993,153.91999999999999]],"batl":null,"id":16570658,"hc":null,"bdatb":null},{"tv":null,"batb":null,"spb":null,"bdatl":null,"trd":null,"spf":null,"ltp":null,"atb":[[1.1200000000000001,43180.110000000001]],"spl":null,"spn":null,"atl":[[1.1299999999999999,29469.900000000001]],"batl":null,"id":19924823,"hc":null,"bdatb":null}],"img":null,"tv":null,"con":null,"marketdefinition":null,"id":"1.258926623"}],"conflatems":null,"op":"mcm","id":3}
{"ct":null,"SegmentType":null,"clk":"AMoCAOcCAKoC","heartbeatms":null,"pt":1780839553936,"initialclk":null,"mc":[{"rc":[{"tv":null,"batb":null,"spb":null,"bdatl":null,"trd":null,"spf":null,"ltp":null,"atb":null,"spl":null,"spn":null,"atl":[[9,7.29]],"batl":null,"id":16570658,"hc":null,"bdatb":null}],"img":null,"tv":null,"con":null,"marketdefinition":null,"id":"1.258926623"}],"conflatems":null,"op":"mcm","id":3}
{"ct":null,"SegmentType":null,"clk":"ANYCAO8CALQC","heartbeatms":null,"pt":1780839554041,"initialclk":null,"mc":[{"rc":[{"tv":null,"batb":null,"spb":null,"bdatl":null,"trd":null,"spf":null,"ltp":null,"atb":[[1.1000000000000001,6768.2200000000003]],"spl":null,"spn":null,"atl":null,"batl":null,"id":16570658,"hc":null,"bdatb":null}],"img":null,"tv":null,"con":null,"marketdefinition":null,"id":"1.258926623"}],"conflatems":null,"op":"mcm","id":3}
{"ct":null,"SegmentType":null,"clk":"AOACAP0CALsC","heartbeatms":null,"pt":1780839554142,"initialclk":null,"mc":[{"rc":[{"tv":null,"batb":null,"spb":null,"bdatl":null,"trd":null,"spf":null,"ltp":null,"atb":[[6.7999999999999998,114.81],[8,865]],"spl":null,"spn":null,"atl":[[13.5,0]],"batl":null,"id":16570658,"hc":null,"bdatb":null}],"img":null,"tv":null,"con":null,"marketdefinition":null,"id":"1.258926623"}],"conflatems":null,"op":"mcm","id":3}
{"ct":null,"SegmentType":null,"clk":"AOgCAIUDAMMC","heartbeatms":null,"pt":1780839554244,"initialclk":null,"mc":[{"rc":[{"tv":null,"batb":null,"spb":null,"bdatl":null,"trd":null,"spf":null,"ltp":null,"atb":[[8.1999999999999993,266.73000000000002]],"spl":null,"spn":null,"atl":[[9.1999999999999993,162.44]],"batl":null,"id":16570658,"hc":null,"bdatb":null}],"img":null,"tv":null,"con":null,"marketdefinition":null,"id":"1.258926623"}],"conflatems":null,"op":"mcm","id":3}
{"ct":null,"SegmentType":null,"clk":"APYCAI4DAMkC","heartbeatms":null,"pt":1780839554305,"initialclk":null,"mc":[{"rc":[{"tv":null,"batb":null,"spb":null,"bdatl":null,"trd":null,"spf":null,"ltp":null,"atb":[[1.1000000000000001,44001.339999999997]],"spl":null,"spn":null,"atl":null,"batl":null,"id":19924823,"hc":null,"bdatb":null}],"img":null,"tv":null,"con":null,"marketdefinition":null,"id":"1.258926623"}],"conflatems":null,"op":"mcm","id":3}
{"ct":null,"SegmentType":null,"clk":"AIIDAJQDANEC","heartbeatms":null,"pt":1780839554409,"initialclk":null,"mc":[{"rc":[{"tv":null,"batb":null,"spb":null,"bdatl":null,"trd":null,"spf":null,"ltp":null,"atb":[[8.4000000000000004,388.42000000000002]],"spl":null,"spn":null,"atl":[[10.5,402.20999999999998]],"batl":null,"id":16570658,"hc":null,"bdatb":null},{"tv":null,"batb":null,"spb":null,"bdatl":null,"trd":null,"spf":null,"ltp":null,"atb":[[1.1000000000000001,46192.339999999997]],"spl":null,"spn":null,"atl":[[1.1399999999999999,23518.299999999999]],"batl":null,"id":19924823,"hc":null,"bdatb":null}],"img":null,"tv":null,"con":null,"marketdefinition":null,"id":"1.258926623"}],"conflatems":null,"op":"mcm","id":3}
{"ct":null,"SegmentType":null,"clk":"AJQDAKUDAOMC","heartbeatms":null,"pt":1780839554609,"initialclk":null,"mc":[{"rc":[{"tv":238353.64999999999,"batb":null,"spb":null,"bdatl":null,"trd":[[8.8000000000000007,1107.4500000000001]],"spf":null,"ltp":null,"atb":[[8.8000000000000007,107.54000000000001]],"spl":null,"spn":null,"atl":null,"batl":null,"id":16570658,"hc":null,"bdatb":null}],"img":null,"tv":2052717.04,"con":null,"marketdefinition":null,"id":"1.258926623"}],"conflatems":null,"op":"mcm","id":3}
{"ct":null,"SegmentType":null,"clk":"AKYDALsDAPYC","heartbeatms":null,"pt":1780839554822,"initialclk":null,"mc":[{"rc":[{"tv":null,"batb":null,"spb":null,"bdatl":null,"trd":null,"spf":null,"ltp":null,"atb":null,"spl":null,"spn":null,"atl":[[1.1399999999999999,23520.299999999999]],"batl":null,"id":19924823,"hc":null,"bdatb":null}],"img":null,"tv":null,"con":null,"marketdefinition":null,"id":"1.258926623"}],"conflatems":null,"op":"mcm","id":3}
{"ct":null,"SegmentType":null,"clk":"AK8DAMIDAP4C","heartbeatms":null,"pt":1780839554917,"initialclk":null,"mc":[{"rc":[{"tv":238353.69,"batb":null,"spb":null,"bdatl":null,"trd":[[8.8000000000000007,1107.49]],"spf":null,"ltp":null,"atb":[[8.8000000000000007,107.52]],"spl":null,"spn":null,"atl":null,"batl":null,"id":16570658,"hc":null,"bdatb":null}],"img":null,"tv":2052717.0800000001,"con":null,"marketdefinition":null,"id":"1.258926623"}],"conflatems":null,"op":"mcm","id":3}
{"ct":null,"SegmentType":null,"clk":"ALoDANQDAI4D","heartbeatms":null,"pt":1780839555023,"initialclk":null,"mc":[{"rc":[{"tv":null,"batb":null,"spb":null,"bdatl":null,"trd":null,"spf":null,"ltp":null,"atb":null,"spl":null,"spn":null,"atl":[[1.1399999999999999,23518.299999999999]],"batl":null,"id":19924823,"hc":null,"bdatb":null}],"img":null,"tv":null,"con":null,"marketdefinition":null,"id":"1.258926623"}],"conflatems":null,"op":"mcm","id":3}
{"ct":null,"SegmentType":null,"clk":"AMIDANkDAJcD","heartbeatms":null,"pt":1780839555121,"initialclk":null,"mc":[{"rc":[{"tv":null,"batb":null,"spb":null,"bdatl":null,"trd":null,"spf":null,"ltp":null,"atb":[[1.1100000000000001,52047.339999999997]],"spl":null,"spn":null,"atl":null,"batl":null,"id":19924823,"hc":null,"bdatb":null}],"img":null,"tv":null,"con":null,"marketdefinition":null,"id":"1.258926623"}],"conflatems":null,"op":"mcm","id":3}
{"ct":null,"SegmentType":null,"clk":"AM0DAOADAKED","heartbeatms":null,"pt":1780839555228,"initialclk":null,"mc":[{"rc":[{"tv":null,"batb":null,"spb":null,"bdatl":null,"trd":null,"spf":null,"ltp":null,"atb":null,"spl":null,"spn":null,"atl":[[1000,1.0700000000000001]],"batl":null,"id":16570658,"hc":null,"bdatb":null}],"img":null,"tv":null,"con":null,"marketdefinition":null,"id":"1.258926623"}],"conflatems":null,"op":"mcm","id":3}
{"ct":null,"SegmentType":null,"clk":"ANwDAPcDALAD","heartbeatms":null,"pt":1780839555434,"initialclk":null,"mc":[{"rc":[{"tv":null,"batb":null,"spb":null,"bdatl":null,"trd":null,"spf":null,"ltp":null,"atb":null,"spl":null,"spn":null,"atl":[[1000,0.87]],"batl":null,"id":16570658,"hc":null,"bdatb":null}],"img":null,"tv":null,"con":null,"marketdefinition":null,"id":"1.258926623"}],"conflatems":null,"op":"mcm","id":3}
{"ct":null,"SegmentType":null,"clk":"AOIDAIIEALcD","heartbeatms":null,"pt":1780839555540,"initialclk":null,"mc":[{"rc":[{"tv":1814377.8899999999,"batb":null,"spb":null,"bdatl":null,"trd":[[1.1299999999999999,151872.23000000001]],"spf":null,"ltp":null,"atb":null,"spl":null,"spn":null,"atl":[[1.1299999999999999,29462.650000000001]],"batl":null,"id":19924823,"hc":null,"bdatb":null}],"img":null,"tv":2052731.5800000001,"con":null,"marketdefinition":null,"id":"1.258926623"}],"conflatems":null,"op":"mcm","id":3}
{"ct":null,"SegmentType":null,"clk":"AK4EANcEAPsD","heartbeatms":null,"pt":1780839556419,"initialclk":null,"mc":[{"rc":[{"tv":1814380,"batb":null,"spb":null,"bdatl":null,"trd":[[1.1200000000000001,5658.3400000000001]],"spf":null,"ltp":1.1200000000000001,"atb":[[1.1200000000000001,43179.050000000003]],"spl":null,"spn":null,"atl":null,"batl":null,"id":19924823,"hc":null,"bdatb":null}],"img":null,"tv":2052733.6899999999,"con":null,"marketdefinition":null,"id":"1.258926623"}],"conflatems":null,"op":"mcm","id":3}
{"ct":null,"SegmentType":null,"clk":"AMQEAOoEAIgE","heartbeatms":null,"pt":1780839556619,"initialclk":null,"mc":[{"rc":[{"tv":1814380.8200000001,"batb":null,"spb":null,"bdatl":null,"trd":[[1.1299999999999999,151873.04999999999]],"spf":null,"ltp":1.1299999999999999,"atb":null,"spl":null,"spn":null,"atl":[[1.1299999999999999,29462.240000000002]],"batl":null,"id":19924823,"hc":null,"bdatb":null}],"img":null,"tv":2052734.51,"con":null,"marketdefinition":null,"id":"1.258926623"}],"conflatems":null,"op":"mcm","id":3}
{"ct":null,"SegmentType":null,"clk":"APQEAJYFAKoE","heartbeatms":null,"pt":1780839557136,"initialclk":null,"mc":[{"rc":[{"tv":null,"batb":null,"spb":null,"bdatl":null,"trd":null,"spf":null,"ltp":null,"atb":[[8.8000000000000007,193.03]],"spl":null,"spn":null,"atl":null,"batl":null,"id":16570658,"hc":null,"bdatb":null}],"img":null,"tv":null,"con":null,"marketdefinition":null,"id":"1.258926623"}],"conflatems":null,"op":"mcm","id":3}
{"ct":null,"SegmentType":null,"clk":"AIcFALAFALoE","heartbeatms":null,"pt":1780839557346,"initialclk":null,"mc":[{"rc":[{"tv":null,"batb":null,"spb":null,"bdatl":null,"trd":null,"spf":null,"ltp":null,"atb":[[7,368.38],[7.5999999999999996,21.949999999999999],[7.2000000000000002,0.85999999999999999]],"spl":null,"spn":null,"atl":[[11,104.45999999999999],[10.5,403.07999999999998]],"batl":null,"id":16570658,"hc":null,"bdatb":null},{"tv":null,"batb":null,"spb":null,"bdatl":null,"trd":null,"spf":null,"ltp":null,"atb":[[1.1000000000000001,46198.360000000001],[1.1100000000000001,52053.089999999997]],"spl":null,"spn":null,"atl":[[1.1699999999999999,9580.6599999999999],[1.1599999999999999,8929.8600000000006],[1.1499999999999999,10290.879999999999]],"batl":null,"id":19924823,"hc":null,"bdatb":null}],"img":null,"tv":null,"con":null,"marketdefinition":null,"id":"1.258926623"}],"conflatems":null,"op":"mcm","id":3}
{"ct":null,"SegmentType":null,"clk":"ALMFANkFAOAE","heartbeatms":null,"pt":1780839557809,"initialclk":null,"mc":[{"rc":[{"tv":null,"batb":null,"spb":null,"bdatl":null,"trd":null,"spf":null,"ltp":null,"atb":null,"spl":null,"spn":null,"atl":[[9.4000000000000004,209.13999999999999],[13.5,5.5999999999999996],[13,5.8300000000000001]],"batl":null,"id":16570658,"hc":null,"bdatb":null},{"tv":1814460.8200000001,"batb":null,"spb":null,"bdatl":null,"trd":[[1.1200000000000001,5738.3400000000001]],"spf":null,"ltp":1.1200000000000001,"atb":[[1.1200000000000001,43139.050000000003]],"spl":null,"spn":null,"atl":[[1.21,9148.8299999999999],[1.2,9101.0499999999993]],"batl":null,"id":19924823,"hc":null,"bdatb":null}],"img":null,"tv":2052814.51,"con":null,"marketdefinition":null,"id":"1.258926623"}],"conflatems":null,"op":"mcm","id":3}
{"ct":null,"SegmentType":null,"clk":"AL4FAOUFAOgE","heartbeatms":null,"pt":1780839557912,"initialclk":null,"mc":[{"rc":[{"tv":null,"batb":null,"spb":null,"bdatl":null,"trd":null,"spf":null,"ltp":null,"atb":[[8.8000000000000007,193.09]],"spl":null,"spn":null,"atl":null,"batl":null,"id":16570658,"hc":null,"bdatb":null}],"img":null,"tv":null,"con":null,"marketdefinition":null,"id":"1.258926623"}],"conflatems":null,"op":"mcm","id":3}
{"ct":null,"SegmentType":null,"clk":"APsFAJ8GAJAF","heartbeatms":null,"pt":1780839558535,"initialclk":null,"mc":[{"rc":[{"tv":238354.09,"batb":null,"spb":null,"bdatl":null,"trd":[[8.8000000000000007,1107.8900000000001]],"spf":null,"ltp":null,"atb":[[8.8000000000000007,192.88999999999999]],"spl":null,"spn":null,"atl":null,"batl":null,"id":16570658,"hc":null,"bdatb":null}],"img":null,"tv":2052814.9099999999,"con":null,"marketdefinition":null,"id":"1.258926623"}],"conflatems":null,"op":"mcm","id":3}
{"ct":null,"SegmentType":null,"clk":"AIIGAKYGAJcF","heartbeatms":null,"pt":1780839558633,"initialclk":null,"mc":[{"rc":[{"tv":null,"batb":null,"spb":null,"bdatl":null,"trd":null,"spf":null,"ltp":null,"atb":null,"spl":null,"spn":null,"atl":[[12.5,0]],"batl":null,"id":16570658,"hc":null,"bdatb":null},{"tv":null,"batb":null,"spb":null,"bdatl":null,"trd":null,"spf":null,"ltp":null,"atb":null,"spl":null,"spn":null,"atl":[[1.1699999999999999,9380.6599999999999]],"batl":null,"id":19924823,"hc":null,"bdatb":null}],"img":null,"tv":null,"con":null,"marketdefinition":null,"id":"1.258926623"}],"conflatems":null,"op":"mcm","id":3}
{"ct":null,"SegmentType":null,"clk":"AI4GALMGAKAF","heartbeatms":null,"pt":1780839558738,"initialclk":null,"mc":[{"rc":[{"tv":null,"batb":null,"spb":null,"bdatl":null,"trd":null,"spf":null,"ltp":null,"atb":[[1.1000000000000001,6769.2200000000003]],"spl":null,"spn":null,"atl":null,"batl":null,"id":16570658,"hc":null,"bdatb":null}],"img":null,"tv":null,"con":null,"marketdefinition":null,"id":"1.258926623"}],"conflatems":null,"op":"mcm","id":3}
{"ct":null,"SegmentType":null,"clk":"AKkGAMQGALIF","heartbeatms":null,"pt":1780839558959,"initialclk":null,"mc":[{"rc":[{"tv":null,"batb":null,"spb":null,"bdatl":null,"trd":null,"spf":null,"ltp":null,"atb":[[1.1000000000000001,6768.4200000000001]],"spl":null,"spn":null,"atl":null,"batl":null,"id":16570658,"hc":null,"bdatb":null}],"img":null,"tv":null,"con":null,"marketdefinition":null,"id":"1.258926623"}],"conflatems":null,"op":"mcm","id":3}
{"ct":null,"SegmentType":null,"clk":"AK4GAM4GALsF","heartbeatms":null,"pt":1780839559053,"initialclk":null,"mc":[{"rc":[{"tv":null,"batb":null,"spb":null,"bdatl":null,"trd":null,"spf":null,"ltp":null,"atb":[[7.7999999999999998,157.80000000000001]],"spl":null,"spn":null,"atl":[[9.5999999999999996,157.25999999999999]],"batl":null,"id":16570658,"hc":null,"bdatb":null},{"tv":null,"batb":null,"spb":null,"bdatl":null,"trd":null,"spf":null,"ltp":null,"atb":null,"spl":null,"spn":null,"atl":[[1.1499999999999999,11354.51]],"batl":null,"id":19924823,"hc":null,"bdatb":null}],"img":null,"tv":null,"con":null,"marketdefinition":null,"id":"1.258926623"}],"conflatems":null,"op":"mcm","id":3}
{"ct":null,"SegmentType":null,"clk":"ALgGANgGAMMF","heartbeatms":null,"pt":1780839559111,"initialclk":null,"mc":[{"rc":[{"tv":null,"batb":null,"spb":null,"bdatl":null,"trd":null,"spf":null,"ltp":null,"atb":[[1.1000000000000001,6768.2200000000003]],"spl":null,"spn":null,"atl":null,"batl":null,"id":16570658,"hc":null,"bdatb":null}],"img":null,"tv":null,"con":null,"marketdefinition":null,"id":"1.258926623"}],"conflatems":null,"op":"mcm","id":3}
{"ct":null,"SegmentType":null,"clk":"AMUGAOIGAMsF","heartbeatms":null,"pt":1780839559213,"initialclk":null,"mc":[{"rc":[{"tv":null,"batb":null,"spb":null,"bdatl":null,"trd":null,"spf":null,"ltp":null,"atb":[[6.7999999999999998,115.01000000000001]],"spl":null,"spn":null,"atl":null,"batl":null,"id":16570658,"hc":null,"bdatb":null}],"img":null,"tv":null,"con":null,"marketdefinition":null,"id":"1.258926623"}],"conflatems":null,"op":"mcm","id":3}
{"ct":null,"SegmentType":null,"clk":"AMwGAOwGANQF","heartbeatms":null,"pt":1780839559316,"initialclk":null,"mc":[{"rc":[{"tv":null,"batb":null,"spb":null,"bdatl":null,"trd":null,"spf":null,"ltp":null,"atb":null,"spl":null,"spn":null,"atl":[[10.5,260.23000000000002]],"batl":null,"id":16570658,"hc":null,"bdatb":null}],"img":null,"tv":null,"con":null,"marketdefinition":null,"id":"1.258926623"}],"conflatems":null,"op":"mcm","id":3}
{"ct":null,"SegmentType":null,"clk":"ANIHAKgHAJcG","heartbeatms":null,"pt":1780839560040,"initialclk":null,"mc":[{"rc":[{"tv":null,"batb":null,"spb":null,"bdatl":null,"trd":null,"spf":null,"ltp":null,"atb":[[7.7999999999999998,156.81],[8,864.13]],"spl":null,"spn":null,"atl":[[11,103.47],[10.5,259.36000000000001]],"batl":null,"id":16570658,"hc":null,"bdatb":null},{"tv":null,"batb":null,"spb":null,"bdatl":null,"trd":null,"spf":null,"ltp":null,"atb":[[1.1000000000000001,46193.120000000003],[1.0900000000000001,39612.160000000003]],"spl":null,"spn":null,"atl":[[1.1399999999999999,23514.07],[1.1499999999999999,11350.18]],"batl":null,"id":19924823,"hc":null,"bdatb":null}],"img":null,"tv":null,"con":null,"marketdefinition":null,"id":"1.258926623"}],"conflatems":null,"op":"mcm","id":3}
{"ct":null,"SegmentType":null,"clk":"AKQIAP8HAOIG","heartbeatms":null,"pt":1780839560936,"initialclk":null,"mc":[{"rc":[{"tv":238354.20999999999,"batb":null,"spb":null,"bdatl":null,"trd":[[9,0.12]],"spf":null,"ltp":9,"atb":null,"spl":null,"spn":null,"atl":[[9,7.2300000000000004]],"batl":null,"id":16570658,"hc":null,"bdatb":null}],"img":null,"tv":2052815.03,"con":null,"marketdefinition":null,"id":"1.258926623"}],"conflatems":null,"op":"mcm","id":3}
{"ct":null,"SegmentType":null,"clk":"AKoIAIUIAOsG","heartbeatms":null,"pt":1780839561023,"initialclk":null,"mc":[{"rc":[{"tv":1814466.6200000001,"batb":null,"spb":null,"bdatl":null,"trd":[[1.1299999999999999,151878.85000000001]],"spf":null,"ltp":1.1299999999999999,"atb":null,"spl":null,"spn":null,"atl":[[1.1299999999999999,29459.34]],"batl":null,"id":19924823,"hc":null,"bdatb":null}],"img":null,"tv":2052820.8300000001,"con":null,"marketdefinition":null,"id":"1.258926623"}],"conflatems":null,"op":"mcm","id":3}
{"ct":null,"SegmentType":null,"clk":"AL8IAJQIAPsG","heartbeatms":null,"pt":1780839561230,"initialclk":null,"mc":[{"rc":[{"tv":1814481.1200000001,"batb":null,"spb":null,"bdatl":null,"trd":[[1.1299999999999999,151893.35000000001]],"spf":null,"ltp":null,"atb":null,"spl":null,"spn":null,"atl":[[1.1299999999999999,29452.09]],"batl":null,"id":19924823,"hc":null,"bdatb":null}],"img":null,"tv":2052835.3300000001,"con":null,"marketdefinition":null,"id":"1.258926623"}],"conflatems":null,"op":"mcm","id":3}
{"ct":null,"SegmentType":null,"clk":"ANQIAKgIAIoH","heartbeatms":null,"pt":1780839561436,"initialclk":null,"mc":[{"rc":[{"tv":238354.38000000001,"batb":null,"spb":null,"bdatl":null,"trd":[[8.8000000000000007,1108.06]],"spf":null,"ltp":8.8000000000000007,"atb":[[8.8000000000000007,192.80000000000001]],"spl":null,"spn":null,"atl":null,"batl":null,"id":16570658,"hc":null,"bdatb":null}],"img":null,"tv":2052835.5,"con":null,"marketdefinition":null,"id":"1.258926623"}],"conflatems":null,"op":"mcm","id":3}
{"ct":null,"SegmentType":null,"clk":"AOcIALsIAJcH","heartbeatms":null,"pt":1780839561647,"initialclk":null,"mc":[{"rc":[{"tv":null,"batb":null,"spb":null,"bdatl":null,"trd":null,"spf":null,"ltp":null,"atb":null,"spl":null,"spn":null,"atl":[[12.5,6.0800000000000001]],"batl":null,"id":16570658,"hc":null,"bdatb":null},{"tv":null,"batb":null,"spb":null,"bdatl":null,"trd":null,"spf":null,"ltp":null,"atb":null,"spl":null,"spn":null,"atl":[[1.22,9062.3500000000004]],"batl":null,"id":19924823,"hc":null,"bdatb":null}],"img":null,"tv":null,"con":null,"marketdefinition":null,"id":"1.258926623"}],"conflatems":null,"op":"mcm","id":3}
{"ct":null,"SegmentType":null,"clk":"APAIAMMIAKAH","heartbeatms":null,"pt":1780839561751,"initialclk":null,"mc":[{"rc":[{"tv":1814525.8600000001,"batb":null,"spb":null,"bdatl":null,"trd":[[1.1200000000000001,5783.0799999999999]],"spf":null,"ltp":1.1200000000000001,"atb":[[1.1200000000000001,43116.68]],"spl":null,"spn":null,"atl":null,"batl":null,"id":19924823,"hc":null,"bdatb":null}],"img":null,"tv":2052880.24,"con":null,"marketdefinition":null,"id":"1.258926623"}],"conflatems":null,"op":"mcm","id":3}
{"ct":null,"SegmentType":null,"clk":"AIMJAN8IAL4H","heartbeatms":null,"pt":1780839562028,"initialclk":null,"mc":[{"rc":[{"tv":null,"batb":null,"spb":null,"bdatl":null,"trd":null,"spf":null,"ltp":null,"atb":[[1.1000000000000001,46185.629999999997]],"spl":null,"spn":null,"atl":[[1.1299999999999999,29444.59]],"batl":null,"id":19924823,"hc":null,"bdatb":null}],"img":null,"tv":null,"con":null,"marketdefinition":null,"id":"1.258926623"}],"conflatems":null,"op":"mcm","id":3}
{"ct":null,"SegmentType":null,"clk":"AJwJAIIJANcH","heartbeatms":null,"pt":1780839562327,"initialclk":null,"mc":[{"rc":[{"tv":null,"batb":null,"spb":null,"bdatl":null,"trd":null,"spf":null,"ltp":null,"atb":null,"spl":null,"spn":null,"atl":[[13.5,0]],"batl":null,"id":16570658,"hc":null,"bdatb":null},{"tv":null,"batb":null,"spb":null,"bdatl":null,"trd":null,"spf":null,"ltp":null,"atb":null,"spl":null,"spn":null,"atl":[[1.21,8960.3500000000004]],"batl":null,"id":19924823,"hc":null,"bdatb":null}],"img":null,"tv":null,"con":null,"marketdefinition":null,"id":"1.258926623"}],"conflatems":null,"op":"mcm","id":3}
{"ct":null,"SegmentType":null,"clk":"AKEJAIsJAN0H","heartbeatms":null,"pt":1780839562430,"initialclk":null,"mc":[{"rc":[{"tv":null,"batb":null,"spb":null,"bdatl":null,"trd":null,"spf":null,"ltp":null,"atb":null,"spl":null,"spn":null,"atl":[[10.5,145.36000000000001]],"batl":null,"id":16570658,"hc":null,"bdatb":null}],"img":null,"tv":null,"con":null,"marketdefinition":null,"id":"1.258926623"}],"conflatems":null,"op":"mcm","id":3}
{"ct":null,"SegmentType":null,"clk":"ALIJAKQJAO0H","heartbeatms":null,"pt":1780839562636,"initialclk":null,"mc":[{"rc":[{"tv":null,"batb":null,"spb":null,"bdatl":null,"trd":null,"spf":null,"ltp":null,"atb":null,"spl":null,"spn":null,"atl":[[10,333.19]],"batl":null,"id":16570658,"hc":null,"bdatb":null}],"img":null,"tv":null,"con":null,"marketdefinition":null,"id":"1.258926623"}],"conflatems":null,"op":"mcm","id":3}
{"ct":null,"SegmentType":null,"clk":"ALgJAKgJAPMH","heartbeatms":null,"pt":1780839562736,"initialclk":null,"mc":[{"rc":[{"tv":null,"batb":null,"spb":null,"bdatl":null,"trd":null,"spf":null,"ltp":null,"atb":null,"spl":null,"spn":null,"atl":[[9.1999999999999993,149.44]],"batl":null,"id":16570658,"hc":null,"bdatb":null},{"tv":1814526.04,"batb":null,"spb":null,"bdatl":null,"trd":[[1.1299999999999999,151893.53]],"spf":null,"ltp":1.1299999999999999,"atb":null,"spl":null,"spn":null,"atl":[[1.1299999999999999,29444.5]],"batl":null,"id":19924823,"hc":null,"bdatb":null}],"img":null,"tv":2052880.4199999999,"con":null,"marketdefinition":null,"id":"1.258926623"}],"conflatems":null,"op":"mcm","id":3}
{"ct":null,"SegmentType":null,"clk":"AMEJALIJAPoH","heartbeatms":null,"pt":1780839562839,"initialclk":null,"mc":[{"rc":[{"tv":null,"batb":null,"spb":null,"bdatl":null,"trd":null,"spf":null,"ltp":null,"atb":null,"spl":null,"spn":null,"atl":[[9,20.23]],"batl":null,"id":16570658,"hc":null,"bdatb":null}],"img":null,"tv":null,"con":null,"marketdefinition":null,"id":"1.258926623"}],"conflatems":null,"op":"mcm","id":3}
{"ct":null,"SegmentType":null,"clk":"AMoJAL8JAIII","heartbeatms":null,"pt":1780839562943,"initialclk":null,"mc":[{"rc":[{"tv":1814531.8400000001,"batb":null,"spb":null,"bdatl":null,"trd":[[1.1200000000000001,5788.8800000000001]],"spf":null,"ltp":1.1200000000000001,"atb":[[1.1200000000000001,43113.779999999999]],"spl":null,"spn":null,"atl":null,"batl":null,"id":19924823,"hc":null,"bdatb":null}],"img":null,"tv":2052886.22,"con":null,"marketdefinition":null,"id":"1.258926623"}],"conflatems":null,"op":"mcm","id":3}
{"ct":null,"SegmentType":null,"clk":"ANIJAM4JAIoI","heartbeatms":null,"pt":1780839563053,"initialclk":null,"mc":[{"rc":[{"tv":1814551.8400000001,"batb":null,"spb":null,"bdatl":null,"trd":[[1.1299999999999999,151913.53]],"spf":null,"ltp":1.1299999999999999,"atb":null,"spl":null,"spn":null,"atl":[[1.1299999999999999,29434.5]],"batl":null,"id":19924823,"hc":null,"bdatb":null}],"img":null,"tv":2052906.22,"con":null,"marketdefinition":null,"id":"1.258926623"}],"conflatems":null,"op":"mcm","id":3}
{"ct":null,"SegmentType":null,"clk":"AOMJANoJAJwI","heartbeatms":null,"pt":1780839563249,"initialclk":null,"mc":[{"rc":[{"tv":1814563.8500000001,"batb":null,"spb":null,"bdatl":null,"trd":[[1.1200000000000001,5800.8900000000003]],"spf":null,"ltp":1.1200000000000001,"atb":[[1.1200000000000001,43107.769999999997]],"spl":null,"spn":null,"atl":null,"batl":null,"id":19924823,"hc":null,"bdatb":null}],"img":null,"tv":2052918.23,"con":null,"marketdefinition":null,"id":"1.258926623"}],"conflatems":null,"op":"mcm","id":3}
{"ct":null,"SegmentType":null,"clk":"APkJAPYJALMI","heartbeatms":null,"pt":1780839563514,"initialclk":null,"mc":[{"rc":[{"tv":238356.23999999999,"batb":null,"spb":null,"bdatl":null,"trd":[[8.8000000000000007,1109.9200000000001]],"spf":null,"ltp":null,"atb":[[8.8000000000000007,191.87000000000001]],"spl":null,"spn":null,"atl":null,"batl":null,"id":16570658,"hc":null,"bdatb":null},{"tv":1814568.99,"batb":null,"spb":null,"bdatl":null,"trd":[[1.1299999999999999,151918.67000000001]],"spf":null,"ltp":1.1299999999999999,"atb":null,"spl":null,"spn":null,"atl":[[1.1299999999999999,29431.93]],"batl":null,"id":19924823,"hc":null,"bdatb":null}],"img":null,"tv":2052925.23,"con":null,"marketdefinition":null,"id":"1.258926623"}],"conflatems":null,"op":"mcm","id":3}
{"ct":null,"SegmentType":null,"clk":"AIAKAP4JAL4I","heartbeatms":null,"pt":1780839563612,"initialclk":null,"mc":[{"rc":[{"tv":null,"batb":null,"spb":null,"bdatl":null,"trd":null,"spf":null,"ltp":null,"atb":[[1.0800000000000001,39053.43]],"spl":null,"spn":null,"atl":null,"batl":null,"id":19924823,"hc":null,"bdatb":null}],"img":null,"tv":null,"con":null,"marketdefinition":null,"id":"1.258926623"}],"conflatems":null,"op":"mcm","id":3}
{"ct":null,"SegmentType":null,"clk":"AOIKAPEKALoJ","heartbeatms":null,"pt":1780839564951,"initialclk":null,"mc":[{"rc":[{"tv":null,"batb":null,"spb":null,"bdatl":null,"trd":null,"spf":null,"ltp":null,"atb":null,"spl":null,"spn":null,"atl":[[1.1299999999999999,28970.139999999999]],"batl":null,"id":19924823,"hc":null,"bdatb":null}],"img":null,"tv":null,"con":null,"marketdefinition":null,"id":"1.258926623"}],"conflatems":null,"op":"mcm","id":3}
{"ct":null,"SegmentType":null,"clk":"AOoKAPUKAMMJ","heartbeatms":null,"pt":1780839565053,"initialclk":null,"mc":[{"rc":[{"tv":1814755.6200000001,"batb":null,"spb":null,"bdatl":null,"trd":[[1.1200000000000001,5987.5200000000004]],"spf":null,"ltp":1.1200000000000001,"atb":[[1.1200000000000001,43014.459999999999]],"spl":null,"spn":null,"atl":null,"batl":null,"id":19924823,"hc":null,"bdatb":null}],"img":null,"tv":2053111.8600000001,"con":null,"marketdefinition":null,"id":"1.258926623"}],"conflatems":null,"op":"mcm","id":3}
{"ct":null,"SegmentType":null,"clk":"AJYLAJILAOQJ","heartbeatms":null,"pt":1780839565421,"initialclk":null,"mc":[{"rc":[{"tv":null,"batb":null,"spb":null,"bdatl":null,"trd":null,"spf":null,"ltp":null,"atb":[[8.8000000000000007,191.81]],"spl":null,"spn":null,"atl":null,"batl":null,"id":16570658,"hc":null,"bdatb":null}],"img":null,"tv":null,"con":null,"marketdefinition":null,"id":"1.258926623"}],"conflatems":null,"op":"mcm","id":3}
{"ct":null,"SegmentType":null,"clk":"AL4LANILAKcK","heartbeatms":null,"pt":1780839566041,"initialclk":null,"mc":[{"rc":[{"tv":1814767.6200000001,"batb":null,"spb":null,"bdatl":null,"trd":[[1.1299999999999999,151930.67000000001]],"spf":null,"ltp":1.1299999999999999,"atb":null,"spl":null,"spn":null,"atl":[[1.1299999999999999,28964.139999999999]],"batl":null,"id":19924823,"hc":null,"bdatb":null}],"img":null,"tv":2053123.8600000001,"con":null,"marketdefinition":null,"id":"1.258926623"}],"conflatems":null,"op":"mcm","id":3}
{"ct":null,"SegmentType":null,"clk":"APMLAIsMANoK","heartbeatms":null,"pt":1780839566615,"initialclk":null,"mc":[{"rc":[{"tv":238360.23999999999,"batb":null,"spb":null,"bdatl":null,"trd":[[8.8000000000000007,1113.9200000000001]],"spf":null,"ltp":null,"atb":[[8.8000000000000007,189.81]],"spl":null,"spn":null,"atl":null,"batl":null,"id":16570658,"hc":null,"bdatb":null}],"img":null,"tv":2053127.8600000001,"con":null,"marketdefinition":null,"id":"1.258926623"}],"conflatems":null,"op":"mcm","id":3}
{"ct":null,"SegmentType":null,"clk":"AIoMAKQMAPMK","heartbeatms":null,"pt":1780839566932,"initialclk":null,"mc":[{"rc":[{"tv":null,"batb":null,"spb":null,"bdatl":null,"trd":null,"spf":null,"ltp":null,"atb":null,"spl":null,"spn":null,"atl":[[1000,1.04]],"batl":null,"id":19924823,"hc":null,"bdatb":null}],"img":null,"tv":null,"con":null,"marketdefinition":null,"id":"1.258926623"}],"conflatems":null,"op":"mcm","id":3}
{"ct":null,"SegmentType":null,"clk":"AJEMAK4MAPsK","heartbeatms":null,"pt":1780839567034,"initialclk":null,"mc":[{"rc":[{"tv":238372.64000000001,"batb":null,"spb":null,"bdatl":null,"trd":[[9,12.52]],"spf":null,"ltp":9,"atb":null,"spl":null,"spn":null,"atl":[[9,14.029999999999999]],"batl":null,"id":16570658,"hc":null,"bdatb":null}],"img":null,"tv":2053140.26,"con":null,"marketdefinition":null,"id":"1.258926623"}],"conflatems":null,"op":"mcm","id":3}
{"ct":null,"SegmentType":null,"clk":"ALUMAM8MAJ8L","heartbeatms":null,"pt":1780839567445,"initialclk":null,"mc":[{"rc":[{"tv":null,"batb":null,"spb":null,"bdatl":null,"trd":null,"spf":null,"ltp":null,"atb":null,"spl":null,"spn":null,"atl":[[1000,0.88]],"batl":null,"id":19924823,"hc":null,"bdatb":null}],"img":null,"tv":null,"con":null,"marketdefinition":null,"id":"1.258926623"}],"conflatems":null,"op":"mcm","id":3}
{"ct":null,"SegmentType":null,"clk":"ANwMAPUMAMQL","heartbeatms":null,"pt":1780839567916,"initialclk":null,"mc":[{"rc":[{"tv":1814967.6200000001,"batb":null,"spb":null,"bdatl":null,"trd":[[1.1299999999999999,152130.67000000001]],"spf":null,"ltp":null,"atb":null,"spl":null,"spn":null,"atl":[[1.1299999999999999,28864.139999999999]],"batl":null,"id":19924823,"hc":null,"bdatb":null}],"img":null,"tv":2053340.26,"con":null,"marketdefinition":null,"id":"1.258926623"}],"conflatems":null,"op":"mcm","id":3}
{"ct":null,"SegmentType":null,"clk":"APgMAJINAOIL","heartbeatms":null,"pt":1780839568222,"initialclk":null,"mc":[{"rc":[{"tv":1814982.1100000001,"batb":null,"spb":null,"bdatl":null,"trd":[[1.1299999999999999,152145.16]],"spf":null,"ltp":null,"atb":null,"spl":null,"spn":null,"atl":[[1.1299999999999999,28856.900000000001]],"batl":null,"id":19924823,"hc":null,"bdatb":null}],"img":null,"tv":2053354.75,"con":null,"marketdefinition":null,"id":"1.258926623"}],"conflatems":null,"op":"mcm","id":3}
{"ct":null,"SegmentType":null,"clk":"AIkNAKUNAPsL","heartbeatms":null,"pt":1780839568426,"initialclk":null,"mc":[{"rc":[{"tv":1814984.1399999999,"batb":null,"spb":null,"bdatl":null,"trd":[[1.1200000000000001,5989.5500000000002]],"spf":null,"ltp":1.1200000000000001,"atb":[[1.1200000000000001,43013.440000000002]],"spl":null,"spn":null,"atl":null,"batl":null,"id":19924823,"hc":null,"bdatb":null}],"img":null,"tv":2053356.78,"con":null,"marketdefinition":null,"id":"1.258926623"}],"conflatems":null,"op":"mcm","id":3}
{"ct":null,"SegmentType":null,"clk":"AKENAMMNAI0M","heartbeatms":null,"pt":1780839568732,"initialclk":null,"mc":[{"rc":[{"tv":null,"batb":null,"spb":null,"bdatl":null,"trd":null,"spf":null,"ltp":null,"atb":null,"spl":null,"spn":null,"atl":[[1.1299999999999999,27993.98]],"batl":null,"id":19924823,"hc":null,"bdatb":null}],"img":null,"tv":null,"con":null,"marketdefinition":null,"id":"1.258926623"}],"conflatems":null,"op":"mcm","id":3}
{"ct":null,"SegmentType":null,"clk":"AOYNAIYOANUM","heartbeatms":null,"pt":1780839569555,"initialclk":null,"mc":[{"rc":[{"tv":null,"batb":null,"spb":null,"bdatl":null,"trd":null,"spf":null,"ltp":null,"atb":null,"spl":null,"spn":null,"atl":[[10,483.18000000000001]],"batl":null,"id":16570658,"hc":null,"bdatb":null}],"img":null,"tv":null,"con":null,"marketdefinition":null,"id":"1.258926623"}],"conflatems":null,"op":"mcm","id":3}
{"ct":null,"SegmentType":null,"clk":"AO4NAI0OAN4M","heartbeatms":null,"pt":1780839569627,"initialclk":null,"mc":[{"rc":[{"tv":null,"batb":null,"spb":null,"bdatl":null,"trd":null,"spf":null,"ltp":null,"atb":null,"spl":null,"spn":null,"atl":[[9.5999999999999996,1.01]],"batl":null,"id":16570658,"hc":null,"bdatb":null}],"img":null,"tv":null,"con":null,"marketdefinition":null,"id":"1.258926623"}],"conflatems":null,"op":"mcm","id":3}
{"ct":null,"SegmentType":null,"clk":"AIUOAKkOAPgM","heartbeatms":null,"pt":1780839569920,"initialclk":null,"mc":[{"rc":[{"tv":null,"batb":null,"spb":null,"bdatl":null,"trd":null,"spf":null,"ltp":null,"atb":[[1.1200000000000001,43011.709999999999]],"spl":null,"spn":null,"atl":null,"batl":null,"id":19924823,"hc":null,"bdatb":null}],"img":null,"tv":null,"con":null,"marketdefinition":null,"id":"1.258926623"}],"conflatems":null,"op":"mcm","id":3}
{"ct":null,"SegmentType":null,"clk":"ALkOANgOAK0N","heartbeatms":null,"pt":1780839570535,"initialclk":null,"mc":[{"rc":[{"tv":238372.70000000001,"batb":null,"spb":null,"bdatl":null,"trd":[[8.8000000000000007,1113.98]],"spf":null,"ltp":8.8000000000000007,"atb":[[8.8000000000000007,189.78]],"spl":null,"spn":null,"atl":null,"batl":null,"id":16570658,"hc":null,"bdatb":null},{"tv":1814984.46,"batb":null,"spb":null,"bdatl":null,"trd":[[1.1200000000000001,5989.8699999999999]],"spf":null,"ltp":null,"atb":[[1.1200000000000001,43011.559999999998]],"spl":null,"spn":null,"atl":null,"batl":null,"id":19924823,"hc":null,"bdatb":null}],"img":null,"tv":2053357.1599999999,"con":null,"marketdefinition":null,"id":"1.258926623"}],"conflatems":null,"op":"mcm","id":3}
{"ct":null,"SegmentType":null,"clk":"AMMOAOAOALMN","heartbeatms":null,"pt":1780839570639,"initialclk":null,"mc":[{"rc":[{"tv":null,"batb":null,"spb":null,"bdatl":null,"trd":null,"spf":null,"ltp":null,"atb":[[8.8000000000000007,104.27]],"spl":null,"spn":null,"atl":null,"batl":null,"id":16570658,"hc":null,"bdatb":null}],"img":null,"tv":null,"con":null,"marketdefinition":null,"id":"1.258926623"}],"conflatems":null,"op":"mcm","id":3}
{"ct":null,"SegmentType":null,"clk":"AMoOAOsOALoN","heartbeatms":null,"pt":1780839570741,"initialclk":null,"mc":[{"rc":[{"tv":null,"batb":null,"spb":null,"bdatl":null,"trd":null,"spf":null,"ltp":null,"atb":[[1.0800000000000001,38937.550000000003]],"spl":null,"spn":null,"atl":null,"batl":null,"id":19924823,"hc":null,"bdatb":null}],"img":null,"tv":null,"con":null,"marketdefinition":null,"id":"1.258926623"}],"conflatems":null,"op":"mcm","id":3}
{"ct":null,"SegmentType":null,"clk":"ANgOAP0OAMYN","heartbeatms":null,"pt":1780839570951,"initialclk":null,"mc":[{"rc":[{"tv":null,"batb":null,"spb":null,"bdatl":null,"trd":null,"spf":null,"ltp":null,"atb":null,"spl":null,"spn":null,"atl":[[1000,1.6200000000000001]],"batl":null,"id":16570658,"hc":null,"bdatb":null},{"tv":null,"batb":null,"spb":null,"bdatl":null,"trd":null,"spf":null,"ltp":null,"atb":[[1.1200000000000001,43011.989999999998]],"spl":null,"spn":null,"atl":null,"batl":null,"id":19924823,"hc":null,"bdatb":null}],"img":null,"tv":null,"con":null,"marketdefinition":null,"id":"1.258926623"}],"conflatems":null,"op":"mcm","id":3}
{"ct":null,"SegmentType":null,"clk":"APEOAJwPANsN","heartbeatms":null,"pt":1780839571226,"initialclk":null,"mc":[{"rc":[{"tv":null,"batb":null,"spb":null,"bdatl":null,"trd":null,"spf":null,"ltp":null,"atb":null,"spl":null,"spn":null,"atl":[[1000,1.1399999999999999]],"batl":null,"id":16570658,"hc":null,"bdatb":null}],"img":null,"tv":null,"con":null,"marketdefinition":null,"id":"1.258926623"}],"conflatems":null,"op":"mcm","id":3}
{"ct":null,"SegmentType":null,"clk":"AJMPAmcPAIgO","heartbeatms":null,"pt":1780839571631,"initialclk":null,"mc":[{"rc":[{"tv":null,"batb":null,"spb":null,"bdatl":null,"trd":null,"spf":null,"ltp":null,"atb":null,"spl":null,"spn":null,"atl":[[1000,0.87]],"batl":null,"id":16570658,"hc":null,"bdatb":null}],"img":null,"tv":null,"con":null,"marketdefinition":null,"id":"1.258926623"}],"conflatems":null,"op":"mcm","id":3}
{"ct":null,"SegmentType":null,"clk":"APoPALQQAOcO","heartbeatms":null,"pt":1780839572718,"initialclk":null,"mc":[{"rc":[{"tv":null,"batb":null,"spb":null,"bdatl":null,"trd":null,"spf":null,"ltp":null,"atb":null,"spl":null,"spn":null,"atl":[[1.1299999999999999,27996.619999999999]],"batl":null,"id":19924823,"hc":null,"bdatb":null}],"img":null,"tv":null,"con":null,"marketdefinition":null,"id":"1.258926623"}],"conflatems":null,"op":"mcm","id":3}
{"ct":null,"SegmentType":null,"clk":"AIcOANUNANkFALcQAN0M","heartbeatms":null,"pt":1780839572750,"Oc":[{"Accountid":null,"Orc":[{"Mb":null,"Uo":[{"Side":0,"pt":0,"Ot":0,"Status":0,"Sv":0,"P":1.1299999999999999,"Sc":0,"rc":"REG_LGA","S":5,"Pd":1780839572000,"Rac":"","Md":null,"Sl":0,"Avp":null,"Sm":0,"id":"431726698780","Bsp":null,"Sr":5,"Cd":null,"Rfo":"SL-Back-0","Rfs":"SL"}],"id":19924823,"hc":null,"FullImage":null,"Ml":null}],"Closed":null,"id":"1.258926623","FullImage":null}],"initialclk":null,"conflatems":null,"op":"ocm","id":2}
{"ct":null,"SegmentType":null,"clk":"AJsQANAQAIYP","heartbeatms":null,"pt":1780839573028,"initialclk":null,"mc":[{"rc":[{"tv":1814987.9199999999,"batb":null,"spb":null,"bdatl":null,"trd":[[1.1299999999999999,152148.62]],"spf":null,"ltp":1.1299999999999999,"atb":null,"spl":null,"spn":null,"atl":[[1.1299999999999999,27994.900000000001]],"batl":null,"id":19924823,"hc":null,"bdatb":null}],"img":null,"tv":2053360.6200000001,"con":null,"marketdefinition":null,"id":"1.258926623"}],"conflatems":null,"op":"mcm","id":3}
{"ct":null,"SegmentType":null,"clk":"AK8QAN4QAJoP","heartbeatms":null,"pt":1780839573230,"initialclk":null,"mc":[{"rc":[{"tv":238377.32000000001,"batb":null,"spb":null,"bdatl":null,"trd":[[9,17.140000000000001]],"spf":null,"ltp":9,"atb":null,"spl":null,"spn":null,"atl":[[9,11.720000000000001]],"batl":null,"id":16570658,"hc":null,"bdatb":null}],"img":null,"tv":2053365.24,"con":null,"marketdefinition":null,"id":"1.258926623"}],"conflatems":null,"op":"mcm","id":3}
{"ct":null,"SegmentType":null,"clk":"AOYQAJQRANEP","heartbeatms":null,"pt":1780839573848,"initialclk":null,"mc":[{"rc":[{"tv":null,"batb":null,"spb":null,"bdatl":null,"trd":null,"spf":null,"ltp":null,"atb":[[1.04,73781.479999999996]],"spl":null,"spn":null,"atl":null,"batl":null,"id":19924823,"hc":null,"bdatb":null}],"img":null,"tv":null,"con":null,"marketdefinition":null,"id":"1.258926623"}],"conflatems":null,"op":"mcm","id":3}
{"ct":null,"SegmentType":null,"clk":"AO4QAJ0RANcP","heartbeatms":null,"pt":1780839573948,"initialclk":null,"mc":[{"rc":[{"tv":null,"batb":null,"spb":null,"bdatl":null,"trd":null,"spf":null,"ltp":null,"atb":[[1.0800000000000001,39053.43]],"spl":null,"spn":null,"atl":null,"batl":null,"id":19924823,"hc":null,"bdatb":null}],"img":null,"tv":null,"con":null,"marketdefinition":null,"id":"1.258926623"}],"conflatems":null,"op":"mcm","id":3}
{"ct":null,"SegmentType":null,"clk":"AIkRALMRAPkP","heartbeatms":null,"pt":1780839574260,"initialclk":null,"mc":[{"rc":[{"tv":1815987.9199999999,"batb":null,"spb":null,"bdatl":null,"trd":[[1.1200000000000001,6989.8699999999999]],"spf":null,"ltp":1.1200000000000001,"atb":[[1.1200000000000001,42511.989999999998]],"spl":null,"spn":null,"atl":null,"batl":null,"id":19924823,"hc":null,"bdatb":null}],"img":null,"tv":2054365.24,"con":null,"marketdefinition":null,"id":"1.258926623"}],"conflatems":null,"op":"mcm","id":3}
{"ct":null,"SegmentType":null,"clk":"AKIRANMRAJUQ","heartbeatms":null,"pt":1780839574569,"initialclk":null,"mc":[{"rc":[{"tv":null,"batb":null,"spb":null,"bdatl":null,"trd":null,"spf":null,"ltp":null,"atb":[[8.8000000000000007,0],[8.5999999999999996,749.58000000000004]],"spl":null,"spn":null,"atl":[[8.8000000000000007,0.26000000000000001],[11,105.47]],"batl":null,"id":16570658,"hc":null,"bdatb":null},{"tv":null,"batb":null,"spb":null,"bdatl":null,"trd":null,"spf":null,"ltp":null,"atb":[[1.1000000000000001,46187.629999999997]],"spl":null,"spn":null,"atl":null,"batl":null,"id":19924823,"hc":null,"bdatb":null}],"img":null,"tv":null,"con":null,"marketdefinition":null,"id":"1.258926623"}],"conflatems":null,"op":"mcm","id":3}
{"ct":null,"SegmentType":null,"clk":"AKsRANoRAJ8Q","heartbeatms":null,"pt":1780839574673,"initialclk":null,"mc":[{"rc":[{"tv":null,"batb":null,"spb":null,"bdatl":null,"trd":null,"spf":null,"ltp":null,"atb":[[8.4000000000000004,295.42000000000002],[7.7999999999999998,290.13],[7.5999999999999996,112.99],[8.1999999999999993,100.45],[8.5999999999999996,583.29999999999995]],"spl":null,"spn":null,"atl":[[9.4000000000000004,207.13999999999999],[11,235.15000000000001],[10.5,393.17000000000002],[10,333.19]],"batl":null,"id":16570658,"hc":null,"bdatb":null},{"tv":null,"batb":null,"spb":null,"bdatl":null,"trd":null,"spf":null,"ltp":null,"atb":[[1.1000000000000001,43996.629999999997],[1.1100000000000001,50701.739999999998],[1.1200000000000001,42509.989999999998]],"spl":null,"spn":null,"atl":[[1.1399999999999999,21679.07],[1.1499999999999999,10286.549999999999]],"batl":null,"id":19924823,"hc":null,"bdatb":null}],"img":null,"tv":null,"con":null,"marketdefinition":null,"id":"1.258926623"}],"conflatems":null,"op":"mcm","id":3}
{"ct":null,"SegmentType":null,"clk":"ALURAOYRAKgQ","heartbeatms":null,"pt":1780839574730,"initialclk":null,"mc":[{"rc":[{"tv":null,"batb":null,"spb":null,"bdatl":null,"trd":null,"spf":null,"ltp":null,"atb":null,"spl":null,"spn":null,"atl":[[9,130.41]],"batl":null,"id":16570658,"hc":null,"bdatb":null}],"img":null,"tv":null,"con":null,"marketdefinition":null,"id":"1.258926623"}],"conflatems":null,"op":"mcm","id":3}
{"ct":null,"SegmentType":null,"clk":"AL4RAPARALIQ","heartbeatms":null,"pt":1780839574829,"initialclk":null,"mc":[{"rc":[{"tv":null,"batb":null,"spb":null,"bdatl":null,"trd":null,"spf":null,"ltp":null,"atb":null,"spl":null,"spn":null,"atl":[[1.1399999999999999,22479.07]],"batl":null,"id":19924823,"hc":null,"bdatb":null}],"img":null,"tv":null,"con":null,"marketdefinition":null,"id":"1.258926623"}],"conflatems":null,"op":"mcm","id":3}
{"ct":null,"SegmentType":null,"clk":"AMgRAPcRALwQ","heartbeatms":null,"pt":1780839574930,"initialclk":null,"mc":[{"rc":[{"tv":null,"batb":null,"spb":null,"bdatl":null,"trd":null,"spf":null,"ltp":null,"atb":[[8.4000000000000004,1],[7,0.98999999999999999],[6.7999999999999998,0.40000000000000002],[8.1999999999999993,23.609999999999999]],"spl":null,"spn":null,"atl":[[10.5,250.66999999999999],[10,89.159999999999997],[9.1999999999999993,0.94999999999999996],[9,11.720000000000001]],"batl":null,"id":16570658,"hc":null,"bdatb":null},{"tv":null,"batb":null,"spb":null,"bdatl":null,"trd":null,"spf":null,"ltp":null,"atb":[[1.1200000000000001,41360.209999999999]],"spl":null,"spn":null,"atl":null,"batl":null,"id":19924823,"hc":null,"bdatb":null}],"img":null,"tv":null,"con":null,"marketdefinition":null,"id":"1.258926623"}],"conflatems":null,"op":"mcm","id":3}
{"ct":null,"SegmentType":null,"clk":"ANcRAI0SANEQ","heartbeatms":null,"pt":1780839575142,"initialclk":null,"mc":[{"rc":[{"tv":1816188.8999999999,"batb":null,"spb":null,"bdatl":null,"trd":[[1.1299999999999999,152349.60000000001]],"spf":null,"ltp":1.1299999999999999,"atb":null,"spl":null,"spn":null,"atl":[[1.1299999999999999,27894.400000000001]],"batl":null,"id":19924823,"hc":null,"bdatb":null}],"img":null,"tv":2054566.22,"con":null,"marketdefinition":null,"id":"1.258926623"}],"conflatems":null,"op":"mcm","id":3}
{"ct":null,"SegmentType":null,"clk":"AOERAJESANwQ","heartbeatms":null,"pt":1780839575242,"initialclk":null,"mc":[{"rc":[{"tv":null,"batb":null,"spb":null,"bdatl":null,"trd":null,"spf":null,"ltp":null,"atb":null,"spl":null,"spn":null,"atl":[[9.4000000000000004,198.81]],"batl":null,"id":16570658,"hc":null,"bdatb":null}],"img":null,"tv":null,"con":null,"marketdefinition":null,"id":"1.258926623"}],"conflatems":null,"op":"mcm","id":3}
{"ct":null,"SegmentType":null,"clk":"APoRAKkSAOoQ","heartbeatms":null,"pt":1780839575450,"initialclk":null,"mc":[{"rc":[{"tv":null,"batb":null,"spb":null,"bdatl":null,"trd":null,"spf":null,"ltp":null,"atb":[[1.1100000000000001,51289.099999999999]],"spl":null,"spn":null,"atl":[[1.1499999999999999,11155.9]],"batl":null,"id":19924823,"hc":null,"bdatb":null}],"img":null,"tv":null,"con":null,"marketdefinition":null,"id":"1.258926623"}],"conflatems":null,"op":"mcm","id":3}
{"ct":null,"SegmentType":null,"clk":"AIQSAKsSAPcQ","heartbeatms":null,"pt":1780839575552,"initialclk":null,"mc":[{"rc":[{"tv":null,"batb":null,"spb":null,"bdatl":null,"trd":null,"spf":null,"ltp":null,"atb":[[1.1200000000000001,40778.099999999999]],"spl":null,"spn":null,"atl":[[1.1299999999999999,27496.139999999999],[1.1399999999999999,22327.540000000001]],"batl":null,"id":19924823,"hc":null,"bdatb":null}],"img":null,"tv":null,"con":null,"marketdefinition":null,"id":"1.258926623"}],"conflatems":null,"op":"mcm","id":3}
{"ct":null,"SegmentType":null,"clk":"ALMSAOMSAKMR","heartbeatms":null,"pt":1780839576067,"initialclk":null,"mc":[{"rc":[{"tv":1816203.3999999999,"batb":null,"spb":null,"bdatl":null,"trd":[[1.1299999999999999,152364.10000000001]],"spf":null,"ltp":null,"atb":null,"spl":null,"spn":null,"atl":[[1.1299999999999999,27488.900000000001]],"batl":null,"id":19924823,"hc":null,"bdatb":null}],"img":null,"tv":2054580.72,"con":null,"marketdefinition":null,"id":"1.258926623"}],"conflatems":null,"op":"mcm","id":3}
{"ct":null,"SegmentType":null,"clk":"AMMSAPMSAKwR","heartbeatms":null,"pt":1780839576224,"initialclk":null,"mc":[{"rc":[{"tv":null,"batb":null,"spb":null,"bdatl":null,"trd":null,"spf":null,"ltp":null,"atb":[[1.1200000000000001,40864.470000000001]],"spl":null,"spn":null,"atl":null,"batl":null,"id":19924823,"hc":null,"bdatb":null}],"img":null,"tv":null,"con":null,"marketdefinition":null,"id":"1.258926623"}],"conflatems":null,"op":"mcm","id":3}
{"ct":null,"SegmentType":null,"clk":"ANISAIQTAMAR","heartbeatms":null,"pt":1780839576430,"initialclk":null,"mc":[{"rc":[{"tv":null,"batb":null,"spb":null,"bdatl":null,"trd":null,"spf":null,"ltp":null,"atb":[[1.1100000000000001,51297.739999999998]],"spl":null,"spn":null,"atl":null,"batl":null,"id":19924823,"hc":null,"bdatb":null}],"img":null,"tv":null,"con":null,"marketdefinition":null,"id":"1.258926623"}],"conflatems":null,"op":"mcm","id":3}
{"ct":null,"SegmentType":null,"clk":"AIkTAMETAP0R","heartbeatms":null,"pt":1780839577049,"initialclk":null,"mc":[{"rc":[{"tv":null,"batb":null,"spb":null,"bdatl":null,"trd":null,"spf":null,"ltp":null,"atb":null,"spl":null,"spn":null,"atl":[[8.8000000000000007,0.40999999999999998]],"batl":null,"id":16570658,"hc":null,"bdatb":null}],"img":null,"tv":null,"con":null,"marketdefinition":null,"id":"1.258926623"}],"conflatems":null,"op":"mcm","id":3}
{"ct":null,"SegmentType":null,"clk":"AJgTAM0TAIcS","heartbeatms":null,"pt":1780839577154,"initialclk":null,"mc":[{"rc":[{"tv":null,"batb":null,"spb":null,"bdatl":null,"trd":null,"spf":null,"ltp":null,"atb":[[1.04,73781.679999999993]],"spl":null,"spn":null,"atl":null,"batl":null,"id":19924823,"hc":null,"bdatb":null}],"img":null,"tv":null,"con":null,"marketdefinition":null,"id":"1.258926623"}],"conflatems":null,"op":"mcm","id":3}
{"ct":null,"SegmentType":null,"clk":"ALkTAOYTAKcS","heartbeatms":null,"pt":1780839577459,"initialclk":null,"mc":[{"rc":[{"tv":1816323.3899999999,"batb":null,"spb":null,"bdatl":null,"trd":[[1.1200000000000001,7109.8599999999997]],"spf":null,"ltp":1.1200000000000001,"atb":[[1.1200000000000001,40804.480000000003]],"spl":null,"spn":null,"atl":null,"batl":null,"id":19924823,"hc":null,"bdatb":null}],"img":null,"tv":2054700.71,"con":null,"marketdefinition":null,"id":"1.258926623"}],"conflatems":null,"op":"mcm","id":3}
{"ct":null,"SegmentType":null,"clk":"AMMTAO8TAK8S","heartbeatms":null,"pt":1780839577563,"initialclk":null,"mc":[{"rc":[{"tv":null,"batb":null,"spb":null,"bdatl":null,"trd":null,"spf":null,"ltp":null,"atb":[[1.04,73781.479999999996]],"spl":null,"spn":null,"atl":null,"batl":null,"id":19924823,"hc":null,"bdatb":null}],"img":null,"tv":null,"con":null,"marketdefinition":null,"id":"1.258926623"}],"conflatems":null,"op":"mcm","id":3}
{"ct":null,"SegmentType":null,"clk":"AKMUANIUAIoT","heartbeatms":null,"pt":1780839578547,"initialclk":null,"mc":[{"rc":[{"tv":238385.5,"batb":null,"spb":null,"bdatl":null,"trd":[[8.8000000000000007,1114.78],[9,24.52]],"spf":null,"ltp":null,"atb":null,"spl":null,"spn":null,"atl":[[8.8000000000000007,0],[9,8.0299999999999994]],"batl":null,"id":16570658,"hc":null,"bdatb":null}],"img":null,"tv":2054708.8899999999,"con":null,"marketdefinition":null,"id":"1.258926623"}],"conflatems":null,"op":"mcm","id":3}
{"ct":null,"SegmentType":null,"clk":"AK4UAN0UAJYT","heartbeatms":null,"pt":1780839578650,"initialclk":null,"mc":[{"rc":[{"tv":null,"batb":null,"spb":null,"bdatl":null,"trd":null,"spf":null,"ltp":null,"atb":[[7.5999999999999996,112.13]],"spl":null,"spn":null,"atl":null,"batl":null,"id":16570658,"hc":null,"bdatb":null},{"tv":null,"batb":null,"spb":null,"bdatl":null,"trd":null,"spf":null,"ltp":null,"atb":null,"spl":null,"spn":null,"atl":[[1.1499999999999999,11152.02]],"batl":null,"id":19924823,"hc":null,"bdatb":null}],"img":null,"tv":null,"con":null,"marketdefinition":null,"id":"1.258926623"}],"conflatems":null,"op":"mcm","id":3}
{"ct":null,"SegmentType":null,"clk":"AOUUAJIVAMoT","heartbeatms":null,"pt":1780839579167,"initialclk":null,"mc":[{"rc":[{"tv":1827197.3899999999,"batb":null,"spb":null,"bdatl":null,"trd":[[1.1200000000000001,17983.860000000001]],"spf":null,"ltp":null,"atb":[[1.1200000000000001,35367.480000000003]],"spl":null,"spn":null,"atl":null,"batl":null,"id":19924823,"hc":null,"bdatb":null}],"img":null,"tv":2065582.8899999999,"con":null,"marketdefinition":null,"id":"1.258926623"}],"conflatems":null,"op":"mcm","id":3}
{"ct":null,"SegmentType":null,"clk":"AO4UAJgVANQT","heartbeatms":null,"pt":1780839579273,"initialclk":null,"mc":[{"rc":[{"tv":null,"batb":null,"spb":null,"bdatl":null,"trd":null,"spf":null,"ltp":null,"atb":null,"spl":null,"spn":null,"atl":[[11.5,385.41000000000002]],"batl":null,"id":16570658,"hc":null,"bdatb":null},{"tv":1827238.0700000001,"batb":null,"spb":null,"bdatl":null,"trd":[[1.1200000000000001,18024.540000000001]],"spf":null,"ltp":null,"atb":[[1.1200000000000001,35347.139999999999]],"spl":null,"spn":null,"atl":null,"batl":null,"id":19924823,"hc":null,"bdatb":null}],"img":null,"tv":2065623.5700000001,"con":null,"marketdefinition":null,"id":"1.258926623"}],"conflatems":null,"op":"mcm","id":3}
{"ct":null,"SegmentType":null,"clk":"APkUAJ8VAN8T","heartbeatms":null,"pt":1780839579375,"initialclk":null,"mc":[{"rc":[{"tv":238385.60000000001,"batb":null,"spb":null,"bdatl":null,"trd":[[9,24.620000000000001]],"spf":null,"ltp":null,"atb":null,"spl":null,"spn":null,"atl":[[9,7.9800000000000004]],"batl":null,"id":16570658,"hc":null,"bdatb":null}],"img":null,"tv":2065623.6699999999,"con":null,"marketdefinition":null,"id":"1.258926623"}],"conflatems":null,"op":"mcm","id":3}
{"ct":null,"SegmentType":null,"clk":"AJgVAL4VAIAU","heartbeatms":null,"pt":1780839579640,"initialclk":null,"mc":[{"rc":[{"tv":null,"batb":null,"spb":null,"bdatl":null,"trd":null,"spf":null,"ltp":null,"atb":null,"spl":null,"spn":null,"atl":[[9.1999999999999993,3.1099999999999999]],"batl":null,"id":16570658,"hc":null,"bdatb":null}],"img":null,"tv":null,"con":null,"marketdefinition":null,"id":"1.258926623"}],"conflatems":null,"op":"mcm","id":3}
{"ct":null,"SegmentType":null,"clk":"AMgVAOAVAKgU","heartbeatms":null,"pt":1780839580150,"initialclk":null,"mc":[{"rc":[{"tv":null,"batb":null,"spb":null,"bdatl":null,"trd":null,"spf":null,"ltp":null,"atb":[[8.8000000000000007,411.11000000000001],[8.5999999999999996,769.24000000000001]],"spl":null,"spn":null,"atl":null,"batl":null,"id":16570658,"hc":null,"bdatb":null},{"tv":null,"batb":null,"spb":null,"bdatl":null,"trd":null,"spf":null,"ltp":null,"atb":null,"spl":null,"spn":null,"atl":[[1.1299999999999999,32053]],"batl":null,"id":19924823,"hc":null,"bdatb":null}],"img":null,"tv":null,"con":null,"marketdefinition":null,"id":"1.258926623"}],"conflatems":null,"op":"mcm","id":3}
{"ct":null,"SegmentType":null,"clk":"AM8VAOcVALEU","heartbeatms":null,"pt":1780839580256,"initialclk":null,"mc":[{"rc":[{"tv":null,"batb":null,"spb":null,"bdatl":null,"trd":null,"spf":null,"ltp":null,"atb":[[7.7999999999999998,290.99000000000001],[7.5999999999999996,113.12000000000001]],"spl":null,"spn":null,"atl":null,"batl":null,"id":16570658,"hc":null,"bdatb":null},{"tv":null,"batb":null,"spb":null,"bdatl":null,"trd":null,"spf":null,"ltp":null,"atb":null,"spl":null,"spn":null,"atl":[[1.1499999999999999,11155.73]],"batl":null,"id":19924823,"hc":null,"bdatb":null}],"img":null,"tv":null,"con":null,"marketdefinition":null,"id":"1.258926623"}],"conflatems":null,"op":"mcm","id":3}
{"ct":null,"SegmentType":null,"clk":"ANoVAO0VALkU","heartbeatms":null,"pt":1780839580357,"initialclk":null,"mc":[{"rc":[{"tv":null,"batb":null,"spb":null,"bdatl":null,"trd":null,"spf":null,"ltp":null,"atb":[[7,0],[8.8000000000000007,382.69999999999999],[7.2000000000000002,0]],"spl":null,"spn":null,"atl":null,"batl":null,"id":16570658,"hc":null,"bdatb":null},{"tv":null,"batb":null,"spb":null,"bdatl":null,"trd":null,"spf":null,"ltp":null,"atb":[[1.1000000000000001,42996.629999999997],[1.1200000000000001,19190.790000000001]],"spl":null,"spn":null,"atl":[[1.1699999999999999,9374.9899999999998],[1.1299999999999999,27488.900000000001]],"batl":null,"id":19924823,"hc":null,"bdatb":null}],"img":null,"tv":null,"con":null,"marketdefinition":null,"id":"1.258926623"}],"conflatems":null,"op":"mcm","id":3}
{"ct":null,"SegmentType":null,"clk":"AOQVAPUVAMEU","heartbeatms":null,"pt":1780839580458,"initialclk":null,"mc":[{"rc":[{"tv":null,"batb":null,"spb":null,"bdatl":null,"trd":null,"spf":null,"ltp":null,"atb":[[8,853.25]],"spl":null,"spn":null,"atl":null,"batl":null,"id":16570658,"hc":null,"bdatb":null},{"tv":null,"batb":null,"spb":null,"bdatl":null,"trd":null,"spf":null,"ltp":null,"atb":null,"spl":null,"spn":null,"atl":[[1.1399999999999999,21986.290000000001],[1.1499999999999999,10808.83]],"batl":null,"id":19924823,"hc":null,"bdatb":null}],"img":null,"tv":null,"con":null,"marketdefinition":null,"id":"1.258926623"}],"conflatems":null,"op":"mcm","id":3}
{"ct":null,"SegmentType":null,"clk":"AO4VAP4VAMYU","heartbeatms":null,"pt":1780839580564,"initialclk":null,"mc":[{"rc":[{"tv":null,"batb":null,"spb":null,"bdatl":null,"trd":null,"spf":null,"ltp":null,"atb":[[8.8000000000000007,541.63999999999999],[8.5999999999999996,1281.29]],"spl":null,"spn":null,"atl":null,"batl":null,"id":16570658,"hc":null,"bdatb":null},{"tv":null,"batb":null,"spb":null,"bdatl":null,"trd":null,"spf":null,"ltp":null,"atb":[[1.1000000000000001,57932.879999999997]],"spl":null,"spn":null,"atl":null,"batl":null,"id":19924823,"hc":null,"bdatb":null}],"img":null,"tv":null,"con":null,"marketdefinition":null,"id":"1.258926623"}],"conflatems":null,"op":"mcm","id":3}
{"ct":null,"SegmentType":null,"clk":"APgVAIkWAMwU","heartbeatms":null,"pt":1780839580665,"initialclk":null,"mc":[{"rc":[{"tv":1827238.46,"batb":null,"spb":null,"bdatl":null,"trd":[[1.1299999999999999,152364.48999999999]],"spf":null,"ltp":1.1299999999999999,"atb":null,"spl":null,"spn":null,"atl":[[1.1299999999999999,27488.700000000001]],"batl":null,"id":19924823,"hc":null,"bdatb":null}],"img":null,"tv":2065624.0600000001,"con":null,"marketdefinition":null,"id":"1.258926623"}],"conflatems":null,"op":"mcm","id":3}
{"ct":null,"SegmentType":null,"clk":"AIIWAJUWANMU","heartbeatms":null,"pt":1780839580770,"initialclk":null,"mc":[{"rc":[{"tv":null,"batb":null,"spb":null,"bdatl":null,"trd":null,"spf":null,"ltp":null,"atb":[[8,275.12]],"spl":null,"spn":null,"atl":null,"batl":null,"id":16570658,"hc":null,"bdatb":null},{"tv":null,"batb":null,"spb":null,"bdatl":null,"trd":null,"spf":null,"ltp":null,"atb":[[1.1100000000000001,37977.269999999997]],"spl":null,"spn":null,"atl":null,"batl":null,"id":19924823,"hc":null,"bdatb":null}],"img":null,"tv":null,"con":null,"marketdefinition":null,"id":"1.258926623"}],"conflatems":null,"op":"mcm","id":3}
{"ct":null,"SegmentType":null,"clk":"AIoWAJ4WANkU","heartbeatms":null,"pt":1780839580872,"initialclk":null,"mc":[{"rc":[{"tv":null,"batb":null,"spb":null,"bdatl":null,"trd":null,"spf":null,"ltp":null,"atb":null,"spl":null,"spn":null,"atl":[[20,1.2]],"batl":null,"id":16570658,"hc":null,"bdatb":null}],"img":null,"tv":null,"con":null,"marketdefinition":null,"id":"1.258926623"}],"conflatems":null,"op":"mcm","id":3}
{"ct":null,"SegmentType":null,"clk":"AJoWALAWAOcU","heartbeatms":null,"pt":1780839581035,"initialclk":null,"mc":[{"rc":[{"tv":null,"batb":null,"spb":null,"bdatl":null,"trd":null,"spf":null,"ltp":null,"atb":[[1.04,73780.729999999996]],"spl":null,"spn":null,"atl":null,"batl":null,"id":19924823,"hc":null,"bdatb":null}],"img":null,"tv":null,"con":null,"marketdefinition":null,"id":"1.258926623"}],"conflatems":null,"op":"mcm","id":3}
{"ct":null,"SegmentType":null,"clk":"AKoWAMYWAPgU","heartbeatms":null,"pt":1780839581245,"initialclk":null,"mc":[{"rc":[{"tv":null,"batb":null,"spb":null,"bdatl":null,"trd":null,"spf":null,"ltp":null,"atb":[[8.4000000000000004,179.56999999999999]],"spl":null,"spn":null,"atl":[[11,371.50999999999999]],"batl":null,"id":16570658,"hc":null,"bdatb":null},{"tv":null,"batb":null,"spb":null,"bdatl":null,"trd":null,"spf":null,"ltp":null,"atb":[[1.1000000000000001,59296.510000000002]],"spl":null,"spn":null,"atl":[[1.1399999999999999,23302.080000000002]],"batl":null,"id":19924823,"hc":null,"bdatb":null}],"img":null,"tv":null,"con":null,"marketdefinition":null,"id":"1.258926623"}],"conflatems":null,"op":"mcm","id":3}
{"ct":null,"SegmentType":null,"clk":"ALkWAOAWAIoV","heartbeatms":null,"pt":1780839581451,"initialclk":null,"mc":[{"rc":[{"tv":null,"batb":null,"spb":null,"bdatl":null,"trd":null,"spf":null,"ltp":null,"atb":[[1.1100000000000001,35794.290000000001]],"spl":null,"spn":null,"atl":[[1.1399999999999999,22053.52],[1.1499999999999999,9939.4799999999996]],"batl":null,"id":19924823,"hc":null,"bdatb":null}],"img":null,"tv":null,"con":null,"marketdefinition":null,"id":"1.258926623"}],"conflatems":null,"op":"mcm","id":3}
{"ct":null,"SegmentType":null,"clk":"AL4WAOcWAJEV","heartbeatms":null,"pt":1780839581553,"initialclk":null,"mc":[{"rc":[{"tv":1827252.96,"batb":null,"spb":null,"bdatl":null,"trd":[[1.1299999999999999,152378.98999999999]],"spf":null,"ltp":null,"atb":null,"spl":null,"spn":null,"atl":[[1.1299999999999999,27481.450000000001]],"batl":null,"id":19924823,"hc":null,"bdatb":null}],"img":null,"tv":2065638.5600000001,"con":null,"marketdefinition":null,"id":"1.258926623"}],"conflatems":null,"op":"mcm","id":3}
{"ct":null,"SegmentType":null,"clk":"AOMWAKcXALoV","heartbeatms":null,"pt":1780839582063,"initialclk":null,"mc":[{"rc":[{"tv":null,"batb":null,"spb":null,"bdatl":null,"trd":null,"spf":null,"ltp":null,"atb":[[1.1200000000000001,19160.790000000001]],"spl":null,"spn":null,"atl":null,"batl":null,"id":19924823,"hc":null,"bdatb":null}],"img":null,"tv":null,"con":null,"marketdefinition":null,"id":"1.258926623"}],"conflatems":null,"op":"mcm","id":3}
{"ct":null,"SegmentType":null,"clk":"AOwWALAXAMQV","heartbeatms":null,"pt":1780839582164,"initialclk":null,"mc":[{"rc":[{"tv":1827261.75,"batb":null,"spb":null,"bdatl":null,"trd":[[1.1200000000000001,18033.330000000002]],"spf":null,"ltp":1.1200000000000001,"atb":[[1.1200000000000001,19156.400000000001]],"spl":null,"spn":null,"atl":null,"batl":null,"id":19924823,"hc":null,"bdatb":null}],"img":null,"tv":2065647.3500000001,"con":null,"marketdefinition":null,"id":"1.258926623"}],"conflatems":null,"op":"mcm","id":3}
{"ct":null,"SegmentType":null,"clk":"APUWALsXAMkV","heartbeatms":null,"pt":1780839582267,"initialclk":null,"mc":[{"rc":[{"tv":null,"batb":null,"spb":null,"bdatl":null,"trd":null,"spf":null,"ltp":null,"atb":null,"spl":null,"spn":null,"atl":[[25,32.810000000000002]],"batl":null,"id":16570658,"hc":null,"bdatb":null}],"img":null,"tv":null,"con":null,"marketdefinition":null,"id":"1.258926623"}],"conflatems":null,"op":"mcm","id":3}
{"ct":null,"SegmentType":null,"clk":"APYXAmcYAMkW","heartbeatms":null,"pt":1780839583762,"initialclk":null,"mc":[{"rc":[{"tv":1827284.95,"batb":null,"spb":null,"bdatl":null,"trd":[[1.1299999999999999,152402.19]],"spf":null,"ltp":1.1299999999999999,"atb":null,"spl":null,"spn":null,"atl":[[1.1299999999999999,27469.849999999999]],"batl":null,"id":19924823,"hc":null,"bdatb":null}],"img":null,"tv":2065670.5500000001,"con":null,"marketdefinition":null,"id":"1.258926623"}],"conflatems":null,"op":"mcm","id":3}
{"ct":null,"SegmentType":null,"clk":"AP0XANEYANMW","heartbeatms":null,"pt":1780839583868,"initialclk":null,"mc":[{"rc":[{"tv":null,"batb":null,"spb":null,"bdatl":null,"trd":null,"spf":null,"ltp":null,"atb":[[8.5999999999999996,1346.29]],"spl":null,"spn":null,"atl":[[11.5,455.41000000000002]],"batl":null,"id":16570658,"hc":null,"bdatb":null},{"tv":null,"batb":null,"spb":null,"bdatl":null,"trd":null,"spf":null,"ltp":null,"atb":[[1.0900000000000001,41324.160000000003]],"spl":null,"spn":null,"atl":[[1.1299999999999999,28941.849999999999]],"batl":null,"id":19924823,"hc":null,"bdatb":null}],"img":null,"tv":null,"con":null,"marketdefinition":null,"id":"1.258926623"}],"conflatems":null,"op":"mcm","id":3}
{"ct":null,"SegmentType":null,"clk":"AJsYAPIYAO8W","heartbeatms":null,"pt":1780839584176,"initialclk":null,"mc":[{"rc":[{"tv":null,"batb":null,"spb":null,"bdatl":null,"trd":null,"spf":null,"ltp":null,"atb":null,"spl":null,"spn":null,"atl":[[1.1299999999999999,29403.639999999999]],"batl":null,"id":19924823,"hc":null,"bdatb":null}],"img":null,"tv":null,"con":null,"marketdefinition":null,"id":"1.258926623"}],"conflatems":null,"op":"mcm","id":3}
{"ct":null,"SegmentType":null,"clk":"ALsYAJoZAIUX","heartbeatms":null,"pt":1780839584446,"initialclk":null,"mc":[{"rc":[{"tv":null,"batb":null,"spb":null,"bdatl":null,"trd":null,"spf":null,"ltp":null,"atb":[[8.4000000000000004,1]],"spl":null,"spn":null,"atl":[[13,0],[9.1999999999999993,117.09999999999999]],"batl":null,"id":16570658,"hc":null,"bdatb":null},{"tv":null,"batb":null,"spb":null,"bdatl":null,"trd":null,"spf":null,"ltp":null,"atb":[[1.1200000000000001,20224.040000000001]],"spl":null,"spn":null,"atl":null,"batl":null,"id":19924823,"hc":null,"bdatb":null}],"img":null,"tv":null,"con":null,"marketdefinition":null,"id":"1.258926623"}],"conflatems":null,"op":"mcm","id":3}
{"ct":null,"SegmentType":null,"clk":"AMAYAJ8ZAIsX","heartbeatms":null,"pt":1780839584547,"initialclk":null,"mc":[{"rc":[{"tv":null,"batb":null,"spb":null,"bdatl":null,"trd":null,"spf":null,"ltp":null,"atb":null,"spl":null,"spn":null,"atl":[[10,96.930000000000007]],"batl":null,"id":16570658,"hc":null,"bdatb":null},{"tv":null,"batb":null,"spb":null,"bdatl":null,"trd":null,"spf":null,"ltp":null,"atb":[[1.1000000000000001,59996.510000000002]],"spl":null,"spn":null,"atl":null,"batl":null,"id":19924823,"hc":null,"bdatb":null}],"img":null,"tv":null,"con":null,"marketdefinition":null,"id":"1.258926623"}],"conflatems":null,"op":"mcm","id":3}
{"ct":null,"SegmentType":null,"clk":"AOwYAMgZALQX","heartbeatms":null,"pt":1780839585061,"initialclk":null,"mc":[{"rc":[{"tv":null,"batb":null,"spb":null,"bdatl":null,"trd":null,"spf":null,"ltp":null,"atb":[[1.1000000000000001,60004]],"spl":null,"spn":null,"atl":[[1.1499999999999999,9946.9799999999996]],"batl":null,"id":19924823,"hc":null,"bdatb":null}],"img":null,"tv":null,"con":null,"marketdefinition":null,"id":"1.258926623"}],"conflatems":null,"op":"mcm","id":3}
{"ct":null,"SegmentType":null,"clk":"APYYANEZALsX","heartbeatms":null,"pt":1780839585166,"initialclk":null,"mc":[{"rc":[{"tv":null,"batb":null,"spb":null,"bdatl":null,"trd":null,"spf":null,"ltp":null,"atb":null,"spl":null,"spn":null,"atl":[[1.1299999999999999,29405.639999999999]],"batl":null,"id":19924823,"hc":null,"bdatb":null}],"img":null,"tv":null,"con":null,"marketdefinition":null,"id":"1.258926623"}],"conflatems":null,"op":"mcm","id":3}
{"ct":null,"SegmentType":null,"clk":"AIcZAOYZAM4X","heartbeatms":null,"pt":1780839585369,"initialclk":null,"mc":[{"rc":[{"tv":null,"batb":null,"spb":null,"bdatl":null,"trd":null,"spf":null,"ltp":null,"atb":null,"spl":null,"spn":null,"atl":[[1.1299999999999999,29403.639999999999]],"batl":null,"id":19924823,"hc":null,"bdatb":null}],"img":null,"tv":null,"con":null,"marketdefinition":null,"id":"1.258926623"}],"conflatems":null,"op":"mcm","id":3}
{"ct":null,"SegmentType":null,"clk":"AKIZAJAaAOYX","heartbeatms":null,"pt":1780839585735,"initialclk":null,"mc":[{"rc":[{"tv":null,"batb":null,"spb":null,"bdatl":null,"trd":null,"spf":null,"ltp":null,"atb":[[1.1100000000000001,36703.379999999997]],"spl":null,"spn":null,"atl":null,"batl":null,"id":19924823,"hc":null,"bdatb":null}],"img":null,"tv":null,"con":null,"marketdefinition":null,"id":"1.258926623"}],"conflatems":null,"op":"mcm","id":3}
{"ct":null,"SegmentType":null,"clk":"AP0ZAI8bANUY","heartbeatms":null,"pt":1780839587073,"initialclk":null,"mc":[{"rc":[{"tv":null,"batb":null,"spb":null,"bdatl":null,"trd":null,"spf":null,"ltp":null,"atb":[[1.1200000000000001,21086.959999999999]],"spl":null,"spn":null,"atl":[[1.1399999999999999,20737.73]],"batl":null,"id":19924823,"hc":null,"bdatb":null}],"img":null,"tv":null,"con":null,"marketdefinition":null,"id":"1.258926623"}],"conflatems":null,"op":"mcm","id":3}
{"ct":null,"SegmentType":null,"clk":"AKkaAMQbAIYZ","heartbeatms":null,"pt":1780839587644,"initialclk":null,"mc":[{"rc":[{"tv":null,"batb":null,"spb":null,"bdatl":null,"trd":null,"spf":null,"ltp":null,"atb":[[7,0.98999999999999999],[7.2000000000000002,0.85999999999999999]],"spl":null,"spn":null,"atl":[[11.5,456.39999999999998],[11,372.37],[10,97.790000000000006]],"batl":null,"id":16570658,"hc":null,"bdatb":null},{"tv":null,"batb":null,"spb":null,"bdatl":null,"trd":null,"spf":null,"ltp":null,"atb":[[1.1000000000000001,60009.830000000002],[1.0900000000000001,41330.550000000003],[1.1100000000000001,53985.160000000003]],"spl":null,"spn":null,"atl":[[1.24,1412.4200000000001],[1.1699999999999999,9380.7299999999996],[1.23,9545.6700000000001],[1.1599999999999999,8934.7999999999993]],"batl":null,"id":19924823,"hc":null,"bdatb":null}],"img":null,"tv":null,"con":null,"marketdefinition":null,"id":"1.258926623"}],"conflatems":null,"op":"mcm","id":3}
{"ct":null,"SegmentType":null,"clk":"ANUaAPAbAK0Z","heartbeatms":null,"pt":1780839588149,"initialclk":null,"mc":[{"rc":[{"tv":null,"batb":null,"spb":null,"bdatl":null,"trd":null,"spf":null,"ltp":null,"atb":[[1.1200000000000001,21153.860000000001]],"spl":null,"spn":null,"atl":null,"batl":null,"id":19924823,"hc":null,"bdatb":null}],"img":null,"tv":null,"con":null,"marketdefinition":null,"id":"1.258926623"}],"conflatems":null,"op":"mcm","id":3}
{"ct":null,"SegmentType":null,"clk":"AOUaAP8bAMAZ","heartbeatms":null,"pt":1780839588353,"initialclk":null,"mc":[{"rc":[{"tv":null,"batb":null,"spb":null,"bdatl":null,"trd":null,"spf":null,"ltp":null,"atb":null,"spl":null,"spn":null,"atl":[[1.22,8862.3500000000004],[1.2,8901.0499999999993]],"batl":null,"id":19924823,"hc":null,"bdatb":null}],"img":null,"tv":null,"con":null,"marketdefinition":null,"id":"1.258926623"}],"conflatems":null,"op":"mcm","id":3}
{"ct":null,"SegmentType":null,"clk":"AIgbALEcAOEZ","heartbeatms":null,"pt":1780839588870,"initialclk":null,"mc":[{"rc":[{"tv":1827315.3899999999,"batb":null,"spb":null,"bdatl":null,"trd":[[1.1299999999999999,152402.35000000001],[1.1200000000000001,18063.610000000001]],"spf":null,"ltp":null,"atb":[[1.1200000000000001,21138.720000000001]],"spl":null,"spn":null,"atl":[[1.1299999999999999,29403.560000000001]],"batl":null,"id":19924823,"hc":null,"bdatb":null}],"img":null,"tv":2065700.99,"con":null,"marketdefinition":null,"id":"1.258926623"}],"conflatems":null,"op":"mcm","id":3}
{"ct":null,"SegmentType":null,"clk":"AJobAMQcAO4Z","heartbeatms":null,"pt":1780839589076,"initialclk":null,"mc":[{"rc":[{"tv":1827319.9299999999,"batb":null,"spb":null,"bdatl":null,"trd":[[1.1299999999999999,152406.89000000001]],"spf":null,"ltp":null,"atb":null,"spl":null,"spn":null,"atl":[[1.1299999999999999,29401.290000000001]],"batl":null,"id":19924823,"hc":null,"bdatb":null}],"img":null,"tv":2065705.53,"con":null,"marketdefinition":null,"id":"1.258926623"}],"conflatems":null,"op":"mcm","id":3}
{"ct":null,"SegmentType":null,"clk":"AKkbANwcAIMa","heartbeatms":null,"pt":1780839589242,"initialclk":null,"mc":[{"rc":[{"tv":null,"batb":null,"spb":null,"bdatl":null,"trd":null,"spf":null,"ltp":null,"atb":[[7.7999999999999998,477.86000000000001]],"spl":null,"spn":null,"atl":[[9.8000000000000007,238.56999999999999]],"batl":null,"id":16570658,"hc":null,"bdatb":null},{"tv":null,"batb":null,"spb":null,"bdatl":null,"trd":null,"spf":null,"ltp":null,"atb":[[1.1100000000000001,55336.510000000002]],"spl":null,"spn":null,"atl":[[1.1499999999999999,11214.49]],"batl":null,"id":19924823,"hc":null,"bdatb":null}],"img":null,"tv":null,"con":null,"marketdefinition":null,"id":"1.258926623"}],"conflatems":null,"op":"mcm","id":3}
{"ct":null,"SegmentType":null,"clk":"ANQbAI0dALka","heartbeatms":null,"pt":1780839589751,"initialclk":null,"mc":[{"rc":[{"tv":null,"batb":null,"spb":null,"bdatl":null,"trd":null,"spf":null,"ltp":null,"atb":null,"spl":null,"spn":null,"atl":[[11,236.00999999999999]],"batl":null,"id":16570658,"hc":null,"bdatb":null},{"tv":null,"batb":null,"spb":null,"bdatl":null,"trd":null,"spf":null,"ltp":null,"atb":[[1.1000000000000001,58646.199999999997]],"spl":null,"spn":null,"atl":null,"batl":null,"id":19924823,"hc":null,"bdatb":null}],"img":null,"tv":null,"con":null,"marketdefinition":null,"id":"1.258926623"}],"conflatems":null,"op":"mcm","id":3}
{"ct":null,"SegmentType":null,"clk":"ANsbAJkdAMYa","heartbeatms":null,"pt":1780839589873,"initialclk":null,"mc":[{"rc":[{"tv":null,"batb":null,"spb":null,"bdatl":null,"trd":null,"spf":null,"ltp":null,"atb":null,"spl":null,"spn":null,"atl":[[9.4000000000000004,181.53]],"batl":null,"id":16570658,"hc":null,"bdatb":null}],"img":null,"tv":null,"con":null,"marketdefinition":null,"id":"1.258926623"}],"conflatems":null,"op":"mcm","id":3}
{"ct":null,"SegmentType":null,"clk":"AOYbAJ4dAM8a","heartbeatms":null,"pt":1780839589958,"initialclk":null,"mc":[{"rc":[{"tv":null,"batb":null,"spb":null,"bdatl":null,"trd":null,"spf":null,"ltp":null,"atb":null,"spl":null,"spn":null,"atl":[[9,25.260000000000002]],"batl":null,"id":16570658,"hc":null,"bdatb":null}],"img":null,"tv":null,"con":null,"marketdefinition":null,"id":"1.258926623"}],"conflatems":null,"op":"mcm","id":3}
{"ct":null,"SegmentType":null,"clk":"AOwbAKgdANca","heartbeatms":null,"pt":1780839590064,"initialclk":null,"mc":[{"rc":[{"tv":238400.34,"batb":null,"spb":null,"bdatl":null,"trd":[[8.8000000000000007,1129.52]],"spf":null,"ltp":8.8000000000000007,"atb":[[8.8000000000000007,534.26999999999998]],"spl":null,"spn":null,"atl":null,"batl":null,"id":16570658,"hc":null,"bdatb":null}],"img":null,"tv":2065720.27,"con":null,"marketdefinition":null,"id":"1.258926623"}],"conflatems":null,"op":"mcm","id":3}
{"ct":null,"SegmentType":null,"clk":"AIQcAMsdAPIa","heartbeatms":null,"pt":1780839590373,"initialclk":null,"mc":[{"rc":[{"tv":null,"batb":null,"spb":null,"bdatl":null,"trd":null,"spf":null,"ltp":null,"atb":[[7.7999999999999998,477],[7.5999999999999996,112.13]],"spl":null,"spn":null,"atl":[[11,235.02000000000001],[10.5,249.81]],"batl":null,"id":16570658,"hc":null,"bdatb":null},{"tv":null,"batb":null,"spb":null,"bdatl":null,"trd":null,"spf":null,"ltp":null,"atb":[[1.1000000000000001,58640.18],[1.1100000000000001,55330.760000000002]],"spl":null,"spn":null,"atl":[[1000,1.1100000000000001],[1.1399999999999999,20733.98],[1.1599999999999999,8931.0400000000009],[1.1499999999999999,11210.780000000001]],"batl":null,"id":19924823,"hc":null,"bdatb":null}],"img":null,"tv":null,"con":null,"marketdefinition":null,"id":"1.258926623"}],"conflatems":null,"op":"mcm","id":3}
{"ct":null,"SegmentType":null,"clk":"AJ8cAOcdAIsb","heartbeatms":null,"pt":1780839590646,"initialclk":null,"mc":[{"rc":[{"tv":1861871.1899999999,"batb":null,"spb":null,"bdatl":null,"trd":[[1.1299999999999999,186958.14999999999]],"spf":null,"ltp":null,"atb":null,"spl":null,"spn":null,"atl":[[1.1299999999999999,12125.66]],"batl":null,"id":19924823,"hc":null,"bdatb":null}],"img":null,"tv":2100271.5299999998,"con":null,"marketdefinition":null,"id":"1.258926623"}],"conflatems":null,"op":"mcm","id":3}
{"ct":null,"SegmentType":null,"clk":"AKkcAPEdAI8b","heartbeatms":null,"pt":1780839590745,"initialclk":null,"mc":[{"rc":[{"tv":null,"batb":null,"spb":null,"bdatl":null,"trd":null,"spf":null,"ltp":null,"atb":null,"spl":null,"spn":null,"atl":[[1000,0.88],[1.1499999999999999,11207.030000000001]],"batl":null,"id":19924823,"hc":null,"bdatb":null}],"img":null,"tv":null,"con":null,"marketdefinition":null,"id":"1.258926623"}],"conflatems":null,"op":"mcm","id":3}
{"ct":null,"SegmentType":null,"clk":"AMgcAJweALob","heartbeatms":null,"pt":1780839591154,"initialclk":null,"mc":[{"rc":[{"tv":null,"batb":null,"spb":null,"bdatl":null,"trd":null,"spf":null,"ltp":null,"atb":[[8.8000000000000007,534.32000000000005]],"spl":null,"spn":null,"atl":null,"batl":null,"id":16570658,"hc":null,"bdatb":null}],"img":null,"tv":null,"con":null,"marketdefinition":null,"id":"1.258926623"}],"conflatems":null,"op":"mcm","id":3}
{"ct":null,"SegmentType":null,"clk":"AM8cAKceAMkb","heartbeatms":null,"pt":1780839591261,"initialclk":null,"mc":[{"rc":[{"tv":null,"batb":null,"spb":null,"bdatl":null,"trd":null,"spf":null,"ltp":null,"atb":null,"spl":null,"spn":null,"atl":[[1.1299999999999999,12635.52]],"batl":null,"id":19924823,"hc":null,"bdatb":null}],"img":null,"tv":null,"con":null,"marketdefinition":null,"id":"1.258926623"}],"conflatems":null,"op":"mcm","id":3}
{"ct":null,"SegmentType":null,"clk":"AKidAPMeAKkc","heartbeatms":null,"pt":1780839592182,"initialclk":null,"mc":[{"rc":[{"tv":238402.34,"batb":null,"spb":null,"bdatl":null,"trd":[[8.8000000000000007,1131.52]],"spf":null,"ltp":null,"atb":[[8.8000000000000007,533.32000000000005]],"spl":null,"spn":null,"atl":null,"batl":null,"id":16570658,"hc":null,"bdatb":null}],"img":null,"tv":2100273.5299999998,"con":null,"marketdefinition":null,"id":"1.258926623"}],"conflatems":null,"op":"mcm","id":3}
{"ct":null,"SegmentType":null,"clk":"AK8dAIUfALwc","heartbeatms":null,"pt":1780839592354,"initialclk":null,"mc":[{"rc":[{"tv":null,"batb":null,"spb":null,"bdatl":null,"trd":null,"spf":null,"ltp":null,"atb":null,"spl":null,"spn":null,"atl":[[9,39.689999999999998]],"batl":null,"id":16570658,"hc":null,"bdatb":null},{"tv":1861885.6899999999,"batb":null,"spb":null,"bdatl":null,"trd":[[1.1299999999999999,186972.64999999999]],"spf":null,"ltp":null,"atb":null,"spl":null,"spn":null,"atl":[[1.1299999999999999,12628.27]],"batl":null,"id":19924823,"hc":null,"bdatb":null}],"img":null,"tv":2100288.0299999998,"con":null,"marketdefinition":null,"id":"1.258926623"}],"conflatems":null,"op":"mcm","id":3}
{"ct":null,"SegmentType":null,"clk":"AOQdAMMfAIAd","heartbeatms":null,"pt":1780839592966,"initialclk":null,"mc":[{"rc":[{"tv":null,"batb":null,"spb":null,"bdatl":null,"trd":null,"spf":null,"ltp":null,"atb":[[1.1100000000000001,55339.400000000001]],"spl":null,"spn":null,"atl":null,"batl":null,"id":19924823,"hc":null,"bdatb":null}],"img":null,"tv":null,"con":null,"marketdefinition":null,"id":"1.258926623"}],"conflatems":null,"op":"mcm","id":3}
{"ct":null,"SegmentType":null,"clk":"AJ0eAOwfALYd","heartbeatms":null,"pt":1780839593485,"initialclk":null,"mc":[{"rc":[{"tv":null,"batb":null,"spb":null,"bdatl":null,"trd":null,"spf":null,"ltp":null,"atb":[[1.1100000000000001,55392.980000000003]],"spl":null,"spn":null,"atl":null,"batl":null,"id":19924823,"hc":null,"bdatb":null}],"img":null,"tv":null,"con":null,"marketdefinition":null,"id":"1.258926623"}],"conflatems":null,"op":"mcm","id":3}
{"ct":null,"SegmentType":null,"clk":"AKseAPcfAMAd","heartbeatms":null,"pt":1780839593545,"initialclk":null,"mc":[{"rc":[{"tv":1861888.9399999999,"batb":null,"spb":null,"bdatl":null,"trd":[[1.1200000000000001,18066.860000000001]],"spf":null,"ltp":1.1200000000000001,"atb":[[1.1000000000000001,58495.790000000001],[1.1200000000000001,21137.09]],"spl":null,"spn":null,"atl":null,"batl":null,"id":19924823,"hc":null,"bdatb":null}],"img":null,"tv":2100291.2799999998,"con":null,"marketdefinition":null,"id":"1.258926623"}],"conflatems":null,"op":"mcm","id":3}
{"ct":null,"SegmentType":null,"clk":"ALUeAIAgAMod","heartbeatms":null,"pt":1780839593650,"initialclk":null,"mc":[{"rc":[{"tv":null,"batb":null,"spb":null,"bdatl":null,"trd":null,"spf":null,"ltp":null,"atb":[[1.1200000000000001,21281.48]],"spl":null,"spn":null,"atl":null,"batl":null,"id":19924823,"hc":null,"bdatb":null}],"img":null,"tv":null,"con":null,"marketdefinition":null,"id":"1.258926623"}],"conflatems":null,"op":"mcm","id":3}
{"ct":null,"SegmentType":null,"clk":"AMMeAJIgAN4d","heartbeatms":null,"pt":1780839593852,"initialclk":null,"mc":[{"rc":[{"tv":1861889.3899999999,"batb":null,"spb":null,"bdatl":null,"trd":[[1.1200000000000001,18067.310000000001]],"spf":null,"ltp":null,"atb":[[1.1200000000000001,21281.259999999998]],"spl":null,"spn":null,"atl":null,"batl":null,"id":19924823,"hc":null,"bdatb":null}],"img":null,"tv":2100291.73,"con":null,"marketdefinition":null,"id":"1.258926623"}],"conflatems":null,"op":"mcm","id":3}
{"ct":null,"SegmentType":null,"clk":"AN0eAKogAIMe","heartbeatms":null,"pt":1780839594167,"initialclk":null,"mc":[{"rc":[{"tv":238402.44,"batb":null,"spb":null,"bdatl":null,"trd":[[9,24.719999999999999]],"spf":null,"ltp":9,"atb":null,"spl":null,"spn":null,"atl":[[9,39.640000000000001]],"batl":null,"id":16570658,"hc":null,"bdatb":null}],"img":null,"tv":2100291.8300000001,"con":null,"marketdefinition":null,"id":"1.258926623"}],"conflatems":null,"op":"mcm","id":3}
{"ct":null,"SegmentType":null,"clk":"AJAfAN0gAmce","heartbeatms":null,"pt":1780839594743,"initialclk":null,"mc":[{"rc":[{"tv":null,"batb":null,"spb":null,"bdatl":null,"trd":null,"spf":null,"ltp":null,"atb":null,"spl":null,"spn":null,"atl":[[1.1499999999999999,11526.700000000001]],"batl":null,"id":19924823,"hc":null,"bdatb":null}],"img":null,"tv":null,"con":null,"marketdefinition":null,"id":"1.258926623"}],"conflatems":null,"op":"mcm","id":3}
{"ct":null,"SegmentType":null,"clk":"AJ4fAO0gANYe","heartbeatms":null,"pt":1780839594939,"initialclk":null,"mc":[{"rc":[{"tv":238402.5,"batb":null,"spb":null,"bdatl":null,"trd":[[8.8000000000000007,1131.5799999999999]],"spf":null,"ltp":8.8000000000000007,"atb":[[8.8000000000000007,533.28999999999996]],"spl":null,"spn":null,"atl":null,"batl":null,"id":16570658,"hc":null,"bdatb":null}],"img":null,"tv":2100291.8900000001,"con":null,"marketdefinition":null,"id":"1.258926623"}],"conflatems":null,"op":"mcm","id":3}
{"ct":null,"SegmentType":null,"clk":"AK4fAP8gAOge","heartbeatms":null,"pt":1780839595148,"initialclk":null,"mc":[{"rc":[{"tv":238403.07999999999,"batb":null,"spb":null,"bdatl":null,"trd":[[8.8000000000000007,1132.1600000000001]],"spf":null,"ltp":null,"atb":[[8.8000000000000007,533]],"spl":null,"spn":null,"atl":null,"batl":null,"id":16570658,"hc":null,"bdatb":null}],"img":null,"tv":2100292.4700000002,"con":null,"marketdefinition":null,"id":"1.258926623"}],"conflatems":null,"op":"mcm","id":3}
{"ct":null,"SegmentType":null,"clk":"ALMfAIchAPQe","heartbeatms":null,"pt":1780839595248,"initialclk":null,"mc":[{"rc":[{"tv":null,"batb":null,"spb":null,"bdatl":null,"trd":null,"spf":null,"ltp":null,"atb":[[1.1100000000000001,55409.010000000002]],"spl":null,"spn":null,"atl":[[1.1299999999999999,12166.48]],"batl":null,"id":19924823,"hc":null,"bdatb":null}],"img":null,"tv":null,"con":null,"marketdefinition":null,"id":"1.258926623"}],"conflatems":null,"op":"mcm","id":3}
{"ct":null,"SegmentType":null,"clk":"AOkfAMohALEf","heartbeatms":null,"pt":1780839595974,"initialclk":null,"mc":[{"rc":[{"tv":1867666.53,"batb":null,"spb":null,"bdatl":null,"trd":[[1.1299999999999999,192749.79000000001]],"spf":null,"ltp":1.1299999999999999,"atb":null,"spl":null,"spn":null,"atl":[[1.1299999999999999,9277.9099999999999]],"batl":null,"id":19924823,"hc":null,"bdatb":null}],"img":null,"tv":2106069.6099999999,"con":null,"marketdefinition":null,"id":"1.258926623"}],"conflatems":null,"op":"mcm","id":3}
{"ct":null,"SegmentType":null,"clk":"AIkgAP0hANsf","heartbeatms":null,"pt":1780839596387,"initialclk":null,"mc":[{"rc":[{"tv":null,"batb":null,"spb":null,"bdatl":null,"trd":null,"spf":null,"ltp":null,"atb":[[8.8000000000000007,532.95000000000005]],"spl":null,"spn":null,"atl":null,"batl":null,"id":16570658,"hc":null,"bdatb":null}],"img":null,"tv":null,"con":null,"marketdefinition":null,"id":"1.258926623"}],"conflatems":null,"op":"mcm","id":3}
{"ct":null,"SegmentType":null,"clk":"AMEgAIYiAOgf","heartbeatms":null,"pt":1780839596494,"initialclk":null,"mc":[{"rc":[{"tv":238403.35999999999,"batb":null,"spb":null,"bdatl":null,"trd":[[8.8000000000000007,1132.4400000000001]],"spf":null,"ltp":null,"atb":[[8.8000000000000007,532.80999999999995]],"spl":null,"spn":null,"atl":null,"batl":null,"id":16570658,"hc":null,"bdatb":null}],"img":null,"tv":2106069.8900000001,"con":null,"marketdefinition":null,"id":"1.258926623"}],"conflatems":null,"op":"mcm","id":3}
{"ct":null,"SegmentType":null,"clk":"ANQgAJIiAO8f","heartbeatms":null,"pt":1780839596547,"initialclk":null,"mc":[{"rc":[{"tv":1867668.76,"batb":null,"spb":null,"bdatl":null,"trd":[[1.1299999999999999,192752.01999999999]],"spf":null,"ltp":null,"atb":null,"spl":null,"spn":null,"atl":[[1.1299999999999999,9276.7999999999993]],"batl":null,"id":19924823,"hc":null,"bdatb":null}],"img":null,"tv":2106072.1200000001,"con":null,"marketdefinition":null,"id":"1.258926623"}],"conflatems":null,"op":"mcm","id":3}
{"ct":null,"SegmentType":null,"clk":"AN0gAJwiAPgf","heartbeatms":null,"pt":1780839596650,"initialclk":null,"mc":[{"rc":[{"tv":238405.35999999999,"batb":null,"spb":null,"bdatl":null,"trd":[[8.8000000000000007,1134.4400000000001]],"spf":null,"ltp":null,"atb":[[8.8000000000000007,531.80999999999995]],"spl":null,"spn":null,"atl":[[9,53.210000000000001]],"batl":null,"id":16570658,"hc":null,"bdatb":null}],"img":null,"tv":2106074.1200000001,"con":null,"marketdefinition":null,"id":"1.258926623"}],"conflatems":null,"op":"mcm","id":3}
{"ct":null,"SegmentType":null,"clk":"AOIgAKciAIAg","heartbeatms":null,"pt":1780839596755,"initialclk":null,"mc":[{"rc":[{"tv":null,"batb":null,"spb":null,"bdatl":null,"trd":null,"spf":null,"ltp":null,"atb":[[1.1200000000000001,21214.360000000001]],"spl":null,"spn":null,"atl":null,"batl":null,"id":19924823,"hc":null,"bdatb":null}],"img":null,"tv":null,"con":null,"marketdefinition":null,"id":"1.258926623"}],"conflatems":null,"op":"mcm","id":3}
{"ct":null,"SegmentType":null,"clk":"AOkgALUiAIcg","heartbeatms":null,"pt":1780839596861,"initialclk":null,"mc":[{"rc":[{"tv":1867868.76,"batb":null,"spb":null,"bdatl":null,"trd":[[1.1200000000000001,18267.310000000001]],"spf":null,"ltp":1.1200000000000001,"atb":[[1.1200000000000001,21114.360000000001]],"spl":null,"spn":null,"atl":null,"batl":null,"id":19924823,"hc":null,"bdatb":null}],"img":null,"tv":2106274.1200000001,"con":null,"marketdefinition":null,"id":"1.258926623"}],"conflatems":null,"op":"mcm","id":3}
{"ct":null,"SegmentType":null,"clk":"APsgAMwiAKMg","heartbeatms":null,"pt":1780839597166,"initialclk":null,"mc":[{"rc":[{"tv":null,"batb":null,"spb":null,"bdatl":null,"trd":null,"spf":null,"ltp":null,"atb":[[1.03,88901.740000000005]],"spl":null,"spn":null,"atl":null,"batl":null,"id":19924823,"hc":null,"bdatb":null}],"img":null,"tv":null,"con":null,"marketdefinition":null,"id":"1.258926623"}],"conflatems":null,"op":"mcm","id":3}
{"ct":null,"SegmentType":null,"clk":"AJIhAO4iAL0g","heartbeatms":null,"pt":1780839597476,"initialclk":null,"mc":[{"rc":[{"tv":null,"batb":null,"spb":null,"bdatl":null,"trd":null,"spf":null,"ltp":null,"atb":null,"spl":null,"spn":null,"atl":[[9.5999999999999996,157.25999999999999]],"batl":null,"id":16570658,"hc":null,"bdatb":null}],"img":null,"tv":null,"con":null,"marketdefinition":null,"id":"1.258926623"}],"conflatems":null,"op":"mcm","id":3}
{"ct":null,"SegmentType":null,"clk":"ALYhAI8jAN4g","heartbeatms":null,"pt":1780839597851,"initialclk":null,"mc":[{"rc":[{"tv":null,"batb":null,"spb":null,"bdatl":null,"trd":null,"spf":null,"ltp":null,"atb":null,"spl":null,"spn":null,"atl":[[9.8000000000000007,85.510000000000005]],"batl":null,"id":16570658,"hc":null,"bdatb":null}],"img":null,"tv":null,"con":null,"marketdefinition":null,"id":"1.258926623"}],"conflatems":null,"op":"mcm","id":3}
{"ct":null,"SegmentType":null,"clk":"AL8hAJ0jAOcg","heartbeatms":null,"pt":1780839597953,"initialclk":null,"mc":[{"rc":[{"tv":1867885.3600000001,"batb":null,"spb":null,"bdatl":null,"trd":[[1.1299999999999999,192766.51999999999],[1.1200000000000001,18269.41]],"spf":null,"ltp":null,"atb":[[1.1200000000000001,21113.310000000001]],"spl":null,"spn":null,"atl":[[1.1299999999999999,9269.5499999999993]],"batl":null,"id":19924823,"hc":null,"bdatb":null}],"img":null,"tv":2106290.7200000002,"con":null,"marketdefinition":null,"id":"1.258926623"}],"conflatems":null,"op":"mcm","id":3}
{"ct":null,"SegmentType":null,"clk":"ANIhAK8jAPog","heartbeatms":null,"pt":1780839598160,"initialclk":null,"mc":[{"rc":[{"tv":238422.19,"batb":null,"spb":null,"bdatl":null,"trd":[[8.8000000000000007,1151.27]],"spf":null,"ltp":null,"atb":[[8.8000000000000007,523.39999999999998]],"spl":null,"spn":null,"atl":null,"batl":null,"id":16570658,"hc":null,"bdatb":null}],"img":null,"tv":2106307.5499999998,"con":null,"marketdefinition":null,"id":"1.258926623"}],"conflatems":null,"op":"mcm","id":3}
{"ct":null,"SegmentType":null,"clk":"AP4hAOIjAKch","heartbeatms":null,"pt":1780839598673,"initialclk":null,"mc":[{"rc":[{"tv":1868058.1100000001,"batb":null,"spb":null,"bdatl":null,"trd":[[1.1299999999999999,192939.26999999999]],"spf":null,"ltp":1.1299999999999999,"atb":null,"spl":null,"spn":null,"atl":[[1.1299999999999999,9183.1700000000001]],"batl":null,"id":19924823,"hc":null,"bdatb":null}],"img":null,"tv":2106480.2999999998,"con":null,"marketdefinition":null,"id":"1.258926623"}],"conflatems":null,"op":"mcm","id":3}
{"ct":null,"SegmentType":null,"clk":"AIciAOwjALEh","heartbeatms":null,"pt":1780839598781,"initialclk":null,"mc":[{"rc":[{"tv":null,"batb":null,"spb":null,"bdatl":null,"trd":null,"spf":null,"ltp":null,"atb":[[1.1000000000000001,59041.519999999997],[1.1100000000000001,57613.459999999999]],"spl":null,"spn":null,"atl":[[1.1299999999999999,10732.639999999999],[1.1399999999999999,22108.290000000001]],"batl":null,"id":19924823,"hc":null,"bdatb":null}],"img":null,"tv":null,"con":null,"marketdefinition":null,"id":"1.258926623"}],"conflatems":null,"op":"mcm","id":3}
{"ct":null,"SegmentType":null,"clk":"AJYiAPkjAMEh","heartbeatms":null,"pt":1780839598984,"initialclk":null,"mc":[{"rc":[{"tv":238762.79999999999,"batb":null,"spb":null,"bdatl":null,"trd":[[9.1999999999999993,234.19999999999999],[9,131.13]],"spf":null,"ltp":9.1999999999999993,"atb":[[9.1999999999999993,644.38999999999999]],"spl":null,"spn":null,"atl":[[9.1999999999999993,0],[9,0]],"batl":null,"id":16570658,"hc":null,"bdatb":null}],"img":null,"tv":2106820.9100000001,"con":null,"marketdefinition":null,"id":"1.258926623"}],"conflatems":null,"op":"mcm","id":3}
{"ct":null,"SegmentType":null,"clk":"AJ4iAIUkAMoh","heartbeatms":null,"pt":1780839599089,"initialclk":null,"mc":[{"rc":[{"tv":null,"batb":null,"spb":null,"bdatl":null,"trd":null,"spf":null,"ltp":null,"atb":[[8.1999999999999993,204.18000000000001]],"spl":null,"spn":null,"atl":null,"batl":null,"id":16570658,"hc":null,"bdatb":null},{"tv":null,"batb":null,"spb":null,"bdatl":null,"trd":null,"spf":null,"ltp":null,"atb":null,"spl":null,"spn":null,"atl":[[1.1299999999999999,11718],[1.1399999999999999,23407.169999999998]],"batl":null,"id":19924823,"hc":null,"bdatb":null}],"img":null,"tv":null,"con":null,"marketdefinition":null,"id":"1.258926623"}],"conflatems":null,"op":"mcm","id":3}
{"ct":null,"SegmentType":null,"clk":"AKgiAI0kANch","heartbeatms":null,"pt":1780839599194,"initialclk":null,"mc":[{"rc":[{"tv":null,"batb":null,"spb":null,"bdatl":null,"trd":null,"spf":null,"ltp":null,"atb":null,"spl":null,"spn":null,"atl":[[9.5999999999999996,1.01]],"batl":null,"id":16570658,"hc":null,"bdatb":null}],"img":null,"tv":null,"con":null,"marketdefinition":null,"id":"1.258926623"}],"conflatems":null,"op":"mcm","id":3}
{"ct":null,"SegmentType":null,"clk":"AK8iAJYkAN8h","heartbeatms":null,"pt":1780839599253,"initialclk":null,"mc":[{"rc":[{"tv":null,"batb":null,"spb":null,"bdatl":null,"trd":null,"spf":null,"ltp":null,"atb":[[8.1999999999999993,23.609999999999999]],"spl":null,"spn":null,"atl":null,"batl":null,"id":16570658,"hc":null,"bdatb":null}],"img":null,"tv":null,"con":null,"marketdefinition":null,"id":"1.258926623"}],"conflatems":null,"op":"mcm","id":3}
{"ct":null,"SegmentType":null,"clk":"ALoiAKAkAO0h","heartbeatms":null,"pt":1780839599358,"initialclk":null,"mc":[{"rc":[{"tv":null,"batb":null,"spb":null,"bdatl":null,"trd":null,"spf":null,"ltp":null,"atb":null,"spl":null,"spn":null,"atl":[[1.1499999999999999,10259.190000000001]],"batl":null,"id":19924823,"hc":null,"bdatb":null}],"img":null,"tv":null,"con":null,"marketdefinition":null,"id":"1.258926623"}],"conflatems":null,"op":"mcm","id":3}
{"ct":null,"SegmentType":null,"clk":"AMMiAKkkAPch","heartbeatms":null,"pt":1780839599454,"initialclk":null,"mc":[{"rc":[{"tv":null,"batb":null,"spb":null,"bdatl":null,"trd":null,"spf":null,"ltp":null,"atb":[[7.7999999999999998,290.13]],"spl":null,"spn":null,"atl":[[9.4000000000000004,315.43000000000001]],"batl":null,"id":16570658,"hc":null,"bdatb":null},{"tv":null,"batb":null,"spb":null,"bdatl":null,"trd":null,"spf":null,"ltp":null,"atb":[[1.1100000000000001,57622.099999999999]],"spl":null,"spn":null,"atl":null,"batl":null,"id":19924823,"hc":null,"bdatb":null}],"img":null,"tv":null,"con":null,"marketdefinition":null,"id":"1.258926623"}],"conflatems":null,"op":"mcm","id":3}
{"ct":null,"SegmentType":null,"clk":"AOYiANEkAJwi","heartbeatms":null,"pt":1780839599886,"initialclk":null,"mc":[{"rc":[{"tv":null,"batb":null,"spb":null,"bdatl":null,"trd":null,"spf":null,"ltp":null,"atb":null,"spl":null,"spn":null,"atl":[[14,5.3799999999999999],[13.5,5.5999999999999996]],"batl":null,"id":16570658,"hc":null,"bdatb":null}],"img":null,"tv":null,"con":null,"marketdefinition":null,"id":"1.258926623"}],"conflatems":null,"op":"mcm","id":3}
{"ct":null,"SegmentType":null,"clk":"AP4iAO8kALoi","heartbeatms":null,"pt":1780839600185,"initialclk":null,"mc":[{"rc":[{"tv":1868286.23,"batb":null,"spb":null,"bdatl":null,"trd":[[1.1299999999999999,193164.13000000001],[1.1200000000000001,18272.669999999998]],"spf":null,"ltp":1.1200000000000001,"atb":[[1.1200000000000001,21111.68]],"spl":null,"spn":null,"atl":[[1.1299999999999999,11605.57]],"batl":null,"id":19924823,"hc":null,"bdatb":null}],"img":null,"tv":2107049.0299999998,"con":null,"marketdefinition":null,"id":"1.258926623"}],"conflatems":null,"op":"mcm","id":3}
{"ct":null,"SegmentType":null,"clk":"AIcjAPwkAMYi","heartbeatms":null,"pt":1780839600301,"initialclk":null,"mc":[{"rc":[{"tv":238777.79000000001,"batb":null,"spb":null,"bdatl":null,"trd":[[9.1999999999999993,249.19]],"spf":null,"ltp":null,"atb":[[9.1999999999999993,636.88999999999999],[9,34.340000000000003]],"spl":null,"spn":null,"atl":null,"batl":null,"id":16570658,"hc":null,"bdatb":null}],"img":null,"tv":2107064.02,"con":null,"marketdefinition":null,"id":"1.258926623"}],"conflatems":null,"op":"mcm","id":3}
{"ct":null,"SegmentType":null,"clk":"AJsjAIslANUi","heartbeatms":null,"pt":1780839600453,"initialclk":null,"mc":[{"rc":[{"tv":null,"batb":null,"spb":null,"bdatl":null,"trd":null,"spf":null,"ltp":null,"atb":[[1.03,88901.990000000005]],"spl":null,"spn":null,"atl":[[1.1299999999999999,12973.07]],"batl":null,"id":19924823,"hc":null,"bdatb":null}],"img":null,"tv":null,"con":null,"marketdefinition":null,"id":"1.258926623"}],"conflatems":null,"op":"mcm","id":3}
{"ct":null,"SegmentType":null,"clk":"AKIjAJclAOAi","heartbeatms":null,"pt":1780839600564,"initialclk":null,"mc":[{"rc":[{"tv":null,"batb":null,"spb":null,"bdatl":null,"trd":null,"spf":null,"ltp":null,"atb":[[8.1999999999999993,9.7200000000000006]],"spl":null,"spn":null,"atl":[[12.5,0]],"batl":null,"id":16570658,"hc":null,"bdatb":null}],"img":null,"tv":null,"con":null,"marketdefinition":null,"id":"1.258926623"}],"conflatems":null,"op":"mcm","id":3}
{"ct":null,"SegmentType":null,"clk":"ALYjAK0lAPoi","heartbeatms":null,"pt":1780839600772,"initialclk":null,"mc":[{"rc":[{"tv":null,"batb":null,"spb":null,"bdatl":null,"trd":null,"spf":null,"ltp":null,"atb":[[9,46.840000000000003]],"spl":null,"spn":null,"atl":null,"batl":null,"id":16570658,"hc":null,"bdatb":null}],"img":null,"tv":null,"con":null,"marketdefinition":null,"id":"1.258926623"}],"conflatems":null,"op":"mcm","id":3}
{"ct":null,"SegmentType":null,"clk":"AMAjAL0lAIgj","heartbeatms":null,"pt":1780839600871,"initialclk":null,"mc":[{"rc":[{"tv":null,"batb":null,"spb":null,"bdatl":null,"trd":null,"spf":null,"ltp":null,"atb":[[1.03,88901.740000000005]],"spl":null,"spn":null,"atl":null,"batl":null,"id":19924823,"hc":null,"bdatb":null}],"img":null,"tv":null,"con":null,"marketdefinition":null,"id":"1.258926623"}],"conflatems":null,"op":"mcm","id":3}
{"ct":null,"SegmentType":null,"clk":"AMgjAL8lAJUj","heartbeatms":null,"pt":1780839600972,"initialclk":null,"mc":[{"rc":[{"tv":1868585.24,"batb":null,"spb":null,"bdatl":null,"trd":[[1.1299999999999999,193463.14000000001]],"spf":null,"ltp":1.1299999999999999,"atb":[[1.0600000000000001,63294.940000000002]],"spl":null,"spn":null,"atl":[[1.1299999999999999,12823.57]],"batl":null,"id":19924823,"hc":null,"bdatb":null}],"img":null,"tv":2107363.0299999998,"con":null,"marketdefinition":null,"id":"1.258926623"}],"conflatems":null,"op":"mcm","id":3}
{"ct":null,"SegmentType":null,"clk":"AM4jAMglAJ0j","heartbeatms":null,"pt":1780839601077,"initialclk":null,"mc":[{"rc":[{"tv":1868597.8999999999,"batb":null,"spb":null,"bdatl":null,"trd":[[1.1299999999999999,193475.79999999999]],"spf":null,"ltp":null,"atb":null,"spl":null,"spn":null,"atl":[[1.1299999999999999,12817.24]],"batl":null,"id":19924823,"hc":null,"bdatb":null}],"img":null,"tv":2107375.6899999999,"con":null,"marketdefinition":null,"id":"1.258926623"}],"conflatems":null,"op":"mcm","id":3}
{"ct":null,"SegmentType":null,"clk":"AOsjAO8lAM8j","heartbeatms":null,"pt":1780839601491,"initialclk":null,"mc":[{"rc":[{"tv":null,"batb":null,"spb":null,"bdatl":null,"trd":null,"spf":null,"ltp":null,"atb":[[1.05,75659.529999999999]],"spl":null,"spn":null,"atl":null,"batl":null,"id":19924823,"hc":null,"bdatb":null}],"img":null,"tv":null,"con":null,"marketdefinition":null,"id":"1.258926623"}],"conflatems":null,"op":"mcm","id":3}
{"ct":null,"SegmentType":null,"clk":"AK8kAMAmAJ0k","heartbeatms":null,"pt":1780839602279,"initialclk":null,"mc":[{"rc":[{"tv":null,"batb":null,"spb":null,"bdatl":null,"trd":null,"spf":null,"ltp":null,"atb":[[1.1100000000000001,57614.599999999999]],"spl":null,"spn":null,"atl":null,"batl":null,"id":19924823,"hc":null,"bdatb":null}],"img":null,"tv":null,"con":null,"marketdefinition":null,"id":"1.258926623"}],"conflatems":null,"op":"mcm","id":3}
{"ct":null,"SegmentType":null,"clk":"ALckAMQmAKUk","heartbeatms":null,"pt":1780839602379,"initialclk":null,"mc":[{"rc":[{"tv":null,"batb":null,"spb":null,"bdatl":null,"trd":null,"spf":null,"ltp":null,"atb":[[1.1100000000000001,57605.959999999999]],"spl":null,"spn":null,"atl":null,"batl":null,"id":19924823,"hc":null,"bdatb":null}],"img":null,"tv":null,"con":null,"marketdefinition":null,"id":"1.258926623"}],"conflatems":null,"op":"mcm","id":3}
{"ct":null,"SegmentType":null,"clk":"AmckANQmALUk","heartbeatms":null,"pt":1780839602489,"initialclk":null,"mc":[{"rc":[{"tv":239501.79000000001,"batb":null,"spb":null,"bdatl":null,"trd":[[9.1999999999999993,973.19000000000005]],"spf":null,"ltp":null,"atb":[[9.1999999999999993,274.88999999999999]],"spl":null,"spn":null,"atl":null,"batl":null,"id":16570658,"hc":null,"bdatb":null},{"tv":null,"batb":null,"spb":null,"bdatl":null,"trd":null,"spf":null,"ltp":null,"atb":[[1.04,73810.729999999996],[1.1000000000000001,59050.160000000003]],"spl":null,"spn":null,"atl":null,"batl":null,"id":19924823,"hc":null,"bdatb":null}],"img":null,"tv":2108099.6899999999,"con":null,"marketdefinition":null,"id":"1.258926623"}],"conflatems":null,"op":"mcm","id":3}
{"ct":null,"SegmentType":null,"clk":"ANEkANsmAL4k","heartbeatms":null,"pt":1780839602587,"initialclk":null,"mc":[{"rc":[{"tv":null,"batb":null,"spb":null,"bdatl":null,"trd":null,"spf":null,"ltp":null,"atb":[[9,72.019999999999996]],"spl":null,"spn":null,"atl":null,"batl":null,"id":16570658,"hc":null,"bdatb":null},{"tv":null,"batb":null,"spb":null,"bdatl":null,"trd":null,"spf":null,"ltp":null,"atb":null,"spl":null,"spn":null,"atl":[[1.1399999999999999,22108.290000000001]],"batl":null,"id":19924823,"hc":null,"bdatb":null}],"img":null,"tv":null,"con":null,"marketdefinition":null,"id":"1.258926623"}],"conflatems":null,"op":"mcm","id":3}
{"ct":null,"SegmentType":null,"clk":"AOIkAO0mAM4k","heartbeatms":null,"pt":1780839602790,"initialclk":null,"mc":[{"rc":[{"tv":null,"batb":null,"spb":null,"bdatl":null,"trd":null,"spf":null,"ltp":null,"atb":[[9,46.840000000000003]],"spl":null,"spn":null,"atl":null,"batl":null,"id":16570658,"hc":null,"bdatb":null}],"img":null,"tv":null,"con":null,"marketdefinition":null,"id":"1.258926623"}],"conflatems":null,"op":"mcm","id":3}
{"ct":null,"SegmentType":null,"clk":"AP0kAIcnAPIk","heartbeatms":null,"pt":1780839603055,"initialclk":null,"mc":[{"rc":[{"tv":null,"batb":null,"spb":null,"bdatl":null,"trd":null,"spf":null,"ltp":null,"atb":[[1.03,88931.740000000005]],"spl":null,"spn":null,"atl":null,"batl":null,"id":19924823,"hc":null,"bdatb":null}],"img":null,"tv":null,"con":null,"marketdefinition":null,"id":"1.258926623"}],"conflatems":null,"op":"mcm","id":3}
{"ct":null,"SegmentType":null,"clk":"AIglAJInAPok","heartbeatms":null,"pt":1780839603158,"initialclk":null,"mc":[{"rc":[{"tv":null,"batb":null,"spb":null,"bdatl":null,"trd":null,"spf":null,"ltp":null,"atb":null,"spl":null,"spn":null,"atl":[[2.2000000000000002,0]],"batl":null,"id":19924823,"hc":null,"bdatb":null}],"img":null,"tv":null,"con":null,"marketdefinition":null,"id":"1.258926623"}],"conflatems":null,"op":"mcm","id":3}
{"ct":null,"SegmentType":null,"clk":"AJklAKMnAIsl","heartbeatms":null,"pt":1780839603363,"initialclk":null,"mc":[{"rc":[{"tv":1868612.3899999999,"batb":null,"spb":null,"bdatl":null,"trd":[[1.1299999999999999,193490.29000000001]],"spf":null,"ltp":null,"atb":null,"spl":null,"spn":null,"atl":[[1.1299999999999999,12809.99]],"batl":null,"id":19924823,"hc":null,"bdatb":null}],"img":null,"tv":2108114.1800000002,"con":null,"marketdefinition":null,"id":"1.258926623"}],"conflatems":null,"op":"mcm","id":3}
{"ct":null,"SegmentType":null,"clk":"ALYlAMMnAK8l","heartbeatms":null,"pt":1780839603674,"initialclk":null,"mc":[{"rc":[{"tv":1868614.74,"batb":null,"spb":null,"bdatl":null,"trd":[[1.1299999999999999,193492.64000000001]],"spf":null,"ltp":null,"atb":null,"spl":null,"spn":null,"atl":[[1.1299999999999999,12808.81]],"batl":null,"id":19924823,"hc":null,"bdatb":null}],"img":null,"tv":2108116.5299999998,"con":null,"marketdefinition":null,"id":"1.258926623"}],"conflatems":null,"op":"mcm","id":3}
{"ct":null,"SegmentType":null,"clk":"ALwlAM0nALsl","heartbeatms":null,"pt":1780839603777,"initialclk":null,"mc":[{"rc":[{"tv":null,"batb":null,"spb":null,"bdatl":null,"trd":null,"spf":null,"ltp":null,"atb":[[1.02,90703.919999999998]],"spl":null,"spn":null,"atl":null,"batl":null,"id":19924823,"hc":null,"bdatb":null}],"img":null,"tv":null,"con":null,"marketdefinition":null,"id":"1.258926623"}],"conflatems":null,"op":"mcm","id":3}
{"ct":null,"SegmentType":null,"clk":"AMQlANMnAMIl","heartbeatms":null,"pt":1780839603878,"initialclk":null,"mc":[{"rc":[{"tv":239701.79000000001,"batb":null,"spb":null,"bdatl":null,"trd":[[9.1999999999999993,1173.1900000000001]],"spf":null,"ltp":null,"atb":[[9.1999999999999993,174.88999999999999]],"spl":null,"spn":null,"atl":null,"batl":null,"id":16570658,"hc":null,"bdatb":null}],"img":null,"tv":2108316.5299999998,"con":null,"marketdefinition":null,"id":"1.258926623"}],"conflatems":null,"op":"mcm","id":3}
{"ct":null,"SegmentType":null,"clk":"AM4lAN0nAMsl","heartbeatms":null,"pt":1780839603984,"initialclk":null,"mc":[{"rc":[{"tv":239901.79000000001,"batb":null,"spb":null,"bdatl":null,"trd":[[9.1999999999999993,1373.1900000000001]],"spf":null,"ltp":null,"atb":[[9.1999999999999993,74.890000000000001],[8.5999999999999996,1146.29]],"spl":null,"spn":null,"atl":null,"batl":null,"id":16570658,"hc":null,"bdatb":null},{"tv":1868615.25,"batb":null,"spb":null,"bdatl":null,"trd":[[1.1299999999999999,193493.14999999999]],"spf":null,"ltp":null,"atb":null,"spl":null,"spn":null,"atl":[[1.1299999999999999,12808.549999999999]],"batl":null,"id":19924823,"hc":null,"bdatb":null}],"img":null,"tv":2108517.04,"con":null,"marketdefinition":null,"id":"1.258926623"}],"conflatems":null,"op":"mcm","id":3}
{"ct":null,"SegmentType":null,"clk":"AOMlAO8nAN4l","heartbeatms":null,"pt":1780839604189,"initialclk":null,"mc":[{"rc":[{"tv":1868788.01,"batb":null,"spb":null,"bdatl":null,"trd":[[1.1299999999999999,193665.91]],"spf":null,"ltp":null,"atb":null,"spl":null,"spn":null,"atl":[[1.1299999999999999,12722.18]],"batl":null,"id":19924823,"hc":null,"bdatb":null}],"img":null,"tv":2108689.7999999998,"con":null,"marketdefinition":null,"id":"1.258926623"}],"conflatems":null,"op":"mcm","id":3}
{"ct":null,"SegmentType":null,"clk":"APYlAIIoAPEl","heartbeatms":null,"pt":1780839604353,"initialclk":null,"mc":[{"rc":[{"tv":null,"batb":null,"spb":null,"bdatl":null,"trd":null,"spf":null,"ltp":null,"atb":[[1.03,88930.990000000005]],"spl":null,"spn":null,"atl":null,"batl":null,"id":19924823,"hc":null,"bdatb":null}],"img":null,"tv":null,"con":null,"marketdefinition":null,"id":"1.258926623"}],"conflatems":null,"op":"mcm","id":3}
{"ct":null,"SegmentType":null,"clk":"AI8mAJcoAIwm","heartbeatms":null,"pt":1780839604655,"initialclk":null,"mc":[{"rc":[{"tv":239918.51999999999,"batb":null,"spb":null,"bdatl":null,"trd":[[9.1999999999999993,1389.9200000000001]],"spf":null,"ltp":null,"atb":[[9.1999999999999993,66.530000000000001]],"spl":null,"spn":null,"atl":null,"batl":null,"id":16570658,"hc":null,"bdatb":null}],"img":null,"tv":2108706.5299999998,"con":null,"marketdefinition":null,"id":"1.258926623"}],"conflatems":null,"op":"mcm","id":3}
{"ct":null,"SegmentType":null,"clk":"AJkmAKAoAJcm","heartbeatms":null,"pt":1780839604761,"initialclk":null,"mc":[{"rc":[{"tv":239920.48999999999,"batb":null,"spb":null,"bdatl":null,"trd":[[9.1999999999999993,1391.8900000000001]],"spf":null,"ltp":null,"atb":[[9.1999999999999993,65.540000000000006]],"spl":null,"spn":null,"atl":null,"batl":null,"id":16570658,"hc":null,"bdatb":null}],"img":null,"tv":2108708.5,"con":null,"marketdefinition":null,"id":"1.258926623"}],"conflatems":null,"op":"mcm","id":3}
{"ct":null,"SegmentType":null,"clk":"AKImAKkoAKAm","heartbeatms":null,"pt":1780839604863,"initialclk":null,"mc":[{"rc":[{"tv":null,"batb":null,"spb":null,"bdatl":null,"trd":null,"spf":null,"ltp":null,"atb":[[1.1200000000000001,20248.759999999998]],"spl":null,"spn":null,"atl":null,"batl":null,"id":19924823,"hc":null,"bdatb":null}],"img":null,"tv":null,"con":null,"marketdefinition":null,"id":"1.258926623"}],"conflatems":null,"op":"mcm","id":3}
{"ct":null,"SegmentType":null,"clk":"ALQmAL4oALYm","heartbeatms":null,"pt":1780839605071,"initialclk":null,"mc":[{"rc":[{"tv":240051.57000000001,"batb":null,"spb":null,"bdatl":null,"trd":[[9.1999999999999993,1522.97]],"spf":null,"ltp":null,"atb":[[9.1999999999999993,0]],"spl":null,"spn":null,"atl":[[9.1999999999999993,201.75999999999999]],"batl":null,"id":16570658,"hc":null,"bdatb":null}],"img":null,"tv":2108839.5800000001,"con":null,"marketdefinition":null,"id":"1.258926623"}],"conflatems":null,"op":"mcm","id":3}
{"ct":null,"SegmentType":null,"clk":"AMMmANMoAMkm","heartbeatms":null,"pt":1780839605278,"initialclk":null,"mc":[{"rc":[{"tv":null,"batb":null,"spb":null,"bdatl":null,"trd":null,"spf":null,"ltp":null,"atb":[[9,34.340000000000003]],"spl":null,"spn":null,"atl":null,"batl":null,"id":16570658,"hc":null,"bdatb":null}],"img":null,"tv":null,"con":null,"marketdefinition":null,"id":"1.258926623"}],"conflatems":null,"op":"mcm","id":3}
{"ct":null,"SegmentType":null,"clk":"AMsmANkoANAm","heartbeatms":null,"pt":1780839605382,"initialclk":null,"mc":[{"rc":[{"tv":null,"batb":null,"spb":null,"bdatl":null,"trd":null,"spf":null,"ltp":null,"atb":[[8.8000000000000007,659.67999999999995]],"spl":null,"spn":null,"atl":null,"batl":null,"id":16570658,"hc":null,"bdatb":null}],"img":null,"tv":null,"con":null,"marketdefinition":null,"id":"1.258926623"}],"conflatems":null,"op":"mcm","id":3}
{"ct":null,"SegmentType":null,"clk":"ANYmAN8oANsm","heartbeatms":null,"pt":1780839605487,"initialclk":null,"mc":[{"rc":[{"tv":null,"batb":null,"spb":null,"bdatl":null,"trd":null,"spf":null,"ltp":null,"atb":[[8.5999999999999996,1159.4500000000001]],"spl":null,"spn":null,"atl":[[9.8000000000000007,238.56999999999999]],"batl":null,"id":16570658,"hc":null,"bdatb":null},{"tv":null,"batb":null,"spb":null,"bdatl":null,"trd":null,"spf":null,"ltp":null,"atb":[[1.01,93233.490000000005],[1.1200000000000001,20320.959999999999]],"spl":null,"spn":null,"atl":null,"batl":null,"id":19924823,"hc":null,"bdatb":null}],"img":null,"tv":null,"con":null,"marketdefinition":null,"id":"1.258926623"}],"conflatems":null,"op":"mcm","id":3}
{"ct":null,"SegmentType":null,"clk":"AOImAOooAOEm","heartbeatms":null,"pt":1780839605590,"initialclk":null,"mc":[{"rc":[{"tv":null,"batb":null,"spb":null,"bdatl":null,"trd":null,"spf":null,"ltp":null,"atb":[[1.1200000000000001,20320.529999999999]],"spl":null,"spn":null,"atl":null,"batl":null,"id":19924823,"hc":null,"bdatb":null}],"img":null,"tv":null,"con":null,"marketdefinition":null,"id":"1.258926623"}],"conflatems":null,"op":"mcm","id":3}
{"ct":null,"SegmentType":null,"clk":"AIInAIkpAPwm","heartbeatms":null,"pt":1780839605857,"initialclk":null,"mc":[{"rc":[{"tv":240055.87,"batb":null,"spb":null,"bdatl":null,"trd":[[9,135.43000000000001]],"spf":null,"ltp":9,"atb":[[9,32.189999999999998]],"spl":null,"spn":null,"atl":null,"batl":null,"id":16570658,"hc":null,"bdatb":null}],"img":null,"tv":2108843.8799999999,"con":null,"marketdefinition":null,"id":"1.258926623"}],"conflatems":null,"op":"mcm","id":3}
{"ct":null,"SegmentType":null,"clk":"AKAnALApAJUn","heartbeatms":null,"pt":1780839606173,"initialclk":null,"mc":[{"rc":[{"tv":null,"batb":null,"spb":null,"bdatl":null,"trd":null,"spf":null,"ltp":null,"atb":null,"spl":null,"spn":null,"atl":[[9.1999999999999993,67.299999999999997]],"batl":null,"id":16570658,"hc":null,"bdatb":null}],"img":null,"tv":null,"con":null,"marketdefinition":null,"id":"1.258926623"}],"conflatems":null,"op":"mcm","id":3}
{"ct":null,"SegmentType":null,"clk":"ALwnAMMpAKwn","heartbeatms":null,"pt":1780839606477,"initialclk":null,"mc":[{"rc":[{"tv":240057.59,"batb":null,"spb":null,"bdatl":null,"trd":[[9,137.15000000000001]],"spf":null,"ltp":null,"atb":[[9,31.329999999999998]],"spl":null,"spn":null,"atl":[[9.1999999999999993,67.329999999999998]],"batl":null,"id":16570658,"hc":null,"bdatb":null}],"img":null,"tv":2108845.6000000001,"con":null,"marketdefinition":null,"id":"1.258926623"}],"conflatems":null,"op":"mcm","id":3}
{"ct":null,"SegmentType":null,"clk":"AM8nANMpAMAn","heartbeatms":null,"pt":1780839606684,"initialclk":null,"mc":[{"rc":[{"tv":null,"batb":null,"spb":null,"bdatl":null,"trd":null,"spf":null,"ltp":null,"atb":[[8.5999999999999996,818.48000000000002]],"spl":null,"spn":null,"atl":null,"batl":null,"id":16570658,"hc":null,"bdatb":null}],"img":null,"tv":null,"con":null,"marketdefinition":null,"id":"1.258926623"}],"conflatems":null,"op":"mcm","id":3}
{"ct":null,"SegmentType":null,"clk":"AOAnAOIpANEn","heartbeatms":null,"pt":1780839606890,"initialclk":null,"mc":[{"rc":[{"tv":null,"batb":null,"spb":null,"bdatl":null,"trd":null,"spf":null,"ltp":null,"atb":[[9,302.76999999999998]],"spl":null,"spn":null,"atl":null,"batl":null,"id":16570658,"hc":null,"bdatb":null}],"img":null,"tv":null,"con":null,"marketdefinition":null,"id":"1.258926623"}],"conflatems":null,"op":"mcm","id":3}
{"ct":null,"SegmentType":null,"clk":"AOcnAO0pANkn","heartbeatms":null,"pt":1780839606994,"initialclk":null,"mc":[{"rc":[{"tv":1868836.99,"batb":null,"spb":null,"bdatl":null,"trd":[[1.1299999999999999,193671.70999999999],[1.1200000000000001,18315.849999999999]],"spf":null,"ltp":1.1200000000000001,"atb":[[1.1200000000000001,20298.939999999999]],"spl":null,"spn":null,"atl":[[1.1299999999999999,12719.27]],"batl":null,"id":19924823,"hc":null,"bdatb":null}],"img":null,"tv":2108894.5800000001,"con":null,"marketdefinition":null,"id":"1.258926623"}],"conflatems":null,"op":"mcm","id":3}
{"ct":null,"SegmentType":null,"clk":"APEnAPUpANwn","heartbeatms":null,"pt":1780839607059,"initialclk":null,"mc":[{"rc":[{"tv":null,"batb":null,"spb":null,"bdatl":null,"trd":null,"spf":null,"ltp":null,"atb":[[7.7999999999999998,477.13]],"spl":null,"spn":null,"atl":null,"batl":null,"id":16570658,"hc":null,"bdatb":null},{"tv":1868837.8600000001,"batb":null,"spb":null,"bdatl":null,"trd":[[1.1299999999999999,193672.57999999999]],"spf":null,"ltp":1.1299999999999999,"atb":null,"spl":null,"spn":null,"atl":[[1.1299999999999999,12718.84],[1.1499999999999999,11527.57]],"batl":null,"id":19924823,"hc":null,"bdatb":null}],"img":null,"tv":2108895.4500000002,"con":null,"marketdefinition":null,"id":"1.258926623"}],"conflatems":null,"op":"mcm","id":3}
{"ct":null,"SegmentType":null,"clk":"ALgoAM8qAK4o","heartbeatms":null,"pt":1780839607995,"initialclk":null,"mc":[{"rc":[{"tv":null,"batb":null,"spb":null,"bdatl":null,"trd":null,"spf":null,"ltp":null,"atb":[[7.7999999999999998,290.13],[8.8000000000000007,564.27999999999997],[7.5999999999999996,101.64],[8.5999999999999996,712.69000000000005],[8,286.92000000000002]],"spl":null,"spn":null,"atl":[[9.8000000000000007,85.510000000000005]],"batl":null,"id":16570658,"hc":null,"bdatb":null},{"tv":null,"batb":null,"spb":null,"bdatl":null,"trd":null,"spf":null,"ltp":null,"atb":[[1.1100000000000001,56254.610000000001]],"spl":null,"spn":null,"atl":[[1.1299999999999999,13067.34],[1.1399999999999999,22507.040000000001],[1.1499999999999999,10259.190000000001]],"batl":null,"id":19924823,"hc":null,"bdatb":null}],"img":null,"tv":null,"con":null,"marketdefinition":null,"id":"1.258926623"}],"conflatems":null,"op":"mcm","id":3}
{"ct":null,"SegmentType":null,"clk":"AMAoANUqALYo","heartbeatms":null,"pt":1780839608086,"initialclk":null,"mc":[{"rc":[{"tv":null,"batb":null,"spb":null,"bdatl":null,"trd":null,"spf":null,"ltp":null,"atb":[[8.1999999999999993,261.18000000000001],[8.5999999999999996,647.69000000000005],[8,369.02999999999997]],"spl":null,"spn":null,"atl":[[12.5,100.83],[12,271.06],[11.5,386.39999999999998]],"batl":null,"id":16570658,"hc":null,"bdatb":null},{"tv":null,"batb":null,"spb":null,"bdatl":null,"trd":null,"spf":null,"ltp":null,"atb":[[1.0900000000000001,39618.550000000003]],"spl":null,"spn":null,"atl":[[1.1299999999999999,11595.34]],"batl":null,"id":19924823,"hc":null,"bdatb":null}],"img":null,"tv":null,"con":null,"marketdefinition":null,"id":"1.258926623"}],"conflatems":null,"op":"mcm","id":3}
{"ct":null,"SegmentType":null,"clk":"AMUoANwqAMAo","heartbeatms":null,"pt":1780839608189,"initialclk":null,"mc":[{"rc":[{"tv":null,"batb":null,"spb":null,"bdatl":null,"trd":null,"spf":null,"ltp":null,"atb":null,"spl":null,"spn":null,"atl":[[1.1299999999999999,10227.84]],"batl":null,"id":19924823,"hc":null,"bdatb":null}],"img":null,"tv":null,"con":null,"marketdefinition":null,"id":"1.258926623"}],"conflatems":null,"op":"mcm","id":3}
{"ct":null,"SegmentType":null,"clk":"AM8oAOMqAMgo","heartbeatms":null,"pt":1780839608290,"initialclk":null,"mc":[{"rc":[{"tv":1868840.22,"batb":null,"spb":null,"bdatl":null,"trd":[[1.1299999999999999,193674.94]],"spf":null,"ltp":null,"atb":null,"spl":null,"spn":null,"atl":[[1.1299999999999999,10226.66]],"batl":null,"id":19924823,"hc":null,"bdatb":null}],"img":null,"tv":2108897.8100000001,"con":null,"marketdefinition":null,"id":"1.258926623"}],"conflatems":null,"op":"mcm","id":3}
{"ct":null,"SegmentType":null,"clk":"ANcoAO0qANIo","heartbeatms":null,"pt":1780839608394,"initialclk":null,"mc":[{"rc":[{"tv":null,"batb":null,"spb":null,"bdatl":null,"trd":null,"spf":null,"ltp":null,"atb":[[7.7999999999999998,0],[8.8000000000000007,295.22000000000003],[7.5999999999999996,10.6],[8.5999999999999996,573.71000000000004]],"spl":null,"spn":null,"atl":[[11,105.34],[10.5,2]],"batl":null,"id":16570658,"hc":null,"bdatb":null}],"img":null,"tv":null,"con":null,"marketdefinition":null,"id":"1.258926623"}],"conflatems":null,"op":"mcm","id":3}
{"ct":null,"SegmentType":null,"clk":"AOAoAPYqAN0o","heartbeatms":null,"pt":1780839608498,"initialclk":null,"mc":[{"rc":[{"tv":null,"batb":null,"spb":null,"bdatl":null,"trd":null,"spf":null,"ltp":null,"atb":[[8.8000000000000007,0],[9,271.44]],"spl":null,"spn":null,"atl":[[9.4000000000000004,181.53],[9.1999999999999993,0.029999999999999999]],"batl":null,"id":16570658,"hc":null,"bdatb":null},{"tv":1868840.8799999999,"batb":null,"spb":null,"bdatl":null,"trd":[[1.1200000000000001,18316.509999999998]],"spf":null,"ltp":1.1200000000000001,"atb":[[1.1200000000000001,19230.970000000001]],"spl":null,"spn":null,"atl":[[1.1299999999999999,9241.2999999999993]],"batl":null,"id":19924823,"hc":null,"bdatb":null}],"img":null,"tv":2108898.4700000002,"con":null,"marketdefinition":null,"id":"1.258926623"}],"conflatems":null,"op":"mcm","id":3}
{"ct":null,"SegmentType":null,"clk":"APEoAIYrAPUo","heartbeatms":null,"pt":1780839608664,"initialclk":null,"mc":[{"rc":[{"tv":null,"batb":null,"spb":null,"bdatl":null,"trd":null,"spf":null,"ltp":null,"atb":null,"spl":null,"spn":null,"atl":[[11.5,60.530000000000001]],"batl":null,"id":16570658,"hc":null,"bdatb":null}],"img":null,"tv":null,"con":null,"marketdefinition":null,"id":"1.258926623"}],"conflatems":null,"op":"mcm","id":3}
{"ct":null,"SegmentType":null,"clk":"APwoAI0rAP0o","heartbeatms":null,"pt":1780839608762,"initialclk":null,"mc":[{"rc":[{"tv":null,"batb":null,"spb":null,"bdatl":null,"trd":null,"spf":null,"ltp":null,"atb":[[1.1000000000000001,60421.18]],"spl":null,"spn":null,"atl":[[1.1399999999999999,22888.869999999999]],"batl":null,"id":19924823,"hc":null,"bdatb":null}],"img":null,"tv":null,"con":null,"marketdefinition":null,"id":"1.258926623"}],"conflatems":null,"op":"mcm","id":3}
{"ct":null,"SegmentType":null,"clk":"AIcpAJsrAIwp","heartbeatms":null,"pt":1780839608918,"initialclk":null,"mc":[{"rc":[{"tv":null,"batb":null,"spb":null,"bdatl":null,"trd":null,"spf":null,"ltp":null,"atb":[[1.1100000000000001,54895.940000000002]],"spl":null,"spn":null,"atl":[[1.1299999999999999,8525.6100000000006]],"batl":null,"id":19924823,"hc":null,"bdatb":null}],"img":null,"tv":null,"con":null,"marketdefinition":null,"id":"1.258926623"}],"conflatems":null,"op":"mcm","id":3}
{"ct":null,"SegmentType":null,"clk":"AI0pAKArAJYp","heartbeatms":null,"pt":1780839608967,"initialclk":null,"mc":[{"rc":[{"tv":1868855.3799999999,"batb":null,"spb":null,"bdatl":null,"trd":[[1.1299999999999999,193689.44]],"spf":null,"ltp":1.1299999999999999,"atb":null,"spl":null,"spn":null,"atl":[[1.1299999999999999,8518.3600000000006]],"batl":null,"id":19924823,"hc":null,"bdatb":null}],"img":null,"tv":2108912.9700000002,"con":null,"marketdefinition":null,"id":"1.258926623"}],"conflatems":null,"op":"mcm","id":3}
{"ct":null,"SegmentType":null,"clk":"AJYpAKkrAJ8p","heartbeatms":null,"pt":1780839609069,"initialclk":null,"mc":[{"rc":[{"tv":null,"batb":null,"spb":null,"bdatl":null,"trd":null,"spf":null,"ltp":null,"atb":null,"spl":null,"spn":null,"atl":[[9.1999999999999993,5.0300000000000002]],"batl":null,"id":16570658,"hc":null,"bdatb":null}],"img":null,"tv":null,"con":null,"marketdefinition":null,"id":"1.258926623"}],"conflatems":null,"op":"mcm","id":3}
{"ct":null,"SegmentType":null,"clk":"ALUpAMQrAMAp","heartbeatms":null,"pt":1780839609381,"initialclk":null,"mc":[{"rc":[{"tv":1868857.4399999999,"batb":null,"spb":null,"bdatl":null,"trd":[[1.1299999999999999,193691.5]],"spf":null,"ltp":null,"atb":null,"spl":null,"spn":null,"atl":[[1.1299999999999999,8517.3299999999999]],"batl":null,"id":19924823,"hc":null,"bdatb":null}],"img":null,"tv":2108915.0299999998,"con":null,"marketdefinition":null,"id":"1.258926623"}],"conflatems":null,"op":"mcm","id":3}
{"ct":null,"SegmentType":null,"clk":"ANkpAOQrAOwp","heartbeatms":null,"pt":1780839609799,"initialclk":null,"mc":[{"rc":[{"tv":null,"batb":null,"spb":null,"bdatl":null,"trd":null,"spf":null,"ltp":null,"atb":[[1.1200000000000001,19086.580000000002]],"spl":null,"spn":null,"atl":null,"batl":null,"id":19924823,"hc":null,"bdatb":null}],"img":null,"tv":null,"con":null,"marketdefinition":null,"id":"1.258926623"}],"conflatems":null,"op":"mcm","id":3}
{"ct":null,"SegmentType":null,"clk":"AOgpAPcrAIIq","heartbeatms":null,"pt":1780839610062,"initialclk":null,"mc":[{"rc":[{"tv":1868863.24,"batb":null,"spb":null,"bdatl":null,"trd":[[1.1299999999999999,193697.29999999999]],"spf":null,"ltp":null,"atb":null,"spl":null,"spn":null,"atl":[[1.1299999999999999,8514.4300000000003]],"batl":null,"id":19924823,"hc":null,"bdatb":null}],"img":null,"tv":2108920.8300000001,"con":null,"marketdefinition":null,"id":"1.258926623"}],"conflatems":null,"op":"mcm","id":3}
{"ct":null,"SegmentType":null,"clk":"APwpAJIsAKMq","heartbeatms":null,"pt":1780839610265,"initialclk":null,"mc":[{"rc":[{"tv":1870863.27,"batb":null,"spb":null,"bdatl":null,"trd":[[1.1299999999999999,195697.32999999999]],"spf":null,"ltp":null,"atb":null,"spl":null,"spn":null,"atl":[[1.1299999999999999,7514.4099999999999]],"batl":null,"id":19924823,"hc":null,"bdatb":null}],"img":null,"tv":2110920.8599999999,"con":null,"marketdefinition":null,"id":"1.258926623"}],"conflatems":null,"op":"mcm","id":3}
{"ct":null,"SegmentType":null,"clk":"AIQqAJUsAKoq","heartbeatms":null,"pt":1780839610364,"initialclk":null,"mc":[{"rc":[{"tv":null,"batb":null,"spb":null,"bdatl":null,"trd":null,"spf":null,"ltp":null,"atb":[[1.1200000000000001,19134.66]],"spl":null,"spn":null,"atl":null,"batl":null,"id":19924823,"hc":null,"bdatb":null}],"img":null,"tv":null,"con":null,"marketdefinition":null,"id":"1.258926623"}],"conflatems":null,"op":"mcm","id":3}
{"ct":null,"SegmentType":null,"clk":"AMUqANEsAO0q","heartbeatms":null,"pt":1780839611095,"initialclk":null,"mc":[{"rc":[{"tv":1870869.04,"batb":null,"spb":null,"bdatl":null,"trd":[[1.1299999999999999,195703.10000000001]],"spf":null,"ltp":null,"atb":null,"spl":null,"spn":null,"atl":[[1.1299999999999999,7511.5299999999997]],"batl":null,"id":19924823,"hc":null,"bdatb":null}],"img":null,"tv":2110926.6299999999,"con":null,"marketdefinition":null,"id":"1.258926623"}],"conflatems":null,"op":"mcm","id":3}
{"ct":null,"SegmentType":null,"clk":"ANIqANksAPQq","heartbeatms":null,"pt":1780839611195,"initialclk":null,"mc":[{"rc":[{"tv":1870873.04,"batb":null,"spb":null,"bdatl":null,"trd":[[1.1200000000000001,18320.509999999998]],"spf":null,"ltp":1.1200000000000001,"atb":[[1.1200000000000001,19132.66]],"spl":null,"spn":null,"atl":null,"batl":null,"id":19924823,"hc":null,"bdatb":null}],"img":null,"tv":2110930.6299999999,"con":null,"marketdefinition":null,"id":"1.258926623"}],"conflatems":null,"op":"mcm","id":3}
{"ct":null,"SegmentType":null,"clk":"AKQrAKwtALsr","heartbeatms":null,"pt":1780839612077,"initialclk":null,"mc":[{"rc":[{"tv":null,"batb":null,"spb":null,"bdatl":null,"trd":null,"spf":null,"ltp":null,"atb":null,"spl":null,"spn":null,"atl":[[10,96.930000000000007]],"batl":null,"id":16570658,"hc":null,"bdatb":null},{"tv":null,"batb":null,"spb":null,"bdatl":null,"trd":null,"spf":null,"ltp":null,"atb":[[1.1100000000000001,54889.800000000003]],"spl":null,"spn":null,"atl":null,"batl":null,"id":19924823,"hc":null,"bdatb":null}],"img":null,"tv":null,"con":null,"marketdefinition":null,"id":"1.258926623"}],"conflatems":null,"op":"mcm","id":3}
{"ct":null,"SegmentType":null,"clk":"ANcrAN8tAOwr","heartbeatms":null,"pt":1780839613039,"initialclk":null,"mc":[{"rc":[{"tv":1870939.04,"batb":null,"spb":null,"bdatl":null,"trd":[[1.1200000000000001,18386.509999999998]],"spf":null,"ltp":null,"atb":[[1.1200000000000001,19099.66]],"spl":null,"spn":null,"atl":null,"batl":null,"id":19924823,"hc":null,"bdatb":null}],"img":null,"tv":2110996.6299999999,"con":null,"marketdefinition":null,"id":"1.258926623"}],"conflatems":null,"op":"mcm","id":3}
{"ct":null,"SegmentType":null,"clk":"AOsrAPUtAPor","heartbeatms":null,"pt":1780839613075,"initialclk":null,"mc":[{"rc":[{"tv":null,"batb":null,"spb":null,"bdatl":null,"trd":null,"spf":null,"ltp":null,"atb":[[9,0]],"spl":null,"spn":null,"atl":null,"batl":null,"id":16570658,"hc":null,"bdatb":null}],"img":null,"tv":null,"con":null,"marketdefinition":null,"id":"1.258926623"}],"conflatems":null,"op":"mcm","id":3}
{"ct":null,"SegmentType":null,"clk":"AIEsAJ4uAJ4s","heartbeatms":null,"pt":1780839613166,"initialclk":null,"mc":[{"rc":[{"tv":1870944.8400000001,"batb":null,"spb":null,"bdatl":null,"trd":[[1.1299999999999999,195708.89999999999]],"spf":null,"ltp":1.1299999999999999,"atb":null,"spl":null,"spn":null,"atl":[[1.1299999999999999,7508.6300000000001]],"batl":null,"id":19924823,"hc":null,"bdatb":null}],"img":null,"tv":2111002.4300000002,"con":null,"marketdefinition":null,"id":"1.258926623"}],"conflatems":null,"op":"mcm","id":3}
{"ct":null,"SegmentType":null,"clk":"AJwsALkuAL4s","heartbeatms":null,"pt":1780839613476,"initialclk":null,"mc":[{"rc":[{"tv":null,"batb":null,"spb":null,"bdatl":null,"trd":null,"spf":null,"ltp":null,"atb":null,"spl":null,"spn":null,"atl":[[9.4000000000000004,1]],"batl":null,"id":16570658,"hc":null,"bdatb":null}],"img":null,"tv":null,"con":null,"marketdefinition":null,"id":"1.258926623"}],"conflatems":null,"op":"mcm","id":3}
{"ct":null,"SegmentType":null,"clk":"AKUsAMYuAMos","heartbeatms":null,"pt":1780839613581,"initialclk":null,"mc":[{"rc":[{"tv":null,"batb":null,"spb":null,"bdatl":null,"trd":null,"spf":null,"ltp":null,"atb":null,"spl":null,"spn":null,"atl":[[1.1299999999999999,9670.5499999999993]],"batl":null,"id":19924823,"hc":null,"bdatb":null}],"img":null,"tv":null,"con":null,"marketdefinition":null,"id":"1.258926623"}],"conflatems":null,"op":"mcm","id":3}
{"ct":null,"SegmentType":null,"clk":"AK4sANEuANYs","heartbeatms":null,"pt":1780839613687,"initialclk":null,"mc":[{"rc":[{"tv":240059.04000000001,"batb":null,"spb":null,"bdatl":null,"trd":[[8.5999999999999996,1218.99]],"spf":null,"ltp":8.5999999999999996,"atb":[[8.5999999999999996,572.99000000000001]],"spl":null,"spn":null,"atl":null,"batl":null,"id":16570658,"hc":null,"bdatb":null},{"tv":1870965.9199999999,"batb":null,"spb":null,"bdatl":null,"trd":[[1.1299999999999999,195729.98000000001]],"spf":null,"ltp":null,"atb":null,"spl":null,"spn":null,"atl":[[1.1299999999999999,9660.0100000000002]],"batl":null,"id":19924823,"hc":null,"bdatb":null}],"img":null,"tv":2111024.96,"con":null,"marketdefinition":null,"id":"1.258926623"}],"conflatems":null,"op":"mcm","id":3}
{"ct":null,"SegmentType":null,"clk":"AM0sAPouAPUs","heartbeatms":null,"pt":1780839614097,"initialclk":null,"mc":[{"rc":[{"tv":null,"batb":null,"spb":null,"bdatl":null,"trd":null,"spf":null,"ltp":null,"atb":null,"spl":null,"spn":null,"atl":[[9,0.96999999999999997]],"batl":null,"id":16570658,"hc":null,"bdatb":null},{"tv":1875008.23,"batb":null,"spb":null,"bdatl":null,"trd":[[1.1299999999999999,199772.29000000001]],"spf":null,"ltp":null,"atb":null,"spl":null,"spn":null,"atl":[[1.1299999999999999,7638.8500000000004]],"batl":null,"id":19924823,"hc":null,"bdatb":null}],"img":null,"tv":2115067.27,"con":null,"marketdefinition":null,"id":"1.258926623"}],"conflatems":null,"op":"mcm","id":3}
{"ct":null,"SegmentType":null,"clk":"APwsAKovAKEt","heartbeatms":null,"pt":1780839614567,"initialclk":null,"mc":[{"rc":[{"tv":1875022.73,"batb":null,"spb":null,"bdatl":null,"trd":[[1.1299999999999999,199786.79000000001]],"spf":null,"ltp":null,"atb":null,"spl":null,"spn":null,"atl":[[1.1299999999999999,7631.6099999999997]],"batl":null,"id":19924823,"hc":null,"bdatb":null}],"img":null,"tv":2115081.77,"con":null,"marketdefinition":null,"id":"1.258926623"}],"conflatems":null,"op":"mcm","id":3}
{"ct":null,"SegmentType":null,"clk":"AIQtALgvAKwt","heartbeatms":null,"pt":1780839614676,"initialclk":null,"mc":[{"rc":[{"tv":null,"batb":null,"spb":null,"bdatl":null,"trd":null,"spf":null,"ltp":null,"atb":[[8.8000000000000007,2.2000000000000002]],"spl":null,"spn":null,"atl":null,"batl":null,"id":16570658,"hc":null,"bdatb":null}],"img":null,"tv":null,"con":null,"marketdefinition":null,"id":"1.258926623"}],"conflatems":null,"op":"mcm","id":3}
{"ct":null,"SegmentType":null,"clk":"ALMtAOIvAOct","heartbeatms":null,"pt":1780839615190,"initialclk":null,"mc":[{"rc":[{"tv":1875028.47,"batb":null,"spb":null,"bdatl":null,"trd":[[1.1299999999999999,199792.53]],"spf":null,"ltp":null,"atb":null,"spl":null,"spn":null,"atl":[[1.1299999999999999,7628.7399999999998]],"batl":null,"id":19924823,"hc":null,"bdatb":null}],"img":null,"tv":2115087.5099999998,"con":null,"marketdefinition":null,"id":"1.258926623"}],"conflatems":null,"op":"mcm","id":3}
{"ct":null,"SegmentType":null,"clk":"AL8tAOwvAO4t","heartbeatms":null,"pt":1780839615294,"initialclk":null,"mc":[{"rc":[{"tv":null,"batb":null,"spb":null,"bdatl":null,"trd":null,"spf":null,"ltp":null,"atb":null,"spl":null,"spn":null,"atl":[[1.1399999999999999,22889.900000000001]],"batl":null,"id":19924823,"hc":null,"bdatb":null}],"img":null,"tv":null,"con":null,"marketdefinition":null,"id":"1.258926623"}],"conflatems":null,"op":"mcm","id":3}
{"ct":null,"SegmentType":null,"clk":"AIAuAKgwAJ8u","heartbeatms":null,"pt":1780839615970,"initialclk":null,"mc":[{"rc":[{"tv":null,"batb":null,"spb":null,"bdatl":null,"trd":null,"spf":null,"ltp":null,"atb":null,"spl":null,"spn":null,"atl":[[9,3.9100000000000001]],"batl":null,"id":16570658,"hc":null,"bdatb":null}],"img":null,"tv":null,"con":null,"marketdefinition":null,"id":"1.258926623"}],"conflatems":null,"op":"mcm","id":3}
{"ct":null,"SegmentType":null,"clk":"AJ8uAMYwAMgu","heartbeatms":null,"pt":1780839616388,"initialclk":null,"mc":[{"rc":[{"tv":null,"batb":null,"spb":null,"bdatl":null,"trd":null,"spf":null,"ltp":null,"atb":null,"spl":null,"spn":null,"atl":[[9.1999999999999993,5]],"batl":null,"id":16570658,"hc":null,"bdatb":null}],"img":null,"tv":null,"con":null,"marketdefinition":null,"id":"1.258926623"}],"conflatems":null,"op":"mcm","id":3}
{"ct":null,"SegmentType":null,"clk":"ALAuANEwAN8u","heartbeatms":null,"pt":1780839616593,"initialclk":null,"mc":[{"rc":[{"tv":null,"batb":null,"spb":null,"bdatl":null,"trd":null,"spf":null,"ltp":null,"atb":null,"spl":null,"spn":null,"atl":[[9,5.3600000000000003]],"batl":null,"id":16570658,"hc":null,"bdatb":null}],"img":null,"tv":null,"con":null,"marketdefinition":null,"id":"1.258926623"}],"conflatems":null,"op":"mcm","id":3}
{"ct":null,"SegmentType":null,"clk":"APQuAJwxAJ4v","heartbeatms":null,"pt":1780839617269,"initialclk":null,"mc":[{"rc":[{"tv":1875035.0500000001,"batb":null,"spb":null,"bdatl":null,"trd":[[1.1200000000000001,18393.09]],"spf":null,"ltp":1.1200000000000001,"atb":[[1.1200000000000001,19096.369999999999]],"spl":null,"spn":null,"atl":null,"batl":null,"id":19924823,"hc":null,"bdatb":null}],"img":null,"tv":2115094.0899999999,"con":null,"marketdefinition":null,"id":"1.258926623"}],"conflatems":null,"op":"mcm","id":3}
{"ct":null,"SegmentType":null,"clk":"APouAKcxAKYv","heartbeatms":null,"pt":1780839617370,"initialclk":null,"mc":[{"rc":[{"tv":null,"batb":null,"spb":null,"bdatl":null,"trd":null,"spf":null,"ltp":null,"atb":[[1.0900000000000001,39627.330000000002]],"spl":null,"spn":null,"atl":null,"batl":null,"id":19924823,"hc":null,"bdatb":null}],"img":null,"tv":null,"con":null,"marketdefinition":null,"id":"1.258926623"}],"conflatems":null,"op":"mcm","id":3}
{"ct":null,"SegmentType":null,"clk":"AIEvALAxALIv","heartbeatms":null,"pt":1780839617484,"initialclk":null,"mc":[{"rc":[{"tv":null,"batb":null,"spb":null,"bdatl":null,"trd":null,"spf":null,"ltp":null,"atb":[[8.1999999999999993,262.04000000000002],[8,370.02999999999997]],"spl":null,"spn":null,"atl":null,"batl":null,"id":16570658,"hc":null,"bdatb":null},{"tv":null,"batb":null,"spb":null,"bdatl":null,"trd":null,"spf":null,"ltp":null,"atb":null,"spl":null,"spn":null,"atl":[[1.1299999999999999,16487.68],[1.1399999999999999,22893.650000000001],[1.1499999999999999,10263.33]],"batl":null,"id":19924823,"hc":null,"bdatb":null}],"img":null,"tv":null,"con":null,"marketdefinition":null,"id":"1.258926623"}],"conflatems":null,"op":"mcm","id":3}
{"ct":null,"SegmentType":null,"clk":"AIsvALoxALsv","heartbeatms":null,"pt":1780839617587,"initialclk":null,"mc":[{"rc":[{"tv":null,"batb":null,"spb":null,"bdatl":null,"trd":null,"spf":null,"ltp":null,"atb":[[7,0],[7.2000000000000002,0]],"spl":null,"spn":null,"atl":null,"batl":null,"id":16570658,"hc":null,"bdatb":null},{"tv":1875036.96,"batb":null,"spb":null,"bdatl":null,"trd":[[1.1299999999999999,199794.44]],"spf":null,"ltp":1.1299999999999999,"atb":[[1.1200000000000001,1820.74]],"spl":null,"spn":null,"atl":[[1.1699999999999999,9374.9899999999998],[1.1299999999999999,16486.73],[1.1399999999999999,22494.900000000001],[1.1599999999999999,8926.1000000000004]],"batl":null,"id":19924823,"hc":null,"bdatb":null}],"img":null,"tv":2115096,"con":null,"marketdefinition":null,"id":"1.258926623"}],"conflatems":null,"op":"mcm","id":3}
{"ct":null,"SegmentType":null,"clk":"AI4vAMgxAMMv","heartbeatms":null,"pt":1780839617679,"initialclk":null,"mc":[{"rc":[{"tv":null,"batb":null,"spb":null,"bdatl":null,"trd":null,"spf":null,"ltp":null,"atb":[[8.8000000000000007,8.0800000000000001]],"spl":null,"spn":null,"atl":null,"batl":null,"id":16570658,"hc":null,"bdatb":null},{"tv":null,"batb":null,"spb":null,"bdatl":null,"trd":null,"spf":null,"ltp":null,"atb":[[1.1100000000000001,53980.709999999999]],"spl":null,"spn":null,"atl":null,"batl":null,"id":19924823,"hc":null,"bdatb":null}],"img":null,"tv":null,"con":null,"marketdefinition":null,"id":"1.258926623"}],"conflatems":null,"op":"mcm","id":3}
{"ct":null,"SegmentType":null,"clk":"AJkvANoxANMv","heartbeatms":null,"pt":1780839617886,"initialclk":null,"mc":[{"rc":[{"tv":null,"batb":null,"spb":null,"bdatl":null,"trd":null,"spf":null,"ltp":null,"atb":[[1.0900000000000001,56161.919999999998]],"spl":null,"spn":null,"atl":null,"batl":null,"id":19924823,"hc":null,"bdatb":null}],"img":null,"tv":null,"con":null,"marketdefinition":null,"id":"1.258926623"}],"conflatems":null,"op":"mcm","id":3}
{"ct":null,"SegmentType":null,"clk":"AJ8vAOMxAN8v","heartbeatms":null,"pt":1780839617994,"initialclk":null,"mc":[{"rc":[{"tv":null,"batb":null,"spb":null,"bdatl":null,"trd":null,"spf":null,"ltp":null,"atb":[[8,324.94999999999999]],"spl":null,"spn":null,"atl":null,"batl":null,"id":16570658,"hc":null,"bdatb":null},{"tv":1875038.9299999999,"batb":null,"spb":null,"bdatl":null,"trd":[[1.1299999999999999,199796.41]],"spf":null,"ltp":null,"atb":[[1.1200000000000001,1758.01]],"spl":null,"spn":null,"atl":[[1.1299999999999999,16485.740000000002],[1.1399999999999999,21953.900000000001]],"batl":null,"id":19924823,"hc":null,"bdatb":null}],"img":null,"tv":2115097.9700000002,"con":null,"marketdefinition":null,"id":"1.258926623"}],"conflatems":null,"op":"mcm","id":3}
{"ct":null,"SegmentType":null,"clk":"AKYvAPIxAOcv","heartbeatms":null,"pt":1780839618100,"initialclk":null,"mc":[{"rc":[{"tv":null,"batb":null,"spb":null,"bdatl":null,"trd":null,"spf":null,"ltp":null,"atb":[[1.1000000000000001,61016.370000000003]],"spl":null,"spn":null,"atl":[[1.1299999999999999,17162.709999999999]],"batl":null,"id":19924823,"hc":null,"bdatb":null}],"img":null,"tv":null,"con":null,"marketdefinition":null,"id":"1.258926623"}],"conflatems":null,"op":"mcm","id":3}
{"ct":null,"SegmentType":null,"clk":"AK0vAPYxAO8v","heartbeatms":null,"pt":1780839618201,"initialclk":null,"mc":[{"rc":[{"tv":null,"batb":null,"spb":null,"bdatl":null,"trd":null,"spf":null,"ltp":null,"atb":[[1.1100000000000001,53134.93]],"spl":null,"spn":null,"atl":[[1.1399999999999999,20197.759999999998]],"batl":null,"id":19924823,"hc":null,"bdatb":null}],"img":null,"tv":null,"con":null,"marketdefinition":null,"id":"1.258926623"}],"conflatems":null,"op":"mcm","id":3}
{"ct":null,"SegmentType":null,"clk":"AN8vALUyAJMw","heartbeatms":null,"pt":1780839618773,"initialclk":null,"mc":[{"rc":[{"tv":null,"batb":null,"spb":null,"bdatl":null,"trd":null,"spf":null,"ltp":null,"atb":[[8.4000000000000004,179.56999999999999]],"spl":null,"spn":null,"atl":[[18,83.329999999999998]],"batl":null,"id":16570658,"hc":null,"bdatb":null},{"tv":null,"batb":null,"spb":null,"bdatl":null,"trd":null,"spf":null,"ltp":null,"atb":[[1.1000000000000001,62380],[1.1100000000000001,53104.93]],"spl":null,"spn":null,"atl":[[1.1399999999999999,21513.549999999999],[1.1499999999999999,10255.84]],"batl":null,"id":19924823,"hc":null,"bdatb":null}],"img":null,"tv":null,"con":null,"marketdefinition":null,"id":"1.258926623"}],"conflatems":null,"op":"mcm","id":3}
{"ct":null,"SegmentType":null,"clk":"APEvAMwyAKIw","heartbeatms":null,"pt":1780839618977,"initialclk":null,"mc":[{"rc":[{"tv":null,"batb":null,"spb":null,"bdatl":null,"trd":null,"spf":null,"ltp":null,"atb":[[1.1200000000000001,1508.01]],"spl":null,"spn":null,"atl":null,"batl":null,"id":19924823,"hc":null,"bdatb":null}],"img":null,"tv":null,"con":null,"marketdefinition":null,"id":"1.258926623"}],"conflatems":null,"op":"mcm","id":3}
{"ct":null,"SegmentType":null,"clk":"AMAwAKgzAO8w","heartbeatms":null,"pt":1780839619865,"initialclk":null,"mc":[{"rc":[{"tv":null,"batb":null,"spb":null,"bdatl":null,"trd":null,"spf":null,"ltp":null,"atb":[[8.4000000000000004,1]],"spl":null,"spn":null,"atl":null,"batl":null,"id":16570658,"hc":null,"bdatb":null}],"img":null,"tv":null,"con":null,"marketdefinition":null,"id":"1.258926623"}],"conflatems":null,"op":"mcm","id":3}
{"ct":null,"SegmentType":null,"clk":"APIwANczAJ8x","heartbeatms":null,"pt":1780839620378,"initialclk":null,"mc":[{"rc":[{"tv":240074.78,"batb":null,"spb":null,"bdatl":null,"trd":[[9.1999999999999993,1527.97],[9,147.88999999999999]],"spf":null,"ltp":9.1999999999999993,"atb":[[9.1999999999999993,290.94],[9,3241.3600000000001]],"spl":null,"spn":null,"atl":[[9.1999999999999993,0],[9,0]],"batl":null,"id":16570658,"hc":null,"bdatb":null},{"tv":1878110.5,"batb":null,"spb":null,"bdatl":null,"trd":[[1.1299999999999999,199810.91],[1.1200000000000001,21450.16]],"spf":null,"ltp":1.1200000000000001,"atb":[[1.1200000000000001,0]],"spl":null,"spn":null,"atl":[[1.1299999999999999,17155.459999999999],[1.1200000000000001,25702.5]],"batl":null,"id":19924823,"hc":null,"bdatb":null}],"img":null,"tv":2118185.2799999998,"con":null,"marketdefinition":null,"id":"1.258926623"}],"conflatems":null,"op":"mcm","id":3}
{"ct":null,"SegmentType":null,"clk":"APswAOAzAKUx","heartbeatms":null,"pt":1780839620482,"initialclk":null,"mc":[{"rc":[{"tv":240249.82000000001,"batb":null,"spb":null,"bdatl":null,"trd":[[9.4000000000000004,2],[9.8000000000000007,171.02000000000001],[9.5999999999999996,2.02]],"spf":null,"ltp":9.8000000000000007,"atb":[[9.4000000000000004,268.27999999999997],[9.8000000000000007,160.80000000000001],[9.5999999999999996,55.07]],"spl":null,"spn":null,"atl":[[9.4000000000000004,0],[9.8000000000000007,0],[9.5999999999999996,0]],"batl":null,"id":16570658,"hc":null,"bdatb":null},{"tv":null,"batb":null,"spb":null,"bdatl":null,"trd":null,"spf":null,"ltp":null,"atb":[[1.1000000000000001,61016.370000000003]],"spl":null,"spn":null,"atl":null,"batl":null,"id":19924823,"hc":null,"bdatb":null}],"img":null,"tv":2118360.3199999998,"con":null,"marketdefinition":null,"id":"1.258926623"}],"conflatems":null,"op":"mcm","id":3}
{"ct":null,"SegmentType":null,"clk":"AIcxAOkzAK8x","heartbeatms":null,"pt":1780839620587,"initialclk":null,"mc":[{"rc":[{"tv":240276.72,"batb":null,"spb":null,"bdatl":null,"trd":[[9.8000000000000007,197.91999999999999]],"spf":null,"ltp":null,"atb":[[8.8000000000000007,2.2000000000000002],[9.8000000000000007,147.34999999999999],[9,463.58999999999998]],"spl":null,"spn":null,"atl":null,"batl":null,"id":16570658,"hc":null,"bdatb":null},{"tv":1878196.8799999999,"batb":null,"spb":null,"bdatl":null,"trd":[[1.1200000000000001,21536.540000000001]],"spf":null,"ltp":null,"atb":null,"spl":null,"spn":null,"atl":[[1.1499999999999999,10256.959999999999],[1.1200000000000001,25246.970000000001]],"batl":null,"id":19924823,"hc":null,"bdatb":null}],"img":null,"tv":2118473.6000000001,"con":null,"marketdefinition":null,"id":"1.258926623"}],"conflatems":null,"op":"mcm","id":3}
{"ct":null,"SegmentType":null,"clk":"AJAxAPUzALYx","heartbeatms":null,"pt":1780839620692,"initialclk":null,"mc":[{"rc":[{"tv":null,"batb":null,"spb":null,"bdatl":null,"trd":null,"spf":null,"ltp":null,"atb":[[9.4000000000000004,242.68000000000001],[8.5999999999999996,52.100000000000001]],"spl":null,"spn":null,"atl":null,"batl":null,"id":16570658,"hc":null,"bdatb":null},{"tv":null,"batb":null,"spb":null,"bdatl":null,"trd":null,"spf":null,"ltp":null,"atb":[[1.1000000000000001,51083.75]],"spl":null,"spn":null,"atl":null,"batl":null,"id":19924823,"hc":null,"bdatb":null}],"img":null,"tv":null,"con":null,"marketdefinition":null,"id":"1.258926623"}],"conflatems":null,"op":"mcm","id":3}
{"ct":null,"SegmentType":null,"clk":"AJoxAIU0ALox","heartbeatms":null,"pt":1780839620799,"initialclk":null,"mc":[{"rc":[{"tv":null,"batb":null,"spb":null,"bdatl":null,"trd":null,"spf":null,"ltp":null,"atb":[[9.5999999999999996,66.700000000000003]],"spl":null,"spn":null,"atl":null,"batl":null,"id":16570658,"hc":null,"bdatb":null}],"img":null,"tv":null,"con":null,"marketdefinition":null,"id":"1.258926623"}],"conflatems":null,"op":"mcm","id":3}
{"ct":null,"SegmentType":null,"clk":"AJ8xAJA0AMIx","heartbeatms":null,"pt":1780839620898,"initialclk":null,"mc":[{"rc":[{"tv":null,"batb":null,"spb":null,"bdatl":null,"trd":null,"spf":null,"ltp":null,"atb":[[9.1999999999999993,344.94]],"spl":null,"spn":null,"atl":[[12.5,151.83000000000001]],"batl":null,"id":16570658,"hc":null,"bdatb":null},{"tv":null,"batb":null,"spb":null,"bdatl":null,"trd":null,"spf":null,"ltp":null,"atb":[[1.0800000000000001,40729.43]],"spl":null,"spn":null,"atl":[[1.1299999999999999,18987.240000000002]],"batl":null,"id":19924823,"hc":null,"bdatb":null}],"img":null,"tv":null,"con":null,"marketdefinition":null,"id":"1.258926623"}],"conflatems":null,"op":"mcm","id":3}
{"ct":null,"SegmentType":null,"clk":"AKYxAJs0AMYx","heartbeatms":null,"pt":1780839620967,"initialclk":null,"mc":[{"rc":[{"tv":null,"batb":null,"spb":null,"bdatl":null,"trd":null,"spf":null,"ltp":null,"atb":[[8.5999999999999996,53.100000000000001]],"spl":null,"spn":null,"atl":null,"batl":null,"id":16570658,"hc":null,"bdatb":null}],"img":null,"tv":null,"con":null,"marketdefinition":null,"id":"1.258926623"}],"conflatems":null,"op":"mcm","id":3}
{"ct":null,"SegmentType":null,"clk":"AMgxAMs0APUx","heartbeatms":null,"pt":1780839621470,"initialclk":null,"mc":[{"rc":[{"tv":null,"batb":null,"spb":null,"bdatl":null,"trd":null,"spf":null,"ltp":null,"atb":null,"spl":null,"spn":null,"atl":[[1.1200000000000001,25708.759999999998]],"batl":null,"id":19924823,"hc":null,"bdatb":null}],"img":null,"tv":null,"con":null,"marketdefinition":null,"id":"1.258926623"}],"conflatems":null,"op":"mcm","id":3}
{"ct":null,"SegmentType":null,"clk":"ANwxAOU0AIcy","heartbeatms":null,"pt":1780839621692,"initialclk":null,"mc":[{"rc":[{"tv":null,"batb":null,"spb":null,"bdatl":null,"trd":null,"spf":null,"ltp":null,"atb":[[1.1100000000000001,53051.349999999999]],"spl":null,"spn":null,"atl":[[1.1200000000000001,25714.759999999998]],"batl":null,"id":19924823,"hc":null,"bdatb":null}],"img":null,"tv":null,"con":null,"marketdefinition":null,"id":"1.258926623"}],"conflatems":null,"op":"mcm","id":3}
{"ct":null,"SegmentType":null,"clk":"AOExAOw0AJAy","heartbeatms":null,"pt":1780839621782,"initialclk":null,"mc":[{"rc":[{"tv":null,"batb":null,"spb":null,"bdatl":null,"trd":null,"spf":null,"ltp":null,"atb":null,"spl":null,"spn":null,"atl":[[14,0]],"batl":null,"id":16570658,"hc":null,"bdatb":null}],"img":null,"tv":null,"con":null,"marketdefinition":null,"id":"1.258926623"}],"conflatems":null,"op":"mcm","id":3}
{"ct":null,"SegmentType":null,"clk":"AOcxAPQ0AJoy","heartbeatms":null,"pt":1780839621882,"initialclk":null,"mc":[{"rc":[{"tv":null,"batb":null,"spb":null,"bdatl":null,"trd":null,"spf":null,"ltp":null,"atb":[[9.8000000000000007,274.72000000000003]],"spl":null,"spn":null,"atl":[[11,112.34],[10,221.75]],"batl":null,"id":16570658,"hc":null,"bdatb":null},{"tv":null,"batb":null,"spb":null,"bdatl":null,"trd":null,"spf":null,"ltp":null,"atb":[[1.1100000000000001,54175.849999999999]],"spl":null,"spn":null,"atl":[[1.1200000000000001,26829.220000000001]],"batl":null,"id":19924823,"hc":null,"bdatb":null}],"img":null,"tv":null,"con":null,"marketdefinition":null,"id":"1.258926623"}],"conflatems":null,"op":"mcm","id":3}
{"ct":null,"SegmentType":null,"clk":"AJAyAKo1AMsy","heartbeatms":null,"pt":1780839622458,"initialclk":null,"mc":[{"rc":[{"tv":null,"batb":null,"spb":null,"bdatl":null,"trd":null,"spf":null,"ltp":null,"atb":[[9,489.50999999999999]],"spl":null,"spn":null,"atl":null,"batl":null,"id":16570658,"hc":null,"bdatb":null},{"tv":null,"batb":null,"spb":null,"bdatl":null,"trd":null,"spf":null,"ltp":null,"atb":null,"spl":null,"spn":null,"atl":[[1.1200000000000001,26831.220000000001]],"batl":null,"id":19924823,"hc":null,"bdatb":null}],"img":null,"tv":null,"con":null,"marketdefinition":null,"id":"1.258926623"}],"conflatems":null,"op":"mcm","id":3}
{"ct":null,"SegmentType":null,"clk":"AJkyALc1ANUy","heartbeatms":null,"pt":1780839622574,"initialclk":null,"mc":[{"rc":[{"tv":null,"batb":null,"spb":null,"bdatl":null,"trd":null,"spf":null,"ltp":null,"atb":[[1.1000000000000001,52083.75]],"spl":null,"spn":null,"atl":null,"batl":null,"id":19924823,"hc":null,"bdatb":null}],"img":null,"tv":null,"con":null,"marketdefinition":null,"id":"1.258926623"}],"conflatems":null,"op":"mcm","id":3}
{"ct":null,"SegmentType":null,"clk":"AKIyAMI1ANwy","heartbeatms":null,"pt":1780839622669,"initialclk":null,"mc":[{"rc":[{"tv":null,"batb":null,"spb":null,"bdatl":null,"trd":null,"spf":null,"ltp":null,"atb":[[1.0900000000000001,56169.419999999998]],"spl":null,"spn":null,"atl":[[1.1299999999999999,18994.740000000002],[1.1200000000000001,26829.220000000001]],"batl":null,"id":19924823,"hc":null,"bdatb":null}],"img":null,"tv":null,"con":null,"marketdefinition":null,"id":"1.258926623"}],"conflatems":null,"op":"mcm","id":3}
{"ct":null,"SegmentType":null,"clk":"APMyAJ42AK0z","heartbeatms":null,"pt":1780839623602,"initialclk":null,"mc":[{"rc":[{"tv":null,"batb":null,"spb":null,"bdatl":null,"trd":null,"spf":null,"ltp":null,"atb":null,"spl":null,"spn":null,"atl":[[1.1200000000000001,27829.220000000001]],"batl":null,"id":19924823,"hc":null,"bdatb":null}],"img":null,"tv":null,"con":null,"marketdefinition":null,"id":"1.258926623"}],"conflatems":null,"op":"mcm","id":3}
{"ct":null,"SegmentType":null,"clk":"AP4yAKU2ALsz","heartbeatms":null,"pt":1780839623701,"initialclk":null,"mc":[{"rc":[{"tv":240470.07000000001,"batb":null,"spb":null,"bdatl":null,"trd":[[9.8000000000000007,391.26999999999998]],"spf":null,"ltp":null,"atb":[[9.8000000000000007,178.05000000000001]],"spl":null,"spn":null,"atl":null,"batl":null,"id":16570658,"hc":null,"bdatb":null}],"img":null,"tv":2118666.9500000002,"con":null,"marketdefinition":null,"id":"1.258926623"}],"conflatems":null,"op":"mcm","id":3}
{"ct":null,"SegmentType":null,"clk":"AJAzALw2ANEz","heartbeatms":null,"pt":1780839623874,"initialclk":null,"mc":[{"rc":[{"tv":240472.07000000001,"batb":null,"spb":null,"bdatl":null,"trd":[[9.8000000000000007,393.26999999999998]],"spf":null,"ltp":null,"atb":[[9.8000000000000007,177.05000000000001],[9.5999999999999996,199.53]],"spl":null,"spn":null,"atl":null,"batl":null,"id":16570658,"hc":null,"bdatb":null}],"img":null,"tv":2118668.9500000002,"con":null,"marketdefinition":null,"id":"1.258926623"}],"conflatems":null,"op":"mcm","id":3}
{"ct":null,"SegmentType":null,"clk":"AJkzAMo2AN0z","heartbeatms":null,"pt":1780839623970,"initialclk":null,"mc":[{"rc":[{"tv":240476.13000000001,"batb":null,"spb":null,"bdatl":null,"trd":[[9.8000000000000007,397.32999999999998]],"spf":null,"ltp":null,"atb":[[9.8000000000000007,175.02000000000001]],"spl":null,"spn":null,"atl":null,"batl":null,"id":16570658,"hc":null,"bdatb":null}],"img":null,"tv":2118673.0099999998,"con":null,"marketdefinition":null,"id":"1.258926623"}],"conflatems":null,"op":"mcm","id":3}
{"ct":null,"SegmentType":null,"clk":"AKUzANI2AOcz","heartbeatms":null,"pt":1780839624081,"initialclk":null,"mc":[{"rc":[{"tv":null,"batb":null,"spb":null,"bdatl":null,"trd":null,"spf":null,"ltp":null,"atb":[[1.04,73812.729999999996],[1.05,75661.529999999999],[1.0700000000000001,39093.82],[1.0800000000000001,40731.43],[1.0900000000000001,56171.419999999998],[1.0600000000000001,63296.940000000002],[1.02,90705.919999999998],[1.03,88932.990000000005],[1.01,93235.490000000005]],"spl":null,"spn":null,"atl":null,"batl":null,"id":19924823,"hc":null,"bdatb":null}],"img":null,"tv":null,"con":null,"marketdefinition":null,"id":"1.258926623"}],"conflatems":null,"op":"mcm","id":3}
{"ct":null,"SegmentType":null,"clk":"AMAzAPA2AIY0","heartbeatms":null,"pt":1780839624378,"initialclk":null,"mc":[{"rc":[{"tv":240694.12,"batb":null,"spb":null,"bdatl":null,"trd":[[9.8000000000000007,615.32000000000005]],"spf":null,"ltp":null,"atb":[[9.8000000000000007,66.019999999999996]],"spl":null,"spn":null,"atl":null,"batl":null,"id":16570658,"hc":null,"bdatb":null}],"img":null,"tv":2118891,"con":null,"marketdefinition":null,"id":"1.258926623"}],"conflatems":null,"op":"mcm","id":3}
{"ct":null,"SegmentType":null,"clk":"AM0zAPo2AJI0","heartbeatms":null,"pt":1780839624484,"initialclk":null,"mc":[{"rc":[{"tv":null,"batb":null,"spb":null,"bdatl":null,"trd":null,"spf":null,"ltp":null,"atb":[[9.4000000000000004,299.18000000000001],[9.1999999999999993,402.94999999999999]],"spl":null,"spn":null,"atl":null,"batl":null,"id":16570658,"hc":null,"bdatb":null}],"img":null,"tv":null,"con":null,"marketdefinition":null,"id":"1.258926623"}],"conflatems":null,"op":"mcm","id":3}
{"ct":null,"SegmentType":null,"clk":"ANQzAIQ3AJo0","heartbeatms":null,"pt":1780839624582,"initialclk":null,"mc":[{"rc":[{"tv":null,"batb":null,"spb":null,"bdatl":null,"trd":null,"spf":null,"ltp":null,"atb":[[9.8000000000000007,0]],"spl":null,"spn":null,"atl":null,"batl":null,"id":16570658,"hc":null,"bdatb":null}],"img":null,"tv":null,"con":null,"marketdefinition":null,"id":"1.258926623"}],"conflatems":null,"op":"mcm","id":3}
{"ct":null,"SegmentType":null,"clk":"AP4zAKc3AMQ0","heartbeatms":null,"pt":1780839624999,"initialclk":null,"mc":[{"rc":[{"tv":null,"batb":null,"spb":null,"bdatl":null,"trd":null,"spf":null,"ltp":null,"atb":[[7.7999999999999998,0.85999999999999999],[7.5999999999999996,11.59]],"spl":null,"spn":null,"atl":[[13,6.8200000000000003],[12.5,152.69],[11,113.2]],"batl":null,"id":16570658,"hc":null,"bdatb":null},{"tv":null,"batb":null,"spb":null,"bdatl":null,"trd":null,"spf":null,"ltp":null,"atb":[[1.0700000000000001,39101.449999999997],[1.0800000000000001,40738.260000000002],[1.1000000000000001,52088.809999999998]],"spl":null,"spn":null,"atl":[[1.1599999999999999,8931.7199999999993],[1.1499999999999999,10262.030000000001]],"batl":null,"id":19924823,"hc":null,"bdatb":null}],"img":null,"tv":null,"con":null,"marketdefinition":null,"id":"1.258926623"}],"conflatems":null,"op":"mcm","id":3}
{"ct":null,"SegmentType":null,"clk":"AIY0ALQ3ANU0","heartbeatms":null,"pt":1780839625098,"initialclk":null,"mc":[{"rc":[{"tv":null,"batb":null,"spb":null,"bdatl":null,"trd":null,"spf":null,"ltp":null,"atb":null,"spl":null,"spn":null,"atl":[[10,136.22999999999999]],"batl":null,"id":16570658,"hc":null,"bdatb":null},{"tv":1878208.6699999999,"batb":null,"spb":null,"bdatl":null,"trd":[[1.1200000000000001,21548.330000000002]],"spf":null,"ltp":null,"atb":null,"spl":null,"spn":null,"atl":[[1.1200000000000001,27823.330000000002]],"batl":null,"id":19924823,"hc":null,"bdatb":null}],"img":null,"tv":2118902.79,"con":null,"marketdefinition":null,"id":"1.258926623"}],"conflatems":null,"op":"mcm","id":3}
{"ct":null,"SegmentType":null,"clk":"AJ80AMs3APk0","heartbeatms":null,"pt":1780839625364,"initialclk":null,"mc":[{"rc":[{"tv":1878210.3000000001,"batb":null,"spb":null,"bdatl":null,"trd":[[1.1200000000000001,21549.959999999999]],"spf":null,"ltp":null,"atb":null,"spl":null,"spn":null,"atl":[[1.1200000000000001,27822.52]],"batl":null,"id":19924823,"hc":null,"bdatb":null}],"img":null,"tv":2118904.4199999999,"con":null,"marketdefinition":null,"id":"1.258926623"}],"conflatems":null,"op":"mcm","id":3}
{"ct":null,"SegmentType":null,"clk":"ALA0ANo3AI41","heartbeatms":null,"pt":1780839625574,"initialclk":null,"mc":[{"rc":[{"tv":null,"batb":null,"spb":null,"bdatl":null,"trd":null,"spf":null,"ltp":null,"atb":null,"spl":null,"spn":null,"atl":[[12.5,158.77000000000001]],"batl":null,"id":16570658,"hc":null,"bdatb":null}],"img":null,"tv":null,"con":null,"marketdefinition":null,"id":"1.258926623"}],"conflatems":null,"op":"mcm","id":3}
{"ct":null,"SegmentType":null,"clk":"ALg0AOQ3AJs1","heartbeatms":null,"pt":1780839625686,"initialclk":null,"mc":[{"rc":[{"tv":null,"batb":null,"spb":null,"bdatl":null,"trd":null,"spf":null,"ltp":null,"atb":[[9.8000000000000007,0.080000000000000002]],"spl":null,"spn":null,"atl":null,"batl":null,"id":16570658,"hc":null,"bdatb":null}],"img":null,"tv":null,"con":null,"marketdefinition":null,"id":"1.258926623"}],"conflatems":null,"op":"mcm","id":3}
{"ct":null,"SegmentType":null,"clk":"AMw0APk3ALA1","heartbeatms":null,"pt":1780839625892,"initialclk":null,"mc":[{"rc":[{"tv":null,"batb":null,"spb":null,"bdatl":null,"trd":null,"spf":null,"ltp":null,"atb":null,"spl":null,"spn":null,"atl":[[1.1599999999999999,8934.5300000000007]],"batl":null,"id":19924823,"hc":null,"bdatb":null}],"img":null,"tv":null,"con":null,"marketdefinition":null,"id":"1.258926623"}],"conflatems":null,"op":"mcm","id":3}
{"ct":null,"SegmentType":null,"clk":"ANM0AII4ALg1","heartbeatms":null,"pt":1780839625991,"initialclk":null,"mc":[{"rc":[{"tv":240726.51999999999,"batb":null,"spb":null,"bdatl":null,"trd":[[9.8000000000000007,615.48000000000002],[9.5999999999999996,34.259999999999998]],"spf":null,"ltp":9.5999999999999996,"atb":[[9.8000000000000007,0],[9.5999999999999996,183.41]],"spl":null,"spn":null,"atl":null,"batl":null,"id":16570658,"hc":null,"bdatb":null}],"img":null,"tv":2118936.8199999998,"con":null,"marketdefinition":null,"id":"1.258926623"}],"conflatems":null,"op":"mcm","id":3}
{"ct":null,"SegmentType":null,"clk":"AOY0AKM4AOw1","heartbeatms":null,"pt":1780839626275,"initialclk":null,"mc":[{"rc":[{"tv":null,"batb":null,"spb":null,"bdatl":null,"trd":null,"spf":null,"ltp":null,"atb":null,"spl":null,"spn":null,"atl":[[13.5,0]],"batl":null,"id":16570658,"hc":null,"bdatb":null}],"img":null,"tv":null,"con":null,"marketdefinition":null,"id":"1.258926623"}],"conflatems":null,"op":"mcm","id":3}
{"ct":null,"SegmentType":null,"clk":"AII1AMY4AJQ2","heartbeatms":null,"pt":1780839626580,"initialclk":null,"mc":[{"rc":[{"tv":null,"batb":null,"spb":null,"bdatl":null,"trd":null,"spf":null,"ltp":null,"atb":[[8.5999999999999996,227.50999999999999]],"spl":null,"spn":null,"atl":[[11,249.56]],"batl":null,"id":16570658,"hc":null,"bdatb":null},{"tv":1878224.79,"batb":null,"spb":null,"bdatl":null,"trd":[[1.1200000000000001,21564.450000000001]],"spf":null,"ltp":null,"atb":[[1.1000000000000001,53452.440000000002]],"spl":null,"spn":null,"atl":[[1.1299999999999999,20322.169999999998],[1.1200000000000001,27815.27]],"batl":null,"id":19924823,"hc":null,"bdatb":null}],"img":null,"tv":2118951.3100000001,"con":null,"marketdefinition":null,"id":"1.258926623"}],"conflatems":null,"op":"mcm","id":3}
{"ct":null,"SegmentType":null,"clk":"AJc1ANk4AKk2","heartbeatms":null,"pt":1780839626787,"initialclk":null,"mc":[{"rc":[{"tv":1878373.9299999999,"batb":null,"spb":null,"bdatl":null,"trd":[[1.1200000000000001,21713.59]],"spf":null,"ltp":null,"atb":null,"spl":null,"spn":null,"atl":[[1.1200000000000001,27740.700000000001]],"batl":null,"id":19924823,"hc":null,"bdatb":null}],"img":null,"tv":2119100.4500000002,"con":null,"marketdefinition":null,"id":"1.258926623"}],"conflatems":null,"op":"mcm","id":3}
{"ct":null,"SegmentType":null,"clk":"AKg1APM4AL42","heartbeatms":null,"pt":1780839627002,"initialclk":null,"mc":[{"rc":[{"tv":null,"batb":null,"spb":null,"bdatl":null,"trd":null,"spf":null,"ltp":null,"atb":null,"spl":null,"spn":null,"atl":[[18,0]],"batl":null,"id":16570658,"hc":null,"bdatb":null},{"tv":null,"batb":null,"spb":null,"bdatl":null,"trd":null,"spf":null,"ltp":null,"atb":null,"spl":null,"spn":null,"atl":[[1.1399999999999999,20197.759999999998]],"batl":null,"id":19924823,"hc":null,"bdatb":null}],"img":null,"tv":null,"con":null,"marketdefinition":null,"id":"1.258926623"}],"conflatems":null,"op":"mcm","id":3}
{"ct":null,"SegmentType":null,"clk":"AL01AP44ANQ2","heartbeatms":null,"pt":1780839627204,"initialclk":null,"mc":[{"rc":[{"tv":null,"batb":null,"spb":null,"bdatl":null,"trd":null,"spf":null,"ltp":null,"atb":[[1.1100000000000001,53887.07]],"spl":null,"spn":null,"atl":[[1000,1.1200000000000001]],"batl":null,"id":19924823,"hc":null,"bdatb":null}],"img":null,"tv":null,"con":null,"marketdefinition":null,"id":"1.258926623"}],"conflatems":null,"op":"mcm","id":3}
{"ct":null,"SegmentType":null,"clk":"AMk1AIw5AOE2","heartbeatms":null,"pt":1780839627270,"initialclk":null,"mc":[{"rc":[{"tv":null,"batb":null,"spb":null,"bdatl":null,"trd":null,"spf":null,"ltp":null,"atb":null,"spl":null,"spn":null,"atl":[[9.8000000000000007,9.5199999999999996]],"batl":null,"id":16570658,"hc":null,"bdatb":null}],"img":null,"tv":null,"con":null,"marketdefinition":null,"id":"1.258926623"}],"conflatems":null,"op":"mcm","id":3}
{"ct":null,"SegmentType":null,"clk":"ANs1AJ45APA2","heartbeatms":null,"pt":1780839627472,"initialclk":null,"mc":[{"rc":[{"tv":null,"batb":null,"spb":null,"bdatl":null,"trd":null,"spf":null,"ltp":null,"atb":[[8.5999999999999996,53.100000000000001]],"spl":null,"spn":null,"atl":[[9.8000000000000007,0.96999999999999997]],"batl":null,"id":16570658,"hc":null,"bdatb":null},{"tv":null,"batb":null,"spb":null,"bdatl":null,"trd":null,"spf":null,"ltp":null,"atb":null,"spl":null,"spn":null,"atl":[[1.1299999999999999,18994.740000000002]],"batl":null,"id":19924823,"hc":null,"bdatb":null}],"img":null,"tv":null,"con":null,"marketdefinition":null,"id":"1.258926623"}],"conflatems":null,"op":"mcm","id":3}
{"ct":null,"SegmentType":null,"clk":"AOQ1AKc5APo2","heartbeatms":null,"pt":1780839627574,"initialclk":null,"mc":[{"rc":[{"tv":null,"batb":null,"spb":null,"bdatl":null,"trd":null,"spf":null,"ltp":null,"atb":[[8.1999999999999993,261.18000000000001],[8,323.94999999999999]],"spl":null,"spn":null,"atl":[[11.5,59.530000000000001],[11,248.69999999999999]],"batl":null,"id":16570658,"hc":null,"bdatb":null},{"tv":null,"batb":null,"spb":null,"bdatl":null,"trd":null,"spf":null,"ltp":null,"atb":[[1.1000000000000001,53446.620000000003],[1.0900000000000001,56165.040000000001]],"spl":null,"spn":null,"atl":[[1000,0.88],[1.1399999999999999,20194.009999999998],[1.1499999999999999,10257.879999999999],[1.1200000000000001,27734.700000000001]],"batl":null,"id":19924823,"hc":null,"bdatb":null}],"img":null,"tv":null,"con":null,"marketdefinition":null,"id":"1.258926623"}],"conflatems":null,"op":"mcm","id":3}
{"ct":null,"SegmentType":null,"clk":"AJI2AN45AKY3","heartbeatms":null,"pt":1780839628095,"initialclk":null,"mc":[{"rc":[{"tv":240823.88000000001,"batb":null,"spb":null,"bdatl":null,"trd":[[9.5999999999999996,131.62000000000001]],"spf":null,"ltp":null,"atb":[[7.4000000000000004,230.13],[8.1999999999999993,271.91000000000003],[9.5999999999999996,134.72999999999999]],"spl":null,"spn":null,"atl":null,"batl":null,"id":16570658,"hc":null,"bdatb":null},{"tv":null,"batb":null,"spb":null,"bdatl":null,"trd":null,"spf":null,"ltp":null,"atb":null,"spl":null,"spn":null,"atl":[[1.1399999999999999,20278.360000000001],[1.1599999999999999,9010.3899999999994]],"batl":null,"id":19924823,"hc":null,"bdatb":null}],"img":null,"tv":2119197.8100000001,"con":null,"marketdefinition":null,"id":"1.258926623"}],"conflatems":null,"op":"mcm","id":3}
{"ct":null,"SegmentType":null,"clk":"AJk2AOQ5ALM3","heartbeatms":null,"pt":1780839628196,"initialclk":null,"mc":[{"rc":[{"tv":null,"batb":null,"spb":null,"bdatl":null,"trd":null,"spf":null,"ltp":null,"atb":null,"spl":null,"spn":null,"atl":[[9.8000000000000007,128.05000000000001]],"batl":null,"id":16570658,"hc":null,"bdatb":null},{"tv":null,"batb":null,"spb":null,"bdatl":null,"trd":null,"spf":null,"ltp":null,"atb":null,"spl":null,"spn":null,"atl":[[1.1200000000000001,26734.700000000001]],"batl":null,"id":19924823,"hc":null,"bdatb":null}],"img":null,"tv":null,"con":null,"marketdefinition":null,"id":"1.258926623"}],"conflatems":null,"op":"mcm","id":3}
{"ct":null,"SegmentType":null,"clk":"AJ82API5AL83","heartbeatms":null,"pt":1780839628302,"initialclk":null,"mc":[{"rc":[{"tv":null,"batb":null,"spb":null,"bdatl":null,"trd":null,"spf":null,"ltp":null,"atb":[[8.1999999999999993,282.63999999999999]],"spl":null,"spn":null,"atl":null,"batl":null,"id":16570658,"hc":null,"bdatb":null},{"tv":null,"batb":null,"spb":null,"bdatl":null,"trd":null,"spf":null,"ltp":null,"atb":null,"spl":null,"spn":null,"atl":[[1.1299999999999999,18705.959999999999],[1.1399999999999999,20355.549999999999]],"batl":null,"id":19924823,"hc":null,"bdatb":null}],"img":null,"tv":null,"con":null,"marketdefinition":null,"id":"1.258926623"}],"conflatems":null,"op":"mcm","id":3}
{"ct":null,"SegmentType":null,"clk":"AKo2AP05AM03","heartbeatms":null,"pt":1780839628371,"initialclk":null,"mc":[{"rc":[{"tv":null,"batb":null,"spb":null,"bdatl":null,"trd":null,"spf":null,"ltp":null,"atb":[[8.1999999999999993,293.37]],"spl":null,"spn":null,"atl":null,"batl":null,"id":16570658,"hc":null,"bdatb":null},{"tv":null,"batb":null,"spb":null,"bdatl":null,"trd":null,"spf":null,"ltp":null,"atb":null,"spl":null,"spn":null,"atl":[[1.1399999999999999,20432.740000000002]],"batl":null,"id":19924823,"hc":null,"bdatb":null}],"img":null,"tv":null,"con":null,"marketdefinition":null,"id":"1.258926623"}],"conflatems":null,"op":"mcm","id":3}
{"ct":null,"SegmentType":null,"clk":"ALQ2AIk6ANQ3","heartbeatms":null,"pt":1780839628472,"initialclk":null,"mc":[{"rc":[{"tv":null,"batb":null,"spb":null,"bdatl":null,"trd":null,"spf":null,"ltp":null,"atb":[[9.5999999999999996,132.83000000000001]],"spl":null,"spn":null,"atl":null,"batl":null,"id":16570658,"hc":null,"bdatb":null}],"img":null,"tv":null,"con":null,"marketdefinition":null,"id":"1.258926623"}],"conflatems":null,"op":"mcm","id":3}
{"ct":null,"SegmentType":null,"clk":"ALk2AMY6AN43","heartbeatms":null,"pt":1780839628577,"initialclk":null,"mc":[{"rc":[{"tv":null,"batb":null,"spb":null,"bdatl":null,"trd":null,"spf":null,"ltp":null,"atb":[[9.4000000000000004,431.44999999999999]],"spl":null,"spn":null,"atl":null,"batl":null,"id":16570658,"hc":null,"bdatb":null}],"img":null,"tv":null,"con":null,"marketdefinition":null,"id":"1.258926623"}],"conflatems":null,"op":"mcm","id":3}
{"ct":null,"SegmentType":null,"clk":"AMM2ANM6AOc3","heartbeatms":null,"pt":1780839628676,"initialclk":null,"mc":[{"rc":[{"tv":240824.04000000001,"batb":null,"spb":null,"bdatl":null,"trd":[[9.8000000000000007,615.63999999999999]],"spf":null,"ltp":9.8000000000000007,"atb":[[8.1999999999999993,304.10000000000002]],"spl":null,"spn":null,"atl":[[9.8000000000000007,128]],"batl":null,"id":16570658,"hc":null,"bdatb":null},{"tv":null,"batb":null,"spb":null,"bdatl":null,"trd":null,"spf":null,"ltp":null,"atb":null,"spl":null,"spn":null,"atl":[[1.1399999999999999,20509.93]],"batl":null,"id":19924823,"hc":null,"bdatb":null}],"img":null,"tv":2119197.9700000002,"con":null,"marketdefinition":null,"id":"1.258926623"}],"conflatems":null,"op":"mcm","id":3}
{"ct":null,"SegmentType":null,"clk":"ANE2AOs6APg3","heartbeatms":null,"pt":1780839628877,"initialclk":null,"mc":[{"rc":[{"tv":240910.42000000001,"batb":null,"spb":null,"bdatl":null,"trd":[[9.5999999999999996,218]],"spf":null,"ltp":9.5999999999999996,"atb":[[9.5999999999999996,89.640000000000001]],"spl":null,"spn":null,"atl":null,"batl":null,"id":16570658,"hc":null,"bdatb":null}],"img":null,"tv":2119284.3500000001,"con":null,"marketdefinition":null,"id":"1.258926623"}],"conflatems":null,"op":"mcm","id":3}
{"ct":null,"SegmentType":null,"clk":"APM2AKY7AK04","heartbeatms":null,"pt":1780839629394,"initialclk":null,"mc":[{"rc":[{"tv":null,"batb":null,"spb":null,"bdatl":null,"trd":null,"spf":null,"ltp":null,"atb":[[9.1999999999999993,415.14999999999998]],"spl":null,"spn":null,"atl":null,"batl":null,"id":16570658,"hc":null,"bdatb":null}],"img":null,"tv":null,"con":null,"marketdefinition":null,"id":"1.258926623"}],"conflatems":null,"op":"mcm","id":3}
{"ct":null,"SegmentType":null,"clk":"AIY3AMQ7AMA4","heartbeatms":null,"pt":1780839629598,"initialclk":null,"mc":[{"rc":[{"tv":null,"batb":null,"spb":null,"bdatl":null,"trd":null,"spf":null,"ltp":null,"atb":[[1.1000000000000001,53439.120000000003]],"spl":null,"spn":null,"atl":[[1.1200000000000001,26727.209999999999]],"batl":null,"id":19924823,"hc":null,"bdatb":null}],"img":null,"tv":null,"con":null,"marketdefinition":null,"id":"1.258926623"}],"conflatems":null,"op":"mcm","id":3}
{"ct":null,"SegmentType":null,"clk":"AJE3AM07AM44","heartbeatms":null,"pt":1780839629701,"initialclk":null,"mc":[{"rc":[{"tv":1878375.9299999999,"batb":null,"spb":null,"bdatl":null,"trd":[[1.1200000000000001,21715.59]],"spf":null,"ltp":null,"atb":null,"spl":null,"spn":null,"atl":[[1.1200000000000001,26726.209999999999]],"batl":null,"id":19924823,"hc":null,"bdatb":null}],"img":null,"tv":2119286.3500000001,"con":null,"marketdefinition":null,"id":"1.258926623"}],"conflatems":null,"op":"mcm","id":3}
{"ct":null,"SegmentType":null,"clk":"AJo3ANQ7ANo4","heartbeatms":null,"pt":1780839629804,"initialclk":null,"mc":[{"rc":[{"tv":null,"batb":null,"spb":null,"bdatl":null,"trd":null,"spf":null,"ltp":null,"atb":null,"spl":null,"spn":null,"atl":[[1.51,228]],"batl":null,"id":19924823,"hc":null,"bdatb":null}],"img":null,"tv":null,"con":null,"marketdefinition":null,"id":"1.258926623"}],"conflatems":null,"op":"mcm","id":3}
{"ct":null,"SegmentType":null,"clk":"AMQ3AIc8AIo5","heartbeatms":null,"pt":1780839630280,"initialclk":null,"mc":[{"rc":[{"tv":null,"batb":null,"spb":null,"bdatl":null,"trd":null,"spf":null,"ltp":null,"atb":null,"spl":null,"spn":null,"atl":[[11,163.19]],"batl":null,"id":16570658,"hc":null,"bdatb":null},{"tv":1878390.4299999999,"batb":null,"spb":null,"bdatl":null,"trd":[[1.1200000000000001,21730.09]],"spf":null,"ltp":null,"atb":null,"spl":null,"spn":null,"atl":[[1.1200000000000001,26718.959999999999]],"batl":null,"id":19924823,"hc":null,"bdatb":null}],"img":null,"tv":2119300.8500000001,"con":null,"marketdefinition":null,"id":"1.258926623"}],"conflatems":null,"op":"mcm","id":3}
{"ct":null,"SegmentType":null,"clk":"AOk3AKw8ALs5","heartbeatms":null,"pt":1780839630686,"initialclk":null,"mc":[{"rc":[{"tv":null,"batb":null,"spb":null,"bdatl":null,"trd":null,"spf":null,"ltp":null,"atb":null,"spl":null,"spn":null,"atl":[[10.5,3.25]],"batl":null,"id":16570658,"hc":null,"bdatb":null},{"tv":1878402.9099999999,"batb":null,"spb":null,"bdatl":null,"trd":[[1.1100000000000001,12.48]],"spf":null,"ltp":1.1100000000000001,"atb":[[1.1100000000000001,53880.830000000002]],"spl":null,"spn":null,"atl":null,"batl":null,"id":19924823,"hc":null,"bdatb":null}],"img":null,"tv":2119313.3300000001,"con":null,"marketdefinition":null,"id":"1.258926623"}],"conflatems":null,"op":"mcm","id":3}
{"ct":null,"SegmentType":null,"clk":"AJY4ANs8APQ5","heartbeatms":null,"pt":1780839631202,"initialclk":null,"mc":[{"rc":[{"tv":1878403.3999999999,"batb":null,"spb":null,"bdatl":null,"trd":[[1.1200000000000001,21730.580000000002]],"spf":null,"ltp":1.1200000000000001,"atb":null,"spl":null,"spn":null,"atl":[[1.1200000000000001,26718.720000000001]],"batl":null,"id":19924823,"hc":null,"bdatb":null}],"img":null,"tv":2119313.8199999998,"con":null,"marketdefinition":null,"id":"1.258926623"}],"conflatems":null,"op":"mcm","id":3}
{"ct":null,"SegmentType":null,"clk":"AKA4AOY8AP85","heartbeatms":null,"pt":1780839631312,"initialclk":null,"mc":[{"rc":[{"tv":1880403.3999999999,"batb":null,"spb":null,"bdatl":null,"trd":[[1.1100000000000001,2012.48]],"spf":null,"ltp":1.1100000000000001,"atb":[[1.1100000000000001,52880.830000000002]],"spl":null,"spn":null,"atl":null,"batl":null,"id":19924823,"hc":null,"bdatb":null}],"img":null,"tv":2121313.8199999998,"con":null,"marketdefinition":null,"id":"1.258926623"}],"conflatems":null,"op":"mcm","id":3}
{"ct":null,"SegmentType":null,"clk":"AM44AJ09ALE6","heartbeatms":null,"pt":1780839631785,"initialclk":null,"mc":[{"rc":[{"tv":1880515.4099999999,"batb":null,"spb":null,"bdatl":null,"trd":[[1.1200000000000001,21842.59]],"spf":null,"ltp":1.1200000000000001,"atb":null,"spl":null,"spn":null,"atl":[[1.1200000000000001,26662.709999999999]],"batl":null,"id":19924823,"hc":null,"bdatb":null}],"img":null,"tv":2121425.8300000001,"con":null,"marketdefinition":null,"id":"1.258926623"}],"conflatems":null,"op":"mcm","id":3}
{"ct":null,"SegmentType":null,"clk":"AN84ALU9AMM6","heartbeatms":null,"pt":1780839631984,"initialclk":null,"mc":[{"rc":[{"tv":1880549.9399999999,"batb":null,"spb":null,"bdatl":null,"trd":[[1.1200000000000001,21877.119999999999]],"spf":null,"ltp":null,"atb":null,"spl":null,"spn":null,"atl":[[1.1200000000000001,26645.439999999999]],"batl":null,"id":19924823,"hc":null,"bdatb":null}],"img":null,"tv":2121460.3599999999,"con":null,"marketdefinition":null,"id":"1.258926623"}],"conflatems":null,"op":"mcm","id":3}
{"ct":null,"SegmentType":null,"clk":"AOk4ALo9AM86","heartbeatms":null,"pt":1780839632087,"initialclk":null,"mc":[{"rc":[{"tv":240911.84,"batb":null,"spb":null,"bdatl":null,"trd":[[9.5999999999999996,219.41999999999999]],"spf":null,"ltp":null,"atb":[[9.5999999999999996,88.930000000000007]],"spl":null,"spn":null,"atl":null,"batl":null,"id":16570658,"hc":null,"bdatb":null}],"img":null,"tv":2121461.7799999998,"con":null,"marketdefinition":null,"id":"1.258926623"}],"conflatems":null,"op":"mcm","id":3}
{"ct":null,"SegmentType":null,"clk":"AIc5AM89AOY6","heartbeatms":null,"pt":1780839632295,"initialclk":null,"mc":[{"rc":[{"tv":1880564.4399999999,"batb":null,"spb":null,"bdatl":null,"trd":[[1.1200000000000001,21891.619999999999]],"spf":null,"ltp":null,"atb":null,"spl":null,"spn":null,"atl":[[1.1200000000000001,26638.189999999999]],"batl":null,"id":19924823,"hc":null,"bdatb":null}],"img":null,"tv":2121476.2799999998,"con":null,"marketdefinition":null,"id":"1.258926623"}],"conflatems":null,"op":"mcm","id":3}
{"ct":null,"SegmentType":null,"clk":"AJk5AOM9APc6","heartbeatms":null,"pt":1780839632504,"initialclk":null,"mc":[{"rc":[{"tv":null,"batb":null,"spb":null,"bdatl":null,"trd":null,"spf":null,"ltp":null,"atb":null,"spl":null,"spn":null,"atl":[[1.1200000000000001,26176.400000000001]],"batl":null,"id":19924823,"hc":null,"bdatb":null}],"img":null,"tv":null,"con":null,"marketdefinition":null,"id":"1.258926623"}],"conflatems":null,"op":"mcm","id":3}
{"ct":null,"SegmentType":null,"clk":"AKw5APM9AI07","heartbeatms":null,"pt":1780839632705,"initialclk":null,"mc":[{"rc":[{"tv":240912.01999999999,"batb":null,"spb":null,"bdatl":null,"trd":[[9.5999999999999996,219.59999999999999]],"spf":null,"ltp":null,"atb":[[9.5999999999999996,88.840000000000003]],"spl":null,"spn":null,"atl":null,"batl":null,"id":16570658,"hc":null,"bdatb":null}],"img":null,"tv":2121476.46,"con":null,"marketdefinition":null,"id":"1.258926623"}],"conflatems":null,"op":"mcm","id":3}
{"ct":null,"SegmentType":null,"clk":"ALQ5APk9AJE7","heartbeatms":null,"pt":1780839632766,"initialclk":null,"mc":[{"rc":[{"tv":null,"batb":null,"spb":null,"bdatl":null,"trd":null,"spf":null,"ltp":null,"atb":[[7.5999999999999996,23.170000000000002]],"spl":null,"spn":null,"atl":null,"batl":null,"id":16570658,"hc":null,"bdatb":null},{"tv":null,"batb":null,"spb":null,"bdatl":null,"trd":null,"spf":null,"ltp":null,"atb":null,"spl":null,"spn":null,"atl":[[1.1499999999999999,10334.4]],"batl":null,"id":19924823,"hc":null,"bdatb":null}],"img":null,"tv":null,"con":null,"marketdefinition":null,"id":"1.258926623"}],"conflatems":null,"op":"mcm","id":3}
{"ct":null,"SegmentType":null,"clk":"AMY5AI8\u002BAKg7","heartbeatms":null,"pt":1780839632980,"initialclk":null,"mc":[{"rc":[{"tv":null,"batb":null,"spb":null,"bdatl":null,"trd":null,"spf":null,"ltp":null,"atb":[[7.5999999999999996,34.75]],"spl":null,"spn":null,"atl":null,"batl":null,"id":16570658,"hc":null,"bdatb":null},{"tv":null,"batb":null,"spb":null,"bdatl":null,"trd":null,"spf":null,"ltp":null,"atb":null,"spl":null,"spn":null,"atl":[[1.1499999999999999,10410.92]],"batl":null,"id":19924823,"hc":null,"bdatb":null}],"img":null,"tv":null,"con":null,"marketdefinition":null,"id":"1.258926623"}],"conflatems":null,"op":"mcm","id":3}
{"ct":null,"SegmentType":null,"clk":"AM85AJg\u002BAK87","heartbeatms":null,"pt":1780839633085,"initialclk":null,"mc":[{"rc":[{"tv":null,"batb":null,"spb":null,"bdatl":null,"trd":null,"spf":null,"ltp":null,"atb":[[8.1999999999999993,314.82999999999998]],"spl":null,"spn":null,"atl":null,"batl":null,"id":16570658,"hc":null,"bdatb":null},{"tv":null,"batb":null,"spb":null,"bdatl":null,"trd":null,"spf":null,"ltp":null,"atb":null,"spl":null,"spn":null,"atl":[[1.1399999999999999,20587.119999999999]],"batl":null,"id":19924823,"hc":null,"bdatb":null}],"img":null,"tv":null,"con":null,"marketdefinition":null,"id":"1.258926623"}],"conflatems":null,"op":"mcm","id":3}
{"ct":null,"SegmentType":null,"clk":"AJM6AOw\u002BAKI8","heartbeatms":null,"pt":1780839634000,"initialclk":null,"mc":[{"rc":[{"tv":241391.95999999999,"batb":null,"spb":null,"bdatl":null,"trd":[[9.8000000000000007,871.63],[10,210.44999999999999],[9.5999999999999996,233.09999999999999]],"spf":null,"ltp":10,"atb":[[9.5999999999999996,82.090000000000003]],"spl":null,"spn":null,"atl":[[9.8000000000000007,0],[10,31.010000000000002]],"batl":null,"id":16570658,"hc":null,"bdatb":null},{"tv":null,"batb":null,"spb":null,"bdatl":null,"trd":null,"spf":null,"ltp":null,"atb":[[1.03,88933.740000000005]],"spl":null,"spn":null,"atl":null,"batl":null,"id":19924823,"hc":null,"bdatb":null}],"img":null,"tv":2121956.3999999999,"con":null,"marketdefinition":null,"id":"1.258926623"}],"conflatems":null,"op":"mcm","id":3}
{"ct":null,"SegmentType":null,"clk":"Amc6AKI/APE8","heartbeatms":null,"pt":1780839634584,"initialclk":null,"mc":[{"rc":[{"tv":null,"batb":null,"spb":null,"bdatl":null,"trd":null,"spf":null,"ltp":null,"atb":[[8.4000000000000004,179.56999999999999]],"spl":null,"spn":null,"atl":[[10.5,146.09999999999999]],"batl":null,"id":16570658,"hc":null,"bdatb":null},{"tv":null,"batb":null,"spb":null,"bdatl":null,"trd":null,"spf":null,"ltp":null,"atb":null,"spl":null,"spn":null,"atl":[[1.1399999999999999,21902.91]],"batl":null,"id":19924823,"hc":null,"bdatb":null}],"img":null,"tv":null,"con":null,"marketdefinition":null,"id":"1.258926623"}],"conflatems":null,"op":"mcm","id":3}
{"ct":null,"SegmentType":null,"clk":"AN06AL0/AIw9","heartbeatms":null,"pt":1780839634883,"initialclk":null,"mc":[{"rc":[{"tv":null,"batb":null,"spb":null,"bdatl":null,"trd":null,"spf":null,"ltp":null,"atb":null,"spl":null,"spn":null,"atl":[[13,0.98999999999999999],[11,26.829999999999998]],"batl":null,"id":16570658,"hc":null,"bdatb":null}],"img":null,"tv":null,"con":null,"marketdefinition":null,"id":"1.258926623"}],"conflatems":null,"op":"mcm","id":3}
{"ct":null,"SegmentType":null,"clk":"AOQ6AMU/AJU9","heartbeatms":null,"pt":1780839634986,"initialclk":null,"mc":[{"rc":[{"tv":null,"batb":null,"spb":null,"bdatl":null,"trd":null,"spf":null,"ltp":null,"atb":null,"spl":null,"spn":null,"atl":[[10.5,153.46000000000001]],"batl":null,"id":16570658,"hc":null,"bdatb":null},{"tv":1880578.4399999999,"batb":null,"spb":null,"bdatl":null,"trd":[[1.1200000000000001,21905.619999999999]],"spf":null,"ltp":null,"atb":null,"spl":null,"spn":null,"atl":[[1.1200000000000001,26169.41]],"batl":null,"id":19924823,"hc":null,"bdatb":null}],"img":null,"tv":2121970.3999999999,"con":null,"marketdefinition":null,"id":"1.258926623"}],"conflatems":null,"op":"mcm","id":3}
{"ct":null,"SegmentType":null,"clk":"AIw7AOk/AMU9","heartbeatms":null,"pt":1780839635402,"initialclk":null,"mc":[{"rc":[{"tv":1880580.4399999999,"batb":null,"spb":null,"bdatl":null,"trd":[[1.1200000000000001,21907.619999999999]],"spf":null,"ltp":null,"atb":null,"spl":null,"spn":null,"atl":[[1.1200000000000001,26168.41]],"batl":null,"id":19924823,"hc":null,"bdatb":null}],"img":null,"tv":2121972.3999999999,"con":null,"marketdefinition":null,"id":"1.258926623"}],"conflatems":null,"op":"mcm","id":3}
{"ct":null,"SegmentType":null,"clk":"AJM7APE/AM89","heartbeatms":null,"pt":1780839635505,"initialclk":null,"mc":[{"rc":[{"tv":241417.95999999999,"batb":null,"spb":null,"bdatl":null,"trd":[[9.5999999999999996,259.10000000000002]],"spf":null,"ltp":9.5999999999999996,"atb":[[9.5999999999999996,69.090000000000003]],"spl":null,"spn":null,"atl":null,"batl":null,"id":16570658,"hc":null,"bdatb":null}],"img":null,"tv":2121998.3999999999,"con":null,"marketdefinition":null,"id":"1.258926623"}],"conflatems":null,"op":"mcm","id":3}
{"ct":null,"SegmentType":null,"clk":"AJ47APk/ANM9","heartbeatms":null,"pt":1780839635568,"initialclk":null,"mc":[{"rc":[{"tv":null,"batb":null,"spb":null,"bdatl":null,"trd":null,"spf":null,"ltp":null,"atb":[[1.1100000000000001,52881.849999999999]],"spl":null,"spn":null,"atl":null,"batl":null,"id":19924823,"hc":null,"bdatb":null}],"img":null,"tv":null,"con":null,"marketdefinition":null,"id":"1.258926623"}],"conflatems":null,"op":"mcm","id":3}
{"ct":null,"SegmentType":null,"clk":"AL47AI1AAP09","heartbeatms":null,"pt":1780839635886,"initialclk":null,"mc":[{"rc":[{"tv":null,"batb":null,"spb":null,"bdatl":null,"trd":null,"spf":null,"ltp":null,"atb":null,"spl":null,"spn":null,"atl":[[1.1299999999999999,18196.09]],"batl":null,"id":19924823,"hc":null,"bdatb":null}],"img":null,"tv":null,"con":null,"marketdefinition":null,"id":"1.258926623"}],"conflatems":null,"op":"mcm","id":3}
{"ct":null,"SegmentType":null,"clk":"AI88APJAAO4\u002B","heartbeatms":null,"pt":1780839636904,"initialclk":null,"mc":[{"rc":[{"tv":1881380.4399999999,"batb":null,"spb":null,"bdatl":null,"trd":[[1.1200000000000001,22707.619999999999]],"spf":null,"ltp":null,"atb":null,"spl":null,"spn":null,"atl":[[1.1200000000000001,25768.41]],"batl":null,"id":19924823,"hc":null,"bdatb":null}],"img":null,"tv":2122798.3999999999,"con":null,"marketdefinition":null,"id":"1.258926623"}],"conflatems":null,"op":"mcm","id":3}
{"ct":null,"SegmentType":null,"clk":"AKI8AidBAIs/","heartbeatms":null,"pt":1780839637071,"initialclk":null,"mc":[{"rc":[{"tv":null,"batb":null,"spb":null,"bdatl":null,"trd":null,"spf":null,"ltp":null,"atb":null,"spl":null,"spn":null,"atl":[[14.5,1.5]],"batl":null,"id":16570658,"hc":null,"bdatb":null}],"img":null,"tv":null,"con":null,"marketdefinition":null,"id":"1.258926623"}],"conflatems":null,"op":"mcm","id":3}
{"ct":null,"SegmentType":null,"clk":"ALE8AKFBAKE/","heartbeatms":null,"pt":1780839637276,"initialclk":null,"mc":[{"rc":[{"tv":241417.98000000001,"batb":null,"spb":null,"bdatl":null,"trd":[[9.5999999999999996,259.12]],"spf":null,"ltp":null,"atb":[[9.5999999999999996,69.079999999999998]],"spl":null,"spn":null,"atl":null,"batl":null,"id":16570658,"hc":null,"bdatb":null},{"tv":null,"batb":null,"spb":null,"bdatl":null,"trd":null,"spf":null,"ltp":null,"atb":[[1.03,88934.009999999995]],"spl":null,"spn":null,"atl":null,"batl":null,"id":19924823,"hc":null,"bdatb":null}],"img":null,"tv":2122798.4199999999,"con":null,"marketdefinition":null,"id":"1.258926623"}],"conflatems":null,"op":"mcm","id":3}
{"ct":null,"SegmentType":null,"clk":"AL88AKlBAKk/","heartbeatms":null,"pt":1780839637378,"initialclk":null,"mc":[{"rc":[{"tv":241480,"batb":null,"spb":null,"bdatl":null,"trd":[[10,272.47000000000003]],"spf":null,"ltp":10,"atb":null,"spl":null,"spn":null,"atl":[[10,0]],"batl":null,"id":16570658,"hc":null,"bdatb":null}],"img":null,"tv":2122860.4399999999,"con":null,"marketdefinition":null,"id":"1.258926623"}],"conflatems":null,"op":"mcm","id":3}
{"ct":null,"SegmentType":null,"clk":"AMg8ALNBALY/","heartbeatms":null,"pt":1780839637486,"initialclk":null,"mc":[{"rc":[{"tv":null,"batb":null,"spb":null,"bdatl":null,"trd":null,"spf":null,"ltp":null,"atb":null,"spl":null,"spn":null,"atl":[[10.5,204.41]],"batl":null,"id":16570658,"hc":null,"bdatb":null}],"img":null,"tv":null,"con":null,"marketdefinition":null,"id":"1.258926623"}],"conflatems":null,"op":"mcm","id":3}
{"ct":null,"SegmentType":null,"clk":"AJw9AM5BAMs/","heartbeatms":null,"pt":1780839637687,"initialclk":null,"mc":[{"rc":[{"tv":241520,"batb":null,"spb":null,"bdatl":null,"trd":[[9.5999999999999996,299.12]],"spf":null,"ltp":9.5999999999999996,"atb":[[7.4000000000000004,219.19999999999999],[9.5999999999999996,49.079999999999998]],"spl":null,"spn":null,"atl":[[10,8.6400000000000006]],"batl":null,"id":16570658,"hc":null,"bdatb":null},{"tv":null,"batb":null,"spb":null,"bdatl":null,"trd":null,"spf":null,"ltp":null,"atb":[[1.03,88933.740000000005]],"spl":null,"spn":null,"atl":[[1.24,1212.4200000000001]],"batl":null,"id":19924823,"hc":null,"bdatb":null}],"img":null,"tv":2122900.4399999999,"con":null,"marketdefinition":null,"id":"1.258926623"}],"conflatems":null,"op":"mcm","id":3}
{"ct":null,"SegmentType":null,"clk":"AKY9ANlBANM/","heartbeatms":null,"pt":1780839637787,"initialclk":null,"mc":[{"rc":[{"tv":null,"batb":null,"spb":null,"bdatl":null,"trd":null,"spf":null,"ltp":null,"atb":[[9,498.25999999999999]],"spl":null,"spn":null,"atl":null,"batl":null,"id":16570658,"hc":null,"bdatb":null},{"tv":null,"batb":null,"spb":null,"bdatl":null,"trd":null,"spf":null,"ltp":null,"atb":null,"spl":null,"spn":null,"atl":[[1.1299999999999999,18396.09]],"batl":null,"id":19924823,"hc":null,"bdatb":null}],"img":null,"tv":null,"con":null,"marketdefinition":null,"id":"1.258926623"}],"conflatems":null,"op":"mcm","id":3}
{"ct":null,"SegmentType":null,"clk":"ALA9AONBANw/","heartbeatms":null,"pt":1780839637892,"initialclk":null,"mc":[{"rc":[{"tv":null,"batb":null,"spb":null,"bdatl":null,"trd":null,"spf":null,"ltp":null,"atb":null,"spl":null,"spn":null,"atl":[[10,83.129999999999995]],"batl":null,"id":16570658,"hc":null,"bdatb":null}],"img":null,"tv":null,"con":null,"marketdefinition":null,"id":"1.258926623"}],"conflatems":null,"op":"mcm","id":3}
{"ct":null,"SegmentType":null,"clk":"AMg9AI1CAP8/","heartbeatms":null,"pt":1780839638206,"initialclk":null,"mc":[{"rc":[{"tv":null,"batb":null,"spb":null,"bdatl":null,"trd":null,"spf":null,"ltp":null,"atb":[[9.4000000000000004,325.06999999999999],[9.1999999999999993,306.44999999999999]],"spl":null,"spn":null,"atl":[[12.5,160.77000000000001]],"batl":null,"id":16570658,"hc":null,"bdatb":null},{"tv":null,"batb":null,"spb":null,"bdatl":null,"trd":null,"spf":null,"ltp":null,"atb":null,"spl":null,"spn":null,"atl":[[1.1399999999999999,22247.16],[1.1200000000000001,8636.0499999999993]],"batl":null,"id":19924823,"hc":null,"bdatb":null}],"img":null,"tv":null,"con":null,"marketdefinition":null,"id":"1.258926623"}],"conflatems":null,"op":"mcm","id":3}
{"ct":null,"SegmentType":null,"clk":"ANA9AJFCAItA","heartbeatms":null,"pt":1780839638302,"initialclk":null,"mc":[{"rc":[{"tv":null,"batb":null,"spb":null,"bdatl":null,"trd":null,"spf":null,"ltp":null,"atb":[[8.4000000000000004,1],[7.7999999999999998,78.739999999999995],[9.1999999999999993,252.44999999999999],[8,574.62]],"spl":null,"spn":null,"atl":[[12.5,200.05000000000001],[12,487.52999999999997],[10.5,59.560000000000002]],"batl":null,"id":16570658,"hc":null,"bdatb":null},{"tv":null,"batb":null,"spb":null,"bdatl":null,"trd":null,"spf":null,"ltp":null,"atb":[[1.0800000000000001,39062.260000000002],[1.1000000000000001,52075.489999999998],[1.1100000000000001,52879.849999999999]],"spl":null,"spn":null,"atl":[[1.1299999999999999,16853.09],[1.1399999999999999,20931.369999999999]],"batl":null,"id":19924823,"hc":null,"bdatb":null}],"img":null,"tv":null,"con":null,"marketdefinition":null,"id":"1.258926623"}],"conflatems":null,"op":"mcm","id":3}
{"ct":null,"SegmentType":null,"clk":"ANc9AJtCAJpA","heartbeatms":null,"pt":1780839638413,"initialclk":null,"mc":[{"rc":[{"tv":null,"batb":null,"spb":null,"bdatl":null,"trd":null,"spf":null,"ltp":null,"atb":null,"spl":null,"spn":null,"atl":[[9.8000000000000007,76.010000000000005],[10.5,1.25]],"batl":null,"id":16570658,"hc":null,"bdatb":null},{"tv":1881382.1699999999,"batb":null,"spb":null,"bdatl":null,"trd":[[1.1200000000000001,22709.349999999999]],"spf":null,"ltp":null,"atb":null,"spl":null,"spn":null,"atl":[[1.1299999999999999,17989.759999999998],[1.1200000000000001,8635.1900000000005]],"batl":null,"id":19924823,"hc":null,"bdatb":null}],"img":null,"tv":2122902.1699999999,"con":null,"marketdefinition":null,"id":"1.258926623"}],"conflatems":null,"op":"mcm","id":3}
{"ct":null,"SegmentType":null,"clk":"AOE9AKRCAKJA","heartbeatms":null,"pt":1780839638511,"initialclk":null,"mc":[{"rc":[{"tv":null,"batb":null,"spb":null,"bdatl":null,"trd":null,"spf":null,"ltp":null,"atb":[[9.4000000000000004,56.5],[9.1999999999999993,116.15000000000001],[8,584.91999999999996],[9.5999999999999996,0]],"spl":null,"spn":null,"atl":[[10,8.6400000000000006],[9.5999999999999996,1]],"batl":null,"id":16570658,"hc":null,"bdatb":null},{"tv":null,"batb":null,"spb":null,"bdatl":null,"trd":null,"spf":null,"ltp":null,"atb":[[1.1000000000000001,47071.860000000001],[1.1100000000000001,51755.349999999999]],"spl":null,"spn":null,"atl":[[1.1200000000000001,7520.7299999999996]],"batl":null,"id":19924823,"hc":null,"bdatb":null}],"img":null,"tv":null,"con":null,"marketdefinition":null,"id":"1.258926623"}],"conflatems":null,"op":"mcm","id":3}
{"ct":null,"SegmentType":null,"clk":"AOo9AKtCAKZA","heartbeatms":null,"pt":1780839638578,"initialclk":null,"mc":[{"rc":[{"tv":null,"batb":null,"spb":null,"bdatl":null,"trd":null,"spf":null,"ltp":null,"atb":[[9.4000000000000004,0],[8.1999999999999993,63.369999999999997],[9.1999999999999993,58.140000000000001],[8,502.81]],"spl":null,"spn":null,"atl":[[9.8000000000000007,0],[12.5,99.219999999999999],[12,216.47]],"batl":null,"id":16570658,"hc":null,"bdatb":null},{"tv":null,"batb":null,"spb":null,"bdatl":null,"trd":null,"spf":null,"ltp":null,"atb":[[1.0900000000000001,56162.440000000002],[1.1100000000000001,51756.779999999999]],"spl":null,"spn":null,"atl":[[1.1299999999999999,16853.09]],"batl":null,"id":19924823,"hc":null,"bdatb":null}],"img":null,"tv":null,"con":null,"marketdefinition":null,"id":"1.258926623"}],"conflatems":null,"op":"mcm","id":3}
{"ct":null,"SegmentType":null,"clk":"APM9ALZCAK9A","heartbeatms":null,"pt":1780839638676,"initialclk":null,"mc":[{"rc":[{"tv":null,"batb":null,"spb":null,"bdatl":null,"trd":null,"spf":null,"ltp":null,"atb":[[7.5999999999999996,46.329999999999998]],"spl":null,"spn":null,"atl":null,"batl":null,"id":16570658,"hc":null,"bdatb":null},{"tv":null,"batb":null,"spb":null,"bdatl":null,"trd":null,"spf":null,"ltp":null,"atb":null,"spl":null,"spn":null,"atl":[[1.1499999999999999,10487.440000000001]],"batl":null,"id":19924823,"hc":null,"bdatb":null}],"img":null,"tv":null,"con":null,"marketdefinition":null,"id":"1.258926623"}],"conflatems":null,"op":"mcm","id":3}
