{"op":"connection","connectionId":"201-200726061308-11113449"}{"op":"status","id":0,"statusCode":"SUCCESS","connectionClosed":false,"connectionsAvailable":4}{"op":"status","id":1,"statusCode":"SUCCESS","connectionClosed":false}{"op":"ocm","id":1,"initialClk":"KrewuuAGJ8Gnzs4GKr/XydkGKtXww98GJ6DoyNQG","clk":"AAAAAAAAAAAAAA==","conflateMs":0,"heartbeatMs":5000,"pt":1784527989289,"ct":"SUB_IMAGE"}{"op":"status","statusCode":"SUCCESS","connectionClosed":false}{"op":"mcm","initialClk":"KqXX+e8KK4b/qukKK5XBodwK","clk":"AAAAAAAA","conflateMs":0,"heartbeatMs":5000,"pt":1784527989586,"ct":"SUB_IMAGE","mc":[{"id":"1.260137374","marketDefinition":{"bspMarket":true,"turnInPlayEnabled":true,"persistenceEnabled":true,"marketBaseRate":10,"eventId":"35834259","eventTypeId":"7","numberOfWinners":1,"bettingType":"ODDS","marketType":"WIN","marketTime":"2026-07-20T06:40:00.000Z","suspendTime":"2026-07-20T06:40:00.000Z","bspReconciled":false,"complete":true,"inPlay":false,"crossMatching":true,"runnersVoidable":false,"numberOfActiveRunners":12,"betDelay":0,"status":"OPEN","runners":[{"adjustmentFactor":2.548,"status":"ACTIVE","sortPriority":1,"id":68064063},{"adjustmentFactor":28.338,"status":"ACTIVE","sortPriority":2,"id":99274452},{"adjustmentFactor":38.202,"status":"ACTIVE","sortPriority":3,"id":100720591},{"adjustmentFactor":14.112,"status":"ACTIVE","sortPriority":4,"id":25417481},{"adjustmentFactor":2.095,"status":"ACTIVE","sortPriority":5,"id":100720592},{"adjustmentFactor":4.065,"status":"ACTIVE","sortPriority":6,"id":4054763},{"adjustmentFactor":2.548,"status":"ACTIVE","sortPriority":7,"id":82788200},{"adjustmentFactor":2.94,"status":"ACTIVE","sortPriority":8,"id":79844992},{"adjustmentFactor":1.346,"status":"ACTIVE","sortPriority":9,"id":100720594},{"adjustmentFactor":2.095,"status":"ACTIVE","sortPriority":10,"id":100720596},{"adjustmentFactor":0.365,"status":"ACTIVE","sortPriority":11,"id":100720597},{"adjustmentFactor":1.346,"status":"ACTIVE","sortPriority":12,"id":100720598},{"adjustmentFactor":7.225,"status":"REMOVED","sortPriority":13,"removalDate":"2026-07-19T09:30:12.000Z","id":100720590},{"adjustmentFactor":1.117,"status":"REMOVED","sortPriority":14,"removalDate":"2026-07-19T09:30:21.000Z","id":2500429},{"adjustmentFactor":5.068,"status":"REMOVED","sortPriority":15,"removalDate":"2026-07-19T14:08:42.000Z","id":98214101},{"adjustmentFactor":0.865,"status":"REMOVED","sortPriority":16,"removalDate":"2026-07-19T14:09:09.000Z","id":92206918},{"adjustmentFactor":0.431,"status":"REMOVED","sortPriority":17,"removalDate":"2026-07-19T18:38:35.000Z","id":100720595},{"adjustmentFactor":6.065,"status":"REMOVED","sortPriority":18,"removalDate":"2026-07-19T21:47:00.000Z","id":100720593},{"adjustmentFactor":4.672,"status":"REMOVED","sortPriority":19,"removalDate":"2026-07-19T21:47:09.000Z","id":61337616}],"regulators":["MR_INT"],"venue":"Gunnedah","countryCode":"AU","discountAllowed":true,"timezone":"Australia/Sydney","openDate":"2026-07-20T02:55:00.000Z","version":7504099953,"raceType":"Flat","priceLadderDefinition":{"type":"CLASSIC"}},"rc":[{"trd":[[19,9.01],[20,1]],"batb":[[9,15.5,3.45],[8,16,29.9],[7,16.5,3.23],[6,17,3.12],[5,17.5,3.03],[4,18,2.94],[3,18.5,7.77],[2,19.5,9.19],[1,20,1],[0,21,1.96]],"batl":[[2,250,10],[0,150,3.46],[1,180,1],[4,920,2.1],[3,600,10.02]],"ltp":19,"tv":10.01,"id":82788200},{"batb":[[1,23,1.66],[0,24,2.2],[9,16,11.6],[8,16.5,3.23],[7,17,20.88],[6,17.5,3.03],[5,18,10.15],[4,18.5,2.86],[3,21,6.8],[2,22,2.38]],"batl":[[3,920,2.1],[2,600,10.02],[0,160,3.37],[1,230,1]],"id":68064063},{"trd":[[3.95,99.16],[4.3,4.66]],"batb":[[0,3.75,1.4],[9,1.02,22],[8,1.12,100],[7,1.51,98.04],[6,1.77,7.79],[5,2.08,5.56],[4,3.1,50.55],[3,3.35,76.83],[2,3.4,31.19],[1,3.7,35.47]],"batl":[[9,34,15],[8,22,5.36],[7,9.8,41.47],[6,9.6,11.79],[5,8.8,11.32],[4,8.4,1.79],[3,7.4,6.93],[2,6.6,1],[1,4.5,103.82],[0,4.4,2.67]],"ltp":3.95,"tv":103.82,"id":99274452},{"trd":[[14.5,18.85],[15.5,1.3],[15,0.61]],"batb":[[0,13.5,1.11],[1,13,13.72],[3,12,7.31],[9,9.6,33.99],[4,11.5,15.17],[2,12.5,13.61],[7,10,4],[8,9.8,4],[6,10.5,4],[5,11,4]],"batl":[[6,920,2.1],[5,600,12.1],[4,440,2.12],[3,250,10],[2,85,3.03],[1,34,4.8],[0,26,1]],"ltp":14.5,"tv":20.76,"id":4054763},{"trd":[[2.66,20.76],[2.64,7.57],[2.44,10.08],[2.46,28.25],[2.48,2.92]],"batb":[[0,2.44,12.05],[9,1.01,1154.83],[8,1.02,22],[7,1.12,100],[6,2.24,222.22],[5,2.26,93.09],[4,2.32,1],[3,2.36,1],[2,2.38,85.57],[1,2.4,45.61]],"batl":[[6,5.7,48.78],[5,5.4,12.03],[0,3.55,1],[9,22,5.36],[8,19,1],[7,16,15],[4,4.9,26.62],[3,4.6,7.81],[2,4.3,3.49],[1,4,62.29]],"ltp":2.44,"tv":69.58,"id":100720591},{"trd":[[15,0.78],[16.5,1.22]],"batb":[[3,11.5,14.33],[4,11,4],[9,9.2,4],[8,9.4,4],[7,9.6,33.04],[6,10,4],[5,10.5,15.17],[2,12.5,10.59],[1,13,1.8],[0,13.5,1.05]],"batl":[[7,920,2.1],[6,600,12.1],[5,440,2.12],[4,250,10],[3,85,2.58],[0,26,1],[2,42,11.55],[1,30,2]],"ltp":15,"tv":2,"id":79844992},{"batb":[[9,16,11.15],[8,16.5,21.56],[7,17,3.12],[6,17.5,3.03],[5,18,2.94],[4,18.5,9.24],[3,19,2.78],[2,20,6.89],[0,24,1.74],[1,22,2.33]],"batl":[[1,210,1],[3,920,2.1],[2,600,10.03],[0,160,3.37]],"id":100720592},{"trd":[[7,42.65],[7.2,5.11],[5.7,1.03]],"batb":[[0,6.6,1.38],[9,2.38,4.35],[8,2.94,3.09],[7,5,27.71],[6,5.2,2],[5,5.3,66.08],[4,5.5,19.96],[3,6,24.36],[2,6.2,1.68],[1,6.4,3.24]],"batl":[[9,920,2.1],[8,600,12.1],[7,440,2.12],[6,250,10],[5,22,3.41],[4,21,1],[3,19,12.05],[2,18,11.17],[1,16.5,12.11],[0,15.5,1]],"ltp":7,"tv":48.79,"id":25417481},{"trd":[[30,1.64],[29,1.39]],"batb":[[0,30,6.35],[9,20,2.63],[8,21,2.5],[7,22,2.38],[6,23,8.15],[5,24,2.17],[4,25,2.08],[3,26,4.4],[2,27,1.92],[1,28,2.51]],"batl":[[1,300,1],[0,210,3.23],[2,600,10.02]],"ltp":29,"tv":3.03,"id":100720598},{"batb":[[8,19.5,9.45],[9,19,18.57],[7,20,6.04],[6,22,2.38],[5,23,2.27],[4,24,2.79],[1,27,1.27],[0,28,1.29],[3,25,5.08],[2,26,1.65]],"batl":[[1,260,1],[0,210,3.04],[2,600,10.02]],"id":100720594},{"batb":[[0,32,2.07],[9,22,16.91],[8,23,7.92],[7,24,2.17],[6,25,2.08],[5,26,2],[4,27,1.92],[3,28,1.85],[2,29,5.08],[1,30,5.52]],"batl":[[2,600,10.02],[1,270,1],[0,260,2.91]],"id":100720596},{"batb":[[2,60,3.42],[1,70,1.61],[9,15,2],[8,16,3.91],[7,30,2],[6,44,1.15],[5,46,1.11],[4,48,1.27],[3,50,7.82],[0,85,4.26]],"batl":[[1,450,0.48],[0,410,2.02]],"id":100720597}],"img":true,"tv":257.99},{"id":"1.260136589","marketDefinition":{"bspMarket":true,"turnInPlayEnabled":true,"persistenceEnabled":true,"marketBaseRate":8,"eventId":"35834238","eventTypeId":"7","numberOfWinners":1,"bettingType":"ODDS","marketType":"WIN","marketTime":"2026-07-20T06:47:00.000Z","suspendTime":"2026-07-20T06:47:00.000Z","bspReconciled":false,"complete":true,"inPlay":false,"crossMatching":true,"runnersVoidable":false,"numberOfActiveRunners":10,"betDelay":0,"status":"OPEN","runners":[{"adjustmentFactor":8.09,"status":"ACTIVE","sortPriority":1,"id":41749902},{"adjustmentFactor":17.512,"status":"ACTIVE","sortPriority":2,"id":309962},{"adjustmentFactor":8.949,"status":"ACTIVE","sortPriority":3,"id":54439633},{"adjustmentFactor":27.401,"status":"ACTIVE","sortPriority":4,"id":100019545},{"adjustmentFactor":6.714,"status":"ACTIVE","sortPriority":5,"id":82602855},{"adjustmentFactor":1.091,"status":"ACTIVE","sortPriority":6,"id":6690785},{"adjustmentFactor":1.915,"status":"ACTIVE","sortPriority":7,"id":85017109},{"adjustmentFactor":22.738,"status":"ACTIVE","sortPriority":8,"id":62098141},{"adjustmentFactor":1.915,"status":"ACTIVE","sortPriority":9,"id":100721527},{"adjustmentFactor":3.676,"status":"ACTIVE","sortPriority":10,"id":38407830},{"adjustmentFactor":13.328,"status":"REMOVED","sortPriority":11,"removalDate":"2026-07-19T22:06:22.000Z","id":71179612},{"adjustmentFactor":2.042,"status":"REMOVED","sortPriority":12,"removalDate":"2026-07-19T22:06:31.000Z","id":100721528},{"adjustmentFactor":6.591,"status":"REMOVED","sortPriority":13,"removalDate":"2026-07-19T22:06:39.000Z","id":55415013},{"adjustmentFactor":4.033,"status":"REMOVED","sortPriority":14,"removalDate":"2026-07-19T22:06:46.000Z","id":92784348}],"regulators":["MR_INT"],"venue":"Blackall","countryCode":"AU","discountAllowed":true,"timezone":"Australia/Queensland","openDate":"2026-07-20T03:04:00.000Z","version":7504098577,"raceType":"Flat","priceLadderDefinition":{"type":"CLASSIC"}},"rc":[{"batb":[[1,5.8,28.01],[0,6,10.28],[8,5.1,70.45],[9,5,2],[7,5.2,14.29],[6,5.3,13.95],[5,5.4,13.64],[4,5.5,13.33],[3,5.6,13.04],[2,5.7,18.13]],"batl":[[5,9.8,9.31],[4,9,1.23],[9,12,11.17],[7,10.5,1],[8,11,1],[6,10,1],[3,8.8,1.23],[2,8.6,1.23],[1,8.4,17.13],[0,8.2,1.83]],"id":309962},{"trd":[[2.66,4.15],[2.64,6.23],[3.8,57.84],[3.05,0.02],[3.85,5.2]],"batb":[[5,2.44,84.49],[6,2.42,42.25],[9,2.36,44.12],[8,2.38,43.48],[7,2.4,42.86],[4,2.46,12.8],[3,2.48,62.8],[2,2.52,4.15],[1,2.54,7.73],[0,2.56,1.34]],"batl":[[5,3.2,1],[3,3.1,12.46],[2,3.05,25.95],[4,3.15,39.78],[0,2.98,3.6],[9,3.65,5.53],[8,3.55,5.71],[7,3.3,1],[6,3.25,1],[1,3,6]],"ltp":2.64,"tv":73.44,"id":100019545},{"trd":[[9.2,1.04]],"batb":[[4,8,13.93],[3,8.2,8.33],[7,7.4,49.19],[1,8.8,27.06],[8,7.2,4],[9,7,4],[6,7.6,9.09],[5,7.8,8.82],[2,8.4,11.6],[0,9,2.2]],"batl":[[9,440,2.12],[8,250,10],[7,110,2],[6,42,5.12],[1,16,2.65],[0,15.5,2],[5,28,12.63],[4,21,1],[3,20,12.78],[2,16.5,1.26]],"ltp":9.2,"tv":1.04,"id":54439633},{"trd":[[48,2.8],[46,4],[44,4]],"batb":[[9,21,8.09],[8,22,2.38],[7,23,2.27],[6,24,2.17],[5,25,2.6],[4,26,5.48],[3,27,2.3],[2,28,1.2],[1,30,2.03],[0,32,4.61]],"batl":[[1,190,1.45],[0,48,2],[7,1000,0.52],[6,920,2.1],[5,600,12.1],[4,440,2.12],[3,250,10],[2,210,1]],"ltp":48,"tv":10.8,"id":100721527},{"trd":[[11,3.15],[13.5,19.31],[13,93.92],[12.5,21.38],[12,3.73],[14,0.08],[14.5,1.54],[15.5,4.74]],"batb":[[9,4.6,2.88],[8,5.9,1.22],[7,6.6,25.14],[6,8.4,12.2],[2,9.8,15.22],[1,10,7.02],[0,10.5,11.42],[5,9.2,7.32],[4,9.4,7.14],[3,9.6,10.98]],"batl":[[5,24,3.5],[3,22,3.12],[2,21,2.5],[1,20,13.17],[8,27,12.17],[7,26,1],[0,19.5,6.59],[9,28,2.5],[6,25,2.68],[4,23,1]],"ltp":11,"tv":147.85,"id":41749902},{"batb":[[8,5.5,13.33],[7,5.6,39.99],[6,5.7,14.85],[5,5.8,12.5],[4,5.9,13.97],[3,6,12.42],[2,6.2,1.61],[1,6.4,2.34],[0,6.6,3.14],[9,4.9,92.06]],"batl":[[9,75,2],[8,44,7.36],[7,34,15],[6,18,12.34],[5,17.5,2],[4,15,17.48],[3,12.5,11.17],[2,12,1.25],[1,9.4,1.11],[0,9.2,1.39]],"id":62098141},{"trd":[[18.5,0.14],[17,2],[17.5,4]],"batb":[[9,9.6,4],[8,9.8,4],[7,10,10.67],[6,10.5,15.17],[5,11,22.4],[4,11.5,6.66],[3,12,9.45],[2,12.5,5.39],[1,13,6.74],[0,14,3.96]],"batl":[[3,23,2.66],[0,20,4.96],[9,70,3.04],[8,38,1],[7,36,14.29],[6,26,1],[5,25,1],[4,24,1.95],[2,22,1.77],[1,21,11.88]],"ltp":18.5,"tv":6.14,"id":82602855},{"batb":[[5,22,6.09],[4,23,3.91],[9,19,18.85],[8,19.5,2.7],[7,20,2.63],[6,21,2.5],[3,24,1],[2,25,5.16],[1,26,5.7],[0,27,1.24]],"batl":[[8,920,2.1],[7,650,1],[6,630,1],[5,620,1],[4,600,13.1],[3,440,2.12],[2,250,1],[1,210,1.28],[0,60,2.17]],"id":85017109},{"batb":[[8,13.5,4],[7,14,8.47],[6,14.5,8.14],[5,15,7.86],[3,16,5],[1,17,9.36],[0,17.5,1.6],[9,13,28.07],[4,15.5,5.42],[2,16.5,8.99]],"batl":[[7,920,2.1],[6,600,12.1],[5,440,2.12],[4,250,10],[3,240,2],[2,120,2.26],[1,40,1.07],[0,36,1.19]],"id":38407830},{"trd":[[30,0.87],[29,0.17]],"batb":[[9,23,15.34],[8,24,2.17],[7,25,2.08],[6,26,2],[5,27,2.92],[4,28,5.66],[3,29,3.12],[2,30,6.87],[1,32,3.01],[0,40,2]],"batl":[[7,1000,0.52],[6,920,2.1],[5,630,1],[4,620,1],[3,600,13.1],[2,440,2.13],[1,250,2.2],[0,75,2]],"ltp":29,"tv":1.04,"id":6690785}],"img":true,"tv":240.31},{"id":"1.260191969","marketDefinition":{"bspMarket":true,"turnInPlayEnabled":true,"persistenceEnabled":true,"marketBaseRate":8,"eventId":"35840727","eventTypeId":"7","numberOfWinners":1,"bettingType":"ODDS","marketType":"WIN","marketTime":"2026-07-20T06:50:00.000Z","suspendTime":"2026-07-20T06:50:00.000Z","bspReconciled":false,"complete":true,"inPlay":false,"crossMatching":true,"runnersVoidable":false,"numberOfActiveRunners":10,"betDelay":0,"status":"OPEN","runners":[{"adjustmentFactor":30.525,"status":"ACTIVE","sortPriority":1,"id":67898814},{"adjustmentFactor":2.663,"status":"ACTIVE","sortPriority":2,"id":55245090},{"adjustmentFactor":17.299,"status":"ACTIVE","sortPriority":3,"id":100722597},{"adjustmentFactor":3.606,"status":"ACTIVE","sortPriority":4,"id":16099652},{"adjustmentFactor":15.49,"status":"ACTIVE","sortPriority":5,"id":95302211},{"adjustmentFactor":0.985,"status":"ACTIVE","sortPriority":6,"id":79067598},{"adjustmentFactor":16.331,"status":"ACTIVE","sortPriority":7,"id":99771288},{"adjustmentFactor":2.663,"status":"ACTIVE","sortPriority":8,"id":47393184},{"adjustmentFactor":8.208,"status":"ACTIVE","sortPriority":9,"id":27757624},{"adjustmentFactor":2.23,"status":"ACTIVE","sortPriority":10,"id":68191140}],"regulators":["MR_INT"],"venue":"Stawell","countryCode":"AU","discountAllowed":true,"timezone":"Australia/Sydney","openDate":"2026-07-20T02:24:00.000Z","version":7504104068,"raceType":"Harness","priceLadderDefinition":{"type":"CLASSIC"}},"rc":[{"batb":[[9,7.2,4],[8,7.4,4.52],[7,7.8,16.14],[6,8,4],[5,8.2,16.4],[4,8.4,4],[3,8.8,25.86],[0,10,2.5],[2,9,11.17],[1,9.8,9.82]],"batl":[[2,32,12.17],[9,920,2.1],[8,610,1],[7,600,13.1],[6,440,2.12],[5,250,10],[4,90,1.94],[3,60,16.14],[0,26,4.71],[1,27,11.17]],"id":27757624},{"batb":[[9,1.58,5.37],[8,1.94,6.38],[7,2.32,4.55],[6,3.6,16.14],[5,4,28.56],[4,4.2,63.02],[3,4.4,18.19],[1,4.7,23.36],[0,4.8,5.2],[2,4.6,1]],"batl":[[9,440,2.12],[8,250,10],[7,44,7.36],[6,34,15],[5,19.5,9.86],[4,12,16.14],[3,11.5,17.49],[2,11,11.17],[1,9.8,7.34],[0,9.6,1.56]],"id":100722597},{"batb":[[8,10,20.14],[7,10.5,4],[9,9,4],[6,11,20.17],[5,11.5,14.64],[4,12,4],[3,12.5,4],[2,13,12.17],[1,13.5,6.91],[0,14,1.78]],"batl":[[9,930,0.23],[8,920,2.1],[7,600,13.1],[6,440,2.12],[5,160,1.08],[4,90,16.14],[3,70,1],[2,55,6.59],[1,48,11.17],[0,42,11.55]],"id":16099652},{"batb":[[5,18.5,10.39],[2,20,23.85],[3,19.5,13.6],[9,16.5,1.04],[8,17,3.12],[7,17.5,3.03],[6,18,2.94],[4,19,2.78],[1,24,3.76],[0,25,1]],"batl":[[1,600,10],[0,390,2.69]],"id":68191140},{"trd":[[11.5,2.08]],"batb":[[9,3.05,24.39],[8,4.2,2],[7,4.5,31.12],[6,4.6,72.16],[5,4.7,16.72],[4,5.1,21.08],[3,5.8,2.49],[1,9.2,1.04],[0,9.4,1.06],[2,6.8,1.04]],"batl":[[8,920,2.1],[7,600,12.1],[6,440,2.12],[5,250,10],[4,25,16.14],[3,22,8.23],[2,16.5,14.69],[1,16,1.03],[0,14.5,11.17]],"ltp":11.5,"tv":2.08,"id":99771288},{"batb":[[9,13.5,4],[8,14,3.85],[7,14.5,3.7],[6,15,17.97],[5,15.5,13.17],[4,16,3.33],[3,16.5,3.23],[2,17,1],[1,17.5,6.24],[0,18,1.39]],"batl":[[0,120,1],[1,130,16.14],[6,920,2.1],[5,600,11.81],[4,160,1],[3,150,1],[2,140,1]],"id":47393184},{"batb":[[9,2.12,44.64],[8,2.46,4.11],[7,4,16.14],[6,4.2,28.57],[5,4.3,2],[4,4.6,56.02],[3,4.7,17.18],[2,5.1,21.08],[1,5.2,1.92],[0,5.3,2.83]],"batl":[[2,14,6.38],[5,22,8.23],[4,20,16.66],[3,14.5,11.76],[1,12,11.17],[9,920,2.1],[8,600,12.1],[7,440,2.12],[6,250,10],[0,11.5,1.3]],"id":95302211},{"trd":[[2.62,2.08]],"batb":[[9,1.19,5.28],[8,1.95,16.14],[7,2.18,58.16],[6,2.32,152.77],[5,2.38,1],[4,2.4,1],[3,2.42,60.86],[2,2.44,45.48],[1,2.5,4],[0,2.52,2]],"batl":[[1,4.7,16.28],[9,22,5.36],[8,16,15],[7,8.4,2.19],[6,7.2,27.88],[5,5.8,1.52],[4,5.7,1],[3,5.5,34.1],[2,5.2,16.14],[0,4.6,3.26]],"ltp":2.62,"tv":2.08,"id":67898814},{"batb":[[7,16,19.47],[6,16.5,3.23],[9,14,3.85],[8,14.5,10.02],[5,17,3.12],[4,17.5,3.03],[3,18.5,11.52],[2,19,7.7],[1,22,4.12],[0,23,1.08]],"batl":[[5,600,10.02],[4,350,1],[3,340,1],[2,330,1],[1,320,16.14],[0,250,1.22]],"id":55245090},{"batb":[[7,30,19.86],[6,32,1.61],[9,28,1.85],[8,29,6.93],[5,34,7.63],[4,36,4.16],[3,44,2.23],[2,55,1.04],[1,75,1.04],[0,95,1.04]],"batl":[[0,400,0.46]],"id":79067598}],"img":true,"tv":4.16},{"id":"1.260192493","marketDefinition":{"bspMarket":true,"turnInPlayEnabled":true,"persistenceEnabled":true,"marketBaseRate":8,"eventId":"35840776","eventTypeId":"7","numberOfWinners":1,"bettingType":"ODDS","marketType":"WIN","marketTime":"2026-07-20T07:10:00.000Z","suspendTime":"2026-07-20T07:10:00.000Z","bspReconciled":false,"complete":true,"inPlay":false,"crossMatching":true,"runnersVoidable":false,"numberOfActiveRunners":8,"betDelay":0,"status":"OPEN","runners":[{"adjustmentFactor":47.5,"status":"ACTIVE","sortPriority":1,"id":100748333},{"adjustmentFactor":11.716,"status":"ACTIVE","sortPriority":2,"id":99811046},{"adjustmentFactor":3.022,"status":"ACTIVE","sortPriority":3,"id":90296582},{"adjustmentFactor":0.318,"status":"ACTIVE","sortPriority":4,"id":44387351},{"adjustmentFactor":19.73,"status":"ACTIVE","sortPriority":5,"id":82618643},{"adjustmentFactor":10.613,"status":"ACTIVE","sortPriority":6,"id":952042},{"adjustmentFactor":6.011,"status":"ACTIVE","sortPriority":7,"id":100748335},{"adjustmentFactor":1.091,"status":"ACTIVE","sortPriority":8,"id":100748336},{"adjustmentFactor":21.727,"status":"REMOVED","sortPriority":9,"removalDate":"2026-07-20T03:01:54.000Z","id":100748334}],"regulators":["MR_INT"],"venue":"Globe Derby","countryCode":"AU","discountAllowed":true,"timezone":"Australia/Adelaide","openDate":"2026-07-20T04:03:00.000Z","version":7504182907,"raceType":"Harness","priceLadderDefinition":{"type":"CLASSIC"}},"rc":[{"batb":[[6,11.5,29.78],[7,11,1],[5,12,22.33],[2,13.5,14.64],[0,14.5,8.07],[8,10.5,4],[9,10,4],[4,12.5,4],[3,13,4],[1,14,1]],"batl":[[5,920,2.1],[4,620,1],[3,610,1],[2,600,10.99],[1,120,4.2],[0,110,16.14]],"id":90296582},{"batb":[[7,2.88,3.19],[6,3.3,1.04],[4,5.1,37.84],[9,2.12,44.64],[8,2.34,4.48],[5,4.4,1.04],[0,6.4,3.9],[3,5.6,43.84],[2,5.7,13.75],[1,6.2,16.62]],"batl":[[9,600,12.1],[8,440,2.12],[7,250,10],[6,30,1],[5,29,16.14],[4,27,6.65],[3,18,12.68],[2,15.5,11.17],[1,15,6.05],[0,14.5,1.03]],"id":952042},{"batb":[[9,1.51,98.04],[8,1.72,8.33],[7,2,6],[6,3,16.14],[5,3.25,36.71],[4,3.5,80.66],[3,3.7,1],[2,3.75,31.43],[1,3.8,25.25],[0,3.85,2.6]],"batl":[[9,440,2.12],[8,250,10],[7,44,7.36],[6,34,15],[5,13.5,13.83],[4,9.4,16.14],[3,9.2,21.97],[2,8.2,11.17],[1,8,7.47],[0,7.8,1.92]],"id":82618643},{"batb":[[8,3.3,3.34],[7,4.4,16.14],[6,4.7,23.52],[5,5.1,49.19],[4,5.2,15.09],[9,2.64,3.66],[3,5.6,18.79],[2,5.7,1.75],[1,5.8,2.59],[0,5.9,2]],"batl":[[8,920,2.1],[7,600,12.1],[6,440,2.12],[5,250,10],[4,36,6.5],[3,24,23.66],[2,16,14.4],[1,14,11.17],[0,13.5,1.11]],"id":99811046},{"trd":[[28,0.72],[27,1.28]],"batb":[[9,18.5,11.58],[8,19,1],[7,19.5,3.74],[6,20,2.63],[5,21,18.64],[4,22,11.98],[3,23,2.27],[2,24,3.21],[1,25,6.04],[0,27,4.68]],"batl":[[1,950,0.52],[0,390,2.6]],"ltp":27,"tv":2,"id":100748336},{"batb":[[9,3.05,24.39],[8,3.35,3.07],[7,4.3,2.34],[6,5.4,1.04],[5,8,15.08],[4,8.2,16.14],[3,9.2,24.59],[2,9.4,11.17],[1,10.5,9.1],[0,11,2.27]],"batl":[[8,920,2.1],[7,600,12.1],[6,440,2.12],[5,250,10],[4,100,1.74],[3,65,16.14],[0,28,6.41],[2,32,11.17],[1,29,11.17]],"id":100748335},{"batb":[[9,1.02,12],[8,1.53,16.14],[7,1.77,81.38],[6,1.84,1],[5,1.86,234.49],[4,1.88,1],[3,1.9,2],[2,1.91,95.98],[1,1.92,74.64],[0,1.93,5.18]],"batl":[[9,44,7.36],[8,34,15],[7,22,5.36],[6,16,15],[5,4.5,49.38],[4,4,44.87],[3,3.95,1],[2,3.9,17.14],[0,3.55,24.26],[1,3.65,1]],"id":100748333},{"batb":[[9,29,1.79],[8,30,1.72],[7,32,1.61],[6,34,6.29],[5,36,1],[4,38,1.35],[3,40,16.14],[2,44,4.69],[1,46,3.23],[0,60,1.46]],"batl":[[0,450,2.4]],"id":44387351}],"img":true,"tv":2},{"id":"1.260136658","marketDefinition":{"bspMarket":true,"turnInPlayEnabled":true,"persistenceEnabled":true,"marketBaseRate":8,"eventId":"35834242","eventTypeId":"7","numberOfWinners":1,"bettingType":"ODDS","marketType":"WIN","marketTime":"2026-07-20T06:30:00.000Z","suspendTime":"2026-07-20T06:30:00.000Z","bspReconciled":false,"complete":true,"inPlay":false,"crossMatching":true,"runnersVoidable":false,"numberOfActiveRunners":12,"betDelay":0,"status":"OPEN","runners":[{"adjustmentFactor":6.471,"status":"ACTIVE","sortPriority":1,"id":56407176},{"adjustmentFactor":0.697,"status":"ACTIVE","sortPriority":2,"id":74493797},{"adjustmentFactor":12.899,"status":"ACTIVE","sortPriority":3,"id":79455963},{"adjustmentFactor":8.111,"status":"ACTIVE","sortPriority":4,"id":6690508},{"adjustmentFactor":2.131,"status":"ACTIVE","sortPriority":5,"id":80934312},{"adjustmentFactor":0.057,"status":"ACTIVE","sortPriority":6,"id":69161915},{"adjustmentFactor":50.879,"status":"ACTIVE","sortPriority":7,"id":5547183},{"adjustmentFactor":4.436,"status":"ACTIVE","sortPriority":8,"id":98996178},{"adjustmentFactor":9.612,"status":"ACTIVE","sortPriority":9,"id":100749630},{"adjustmentFactor":0.083,"status":"ACTIVE","sortPriority":10,"id":78977433},{"adjustmentFactor":2.495,"status":"ACTIVE","sortPriority":11,"id":69865836},{"adjustmentFactor":2.131,"status":"ACTIVE","sortPriority":12,"id":99951973},{"adjustmentFactor":0.199,"status":"REMOVED","sortPriority":13,"removalDate":"2026-07-19T09:29:28.000Z","id":83119531}],"regulators":["MR_INT"],"venue":"Pakenham","countryCode":"AU","discountAllowed":true,"timezone":"Australia/Sydney","openDate":"2026-07-20T02:30:00.000Z","version":7504096535,"raceType":"Flat","priceLadderDefinition":{"type":"CLASSIC"}},"rc":[{"trd":[[15,5.2],[18,14.38],[16.5,27.62],[19.5,2.1],[20,1.38],[13,38.73],[11,9.89],[16,5.19],[12.5,1.6],[11.5,0.08],[14.5,1.38],[13.5,0.23],[29,0.12]],"batb":[[9,11,5.99],[8,11.5,11.7],[7,12,17.16],[6,12.5,22.63],[5,13,26.75],[4,13.5,7.79],[3,14,7.34],[2,14.5,10.71],[1,15,2.4],[0,15.5,1.45]],"batl":[[1,18,6.78],[5,20,2.99],[9,24,4.13],[8,23,6.49],[7,22,4.99],[6,21,2.99],[4,19.5,1],[3,19,1],[2,18.5,1],[0,17.5,1]],"ltp":15,"tv":107.9,"id":56407176},{"trd":[[18,3.39],[16,28.77],[15,4.17],[13.5,3.76]],"batb":[[5,13.5,5.79],[1,15.5,11.98],[2,15,3.47],[6,13,7.95],[0,16,1.91],[3,14.5,7.4],[9,11.5,9.71],[8,12,13.5],[7,12.5,9.98],[4,14,11.04]],"batl":[[5,22,2.74],[2,19.5,7.2],[1,19,10.39],[9,26,1],[8,25,1.85],[7,24,2.85],[6,23,1.74],[4,21,3.17],[3,20,3.35],[0,18.5,2.85]],"ltp":18,"tv":40.09,"id":98996178},{"trd":[[280,0.08],[530,0.01]],"batb":[[9,2.12,44.64],[8,3.05,24.39],[7,4.1,16.13],[6,4.6,2.88],[5,6.2,10.14],[0,190,2.91],[4,16,3],[3,30,2.41],[2,85,6.58],[1,140,1.59]],"batl":[[1,790,0.25],[0,470,2.55]],"ltp":280,"tv":0.09,"id":78977433},{"trd":[[25,5.79],[26,4.29],[27,1.47],[15,1.19],[13.5,2.95],[19.5,4],[21,1.04],[13,5.1]],"batb":[[9,17.5,10.24],[8,18,7.05],[7,18.5,3.55],[6,19,6.08],[5,19.5,3.71],[4,20,2.66],[0,25,2.71],[3,22,2.56],[2,23,1.06],[1,24,2.56]],"batl":[[9,440,2.12],[8,250,10],[7,200,2],[6,130,1.81],[5,65,11.17],[4,36,2.03],[3,34,1.42],[2,32,1.42],[0,29,2.04],[1,30,2.52]],"ltp":25,"tv":25.83,"id":6690508},{"trd":[[8.8,7.23],[8.6,1.9],[8.2,6.59],[7.8,4.59],[7.6,33.9],[7.4,10.38],[8,5.92],[10.5,0.32]],"batb":[[3,7.2,30.05],[4,7,17.01],[5,6.8,21.31],[2,7.4,12.11],[0,7.8,2.52],[9,6,4],[8,6.2,15.54],[7,6.4,35.82],[6,6.6,14.71],[1,7.6,2.67]],"batl":[[4,9.8,5.81],[3,9.6,1.62],[9,12,2.87],[8,11.5,2.9],[7,11,4.29],[6,10.5,12.56],[5,10,2],[0,8.8,1.48],[2,9.2,1.5],[1,9,1.35]],"ltp":8.8,"tv":70.83,"id":100749630},{"trd":[[1.91,112.5],[1.92,159.94],[1.9,19.3],[1.93,43.31],[1.95,108.26],[1.94,82.5],[1.97,28.36],[1.98,10.1],[1.99,25.51],[2.04,387.37],[2.02,150.3],[2,224.37],[2.16,13.42],[2.2,97.59],[2.18,29.07],[2.06,60.39],[2.08,4.15],[2.14,90.27],[2.1,31.14],[1.96,47.31],[2.48,2.6],[2.12,1.04]],"batb":[[3,1.85,88.9],[4,1.84,10.38],[9,1.78,151.41],[6,1.82,10.38],[0,1.9,18.16],[8,1.8,10.38],[7,1.81,18.17],[5,1.83,10.38],[2,1.86,31.82],[1,1.89,19.8]],"batl":[[0,1.91,72.31],[9,2.18,25.95],[5,1.98,184.79],[1,1.92,24.59],[8,2.12,14.78],[7,2.08,10.38],[6,2.04,71.85],[4,1.97,18.18],[3,1.94,19.3],[2,1.93,140.94]],"ltp":1.91,"tv":1728.8,"id":5547183},{"trd":[[44,4],[55,0.3],[42,5.2],[50,5.08],[40,4.69],[36,22.63],[38,8.34],[48,0.5],[27,0.74],[26,0.92],[160,0.02]],"batb":[[1,40,1.45],[9,27,6.36],[8,28,5.96],[7,29,4.75],[6,30,4.68],[5,32,9.16],[4,34,4.56],[0,42,2],[3,36,5.73],[2,38,1]],"batl":[[5,920,2.1],[4,600,12.1],[3,440,2.13],[2,260,1.43],[1,65,3.85],[0,60,1.04]],"ltp":44,"tv":52.42,"id":69865836},{"trd":[[340,0.24],[580,0.03],[300,0.43],[290,1.66],[390,0.02],[280,1.33],[270,1.04],[630,0.01]],"batb":[[0,290,1.66],[2,110,3.44],[1,190,1.18],[9,1.02,73.91],[8,1.16,100],[7,1.51,98.04],[6,4.6,3.4],[5,16,3],[4,30,2.22],[3,75,3.46]],"batl":[[1,1000,0.2],[0,480,2.02]],"ltp":340,"tv":4.76,"id":69161915},{"trd":[[21,7.28],[22,2.96],[20,3.62],[19,6.23],[17.5,4.16],[15,6.6],[14,9.81],[12,53.12],[11.5,10.8],[18.5,1.61],[16,43.65],[18,0.83],[12.5,0.34],[15.5,1.33],[14.5,0.16],[19.5,1.02]],"batb":[[9,15.5,7.59],[8,16,5.5],[7,16.5,3.87],[6,17,5.32],[5,17.5,3.64],[4,18,9.68],[3,18.5,4.19],[2,19,1.79],[1,19.5,3.22],[0,20,2.61]],"batl":[[2,25,6.57],[1,24,9.99],[4,27,5.78],[3,26,11.42],[9,34,1],[8,32,1],[7,30,1],[6,29,1],[5,28,1],[0,23,29.2]],"ltp":21,"tv":153.52,"id":80934312},{"trd":[[190,0.13],[140,3.04],[130,0.38],[150,6.19],[180,0.87],[390,0.01]],"batb":[[3,65,3.33],[9,4.1,16.13],[8,4.6,2.88],[7,6.2,9.62],[6,16,3.38],[5,30,2],[4,36,7.4],[2,90,1.08],[1,110,2],[0,120,1.19]],"batl":[[2,580,1.08],[1,270,2],[0,260,1.11]],"ltp":190,"tv":10.62,"id":99951973},{"trd":[[7.8,74.78],[8,78.35],[7.6,40.08],[7.4,6.76],[7.2,14.43],[8.2,23.12],[8.6,0.91],[8.4,19.93],[5.9,4.34],[5.7,29.86],[6.8,23.88],[5.8,7.33],[6.4,5.2],[5.5,0.1],[5.1,1.84]],"batb":[[1,7.6,3.52],[0,7.8,1.22],[3,7.2,12.64],[9,6,19.83],[8,6.2,13.54],[7,6.4,22.26],[6,6.6,19.81],[5,6.8,29.78],[4,7,21.17],[2,7.4,10.7]],"batl":[[9,11,13.23],[1,8.4,10.9],[8,10.5,11.71],[7,9.6,11.59],[6,9.4,1.11],[5,9.2,2.63],[4,9,18.73],[3,8.8,2.06],[2,8.6,10.75],[0,8.2,11.79]],"ltp":7.8,"tv":330.91,"id":79455963},{"trd":[[95,2.41],[75,2],[85,3.12],[90,2.02],[80,1.1],[65,2.6],[60,1.04],[55,0.05],[50,1.51],[260,0.01]],"batb":[[0,70,1.51],[9,38,5.83],[8,40,1.28],[7,42,1.22],[6,44,2.91],[5,46,1.44],[4,48,1.06],[3,50,1.69],[1,60,6.15],[2,55,1.31]],"batl":[[0,130,1.75],[1,150,2.15],[9,650,1],[8,640,1],[7,630,1],[6,620,1],[5,610,1],[4,600,11.02],[3,370,1.47],[2,180,1.18]],"ltp":95,"tv":15.86,"id":74493797}],"img":true,"tv":2541.63},{"id":"1.260192491","marketDefinition":{"bspMarket":true,"turnInPlayEnabled":true,"persistenceEnabled":true,"marketBaseRate":8,"eventId":"35840776","eventTypeId":"7","numberOfWinners":1,"bettingType":"ODDS","marketType":"WIN","marketTime":"2026-07-20T06:33:00.000Z","suspendTime":"2026-07-20T06:33:00.000Z","bspReconciled":false,"complete":true,"inPlay":false,"crossMatching":true,"runnersVoidable":false,"numberOfActiveRunners":8,"betDelay":0,"status":"OPEN","runners":[{"adjustmentFactor":17.287,"status":"ACTIVE","sortPriority":1,"id":90458476},{"adjustmentFactor":5.706,"status":"ACTIVE","sortPriority":2,"id":92822751},{"adjustmentFactor":0.975,"status":"ACTIVE","sortPriority":3,"id":43653174},{"adjustmentFactor":11.858,"status":"ACTIVE","sortPriority":4,"id":71345123},{"adjustmentFactor":48.134,"status":"ACTIVE","sortPriority":5,"id":71121948},{"adjustmentFactor":0.599,"status":"ACTIVE","sortPriority":6,"id":91496756},{"adjustmentFactor":0.144,"status":"ACTIVE","sortPriority":7,"id":60010414},{"adjustmentFactor":15.297,"status":"ACTIVE","sortPriority":8,"id":89353228}],"regulators":["MR_INT"],"venue":"Globe Derby","countryCode":"AU","discountAllowed":true,"timezone":"Australia/Adelaide","openDate":"2026-07-20T04:03:00.000Z","version":7504104271,"raceType":"Harness","priceLadderDefinition":{"type":"CLASSIC"}},"rc":[{"batb":[[9,6.6,1],[8,6.8,1],[7,7.2,4],[6,7.4,14.74],[5,7.6,4],[4,8.2,28.01],[3,8.4,11.17],[2,9.2,10.54],[1,9.4,1.06],[0,9.6,1.56]],"batl":[[9,75,2.34],[8,42,1],[7,40,1],[6,38,2],[5,36,1],[4,34,1],[3,32,2],[2,30,11.17],[1,27,11.17],[0,26,2.65]],"id":92822751},{"batb":[[9,21,1.04],[8,30,2.29],[7,38,1.35],[6,40,1.28],[5,42,1.22],[4,44,5.2],[3,46,1.11],[2,65,3.16],[0,95,4.6],[1,90,2.98]],"batl":[[1,1000,2.85],[0,520,2.36]],"id":60010414},{"batb":[[2,4.6,3.35],[9,1.8,7.5],[8,2.12,5.36],[7,3.35,2],[6,3.5,32.56],[5,3.8,72.02],[4,3.85,22.91],[3,4.1,27.88],[0,4.8,2.08],[1,4.7,3.19]],"batl":[[9,600,12.1],[8,440,2.12],[7,250,10.01],[6,44,7.36],[5,34,15],[4,24,3.34],[3,16.5,11.15],[2,11,19.61],[1,9.2,11.17],[0,9,1.67]],"id":90458476},{"trd":[[36,2]],"batb":[[9,24,7.99],[8,25,3.08],[7,26,2],[6,27,1.92],[5,28,9.32],[4,29,1.79],[3,30,1.72],[2,32,7.6],[1,34,2],[0,36,1.75]],"batl":[[0,390,2.51],[2,900,2.85],[1,600,10]],"ltp":36,"tv":2,"id":43653174},{"batb":[[0,44,2.23],[2,38,2.35],[1,40,5.01],[9,27,1.92],[8,28,1.85],[7,29,7.71],[6,30,1.72],[5,32,1.61],[4,34,8.63],[3,36,1.43]],"batl":[[0,1000,3.3]],"id":91496756},{"batb":[[9,4.7,2],[8,4.8,1],[7,4.9,1],[6,5.6,19.92],[5,5.9,41.16],[4,6,13.75],[1,6.8,14.9],[0,7,3.57],[3,6.2,2],[2,6.6,2]],"batl":[[1,19.5,17.55],[0,16.5,12.14],[9,600,12.1],[8,440,2.12],[7,250,10],[6,28,6.4],[5,23,1],[4,22,1],[3,21,1],[2,20,1]],"id":71345123},{"batb":[[9,2.32,4.55],[8,3.5,3.55],[7,4,27.97],[6,4.2,63.02],[5,4.3,2],[4,4.4,19.33],[3,4.7,23.36],[2,5,2],[1,5.1,2.94],[0,5.2,2]],"batl":[[9,920,2.1],[8,600,12.1],[7,440,2.12],[6,250,10],[5,44,7.36],[4,19.5,9.34],[2,12.5,17.73],[1,11,11.17],[3,13.5,7.33],[0,10.5,1.43]],"id":89353228},{"batb":[[6,1.64,106.69],[8,1.01,1159.69],[7,1.02,12],[4,1.76,115.11],[3,1.77,86.91],[2,1.78,1],[1,1.84,3.96],[5,1.71,285.01],[0,1.88,5.32]],"batl":[[9,9.2,2.51],[8,3.7,63.65],[7,3.4,45.13],[6,3.25,1],[5,3.2,1],[4,3.15,1],[3,3.1,1],[2,3.05,1],[1,3,28.12],[0,2.92,2.31]],"id":71121948}],"img":true,"tv":2},{"id":"1.260136666","marketDefinition":{"bspMarket":true,"turnInPlayEnabled":true,"persistenceEnabled":true,"marketBaseRate":8,"eventId":"35834242","eventTypeId":"7","numberOfWinners":1,"bettingType":"ODDS","marketType":"WIN","marketTime":"2026-07-20T07:00:00.000Z","suspendTime":"2026-07-20T07:00:00.000Z","bspReconciled":false,"complete":true,"inPlay":false,"crossMatching":true,"runnersVoidable":false,"numberOfActiveRunners":11,"betDelay":0,"status":"OPEN","runners":[{"adjustmentFactor":6.56,"status":"ACTIVE","sortPriority":1,"id":100749631},{"adjustmentFactor":10.951,"status":"ACTIVE","sortPriority":2,"id":74901081},{"adjustmentFactor":33.17,"status":"ACTIVE","sortPriority":3,"id":97211330},{"adjustmentFactor":3.518,"status":"ACTIVE","sortPriority":4,"id":82344583},{"adjustmentFactor":4.227,"status":"ACTIVE","sortPriority":5,"id":100749632},{"adjustmentFactor":3.847,"status":"ACTIVE","sortPriority":6,"id":83642512},{"adjustmentFactor":11.969,"status":"ACTIVE","sortPriority":7,"id":91807545},{"adjustmentFactor":18.219,"status":"ACTIVE","sortPriority":8,"id":89669672},{"adjustmentFactor":3.847,"status":"ACTIVE","sortPriority":9,"id":100749633},{"adjustmentFactor":0.175,"status":"ACTIVE","sortPriority":10,"id":74300318},{"adjustmentFactor":3.518,"status":"ACTIVE","sortPriority":11,"id":88111702},{"adjustmentFactor":2.066,"status":"REMOVED","sortPriority":12,"removalDate":"2026-07-19T09:29:44.000Z","id":67324674},{"adjustmentFactor":3.339,"status":"REMOVED","sortPriority":13,"removalDate":"2026-07-19T22:01:25.000Z","id":81601707},{"adjustmentFactor":1.8,"status":"REMOVED","sortPriority":14,"removalDate":"2026-07-19T22:01:35.000Z","id":85854865}],"regulators":["MR_INT"],"venue":"Pakenham","countryCode":"AU","discountAllowed":true,"timezone":"Australia/Sydney","openDate":"2026-07-20T02:30:00.000Z","version":7504096519,"raceType":"Flat","priceLadderDefinition":{"type":"CLASSIC"}},"rc":[{"trd":[[2.66,1.19],[2.82,47.29],[2.8,2.28],[2.7,0.62],[2.76,4],[2.64,1.91],[2.74,7.3]],"batb":[[8,2.44,185.17],[7,2.56,6],[6,2.58,72.33],[5,2.6,43.76],[4,2.66,5.19],[3,2.68,6],[2,2.7,1.73],[1,2.76,3.13],[9,2.08,81.83],[0,2.78,12.48]],"batl":[[0,3.45,1.97],[1,3.7,2.88],[9,4.2,1],[8,4.1,4.87],[7,4,2.4],[6,3.95,2],[5,3.9,6.87],[4,3.85,2],[3,3.8,2],[2,3.75,5.36]],"ltp":2.7,"tv":64.59,"id":97211330},{"batb":[[9,15,19.71],[8,15.5,3.45],[7,16,3.33],[6,19,15.34],[2,25,6.58],[5,20,3.15],[4,21,9.77],[3,22,3.3],[1,27,1.1],[0,34,2]],"batl":[[8,920,2.1],[7,610,1],[6,600,13.1],[5,590,3.6],[4,440,2.12],[3,210,1.16],[0,50,2],[2,140,17.59],[1,100,1.42]],"id":88111702},{"trd":[[23,0.86],[22,0.18]],"batb":[[4,18.5,1.99],[9,15.5,19.59],[8,16,3.33],[7,16.5,20.34],[6,17,3.12],[5,17.5,3.03],[3,20,5.98],[2,21,5.59],[1,22,1.94],[0,23,1.52]],"batl":[[2,50,1.33],[0,42,1.41],[8,920,2.1],[7,600,12.1],[6,440,2.12],[5,250,10],[4,160,17.68],[3,70,1.3],[1,44,2.25]],"ltp":22,"tv":1.04,"id":100749633},{"batb":[[9,10,33.63],[8,10.5,20.14],[7,11,15.94],[6,11.5,4],[5,12,7.28],[4,12.5,1],[3,13,4],[2,13.5,18.86],[0,15,2.57],[1,14,1.76]],"batl":[[9,180,2],[8,95,2.57],[7,80,16.14],[6,60,11.17],[3,38,3.17],[5,42,1],[4,40,1.29],[2,36,12.8],[1,29,1],[0,26,2.83]],"id":100749632},{"trd":[[180,0.17]],"batb":[[9,2.14,4.67],[8,3.05,24.39],[7,4.1,16.13],[6,4.6,2.88],[5,6.2,9.62],[4,16,3],[3,60,4.31],[2,95,3.09],[1,160,1.8],[0,200,2]],"batl":[[1,1000,41.82],[0,620,2.02]],"ltp":180,"tv":0.17,"id":74300318},{"trd":[[11,8.85],[12.5,1.6],[11.5,0.46]],"batb":[[9,4.5,1.71],[8,8,30.59],[7,8.6,34.6],[6,8.8,4],[5,9.2,1.5],[4,9.4,11.17],[3,9.8,1.5],[2,10,11.08],[1,10.5,1.5],[0,11.5,2.13]],"batl":[[9,250,10],[8,95,2],[7,75,1.5],[6,55,5.38],[5,50,16.14],[4,38,13.98],[3,26,11.17],[1,14,22.58],[2,18,1],[0,13.5,6.08]],"ltp":11,"tv":10.91,"id":100749631},{"batb":[[9,2.12,44.64],[8,2.24,4.84],[7,2.74,3.45],[6,4.1,16.14],[5,4.2,30.47],[4,4.8,70.17],[3,5.1,15.11],[2,5.5,39.18],[1,6.2,23.11],[0,6.4,1.56]],"batl":[[9,18.5,16.14],[5,8.2,1],[8,17.5,14.66],[6,11.5,12.16],[7,15.5,27.89],[4,8,1],[3,7.8,6.34],[2,7.6,1],[1,7.4,1],[0,7,103.82]],"id":91807545},{"trd":[[9,2.67],[9.2,2.18],[9.4,5.44]],"batb":[[9,3.1,2.86],[8,3.9,2.07],[7,5.3,30.32],[6,6.4,16.14],[5,6.8,49.97],[4,8,2],[3,8.2,17.29],[2,8.4,11.17],[1,8.6,1.68],[0,9,1.44]],"batl":[[7,22,17.74],[9,36,23.06],[1,14,6.87],[8,23,1],[6,21,1.91],[5,18.5,11.17],[4,18,1],[3,17.5,1.49],[2,16.5,1.61],[0,13.5,1.11]],"ltp":9,"tv":10.29,"id":74901081},{"trd":[[5.7,0.93],[6.4,54.73],[5.9,4.9],[6.2,4.62],[5.8,3.24],[5.6,1.14],[6.6,4.41]],"batb":[[9,5.1,15.11],[8,5.5,46.34],[2,6.4,20.66],[3,6.2,2.31],[6,5.7,2.26],[7,5.6,2.61],[5,5.8,2.5],[4,6,1.73],[1,6.6,2.14],[0,7.4,2]],"batl":[[0,10.5,3],[9,15.5,2],[8,15,1],[7,14.5,2],[6,14,1],[5,13.5,2.5],[4,13,20.38],[3,12.5,2.55],[2,12,13.69],[1,11.5,1.5]],"ltp":5.8,"tv":73.97,"id":89669672},{"batb":[[2,20,8.02],[1,21,5.59],[9,13,4],[8,13.5,13.72],[7,14,3.85],[6,14.5,3.7],[5,15.5,16.14],[4,16,3.33],[3,16.5,17.2],[0,23,1.97]],"batl":[[5,160,17.66],[9,920,2.1],[8,600,12.1],[7,440,2.12],[6,180,1],[4,150,1],[3,130,1],[2,120,1],[1,100,20.76],[0,44,2.52]],"id":82344583},{"batb":[[7,14,13.4],[6,18,18.63],[1,23,10.69],[9,4.6,2.88],[8,6.2,9.62],[3,21,1.66],[0,25,1.48],[5,19,16.14],[4,20,2.63],[2,22,4.04]],"batl":[[5,920,2.1],[4,600,12.1],[3,440,2.13],[2,190,1.28],[1,60,2],[0,50,2.3]],"id":83642512}],"img":true,"tv":160.97},{"id":"1.260192495","marketDefinition":{"bspMarket":true,"turnInPlayEnabled":true,"persistenceEnabled":true,"marketBaseRate":8,"eventId":"35840776","eventTypeId":"7","numberOfWinners":1,"bettingType":"ODDS","marketType":"WIN","marketTime":"2026-07-20T07:37:00.000Z","suspendTime":"2026-07-20T07:37:00.000Z","bspReconciled":false,"complete":true,"inPlay":false,"crossMatching":true,"runnersVoidable":false,"numberOfActiveRunners":10,"betDelay":0,"status":"OPEN","runners":[{"adjustmentFactor":16.615,"status":"ACTIVE","sortPriority":1,"id":39133854},{"adjustmentFactor":0.04,"status":"ACTIVE","sortPriority":2,"id":38138891},{"adjustmentFactor":1.789,"status":"ACTIVE","sortPriority":3,"id":25964776},{"adjustmentFactor":0.056,"status":"ACTIVE","sortPriority":4,"id":25695674},{"adjustmentFactor":10.789,"status":"ACTIVE","sortPriority":5,"id":46863069},{"adjustmentFactor":1.043,"status":"ACTIVE","sortPriority":6,"id":57080352},{"adjustmentFactor":5.466,"status":"ACTIVE","sortPriority":7,"id":75084938},{"adjustmentFactor":13.943,"status":"ACTIVE","sortPriority":8,"id":87209380},{"adjustmentFactor":0.461,"status":"ACTIVE","sortPriority":9,"id":46626367},{"adjustmentFactor":49.798,"status":"ACTIVE","sortPriority":10,"id":38467046}],"regulators":["MR_INT"],"venue":"Globe Derby","countryCode":"AU","discountAllowed":true,"timezone":"Australia/Adelaide","openDate":"2026-07-20T04:03:00.000Z","version":7504104263,"raceType":"Harness","priceLadderDefinition":{"type":"CLASSIC"}},"rc":[{"batb":[[5,27,9.67],[9,23,2.27],[8,24,9.03],[7,25,2.08],[6,26,2],[4,28,1.85],[3,29,1.79],[2,30,6.58],[1,32,1.31],[0,34,2.62]],"batl":[[0,600,11.53],[9,690,1],[8,680,1],[7,670,1],[6,660,1],[5,650,1],[4,640,1],[3,630,1],[2,620,1],[1,610,1]],"id":25964776},{"batb":[[9,1.02,12],[8,1.16,100],[7,1.51,98.04],[6,2.12,44.64],[4,4.8,23.09],[3,5.1,49.19],[2,5.2,15.09],[1,5.6,18.79],[5,4.3,2],[0,5.7,3.75]],"batl":[[6,920,2.1],[5,600,12.1],[4,440,2.12],[3,250,10],[1,15.5,12.17],[0,14,11.17],[2,24,7.52]],"id":46863069},{"batb":[[9,1.16,100],[8,1.51,98.04],[7,2.12,44.64],[6,3.05,24.39],[5,4.1,16.13],[4,4.6,2.88],[3,6.2,9.93],[2,55,3.11],[1,65,3.15],[0,85,3.57]],"batl":[[0,510,0.36]],"id":46626367},{"batb":[[8,1.01,1154.26],[7,1.02,12],[6,1.8,80.1],[5,1.86,234.49],[3,1.91,95.98],[2,1.92,71.29],[4,1.89,1],[1,1.93,6.18],[0,1.94,2]],"batl":[[9,34,15],[8,16,15],[7,4.5,49.38],[6,4.1,43.25],[0,3.65,23.34],[5,3.95,1],[4,3.9,1],[3,3.85,1],[2,3.8,1],[1,3.75,1]],"id":38467046},{"batb":[[9,1.02,12],[8,1.16,100],[7,1.51,98.04],[6,2.12,44.64],[5,4.2,26.81],[4,4.4,59.31],[3,4.5,18.19],[2,4.9,22.16],[1,5,2],[0,5.1,2]],"batl":[[6,920,2.1],[5,600,12.1],[4,440,2.12],[3,250,10],[2,21,8.64],[1,13.5,11.45],[0,12,11.17]],"id":87209380},{"batb":[[5,19.5,13.6],[1,23,7.77],[4,20,2.63],[9,17.5,11.9],[8,18,2.94],[7,18.5,2.86],[6,19,2.78],[3,21,2.5],[2,22,2.38],[0,24,5.16]],"batl":[[0,600,11.69],[9,700,1],[8,690,1],[7,680,1],[6,670,1],[5,660,1],[4,650,1],[3,640,1],[2,630,1],[1,620,1]],"id":57080352},{"batb":[[9,2.12,44.64],[8,3.05,24.39],[4,8.2,13.46],[3,8.8,25.86],[2,9,11.17],[1,9.8,9.82],[7,7,4],[6,7.2,4],[5,7.4,4],[0,10,3]],"batl":[[9,920,2.1],[8,640,1],[7,630,1],[6,620,1],[5,610,1],[4,600,13.1],[3,440,2.12],[2,250,10.01],[1,90,1.94],[0,28,11.17]],"id":75084938},{"trd":[[4.4,4.54],[4.5,4]],"batb":[[7,1.01,1154.26],[6,1.02,12],[5,1.16,100],[4,1.51,98.04],[3,3.2,36.44],[2,3.4,84.03],[1,3.65,33.61],[0,3.7,25.74]],"batl":[[9,250,10],[8,34,15],[6,12,15.71],[1,9,21.15],[0,8,11.17],[7,12.5,1],[5,10,1],[4,9.8,1],[3,9.6,1],[2,9.4,1]],"ltp":4.4,"tv":8.54,"id":39133854},{"batb":[[9,1.16,100],[8,1.51,98.04],[7,2.12,44.64],[6,3.05,24.39],[5,4.1,16.13],[4,4.6,2.88],[3,6.2,9.85],[2,120,5.29],[1,130,1],[0,150,1.26]],"batl":[[0,890,0.21]],"id":25695674},{"batb":[[9,2.08,4],[8,2.1,1],[7,2.12,45.64],[6,3.05,24.39],[5,4.1,16.13],[4,4.6,2.88],[3,6.2,9.85],[2,120,5.29],[1,130,1],[0,150,1.26]],"batl":[[0,890,0.21]],"id":38138891}],"img":true,"tv":8.54},{"id":"1.260136803","marketDefinition":{"bspMarket":true,"turnInPlayEnabled":true,"persistenceEnabled":true,"marketBaseRate":10,"eventId":"35834254","eventTypeId":"7","numberOfWinners":1,"bettingType":"ODDS","marketType":"WIN","marketTime":"2026-07-20T06:55:00.000Z","suspendTime":"2026-07-20T06:55:00.000Z","bspReconciled":false,"complete":true,"inPlay":false,"crossMatching":true,"runnersVoidable":false,"numberOfActiveRunners":10,"betDelay":0,"status":"OPEN","runners":[{"adjustmentFactor":0.483,"status":"ACTIVE","sortPriority":1,"id":57883707},{"adjustmentFactor":14.676,"status":"ACTIVE","sortPriority":2,"id":100721218},{"adjustmentFactor":18.079,"status":"ACTIVE","sortPriority":3,"id":100721219},{"adjustmentFactor":53.731,"status":"ACTIVE","sortPriority":4,"id":94448588},{"adjustmentFactor":0.968,"status":"ACTIVE","sortPriority":5,"id":100721221},{"adjustmentFactor":2.858,"status":"ACTIVE","sortPriority":6,"id":99171722},{"adjustmentFactor":0.483,"status":"ACTIVE","sortPriority":7,"id":100721222},{"adjustmentFactor":8.347,"status":"ACTIVE","sortPriority":8,"id":77728021},{"adjustmentFactor":0.288,"status":"ACTIVE","sortPriority":9,"id":100721224},{"adjustmentFactor":0.086,"status":"ACTIVE","sortPriority":10,"id":100721225},{"adjustmentFactor":2.388,"status":"REMOVED","sortPriority":11,"removalDate":"2026-07-19T09:20:56.000Z","id":77428498},{"adjustmentFactor":3.68,"status":"REMOVED","sortPriority":12,"removalDate":"2026-07-19T09:21:05.000Z","id":12140598},{"adjustmentFactor":2.207,"status":"REMOVED","sortPriority":13,"removalDate":"2026-07-19T20:14:05.000Z","id":100486265},{"adjustmentFactor":0.261,"status":"REMOVED","sortPriority":14,"removalDate":"2026-07-19T20:24:43.000Z","id":100721223},{"adjustmentFactor":4.755,"status":"REMOVED","sortPriority":15,"removalDate":"2026-07-19T21:50:54.000Z","id":60228967},{"adjustmentFactor":2.376,"status":"REMOVED","sortPriority":16,"removalDate":"2026-07-19T21:51:09.000Z","id":43058012},{"adjustmentFactor":2.007,"status":"REMOVED","sortPriority":17,"removalDate":"2026-07-19T21:51:21.000Z","id":20723919}],"regulators":["MR_INT"],"venue":"Wagga","countryCode":"AU","discountAllowed":true,"timezone":"Australia/Sydney","openDate":"2026-07-20T02:40:00.000Z","version":7504101562,"raceType":"Flat","priceLadderDefinition":{"type":"CLASSIC"}},"rc":[{"batb":[[0,60,1.38],[1,55,6.94],[9,36,17.57],[8,38,9.32],[7,40,5.15],[6,42,2.22],[5,44,1.15],[4,46,1.33],[3,48,2.48],[2,50,1.57]],"batl":[[2,1000,0.52],[1,720,1],[0,600,10.57]],"id":100721222},{"trd":[[140,0.04],[130,0.81]],"batb":[[0,110,3.22],[3,65,5.03],[2,70,2.8],[9,2.12,44.64],[8,3.05,24.39],[7,4.1,16.13],[6,4.6,2.88],[5,6.2,9.62],[4,16,3.2],[1,100,1.32]],"batl":[[0,580,0.46]],"ltp":140,"tv":0.85,"id":100721224},{"trd":[[180,0.15]],"batb":[[1,150,3.15],[9,2.12,44.64],[8,3.05,24.39],[7,4.1,16.13],[6,4.6,2.88],[5,6.2,9.62],[4,16,3.22],[3,90,3.21],[2,110,2.78],[0,170,2.89]],"batl":[[1,850,0.25],[0,790,2.02]],"ltp":180,"tv":0.15,"id":100721225},{"trd":[[8.2,2.44]],"batb":[[9,2.12,44.64],[8,2.6,3.75],[7,3.2,2.73],[6,5.1,34.13],[5,5.8,77.56],[4,5.9,20.08],[3,6.4,2.44],[2,6.8,2.51],[1,7,21.06],[0,7.6,3.36]],"batl":[[1,9.4,2.51],[4,22,9.6],[3,19,11.17],[9,440,2.12],[8,250,10],[7,44,7.36],[6,34,15],[5,32,16.14],[2,17.5,11.69],[0,9,5.19]],"ltp":8.2,"tv":2.44,"id":100721218},{"trd":[[4.7,12.75],[2.64,9.24],[4.6,38.41],[2.66,2.18]],"batb":[[9,1.12,100],[8,2.14,16.14],[7,2.3,83.79],[6,2.44,9.01],[5,2.5,149.63],[4,2.64,65.97],[3,2.66,53.05],[2,2.7,4.84],[1,2.72,2.28],[0,2.76,11.23]],"batl":[[9,22,5.36],[8,18,3.05],[7,16,15],[6,8.4,5.82],[5,6.8,20.23],[4,6.2,69.3],[3,5.2,1.19],[2,5.1,16.14],[1,3.85,25.95],[0,3.8,2.08]],"ltp":2.64,"tv":62.58,"id":100721219},{"batb":[[0,42,1.21],[1,40,3.31],[7,29,5.97],[5,32,2.61],[2,38,3.42],[8,28,18.99],[3,36,5.76],[9,27,1.92],[6,30,1.72],[4,34,2.2]],"batl":[[1,600,10],[0,510,1.73]],"id":100721221},{"trd":[[20,10.38],[17,9.21],[16,6.15],[17.5,3.34]],"batb":[[9,12,4],[8,12.5,20.14],[7,13,13.69],[6,13.5,23.21],[5,14,3.85],[4,14.5,10.27],[0,19,1.92],[3,17,7.64],[2,17.5,1.37],[1,18,1.37]],"batl":[[6,920,2.1],[5,600,12.1],[4,440,2.12],[3,250,10],[2,170,1],[1,130,2.17],[0,120,16.58]],"ltp":20,"tv":29.08,"id":99171722},{"trd":[[2.2,42.99],[2.28,104.84],[2.22,4.43],[2.26,8.84],[2.14,1.04]],"batb":[[8,2.04,85.7],[7,2.06,4],[9,2.02,260.6],[4,2.16,100.7],[3,2.18,14.15],[6,2.12,4],[5,2.14,4],[2,2.2,4],[1,2.22,7.14],[0,2.24,5.65]],"batl":[[9,85,2],[8,44,7.36],[7,34,15],[6,22,5.36],[5,16,15],[4,5.3,57.9],[3,4.8,29.57],[2,4.3,22.82],[1,4.1,16.14],[0,4,4.27]],"ltp":2.28,"tv":162.14,"id":94448588},{"trd":[[90,0.75]],"batb":[[0,80,3.27],[9,4.6,2.88],[8,6.2,9.62],[7,16,3],[6,40,16.14],[5,42,4.33],[4,44,7.07],[3,50,1.16],[2,55,3.46],[1,70,2.72]],"batl":[[0,400,2.52],[1,860,1]],"ltp":90,"tv":0.75,"id":57883707},{"trd":[[11.5,33.43],[11,16.86],[8.2,15.65],[10.5,26.6],[8,8.96],[7.4,3.69],[8.4,4.27],[12,1.96]],"batb":[[9,4.1,16.13],[8,4.9,11.44],[7,5.7,50.55],[6,5.8,16.14],[5,6.2,5.79],[4,6.4,6.89],[0,7.2,5.9],[3,6.6,1.75],[2,6.8,17.56],[1,7,17.46]],"batl":[[9,920,2.1],[8,600,12.1],[7,440,2.12],[6,250,10],[5,32,16.14],[4,20,14.92],[3,18,12.41],[2,16.5,6.45],[1,14.5,7.89],[0,14,1.39]],"ltp":7.4,"tv":111.42,"id":77728021}],"img":true,"tv":369.41},{"id":"1.260192340","marketDefinition":{"bspMarket":true,"turnInPlayEnabled":true,"persistenceEnabled":true,"marketBaseRate":8,"eventId":"35840768","eventTypeId":"7","numberOfWinners":1,"bettingType":"ODDS","marketType":"WIN","marketTime":"2026-07-20T07:56:00.000Z","suspendTime":"2026-07-20T07:56:00.000Z","bspReconciled":false,"complete":true,"inPlay":false,"crossMatching":true,"runnersVoidable":false,"numberOfActiveRunners":10,"betDelay":0,"status":"OPEN","runners":[{"adjustmentFactor":0.382,"status":"ACTIVE","sortPriority":1,"id":38605561},{"adjustmentFactor":1.099,"status":"ACTIVE","sortPriority":2,"id":43884233},{"adjustmentFactor":0.883,"status":"ACTIVE","sortPriority":3,"id":25521782},{"adjustmentFactor":7.058,"status":"ACTIVE","sortPriority":4,"id":62688374},{"adjustmentFactor":0.382,"status":"ACTIVE","sortPriority":5,"id":41313890},{"adjustmentFactor":47.334,"status":"ACTIVE","sortPriority":6,"id":85602501},{"adjustmentFactor":1.291,"status":"ACTIVE","sortPriority":7,"id":2238253},{"adjustmentFactor":40.549,"status":"ACTIVE","sortPriority":8,"id":100748350},{"adjustmentFactor":0.382,"status":"ACTIVE","sortPriority":9,"id":5790813},{"adjustmentFactor":0.641,"status":"ACTIVE","sortPriority":10,"id":44415939}],"regulators":["MR_INT"],"venue":"Gloucester Park","countryCode":"AU","discountAllowed":true,"timezone":"Australia/Perth","openDate":"2026-07-20T05:13:00.000Z","version":7504136100,"raceType":"Harness","priceLadderDefinition":{"type":"CLASSIC"}},"rc":[{"batb":[[9,16.5,3.23],[8,17,1],[7,18.5,2.86],[6,19.5,2.7],[5,20,2.63],[4,21,11.72],[3,22,11.98],[2,23,8.84],[1,24,2.17],[0,27,3.68]],"batl":[[0,600,11.6],[9,700,1],[8,690,1],[7,680,1],[6,670,1],[5,660,1],[4,650,1],[3,640,1],[2,630,1],[1,620,1]],"id":25521782},{"batb":[[9,16.5,3.23],[8,17,3.12],[7,17.5,14.73],[6,18,2.94],[5,18.5,14.38],[4,19,2.78],[2,20,9.2],[0,22,5.55],[3,19.5,2.7],[1,21,1]],"batl":[[0,390,0.73]],"id":2238253},{"batb":[[4,1.41,189.69],[3,1.48,100.44],[2,1.81,248.96],[1,1.86,100.49],[6,1.01,1258.52],[5,1.02,12],[0,1.88,5.32]],"batl":[[4,2.32,25.95],[0,2.22,25.95],[9,2.42,1],[8,2.4,1],[7,2.38,1],[6,2.36,1],[5,2.34,1],[3,2.3,1],[2,2.28,1],[1,2.26,1]],"id":85602501},{"batb":[[9,24,2.17],[8,25,2.08],[7,27,1.92],[6,28,1.85],[5,29,1.79],[4,30,1.72],[3,32,8.04],[2,34,7.63],[1,36,5.06],[0,44,2.01]],"batl":[[0,400,0.45]],"id":5790813},{"batb":[[9,24,2.17],[8,25,2.08],[7,27,1.92],[6,28,1.85],[5,29,1.79],[4,30,1.72],[3,32,8.04],[2,34,7.63],[1,36,5.06],[0,44,2.01]],"batl":[[0,400,0.45]],"id":41313890},{"batb":[[9,1.02,12],[8,1.16,100],[7,1.7,106.78],[6,1.98,1],[5,2.02,198.71],[4,2.04,59.35],[3,2.06,2],[2,2.08,1],[1,2.12,81.89],[0,2.14,2]],"batl":[[2,7.6,53.42],[1,6.2,33.24],[0,6,11.17],[7,920,2.1],[6,600,12.1],[5,460,2.6],[4,440,2.12],[3,250,10]],"id":100748350},{"batb":[[9,24,2.17],[8,25,2.08],[7,27,1.92],[6,28,1.85],[5,29,1.79],[4,30,1.72],[3,32,8.04],[2,34,7.63],[1,36,5.06],[0,44,2.01]],"batl":[[0,400,0.45]],"id":38605561},{"batb":[[9,15.5,1],[8,16,3.33],[7,17,3.12],[6,17.5,3.03],[5,18,2.94],[4,19,2.78],[3,19.5,21.17],[2,20,5.88],[1,21,2.5],[0,24,4.16]],"batl":[[0,390,0.69]],"id":43884233},{"batb":[[0,8.4,1.19],[6,7.2,34.53],[5,7.4,12.17],[1,8.2,13.01],[4,7.6,1],[9,6.6,4],[8,6.8,2],[7,7,2],[3,7.8,4],[2,8,1]],"batl":[[6,75,2],[9,90,1],[8,85,1],[5,70,2],[4,65,2],[3,60,2],[2,55,12.17],[7,80,1],[1,50,1],[0,48,3.68]],"id":62688374},{"batb":[[9,20,2.63],[8,21,2.5],[7,22,2.38],[6,23,2.27],[5,24,2.17],[4,25,2.08],[3,26,10.33],[2,27,7.75],[1,28,4.63],[0,34,2.62]],"batl":[[0,390,0.53]],"id":44415939}],"img":true},{"id":"1.260191301","marketDefinition":{"bspMarket":true,"turnInPlayEnabled":true,"persistenceEnabled":true,"marketBaseRate":8,"eventId":"35840588","eventTypeId":"7","numberOfWinners":1,"bettingType":"ODDS","marketType":"WIN","marketTime":"2026-07-20T07:18:00.000Z","suspendTime":"2026-07-20T07:18:00.000Z","bspReconciled":false,"complete":true,"inPlay":false,"crossMatching":true,"runnersVoidable":false,"numberOfActiveRunners":9,"betDelay":0,"status":"OPEN","runners":[{"adjustmentFactor":37.508,"status":"ACTIVE","sortPriority":1,"id":840328},{"adjustmentFactor":20.622,"status":"ACTIVE","sortPriority":2,"id":9981629},{"adjustmentFactor":14.909,"status":"ACTIVE","sortPriority":3,"id":73179259},{"adjustmentFactor":5.612,"status":"ACTIVE","sortPriority":4,"id":70594148},{"adjustmentFactor":6.055,"status":"ACTIVE","sortPriority":5,"id":36758267},{"adjustmentFactor":1.5,"status":"ACTIVE","sortPriority":6,"id":70458131},{"adjustmentFactor":7.778,"status":"ACTIVE","sortPriority":7,"id":40446414},{"adjustmentFactor":3.767,"status":"ACTIVE","sortPriority":8,"id":48501703},{"adjustmentFactor":2.248,"status":"ACTIVE","sortPriority":9,"id":68571178}],"regulators":["MR_INT"],"venue":"Redcliffe","countryCode":"AU","discountAllowed":true,"timezone":"Australia/Sydney","openDate":"2026-07-20T07:18:00.000Z","version":7504105225,"raceType":"Harness","priceLadderDefinition":{"type":"CLASSIC"}},"rc":[{"batb":[[9,2.04,5.77],[8,2.12,44.64],[7,2.46,4.11],[6,3.8,34.82],[5,3.85,16.14],[4,4.3,2],[3,4.6,56.02],[2,4.7,17.67],[1,5.1,21.08],[0,5.2,3.92]],"batl":[[7,920,2.1],[6,600,12.1],[5,440,2.12],[4,250,10],[3,22,8.23],[2,20,16.14],[1,14,17.93],[0,12.5,11.17]],"id":73179259},{"batb":[[9,1.74,140.87],[8,1.81,16.14],[7,1.94,50.7],[5,2.18,170.9],[2,2.28,67.52],[6,2.14,1],[4,2.24,1],[3,2.26,1],[1,2.3,4.35],[0,2.32,2]],"batl":[[9,250,10],[8,44,7.36],[7,34,15],[6,22,5.36],[5,6.8,29.8],[4,5.8,1],[3,5.7,1],[2,5.5,35.19],[1,4.9,11.17],[0,4.8,16.14]],"id":840328},{"batb":[[3,18.5,11.52],[8,16,12.33],[9,15.5,3.45],[7,16.5,3.23],[6,17,3.12],[5,17.5,8.6],[4,18,2.94],[2,20,2.63],[1,21,1],[0,22,5.55]],"batl":[[1,600,11.02],[0,290,16.84]],"id":48501703},{"batb":[[9,1.51,98.04],[8,2.12,44.64],[7,2.54,3.9],[6,3.15,2.79],[5,5.2,16.14],[4,5.3,19.37],[3,5.6,11.17],[2,6.2,38.78],[0,7.2,14.85],[1,6.4,4]],"batl":[[9,620,1],[8,610,1],[7,600,13.1],[6,440,2.12],[5,250,10],[4,34,16.14],[3,29,6.17],[2,24,11.17],[1,19.5,11.17],[0,17,7.27]],"id":68571178},{"batb":[[9,3.15,16.14],[8,3.2,2],[7,3.25,46.67],[6,3.3,1],[5,3.35,1],[4,3.7,74.69],[3,3.9,1],[2,3.95,30.3],[1,4,22.09],[0,4.1,2.44]],"batl":[[9,920,2.1],[8,600,12.1],[7,440,2.12],[6,250,10],[5,44,7.36],[4,34,15],[3,15.5,11.92],[2,12.5,18.71],[1,10,11.17],[0,9.8,16.14]],"id":9981629},{"batb":[[9,10,4],[8,10.5,4],[7,11,4],[6,11.5,15.17],[5,12,22.33],[4,12.5,4],[0,14.5,8.07],[3,13,4],[2,13.5,4],[1,14,1]],"batl":[[4,920,2.1],[3,600,13.1],[2,440,2.12],[1,250,10.97],[0,150,16.14]],"id":36758267},{"batb":[[9,10,4],[8,10.5,4],[7,11,4],[6,11.5,15.17],[5,12,22.33],[4,12.5,4],[0,14.5,8.07],[3,13,4],[2,13.5,4],[1,14,1]],"batl":[[4,920,2.1],[3,600,13.1],[2,440,2.12],[1,250,10.97],[0,150,16.14]],"id":70594148},{"batb":[[9,19.5,2.7],[8,20,2.63],[7,21,18.64],[6,22,8.95],[5,23,2.27],[4,24,2.17],[3,25,2.08],[2,26,2],[1,27,8.11],[0,34,2.62]],"batl":[[0,390,0.53]],"id":70458131},{"batb":[[9,4.1,1.94],[7,7.2,19.87],[8,7,16.14],[6,7.4,4],[5,8,4],[3,8.4,15.17],[2,8.8,25.86],[1,9.8,9.82],[4,8.2,4],[0,10,1]],"batl":[[9,620,1],[8,610,1],[7,600,13.1],[6,440,2.12],[5,250,10],[4,90,1.95],[3,65,1],[2,60,2],[1,55,17.14],[0,38,11.17]],"id":40446414}],"img":true},{"id":"1.260192334","marketDefinition":{"bspMarket":true,"turnInPlayEnabled":true,"persistenceEnabled":true,"marketBaseRate":8,"eventId":"35840768","eventTypeId":"7","numberOfWinners":1,"bettingType":"ODDS","marketType":"WIN","marketTime":"2026-07-20T07:03:00.000Z","suspendTime":"2026-07-20T07:03:00.000Z","bspReconciled":false,"complete":true,"inPlay":false,"crossMatching":true,"runnersVoidable":false,"numberOfActiveRunners":12,"betDelay":0,"status":"OPEN","runners":[{"adjustmentFactor":3.11,"status":"ACTIVE","sortPriority":1,"id":27341073},{"adjustmentFactor":47.431,"status":"ACTIVE","sortPriority":2,"id":65574394},{"adjustmentFactor":0.442,"status":"ACTIVE","sortPriority":3,"id":2207238},{"adjustmentFactor":6.25,"status":"ACTIVE","sortPriority":4,"id":12747055},{"adjustmentFactor":6.25,"status":"ACTIVE","sortPriority":5,"id":59735573},{"adjustmentFactor":3.11,"status":"ACTIVE","sortPriority":6,"id":62688376},{"adjustmentFactor":1.429,"status":"ACTIVE","sortPriority":7,"id":66834728},{"adjustmentFactor":6.25,"status":"ACTIVE","sortPriority":8,"id":21163447},{"adjustmentFactor":9.337,"status":"ACTIVE","sortPriority":9,"id":73793682},{"adjustmentFactor":12.584,"status":"ACTIVE","sortPriority":10,"id":76055924},{"adjustmentFactor":2.378,"status":"ACTIVE","sortPriority":11,"id":63436713},{"adjustmentFactor":1.429,"status":"ACTIVE","sortPriority":12,"id":93234332}],"regulators":["MR_INT"],"venue":"Gloucester Park","countryCode":"AU","discountAllowed":true,"timezone":"Australia/Perth","openDate":"2026-07-20T05:13:00.000Z","version":7504136112,"raceType":"Harness","priceLadderDefinition":{"type":"CLASSIC"}},"rc":[{"batb":[[5,23,1],[4,24,7.86],[9,19.5,2.7],[8,20,2.63],[7,21,2.5],[6,22,10.6],[3,25,2.08],[2,26,2],[1,27,3.32],[0,28,5.68]],"batl":[[0,600,11.61],[2,630,1],[1,620,1]],"id":93234332},{"batb":[[9,8.6,4],[8,8.8,4],[7,9,4],[6,9.2,24.59],[5,9.4,11.17],[4,9.8,1.04],[3,10,1],[2,10.5,10.01],[1,13,1.04],[0,16.5,1.04]],"batl":[[6,920,2.1],[5,600,13.1],[4,440,2.12],[3,250,10],[2,100,1.74],[1,75,16.14],[0,44,11.67]],"id":21163447},{"batb":[[9,13.5,13.31],[6,15,17.97],[8,14,3.85],[7,14.5,3.7],[5,15.5,2.04],[4,16,3.33],[3,16.5,3.23],[2,17,1],[1,17.5,6.8],[0,19.5,1.04]],"batl":[[5,650,1],[4,640,1],[3,630,1],[2,620,1],[1,610,1],[0,600,10.81]],"id":27341073},{"batb":[[8,6.4,2],[5,7,16.2],[2,8,12.42],[9,6.2,4],[7,6.6,3.04],[6,6.8,36.77],[4,7.2,1],[3,7.8,12.71],[1,8.8,1.04],[0,11,1.04]],"batl":[[9,600,12.1],[8,440,2.12],[7,250,10],[6,60,2],[5,55,1],[4,50,1],[3,38,4.67],[2,34,1],[1,29,13.12],[0,25,11.82]],"id":73793682},{"batb":[[8,4.8,1],[1,6.4,1.56],[9,4.7,2],[7,4.9,1],[6,5.4,2],[5,5.5,2],[4,5.6,43.84],[3,5.7,1],[2,6.2,16.62],[0,6.6,2.27]],"batl":[[1,14.5,11.17],[0,14,1.07],[9,920,2.1],[8,840,2.6],[7,600,12.1],[6,440,2.12],[5,250,10],[4,38,1],[3,27,6.65],[2,18,19.33]],"id":76055924},{"batb":[[5,23,1],[4,24,7.86],[9,19.5,2.7],[8,20,2.63],[7,21,2.5],[6,22,10.6],[3,25,2.08],[2,26,2],[1,27,3.32],[0,28,5.68]],"batl":[[0,600,11.6],[2,630,1],[1,620,1]],"id":66834728},{"batb":[[6,8.6,5.04],[0,10.5,11.05],[7,8.4,18.22],[3,9.2,24.59],[2,9.4,11.17],[9,7.8,1],[8,8.2,4],[5,8.8,4],[4,9,4],[1,10,1]],"batl":[[6,920,2.1],[5,600,13.1],[4,440,2.12],[3,250,10],[2,100,1.74],[1,75,16.14],[0,44,11.67]],"id":59735573},{"batb":[[6,14.5,11.97],[5,15,17.97],[1,17,10.31],[2,16.5,3.23],[9,13,4],[4,15.5,1],[8,13.5,4],[7,14,3.85],[3,16,1],[0,17.5,6.8]],"batl":[[0,600,11.81]],"id":62688376},{"batb":[[9,1.22,16.14],[8,1.44,224.05],[7,1.53,1],[6,1.54,1],[5,1.55,1],[4,1.57,71.6],[3,1.86,234.49],[2,1.9,1],[1,1.91,94.98],[0,1.98,5.05]],"batl":[[9,85,5],[8,44,7.36],[7,34,15],[6,22,5.36],[5,16,15],[4,4.5,49.38],[3,4.3,16.14],[2,4.2,47.41],[1,3.7,1],[0,3.6,21.72]],"id":65574394},{"batb":[[7,17.5,11.37],[9,16.5,3.23],[2,20,9.4],[1,21,1],[6,18,2.94],[5,18.5,14.38],[4,19,1],[8,17,3.12],[3,19.5,2.7],[0,22,5.55]],"batl":[[2,620,1],[1,600,11.02],[0,320,16.84]],"id":63436713},{"batb":[[9,34,1.52],[8,36,1.43],[7,38,5.96],[6,40,1.28],[5,44,4.92],[4,46,2.6],[3,50,1.04],[2,60,1.46],[1,70,1.04],[0,90,1.04]],"batl":[[0,450,0.4]],"id":2207238},{"batb":[[7,8.4,18.22],[3,9.2,24.59],[2,9.4,11.17],[0,10.5,10.01],[9,7.8,1],[8,8.2,4],[6,8.6,4],[5,8.8,4],[4,9,4],[1,10,1]],"batl":[[6,920,2.1],[5,600,13.1],[4,440,2.12],[3,250,10],[2,100,1.74],[1,75,16.14],[0,44,11.67]],"id":12747055}],"img":true},{"id":"1.260192337","marketDefinition":{"bspMarket":true,"turnInPlayEnabled":true,"persistenceEnabled":true,"marketBaseRate":8,"eventId":"35840768","eventTypeId":"7","numberOfWinners":1,"bettingType":"ODDS","marketType":"WIN","marketTime":"2026-07-20T07:29:00.000Z","suspendTime":"2026-07-20T07:29:00.000Z","bspReconciled":false,"complete":true,"inPlay":false,"crossMatching":true,"runnersVoidable":false,"numberOfActiveRunners":9,"betDelay":0,"status":"OPEN","runners":[{"adjustmentFactor":5.744,"status":"ACTIVE","sortPriority":1,"id":41665191},{"adjustmentFactor":3.614,"status":"ACTIVE","sortPriority":2,"id":37618549},{"adjustmentFactor":5.744,"status":"ACTIVE","sortPriority":3,"id":4571458},{"adjustmentFactor":29.384,"status":"ACTIVE","sortPriority":4,"id":38629274},{"adjustmentFactor":13.33,"status":"ACTIVE","sortPriority":5,"id":12745112},{"adjustmentFactor":23.855,"status":"ACTIVE","sortPriority":6,"id":60463853},{"adjustmentFactor":13.33,"status":"ACTIVE","sortPriority":7,"id":11612818},{"adjustmentFactor":2.5,"status":"ACTIVE","sortPriority":8,"id":29058667},{"adjustmentFactor":2.5,"status":"ACTIVE","sortPriority":9,"id":69354359},{"adjustmentFactor":6.625,"status":"REMOVED","sortPriority":10,"removalDate":"2026-07-20T04:29:30.000Z","id":42496307}],"regulators":["MR_INT"],"venue":"Gloucester Park","countryCode":"AU","discountAllowed":true,"timezone":"Australia/Perth","openDate":"2026-07-20T05:13:00.000Z","version":7504193075,"raceType":"Harness","priceLadderDefinition":{"type":"CLASSIC"}},"rc":[{"batb":[[0,6.4,1.56],[9,1.16,100],[8,1.51,98.04],[7,2.12,44.64],[6,4.2,16.14],[5,4.7,28.67],[4,5.6,43.84],[3,5.7,15.46],[1,6.2,16.62],[2,6,1]],"batl":[[7,920,2.1],[6,600,12.1],[5,440,2.12],[4,250,10],[3,28,16.14],[2,27,6.65],[1,21,14.67],[0,17,11.17]],"id":12745112},{"batb":[[9,8.4,15.17],[5,9.2,28.59],[0,10.5,11.01],[4,9.4,4],[2,9.8,4],[8,8.6,4],[7,8.8,4],[6,9,4],[3,9.6,4],[1,10,1]],"batl":[[6,920,2.1],[5,600,13.1],[4,440,2.12],[3,100,1.74],[2,65,16.14],[1,36,11.17],[0,29,11.17]],"id":41665191},{"batb":[[1,18,9.6],[6,15.5,11.43],[2,17.5,3.03],[5,16,16.77],[3,17,3.12],[9,14,3.85],[8,14.5,3.7],[7,15,3.57],[4,16.5,3.23],[0,18.5,6.47]],"batl":[[2,620,1],[1,600,11.02],[0,270,16.9]],"id":29058667},{"batb":[[9,1.02,12],[8,1.16,100],[7,1.51,98.04],[6,2.12,16.14],[5,2.34,76],[4,2.7,25.19],[3,2.96,102.89],[1,3.15,41.2],[0,3.2,5.12],[2,3.1,1]],"batl":[[8,920,2.1],[7,600,12.1],[6,440,2.12],[5,250,10],[4,34,15],[3,12,16.14],[2,10,19.21],[1,8.2,31.3],[0,7,11.17]],"id":38629274},{"batb":[[9,1.16,100],[8,1.51,98.04],[7,2.12,44.64],[6,4.2,16.14],[5,4.7,28.67],[4,5.6,43.84],[3,5.7,15.46],[1,6.2,16.62],[2,6,1],[0,6.4,1.56]],"batl":[[7,920,2.1],[6,600,12.1],[5,440,2.12],[4,250,10],[3,28,16.14],[2,27,6.65],[1,21,14.67],[0,17,11.17]],"id":11612818},{"batb":[[6,3.5,80.66],[5,3.55,16.79],[1,3.75,32.43],[9,3.35,2],[8,3.4,2],[7,3.45,2],[0,3.8,4.63],[4,3.6,2],[3,3.65,2],[2,3.7,1]],"batl":[[7,920,2.1],[6,600,12.1],[5,440,2.12],[4,250,10],[3,15.5,16.14],[2,13.5,13.83],[1,11,23.1],[0,9.2,11.17]],"id":60463853},{"batb":[[7,13,25.81],[9,12,4],[8,12.5,4],[2,15.5,12.05],[1,16,13.44],[6,13.5,4],[5,14,3.85],[4,14.5,3.7],[3,15,3.57],[0,18.5,5.47]],"batl":[[3,620,1],[2,600,11.02],[1,270,16.14],[0,230,1.27]],"id":69354359},{"batb":[[9,1.5,1],[8,1.51,99.04],[7,2.12,44.64],[6,4,33.05],[5,4.2,16.14],[4,4.8,13.38],[3,5.9,41.16],[1,6.8,14.9],[2,6.6,1],[0,7,1.43]],"batl":[[2,28,22.54],[3,30,1],[1,17,16.63],[0,14,11.17],[7,920,2.1],[6,600,12.1],[5,440,2.12],[4,250,10]],"id":4571458},{"batb":[[9,12,20.14],[8,12.5,14.16],[5,14,19.36],[0,16.5,7.16],[3,15,3.57],[1,16,1],[7,13,4],[6,13.5,4],[4,14.5,3.7],[2,15.5,3.45]],"batl":[[4,650,1],[3,630,1],[2,620,1],[1,600,11.02],[0,230,16.97]],"id":37618549}],"img":true},{"id":"1.260191305","marketDefinition":{"bspMarket":true,"turnInPlayEnabled":true,"persistenceEnabled":true,"marketBaseRate":8,"eventId":"35840588","eventTypeId":"7","numberOfWinners":1,"bettingType":"ODDS","marketType":"WIN","marketTime":"2026-07-20T08:13:00.000Z","suspendTime":"2026-07-20T08:13:00.000Z","bspReconciled":false,"complete":true,"inPlay":false,"crossMatching":true,"runnersVoidable":false,"numberOfActiveRunners":9,"betDelay":0,"status":"OPEN","runners":[{"adjustmentFactor":0.262,"status":"ACTIVE","sortPriority":1,"id":50889685},{"adjustmentFactor":4.353,"status":"ACTIVE","sortPriority":2,"id":43568336},{"adjustmentFactor":5.725,"status":"ACTIVE","sortPriority":3,"id":46864009},{"adjustmentFactor":17.856,"status":"ACTIVE","sortPriority":4,"id":36955482},{"adjustmentFactor":15.107,"status":"ACTIVE","sortPriority":5,"id":23065746},{"adjustmentFactor":6.682,"status":"ACTIVE","sortPriority":6,"id":49548036},{"adjustmentFactor":2.105,"status":"ACTIVE","sortPriority":7,"id":47095286},{"adjustmentFactor":32.803,"status":"ACTIVE","sortPriority":8,"id":38858883},{"adjustmentFactor":15.107,"status":"ACTIVE","sortPriority":9,"id":46065793}],"regulators":["MR_INT"],"venue":"Redcliffe","countryCode":"AU","discountAllowed":true,"timezone":"Australia/Sydney","openDate":"2026-07-20T07:18:00.000Z","version":7504105217,"raceType":"Harness","priceLadderDefinition":{"type":"CLASSIC"}},"rc":[{"batb":[[9,1.51,98.04],[8,2.12,44.64],[7,6.8,32.22],[6,8.2,4],[5,8.4,4],[4,8.6,16.29],[3,8.8,13.01],[2,9.6,11.17],[1,10,1],[0,10.5,5.19]],"batl":[[4,620,1],[3,610,1],[2,600,11.02],[1,250,10.29],[0,32,11.17]],"id":49548036},{"batb":[[9,1.02,12],[8,1.16,100],[7,1.51,98.04],[6,2.12,44.64],[5,10.5,19.67],[4,14,3.85],[3,14.5,3.7],[2,15,10.25],[1,15.5,16.74],[0,19,1.73]],"batl":[[2,630,1],[1,620,1],[0,600,11.19]],"id":43568336},{"batb":[[9,1.02,12],[8,1.16,100],[7,1.51,98.04],[6,3.5,74.75],[5,3.95,31.67],[4,4.3,24.34],[3,4.6,17.18],[2,4.7,8.42],[1,4.8,2.08],[0,4.9,2]],"batl":[[1,13.5,11.17],[9,920,2.1],[8,630,1],[7,620,1],[6,610,1],[5,600,13.1],[4,440,2.12],[3,250,10],[2,34,1.93],[0,12,11.17]],"id":23065746},{"batb":[[8,1.01,1154.26],[7,1.02,12],[6,1.16,100],[5,2.3,143.74],[4,2.48,63.13],[3,2.5,51.21],[2,2.64,18.99],[1,2.66,41.02],[0,2.68,2]],"batl":[[7,920,2.1],[6,600,13.1],[5,440,2.12],[4,250,10],[3,10.5,3.28],[2,8.2,2.89],[1,6.6,27.79],[0,5.9,12.62]],"id":38858883},{"batb":[[9,1.01,1154.26],[8,1.02,12],[7,1.16,100],[6,1.51,98.04],[5,2.12,44.64],[4,40,1.28],[3,42,6.01],[2,75,1.26],[1,80,2.6],[0,85,2.84]],"batl":[[0,990,0.05]],"id":50889685},{"batb":[[9,1.01,1154.26],[8,1.02,12],[7,1.16,100],[6,1.51,98.04],[5,2.8,103.82],[4,2.98,47.19],[3,3.15,39.72],[2,3.35,13.25],[1,3.4,28.71],[0,3.45,2]],"batl":[[7,920,2.1],[6,600,13.1],[5,440,2.12],[4,250,10],[3,16,2.08],[2,11,2.08],[1,9,20.38],[0,8.2,11.17]],"id":46065793},{"batb":[[2,21,7.17],[1,22,5.75],[9,1.16,100],[8,1.51,98.04],[7,2.12,44.64],[6,16,12.46],[5,18.5,7.9],[4,19.5,2.7],[3,20,2.63],[0,29,1.11]],"batl":[[0,600,11.15],[9,690,1],[8,680,1],[7,670,1],[6,660,1],[5,650,1],[4,640,1],[3,630,1],[2,620,1],[1,610,1]],"id":47095286},{"batb":[[9,1.02,12],[8,1.16,100],[7,1.51,98.04],[6,2.12,44.64],[5,4.8,49.18],[4,5.5,2],[3,5.7,19.88],[2,5.9,17.31],[1,6.2,11.9],[0,7,6.1]],"batl":[[6,920,2.1],[5,610,1],[4,600,13.1],[3,440,2.12],[2,70,1.01],[1,20,11.17],[0,17.5,11.17]],"id":46864009},{"batb":[[9,1.02,12],[8,1.16,100],[7,1.51,98.04],[6,3.5,74.75],[5,3.95,31.67],[4,4.3,24.34],[3,4.6,17.18],[2,4.7,8.42],[1,4.8,2.08],[0,4.9,2]],"batl":[[1,13.5,11.17],[9,920,2.1],[8,630,1],[7,620,1],[6,610,1],[5,600,13.1],[4,440,2.12],[3,250,10],[2,34,1.93],[0,12,11.17]],"id":36955482}],"img":true},{"id":"1.260191303","marketDefinition":{"bspMarket":true,"turnInPlayEnabled":true,"persistenceEnabled":true,"marketBaseRate":8,"eventId":"35840588","eventTypeId":"7","numberOfWinners":1,"bettingType":"ODDS","marketType":"WIN","marketTime":"2026-07-20T07:48:00.000Z","suspendTime":"2026-07-20T07:48:00.000Z","bspReconciled":false,"complete":true,"inPlay":false,"crossMatching":true,"runnersVoidable":false,"numberOfActiveRunners":9,"betDelay":0,"status":"OPEN","runners":[{"adjustmentFactor":26.414,"status":"ACTIVE","sortPriority":1,"id":28329828},{"adjustmentFactor":22.788,"status":"ACTIVE","sortPriority":2,"id":28342476},{"adjustmentFactor":5.582,"status":"ACTIVE","sortPriority":3,"id":60463570},{"adjustmentFactor":25.517,"status":"ACTIVE","sortPriority":4,"id":12858590},{"adjustmentFactor":0.751,"status":"ACTIVE","sortPriority":5,"id":40598058},{"adjustmentFactor":10.396,"status":"ACTIVE","sortPriority":6,"id":77468482},{"adjustmentFactor":3.331,"status":"ACTIVE","sortPriority":7,"id":80452008},{"adjustmentFactor":1.481,"status":"ACTIVE","sortPriority":8,"id":60569837},{"adjustmentFactor":3.741,"status":"ACTIVE","sortPriority":9,"id":44064810}],"regulators":["MR_INT"],"venue":"Redcliffe","countryCode":"AU","discountAllowed":true,"timezone":"Australia/Sydney","openDate":"2026-07-20T07:18:00.000Z","version":7504105221,"raceType":"Harness","priceLadderDefinition":{"type":"CLASSIC"}},"rc":[{"batb":[[8,1.01,1154.26],[7,1.02,12],[6,1.16,100],[5,1.51,98.04],[4,2.72,40.44],[3,2.92,105.03],[2,2.94,34.36],[1,3.05,42.16],[0,3.1,5.23]],"batl":[[2,9.8,19.64],[1,7.4,25.5],[0,6.6,11.17],[6,920,2.1],[5,600,12.1],[4,440,2.12],[3,250,10]],"id":12858590},{"batb":[[9,19,2.78],[8,19.5,2.7],[7,20,2.63],[6,21,2.5],[5,22,1],[4,23,1],[3,27,5.64],[2,30,3.19],[1,48,4.49],[0,70,1.25]],"batl":[[0,470,0.39]],"id":40598058},{"batb":[[5,2.7,42.81],[4,2.82,110.8],[3,2.92,45.01],[2,2.94,36.39],[8,1.01,1154.26],[7,1.02,12],[6,1.16,100],[1,2.96,3.38],[0,2.98,2]],"batl":[[2,9.2,21.08],[1,7.2,27.07],[0,6.4,11.46],[6,920,2.1],[5,600,12.1],[4,440,2.12],[3,250,10]],"id":28329828},{"batb":[[4,7.2,14.1],[3,8.2,28.01],[2,8.4,11.17],[1,9.2,10.54],[9,5.5,2],[8,6.2,2],[7,6.4,2],[6,6.6,1],[5,6.8,1],[0,9.4,1.06]],"batl":[[1,25,11.17],[0,23,11.17],[8,920,2.1],[5,600,13.1],[7,620,1],[6,610,1],[4,440,2.12],[3,250,10],[2,75,2.34]],"id":60463570},{"batb":[[4,6.2,16.72],[3,7.2,32.53],[2,7.4,11.17],[1,8.2,12.01],[9,4.9,2],[8,5,2],[7,5.6,2],[6,5.8,1],[5,5.9,1],[0,8.4,1.19]],"batl":[[1,21,11.17],[0,19,11.17],[8,920,2.1],[5,600,13.1],[7,620,1],[6,610,1],[4,440,2.12],[3,250,10],[2,48,3.68]],"id":77468482},{"batb":[[4,2.98,43.07],[3,3.1,96.03],[2,3.2,29.46],[1,3.35,36.78],[0,3.4,4.94],[8,1.01,1154.26],[7,1.02,12],[6,1.16,100],[5,1.51,98.04]],"batl":[[2,10.5,18.19],[1,8.6,22.19],[0,7.6,11.17],[6,920,2.1],[5,600,12.1],[4,440,2.12],[3,250,10]],"id":28342476},{"batb":[[3,14.5,10.44],[2,18.5,11.52],[1,19,7.7],[0,22,4.55],[9,1.51,98.04],[8,2.12,44.64],[7,10,4],[6,10.5,4],[5,13.5,4],[4,14,3.85]],"batl":[[8,440,2.82],[9,600,12.1],[7,44,1],[6,42,1],[5,40,1],[4,38,1],[3,36,1],[2,34,1],[1,32,1],[0,30,7.27]],"id":44064810},{"batb":[[9,17,3.12],[8,18,2.94],[7,18.5,2.86],[6,19,2.78],[5,19.5,10.9],[4,20,7.21],[3,21,2.5],[2,22,2.38],[1,23,1],[0,24,5.16]],"batl":[[0,600,11.69],[3,630,1],[2,620,1],[1,610,1]],"id":80452008},{"batb":[[9,16,3.33],[8,16.5,11.47],[7,17,1],[6,18.5,2.86],[5,19,2.78],[4,19.5,2.7],[3,20,2.63],[2,21,9.07],[1,22,11.98],[0,27,3.68]],"batl":[[0,600,11.61],[6,670,1],[5,660,1],[4,650,1],[3,640,1],[2,630,1],[1,620,1]],"id":60569837}],"img":true}]}{"op":"mcm","clk":"AA4ACgAE","pt":1784527989788,"mc":[{"id":"1.260137374","rc":[{"batb":[[0,85,4.95]],"id":100720597}]},{"id":"1.260136658","rc":[{"batb":[[6,13,18.42]],"id":98996178}]}]}{"op":"mcm","clk":"AB4AEwAK","pt":1784527990097,"mc":[{"id":"1.260136658","rc":[{"trd":[[25,11.21]],"batb":[[9,17,16.58],[8,17.5,10.24],[7,18,7.05],[6,18.5,3.55],[5,19,6.08],[4,19.5,3.71],[3,20,2.66],[2,22,2.56],[1,23,1.06],[0,24,2.56]],"tv":31.25,"id":6690508}],"tv":2547.05}]}{"op":"mcm","clk":"ACIAFwAP","pt":1784527990194,"mc":[{"id":"1.260136658","rc":[{"batb":[[0,24,4.56]],"id":6690508}]}]}{"op":"mcm","clk":"AFMAOwAo","pt":1784527991525,"mc":[{"id":"1.260136658","rc":[{"batl":[[4,19.5,2.99]],"id":56407176}]}]}{"op":"mcm","clk":"AIUBAFIAUA==","pt":1784527992600,"mc":[{"id":"1.260137374","rc":[{"batb":[[1,30,1.52]],"id":100720596}]}]}{"op":"mcm","clk":"AIYBAFQAUQ==","pt":1784527992605,"mc":[{"id":"1.260136658","rc":[{"batl":[[6,920,2.1],[5,600,12.1],[4,440,2.13],[3,260,1.43],[2,65,3.85],[1,60,1.04],[0,55,2]],"id":69865836}]}]}{"op":"mcm","clk":"AI4BAFgAVA==","pt":1784527992710,"mc":[{"id":"1.260137374","rc":[{"batb":[[0,32,6.06]],"id":100720596}]}]}{"op":"mcm","clk":"ALkBAHEAcA==","pt":1784527993421,"mc":[{"id":"1.260136658","rc":[{"batl":[[9,130,1.81],[8,65,11.17],[7,42,1],[6,40,1],[5,38,1],[4,36,3.03],[3,34,2.42],[2,32,2.42]],"id":6690508},{"batl":[[8,920,2.1],[7,600,12.1],[6,440,2.13],[5,260,1.01],[4,80,1.21],[3,75,1.21]],"id":69865836},{"batl":[[9,630,1],[8,620,1],[7,610,1],[6,600,11.02],[5,370,1.05],[4,220,1.01],[3,170,1],[2,160,1.59]],"id":74493797}]}]}{"op":"mcm","clk":"ALoBAHIAcQ==","pt":1784527993469,"mc":[{"id":"1.260192491","rc":[{"batb":[[9,6.8,1],[8,7.2,4],[7,7.4,14.74],[6,7.6,4],[5,7.8,4]],"id":92822751},{"batb":[[9,30,2.29],[8,38,1.35],[7,40,1.28],[6,42,1.22],[5,44,5.2],[4,46,1.11],[3,50,1.02],[1,90,3.98]],"id":60010414},{"batl":[[0,1000,4.3]],"id":91496756},{"batl":[[9,3.4,45.13],[8,3.3,1],[7,3.25,1],[6,3.2,1],[5,3.15,1],[4,3.1,1],[3,3.05,1],[2,3,28.12],[1,2.96,1]],"id":71121948}]}]}{"op":"ocm","id":1,"clk":"AEYAUQBtAJsBAD8=","pt":1784527994289,"ct":"HEARTBEAT"}{"op":"mcm","clk":"AKsCALoBAKkB","pt":1784527995620,"mc":[{"id":"1.260136666","rc":[{"batl":[[9,29,1.5]],"id":91807545}]}]}{"op":"mcm","clk":"ALkCAMIBALAB","pt":1784527995821,"mc":[{"id":"1.260137374","rc":[{"batl":[[9,44,7.36],[8,34,15],[7,22,5.36],[6,9.8,41.47],[5,9.6,11.79],[4,8.8,11.32],[3,8.4,1.79],[2,7.4,6.93],[1,6.6,1]],"id":99274452}]}]}{"op":"mcm","clk":"ALkCAMMBALAB","pt":1784527995824,"mc":[{"id":"1.260136666","rc":[{"batl":[[9,18,16.14]],"id":91807545}]}]}{"op":"mcm","clk":"AMoCAMwBALcB","pt":1784527996128,"mc":[{"id":"1.260136666","rc":[{"batl":[[9,36,6.91]],"id":74901081}]}]}{"op":"mcm","clk":"AOYCANoBAMsB","pt":1784527996544,"mc":[{"id":"1.260137374","rc":[{"batb":[[2,60,4.42],[1,70,2.61]],"id":100720597}]}]}{"op":"mcm","clk":"AOYCANsBAMsB","pt":1784527996545,"mc":[{"id":"1.260136658","rc":[{"batl":[[5,38,2]],"id":6690508},{"batl":[[9,920,2.1],[8,600,12.1],[7,440,2.13],[6,260,1.01],[5,80,2.21],[4,75,1],[3,70,1.21]],"id":69865836}]}]}{"op":"mcm","clk":"APACAOEBANgB","pt":1784527996748,"mc":[{"id":"1.260136666","rc":[{"batl":[[2,140,1.45]],"id":88111702}]},{"id":"1.260136658","rc":[{"batl":[[9,440,2.12],[8,250,10],[7,200,2],[6,130,1.81],[5,65,11.17],[4,36,2.03],[3,34,1.42],[2,32,1.42]],"id":6690508},{"batl":[[9,0,0],[8,0,0],[7,0,0],[6,920,2.1],[5,600,12.1],[4,440,2.13],[3,260,1.43]],"id":69865836},{"batl":[[9,650,1],[8,640,1],[7,630,1],[6,620,1],[5,610,1],[4,600,11.02],[3,370,1.47],[2,180,1.18]],"id":74493797}]}]}{"op":"mcm","clk":"APUCAOEBANgB","pt":1784527996755,"mc":[{"id":"1.260137374","rc":[{"batb":[[2,60,3.42],[1,70,1.61]],"id":100720597}]}]}{"op":"mcm","clk":"APgCAOUBANsB","pt":1784527996808,"mc":[{"id":"1.260136658","rc":[{"batl":[[2,1000,0.2],[1,480,2],[0,470,1.06]],"id":69161915},{"trd":[[7.8,76.86]],"batb":[[9,5.9,2.45],[8,6,19.83],[7,6.2,13.54],[6,6.4,22.26],[5,6.6,19.81],[4,6.8,29.78],[3,7,21.17],[2,7.2,12.64],[1,7.4,10.7],[0,7.6,3.7]],"tv":332.99,"id":79455963}],"tv":2549.13}]}{"op":"mcm","clk":"AP8CAOkBAN4B","pt":1784527996904,"mc":[{"id":"1.260136666","rc":[{"batl":[[9,920,2.1],[8,610,1],[7,600,13.1],[6,590,3.6],[5,440,2.12],[4,210,1.16],[3,150,16.14]],"id":88111702}]},{"id":"1.260136658","rc":[{"batb":[[0,7.6,3.52]],"id":79455963}]}]}{"op":"mcm","clk":"AIEDAOkBAN4B","pt":1784527996906,"mc":[{"id":"1.260136589","rc":[{"batl":[[9,250,10],[8,110,2],[7,42,5.12],[6,28,12.63],[5,21,1],[4,20,12.17],[3,17,5.97],[1,16,1.65],[0,15.5,1]],"id":54439633},{"batl":[[9,27,12.17],[8,26,1],[7,25,2.68],[6,24,3.5],[5,23,1],[4,22,3.12],[3,21,2.5],[2,20,13.17],[1,19.5,2.29],[0,18,5.9]],"id":41749902},{"batl":[[2,260,1],[1,210,1.13],[0,70,2.39]],"id":85017109},{"batl":[[8,1000,0.52],[7,920,2.1],[6,630,1],[5,620,1],[4,600,13.1],[3,440,2.13],[2,260,1],[1,250,1.2]],"id":6690785}]}]}{"op":"mcm","clk":"AIYDAO8BAOMB","pt":1784527997006,"mc":[{"id":"1.260136658","rc":[{"batl":[[6,0,0],[5,920,2.1],[4,600,12.1],[3,440,2.13],[2,260,1.43],[1,65,3.85]],"id":69865836}]}]}{"op":"mcm","clk":"AJADAPIBAOcB","pt":1784527997157,"mc":[{"id":"1.260192334","rc":[{"batl":[[9,250,10],[8,85,5],[7,44,7.36],[6,34,15],[5,22,5.36],[4,16,15],[3,4.5,49.38]],"id":65574394}]}]}{"op":"mcm","clk":"AKQDAP0BAPIB","pt":1784527997466,"mc":[{"id":"1.260192334","rc":[{"batl":[[6,0,0],[5,920,2.1],[4,600,13.1],[3,440,2.12],[2,250,10],[1,100,1.74]],"id":59735573}]}]}{"op":"mcm","clk":"AKkDAIACAPMB","pt":1784527997518,"mc":[{"id":"1.260136666","rc":[{"batb":[[9,1.51,98.04],[8,2.12,44.64],[7,2.24,4.84],[6,2.74,3.45]],"id":91807545}]}]}{"op":"mcm","clk":"AKsDAIECAPcB","pt":1784527997568,"mc":[{"id":"1.260192334","rc":[{"batl":[[1,100,2.24],[0,44,11.17]],"id":59735573}]}]}{"op":"mcm","clk":"ALIDAIcCAPwB","pt":1784527997668,"mc":[{"id":"1.260192334","rc":[{"batl":[[6,0,0],[5,920,2.1],[4,600,13.1],[3,440,2.12],[2,250,10],[1,100,1.74]],"id":21163447}]}]}{"op":"mcm","clk":"ALIDAIoCAP4B","pt":1784527997716,"mc":[{"id":"1.260136666","rc":[{"batb":[[9,2.12,44.64],[8,2.24,4.84],[7,2.74,3.45],[6,3.95,16.14]],"id":91807545}]}]}{"op":"mcm","clk":"ALgDAIwCAIIC","pt":1784527997771,"mc":[{"id":"1.260192334","rc":[{"batl":[[1,100,2.24]],"id":21163447}]}]}{"op":"mcm","clk":"AL4DAI4CAIYC","pt":1784527997871,"mc":[{"id":"1.260192334","rc":[{"batl":[[0,44,11.17]],"id":21163447},{"batl":[[6,0,0],[5,920,2.1],[4,600,13.1],[3,440,2.12],[2,250,10],[1,100,1.74]],"id":12747055}]}]}{"op":"mcm","clk":"AMEDAI8CAIcC","pt":1784527997968,"mc":[{"id":"1.260192334","rc":[{"batl":[[1,100,2.24]],"id":12747055}]}]}{"op":"mcm","clk":"AMQDAJICAIoC","pt":1784527998069,"mc":[{"id":"1.260192334","rc":[{"batl":[[0,44,11.17]],"id":12747055}]}]}{"op":"mcm","clk":"AMUDAJQCAIoC","pt":1784527998124,"mc":[{"id":"1.260136666","rc":[{"batb":[[9,3.05,24.39],[8,3.1,2.86],[7,3.9,2.07],[6,5.3,30.32]],"id":74901081}]}]}{"op":"mcm","clk":"AMoDAJYCAI4C","pt":1784527998174,"mc":[{"id":"1.260192334","rc":[{"batl":[[2,0,0],[1,620,1],[0,600,11.72]],"id":63436713}]}]}{"op":"mcm","clk":"AM0DAJcCAI4C","pt":1784527998227,"mc":[{"id":"1.260137374","rc":[{"batl":[[9,250,10],[8,44,7.36],[7,34,15],[6,22,5.36],[5,9.8,41.47],[4,9.6,11.79],[3,8.8,11.32],[2,8.4,1.79],[1,7.4,6.93],[0,6.6,1]],"id":99274452}]}]}{"op":"mcm","clk":"ANUDAJ0CAJIC","pt":1784527998330,"mc":[{"id":"1.260137374","rc":[{"batl":[[9,44,7.36],[8,34,15],[7,22,5.36],[6,9.8,41.47],[5,9.6,11.79],[4,8.8,11.32],[3,8.4,1.79],[2,7.4,6.93],[1,6.6,1],[0,6.4,1]],"id":99274452}]}]}{"op":"mcm","clk":"ANUDAJ8CAJIC","pt":1784527998333,"mc":[{"id":"1.260136666","rc":[{"batb":[[9,3.1,2.86],[8,3.9,2.07],[7,5.3,30.32],[6,6.6,16.14]],"id":74901081}]}]}{"op":"mcm","clk":"ANcDAKICAJcC","pt":1784527998393,"mc":[{"id":"1.260192334","rc":[{"batb":[[9,1.02,12]],"id":65574394}]}]}{"op":"mcm","clk":"AOwDAK8CAJ8C","pt":1784527998790,"mc":[{"id":"1.260192491","rc":[{"batl":[[0,390,2.54]],"id":43653174}]}]}{"op":"mcm","clk":"APMDALICAKEC","pt":1784527998893,"mc":[{"id":"1.260192491","rc":[{"batl":[[0,390,4.54]],"id":43653174}]}]}{"op":"mcm","clk":"APgDALYCAKEC","pt":1784527998992,"mc":[{"id":"1.260192491","rc":[{"batl":[[2,900,0.85]],"id":43653174}]}]}{"op":"mcm","clk":"AP0DALgCAKMC","pt":1784527999045,"mc":[{"id":"1.260192491","rc":[{"batb":[[9,21,1.04],[8,30,2.29],[7,38,1.35],[6,40,1.28],[5,42,1.22],[4,44,5.2],[3,46,1.11],[1,90,2.98]],"id":60010414},{"batl":[[0,1000,3.3]],"id":91496756},{"batl":[[9,3.7,63.65],[8,3.4,45.13],[7,3.3,1],[6,3.25,1],[5,3.2,1],[4,3.15,1],[3,3.1,1],[2,3.05,1],[1,3,28.12]],"id":71121948}]}]}{"op":"ocm","id":1,"clk":"AJwBAMMBAO0BAMICAIoB","pt":1784527999289,"ct":"HEARTBEAT"}{"op":"mcm","clk":"ANYEAPMCAOQC","pt":1784528000205,"mc":[{"id":"1.260136589","rc":[{"batb":[[8,19.5,10.67]],"id":85017109}]}]}{"op":"mcm","clk":"APwEAJ4DAPUC","pt":1784528000726,"mc":[{"id":"1.260136658","rc":[{"batl":[[2,0,0],[1,580,1.08],[0,270,2.65]],"id":99951973}]}]}{"op":"mcm","clk":"AIEFAKMDAPgC","pt":1784528000828,"mc":[{"id":"1.260136658","rc":[{"batl":[[2,580,1.08],[1,270,2],[0,260,1.11]],"id":99951973}]}]}{"op":"mcm","clk":"AI4FAKkDAP0C","pt":1784528001030,"mc":[{"id":"1.260137374","rc":[{"batb":[[9,2.12,44.64],[8,2.38,4.35],[7,2.94,3.09]],"id":25417481}]}]}{"op":"mcm","clk":"AJUFAK0DAP4C","pt":1784528001133,"mc":[{"id":"1.260137374","rc":[{"batb":[[9,2.38,4.35],[8,2.94,3.09],[7,5.2,2],[6,5.3,66.08],[5,5.4,27.71]],"id":25417481}]}]}{"op":"mcm","clk":"AKcFALkDAIYD","pt":1784528001488,"mc":[{"id":"1.260192495","rc":[{"batb":[[9,1.02,12],[8,1.16,100],[7,1.51,98.04],[6,2.12,44.64],[5,3.05,24.39],[4,4.1,16.13],[3,4.6,2.88],[2,6.2,9.93],[1,55,3.11],[0,65,4.12]],"id":46626367}]}]}{"op":"mcm","clk":"ALAFAL0DAIwD","pt":1784528001593,"mc":[{"id":"1.260192495","rc":[{"batb":[[9,1.16,100],[8,1.51,98.04],[7,2.12,44.64],[6,3.05,24.39],[5,4.1,16.13],[4,4.6,2.88],[3,6.2,9.93],[2,55,3.11],[1,65,3.15],[0,70,3.57]],"id":46626367}]}]}{"op":"mcm","clk":"ANMFAM0DAJgD","pt":1784528002117,"mc":[{"id":"1.260136658","rc":[{"batl":[[9,12,1]],"id":79455963}]}]}{"op":"mcm","clk":"AOcFANoDAKID","pt":1784528002520,"mc":[{"id":"1.260136658","rc":[{"batl":[[0,470,1.04]],"id":69161915}]}]}{"op":"mcm","clk":"APYFAOADAKkD","pt":1784528002727,"mc":[{"id":"1.260136658","rc":[{"batl":[[0,470,1.06]],"id":69161915}]}]}{"op":"mcm","clk":"AIsGAOsDALID","pt":1784528003134,"mc":[{"id":"1.260136658","rc":[{"batb":[[9,11,6.99],[8,11.5,12.7],[7,12,18.16],[6,12.5,23.63],[5,13,27.75],[4,13.5,8.79],[3,14,8.34]],"id":56407176}]}]}{"op":"mcm","clk":"AKsGAPADALgD","pt":1784528003439,"mc":[{"id":"1.260137374","rc":[{"batb":[[1,23,2.66],[0,24,3.2]],"id":68064063}]},{"id":"1.260136589","rc":[{"batb":[[0,10.5,1.7]],"id":41749902}]}]}{"op":"mcm","clk":"AKwGAPIDALkD","pt":1784528003488,"mc":[{"id":"1.260192491","rc":[{"batb":[[9,30,2.29],[8,38,1.35],[7,40,1.28],[6,42,1.22],[5,44,5.2],[4,46,1.11],[3,50,1.02]],"id":60010414},{"batl":[[9,3.3,1],[8,3.25,1],[7,3.2,1],[6,3.15,1],[5,3.1,1],[4,3.05,1],[3,3,28.12],[2,2.96,1],[1,2.94,1],[0,2.92,3.31]],"id":71121948}]}]}{"op":"mcm","clk":"AK4GAPIDALoD","pt":1784528003490,"mc":[{"id":"1.260136589","rc":[{"batb":[[1,10,16.74]],"id":41749902}]}]}{"op":"mcm","clk":"AK8GAPQDALoD","pt":1784528003496,"mc":[{"id":"1.260136658","rc":[{"batl":[[9,130,1.81],[8,65,11.17],[7,42,1],[6,40,1],[5,38,1],[4,36,3.03],[3,34,2.42],[2,32,2.42]],"id":6690508},{"batl":[[7,920,2.1],[6,600,12.1],[5,440,2.13],[4,260,1.01],[3,80,1.21],[2,75,1.21]],"id":69865836},{"batl":[[9,630,1],[8,620,1],[7,610,1],[6,600,11.02],[5,370,1.05],[4,220,1.01],[3,170,1],[2,160,1.59]],"id":74493797}]}]}{"op":"mcm","clk":"ALQGAPYDAL0D","pt":1784528003594,"mc":[{"id":"1.260136589","rc":[{"batl":[[1,19.5,1.5],[0,18,6.76]],"id":41749902}]}]}{"op":"mcm","clk":"ALQGAPcDAL0D","pt":1784528003596,"mc":[{"id":"1.260136658","rc":[{"batl":[[7,0,0],[6,920,2.1],[5,600,12.1],[4,440,2.13],[3,260,1.01],[2,80,1.21],[1,75,1.21],[0,65,3.85]],"id":69865836}]}]}{"op":"mcm","clk":"ALYGAPcDAL0D","pt":1784528003599,"mc":[{"id":"1.260137374","rc":[{"batb":[[1,23,1.66],[0,24,2.2]],"id":68064063}]}]}{"op":"mcm","clk":"AMYGAIMEAMQD","pt":1784528003998,"mc":[{"id":"1.260136589","rc":[{"batl":[[9,25,2.68],[8,24,3.5],[7,23,1],[6,22,3.12],[5,21,2.5],[4,20,13.17],[3,19.5,1.5],[2,19,1.46],[1,18.5,1.46]],"id":41749902}]}]}{"op":"mcm","clk":"AM4GAIsEAMkD","pt":1784528004212,"mc":[{"id":"1.260136589","rc":[{"batb":[[1,10,17.01]],"id":41749902}]}]}{"op":"ocm","id":1,"clk":"APYBAJoCAOUCAOIDAO4B","pt":1784528004289,"ct":"HEARTBEAT"}{"op":"mcm","clk":"AM8GAJAEAMsD","pt":1784528004307,"mc":[{"id":"1.260136658","rc":[{"batl":[[9,440,2.12],[8,250,10],[7,200,2],[6,130,1.81],[5,65,11.17],[4,36,2.03],[3,34,1.42],[2,32,1.42]],"id":6690508},{"batl":[[6,0,0],[5,0,0],[4,920,2.1],[3,600,12.1],[2,440,2.13],[1,260,1.43]],"id":69865836},{"batl":[[9,650,1],[8,640,1],[7,630,1],[6,620,1],[5,610,1],[4,600,11.02],[3,370,1.47],[2,180,1.18]],"id":74493797}]}]}{"op":"mcm","clk":"ANEGAJAEAMsD","pt":1784528004316,"mc":[{"id":"1.260136589","rc":[{"batb":[[0,10.5,1.52]],"id":41749902}]}]}{"op":"mcm","clk":"ANkGAJcEAM0D","pt":1784528004416,"mc":[{"id":"1.260136589","rc":[{"batb":[[9,6.6,25.14],[8,8.4,12.2],[7,8.8,7.69],[6,9,7.5]],"id":41749902}]}]}{"op":"mcm","clk":"AOcGAJ0EANID","pt":1784528004670,"mc":[{"id":"1.260192491","rc":[{"batb":[[5,44,1.15]],"id":60010414}]}]}{"op":"mcm","clk":"AIMHAKwEANkD","pt":1784528005174,"mc":[{"id":"1.260192491","rc":[{"batb":[[9,4.6,2.88],[8,6.2,9.62],[7,12.5,1.04],[6,16,3],[5,17,1.04],[4,21,1.04],[3,30,2.29]],"id":60010414},{"batl":[[9,3.7,63.65],[8,3.4,45.13],[7,3.3,1],[6,3.25,1],[5,3.2,1],[4,3.15,1],[3,3.1,1],[2,3.05,1],[1,3,28.12],[0,2.92,2.31]],"id":71121948}]}]}{"op":"mcm","clk":"AIkHAK8EANwD","pt":1784528005277,"mc":[{"id":"1.260191305","rc":[{"batb":[[9,1.16,100],[8,1.51,98.04],[7,2.12,44.64],[4,8.6,4],[0,10.5,1.91]],"batl":[[1,250,10.01]],"id":49548036},{"batb":[[9,0,0],[8,1.01,1154.26],[7,1.02,12],[6,1.16,100],[5,1.51,98.04],[4,2.12,44.64],[3,14,3.85],[2,14.5,3.7],[1,15,3.57],[0,15.5,16.74]],"batl":[[0,600,11.02]],"id":43568336},{"batb":[[9,0,0],[8,0,0],[7,1.01,1154.26],[6,1.02,12],[5,1.16,100],[4,1.51,98.04],[3,4.3,24.34],[2,4.6,17.18]],"batl":[[9,0,0],[8,920,2.1],[7,630,1],[6,620,1],[5,610,1],[4,600,13.1],[3,440,2.12],[2,250,10]],"id":23065746},{"batb":[[8,0,0],[7,0,0],[6,0,0],[5,1.01,1154.26],[4,1.02,12],[3,1.16,100],[2,2.5,51.21]],"batl":[[7,0,0],[6,0,0],[5,920,2.1],[4,600,13.1],[3,440,2.12],[2,250,10]],"id":38858883},{"batb":[[9,0,0],[8,1.01,1154.26],[7,1.02,12],[6,1.16,100],[5,1.51,98.04],[4,2.12,44.64],[3,40,1.28],[2,42,1.45],[0,85,2.6]],"batl":[[0,390,0.02]],"id":50889685},{"batb":[[9,0,0],[8,0,0],[7,0,0],[6,1.01,1154.26],[5,1.02,12],[4,1.16,100],[3,1.51,98.04],[2,3.15,39.72]],"batl":[[7,0,0],[6,0,0],[5,920,2.1],[4,600,13.1],[3,440,2.12],[2,250,10]],"id":46065793},{"batb":[[9,1.01,1154.26],[8,1.02,12],[7,1.16,100],[6,1.51,98.04],[5,2.12,44.64],[4,18.5,7.9],[3,19.5,2.7],[2,20,2.63],[1,21,2.5],[0,22,5.75]],"batl":[[0,600,11.02]],"id":47095286},{"batb":[[9,0,0],[8,0,0],[7,1.01,1154.26],[6,1.02,12],[5,1.16,100],[4,1.51,98.04],[3,2.12,44.64],[2,5.5,2],[1,5.9,17.31],[0,6.2,12.81]],"batl":[[6,0,0],[5,920,2.1],[4,610,1],[3,600,13.1],[2,440,2.12]],"id":46864009},{"batb":[[9,0,0],[8,0,0],[7,1.01,1154.26],[6,1.02,12],[5,1.16,100],[4,1.51,98.04],[3,4.3,24.34],[2,4.6,17.18]],"batl":[[9,0,0],[8,920,2.1],[7,630,1],[6,620,1],[5,610,1],[4,600,13.1],[3,440,2.12],[2,250,10]],"id":36955482}]}]}{"op":"mcm","clk":"AJIHALUEAOID","pt":1784528005435,"mc":[{"id":"1.260136658","rc":[{"trd":[[7.8,81.8]],"tv":337.93,"id":79455963}],"tv":2554.07}]}{"op":"mcm","clk":"AJgHALcEAOgD","pt":1784528005592,"mc":[{"id":"1.260191305","rc":[{"batb":[[9,1.01,1154.26],[8,1.02,12],[7,1.16,100],[6,1.51,98.04],[5,2.12,44.64],[4,8.2,4],[3,8.4,4],[2,8.6,4],[1,8.8,13.01],[0,9.6,12.08]],"id":49548036},{"batb":[[8,0,0],[7,0,0],[6,1.01,1154.26],[5,1.02,12],[4,1.16,100],[3,1.51,98.04],[2,2.12,44.87]],"id":50889685}]}]}{"op":"mcm","clk":"AKEHAMQEAPID","pt":1784528005900,"mc":[{"id":"1.260136658","rc":[{"batl":[[1,8.4,22.08]],"id":79455963}]}]}{"op":"mcm","clk":"AKUHAMkEAPQD","pt":1784528006005,"mc":[{"id":"1.260136658","rc":[{"trd":[[7.6,45.28]],"batb":[[9,5.7,50.03],[8,5.9,2.45],[7,6,19.83],[6,6.2,13.54],[5,6.4,22.26],[4,6.6,19.81],[3,6.8,29.78],[2,7,21.17],[1,7.2,12.64],[0,7.4,11.62]],"ltp":7.6,"tv":343.13,"id":79455963}],"tv":2559.27}]}{"op":"mcm","clk":"AKwHAM8EAPwD","pt":1784528006105,"mc":[{"id":"1.260191305","rc":[{"batb":[[9,1.16,100],[8,1.51,98.04],[7,2.12,44.64],[6,8.2,4],[5,8.4,4],[4,8.6,4],[3,8.8,13.01],[2,9.6,11.17],[1,10,23.32],[0,12.5,7.52]],"batl":[[5,620,1],[4,610,1],[3,600,11.02],[2,250,10.01],[1,140,1.25]],"id":49548036},{"batb":[[9,1.02,12],[8,1.16,100],[7,1.51,98.04],[6,2.12,44.64],[5,14,3.85],[4,14.5,3.7],[3,15,3.57],[2,15.5,16.74],[1,18.5,11.52],[0,22,4.12]],"batl":[[0,600,11.72]],"id":43568336},{"batb":[[8,1.01,1154.26],[7,1.02,12],[6,1.16,100],[5,1.51,98.04],[4,4.3,24.34],[3,4.6,73.2],[2,4.8,2.08],[1,4.9,2],[0,5.1,21.08]],"batl":[[9,920,2.1],[8,630,1],[7,620,1],[6,610,1],[5,600,13.1],[4,440,2.12],[3,250,10],[2,22,8.23]],"id":23065746},{"batb":[[7,1.01,1154.26],[6,1.02,12],[5,1.16,100],[4,2.5,51.21],[3,2.62,124.48],[2,2.66,41.02],[1,2.68,2],[0,2.72,50.25]],"batl":[[6,920,2.1],[5,600,13.1],[4,440,2.12],[3,250,10],[2,8.2,24.01]],"id":38858883},{"batb":[[7,1.01,1154.26],[6,1.02,12],[5,1.16,100],[4,1.51,98.04],[3,2.12,44.87],[2,80,2.6],[1,85,2.6],[0,120,2.2]],"batl":[[0,890,0.21]],"id":50889685},{"batb":[[8,1.01,1154.26],[7,1.02,12],[6,1.16,100],[5,1.51,98.04],[4,3.15,39.72],[3,3.3,87.68],[2,3.4,28.71],[1,3.45,2],[0,3.55,33.89]],"batl":[[6,920,2.1],[5,600,13.1],[4,440,2.12],[3,250,10],[2,11,17.29]],"id":46065793},{"batb":[[9,1.16,100],[8,1.51,98.04],[7,2.12,44.64],[6,18.5,7.9],[5,19.5,2.7],[4,20,2.63],[3,21,2.5],[2,22,5.75],[1,28,7.47],[0,36,2.47]],"batl":[[0,600,11.51]],"id":47095286},{"batb":[[9,1.01,1154.26],[8,1.02,12],[7,1.16,100],[6,1.51,98.04],[5,2.12,44.64],[4,5.5,2],[3,5.9,17.31],[2,6.2,11.9],[1,6.8,34.77],[0,7.8,13.62]],"batl":[[6,920,2.1],[5,610,1],[4,600,13.1],[3,440,2.12],[2,38,4.67]],"id":46864009},{"batb":[[8,1.01,1154.26],[7,1.02,12],[6,1.16,100],[5,1.51,98.04],[4,4.3,24.34],[3,4.6,73.2],[2,4.8,2.08],[1,4.9,2],[0,5.1,21.08]],"batl":[[9,920,2.1],[8,630,1],[7,620,1],[6,610,1],[5,600,13.1],[4,440,2.12],[3,250,10],[2,22,8.23]],"id":36955482}]}]}{"op":"mcm","clk":"AKwHANEEAPwD","pt":1784528006106,"mc":[{"id":"1.260136658","rc":[{"batl":[[9,10.5,11.71],[8,9.6,11.59],[7,9.4,1.11],[6,9.2,2.63],[5,9,18.73],[4,8.8,2.06],[3,8.6,10.75],[2,8.4,22.08],[1,8.2,11.79],[0,8,2.17]],"id":79455963}]}]}{"op":"mcm","clk":"ALYHAOAEAIkE","pt":1784528006313,"mc":[{"id":"1.260136658","rc":[{"batb":[[0,7.4,10.7]],"id":79455963}]}]}{"op":"mcm","clk":"AMAHAOYEAJ0E","pt":1784528006561,"mc":[{"id":"1.260136658","rc":[{"batb":[[1,7.2,2.96]],"id":79455963}]}]}{"op":"mcm","clk":"AMgHAOkEAKAE","pt":1784528006614,"mc":[{"id":"1.260137374","rc":[{"batb":[[2,60,4.42],[1,70,2.61]],"id":100720597}]}]}{"op":"mcm","clk":"AK0IAKoFANgE","pt":1784528008201,"mc":[{"id":"1.260136666","rc":[{"batl":[[9,250,10],[8,180,2],[7,95,2.57]],"id":100749632}]}]}{"op":"mcm","clk":"AL4IALcFANsE","pt":1784528008410,"mc":[{"id":"1.260136666","rc":[{"batl":[[9,180,2],[8,95,2.57],[7,85,16.14]],"id":100749632}]}]}{"op":"mcm","clk":"AOgIANsFAOkE","pt":1784528009220,"mc":[{"id":"1.260136658","rc":[{"batb":[[1,15.5,16.13]],"id":98996178}]}]}{"op":"ocm","id":1,"clk":"ALwCAJUDANIDAIEFALkC","pt":1784528009289,"ct":"HEARTBEAT"}{"op":"mcm","clk":"AO8IAOEFAOsE","pt":1784528009325,"mc":[{"id":"1.260136658","rc":[{"batb":[[9,12,13.5],[8,12.5,9.98],[7,13,18.42],[6,13.5,5.79],[5,14,11.04],[4,14.5,7.4],[3,15,3.47],[2,15.5,16.13],[1,16,1.91],[0,16.5,1.03]],"id":98996178}]}]}{"op":"mcm","clk":"APIIAOYFAOwE","pt":1784528009423,"mc":[{"id":"1.260136658","rc":[{"batb":[[3,15,7.76]],"id":98996178}]}]}{"op":"mcm","clk":"APUIAOYFAOwE","pt":1784528009427,"mc":[{"id":"1.260137374","rc":[{"batl":[[9,34,15],[8,22,5.36],[7,9.8,41.47],[6,9.6,11.79],[5,8.8,11.32],[4,8.4,1.79],[3,7.4,6.93],[2,6.6,1],[1,6.4,1],[0,4.4,103.82]],"id":99274452}]}]}{"op":"mcm","clk":"AP4IAOsFAO0E","pt":1784528009537,"mc":[{"id":"1.260137374","rc":[{"batl":[[9,44,7.36],[8,34,15],[7,22,5.36],[6,9.8,41.47],[5,9.6,11.79],[4,8.8,11.32],[3,8.4,1.79],[2,7.4,6.93],[1,6.6,1]],"id":99274452},{"batb":[[2,60,3.42],[1,70,1.61]],"id":100720597}]}]}{"op":"mcm","clk":"AJoJAPwFAP0E","pt":1784528010137,"mc":[{"id":"1.260137374","rc":[{"batl":[[9,34,15],[8,22,5.36],[7,9.8,41.47],[6,9.6,11.79],[5,8.8,11.32],[4,8.4,1.79],[3,7.4,6.93],[2,6.6,1],[1,4.4,103.82],[0,4.3,2.7]],"id":99274452}]}]}{"op":"mcm","clk":"AKcJAIYGAIsF","pt":1784528010547,"mc":[{"id":"1.260136666","rc":[{"batb":[[9,1.51,98.04],[8,2.12,44.64],[7,2.24,4.84],[6,2.74,3.45],[5,3.95,16.14]],"id":91807545}]}]}{"op":"mcm","clk":"AKwJAIkGAIsF","pt":1784528010653,"mc":[{"id":"1.260136666","rc":[{"batb":[[9,2.12,44.64],[8,2.24,4.84],[7,2.74,3.45],[6,3.95,16.14],[5,4,30.47]],"id":91807545}]}]}{"op":"mcm","clk":"ALUJAJIGAIwF","pt":1784528010851,"mc":[{"id":"1.260192493","rc":[{"batl":[[6,920,2.1],[5,620,1],[4,610,1],[3,600,10.99],[2,120,4.2],[1,110,16.14],[0,100,4.22]],"id":90296582}]}]}{"op":"mcm","clk":"ALsJAJUGAI4F","pt":1784528010965,"mc":[{"id":"1.260192493","rc":[{"batl":[[6,0,0],[5,920,2.1],[4,620,1],[3,610,1],[2,600,10.99]],"id":90296582}]}]}{"op":"mcm","clk":"AKQKAL8GALQF","pt":1784528013007,"mc":[{"id":"1.260137374","rc":[{"batb":[[0,85,2.36]],"id":100720597}]}]}{"op":"mcm","clk":"AKkKAMEGALcF","pt":1784528013112,"mc":[{"id":"1.260137374","rc":[{"batb":[[9,16,3.91],[8,30,2],[7,44,1.15],[6,46,1.11],[5,48,1.27],[4,50,7.82],[3,60,3.42],[2,70,1.61],[1,85,2.36],[0,95,2.6]],"id":100720597}]}]}{"op":"mcm","clk":"ALIKAMoGALwF","pt":1784528013417,"mc":[{"id":"1.260136658","rc":[{"batl":[[9,130,1.81],[8,65,11.17],[7,42,1],[6,40,1],[5,38,1],[4,36,3.03],[3,34,2.42],[2,32,2.42]],"id":6690508},{"batb":[[1,7.2,3.96]],"id":79455963},{"batl":[[9,630,1],[8,620,1],[7,610,1],[6,600,11.02],[5,370,1.05],[4,220,1.01],[3,170,1],[2,160,1.59]],"id":74493797}]}]}{"op":"mcm","clk":"ALMKAMsGAL4F","pt":1784528013465,"mc":[{"id":"1.260192491","rc":[{"batl":[[9,3.4,45.13],[8,3.3,1],[7,3.25,1],[6,3.2,1],[5,3.15,1],[4,3.1,1],[3,3.05,1],[2,3,28.12],[1,2.96,1]],"id":71121948}]},{"id":"1.260191305","rc":[{"batb":[[9,8.2,4],[8,8.4,4],[7,8.6,4],[6,8.8,13.01],[5,9.6,11.17],[4,10,22.41],[3,11,4.91],[2,11.5,4],[1,12,1]],"id":49548036},{"batb":[[9,15,3.57],[8,15.5,16.74],[7,17,3.12],[6,17.5,3.03],[5,18,2.94],[4,18.5,14.38],[3,19.5,2.7],[2,20,2.63],[1,21,1],[0,22,5.12]],"id":43568336},{"batb":[[8,1.01,1154.26],[7,1.02,12],[6,1.16,100],[5,2.5,51.21],[4,2.62,124.48],[3,2.66,41.02],[2,2.68,2],[1,2.7,1]],"id":38858883},{"batb":[[8,1.01,1154.26],[7,1.02,12],[6,1.16,100],[5,1.51,98.04],[4,2.12,44.87],[3,80,2.6],[2,85,2.6],[1,110,1],[0,120,3.2]],"id":50889685},{"batb":[[9,1.01,1154.26],[8,1.02,12],[7,1.16,100],[6,1.51,98.04],[5,3.15,39.72],[4,3.3,87.68],[3,3.4,28.71],[2,3.45,2],[1,3.5,1]],"id":46065793},{"batb":[[9,21,2.5],[8,22,5.75],[7,25,2.08],[6,26,2],[5,27,1.92],[4,28,9.32],[3,30,1.72],[2,32,1.61],[1,34,1]],"id":47095286}]}]}{"op":"mcm","clk":"ALsKAM8GAMIF","pt":1784528013620,"mc":[{"id":"1.260137374","rc":[{"batb":[[1,85,2.14],[0,95,2.8]],"id":100720597}]}]}{"op":"mcm","clk":"ALsKANIGAMYF","pt":1784528013678,"mc":[{"id":"1.260192491","rc":[{"batb":[[9,6.2,9.62],[8,12.5,1.04],[7,16,3],[6,17,1.04],[5,21,1.04],[4,30,2.29],[3,50,1.02]],"id":60010414}]}]}{"op":"mcm","clk":"AMIKANgGAMgF","pt":1784528013823,"mc":[{"id":"1.260136666","rc":[{"batl":[[9,29,1.5]],"id":91807545}]}]}{"op":"mcm","clk":"AMkKAN8GAM4F","pt":1784528014029,"mc":[{"id":"1.260136666","rc":[{"batl":[[9,18.5,16.14]],"id":91807545}]}]}{"op":"mcm","clk":"ANMKAOIGANEF","pt":1784528014132,"mc":[{"id":"1.260136589","rc":[{"batl":[[4,20,2]],"id":41749902}]}]}{"op":"mcm","clk":"ANcKAOQGANIF","pt":1784528014234,"mc":[{"id":"1.260136589","rc":[{"batl":[[3,19.5,12.67]],"id":41749902}]}]}{"op":"ocm","id":1,"clk":"AOsCAOsDAMwEAP0FAO0C","pt":1784528014289,"ct":"HEARTBEAT"}{"op":"mcm","clk":"ANsKAOwGANgF","pt":1784528014489,"mc":[{"id":"1.260192334","rc":[{"batb":[[9,6.4,2],[8,6.6,3.04],[7,6.8,36.77],[6,7,16.2],[5,7.2,1],[4,7.8,12.71],[3,8,12.42],[2,8.8,1.04],[1,9,2]],"id":73793682}]}]}{"op":"mcm","clk":"ANsKAO4GANgF","pt":1784528014537,"mc":[{"id":"1.260136658","rc":[{"batb":[[2,15.5,11.98]],"id":98996178}]}]}{"op":"mcm","clk":"AN4KAPEGANsF","pt":1784528014640,"mc":[{"id":"1.260136666","rc":[{"batl":[[9,36,23.06]],"id":74901081}]},{"id":"1.260136658","rc":[{"batb":[[1,16,7.56]],"id":98996178},{"trd":[[1.9,55.61]],"batb":[[9,1.76,20.76],[8,1.78,151.41],[7,1.8,10.38],[6,1.81,18.17],[5,1.82,10.38],[4,1.83,10.38],[3,1.84,10.38],[2,1.85,88.9],[1,1.86,31.82],[0,1.89,19.8]],"batl":[[9,2.12,14.78],[8,2.08,10.38],[7,2.04,71.85],[6,1.98,184.79],[5,1.97,18.18],[4,1.94,19.3],[3,1.93,140.94],[2,1.92,24.59],[1,1.91,72.31],[0,1.9,2.61]],"ltp":1.9,"tv":1765.11,"id":5547183}],"tv":2595.58}]}{"op":"mcm","clk":"AOMKAPUGAN0F","pt":1784528014695,"mc":[{"id":"1.260192493","rc":[{"batb":[[9,1.53,16.14],[8,1.77,81.38],[7,1.84,1],[6,1.86,234.49],[5,1.88,1],[4,1.9,2],[3,1.91,95.98],[2,1.92,74.64],[1,1.93,5.18],[0,1.94,2]],"id":100748333}]}]}{"op":"mcm","clk":"AOYKAPcGAN0F","pt":1784528014741,"mc":[{"id":"1.260136658","rc":[{"batb":[[0,1.87,5.89]],"id":5547183},{"batb":[[9,16,5.5],[8,16.5,3.87],[7,17,5.32],[6,17.5,3.64],[5,18,9.68],[4,18.5,4.19],[3,19,1.79],[2,19.5,3.22],[1,20,2.61],[0,21,3.53]],"id":80934312}]}]}{"op":"mcm","clk":"AO4KAPsGAOEF","pt":1784528014845,"mc":[{"id":"1.260136658","rc":[{"trd":[[17.5,0.35]],"batl":[[9,25,4.15],[8,24,4.13],[7,23,6.49],[6,22,4.99],[5,21,2.99],[4,20,2.99],[3,19.5,2.99],[2,19,1],[1,18.5,1],[0,18,7.43]],"ltp":17.5,"tv":108.25,"id":56407176},{"trd":[[18,3.5],[18.5,0.23]],"batl":[[0,18.5,2.51]],"ltp":18.5,"tv":40.43,"id":98996178},{"trd":[[280,0.1]],"batl":[[0,470,2.53]],"tv":0.11,"id":78977433},{"trd":[[29,0.21]],"batl":[[0,29,1.83]],"ltp":29,"tv":31.46,"id":6690508},{"trd":[[8.8,7.93]],"batl":[[9,12.5,1.9],[8,12,2.87],[7,11.5,2.9],[6,11,4.29],[5,10.5,12.56],[4,10,2],[3,9.8,5.81],[2,9.6,1.62],[1,9.2,1.5],[0,9,2.13]],"tv":71.53,"id":100749630},{"trd":[[1.87,14.02],[1.88,1.05]],"batb":[[9,1.72,54.67],[8,1.76,20.76],[7,1.78,151.41],[6,1.8,10.38],[5,1.81,18.17],[4,1.82,10.38],[3,1.83,10.38],[2,1.84,10.38],[1,1.85,88.9],[0,1.86,31.82]],"batl":[[9,2.08,10.38],[8,2.04,71.85],[7,1.98,184.79],[6,1.97,18.18],[5,1.94,19.3],[4,1.93,140.94],[3,1.92,24.59],[2,1.91,72.31],[1,1.9,2.61],[0,1.89,5.78]],"ltp":1.87,"tv":1780.18,"id":5547183},{"trd":[[65,0.09]],"batl":[[0,65,3.76]],"ltp":65,"tv":52.51,"id":69865836},{"trd":[[460,0.01]],"batl":[[0,470,1.05]],"ltp":460,"tv":4.77,"id":69161915},{"trd":[[22,3.24]],"batl":[[0,23,28.92]],"ltp":22,"tv":153.8,"id":80934312},{"trd":[[190,0.16]],"batl":[[0,260,1.07]],"tv":10.65,"id":99951973},{"trd":[[8,79.12]],"batl":[[0,8,1.4]],"ltp":8,"tv":343.9,"id":79455963},{"trd":[[95,2.48]],"batl":[[0,130,1.69]],"tv":15.93,"id":74493797}],"tv":2613.52}]}{"op":"mcm","clk":"APQKAP8GAOMF","pt":1784528014947,"mc":[{"id":"1.260136658","rc":[{"batl":[[9,440,2.12],[8,250,10],[7,200,2],[6,130,1.81],[5,65,11.17],[4,36,2.03],[3,34,1.42],[2,32,1.42]],"id":6690508},{"batb":[[9,1.76,20.76],[8,1.78,151.41],[7,1.8,10.38],[6,1.81,18.17],[5,1.82,10.38],[4,1.83,10.38],[3,1.84,10.38],[2,1.85,88.9],[1,1.86,31.82],[0,1.87,6.27]],"batl":[[9,2.12,14.78],[8,2.08,10.38],[7,2.04,71.85],[6,1.98,184.79]],"id":5547183},{"batb":[[9,5.9,2.45],[8,6,19.83],[7,6.2,13.54],[6,6.4,22.26],[5,6.6,19.81],[4,6.8,29.78],[3,7,21.17],[2,7.2,3.96],[1,7.4,10.7],[0,7.6,1.7]],"id":79455963},{"batl":[[9,650,1],[8,640,1],[7,630,1],[6,620,1],[5,610,1],[4,600,11.02],[3,370,1.47],[2,180,1.18]],"id":74493797}]}]}{"op":"mcm","clk":"APkKAIIHAOcF","pt":1784528015051,"mc":[{"id":"1.260136658","rc":[{"trd":[[1.89,1.96]],"batl":[[0,1.89,4.8]],"ltp":1.89,"tv":1782.14,"id":5547183}],"tv":2615.48}]}{"op":"mcm","clk":"AP4KAIYHAOkF","pt":1784528015107,"mc":[{"id":"1.260136666","rc":[{"batl":[[9,0,0],[8,920,2.1],[7,610,1],[6,600,13.1],[5,590,3.6],[4,440,2.12],[3,210,1.16]],"id":88111702}]}]}{"op":"mcm","clk":"AIULAIwHAO8F","pt":1784528015309,"mc":[{"id":"1.260136666","rc":[{"batl":[[2,140,17.59]],"id":88111702}]},{"id":"1.260136658","rc":[{"batl":[[2,19.5,5.42]],"id":98996178},{"batl":[[9,2.18,25.95]],"id":5547183},{"batl":[[5,28,2]],"id":80934312}]}]}{"op":"mcm","clk":"AIoLAJAHAO8F","pt":1784528015411,"mc":[{"id":"1.260136658","rc":[{"trd":[[1.89,2.48]],"batl":[[0,1.89,4.54]],"tv":1782.66,"id":5547183}],"tv":2616}]}{"op":"mcm","clk":"AJULAJcHAPMF","pt":1784528015614,"mc":[{"id":"1.260136666","rc":[{"batb":[[8,13.5,4]],"id":82344583}]}]}{"op":"mcm","clk":"AJsLAJsHAPQF","pt":1784528015714,"mc":[{"id":"1.260136666","rc":[{"batb":[[7,14,13.57]],"id":82344583}]},{"id":"1.260136658","rc":[{"batl":[[5,920,2.1],[4,600,12.1],[3,440,2.13],[2,260,1.01],[1,85,2.52]],"id":69865836}]}]}{"op":"mcm","clk":"AK4LAKcHAPoF","pt":1784528016022,"mc":[{"id":"1.260137374","rc":[{"batb":[[9,1.05,23.9]],"id":99274452},{"batb":[[9,30,2],[8,38,2]],"id":100720597}]},{"id":"1.260136666","rc":[{"batb":[[9,1.51,98.04],[8,2.12,44.64],[7,2.24,4.84],[6,2.74,3.45]],"id":91807545}]}]}{"op":"mcm","clk":"ALoLALAHAIAG","pt":1784528016228,"mc":[{"id":"1.260136666","rc":[{"batb":[[5,4,46.62]],"id":91807545}]}]}{"op":"mcm","clk":"AMoLAL4HAJMG","pt":1784528016498,"mc":[{"id":"1.260192493","rc":[{"batl":[[6,920,2.1],[5,620,1],[4,610,1],[3,600,10.99],[2,120,1]],"id":90296582},{"batb":[[3,1.91,96.98],[2,1.92,75.64]],"id":100748333}]}]}{"op":"mcm","clk":"ANALAMEHAJQG","pt":1784528016543,"mc":[{"id":"1.260137374","rc":[{"batb":[[9,38,2],[8,44,1.15],[7,46,1.11],[6,48,1.27],[5,50,7.82],[4,55,1]],"id":100720597}]},{"id":"1.260136666","rc":[{"batb":[[9,3.05,24.39],[8,3.1,2.86],[7,3.9,2.07],[6,5.3,30.32]],"id":74901081}]}]}{"op":"mcm","clk":"ANwLANEHAJ0G","pt":1784528016745,"mc":[{"id":"1.260136666","rc":[{"batb":[[9,3.1,2.86],[8,3.9,2.07],[7,5.3,30.32],[6,6.4,16.14]],"id":74901081}]}]}{"op":"mcm","clk":"AIsMAPIHAKcG","pt":1784528017415,"mc":[{"id":"1.260136658","rc":[{"batl":[[9,2.24,1],[8,2.18,25.95],[7,2.08,10.38],[6,2.04,71.85],[5,1.98,184.79],[4,1.94,19.3],[3,1.93,140.94],[2,1.92,24.59],[1,1.91,72.31]],"id":5547183}]}]}{"op":"mcm","clk":"AJQMAPYHAKwG","pt":1784528017517,"mc":[{"id":"1.260136658","rc":[{"batl":[[0,1.9,6.35]],"id":5547183}]}]}{"op":"mcm","clk":"ALcMAJMIAMAG","pt":1784528018134,"mc":[{"id":"1.260136658","rc":[{"batb":[[9,11.5,12.7],[8,12,18.16],[7,12.5,23.63],[6,13,27.75],[5,13.5,8.79],[4,14,8.34],[3,14.5,8.71],[2,15,2.4],[1,15.5,1.45],[0,16,3.5]],"batl":[[6,22,2.99]],"id":56407176},{"batl":[[9,27,1],[8,26,1],[7,25,1.85],[6,24,2.85],[5,23,1.74],[4,22,2.74],[3,21,3.17],[2,20,8.93]],"id":98996178},{"batl":[[9,600,12.1],[8,440,2.12],[7,250,10],[6,200,2],[5,130,1.81],[4,65,11.17],[3,36,2.03],[2,34,1.42],[1,32,3.94]],"id":6690508},{"batb":[[0,46,2]],"id":69865836},{"batl":[[1,510,2]],"id":69161915}]}]}{"op":"mcm","clk":"ALwMAJYIAMEG","pt":1784528018238,"mc":[{"id":"1.260136658","rc":[{"batb":[[9,12.5,23.63],[8,13,27.75],[7,13.5,8.79],[6,14,8.34],[5,14.5,8.71],[4,15,2.4],[3,15.5,1.45],[2,16,3.5],[1,16.5,1.06],[0,17,1.53]],"id":56407176},{"batb":[[9,6.2,15.54],[8,6.4,35.82],[7,6.6,14.71],[6,6.8,21.31],[5,7,17.01],[4,7.2,30.05],[3,7.4,12.11],[2,7.6,2.67],[1,7.8,2.52],[0,8.4,3.09]],"id":100749630},{"batl":[[0,65,4.63]],"id":69865836},{"trd":[[23,0.04]],"batl":[[0,23,28.9]],"ltp":23,"tv":153.84,"id":80934312},{"batl":[[0,8,4.64]],"id":79455963},{"batl":[[9,640,1],[8,630,1],[7,620,1],[6,610,1],[5,600,11.02],[4,370,1.47],[3,180,1.18],[2,150,2.15],[1,130,1.49],[0,110,1.14]],"id":74493797}],"tv":2616.04}]}{"op":"mcm","clk":"AMEMAJkIAMYG","pt":1784528018336,"mc":[{"id":"1.260136658","rc":[{"batb":[[4,15,6.69]],"batl":[[0,18,6.78]],"id":56407176},{"trd":[[8.8,9.49]],"batb":[[2,7.6,11.76]],"batl":[[9,14,1],[8,12.5,1.9],[7,12,2.87],[6,11.5,2.9],[5,11,4.29],[4,10.5,12.56],[3,10,2],[2,9.8,5.81],[1,9.6,1.62],[0,9.2,1.5]],"tv":73.09,"id":100749630},{"batl":[[3,180,1.33],[2,130,1.31],[1,120,1.12],[0,100,2.2]],"id":74493797}],"tv":2617.6}]}{"op":"mcm","clk":"AMUMAJ0IAMkG","pt":1784528018436,"mc":[{"id":"1.260136658","rc":[{"batl":[[0,18,5.28]],"id":56407176},{"batb":[[9,6.2,4],[0,8.4,4.1]],"batl":[[0,9,2]],"id":100749630}]}]}{"op":"mcm","clk":"AMkMAKEIAMoG","pt":1784528018541,"mc":[{"id":"1.260136658","rc":[{"batl":[[1,18.5,2.01]],"id":56407176},{"batl":[[9,14.5,1],[8,14,1],[7,12.5,1.9],[6,12,2.87],[5,11.5,4.9],[4,11,4.29],[3,10.5,12.56],[2,10,2],[1,9.8,5.81],[0,9.6,1.62]],"id":100749630},{"batb":[[9,28,5.96],[8,29,4.75],[7,30,4.68],[6,32,9.16],[5,34,4.56],[4,36,5.73],[3,38,1],[2,40,1.45],[1,44,1.48]],"id":69865836},{"batl":[[0,8,6.35]],"id":79455963}]}]}{"op":"mcm","clk":"AM4MAKYIAM8G","pt":1784528018646,"mc":[{"id":"1.260136658","rc":[{"batb":[[3,7,10]],"id":79455963}]}]}{"op":"mcm","clk":"ANAMAKgIANQG","pt":1784528018744,"mc":[{"id":"1.260136658","rc":[{"batl":[[9,15,1],[8,14.5,1],[7,14,1],[6,12.5,1.9],[5,12,2.87],[4,11.5,4.9],[3,11,4.29],[2,10.5,12.56],[1,10,2],[0,9.8,5.81]],"id":100749630}]}]}{"op":"ocm","id":1,"clk":"ALYDAOUEAL4FAIsHALwD","pt":1784528019289,"ct":"HEARTBEAT"}{"op":"mcm","clk":"APUMAMwIAOUG","pt":1784528019424,"mc":[{"id":"1.260136658","rc":[{"batl":[[0,9.8,4.08]],"id":100749630}]}]}{"op":"mcm","clk":"AP0MANEIAOcG","pt":1784528019520,"mc":[{"id":"1.260136658","rc":[{"batl":[[2,790,0.25],[1,470,2.02],[0,380,1.55]],"id":78977433},{"batb":[[9,6.4,35.82],[8,6.6,14.71],[7,6.8,21.31],[6,7,17.01],[5,7.2,30.05],[4,7.4,12.11],[3,7.6,11.76],[2,7.8,2.42],[1,8,1.81]],"id":100749630}]}]}{"op":"mcm","clk":"AIINANcIAOgG","pt":1784528019618,"mc":[{"id":"1.260136658","rc":[{"batl":[[2,790,0.27],[1,380,1.1],[0,320,2.45]],"id":78977433}]}]}{"op":"mcm","clk":"AIkNANwIAOoG","pt":1784528019717,"mc":[{"id":"1.260136658","rc":[{"batl":[[4,370,1.05],[3,220,1.01],[2,160,1.01]],"id":74493797}]}]}{"op":"mcm","clk":"AIwNAN0IAOsG","pt":1784528019767,"mc":[{"id":"1.260192334","rc":[{"batl":[[1,100,1.74]],"id":59735573},{"batl":[[1,100,1.74]],"id":12747055}]}]}{"op":"mcm","clk":"AJINAOEIAO4G","pt":1784528019875,"mc":[{"id":"1.260192334","rc":[{"batl":[[0,44,11.53]],"id":21163447},{"batl":[[0,44,11.53]],"id":59735573},{"batl":[[0,44,11.53]],"id":12747055}]}]}{"op":"mcm","clk":"AJMNAOQIAO4G","pt":1784528019922,"mc":[{"id":"1.260136658","rc":[{"batl":[[3,11,5.99]],"id":100749630}]}]}{"op":"mcm","clk":"AJYNAOcIAPAG","pt":1784528019976,"mc":[{"id":"1.260192340","rc":[{"batb":[[0,8.4,3.19]],"id":62688374}]}]}{"op":"mcm","clk":"AJwNAO0IAPQG","pt":1784528020082,"mc":[{"id":"1.260192334","rc":[{"batl":[[1,100,1.74]],"id":21163447}]}]}{"op":"mcm","clk":"APQNAK0JAKMH","pt":1784528021515,"mc":[{"id":"1.260136658","rc":[{"batb":[[9,17,18.57],[8,17.5,12.23],[7,18,9.04],[6,18.5,5.54],[5,19,8.07],[4,19.5,5.7]],"id":6690508}]}]}{"op":"mcm","clk":"AIgOALYJAK8H","pt":1784528021825,"mc":[{"id":"1.260136658","rc":[{"batb":[[9,12.5,14.82]],"id":56407176},{"batb":[[7,13,7.95]],"id":98996178}]}]}{"op":"mcm","clk":"AI0OALwJALAH","pt":1784528021926,"mc":[{"id":"1.260136666","rc":[{"batb":[[9,2.12,44.64],[8,2.14,4.67],[7,3.05,24.39],[6,4.1,16.13],[5,4.6,2.88],[4,6.2,9.62],[3,16,3],[2,60,4.67],[1,160,1.11]],"batl":[[1,1000,41.53]],"id":74300318}]}]}{"op":"mcm","clk":"AJQOAL4JALMH","pt":1784528022029,"mc":[{"id":"1.260137374","rc":[{"batb":[[9,19.5,2.7],[8,20,2.63],[7,21,2.5],[6,22,2.38],[5,23,8.15],[4,24,2.17],[3,25,2.08]],"batl":[[0,210,2]],"id":100720598}]}]}{"op":"mcm","clk":"AKAOAMgJAL0H","pt":1784528022297,"mc":[{"id":"1.260137374","rc":[{"batl":[[2,0,0],[1,600,10.02],[0,300,3]],"id":100720598}]}]}{"op":"mcm","clk":"AKgOAMwJAL8H","pt":1784528022402,"mc":[{"id":"1.260137374","rc":[{"batl":[[5,21,1],[4,19,12.05],[3,18,11.17],[2,16.5,11.17],[1,16,4.18]],"id":25417481}]}]}{"op":"mcm","clk":"ALIOANQJAMIH","pt":1784528022600,"mc":[{"id":"1.260136666","rc":[{"batb":[[9,1.51,98.04],[8,2.12,44.64],[7,2.14,4.67],[6,3.05,24.39],[5,4.1,16.13],[4,4.6,2.88],[3,6.2,9.62],[2,16,3.36]],"id":74300318}]}]}{"op":"mcm","clk":"ALQOANkJAMMH","pt":1784528022694,"mc":[{"id":"1.260136666","rc":[{"batb":[[9,2.12,44.64],[8,2.14,4.67],[7,3.05,24.39],[6,4.1,16.13],[5,4.6,2.88],[4,6.2,9.62],[3,16,3.61],[2,70,4.67]],"id":74300318}]}]}{"op":"mcm","clk":"ALoOAN4JAMYH","pt":1784528022800,"mc":[{"id":"1.260136666","rc":[{"batb":[[9,1.51,98.04],[8,2.12,44.64]],"id":74300318}]}]}{"op":"mcm","clk":"ANUOAP8JANUH","pt":1784528023411,"mc":[{"id":"1.260137374","rc":[{"batb":[[9,20,2.63],[8,21,2.5],[7,22,2.38],[6,23,8.15],[5,24,2.17],[4,25,2.08],[3,26,2]],"id":100720598}]}]}{"op":"mcm","clk":"ANUOAIEKANUH","pt":1784528023412,"mc":[{"id":"1.260192495","rc":[{"batb":[[9,1.02,12],[8,1.16,100],[7,1.51,98.04],[6,2.12,44.64],[5,3.05,24.39],[4,4.1,16.13],[3,4.6,2.88],[2,6.2,9.85],[1,120,5.29],[0,130,1.51]],"id":25695674},{"batb":[[9,2.06,4],[8,2.08,4],[7,2.1,1],[6,2.12,45.64],[5,3.05,24.39],[4,4.1,16.13],[3,4.6,2.88],[2,6.2,9.85],[1,120,5.29],[0,130,1.51]],"id":38138891}]}]}{"op":"mcm","clk":"ANYOAIYKANcH","pt":1784528023509,"mc":[{"id":"1.260192495","rc":[{"batb":[[9,1.16,100],[8,1.51,98.04],[7,2.12,44.64],[6,3.05,24.39],[5,4.1,16.13],[4,4.6,2.88],[3,6.2,9.85],[2,120,5.29],[1,130,1],[0,160,1.26]],"id":25695674},{"batb":[[9,2.08,4],[8,2.1,1],[7,2.12,45.64],[6,3.05,24.39],[5,4.1,16.13],[4,4.6,2.88],[3,6.2,9.85],[2,120,5.29],[1,130,1],[0,160,1.26]],"id":38138891}]},{"id":"1.260192493","rc":[{"batl":[[0,100,5.22]],"id":90296582},{"batb":[[9,19,1],[8,19.5,3.74],[7,20,2.63],[6,21,18.64],[5,22,11.98],[4,23,2.27],[3,24,3.21],[2,25,8.12],[1,26,1],[0,27,5.68]],"id":100748336},{"batb":[[9,34,6.29],[8,36,1],[7,38,1.35],[6,40,16.14],[5,42,1.22],[4,44,5.84],[3,46,4.13],[2,48,1.27],[1,50,1.02]],"id":44387351}]}]}{"op":"mcm","clk":"ANoOAIgKANkH","pt":1784528023514,"mc":[{"id":"1.260136658","rc":[{"batb":[[9,17.5,12.23],[8,18,9.04],[7,18.5,5.54],[6,19,8.07],[5,19.5,5.7],[4,20,2],[3,21,3.16]],"batl":[[9,200,2],[8,130,1.81],[7,65,11.17],[6,42,1],[5,40,1],[4,38,1]],"id":6690508},{"batl":[[9,14,1],[8,13.5,1],[7,13,1]],"id":100749630},{"batb":[[9,29,4.75],[8,30,4.68],[7,32,9.16],[6,34,4.56],[5,36,5.73],[4,38,1],[3,40,2.73],[2,42,1.22]],"batl":[[6,920,2.1],[5,600,12.1],[4,440,2.9],[3,100,1],[2,95,1.24]],"id":69865836},{"batl":[[4,370,1.47],[3,180,1.33],[2,130,1.27]],"id":74493797}]}]}{"op":"mcm","clk":"AOEOAIsKANsH","pt":1784528023618,"mc":[{"id":"1.260137374","rc":[{"batb":[[8,21,16.64],[1,28,7]],"batl":[[0,300,3.96]],"id":100720598}]}]}{"op":"mcm","clk":"AOEOAI0KANsH","pt":1784528023620,"mc":[{"id":"1.260136666","rc":[{"batb":[[9,2.12,44.64],[8,3.05,24.39],[7,4.1,16.13],[6,4.6,2.88],[5,6.2,9.62],[4,16,3.61],[3,70,4.31],[2,120,2.72],[1,170,1.49]],"batl":[[1,1000,41.79]],"id":74300318}]},{"id":"1.260136658","rc":[{"batb":[[9,12.5,23.63]],"id":56407176},{"batb":[[6,13.5,15.84]],"id":98996178},{"batb":[[9,16,8.73]],"id":80934312}]}]}{"op":"mcm","clk":"AOQOAJEKAN8H","pt":1784528023716,"mc":[{"id":"1.260192491","rc":[{"batb":[[9,12.5,1.04],[8,16,3],[7,17,1.04],[6,21,1.04],[5,30,2.29],[4,48,1.06],[1,90,3.98]],"id":60010414},{"batb":[[0,44,3.23]],"batl":[[0,1000,4.3]],"id":91496756}]}]}{"op":"mcm","clk":"AOcOAJMKAN8H","pt":1784528023722,"mc":[{"id":"1.260136658","rc":[{"batl":[[6,0,0],[5,920,2.1],[4,600,12.1],[3,440,2.9],[2,100,1],[1,95,1.66]],"id":69865836}]}]}{"op":"mcm","clk":"AOsOAJkKAOAH","pt":1784528023821,"mc":[{"id":"1.260137374","rc":[{"batb":[[9,21,16.64],[8,22,2.38],[7,23,8.15],[6,24,2.17],[5,25,2.08],[4,26,2],[3,27,1.92],[2,28,6.06],[1,29,1.44],[0,30,5.85]],"id":100720598}]}]}{"op":"mcm","clk":"APIOAKMKAOIH","pt":1784528023978,"mc":[{"id":"1.260136658","rc":[{"batb":[[9,17,18.57],[8,17.5,12.23],[7,18,9.04],[6,18.5,5.54],[5,19,8.07],[4,19.5,5.7],[3,20,2.66]],"batl":[[9,600,12.1],[8,440,2.12],[7,250,10],[6,200,2],[5,130,1.81],[4,65,11.17]],"id":6690508},{"batb":[[9,28,5.96],[8,29,4.75],[7,30,4.68],[6,32,9.16],[5,34,4.56],[4,36,5.73],[3,38,1],[2,40,1.45]],"batl":[[5,0,0],[4,920,2.1],[3,600,12.1],[2,440,2.13],[1,260,1.43]],"id":69865836},{"batl":[[4,370,1.05],[3,220,1.01],[2,160,1.01]],"id":74493797}]}]}{"op":"mcm","clk":"AP4OAK8KAOYH","pt":1784528024188,"mc":[{"id":"1.260136658","rc":[{"batl":[[2,25,2.31]],"id":80934312}]},{"id":"1.260192491","rc":[{"batb":[[9,6.2,9.62],[8,12.5,1.04],[7,16,3],[6,17,1.04],[5,21,1.04],[4,30,2.29],[3,48,1.06]],"id":60010414},{"batl":[[9,3.7,63.65],[8,3.4,45.13],[7,3.3,1],[6,3.25,1],[5,3.2,1],[4,3.15,1],[3,3.1,1],[2,3.05,1],[1,3,28.12]],"id":71121948}]}]}{"op":"mcm","clk":"AIIPALQKAOcH","pt":1784528024283,"mc":[{"id":"1.260136658","rc":[{"batl":[[1,24,14.25]],"id":80934312}]}]}{"op":"ocm","id":1,"clk":"AP0DAOIFAL4GAKUIAJkE","pt":1784528024289,"ct":"HEARTBEAT"}{"op":"mcm","clk":"AI8PALsKAO8H","pt":1784528024605,"mc":[{"id":"1.260136658","rc":[{"batl":[[9,14.5,1],[8,14,1],[7,13.5,1],[6,13,1],[5,12.5,1.9],[4,12,2.87],[3,11.5,4.9],[2,11,5.99],[1,10.5,12.56],[0,10,2]],"id":100749630}]}]}{"op":"mcm","clk":"AJAPAL4KAPEH","pt":1784528024688,"mc":[{"id":"1.260192491","rc":[{"batb":[[9,12.5,1.04],[8,16,3],[7,17,1.04],[6,21,1.04],[5,30,2.29],[4,48,1.06],[3,55,3.24]],"id":60010414}]}]}{"op":"mcm","clk":"AJIPAMIKAPQH","pt":1784528024697,"mc":[{"id":"1.260136658","rc":[{"batl":[[0,10,6.08]],"id":100749630}]}]}{"op":"mcm","clk":"AJcPAMUKAPoH","pt":1784528024798,"mc":[{"id":"1.260136658","rc":[{"batl":[[9,14,1],[8,13.5,1],[7,13,1],[6,12.5,1.9],[5,12,2.87],[4,11.5,4.9],[3,11,5.99],[2,10.5,12.56],[1,10,6.08],[0,9.8,1.5]],"id":100749630}]}]}{"op":"mcm","clk":"AJwPAMoKAP8H","pt":1784528024943,"mc":[{"id":"1.260136658","rc":[{"batl":[[9,14.5,1],[8,14,1],[7,13.5,1],[6,13,1],[5,12.5,1.9],[4,12,2.87],[3,11.5,4.9],[2,11,5.99],[1,10.5,12.56],[0,10,6.08]],"id":100749630}]}]}{"op":"mcm","clk":"AKAPANEKAIII","pt":1784528025045,"mc":[{"id":"1.260136658","rc":[{"batb":[[2,16,5]],"id":56407176}]}]}{"op":"mcm","clk":"AKIPANQKAIcI","pt":1784528025104,"mc":[{"id":"1.260136658","rc":[{"batl":[[2,0,0],[1,580,1.08],[0,270,2.61]],"id":99951973}]}]}{"op":"mcm","clk":"AKgPANsKAIoI","pt":1784528025225,"mc":[{"id":"1.260136658","rc":[{"batl":[[2,580,1.08],[1,270,2],[0,260,1.07]],"id":99951973}]}]}{"op":"mcm","clk":"AKgPAN0KAIwI","pt":1784528025304,"mc":[{"id":"1.260192491","rc":[{"batb":[[9,6.2,9.62],[8,12.5,1.04],[7,16,3],[6,17,1.04],[5,21,1.04],[4,30,2.29],[1,90,2.98]],"id":60010414},{"batb":[[0,44,2.23]],"batl":[[0,1000,3.3]],"id":91496756}]}]}{"op":"mcm","clk":"AK8PAOQKAJQI","pt":1784528025415,"mc":[{"id":"1.260136589","rc":[{"batl":[[4,20,1],[3,19.5,13.67]],"id":41749902}]}]}{"op":"mcm","clk":"ALUPAOkKAJ4I","pt":1784528025612,"mc":[{"id":"1.260191305","rc":[{"batb":[[8,0,0],[7,1.01,1154.26],[6,1.02,12],[5,1.16,100],[4,1.51,98.04],[3,4.3,24.34],[2,4.6,73.2],[1,4.8,2.08]],"id":36955482}]}]}{"op":"mcm","clk":"ALwPAOoKAKAI","pt":1784528025714,"mc":[{"id":"1.260137374","rc":[{"batl":[[9,0,0],[8,920,2.1],[7,600,12.1],[6,440,2.12],[5,250,10],[1,16,5.18]],"id":25417481}]},{"id":"1.260191305","rc":[{"batb":[[8,1.01,1154.26],[7,1.02,12],[6,1.16,100],[5,1.51,98.04],[4,4.3,24.34],[3,4.6,73.2],[2,4.8,2.08],[1,5.1,21.08],[0,5.2,2]],"id":36955482}]}]}{"op":"mcm","clk":"ALwPAOwKAKAI","pt":1784528025715,"mc":[{"id":"1.260136658","rc":[{"batl":[[9,650,1],[8,640,1],[7,630,1],[6,620,1],[5,610,1],[4,600,11.02],[3,370,1.47],[2,180,1.33],[0,100,2.6]],"id":74493797}]}]}{"op":"mcm","clk":"AL8PAO4KAKII","pt":1784528025817,"mc":[{"id":"1.260191305","rc":[{"batb":[[8,0,0],[7,1.01,1154.26],[6,1.02,12],[5,1.16,100],[4,1.51,98.04],[3,2.12,44.87],[2,80,2.6],[1,85,2.6],[0,120,2.2]],"id":50889685},{"batb":[[9,18.5,7.9],[8,19.5,2.7],[7,20,2.63],[6,21,2.5],[5,22,5.75],[4,25,2.08],[3,26,2],[2,27,1.92],[1,28,9.32]],"id":47095286}]}]}{"op":"mcm","clk":"AOMPAIELALUI","pt":1784528026484,"mc":[{"id":"1.260192491","rc":[{"batb":[[3,55,4.24]],"id":60010414}]}]}{"op":"mcm","clk":"AOcPAIMLALYI","pt":1784528026493,"mc":[{"id":"1.260136658","rc":[{"batl":[[9,440,2.12],[8,250,10],[7,200,2],[6,130,1.81],[5,65,11.17],[4,38,1]],"id":6690508}]}]}{"op":"mcm","clk":"APMPAI8LALsI","pt":1784528026695,"mc":[{"id":"1.260136658","rc":[{"batb":[[9,6.4,24.3]],"id":100749630}]}]}{"op":"mcm","clk":"APgPAJMLAL0I","pt":1784528026798,"mc":[{"id":"1.260136658","rc":[{"batb":[[6,7,28.53]],"id":100749630}]}]}{"op":"mcm","clk":"APkPAJMLAL0I","pt":1784528026802,"mc":[{"id":"1.260136589","rc":[{"batb":[[8,19.5,2.7]],"id":85017109}]}]}{"op":"mcm","clk":"APsPAJULAMAI","pt":1784528026893,"mc":[{"id":"1.260136658","rc":[{"batl":[[9,600,12.1],[8,440,2.12],[7,250,10],[6,200,2],[5,130,1.81],[4,65,11.17]],"id":6690508}]}]}{"op":"mcm","clk":"AKYQAKILANEI","pt":1784528027610,"mc":[{"id":"1.260191305","rc":[{"batb":[[9,2.12,44.64],[8,8.2,4],[7,8.4,4],[6,8.6,4],[5,8.8,13.01]],"id":49548036},{"batb":[[8,15.5,8.35]],"id":43568336}]}]}{"op":"mcm","clk":"AKYQAKULANEI","pt":1784528027612,"mc":[{"id":"1.260136658","rc":[{"batb":[[4,15,14.67]],"id":56407176},{"batl":[[6,24,14.02]],"id":98996178}]}]}{"op":"mcm","clk":"AKsQAKcLANII","pt":1784528027709,"mc":[{"id":"1.260191305","rc":[{"batb":[[9,8.2,4],[8,8.4,4],[7,8.6,4],[6,8.8,13.01],[5,10,22.41],[4,10.5,11.17]],"id":49548036},{"batb":[[9,15,11.96]],"id":43568336}]}]}{"op":"mcm","clk":"AKsQAKkLANII","pt":1784528027714,"mc":[{"id":"1.260136658","rc":[{"batb":[[1,60,3.55]],"id":74493797}]}]}{"op":"mcm","clk":"AK0QAKoLANMI","pt":1784528027812,"mc":[{"id":"1.260136658","rc":[{"batb":[[9,40,1.28],[8,42,1.22],[7,44,2.91],[6,46,1.44],[5,48,1.06],[4,50,1.69],[3,55,1.31],[2,60,3.55],[1,70,1.33],[0,75,2.78]],"id":74493797}]}]}{"op":"mcm","clk":"ALIQAK4LANQI","pt":1784528027917,"mc":[{"id":"1.260136658","rc":[{"batb":[[9,26,9.21],[8,30,2],[7,38,5.83],[6,40,1.28],[5,44,1.76],[4,46,1]],"id":74493797}]}]}{"op":"mcm","clk":"ALQQALILANUI","pt":1784528028015,"mc":[{"id":"1.260136658","rc":[{"batb":[[9,16,3],[8,26,9.21],[7,30,2],[6,38,4.48]],"id":74493797}]}]}{"op":"mcm","clk":"ALcQALULANgI","pt":1784528028118,"mc":[{"id":"1.260136658","rc":[{"batb":[[9,29,4.75],[8,30,4.68],[7,32,9.16],[6,34,4.56],[5,36,1.43],[4,38,1],[3,40,1.45],[2,44,1.48],[1,46,2],[0,48,2.6]],"id":69865836}]}]}{"op":"mcm","clk":"AMYQAL8LANwI","pt":1784528028381,"mc":[{"id":"1.260136658","rc":[{"batl":[[3,11.5,5.9]],"id":100749630},{"batb":[[9,27,6.36],[8,28,5.96],[7,29,4.75],[6,30,4.68],[5,32,9.16],[4,34,4.56]],"id":69865836}]}]}{"op":"mcm","clk":"AN8QAMwLAOgI","pt":1784528028992,"mc":[{"id":"1.260192491","rc":[{"batl":[[0,390,4.51]],"id":43653174}]}]}{"op":"mcm","clk":"AOEQAM4LAOwI","pt":1784528029096,"mc":[{"id":"1.260192491","rc":[{"batl":[[2,900,2.85],[0,390,2.51]],"id":43653174}]}]}{"op":"mcm","clk":"AOQQANELAO4I","pt":1784528029194,"mc":[{"id":"1.260192491","rc":[{"batb":[[3,55,3.24]],"id":60010414}]}]}{"op":"ocm","id":1,"clk":"AMgEAKsGAKwHALEJANkE","pt":1784528029289,"ct":"HEARTBEAT"}{"op":"mcm","clk":"AOkQANULAPAI","pt":1784528029293,"mc":[{"id":"1.260192491","rc":[{"batl":[[2,900,0.85],[0,390,2.54]],"id":43653174}]}]}{"op":"mcm","clk":"AO4QANoLAPQI","pt":1784528029394,"mc":[{"id":"1.260192491","rc":[{"batl":[[2,900,2.85]],"id":43653174}]}]}{"op":"mcm","clk":"APEQANsLAPQI","pt":1784528029399,"mc":[{"id":"1.260136803","rc":[{"batb":[[9,2.14,16.14],[8,2.3,83.79],[7,2.44,9.01],[6,2.5,149.63],[5,2.64,65.97],[4,2.66,53.05],[3,2.7,4.84],[2,2.72,2.28],[1,2.76,11.23],[0,3.75,12.98]],"id":100721219}]}]}{"op":"mcm","clk":"APYQAN8LAPgI","pt":1784528029502,"mc":[{"id":"1.260136803","rc":[{"trd":[[3.8,4.16]],"batb":[[9,1.12,100],[8,2.14,16.14],[7,2.3,83.79]],"batl":[[9,34,15],[8,22,5.36],[7,18,3.05],[6,16,15],[5,8.4,5.82],[4,6.8,20.23],[3,6.2,69.3],[2,5.2,1.19],[1,5.1,16.14],[0,3.85,25.95]],"ltp":3.8,"tv":66.74,"id":100721219},{"batb":[[0,80,3.5]],"id":57883707}],"tv":373.57}]}{"op":"mcm","clk":"APoQAOQLAP0I","pt":1784528029609,"mc":[{"id":"1.260136658","rc":[{"batb":[[0,290,2.04]],"id":69161915},{"batb":[[3,19,8]],"id":80934312}]}]}{"op":"mcm","clk":"APwQAOcLAIEJ","pt":1784528029705,"mc":[{"id":"1.260136658","rc":[{"batb":[[2,110,2.73],[1,180,1.33]],"id":69161915}]}]}{"op":"mcm","clk":"AIIRAOoLAIQJ","pt":1784528029807,"mc":[{"id":"1.260137374","rc":[{"batl":[[9,920,2.1],[8,600,12.1],[7,440,2.12],[6,250,10],[5,19,12.05],[4,18,11.17],[3,16.5,11.17],[2,16,5.18],[1,15.5,1],[0,8,41.53]],"id":25417481}]}]}{"op":"mcm","clk":"AIIRAOsLAIYJ","pt":1784528029810,"mc":[{"id":"1.260136803","rc":[{"batb":[[1,100,1.43]],"id":100721224},{"batb":[[0,7.6,3.99]],"id":100721218}]}]}{"op":"mcm","clk":"AIcRAPELAIkJ","pt":1784528029912,"mc":[{"id":"1.260192493","rc":[{"batb":[[3,46,1.11]],"id":44387351}]}]}{"op":"mcm","clk":"AIcRAPILAIkJ","pt":1784528029914,"mc":[{"id":"1.260136803","rc":[{"batb":[[0,170,2.7]],"id":100721225},{"batb":[[9,1.01,1154.83],[8,1.02,22],[7,1.12,100],[6,2.14,16.14],[5,2.3,83.79],[4,2.5,149.63],[3,2.64,58.66],[2,2.66,53.05]],"id":100721219},{"batb":[[0,7.2,3.54]],"id":77728021}]}]}{"op":"mcm","clk":"AIgRAPILAIoJ","pt":1784528029916,"mc":[{"id":"1.260137374","rc":[{"batb":[[9,2.12,44.64],[8,2.38,4.35],[7,2.94,3.09],[6,5.2,2],[5,5.3,66.08],[4,5.4,27.71],[3,5.5,19.96],[2,6,24.36],[1,6.2,1.68],[0,6.4,3.47]],"batl":[[9,0,0],[8,920,2.1],[7,600,12.1],[6,440,2.12],[5,250,10],[4,19,12.05],[3,18,11.17],[2,16.5,11.17],[1,16,5.18]],"id":25417481}]}]}{"op":"mcm","clk":"AIgRAPQLAIoJ","pt":1784528030009,"mc":[{"id":"1.260192493","rc":[{"batb":[[1,50,4.04]],"id":44387351}]}]}{"op":"mcm","clk":"AIgRAPULAIsJ","pt":1784528030014,"mc":[{"id":"1.260136803","rc":[{"batb":[[9,3.45,2.45],[8,4.1,16.13],[7,4.9,11.44],[6,5.7,50.55],[5,5.8,16.14],[4,6.2,12.68]],"id":77728021}]}]}{"op":"mcm","clk":"AI4RAPoLAI4J","pt":1784528030114,"mc":[{"id":"1.260136658","rc":[{"batb":[[1,23,6.14]],"id":6690508}]}]}{"op":"mcm","clk":"AJgRAP4LAJEJ","pt":1784528030213,"mc":[{"id":"1.260192493","rc":[{"batb":[[9,32,1.61],[8,34,6.29],[7,36,1],[6,38,1.35],[5,40,16.14],[4,42,1.22],[3,44,5.84],[2,46,1.32],[1,50,3.02]],"id":44387351}]}]}{"op":"mcm","clk":"AKcRAIwMAJsJ","pt":1784528030521,"mc":[{"id":"1.260136658","rc":[{"batb":[[4,18.5,6.48]],"id":80934312}]}]}{"op":"mcm","clk":"AOgRAK0MAMsJ","pt":1784528031499,"mc":[{"id":"1.260137374","rc":[{"batl":[[9,920,2.1],[8,600,12.1],[7,440,2.12],[6,250,10],[5,19,12.05],[4,18,11.17],[3,16.5,11.17],[2,16,5.18],[1,8,41.53],[0,7.8,1.87]],"id":25417481}]}]}{"op":"mcm","clk":"APYRALkMANUJ","pt":1784528031805,"mc":[{"id":"1.260136803","rc":[{"batl":[[9,250,10],[8,65,2]],"id":100721218},{"batl":[[9,27,2]],"id":100721219}]}]}{"op":"mcm","clk":"AP4RALwMANsJ","pt":1784528031907,"mc":[{"id":"1.260137374","rc":[{"batb":[[9,1.67,3.24],[8,2.12,44.64],[7,2.38,4.35],[6,2.94,3.09],[5,5.2,2],[4,5.3,66.08],[3,5.4,27.71],[2,5.5,19.96],[1,6,24.36],[0,6.2,1.91]],"id":25417481}]},{"id":"1.260136803","rc":[{"batl":[[9,600,12.1],[8,440,2.12],[7,250,10],[6,100,2]],"id":77728021}]}]}{"op":"mcm","clk":"AK8SANgMAO0J","pt":1784528032878,"mc":[{"id":"1.260136658","rc":[{"batl":[[0,470,1.04]],"id":69161915}]}]}{"op":"mcm","clk":"ALoSAN4MAPEJ","pt":1784528033085,"mc":[{"id":"1.260136658","rc":[{"batl":[[7,23,7.49],[6,22,3.99],[5,21,3.99],[4,20,3.99]],"id":56407176}]}]}{"op":"mcm","clk":"AL8SAOEMAPEJ","pt":1784528033184,"mc":[{"id":"1.260136658","rc":[{"batl":[[0,18,6.78]],"id":56407176}]}]}{"op":"mcm","clk":"AMYSAOgMAPMJ","pt":1784528033392,"mc":[{"id":"1.260136666","rc":[{"batl":[[9,29,1.5]],"id":91807545}]}]}{"op":"mcm","clk":"AMoSAOgMAPYJ","pt":1784528033490,"mc":[{"id":"1.260137374","rc":[{"batb":[[1,23,2.66],[0,24,3.2]],"id":68064063}]}]}{"op":"mcm","clk":"AMoSAOoMAPcJ","pt":1784528033493,"mc":[{"id":"1.260136658","rc":[{"batb":[[9,17.5,12.23],[8,18,9.04],[7,18.5,5.54],[6,19,8.07],[5,19.5,5.7],[4,20,2],[3,21,3.16]],"batl":[[9,200,2],[8,130,1.81],[7,65,11.17],[6,42,1],[5,40,1],[4,38,1]],"id":6690508},{"batb":[[9,29,4.75],[8,30,4.68],[7,32,9.16],[6,34,4.56],[5,36,1.43],[4,38,1.35]],"batl":[[5,920,2.1],[4,600,12.1],[3,440,2.13],[2,260,1.01],[1,80,1.42]],"id":69865836},{"batb":[[9,40,1.28],[8,42,1.22],[7,44,2.91],[6,46,1.44],[5,48,1.06],[4,50,1.69]],"id":74493797}]},{"id":"1.260136803","rc":[{"batb":[[9,3.05,24.39],[8,4.1,16.13],[7,4.6,2.88],[6,6.2,9.62],[5,16,3.22],[4,90,3.21],[3,110,2.78],[2,150,2.99],[1,160,1.16],[0,170,3.7]],"id":100721225},{"batb":[[9,2.04,85.7],[8,2.06,4],[7,2.1,4]],"id":94448588},{"batb":[[9,16,3],[8,40,16.14],[7,42,4.33],[6,44,8.01],[5,46,1.11],[4,48,1.27],[3,50,2.18]],"id":57883707}]}]}{"op":"mcm","clk":"AM0SAOwMAPkJ","pt":1784528033588,"mc":[{"id":"1.260192491","rc":[{"batb":[[9,16,3],[8,17,1.04],[7,21,1.04],[6,30,2.29],[5,48,1.06],[4,50,1.02]],"id":60010414},{"batl":[[9,3.3,1],[8,3.25,1],[7,3.2,1],[6,3.15,1],[5,3.1,1],[4,3.05,1],[3,3,28.12],[2,2.96,1],[1,2.94,1]],"id":71121948}]}]}{"op":"mcm","clk":"ANASAPAMAPoJ","pt":1784528033596,"mc":[{"id":"1.260136666","rc":[{"batl":[[9,18,16.14]],"id":91807545}]}]}{"op":"mcm","clk":"ANESAPEMAPsJ","pt":1784528033690,"mc":[{"id":"1.260192491","rc":[{"batl":[[0,2.92,3.31]],"id":71121948}]}]}{"op":"mcm","clk":"ANUSAPUMAPwJ","pt":1784528033697,"mc":[{"id":"1.260136658","rc":[{"batl":[[9,28,1.06],[8,27,1],[7,26,1],[6,25,1.85],[5,24,14.02],[4,23,1.74],[3,22,2.74],[2,21,3.17],[1,20,8.93],[0,19,11.34]],"id":98996178}]}]}{"op":"mcm","clk":"ANkSAPkMAP0J","pt":1784528033798,"mc":[{"id":"1.260136658","rc":[{"batl":[[9,27,1],[8,26,1],[7,25,1.85],[6,24,14.02],[5,23,1.74],[4,22,2.74],[3,21,3.17],[2,20,8.93],[1,19,11.34],[0,18,1.56]],"id":98996178},{"batb":[[6,16,4.47]],"id":99951973}]}]}{"op":"mcm","clk":"AN4SAPwMAIAK","pt":1784528033903,"mc":[{"id":"1.260136666","rc":[{"batl":[[9,36,6.91]],"id":74901081}]},{"id":"1.260136658","rc":[{"batl":[[0,18,3.22]],"id":98996178}]}]}{"op":"mcm","clk":"AOYSAIQNAIcK","pt":1784528034211,"mc":[{"id":"1.260192491","rc":[{"batb":[[9,6.2,9.62],[8,12.5,1.04],[7,16,3],[6,17,1.04],[5,21,1.04],[4,30,2.29]],"id":60010414},{"batl":[[2,900,0.85],[0,390,4.54]],"id":43653174},{"batl":[[9,3.7,63.65],[8,3.4,45.13],[7,3.3,1],[6,3.25,1],[5,3.2,1],[4,3.15,1],[3,3.1,1],[2,3.05,1],[1,3,28.12]],"id":71121948}]}]}{"op":"ocm","id":1,"clk":"AIgFAOUGALcIAMMKAMYF","pt":1784528034289,"ct":"HEARTBEAT"}{"op":"mcm","clk":"APISAI0NAI4K","pt":1784528034513,"mc":[{"id":"1.260136666","rc":[{"batl":[[2,140,1.45]],"id":88111702}]},{"id":"1.260136658","rc":[{"batl":[[9,600,12.1],[8,440,2.12],[7,250,10],[6,200,2],[5,130,1.81],[4,65,11.17]],"id":6690508},{"batb":[[9,27,6.36],[8,28,5.96],[7,29,4.75],[6,30,4.68],[5,32,9.16],[4,34,4.56]],"batl":[[5,0,0],[4,920,2.1],[3,600,12.1],[2,440,2.13],[1,260,1.43]],"id":69865836},{"batb":[[9,16,3],[8,26,9.21],[7,30,2],[6,38,4.48],[5,44,1.76],[4,46,1]],"id":74493797}]}]}{"op":"mcm","clk":"AP8SAJINAJAK","pt":1784528034717,"mc":[{"id":"1.260136666","rc":[{"batl":[[9,920,2.1],[8,610,1],[7,600,13.1],[6,590,3.6],[5,440,2.12],[4,210,1.16],[3,150,16.14]],"id":88111702}]}]}{"op":"mcm","clk":"AJATAJ0NAJYK","pt":1784528035122,"mc":[{"id":"1.260192491","rc":[{"batl":[[0,2.92,2.31]],"id":71121948}]}]}{"op":"mcm","clk":"AJ8TAKcNAJwK","pt":1784528035380,"mc":[{"id":"1.260136666","rc":[{"batb":[[5,4,30.47]],"id":91807545}]}]}{"op":"mcm","clk":"AKETAKkNAJ8K","pt":1784528035480,"mc":[{"id":"1.260136658","rc":[{"trd":[[320,0.2],[300,1.38]],"batb":[[0,290,1.46]],"batl":[[3,1000,0.2],[2,510,2],[1,470,1.04],[0,300,2.02]],"ltp":300,"tv":5.92,"id":69161915}],"tv":2618.75}]}{"op":"mcm","clk":"AKcTAKsNAKEK","pt":1784528035582,"mc":[{"id":"1.260136666","rc":[{"batb":[[9,2.12,44.64],[8,2.24,4.84],[7,2.74,3.45],[6,3.95,16.14]],"id":91807545}]},{"id":"1.260136658","rc":[{"trd":[[290,5.37],[300,4.62]],"batb":[[9,1.01,1154.83],[8,1.02,73.91],[7,1.16,100],[6,1.51,98.04],[5,4.6,3.4],[4,16,3],[3,30,2.22],[2,75,3.46],[1,110,2.73],[0,180,1.33]],"batl":[[3,0,0],[2,0,0],[1,1000,0.2],[0,470,1.44]],"tv":12.87,"id":69161915}],"tv":2625.7}]}{"op":"mcm","clk":"AKoTAK4NAKYK","pt":1784528035685,"mc":[{"id":"1.260136658","rc":[{"batb":[[9,1.02,73.91],[8,1.16,100],[7,1.51,98.04],[6,4.6,3.4],[5,16,3],[4,30,2.22],[3,75,3.46],[2,110,2.73],[1,180,1.2],[0,280,2.13]],"batl":[[2,1000,0.2],[1,470,1.04],[0,460,2.77]],"id":69161915}]}]}{"op":"mcm","clk":"ALYTALgNAKsK","pt":1784528035899,"mc":[{"id":"1.260136658","rc":[{"batb":[[0,280,2.22]],"id":69161915}]}]}{"op":"mcm","clk":"ALcTALoNALAK","pt":1784528035989,"mc":[{"id":"1.260136666","rc":[{"batb":[[9,3.05,24.39],[8,3.1,2.86],[7,3.9,2.07],[6,5.3,30.32]],"id":74901081}]}]}{"op":"mcm","clk":"ALoTAL0NALIK","pt":1784528036093,"mc":[{"id":"1.260136658","rc":[{"batb":[[1,180,1.09],[0,280,2.09]],"batl":[[0,460,3]],"id":69161915}]}]}{"op":"mcm","clk":"AL8TAMANALcK","pt":1784528036194,"mc":[{"id":"1.260136666","rc":[{"batb":[[9,3.1,2.86],[8,3.9,2.07],[7,5.3,30.32],[6,6.6,16.14]],"id":74901081}]}]}{"op":"mcm","clk":"AM8TAMgNAMAK","pt":1784528036505,"mc":[{"id":"1.260136666","rc":[{"batb":[[9,15.5,3.45],[8,16,3.33],[7,19,15.34],[6,20,3.15],[5,21,9.77],[4,22,3.3],[3,24,1]],"id":88111702}]},{"id":"1.260136658","rc":[{"batb":[[4,20,3.99],[3,21,5.15],[2,22,4.55]],"batl":[[9,250,10],[8,200,2],[7,130,1.81],[6,65,11.17],[5,40,1.99],[4,38,2.99]],"id":6690508}]},{"id":"1.260136803","rc":[{"batb":[[9,4.1,16.13],[8,4.6,2.88],[7,6.2,9.62],[6,16,3.22],[5,90,3.21],[4,110,2.6],[3,140,1.18],[2,150,3.99]],"id":100721225},{"batb":[[3,36,6.76]],"id":100721221},{"batb":[[2,2.2,5]],"id":94448588},{"batb":[[9,40,16.14],[8,42,4.33],[7,44,8.01],[6,46,1.11],[5,48,1.27],[4,50,2.18],[3,55,4.46],[2,65,1],[1,70,3.72]],"id":57883707}]}]}{"op":"mcm","clk":"ANITAMkNAMAK","pt":1784528036509,"mc":[{"id":"1.260192491","rc":[{"batb":[[3,55,4.24]],"id":60010414}]}]}{"op":"mcm","clk":"ANkTAM0NAMIK","pt":1784528036604,"mc":[{"id":"1.260136658","rc":[{"batl":[[4,38,1.99]],"id":6690508}]},{"id":"1.260136803","rc":[{"batb":[[9,2.12,44.64],[8,3.05,24.39],[7,4.1,16.13],[6,4.6,2.88],[5,6.2,9.62],[4,16,3.22],[3,90,3.21],[2,110,2.78],[1,150,3.15],[0,170,2.7]],"id":100721225},{"batb":[[9,6.2,9.62],[8,16,3],[7,40,16.14],[6,42,4.33],[5,44,8.01],[4,46,1.32],[3,50,1.16],[2,55,3.46],[1,70,2.72]],"id":57883707}]}]}{"op":"mcm","clk":"AN8TANANAMcK","pt":1784528036713,"mc":[{"id":"1.260192491","rc":[{"batb":[[3,55,3.24]],"id":60010414}]}]}{"op":"mcm","clk":"APsTAN0NANIK","pt":1784528037117,"mc":[{"id":"1.260136658","rc":[{"batl":[[6,24,2.85]],"id":98996178}]}]}{"op":"mcm","clk":"AMcUAIUOAIIL","pt":1784528038399,"mc":[{"id":"1.260136658","rc":[{"batl":[[5,920,2.1],[4,600,12.1],[3,440,2.13],[2,260,1.43],[1,65,3.76],[0,60,2.97]],"id":69865836}]}]}{"op":"ocm","id":1,"clk":"AMYFAJwHAK4JAMoLAJAG","pt":1784528039289,"ct":"HEARTBEAT"}{"op":"mcm","clk":"AIkVAKQOAKkL","pt":1784528040223,"mc":[{"id":"1.260136658","rc":[{"batb":[[0,7.6,3.4]],"id":79455963},{"batl":[[0,100,2.2]],"id":74493797}]}]}{"op":"mcm","clk":"AIwVAKoOAKoL","pt":1784528040329,"mc":[{"id":"1.260136658","rc":[{"batl":[[0,100,2.59]],"id":74493797}]}]}{"op":"mcm","clk":"AJAVAK4OAKwL","pt":1784528040431,"mc":[{"id":"1.260136658","rc":[{"trd":[[48,1.99]],"batb":[[0,48,1.85]],"ltp":48,"tv":54,"id":69865836},{"batb":[[0,7.6,1.7]],"id":79455963}],"tv":2627.19}]}{"op":"mcm","clk":"AJUVALIOAK8L","pt":1784528040634,"mc":[{"id":"1.260136803","rc":[{"batb":[[9,1.51,98.04],[8,2.12,44.64],[7,3.05,24.39],[6,4.1,16.13],[5,4.6,2.88],[4,6.2,9.62],[3,16,3.22],[2,90,3.21],[1,110,2.78],[0,150,3.25]],"id":100721225}]}]}{"op":"mcm","clk":"AJwVALMOALIL","pt":1784528040736,"mc":[{"id":"1.260136803","rc":[{"batb":[[9,2.12,44.64],[8,3.05,24.39],[7,4.1,16.13],[6,4.6,2.88],[5,6.2,9.62],[4,16,3.22],[3,90,3.21],[2,110,2.78],[1,150,2.99],[0,160,2.86]],"id":100721225}]}]}{"op":"mcm","clk":"AJ4VALQOALUL","pt":1784528040791,"mc":[{"id":"1.260136803","rc":[{"batb":[[0,80,3.27]],"id":57883707}]}]}{"op":"mcm","clk":"AKQVALUOALkL","pt":1784528040892,"mc":[{"id":"1.260136803","rc":[{"batb":[[0,160,2.84]],"id":100721225}]}]}{"op":"mcm","clk":"AKQVALUOALoL","pt":1784528040896,"mc":[{"id":"1.260191305","rc":[{"batb":[[8,0,0],[7,1.01,1154.26],[6,1.02,12],[5,1.16,100],[4,1.51,98.04],[3,4.3,24.34],[2,4.6,73.2],[1,4.8,2.08]],"id":23065746}]}]}{"op":"mcm","clk":"AKYVALYOALwL","pt":1784528040992,"mc":[{"id":"1.260136803","rc":[{"batb":[[0,80,3.5]],"id":57883707}]}]}{"op":"mcm","clk":"AKkVALYOAL4L","pt":1784528041002,"mc":[{"id":"1.260191305","rc":[{"batb":[[8,1.01,1154.26],[7,1.02,12],[6,1.16,100],[5,1.51,98.04],[4,4.3,24.34],[3,4.6,73.2],[2,4.8,2.08],[1,5.1,21.08],[0,5.2,2]],"id":23065746}]}]}{"op":"mcm","clk":"ALEVALkOAMML","pt":1784528041204,"mc":[{"id":"1.260191305","rc":[{"batb":[[8,0,0],[7,1.01,1154.26],[6,1.02,12],[5,1.16,100],[4,2.5,51.21],[3,2.62,124.48],[2,2.66,41.02]],"id":38858883}]}]}{"op":"mcm","clk":"ALcVALwOAMYL","pt":1784528041309,"mc":[{"id":"1.260191305","rc":[{"batb":[[8,1.01,1154.26],[7,1.02,12],[6,1.16,100],[5,2.5,51.21],[4,2.62,124.48],[3,2.66,41.02],[2,2.7,1],[1,2.72,50.25],[0,2.74,2]],"id":38858883}]}]}{"op":"mcm","clk":"AMAVAMAOAMsL","pt":1784528041511,"mc":[{"id":"1.260136803","rc":[{"batb":[[2,110,3.3]],"id":100721225}]}]}{"op":"mcm","clk":"AMkVAMYOAM8L","pt":1784528041710,"mc":[{"id":"1.260136803","rc":[{"batb":[[0,160,2.71]],"id":100721225}]}]}{"op":"mcm","clk":"AM0VAMoOANIL","pt":1784528041816,"mc":[{"id":"1.260136658","rc":[{"trd":[[1.9,58.11]],"batl":[[0,1.9,5.1]],"ltp":1.9,"tv":1785.16,"id":5547183}],"tv":2629.69}]}{"op":"mcm","clk":"AO8VAOEOAOUL","pt":1784528042527,"mc":[{"id":"1.260136658","rc":[{"batl":[[2,0,0],[1,790,0.33]],"id":78977433},{"batl":[[2,0,0],[1,1000,0.2]],"id":69161915}]}]}{"op":"mcm","clk":"APQVAOQOAOoL","pt":1784528042630,"mc":[{"id":"1.260136658","rc":[{"batl":[[2,790,0.25],[1,470,2.08]],"id":78977433},{"batl":[[1,0,0],[0,1000,0.83]],"id":69161915}]},{"id":"1.260136803","rc":[{"batb":[[1,150,2.82]],"id":100721225}]}]}{"op":"mcm","clk":"APgVAOkOAOsL","pt":1784528042732,"mc":[{"id":"1.260136658","rc":[{"batl":[[2,0,0],[1,790,0.25],[0,470,2.53]],"id":78977433}]}]}{"op":"mcm","clk":"APwVAOsOAPAL","pt":1784528042838,"mc":[{"id":"1.260136666","rc":[{"batb":[[2,120,2.33],[1,140,1.18]],"id":74300318}]}]}{"op":"mcm","clk":"AP8VAPAOAPEL","pt":1784528042889,"mc":[{"id":"1.260136666","rc":[{"batb":[[0,200,2.7]],"id":74300318}]}]}{"op":"mcm","clk":"AJkWAIIPAIMM","pt":1784528043506,"mc":[{"id":"1.260136666","rc":[{"batl":[[2,50,2.33]],"id":100749633},{"batl":[[9,600,12.1],[8,440,2.12],[7,180,1],[6,160,17.66],[5,150,1],[4,130,1],[3,120,1],[2,100,20.76],[1,50,1]],"id":82344583},{"batl":[[9,920,2.1],[8,600,12.1],[7,440,2.13],[6,190,1.28],[5,75,1],[4,70,1],[3,65,1],[2,60,3],[1,55,1]],"id":83642512}]}]}{"op":"mcm","clk":"AJsWAIIPAIMM","pt":1784528043510,"mc":[{"id":"1.260137374","rc":[{"batb":[[9,17,20.88],[8,17.5,3.03],[7,18,10.15],[6,18.5,2.86],[5,19,2.78],[4,20,2.63]],"id":68064063}]}]}{"op":"mcm","clk":"AKQWAIkPAIsM","pt":1784528043616,"mc":[{"id":"1.260137374","rc":[{"batb":[[9,17.5,3.03],[8,18,10.15],[7,18.5,2.86],[6,19,2.78],[5,20,2.63],[4,21,6.09],[3,22,2.38],[2,23,2.66],[1,24,2.23],[0,25,1.57]],"id":68064063}]}]}{"op":"mcm","clk":"AKYWAI8PAJEM","pt":1784528043709,"mc":[{"id":"1.260136666","rc":[{"batb":[[2,25,8.66]],"id":88111702},{"batb":[[4,6,3.73],[3,6.2,4.31]],"id":89669672}]}]}{"op":"mcm","clk":"AKoWAJEPAJUM","pt":1784528043808,"mc":[{"id":"1.260136666","rc":[{"batb":[[9,20,3.15],[8,21,9.77],[7,22,2.85],[6,23,2.72],[5,24,3.17],[4,25,9.04],[3,29,1.79],[2,30,1.72],[1,32,1.72]],"id":88111702},{"batl":[[2,50,1.33]],"id":100749633},{"batl":[[9,920,2.1],[8,600,12.1],[7,440,2.12],[6,180,1],[5,160,17.66],[4,150,1],[3,130,1],[2,120,1],[1,100,20.76]],"id":82344583},{"batl":[[9,0,0],[8,0,0],[7,0,0],[6,0,0],[5,920,2.1],[4,600,12.1],[3,440,2.13],[2,190,1.28],[1,60,2]],"id":83642512}]},{"id":"1.260136658","rc":[{"batl":[[7,920,2.1],[6,600,12.1],[5,440,2.13],[4,260,1.01],[3,80,1.21],[2,75,1.21]],"id":69865836}]}]}{"op":"mcm","clk":"ALQWAJQPAJoM","pt":1784528043917,"mc":[{"id":"1.260136666","rc":[{"batb":[[0,34,3]],"id":88111702}]}]}{"op":"mcm","clk":"ALQWAJYPAJoM","pt":1784528043918,"mc":[{"id":"1.260192491","rc":[{"batb":[[9,16,3],[8,17,1.04],[7,21,1.04],[6,30,2.29],[5,48,1.06],[4,50,1.02]],"id":60010414},{"batl":[[9,3.4,45.13],[8,3.3,1],[7,3.25,1],[6,3.2,1],[5,3.15,1],[4,3.1,1],[3,3.05,1],[2,3,28.12],[1,2.96,1]],"id":71121948}]}]}{"op":"mcm","clk":"ALgWAJgPAJwM","pt":1784528044019,"mc":[{"id":"1.260136666","rc":[{"batb":[[0,34,3.28]],"id":88111702}]},{"id":"1.260136658","rc":[{"batb":[[9,29,4.75],[8,30,4.68],[7,32,9.16],[6,34,4.56],[5,36,1.43],[4,38,1.35]],"id":69865836},{"batb":[[9,40,1.28],[8,42,1.22],[7,44,2.91],[6,46,1.44],[5,48,1.06],[4,50,1.69]],"id":74493797}]}]}{"op":"mcm","clk":"ALoWAJsPAJ4M","pt":1784528044118,"mc":[{"id":"1.260136666","rc":[{"batb":[[4,25,8.64]],"id":88111702}]},{"id":"1.260136658","rc":[{"batl":[[9,130,1.81],[8,65,11.17],[7,44,1],[6,42,1],[5,40,2.99],[4,38,2.99]],"id":6690508}]}]}{"op":"mcm","clk":"ALsWAJsPAJ8M","pt":1784528044119,"mc":[{"id":"1.260192337","rc":[{"batl":[[9,920,2.1],[8,600,12.1],[7,440,2.12],[6,250,10],[5,44,7.36]],"id":38629274},{"batl":[[8,920,2.1],[7,600,12.1],[6,440,2.12],[5,250,10],[4,44,7.36]],"id":60463853}]}]}{"op":"mcm","clk":"AL0WAJ0PAJ8M","pt":1784528044125,"mc":[{"id":"1.260137374","rc":[{"batb":[[2,23,1.66],[1,24,1.23]],"id":68064063}]}]}{"op":"ocm","id":1,"clk":"AI8GALkHAK8KANUMANYG","pt":1784528044289,"ct":"HEARTBEAT"}{"op":"mcm","clk":"ANgWALAPAK8M","pt":1784528044624,"mc":[{"id":"1.260137374","rc":[{"batl":[[3,0,0],[2,920,2.1],[1,600,10.02]],"id":68064063},{"batb":[[9,1.02,22],[8,1.12,100],[7,2.24,222.22],[6,2.26,93.09],[5,2.32,1],[4,2.36,1],[3,2.38,85.57],[2,2.4,45.61],[1,2.44,11.42],[0,2.46,4.49]],"batl":[[9,19,1],[8,16,15],[7,5.7,48.78],[6,5.4,12.03],[5,4.9,26.62],[4,4.6,7.81],[3,4.3,3.49],[2,4,62.29],[1,3.95,3.86]],"id":100720591}]}]}{"op":"mcm","clk":"ANwWALkPALMM","pt":1784528044733,"mc":[{"id":"1.260136666","rc":[{"batb":[[9,16,3.33],[8,19,15.34],[7,20,3.15],[6,21,9.77],[5,22,2.85],[4,23,2.72],[3,24,3.17],[2,25,8.26],[1,27,1.1]],"id":88111702}]},{"id":"1.260136658","rc":[{"batl":[[7,0,0],[6,0,0],[5,920,2.1],[4,600,12.1],[3,440,2.13],[2,260,1.43]],"id":69865836}]}]}{"op":"mcm","clk":"AN4WALkPALMM","pt":1784528044735,"mc":[{"id":"1.260137374","rc":[{"batb":[[0,25,3.57]],"batl":[[3,920,2.1],[2,600,10.02],[1,240,1]],"id":68064063},{"batb":[[9,1.12,100],[8,1.51,98.04],[7,1.77,7.79],[6,2.08,5.56],[5,3.1,50.55],[4,3.25,23.9]],"batl":[[3,6.6,1],[2,5.5,23.9]],"id":99274452},{"batb":[[0,13.5,5.9]],"id":4054763},{"batl":[[9,22,5.36],[8,19,1],[7,16,15],[6,5.7,48.78],[0,3.6,1]],"id":100720591},{"batb":[[1,13,3.8]],"id":79844992},{"batb":[[9,1.73,7.97]],"id":25417481},{"batl":[[2,600,10.02],[1,380,1],[0,300,2.96]],"id":100720598},{"batl":[[1,300,1]],"id":100720594},{"batb":[[9,30,2]],"batl":[[1,0,0],[0,450,0.5]],"id":100720597}]}]}{"op":"mcm","clk":"AOMWALwPALgM","pt":1784528044835,"mc":[{"id":"1.260137374","rc":[{"batb":[[9,1.77,7.79],[8,2.08,5.56],[7,3.1,50.55],[6,3.25,23.9],[5,3.35,76.83],[4,3.4,31.19],[3,3.55,13.05],[2,3.7,45.9],[1,3.75,1.4],[0,3.85,4.08]],"id":99274452},{"batb":[[9,2.38,4.35],[8,2.94,3.09],[7,5.2,2],[6,5.3,66.08],[5,5.4,27.71],[4,5.5,31.73],[3,5.8,12.63],[2,6,24.36],[1,6.2,12.18],[0,6.8,2.06]],"id":25417481},{"batb":[[9,20,4.63],[8,21,16.64],[7,22,2.38],[6,23,8.15],[5,24,2.17],[4,25,2.08],[3,26,2],[2,27,1.92],[1,28,7],[0,30,6.32]],"id":100720598}]}]}{"op":"mcm","clk":"AOUWAL0PALoM","pt":1784528044934,"mc":[{"id":"1.260192337","rc":[{"batl":[[7,920,2.1],[6,600,13.1],[5,440,2.12],[4,250,10]],"id":41665191}]}]}{"op":"mcm","clk":"AOsWAMEPALwM","pt":1784528045040,"mc":[{"id":"1.260136658","rc":[{"batb":[[0,8.4,5.4]],"id":100749630}]}]}{"op":"mcm","clk":"APEWAMcPAL4M","pt":1784528045090,"mc":[{"id":"1.260136658","rc":[{"batb":[[9,6.6,14.71],[8,6.8,21.31],[7,7,28.53],[6,7.2,30.05],[5,7.4,12.11],[4,7.6,11.76],[3,7.8,2.42],[2,8,1.81],[1,8.4,5.4],[0,8.6,1.3]],"batl":[[9,14,1],[8,13.5,1],[7,13,1],[6,12.5,1.9],[5,12,2.87],[4,11.5,5.9],[3,11,5.99],[2,10.5,12.56],[1,10,6.08],[0,9.8,1.14]],"id":100749630}]}]}{"op":"mcm","clk":"APMWAMcPAL4M","pt":1784528045093,"mc":[{"id":"1.260137374","rc":[{"batb":[[9,1.51,98.04],[8,1.77,7.79],[7,2.08,5.56],[6,3.1,50.55],[5,3.25,23.9],[4,3.35,76.83],[3,3.4,31.19],[2,3.55,13.05],[1,3.7,46.3]],"id":99274452}]}]}{"op":"mcm","clk":"APgWAM0PAMAM","pt":1784528045199,"mc":[{"id":"1.260136658","rc":[{"batb":[[3,7.8,11.24]],"id":100749630}]}]}{"op":"mcm","clk":"AJUXAOgPAM0M","pt":1784528045909,"mc":[{"id":"1.260136658","rc":[{"batb":[[1,8.4,4.39]],"id":100749630}]}]}{"op":"mcm","clk":"AKgXAPsPANAM","pt":1784528046224,"mc":[{"id":"1.260136666","rc":[{"batb":[[0,34,2.28]],"id":88111702}]},{"id":"1.260136658","rc":[{"batl":[[9,250,10],[8,200,2],[7,130,1.81],[6,65,11.17],[5,40,1.99],[4,38,1.99]],"id":6690508},{"batl":[[1,10,2]],"id":100749630},{"batb":[[9,27,6.36],[8,28,5.96],[7,29,4.75],[6,30,4.68],[5,32,9.16],[4,34,4.56]],"id":69865836},{"batb":[[9,16,3],[8,26,9.21],[7,30,2],[6,38,4.48],[5,44,1.76],[4,46,1]],"id":74493797}]}]}{"op":"mcm","clk":"AKwXAIAQANIM","pt":1784528046323,"mc":[{"id":"1.260136658","rc":[{"batl":[[0,9.8,5.22]],"id":100749630}]}]}{"op":"mcm","clk":"ALIXAIgQANMM","pt":1784528046427,"mc":[{"id":"1.260136658","rc":[{"batl":[[9,13.5,1],[8,13,1],[7,12.5,1.9],[6,12,2.87],[5,11.5,5.9],[4,11,5.99],[3,10.5,12.56],[2,10,2],[1,9.8,5.22],[0,9.6,1.18]],"id":100749630}]}]}{"op":"mcm","clk":"ALgXAIwQANUM","pt":1784528046522,"mc":[{"id":"1.260192491","rc":[{"batb":[[3,55,4.24]],"id":60010414}]},{"id":"1.260136658","rc":[{"batl":[[7,920,2.1],[6,600,12.1],[5,440,2.13],[4,260,1.22],[3,75,1],[2,70,1.21]],"id":69865836}]}]}{"op":"mcm","clk":"ALkXAIwQANgM","pt":1784528046533,"mc":[{"id":"1.260191305","rc":[{"batb":[[9,0,0],[8,1.01,1154.26],[7,1.02,12],[6,1.16,100],[5,1.51,98.04],[4,3.15,39.72],[3,3.3,87.68],[2,3.4,28.71]],"id":46065793}]}]}{"op":"mcm","clk":"AL0XAJMQANsM","pt":1784528046627,"mc":[{"id":"1.260136658","rc":[{"batb":[[9,12.5,14.82]],"id":56407176}]},{"id":"1.260192491","rc":[{"batb":[[3,55,3.24]],"id":60010414}]}]}{"op":"mcm","clk":"AMEXAJMQAN0M","pt":1784528046630,"mc":[{"id":"1.260191305","rc":[{"batb":[[9,1.01,1154.26],[8,1.02,12],[7,1.16,100],[6,1.51,98.04],[5,3.15,39.72],[4,3.3,87.68],[3,3.4,28.71],[2,3.5,1],[1,3.55,33.89],[0,3.6,2]],"id":46065793}]}]}{"op":"mcm","clk":"AMYXAJoQAOAM","pt":1784528046731,"mc":[{"id":"1.260136658","rc":[{"batb":[[1,23,1.06]],"id":6690508},{"batl":[[7,0,0],[6,0,0],[5,920,2.1],[4,600,12.1],[3,440,2.13],[2,260,1.43]],"id":69865836}]}]}{"op":"mcm","clk":"AMoXAKAQAOUM","pt":1784528046836,"mc":[{"id":"1.260136658","rc":[{"batb":[[0,190,3.15]],"id":78977433},{"batb":[[9,18,9.04],[8,18.5,5.54],[7,19,8.07],[6,19.5,5.7],[5,20,3.99],[4,21,5.15],[3,22,4.55],[2,23,1.06],[1,24,4.56],[0,25,5.08]],"id":6690508},{"batl":[[9,10,11.17]],"id":79455963}]}]}{"op":"mcm","clk":"ANsXAK0QAPQM","pt":1784528047340,"mc":[{"id":"1.260136666","rc":[{"batl":[[2,17.5,1]],"id":100749631}]}]}{"op":"mcm","clk":"ANsXAK8QAPUM","pt":1784528047346,"mc":[{"id":"1.260192491","rc":[{"batb":[[9,6.2,9.62],[8,12.5,1.04],[7,16,3],[6,17,1.04],[5,21,1.04],[4,30,2.29]],"id":60010414},{"batl":[[9,440,2.12],[8,250,10.01],[7,44,7.36],[6,34,15],[5,24,3.34],[4,16.5,11.15],[3,13.5,3.35]],"id":90458476},{"batl":[[9,3.7,63.65],[8,3.4,45.13],[7,3.3,1],[6,3.25,1],[5,3.2,1],[4,3.15,1],[3,3.1,1],[2,3.05,1],[1,3,28.12]],"id":71121948}]}]}{"op":"mcm","clk":"AN4XALMQAPkM","pt":1784528047442,"mc":[{"id":"1.260192491","rc":[{"batl":[[9,600,12.1],[8,440,2.12],[7,250,10.01],[6,44,7.36],[5,34,15]],"id":90458476}]}]}{"op":"mcm","clk":"AOYXALgQAP8M","pt":1784528047602,"mc":[{"id":"1.260136658","rc":[{"batb":[[1,180,1.62]],"id":69161915}]}]}{"op":"mcm","clk":"APMXAL8QAIkN","pt":1784528047805,"mc":[{"id":"1.260136658","rc":[{"batl":[[1,8.2,1.82]],"id":79455963}]}]}{"op":"mcm","clk":"AIsYAMkQAJAN","pt":1784528048116,"mc":[{"id":"1.260136658","rc":[{"batb":[[9,12.5,23.63]],"id":56407176},{"batl":[[0,1000,0.91]],"id":69161915}]}]}{"op":"mcm","clk":"AJ4YANYQAJYN","pt":1784528048420,"mc":[{"id":"1.260136658","rc":[{"batl":[[9,25,5.15],[8,24,5.13],[3,19.5,3.99]],"id":56407176},{"batb":[[5,20,4.99],[4,21,6.15],[3,22,5.55],[2,23,2.06]],"id":6690508}]}]}{"op":"mcm","clk":"AL4YAO8QAKMN","pt":1784528049033,"mc":[{"id":"1.260192493","rc":[{"batb":[[9,2.12,44.64],[8,3.05,24.39],[7,3.35,3.07],[6,4.3,2.34],[5,5.4,1.04]],"id":100748335},{"batb":[[9,30,1.72],[8,32,1.61],[7,34,6.29],[6,36,1],[5,38,1.35],[4,40,16.14],[3,42,1.22],[2,44,5.84],[1,46,1.32]],"id":44387351}]}]}{"op":"mcm","clk":"AMAYAPEQAKQN","pt":1784528049133,"mc":[{"id":"1.260192493","rc":[{"batb":[[9,3.05,24.39],[8,3.35,3.07],[7,4.3,2.34],[6,5.4,1.04],[5,8.2,16.14],[4,8.4,15.08]],"id":100748335},{"batb":[[1,46,4.34]],"id":44387351}]}]}{"op":"ocm","id":1,"clk":"AN0GAPMHANILANMNALcH","pt":1784528049289,"ct":"HEARTBEAT"}{"op":"mcm","clk":"ANkYAP0QALUN","pt":1784528049602,"mc":[{"id":"1.260136658","rc":[{"batb":[[0,48,2.6]],"batl":[[0,60,3.56]],"id":69865836}]}]}{"op":"mcm","clk":"AN8YAP8QALoN","pt":1784528049700,"mc":[{"id":"1.260136658","rc":[{"batb":[[7,6.2,24.71]],"id":79455963}]}]}{"op":"mcm","clk":"AOUYAIERAL4N","pt":1784528049805,"mc":[{"id":"1.260137374","rc":[{"batb":[[2,12.5,12.59],[1,13,1.8]],"id":79844992}]}]}{"op":"mcm","clk":"AJQZAK0RANoN","pt":1784528050931,"mc":[{"id":"1.260136658","rc":[{"batb":[[4,7.6,10.91],[0,8.6,2.15]],"id":100749630},{"batb":[[0,1.87,7.12]],"id":5547183}]}]}{"op":"mcm","clk":"AJ4ZALMRANwN","pt":1784528051040,"mc":[{"id":"1.260136658","rc":[{"batb":[[9,6.8,21.31],[8,7,28.53],[7,7.2,30.05],[6,7.4,12.11],[5,7.6,10.91],[4,7.8,11.24],[3,8,1.81],[2,8.4,4.39],[1,8.6,3.73],[0,8.8,1.1]],"batl":[[1,9.8,6.72]],"id":100749630},{"trd":[[300,4.74]],"batl":[[0,1000,0.85]],"tv":12.99,"id":69161915}],"tv":2629.81}]}{"op":"mcm","clk":"AKMZALYRAOEN","pt":1784528051135,"mc":[{"id":"1.260136658","rc":[{"batb":[[3,8,10.38]],"id":100749630}]}]}{"op":"mcm","clk":"ALIZAMYRAOsN","pt":1784528051442,"mc":[{"id":"1.260136658","rc":[{"batb":[[2,23,4.05]],"batl":[[9,48,1.99],[8,46,1.99],[7,44,1.99],[6,42,1.99]],"id":6690508}]}]}{"op":"mcm","clk":"AL4ZAM0RAO8N","pt":1784528051604,"mc":[{"id":"1.260137374","rc":[{"batb":[[0,32,2.06]],"id":100720596}]}]}{"op":"mcm","clk":"AL8ZANMRAPEN","pt":1784528051703,"mc":[{"id":"1.260136658","rc":[{"batb":[[9,17.5,12.23],[8,18,9.04],[7,18.5,5.54],[6,19,8.07],[5,19.5,5.7],[4,20,4.99],[3,21,6.15],[2,22,5.55],[1,23,4.05],[0,24,4.56]],"id":6690508},{"batl":[[0,1000,0.72]],"id":69161915}]}]}{"op":"mcm","clk":"AMEZANMRAPEN","pt":1784528051709,"mc":[{"id":"1.260137374","rc":[{"batb":[[1,30,5.52]],"id":100720596}]}]}{"op":"mcm","clk":"AMYZANYRAPIN","pt":1784528051811,"mc":[{"id":"1.260136658","rc":[{"batb":[[9,18,9.04],[8,18.5,5.54],[7,19,8.07],[6,19.5,5.7],[5,20,4.99],[4,21,6.15],[3,22,5.55],[2,23,4.05],[1,24,7.64],[0,27,2.33]],"id":6690508}]}]}{"op":"mcm","clk":"AMkZANkRAPQN","pt":1784528051906,"mc":[{"id":"1.260136658","rc":[{"trd":[[27,1.79]],"batb":[[0,27,2.17]],"ltp":27,"tv":31.78,"id":6690508},{"batb":[[3,8,10.4]],"id":100749630}],"tv":2630.13}]}{"op":"mcm","clk":"AMsZANkRAPQN","pt":1784528051909,"mc":[{"id":"1.260137374","rc":[{"batb":[[0,32,2.07]],"id":100720596}]}]}{"op":"mcm","clk":"AOEZAOsRAIoO","pt":1784528052521,"mc":[{"id":"1.260136658","rc":[{"batl":[[9,640,1],[8,630,1],[7,620,1],[6,610,1],[5,600,11.02],[4,370,1.05],[3,300,5.61]],"id":74493797}]}]}{"op":"mcm","clk":"AIYaAIMSAKoO","pt":1784528053533,"mc":[{"id":"1.260137374","rc":[{"batb":[[2,23,3.93]],"id":68064063}]}]}{"op":"mcm","clk":"AIYaAIUSAKsO","pt":1784528053534,"mc":[{"id":"1.260136658","rc":[{"batb":[[9,19,8.07],[8,19.5,5.7],[7,20,4.99],[6,21,6.15],[5,22,5.55],[4,23,4.05],[3,24,7.64],[2,25,2.08],[1,26,1]],"batl":[[9,48,2.99],[8,46,2.99],[7,44,2.99],[6,42,2.99]],"id":6690508},{"batb":[[9,29,4.75],[8,30,4.68],[7,32,9.16],[6,34,4.56],[5,36,1.43],[4,38,1.35]],"batl":[[7,920,2.1],[6,600,12.1],[5,440,2.13],[4,260,1.01],[3,80,1.21],[2,75,1.21]],"id":69865836},{"batb":[[9,40,1.28],[8,42,1.22],[7,44,2.91],[6,46,1.44],[5,48,1.06],[4,50,1.69]],"id":74493797}]}]}{"op":"mcm","clk":"AIoaAIcSAK0O","pt":1784528053634,"mc":[{"id":"1.260192491","rc":[{"batl":[[0,1000,4.3]],"id":91496756},{"batl":[[9,3.4,45.13],[8,3.3,1],[7,3.25,1],[6,3.2,1],[5,3.15,1],[4,3.1,1],[3,3.05,1],[2,3,28.12],[1,2.96,1]],"id":71121948}]}]}{"op":"mcm","clk":"AI8aAIkSALEO","pt":1784528053739,"mc":[{"id":"1.260192491","rc":[{"batb":[[1,90,3.98]],"id":60010414},{"batb":[[0,44,3.23]],"id":91496756}]}]}{"op":"mcm","clk":"AJQaAIoSALMO","pt":1784528053838,"mc":[{"id":"1.260192491","rc":[{"batb":[[9,16,3],[8,17,1.04],[7,21,1.04],[6,30,2.29],[5,48,1.06],[4,50,1.02]],"id":60010414}]}]}{"op":"mcm","clk":"AJ0aAI0SALsO","pt":1784528054145,"mc":[{"id":"1.260136658","rc":[{"batl":[[5,23,12.91]],"id":98996178}]}]}{"op":"ocm","id":1,"clk":"AJ4HAJ8IANkMAMAOAPoH","pt":1784528054289,"ct":"HEARTBEAT"}{"op":"mcm","clk":"ALMaAJcSAMoO","pt":1784528054705,"mc":[{"id":"1.260136658","rc":[{"batl":[[0,100,2.2]],"id":74493797}]}]}{"op":"mcm","clk":"ALgaAJkSAM0O","pt":1784528054810,"mc":[{"id":"1.260136658","rc":[{"batl":[[0,100,2.6]],"id":74493797}]}]}{"op":"mcm","clk":"AMgaAKMSANYO","pt":1784528055218,"mc":[{"id":"1.260136658","rc":[{"batb":[[9,18.5,5.54],[8,19,8.07],[7,19.5,5.7],[6,20,4.99],[5,21,6.15],[4,22,5.55],[3,23,4.05],[2,24,7.64],[1,25,2.08]],"batl":[[9,48,1.99],[8,46,1.99],[7,44,1.99],[6,42,1.99]],"id":6690508},{"batb":[[9,27,6.36],[8,28,5.96],[7,29,4.75],[6,30,4.68],[5,32,9.16],[4,34,4.56]],"batl":[[7,0,0],[6,0,0],[5,920,2.1],[4,600,12.1],[3,440,2.13],[2,260,1.43]],"id":69865836},{"batb":[[9,16,3],[8,26,9.21],[7,30,2],[6,38,4.48],[5,44,1.76],[4,46,1]],"id":74493797}]}]}{"op":"mcm","clk":"AP4aANISAIYP","pt":1784528056540,"mc":[{"id":"1.260136658","rc":[{"batl":[[7,44,2.99]],"id":6690508},{"batl":[[7,920,2.1],[6,600,12.1],[5,440,2.13],[4,260,1.22],[3,75,1],[2,70,1.21]],"id":69865836}]}]}{"op":"mcm","clk":"AP4aANQSAIkP","pt":1784528056550,"mc":[{"id":"1.260192491","rc":[{"batb":[[3,55,4.24]],"id":60010414}]}]}{"op":"mcm","clk":"AIIbANkSAIwP","pt":1784528056644,"mc":[{"id":"1.260136658","rc":[{"batl":[[7,44,1.99]],"id":6690508},{"batl":[[7,0,0],[6,0,0],[5,920,2.1],[4,600,12.1],[3,440,2.13],[2,260,1.43]],"id":69865836}]}]}{"op":"mcm","clk":"AIUbAN4SAJAP","pt":1784528056743,"mc":[{"id":"1.260192491","rc":[{"batb":[[9,6.2,9.62],[8,12.5,1.04],[7,16,3],[6,17,1.04],[5,21,1.04],[4,30,2.29],[3,55,3.24],[1,90,2.98]],"id":60010414},{"batb":[[0,44,2.23]],"batl":[[0,1000,3.3]],"id":91496756},{"batl":[[9,3.7,63.65],[8,3.4,45.13],[7,3.3,1],[6,3.25,1],[5,3.2,1],[4,3.15,1],[3,3.1,1],[2,3.05,1],[1,3,28.12]],"id":71121948}]}]}{"op":"mcm","clk":"AIgbAOMSAJIP","pt":1784528056854,"mc":[{"id":"1.260136658","rc":[{"batb":[[0,280,2.18]],"id":69161915}]}]}{"op":"mcm","clk":"ALYbAJITALYP","pt":1784528058024,"mc":[{"id":"1.260136658","rc":[{"batl":[[1,1000,0.2],[0,990,1.86]],"id":69161915}]},{"id":"1.260136803","rc":[{"batb":[[1,2.76,9.23]],"id":100721219}]}]}{"op":"mcm","clk":"AL8bAJ0TALoP","pt":1784528058231,"mc":[{"id":"1.260192334","rc":[{"batb":[[9,6.2,4],[8,6.4,2],[7,6.6,3.04],[6,6.8,36.77],[5,7,16.2],[4,7.2,1],[3,7.8,12.71],[2,8,12.42],[1,8.8,1.04]],"id":73793682}]}]}{"op":"mcm","clk":"AMMbAKQTAMAP","pt":1784528058338,"mc":[{"id":"1.260192334","rc":[{"batb":[[9,6.4,2],[8,6.6,3.04],[7,6.8,36.77],[6,7,16.2],[5,7.2,1],[4,7.8,12.71],[3,8,12.42],[2,8.2,2]],"id":73793682}]}]}{"op":"mcm","clk":"AMcbAKsTAMoP","pt":1784528058536,"mc":[{"id":"1.260192493","rc":[{"batb":[[9,1.02,12],[8,1.53,16.14],[7,1.77,81.38],[6,1.84,1],[5,1.86,234.49],[4,1.88,1],[3,1.9,2],[2,1.91,96.98],[1,1.92,75.64],[0,1.93,5.18]],"id":100748333}]}]}{"op":"mcm","clk":"AMkbAK4TAM0P","pt":1784528058635,"mc":[{"id":"1.260192493","rc":[{"batl":[[0,100,4.22]],"id":90296582}]}]}{"op":"mcm","clk":"AM8bALQTANIP","pt":1784528058840,"mc":[{"id":"1.260192340","rc":[{"batb":[[0,8.4,1.19]],"id":62688374}]}]}{"op":"mcm","clk":"ANMbALUTANMP","pt":1784528058943,"mc":[{"id":"1.260136658","rc":[{"trd":[[300,4.85]],"batl":[[0,990,1.81]],"tv":13.1,"id":69161915}],"tv":2630.24}]}{"op":"mcm","clk":"AN0bALoTAN0P","pt":1784528059145,"mc":[{"id":"1.260136658","rc":[{"batl":[[7,23,18.66]],"id":56407176}]}]}{"op":"ocm","id":1,"clk":"APYHAMcIAOQNALoPAMAI","pt":1784528059289,"ct":"HEARTBEAT"}{"op":"mcm","clk":"AOcbAMQTAOMP","pt":1784528059404,"mc":[{"id":"1.260136658","rc":[{"batl":[[9,2.28,6],[8,2.24,1],[7,2.18,25.95],[6,2.08,10.38],[5,2.04,71.85],[3,1.93,19.3]],"id":5547183}]}]}{"op":"mcm","clk":"AOgbAMUTAOUP","pt":1784528059451,"mc":[{"id":"1.260192491","rc":[{"batl":[[0,390,4.51]],"id":43653174}]}]}{"op":"mcm","clk":"AOobAMkTAOYP","pt":1784528059506,"mc":[{"id":"1.260136658","rc":[{"trd":[[1.88,2.75]],"batb":[[0,1.87,6.27]],"batl":[[9,2.24,1],[8,2.18,25.95],[7,2.08,10.38],[6,2.04,71.85],[5,1.94,19.3],[4,1.93,19.3],[3,1.92,24.59],[2,1.91,72.31],[1,1.9,189.89],[0,1.88,120.79]],"ltp":1.88,"tv":1786.86,"id":5547183},{"batb":[[0,280,2.22]],"id":69161915}],"tv":2631.94}]}{"op":"mcm","clk":"AOobAMoTAOYP","pt":1784528059552,"mc":[{"id":"1.260192491","rc":[{"batl":[[2,900,2.85],[0,390,2.51]],"id":43653174}]}]}{"op":"mcm","clk":"AO4bAM4TAOgP","pt":1784528059609,"mc":[{"id":"1.260136658","rc":[{"trd":[[1.88,3.49]],"batb":[[9,1.71,388.12],[8,1.76,20.76],[7,1.78,151.41],[6,1.8,10.38],[5,1.81,18.17],[4,1.82,10.38],[3,1.83,10.38],[2,1.84,10.38],[1,1.85,88.9],[0,1.86,31.82]],"batl":[[0,1.88,139.59]],"tv":1787.6,"id":5547183}],"tv":2632.68}]}{"op":"mcm","clk":"AO8bAM8TAOoP","pt":1784528059655,"mc":[{"id":"1.260192491","rc":[{"batl":[[0,390,4.51]],"id":43653174}]}]}{"op":"mcm","clk":"APMbANMTAO4P","pt":1784528059715,"mc":[{"id":"1.260136658","rc":[{"batl":[[9,2.28,6],[8,2.24,1],[7,2.18,25.95],[6,2.08,10.38],[5,2.04,71.85]],"id":5547183}]}]}{"op":"mcm","clk":"APMbANQTAPAP","pt":1784528059721,"mc":[{"id":"1.260192491","rc":[{"batl":[[2,900,0.85]],"id":43653174}]}]}{"op":"mcm","clk":"APcbANYTAPIP","pt":1784528059815,"mc":[{"id":"1.260192495","rc":[{"batb":[[9,1.02,12],[8,1.16,100],[7,1.51,98.04],[6,2.12,44.64],[5,3.05,24.39],[4,4.1,16.13],[3,4.6,2.88],[2,6.2,9.93],[1,55,3.11],[0,65,4.12]],"id":46626367},{"batb":[[9,1.02,12],[8,1.16,100],[7,1.51,98.04],[6,2.12,44.64],[5,3.05,24.39],[4,4.1,16.13],[3,4.6,2.88],[2,6.2,9.85],[1,120,5.29],[0,130,1.51]],"id":25695674},{"batb":[[9,2.06,4],[8,2.08,4],[7,2.1,1],[6,2.12,45.64],[5,3.05,24.39],[4,4.1,16.13],[3,4.6,2.88],[2,6.2,9.85],[1,120,5.29],[0,130,1.51]],"id":38138891}]},{"id":"1.260192491","rc":[{"batl":[[0,390,4.54]],"id":43653174}]}]}{"op":"mcm","clk":"AP0bANgTAPMP","pt":1784528059914,"mc":[{"id":"1.260192495","rc":[{"batb":[[9,1.16,100],[8,1.51,98.04],[7,2.12,44.64],[6,3.05,24.39],[5,4.1,16.13],[4,4.6,2.88],[3,6.2,9.93],[2,55,3.11],[1,65,3.15],[0,75,3.57]],"id":46626367},{"batb":[[9,1.16,100],[8,1.51,98.04],[7,2.12,44.64],[6,3.05,24.39],[5,4.1,16.13],[4,4.6,2.88],[3,6.2,9.85],[2,120,5.29],[1,130,1],[0,170,1.26]],"id":25695674},{"batb":[[9,2.08,4],[8,2.1,1],[7,2.12,45.64],[6,3.05,24.39],[5,4.1,16.13],[4,4.6,2.88],[3,6.2,9.85],[2,120,5.29],[1,130,1],[0,170,1.26]],"id":38138891}]}]}{"op":"mcm","clk":"AP0bANkTAPQP","pt":1784528060015,"mc":[{"id":"1.260136658","rc":[{"batb":[[0,1.86,20.99]],"id":5547183}]}]}{"op":"mcm","clk":"AIQcAN4TAPkP","pt":1784528060117,"mc":[{"id":"1.260136658","rc":[{"batb":[[1,1.85,108.15]],"id":5547183}]}]}{"op":"mcm","clk":"AJwcAOcTAIoQ","pt":1784528060728,"mc":[{"id":"1.260136658","rc":[{"batl":[[2,0,0],[1,580,1.39],[0,230,2.76]],"id":99951973}]}]}{"op":"mcm","clk":"ALccAPcTAJwQ","pt":1784528061441,"mc":[{"id":"1.260137374","rc":[{"batb":[[0,21,3.96]],"id":82788200},{"batb":[[0,24,3.74]],"id":100720592},{"batb":[[3,5.8,19.95]],"id":25417481},{"batb":[[9,21,16.64],[8,22,2.38],[7,23,8.15],[6,24,2.17],[5,25,2.08],[4,26,2],[3,27,1.92],[2,28,7],[1,30,5.54],[0,32,2.78]],"id":100720598},{"batb":[[0,28,3.29]],"id":100720594}]}]}{"op":"mcm","clk":"ALscAPkTAKAQ","pt":1784528061544,"mc":[{"id":"1.260137374","rc":[{"batb":[[2,23,1.66]],"id":68064063},{"batb":[[9,1.01,1154.83],[8,1.02,22],[7,1.12,100],[6,2.24,222.22]],"id":100720591},{"batb":[[7,4.2,37.01],[6,5.2,2],[5,5.3,66.08]],"id":25417481},{"batl":[[3,600,10.02],[2,300,1],[1,210,3.04],[0,200,11.17]],"id":100720594}]}]}{"op":"mcm","clk":"AMAcAPoTAKIQ","pt":1784528061646,"mc":[{"id":"1.260137374","rc":[{"batb":[[9,1.02,22],[8,1.12,100],[7,1.9,93.09]],"id":100720591},{"batb":[[1,30,5.49]],"id":100720598},{"batb":[[9,19.5,9.45],[8,20,6.04],[7,22,2.38],[6,23,2.27],[5,24,2.17],[4,25,5.08],[3,26,1.65],[2,27,1.27],[1,28,2.51],[0,29,1.3]],"batl":[[4,600,10.02],[3,300,1],[2,210,1.04],[1,200,11.17],[0,190,2.46]],"id":100720594}]}]}{"op":"mcm","clk":"ANQcAIkUAKwQ","pt":1784528062006,"mc":[{"id":"1.260137374","rc":[{"batb":[[9,22,2.38],[8,23,8.15],[7,24,2.17],[6,25,2.08],[5,26,2],[4,27,1.92],[3,28,7],[2,30,5.49],[1,32,2.78],[0,34,1.64]],"id":100720598}]}]}{"op":"mcm","clk":"ANocAIwUALEQ","pt":1784528062109,"mc":[{"id":"1.260137374","rc":[{"batb":[[0,24,3.73]],"id":100720592},{"batb":[[1,28,2.41],[0,29,1.4]],"id":100720594}]}]}{"op":"mcm","clk":"ANscAI8UALcQ","pt":1784528062213,"mc":[{"id":"1.260136658","rc":[{"batb":[[8,7,17.01]],"id":100749630}]}]}{"op":"mcm","clk":"AOAcAI8UALcQ","pt":1784528062221,"mc":[{"id":"1.260137374","rc":[{"batb":[[9,16.5,21.56],[8,17,3.12],[7,17.5,3.03],[6,18,2.94],[5,18.5,9.24],[4,19,2.78],[3,20,6.89],[2,22,1.68],[1,24,3.11],[0,25,1.22]],"id":100720592}]}]}{"op":"mcm","clk":"AOMcAJEUALoQ","pt":1784528062314,"mc":[{"id":"1.260136658","rc":[{"batb":[[7,7.2,41.57]],"id":100749630}]}]}{"op":"mcm","clk":"APIcAJ0UAMcQ","pt":1784528062718,"mc":[{"id":"1.260136658","rc":[{"trd":[[300,4.97]],"batl":[[0,990,1.75]],"tv":13.22,"id":69161915}],"tv":2632.8}]}{"op":"mcm","clk":"APccAKAUAMoQ","pt":1784528062820,"mc":[{"id":"1.260136658","rc":[{"batb":[[0,280,2.13]],"id":69161915}]}]}{"op":"mcm","clk":"AP0cAKMUAM8Q","pt":1784528063025,"mc":[{"id":"1.260136658","rc":[{"batb":[[9,18.5,6.54],[8,19,9.07],[7,19.5,6.7]],"id":6690508},{"batb":[[6,30,5.68],[5,32,10.16]],"id":69865836}]}]}{"op":"mcm","clk":"AJEdAKkUANsQ","pt":1784528063431,"mc":[{"id":"1.260137374","rc":[{"batb":[[2,23,3.93]],"id":68064063},{"batb":[[9,17,3.12],[8,17.5,3.03],[7,18,2.94],[6,18.5,9.24],[5,19,2.78],[4,20,6.89],[3,22,1.68],[2,23,2.27]],"id":100720592},{"batb":[[9,20,8.67],[8,21,2.5],[2,27,3.19],[0,29,2.4]],"id":100720594}]}]}{"op":"mcm","clk":"AJEdAKsUANwQ","pt":1784528063434,"mc":[{"id":"1.260136658","rc":[{"batl":[[9,48,2.99],[8,46,2.99],[7,44,2.99],[6,42,2.99]],"id":6690508},{"batb":[[9,29,4.75],[8,30,5.68],[7,32,10.16],[6,34,4.56],[5,36,1.43],[4,38,1.35]],"id":69865836},{"batb":[[9,40,1.28],[8,42,1.22],[7,44,2.91],[6,46,1.44],[5,48,1.06],[4,50,1.69]],"id":74493797}]}]}{"op":"mcm","clk":"AJUdAK4UAOAQ","pt":1784528063537,"mc":[{"id":"1.260136658","rc":[{"batl":[[7,920,2.1],[6,600,12.1],[5,440,2.13],[4,260,1.01],[3,80,1.21],[2,75,1.21]],"id":69865836}]}]}{"op":"mcm","clk":"AJkdALAUAOIQ","pt":1784528063636,"mc":[{"id":"1.260137374","rc":[{"batb":[[2,30,5.47]],"id":100720598},{"batb":[[1,28,2]],"id":100720594}]}]}{"op":"mcm","clk":"AJkdALUUAOMQ","pt":1784528063639,"mc":[{"id":"1.260192491","rc":[{"batb":[[9,16,3],[8,17,1.04],[7,21,1.04],[6,30,2.29],[5,48,1.06],[4,50,1.02]],"id":60010414},{"batl":[[9,3.4,45.13],[8,3.3,1],[7,3.25,1],[6,3.2,1],[5,3.15,1],[4,3.1,1],[3,3.05,1],[2,3,28.12],[1,2.96,1]],"id":71121948}]}]}{"op":"mcm","clk":"AJ4dALUUAOUQ","pt":1784528063738,"mc":[{"id":"1.260137374","rc":[{"batb":[[0,29,2.81]],"id":100720594}]}]}{"op":"mcm","clk":"AKIdALgUAOgQ","pt":1784528063837,"mc":[{"id":"1.260137374","rc":[{"batb":[[0,29,2.8]],"id":100720594}]}]}{"op":"mcm","clk":"AK4dAL8UAPIQ","pt":1784528064149,"mc":[{"id":"1.260136658","rc":[{"batl":[[9,48,1.99],[8,46,1.99],[7,44,1.99],[6,42,1.99]],"id":6690508},{"batb":[[9,27,6.36],[8,28,5.96],[7,29,4.75],[6,30,5.68],[5,32,10.16],[4,34,4.56]],"id":69865836},{"batb":[[9,16,3],[8,26,9.21],[7,30,2],[6,38,4.48],[5,44,1.76],[4,46,1]],"id":74493797}]}]}{"op":"ocm","id":1,"clk":"ALEIAO4IAO0OAKoQAIwJ","pt":1784528064289,"ct":"HEARTBEAT"}{"op":"mcm","clk":"ALYdAM0UAPoQ","pt":1784528064457,"mc":[{"id":"1.260137374","rc":[{"batb":[[2,23,1.66]],"id":68064063},{"batb":[[9,16.5,21.56],[8,17,3.12],[7,17.5,3.03],[6,18,2.94],[5,18.5,9.24],[4,19,2.78],[3,20,6.89],[2,22,1.68]],"id":100720592},{"batb":[[2,27,1.27],[0,29,1.8]],"id":100720594}]},{"id":"1.260136658","rc":[{"batb":[[9,26,6.65],[8,27,6.36],[7,28,5.96],[6,29,4.75],[5,30,5.68],[4,32,10.16],[3,34,4.56],[2,40,1.45],[1,44,3.48]],"id":69865836}]}]}{"op":"mcm","clk":"AL8dANIUAP0Q","pt":1784528064608,"mc":[{"id":"1.260136658","rc":[{"batl":[[5,23,1.74]],"id":98996178},{"batl":[[1,9.8,2.64]],"id":100749630},{"batl":[[0,990,1.57]],"id":69161915}]}]}{"op":"mcm","clk":"AMIdANUUAP8Q","pt":1784528064710,"mc":[{"id":"1.260136658","rc":[{"batl":[[6,24,14.02]],"id":98996178},{"batl":[[2,10,6.08]],"id":100749630},{"batb":[[0,280,2.04]],"batl":[[0,990,1.75]],"id":69161915}]}]}{"op":"mcm","clk":"AM4dAN4UAIYR","pt":1784528065019,"mc":[{"id":"1.260136658","rc":[{"batl":[[7,0,0],[6,0,0],[5,920,2.1],[4,600,12.1],[3,440,2.13],[2,260,1.43]],"id":69865836}]}]}{"op":"mcm","clk":"ANUdAOIUAIwR","pt":1784528065221,"mc":[{"id":"1.260136658","rc":[{"batb":[[2,24,2.56]],"id":6690508}]}]}{"op":"mcm","clk":"ANodAOQUAJER","pt":1784528065323,"mc":[{"id":"1.260137374","rc":[{"batb":[[0,29,1.81]],"id":100720594}]}]}{"op":"mcm","clk":"ANodAOUUAJER","pt":1784528065326,"mc":[{"id":"1.260136658","rc":[{"batb":[[9,19,9.07],[8,19.5,6.7],[7,20,4.99],[6,21,6.15],[5,22,5.55],[4,23,4.05],[3,24,2.56],[2,25,2.08],[1,26,5.08]],"id":6690508}]}]}{"op":"mcm","clk":"AOQdAOgUAJkR","pt":1784528065543,"mc":[{"id":"1.260137374","rc":[{"batb":[[0,29,1.71]],"id":100720594}]}]}{"op":"mcm","clk":"AOcdAOoUAJ0R","pt":1784528065633,"mc":[{"id":"1.260136658","rc":[{"batb":[[1,180,1.09]],"id":69161915}]}]}{"op":"mcm","clk":"AOsdAO4UAKMR","pt":1784528065741,"mc":[{"id":"1.260136658","rc":[{"batb":[[0,280,2.57]],"id":69161915}]}]}{"op":"mcm","clk":"AI8eAIYVAMkR","pt":1784528066127,"mc":[{"id":"1.260192334","rc":[{"batb":[[9,6.2,4],[8,6.4,2],[7,6.6,3.04],[6,6.8,36.77],[5,7,16.2],[4,7.2,1],[3,7.8,12.71],[2,8,12.42]],"id":73793682}]}]}{"op":"mcm","clk":"AJgeAJAVANER","pt":1784528066235,"mc":[{"id":"1.260192334","rc":[{"batb":[[9,6.4,2],[8,6.6,3.04],[7,6.8,36.77],[6,7,16.2],[5,7.2,1],[4,7.8,12.71],[3,8,12.42],[2,8.8,1.04],[1,9,2]],"id":73793682}]}]}{"op":"mcm","clk":"AKUeAJ8VAN0R","pt":1784528066439,"mc":[{"id":"1.260136658","rc":[{"batb":[[3,24,4.55]],"id":6690508},{"batb":[[0,280,2.56]],"id":69161915}]}]}{"op":"mcm","clk":"AKceAKIVAN4R","pt":1784528066535,"mc":[{"id":"1.260136658","rc":[{"batl":[[7,44,2.99]],"id":6690508},{"batl":[[7,920,2.1],[6,600,12.1],[5,440,2.13],[4,260,1.22],[3,75,1],[2,70,1.21]],"id":69865836}]}]}{"op":"mcm","clk":"AKgeAKMVAN4R","pt":1784528066539,"mc":[{"id":"1.260192491","rc":[{"batb":[[3,55,4.24]],"id":60010414}]}]}{"op":"mcm","clk":"AKoeAKMVAN8R","pt":1784528066541,"mc":[{"id":"1.260137374","rc":[{"batb":[[9,1.77,7.79],[8,2.08,5.56],[7,2.62,61.29]],"batl":[[9,44,7.36],[8,34,15],[7,22,5.36],[6,9.8,41.47],[5,9.6,11.79]],"id":99274452},{"batb":[[9,1.01,1154.83],[8,1.02,22],[7,1.12,100],[6,1.9,93.09],[5,2.24,222.22],[4,2.32,1],[3,2.36,1],[2,2.38,85.57]],"batl":[[9,34,15],[8,22,5.36],[7,19,1],[6,16,15],[5,5.7,48.78],[4,4.9,26.62]],"id":100720591},{"batl":[[9,0,0],[8,920,2.1],[7,600,12.1],[6,440,2.12],[5,250,10],[4,19,12.05],[3,18,11.17]],"id":25417481}]}]}{"op":"mcm","clk":"ALIeAKsVAOUR","pt":1784528066640,"mc":[{"id":"1.260137374","rc":[{"batb":[[9,1.51,98.04],[8,1.77,7.79],[7,2.08,5.56],[6,2.62,61.29]],"batl":[[9,34,15],[8,22,5.36],[7,10,11.32]],"id":99274452},{"batb":[[9,1.02,22],[8,1.12,100],[7,1.9,93.09],[6,2.24,222.22],[5,2.26,45.61]],"batl":[[9,22,5.36],[8,19,1],[7,16,15],[6,5.7,48.78],[5,5.3,7.81]],"id":100720591},{"batl":[[7,0,0],[6,920,2.1],[5,600,12.1],[4,440,2.12],[3,250,10],[2,85,2.96]],"id":79844992},{"batl":[[4,19,23.22]],"id":25417481}]},{"id":"1.260136658","rc":[{"batl":[[7,44,1.99]],"id":6690508},{"batl":[[7,0,0],[6,0,0],[5,920,2.1],[4,600,12.1],[3,440,2.13],[2,260,1.43]],"id":69865836}]}]}{"op":"mcm","clk":"ALoeAK8VAOsR","pt":1784528066749,"mc":[{"id":"1.260192491","rc":[{"batb":[[9,6.2,9.62],[8,12.5,1.04],[7,16,3],[6,17,1.04],[5,21,1.04],[4,30,2.29]],"id":60010414},{"batl":[[9,3.7,63.65],[8,3.4,45.13],[7,3.3,1],[6,3.25,1],[5,3.2,1],[4,3.15,1],[3,3.1,1],[2,3.05,1],[1,3,28.12]],"id":71121948}]}]}{"op":"mcm","clk":"AMQeALYVAPMR","pt":1784528066948,"mc":[{"id":"1.260192491","rc":[{"batb":[[3,55,3.24]],"id":60010414}]}]}{"op":"mcm","clk":"ANAeAMEVAPoR","pt":1784528067155,"mc":[{"id":"1.260136658","rc":[{"batb":[[4,46,5.8]],"id":99951973},{"batb":[[9,16,3.38],[8,30,2],[7,38,4.48],[6,40,5.24]],"id":74493797}]}]}{"op":"mcm","clk":"ANIeAMMVAP4R","pt":1784528067252,"mc":[{"id":"1.260136658","rc":[{"batl":[[3,8.6,11.79]],"id":79455963}]}]}{"op":"mcm","clk":"ANseAMoVAIkS","pt":1784528067506,"mc":[{"id":"1.260136658","rc":[{"batl":[[4,8.8,3.1]],"id":79455963}]}]}{"op":"mcm","clk":"AN0eAMoVAIsS","pt":1784528067564,"mc":[{"id":"1.260191305","rc":[{"batb":[[9,14.5,3.7],[8,15,12.61]],"id":43568336},{"batb":[[3,2.66,3.76]],"id":38858883},{"batb":[[7,0,0],[6,1.01,1154.26],[5,1.02,12],[4,1.16,100],[3,1.51,98.04],[2,2.12,44.87],[1,80,2.6]],"id":50889685},{"batb":[[3,3.4,2.94]],"id":46065793},{"batb":[[9,2.12,44.64],[8,18.5,7.9],[7,19.5,2.7],[6,20,2.63],[5,21,2.93]],"id":47095286},{"batb":[[9,0,0],[8,1.01,1154.26],[7,1.02,12],[6,1.16,100],[5,1.51,98.04],[4,2.12,44.64],[3,5.5,2],[2,5.9,17.31]],"id":46864009}]}]}{"op":"mcm","clk":"AOEeAMwVAJES","pt":1784528067657,"mc":[{"id":"1.260191305","rc":[{"batb":[[2,20,10.33]],"id":43568336},{"batb":[[0,2.74,39.26]],"id":38858883},{"batb":[[7,1.01,1154.26],[6,1.02,12],[5,1.16,100],[4,1.51,98.04],[3,2.12,44.87],[2,80,2.6],[1,120,1.69],[0,130,3.11]],"id":50889685},{"batb":[[0,3.6,27.77]],"id":46065793},{"batb":[[2,27,7.24]],"id":47095286},{"batb":[[9,1.01,1154.26],[8,1.02,12],[7,1.16,100],[6,1.51,98.04],[5,2.12,44.64],[4,5.5,2],[3,5.9,17.31],[2,6.8,34.77],[1,7,11.9]],"id":46864009}]}]}{"op":"mcm","clk":"AO8eANQVAJYS","pt":1784528067915,"mc":[{"id":"1.260136658","rc":[{"batl":[[5,9,19.77]],"id":79455963}]}]}{"op":"mcm","clk":"AP8eANcVAJgS","pt":1784528068118,"mc":[{"id":"1.260136658","rc":[{"batb":[[0,46,2.6]],"id":69865836}]}]}{"op":"mcm","clk":"AIUfANsVAJwS","pt":1784528068222,"mc":[{"id":"1.260137374","rc":[{"batb":[[9,1.77,7.79],[8,2.08,5.56],[7,2.62,61.29],[6,3.25,23.9],[5,3.35,76.83],[4,3.4,31.19],[3,3.55,13.05],[2,3.7,46.3],[1,3.85,4.08],[0,4,3.96]],"id":99274452}]}]}{"op":"mcm","clk":"AIcfAOAVAJ4S","pt":1784528068323,"mc":[{"id":"1.260136658","rc":[{"trd":[[300,5.09]],"batl":[[0,990,1.69]],"tv":13.34,"id":69161915},{"batl":[[6,9.2,3.66]],"id":79455963}],"tv":2632.92}]}{"op":"mcm","clk":"AIkfAOAVAJ4S","pt":1784528068327,"mc":[{"id":"1.260137374","rc":[{"batb":[[9,1.51,98.04],[8,1.77,7.79],[7,2.08,5.56],[6,2.62,61.29]],"id":99274452}]}]}{"op":"mcm","clk":"AI8fAOcVAKIS","pt":1784528068529,"mc":[{"id":"1.260136658","rc":[{"batl":[[5,9,18.73],[4,8.8,2.06],[3,8.6,10.75]],"id":79455963}]}]}{"op":"mcm","clk":"AKcfAPoVAKsS","pt":1784528068937,"mc":[{"id":"1.260136658","rc":[{"trd":[[21,12.47]],"batb":[[9,15.5,7.59],[8,16,8.73],[7,16.5,3.87],[6,17,5.32],[5,17.5,3.64],[4,18,9.68],[3,18.5,6.48],[2,19,8],[1,19.5,3.22],[0,20,3.54]],"ltp":21,"tv":159.03,"id":80934312}],"tv":2638.11}]}{"op":"ocm","id":1,"clk":"AP4IAJsJAPQPAIURAO0J","pt":1784528069289,"ct":"HEARTBEAT"}{"op":"mcm","clk":"ALgfAIUWALQS","pt":1784528069345,"mc":[{"id":"1.260136803","rc":[{"batb":[[4,14.5,3.7]],"id":99171722}]}]}{"op":"mcm","clk":"ALsfAIgWALUS","pt":1784528069448,"mc":[{"id":"1.260136803","rc":[{"batb":[[9,12.5,20.14],[8,13,13.69],[7,13.5,23.21],[6,14,3.85],[5,14.5,3.7],[4,15,6.57]],"id":99171722}]}]}{"op":"mcm","clk":"AMAfAIoWALcS","pt":1784528069551,"mc":[{"id":"1.260136803","rc":[{"batb":[[0,110,3.01]],"id":100721224}]}]}{"op":"mcm","clk":"AMofAJIWAMAS","pt":1784528069852,"mc":[{"id":"1.260136803","rc":[{"batb":[[0,110,3.23]],"id":100721224}]}]}{"op":"mcm","clk":"ANgfAJgWAMsS","pt":1784528070162,"mc":[{"id":"1.260136658","rc":[{"batl":[[0,230,2.3]],"id":99951973}]}]}{"op":"mcm","clk":"AN4fAJsWAM8S","pt":1784528070220,"mc":[{"id":"1.260136658","rc":[{"batl":[[0,230,2.76]],"id":99951973}]}]}{"op":"mcm","clk":"APUfAKoWANgS","pt":1784528070734,"mc":[{"id":"1.260136658","rc":[{"batl":[[2,790,0.25],[1,470,2.02],[0,380,1.55]],"id":78977433},{"batl":[[2,1000,0.2],[1,990,1.34],[0,980,1.39]],"id":69161915},{"trd":[[21,14.33]],"batb":[[0,20,2.61]],"batl":[[0,23,29.01]],"tv":160.89,"id":80934312}],"tv":2639.97}]}{"op":"mcm","clk":"APcfAK0WANsS","pt":1784528070828,"mc":[{"id":"1.260136658","rc":[{"batl":[[2,0,0],[1,1000,0.2]],"id":69161915},{"batl":[[3,26,3.03]],"id":80934312},{"batl":[[0,8,4.64]],"id":79455963}]}]}{"op":"mcm","clk":"APofALEWAN0S","pt":1784528070939,"mc":[{"id":"1.260136658","rc":[{"batb":[[1,26,6.58]],"id":6690508}]}]}{"op":"mcm","clk":"AP8fALYWAOES","pt":1784528071144,"mc":[{"id":"1.260136658","rc":[{"batb":[[9,12,6.99],[8,12.5,23.63],[7,13,27.75],[6,13.5,8.79],[5,14,8.34],[4,14.5,8.71],[3,15,14.67],[2,15.5,1.45],[1,16,5],[0,16.5,1.06]],"id":56407176},{"batb":[[2,8.4,1.3]],"id":100749630},{"batl":[[0,60,2.7]],"id":69865836},{"batl":[[0,8,1.4]],"id":79455963},{"batl":[[9,650,1],[8,640,1],[7,630,1],[6,620,1],[5,610,1],[4,600,11.02],[3,370,1.05],[2,300,5.61],[1,180,1.51]],"id":74493797}]}]}{"op":"mcm","clk":"AIIgALkWAOQS","pt":1784528071237,"mc":[{"id":"1.260136658","rc":[{"batl":[[9,24,5.13],[8,23,18.66],[7,22,3.99],[6,21,3.99],[5,20,3.99],[4,19.5,3.99],[3,19,1],[2,18.5,2.01],[1,18,6.78],[0,17.5,1.34]],"id":56407176},{"batl":[[9,10.5,11.71],[8,10,11.17],[7,9.6,11.59],[6,9.4,1.11],[5,9.2,3.66],[4,9,18.73],[3,8.8,2.06],[2,8.6,10.75],[1,8.4,22.08],[0,8.2,1.82]],"id":79455963},{"batl":[[1,180,1.18],[0,150,2.93]],"id":74493797}]}]}{"op":"mcm","clk":"AIggAL4WAOgS","pt":1784528071449,"mc":[{"id":"1.260136658","rc":[{"batb":[[1,16,3.5]],"id":56407176}]}]}{"op":"mcm","clk":"AIsgAMAWAOoS","pt":1784528071544,"mc":[{"id":"1.260192340","rc":[{"batb":[[0,8.4,3.19]],"id":62688374}]}]}{"op":"mcm","clk":"AI4gAMIWAOwS","pt":1784528071646,"mc":[{"id":"1.260136658","rc":[{"batl":[[0,150,2.84]],"id":74493797}]}]}{"op":"mcm","clk":"AJsgAMYWAPkS","pt":1784528072049,"mc":[{"id":"1.260136658","rc":[{"batl":[[2,8.6,15.94]],"id":79455963}]}]}{"op":"mcm","clk":"AJ4gAMYWAPkS","pt":1784528072057,"mc":[{"id":"1.260137374","rc":[{"batb":[[8,16,22.27]],"batl":[[5,920,2.1],[4,600,10.02],[3,250,10],[2,180,1],[1,150,3.46],[0,140,11.17]],"id":82788200},{"batl":[[4,920,2.1],[3,600,10.02],[2,240,1],[1,160,3.37],[0,150,11.17]],"id":68064063},{"batl":[[7,13,27.2],[6,10,11.32],[5,9.8,41.47]],"id":99274452},{"batb":[[4,11.5,4]],"batl":[[7,920,2.1],[6,600,12.1],[5,440,2.12],[4,250,10],[3,85,3.03],[2,80,11.17]],"id":4054763},{"batl":[[9,34,15],[8,22,5.36],[7,19,1],[6,16,15],[5,5.7,48.78],[4,5.3,7.81]],"id":100720591},{"batb":[[5,10.5,4]],"batl":[[7,920,2.1],[6,600,12.1],[5,440,2.12],[4,250,10],[3,85,2.58],[2,75,11.55]],"id":79844992},{"batl":[[4,920,2.1],[3,600,10.03],[2,210,1],[1,160,3.37],[0,150,11.17]],"id":100720592},{"batl":[[4,26,16.75],[3,19,23.22]],"id":25417481},{"batb":[[8,23,2.27]],"id":100720598},{"batb":[[8,23,2.27]],"id":100720596},{"batb":[[9,16,3.91],[8,30,2],[7,44,1.15],[6,46,1.11],[5,48,1.27],[4,50,7.82],[3,55,5.46]],"id":100720597}]}]}{"op":"mcm","clk":"AKIgAMYWAPsS","pt":1784528072155,"mc":[{"id":"1.260137374","rc":[{"batl":[[6,920,2.1],[5,600,10.02],[4,250,10],[3,180,1],[2,150,3.46],[1,140,11.17],[0,130,2.6]],"id":82788200},{"batl":[[5,920,2.1],[4,600,10.02],[3,240,1],[2,160,3.37],[1,150,11.17],[0,140,2.56]],"id":68064063},{"batl":[[9,22,5.36],[8,19,1],[7,16,15],[6,6.8,26.62]],"id":100720591},{"batb":[[9,9.4,4],[8,9.6,33.04],[7,9.8,11.17]],"id":79844992},{"batl":[[5,920,2.1],[4,600,10.03],[3,210,1],[2,160,3.37],[1,150,11.17],[0,140,2.51]],"id":100720592}]}]}{"op":"mcm","clk":"AKYgAMcWAP4S","pt":1784528072256,"mc":[{"id":"1.260137374","rc":[{"batl":[[2,150,1.46]],"id":82788200},{"batl":[[2,160,1.37]],"id":68064063},{"batl":[[2,160,1.37]],"id":100720592},{"batb":[[2,30,5.08]],"id":100720598}]}]}{"op":"mcm","clk":"AKsgAMgWAIAT","pt":1784528072306,"mc":[{"id":"1.260137374","rc":[{"batb":[[0,34,2.03]],"id":100720598}]}]}{"op":"mcm","clk":"ALEgAMkWAIMT","pt":1784528072459,"mc":[{"id":"1.260137374","rc":[{"batb":[[2,12.5,16.75]],"id":4054763}]}]}{"op":"mcm","clk":"ALEgAMsWAIMT","pt":1784528072460,"mc":[{"id":"1.260136658","rc":[{"batb":[[0,16.5,1.91]],"id":56407176}]}]}{"op":"mcm","clk":"ALYgAM4WAIQT","pt":1784528072563,"mc":[{"id":"1.260136658","rc":[{"batb":[[9,12.5,23.63],[8,13,27.75],[7,13.5,8.79],[6,14,8.34],[5,14.5,8.71],[4,15,13.82],[3,15.5,1.45],[2,16,3.5],[1,16.5,1.91],[0,17,1.34]],"id":56407176}]}]}{"op":"mcm","clk":"ALggANAWAIYT","pt":1784528072614,"mc":[{"id":"1.260136658","rc":[{"batl":[[3,8.8,7.25]],"id":79455963}]}]}{"op":"mcm","clk":"ALkgANEWAIcT","pt":1784528072715,"mc":[{"id":"1.260136658","rc":[{"batl":[[9,25,5.15],[8,24,5.13],[7,23,18.66],[6,22,3.99],[5,21,3.99],[4,20,3.99],[3,19.5,3.99],[2,19,1],[1,18.5,2.01],[0,18,6.78]],"id":56407176}]}]}{"op":"mcm","clk":"AMIgANYWAIkT","pt":1784528072824,"mc":[{"id":"1.260136658","rc":[{"batl":[[4,9,23.92],[0,8.2,3.49]],"id":79455963}]}]}{"op":"mcm","clk":"ANggAOEWAJIT","pt":1784528073230,"mc":[{"id":"1.260136658","rc":[{"batl":[[5,9.2,8.86]],"id":79455963}]}]}{"op":"mcm","clk":"AOMgAOUWAJYT","pt":1784528073435,"mc":[{"id":"1.260137374","rc":[{"batb":[[2,23,3.93],[1,24,2.23]],"id":68064063},{"batb":[[9,17,3.12],[8,17.5,3.03],[7,18,2.94],[6,18.5,9.24],[5,19,2.78],[4,20,6.89],[3,22,1.68],[2,23,2.27]],"id":100720592},{"batb":[[9,23,2.27],[8,24,2.17],[7,25,2.08],[6,26,2],[5,27,1.92],[4,28,6.06],[3,29,2.73]],"id":100720598},{"batb":[[3,26,3.65],[2,27,3.19]],"id":100720594}]}]}{"op":"mcm","clk":"AOYgAOoWAJcT","pt":1784528073440,"mc":[{"id":"1.260136658","rc":[{"batb":[[9,40,5.24],[8,42,1.22],[7,44,2.91],[6,46,1.44],[5,48,1.06],[4,50,1.69]],"batl":[[9,630,1],[8,620,1],[7,610,1],[6,600,11.02],[5,370,1.05],[4,300,5.19],[3,220,1.01],[2,170,1],[1,160,1.59]],"id":74493797}]}]}{"op":"mcm","clk":"AOggAOwWAJsT","pt":1784528073537,"mc":[{"id":"1.260136658","rc":[{"batl":[[9,48,2.99],[8,46,2.99],[7,44,2.99],[6,42,2.99]],"id":6690508},{"batb":[[9,29,4.75],[8,30,5.68],[7,32,10.16],[6,34,4.56],[5,36,1.43],[4,38,1.35],[3,40,1.45],[2,42,1.22]],"batl":[[7,920,2.1],[6,600,12.1],[5,440,2.13],[4,260,1.01],[3,80,1.21],[2,75,1.21]],"id":69865836},{"batl":[[6,9.4,6.3]],"id":79455963},{"batb":[[9,40,6.52]],"id":74493797}]}]}{"op":"mcm","clk":"APIgAO8WAKkT","pt":1784528073741,"mc":[{"id":"1.260136803","rc":[{"trd":[[3.75,25.95]],"batb":[[9,0,0],[8,1.01,1154.83],[7,1.02,22],[6,1.12,100],[5,2.14,16.14],[4,2.3,83.79],[3,2.5,149.63],[2,2.64,58.66],[1,2.66,53.05],[0,2.76,9.23]],"ltp":3.75,"tv":92.69,"id":100721219}],"tv":399.52}]}{"op":"mcm","clk":"APQgAPEWAKoT","pt":1784528073746,"mc":[{"id":"1.260192491","rc":[{"batb":[[9,16,3],[8,17,1.04],[7,21,1.04],[6,30,2.29],[5,48,1.06],[4,50,1.02]],"id":60010414},{"batl":[[0,2.92,3.31]],"id":71121948}]}]}{"op":"mcm","clk":"APwgAPEWAK8T","pt":1784528073847,"mc":[{"id":"1.260137374","rc":[{"batb":[[2,23,1.66],[1,24,1.23]],"id":68064063},{"batb":[[9,16.5,21.56],[8,17,3.12],[7,17.5,3.03],[6,18,2.94],[5,18.5,9.24],[4,19,2.78],[3,20,6.89],[2,22,1.68]],"id":100720592},{"batb":[[2,27,1.27]],"id":100720594}]}]}{"op":"mcm","clk":"APwgAPMWAK8T","pt":1784528073848,"mc":[{"id":"1.260136658","rc":[{"batl":[[7,9.6,16.78]],"id":79455963},{"batb":[[9,30,2],[8,38,4.48],[7,40,6.52],[6,42,1.22],[5,44,1.76],[4,46,1]],"batl":[[9,650,1],[8,640,1],[7,630,1],[6,620,1],[5,610,1],[4,600,11.02],[3,370,1.05],[2,300,5.61],[1,180,1.18]],"id":74493797}]},{"id":"1.260136803","rc":[{"batb":[[9,1.01,1154.83],[8,1.02,22],[7,1.12,100],[6,2.14,16.14],[5,2.3,83.79],[4,2.5,149.63],[3,2.52,6.95]],"id":100721219},{"batb":[[0,80,3.27]],"id":57883707}]}]}{"op":"mcm","clk":"APwgAPYWALET","pt":1784528073851,"mc":[{"id":"1.260192491","rc":[{"batl":[[9,3.3,1],[8,3.25,1],[7,3.2,1],[6,3.15,1],[5,3.1,1],[4,3.05,1],[3,3,28.12],[2,2.96,1],[1,2.94,1]],"id":71121948}]}]}{"op":"mcm","clk":"AJQhAIgXAMQT","pt":1784528074259,"mc":[{"id":"1.260136658","rc":[{"batl":[[9,10,11.17],[8,9.8,5.19]],"id":79455963}]}]}{"op":"ocm","id":1,"clk":"AK0JAL8JAIwRAPMRALwK","pt":1784528074289,"ct":"HEARTBEAT"}{"op":"mcm","clk":"AKMhAJIXAMsT","pt":1784528074416,"mc":[{"id":"1.260136658","rc":[{"batl":[[9,10,16.36]],"id":79455963}]}]}{"op":"mcm","clk":"AL0hAKwXAOIT","pt":1784528075031,"mc":[{"id":"1.260136658","rc":[{"trd":[[17,2.68]],"batb":[[9,12,6.99],[8,12.5,23.63],[7,13,27.75],[6,13.5,8.79],[5,14,8.34],[4,14.5,8.71],[3,15,13.82],[2,15.5,1.45],[1,16,3.5],[0,16.5,1.91]],"ltp":17,"tv":110.93,"id":56407176},{"trd":[[75,7.56]],"batb":[[9,16,3.38],[8,30,2],[7,38,4.48],[6,40,6.52],[5,42,1.22],[4,44,1.76],[3,46,1],[2,55,1.31],[1,60,3.55],[0,70,1.33]],"ltp":75,"tv":21.49,"id":74493797}],"tv":2648.21}]}{"op":"mcm","clk":"AMEhAK4XAOUT","pt":1784528075137,"mc":[{"id":"1.260191301","rc":[{"batb":[[9,1.51,98.04],[8,2.04,5.77],[7,2.12,44.64],[6,2.46,4.11]],"id":73179259}]}]}{"op":"mcm","clk":"AMQhALEXAOkT","pt":1784528075235,"mc":[{"id":"1.260191301","rc":[{"batb":[[9,2.04,5.77],[8,2.12,44.64],[7,2.46,4.11],[6,3.85,16.14],[5,3.9,34.82]],"id":73179259}]}]}{"op":"mcm","clk":"AM0hALMXAO4T","pt":1784528075339,"mc":[{"id":"1.260136658","rc":[{"batl":[[9,48,1.99],[8,46,1.99],[7,44,1.99],[6,42,1.99]],"id":6690508},{"batb":[[9,26,6.65],[8,27,6.36],[7,28,5.96],[6,29,4.75],[5,30,5.68],[4,32,10.16],[3,34,4.56],[2,40,1.45]],"batl":[[7,0,0],[6,0,0],[5,920,2.1],[4,600,12.1],[3,440,2.13],[2,260,1.43]],"id":69865836}]}]}{"op":"mcm","clk":"AOQhAL4XAPgT","pt":1784528075747,"mc":[{"id":"1.260136658","rc":[{"batb":[[9,0,0],[8,1.01,1154.83],[7,1.02,73.91],[6,1.16,100],[5,1.51,98.04],[4,4.6,3.4],[3,16,3],[2,30,2.22],[1,75,3.84]],"batl":[[1,0,0]],"id":69161915}]}]}{"op":"mcm","clk":"AOkhAMMXAPsT","pt":1784528075851,"mc":[{"id":"1.260136666","rc":[{"batb":[[9,15.5,3.45],[8,16,3.86],[2,25,3.5]],"batl":[[9,0,0],[8,920,2.1],[7,610,1],[6,600,13.1],[5,590,3.6],[4,440,2.12]],"id":88111702}]}]}{"op":"mcm","clk":"AOshAMQXAP4T","pt":1784528075950,"mc":[{"id":"1.260136803","rc":[{"batb":[[9,1.51,98.04],[8,2.12,44.64],[7,3.05,24.39],[6,4.1,16.13],[5,4.6,2.88],[4,6.2,9.62],[3,16,3.22],[1,150,2]],"batl":[[1,0,0]],"id":100721225},{"batb":[[9,1.51,98.04],[8,2.12,44.64],[7,2.6,3.75],[6,3.2,2.73],[5,5.1,34.13],[4,5.8,16.14],[3,5.9,20.08],[2,6.4,2.44],[1,6.8,2.51]],"batl":[[9,440,2.12],[8,250,10],[7,65,2],[6,44,7.36],[5,34,15],[4,32,16.14]],"id":100721218},{"batb":[[9,0,0],[8,0,0],[7,1.01,1154.83],[6,1.02,22],[5,1.12,100],[4,2.14,16.14],[3,2.3,83.79],[2,2.52,6.95]],"batl":[[3,6.2,11.17]],"id":100721219}]}]}{"op":"mcm","clk":"AO4hAMQXAP8T","pt":1784528075952,"mc":[{"id":"1.260137374","rc":[{"batb":[[9,17,3.12],[8,17.5,3.03],[7,18,10.15],[6,18.5,2.86],[5,19,2.78],[4,20,2.63]],"batl":[[5,0,0],[4,920,2.1],[3,600,10.02],[2,240,1]],"id":68064063},{"batb":[[9,1.12,100],[8,1.51,98.04],[7,1.77,7.79],[6,2.08,5.56],[5,2.62,61.29],[2,3.7,17.65]],"batl":[[9,44,7.36],[8,34,15],[7,22,5.36],[6,13,27.2],[5,10,11.32]],"id":99274452},{"batb":[[9,9.2,4],[8,9.4,4],[2,12.5,2]],"batl":[[7,0,0],[6,920,2.1],[5,600,12.1],[4,440,2.12],[3,250,10]],"id":79844992},{"batb":[[9,16,3.33],[8,16.5,3.23],[7,17,3.12],[6,17.5,3.03],[5,18,2.94],[4,18.5,9.24],[3,19,3.26]],"batl":[[5,0,0],[4,920,2.1],[3,600,10.03],[2,210,1]],"id":100720592},{"batb":[[9,19.5,2.7],[8,20,8.67],[7,21,2.5],[6,22,2.38],[5,23,2.27],[4,24,2.17]],"batl":[[4,0,0],[3,600,10.02],[2,300,1]],"id":100720594}]}]}{"op":"mcm","clk":"AO4hAMYXAP8T","pt":1784528075954,"mc":[{"id":"1.260136666","rc":[{"batb":[[3,24,2.17]],"id":88111702}]}]}{"op":"mcm","clk":"AIoiANsXAI0U","pt":1784528076415,"mc":[{"id":"1.260136803","rc":[{"batb":[[8,1.01,1154.83],[7,1.02,22],[6,1.12,100],[5,2.14,16.14],[4,2.3,83.79],[3,2.52,6.95],[2,2.66,53.05],[1,2.76,9.23],[0,2.78,1.88]],"id":100721219}]}]}{"op":"mcm","clk":"AI4iANwXAJAU","pt":1784528076515,"mc":[{"id":"1.260137374","rc":[{"batb":[[9,15.5,3.45],[8,16,3.33],[7,16.5,3.23],[6,17,3.12],[5,17.5,3.03],[4,18,10.15],[3,18.5,2.86]],"id":68064063},{"batb":[[9,18,2.94],[8,18.5,9.61],[7,19,2.78],[6,19.5,2.7],[5,20,8.67],[4,21,2.5],[3,26,1.65]],"id":100720594}]}]}{"op":"mcm","clk":"AI4iAN4XAJAU","pt":1784528076522,"mc":[{"id":"1.260136666","rc":[{"batb":[[9,14.5,11.57],[8,15,19.71],[7,15.5,3.45],[6,16,3.86],[5,20,3.15],[4,21,9.77],[3,22,3.3],[2,25,1.42]],"id":88111702}]},{"id":"1.260136658","rc":[{"batl":[[7,44,2.99]],"id":6690508},{"batl":[[7,920,2.1],[6,600,12.1],[5,440,2.13],[4,260,1.22],[3,75,1],[2,70,1.21]],"id":69865836},{"trd":[[21,14.55]],"batb":[[9,16,8.73],[8,16.5,3.87],[7,17,5.32],[6,17.5,3.64],[5,18,9.68],[4,18.5,6.48],[3,19,8],[2,19.5,3.22],[1,20,2.61],[0,21,3.59]],"batl":[[0,23,28.9]],"tv":161.11,"id":80934312}],"tv":2648.43}]}{"op":"mcm","clk":"AI4iAN8XAJEU","pt":1784528076565,"mc":[{"id":"1.260192491","rc":[{"batb":[[3,55,4.24]],"id":60010414}]}]}{"op":"mcm","clk":"AI8iAOIXAJIU","pt":1784528076616,"mc":[{"id":"1.260136803","rc":[{"batb":[[0,2.78,5.11]],"id":100721219}]}]}{"op":"mcm","clk":"AJAiAOMXAJMU","pt":1784528076620,"mc":[{"id":"1.260136658","rc":[{"batb":[[2,15.5,2.95]],"id":56407176},{"batl":[[3,26,10.41]],"id":80934312}]}]}{"op":"mcm","clk":"AJUiAOgXAJYU","pt":1784528076719,"mc":[{"id":"1.260136658","rc":[{"batl":[[7,44,1.99]],"id":6690508},{"batl":[[7,0,0],[6,0,0],[5,920,2.1],[4,600,12.1],[3,440,2.13],[2,260,1.43]],"id":69865836}]}]}{"op":"mcm","clk":"AJYiAOkXAJcU","pt":1784528076766,"mc":[{"id":"1.260192491","rc":[{"batb":[[9,6.2,9.62],[8,12.5,1.04],[7,16,3],[6,17,1.04],[5,21,1.04],[4,30,2.29],[3,55,3.24]],"id":60010414},{"batl":[[9,3.7,63.65],[8,3.4,45.13],[7,3.3,1],[6,3.25,1],[5,3.2,1],[4,3.15,1],[3,3.1,1],[2,3.05,1],[1,3,28.12],[0,2.92,2.31]],"id":71121948}]}]}{"op":"mcm","clk":"AKIiAO4XAKAU","pt":1784528077126,"mc":[{"id":"1.260137374","rc":[{"batb":[[1,13,4]],"id":4054763}]}]}{"op":"mcm","clk":"AKQiAPAXAKIU","pt":1784528077227,"mc":[{"id":"1.260137374","rc":[{"batb":[[0,25,3.95]],"id":68064063},{"batb":[[9,9.8,4],[8,10,4],[7,10.5,4],[6,11,4],[5,11.5,4],[4,12,7.31],[3,12.5,16.75],[2,13,4],[1,13.5,5.9],[0,14,9.72]],"id":4054763}]}]}{"op":"mcm","clk":"AKoiAPQXAKQU","pt":1784528077332,"mc":[{"id":"1.260137374","rc":[{"batb":[[9,10,4],[8,10.5,4],[7,11,4],[6,11.5,4],[5,12,7.31],[4,12.5,16.75],[3,13,4],[2,13.5,1.11],[1,14,9.72],[0,14.5,2.66]],"id":4054763}]}]}{"op":"mcm","clk":"AKsiAPcXAKcU","pt":1784528077432,"mc":[{"id":"1.260136658","rc":[{"batb":[[9,1.02,73.91],[8,1.16,100],[7,1.51,98.04],[6,4.6,3.4],[5,16,3],[4,30,2.22],[3,75,3.46],[2,130,2.3],[1,200,1.02]],"batl":[[1,1000,0.2]],"id":69161915}]}]}{"op":"mcm","clk":"AK4iAPoXAKwU","pt":1784528077536,"mc":[{"id":"1.260136666","rc":[{"batb":[[9,15.5,3.45],[8,16,3.33],[7,19.5,14.95],[6,20,3.15],[5,21,9.77],[4,22,3.3],[3,25,1.02],[2,26,4.97]],"batl":[[9,920,2.1],[8,610,1],[7,600,13.1],[6,590,3.6],[5,440,2.12],[4,210,1.16]],"id":88111702}]},{"id":"1.260136803","rc":[{"batb":[[9,2.12,44.64],[8,3.05,24.39],[7,4.1,16.13],[6,4.6,2.88],[5,6.2,9.62],[4,16,3.22],[3,90,3.21],[1,150,2.82]],"batl":[[1,850,0.25]],"id":100721225},{"batb":[[9,2.12,44.64],[8,2.6,3.75],[7,3.2,2.73],[6,5.1,34.13],[5,5.8,77.56],[4,5.9,20.08],[3,6.4,2.44],[2,6.8,2.51],[1,7,21.06]],"batl":[[9,250,10],[8,65,2],[7,44,7.36],[6,34,15],[5,32,16.14],[4,22,9.6]],"id":100721218},{"batb":[[9,1.02,22],[8,1.12,100],[7,2.14,16.14],[6,2.3,83.79],[5,2.52,6.95],[4,2.66,53.05],[3,2.76,9.23],[2,2.78,5.11],[1,2.9,118.13],[0,3.1,45.81]],"batl":[[9,22,5.36],[8,18,3.05],[7,16,15],[6,8.4,5.82],[5,8.2,41.98]],"id":100721219}]}]}{"op":"mcm","clk":"ALEiAPoXAK0U","pt":1784528077538,"mc":[{"id":"1.260137374","rc":[{"batb":[[9,16,3.33],[8,16.5,3.23],[7,17,3.12],[6,17.5,20.25],[5,18,2.94],[4,18.5,2.86],[3,22,5.8]],"batl":[[5,920,2.1],[4,600,10.02],[3,240,1],[2,170,1.28]],"id":68064063},{"batb":[[9,1.51,98.04],[8,1.77,7.79],[7,2.08,5.56],[6,2.62,61.29],[5,3.4,106.41],[4,3.55,13.05],[3,3.7,17.25],[2,3.75,28.54]],"batl":[[5,10,51.87]],"id":99274452},{"batb":[[9,9.4,4],[8,9.6,33.04],[2,12.5,12.59]],"batl":[[7,920,2.1],[6,600,12.1],[5,440,2.12],[4,250,10],[3,85,2.58]],"id":79844992},{"batb":[[9,16.5,3.23],[8,17,20.88],[7,17.5,3.03],[6,18,2.94],[5,18.5,9.24],[4,19,2.78],[3,21,6.57]],"batl":[[5,920,2.1],[4,600,10.03],[3,210,1],[2,160,1.37]],"id":100720592},{"batb":[[6,19.5,18.06],[3,26,6.52]],"batl":[[4,600,10.02],[3,300,1],[2,210,1.04]],"id":100720594}]}]}{"op":"mcm","clk":"ALMiAPsXALAU","pt":1784528077637,"mc":[{"id":"1.260136803","rc":[{"batb":[[9,1.01,1154.83],[8,1.02,22],[7,1.12,100],[6,2.14,16.14],[5,2.3,83.79]],"id":100721219}]}]}{"op":"mcm","clk":"ALUiAPsXALAU","pt":1784528077639,"mc":[{"id":"1.260137374","rc":[{"batb":[[9,16.5,3.23],[8,17,3.12],[7,17.5,20.25],[6,18,2.94],[5,18.5,2.86],[4,19.5,7.21]],"id":68064063}]}]}{"op":"mcm","clk":"ALUiAP0XALIU","pt":1784528077644,"mc":[{"id":"1.260136666","rc":[{"batb":[[1,27,1.66]],"id":88111702}]}]}{"op":"mcm","clk":"ALciAP8XALMU","pt":1784528077738,"mc":[{"id":"1.260136666","rc":[{"batb":[[9,15,19.71],[8,15.5,3.45],[7,16,3.33],[6,19.5,14.95],[5,20,3.15],[4,21,9.77],[3,22,3.72]],"id":88111702}]}]}{"op":"mcm","clk":"AMMiAIcYAMIU","pt":1784528078045,"mc":[{"id":"1.260136658","rc":[{"batb":[[3,24,5.55]],"id":6690508},{"batb":[[9,26,7.65],[8,27,7.36],[7,28,6.96],[6,29,5.75]],"id":69865836}]}]}{"op":"mcm","clk":"AMYiAIcYAMIU","pt":1784528078047,"mc":[{"id":"1.260137374","rc":[{"batb":[[0,25,3.57]],"id":68064063},{"batb":[[3,11.5,4.61]],"id":79844992}]}]}{"op":"mcm","clk":"AM0iAIwYAMUU","pt":1784528078158,"mc":[{"id":"1.260137374","rc":[{"batb":[[1,13,11.51]],"id":79844992}]}]}{"op":"mcm","clk":"AM4iAI0YAMcU","pt":1784528078248,"mc":[{"id":"1.260136803","rc":[{"batb":[[9,1.12,100],[8,1.51,98.04],[7,2.12,44.64],[6,3.05,24.39],[5,4.1,16.13],[4,4.6,2.88],[3,6.2,9.62],[2,16,3.22],[1,90,3.91],[0,150,2.93]],"id":100721225}]}]}{"op":"mcm","clk":"ANEiAJEYAMkU","pt":1784528078351,"mc":[{"id":"1.260136803","rc":[{"batb":[[9,2.12,44.64],[8,3.05,24.39],[7,4.1,16.13],[6,4.6,2.88],[5,6.2,9.62],[4,16,3.22],[3,90,3.21],[2,95,2.6],[1,100,3.3]],"id":100721225}]}]}{"op":"mcm","clk":"ANIiAJQYAMkU","pt":1784528078355,"mc":[{"id":"1.260136658","rc":[{"trd":[[8,84.2]],"tv":348.98,"id":79455963}],"tv":2653.51}]}{"op":"mcm","clk":"ANUiAJYYAMsU","pt":1784528078451,"mc":[{"id":"1.260136658","rc":[{"batl":[[9,32,1],[8,30,1],[7,29,1],[6,28,2],[5,27,5.78],[4,26,10.41],[3,25,2.31],[2,24,14.25],[1,23,28.9],[0,22,3.5]],"id":80934312},{"batb":[[1,7.4,14.55]],"id":79455963}]}]}{"op":"mcm","clk":"ANkiAJkYAM0U","pt":1784528078553,"mc":[{"id":"1.260136658","rc":[{"batb":[[1,7.4,10.7]],"id":79455963}]}]}{"op":"mcm","clk":"ANwiAJkYAM0U","pt":1784528078554,"mc":[{"id":"1.260137374","rc":[{"batb":[[9,15,3.57],[8,15.5,3.45],[7,16,22.27],[6,16.5,3.23],[5,17,3.12],[4,17.5,3.03],[3,18,3.73]],"id":82788200},{"batb":[[5,18.5,2.86]],"id":100720592}]}]}{"op":"mcm","clk":"AN0iAJoYAM8U","pt":1784528078658,"mc":[{"id":"1.260136658","rc":[{"batb":[[5,18,5.43],[1,20,11.96]],"batl":[[4,26,3.03]],"id":80934312}]}]}{"op":"mcm","clk":"AOEiAJoYAM8U","pt":1784528078659,"mc":[{"id":"1.260137374","rc":[{"batb":[[9,15.5,3.45],[8,16,22.27],[7,16.5,3.23],[6,17,3.12],[5,17.5,3.03],[4,18,3.73],[3,19.5,9.19],[2,20,1],[1,21,3.42],[0,22,7.52]],"id":82788200},{"batb":[[2,22,8.07]],"id":100720592}]}]}{"op":"mcm","clk":"AOUiAJsYANIU","pt":1784528078759,"mc":[{"id":"1.260137374","rc":[{"batb":[[9,16,22.27],[8,16.5,3.23],[7,17,3.12],[6,17.5,3.03],[5,18,3.73],[4,19.5,9.19],[3,20,1],[2,21,1.42],[1,22,7.52],[0,23,3.76]],"id":82788200}]}]}{"op":"mcm","clk":"APciAKUYANsU","pt":1784528079116,"mc":[{"id":"1.260136658","rc":[{"batl":[[6,24,2.85]],"id":98996178}]},{"id":"1.260136803","rc":[{"batb":[[0,150,3.05]],"id":100721225},{"batb":[[2,2.78,3.23]],"id":100721219}]}]}{"op":"mcm","clk":"AP0iAKgYAN4U","pt":1784528079218,"mc":[{"id":"1.260136803","rc":[{"batb":[[0,150,2.94]],"id":100721225}]}]}{"op":"ocm","id":1,"clk":"AOoJAOgJAJcSAPESAJEL","pt":1784528079289,"ct":"HEARTBEAT"}{"op":"mcm","clk":"AKcjAMgYAPYU","pt":1784528079829,"mc":[{"id":"1.260136658","rc":[{"batl":[[2,1000,0.2],[1,980,1.04],[0,970,1.71]],"id":69161915}]}]}{"op":"mcm","clk":"AKwjAMwYAPgU","pt":1784528079931,"mc":[{"id":"1.260136658","rc":[{"batb":[[0,70,1.66]],"id":74493797}]}]}{"op":"mcm","clk":"ALQjAM8YAPwU","pt":1784528080040,"mc":[{"id":"1.260137374","rc":[{"batb":[[5,20,2.63],[2,27,5.57]],"id":100720594}]}]}{"op":"mcm","clk":"AL0jANMYAIMV","pt":1784528080242,"mc":[{"id":"1.260137374","rc":[{"batb":[[1,22,6.98]],"id":82788200}]}]}{"op":"mcm","clk":"AMEjANQYAIUV","pt":1784528080343,"mc":[{"id":"1.260137374","rc":[{"batb":[[0,23,4.3]],"id":82788200}]}]}{"op":"mcm","clk":"APwjAPYYAK0V","pt":1784528081427,"mc":[{"id":"1.260136589","rc":[{"batb":[[1,13,6],[0,14,4.65]],"id":82602855}]}]}{"op":"mcm","clk":"APwjAPgYAK4V","pt":1784528081436,"mc":[{"id":"1.260136658","rc":[{"batb":[[4,14.5,10.7]],"id":56407176}]}]}{"op":"mcm","clk":"AIMkAPgYALEV","pt":1784528081529,"mc":[{"id":"1.260137374","rc":[{"batl":[[9,34,15],[8,30,2]],"id":99274452},{"batl":[[8,920,2.1],[7,600,12.1],[6,440,2.12],[5,250,10],[4,180,2]],"id":4054763},{"batl":[[8,920,2.1],[7,600,12.1],[6,440,2.12],[5,250,10],[4,180,2]],"id":79844992},{"batl":[[9,920,2.1],[8,600,12.1],[7,440,2.12],[6,250,10],[5,55,2]],"id":25417481}]},{"id":"1.260136589","rc":[{"batb":[[2,6.4,2.34],[1,6.6,3.14],[0,6.8,1.47]],"id":62098141}]}]}{"op":"mcm","clk":"AIMkAPoYALEV","pt":1784528081531,"mc":[{"id":"1.260136658","rc":[{"batl":[[3,21,9.03],[2,20,3.35]],"id":98996178},{"batl":[[2,0,0],[1,790,0.27]],"id":78977433},{"batb":[[1,120,1.19],[0,130,2]],"id":99951973},{"batb":[[6,6.4,15.77],[1,7.4,18.48]],"batl":[[4,9,17.08]],"id":79455963},{"batb":[[1,60,1.55],[0,70,3.66]],"id":74493797}]}]}{"op":"mcm","clk":"AIkkAPwYALUV","pt":1784528081625,"mc":[{"id":"1.260136589","rc":[{"batb":[[9,5.5,13.33],[8,5.6,39.99],[7,5.7,14.85],[6,5.8,12.5],[5,5.9,13.97],[4,6,12.42],[3,6.2,11.54]],"id":62098141}]}]}{"op":"mcm","clk":"AK8kAKEZANIV","pt":1784528082553,"mc":[{"id":"1.260136658","rc":[{"batb":[[1,60,1.56]],"id":74493797}]}]}{"op":"mcm","clk":"ALkkAKsZANoV","pt":1784528082853,"mc":[{"id":"1.260136803","rc":[{"batb":[[9,4.1,16.13],[8,4.9,11.44],[7,5.7,50.55],[6,5.8,16.14],[5,6.2,5.79],[4,6.4,6.5]],"id":77728021}]}]}{"op":"mcm","clk":"AMkkALUZAOEV","pt":1784528083161,"mc":[{"id":"1.260136658","rc":[{"batl":[[9,640,1],[8,630,1],[7,620,1],[6,610,1],[5,600,11.02],[4,370,1.05],[3,300,5.61],[2,180,1.18],[1,150,2.15],[0,120,1.27]],"id":74493797}]}]}{"op":"mcm","clk":"AMwkALgZAOQV","pt":1784528083263,"mc":[{"id":"1.260136658","rc":[{"batl":[[9,630,1],[8,620,1],[7,610,1],[6,600,11.02],[5,370,1.05],[4,300,5.61],[3,180,1.18],[2,150,2.15],[1,120,1.07],[0,100,2.2]],"id":74493797}]}]}{"op":"mcm","clk":"ANAkALwZAOUV","pt":1784528083363,"mc":[{"id":"1.260136658","rc":[{"batl":[[9,640,1],[8,630,1],[7,620,1],[6,610,1],[5,600,11.02],[4,370,1.05],[3,300,5.61],[2,180,1.33]],"id":74493797}]}]}{"op":"mcm","clk":"ANMkAMAZAOgV","pt":1784528083467,"mc":[{"id":"1.260136658","rc":[{"batl":[[9,48,2.99],[8,46,2.99],[7,44,2.99],[6,42,2.99]],"id":6690508},{"batb":[[9,29,5.75],[8,30,5.68],[7,32,10.16],[6,34,4.56],[5,36,1.43],[4,38,1.35],[3,40,1.45],[2,42,1.22]],"batl":[[7,920,2.1],[6,600,12.1],[5,440,2.13],[4,260,1.01],[3,80,1.21],[2,75,1.21]],"id":69865836},{"batl":[[3,1000,1.2],[2,990,1]],"id":69161915},{"batb":[[1,120,2.19],[0,130,3]],"id":99951973},{"batb":[[9,38,5.83],[8,40,6.52],[7,42,1.22],[6,44,2.91],[5,46,1.44],[4,48,1.06],[3,50,1.69]],"batl":[[9,610,1],[8,600,11.02],[7,370,1.05],[6,300,5.61],[5,180,1.59],[4,170,1],[3,160,1.74],[2,130,1]],"id":74493797}]}]}{"op":"mcm","clk":"ANckAMAZAOgV","pt":1784528083468,"mc":[{"id":"1.260137374","rc":[{"batb":[[9,17.5,20.25],[8,18,2.94],[7,18.5,2.86],[6,19.5,7.21],[5,20,2.63],[4,21,2.5],[2,23,3.93]],"id":68064063},{"batb":[[9,17,20.88],[8,17.5,3.03],[7,18,2.94],[6,18.5,2.86],[5,19,2.78],[4,21,6.57],[3,22,8.07],[2,23,2.27]],"id":100720592},{"batb":[[9,19.5,18.06],[8,20,2.63],[7,21,2.5],[6,23,2.27],[5,24,2.17],[4,25,2.08]],"id":100720594}]}]}{"op":"mcm","clk":"AOAkAMUZAPEV","pt":1784528083669,"mc":[{"id":"1.260192491","rc":[{"batb":[[9,16,3],[8,17,1.04],[7,21,1.04],[6,30,2.29],[5,48,1.06],[4,50,1.02]],"id":60010414},{"batl":[[9,3.4,45.13],[8,3.3,1],[7,3.25,1],[6,3.2,1],[5,3.15,1],[4,3.1,1],[3,3.05,1],[2,3,28.12],[1,2.96,1]],"id":71121948}]}]}{"op":"mcm","clk":"AOgkAMwZAPsV","pt":1784528083928,"mc":[{"id":"1.260136658","rc":[{"batl":[[9,48,1.99],[8,46,1.99],[7,44,1.99],[6,42,1.99]],"id":6690508},{"batb":[[9,26,7.65],[8,27,7.36],[7,28,6.96],[6,29,5.75],[5,30,5.68],[4,32,10.16],[3,34,4.56],[2,40,1.45]],"batl":[[7,0,0],[6,0,0],[5,920,2.1],[4,600,12.1],[3,440,2.13],[2,260,1.43]],"id":69865836},{"batl":[[3,0,0],[2,1000,0.2]],"id":69161915},{"batb":[[1,120,1.19],[0,130,2]],"id":99951973},{"batb":[[9,16,3.38],[8,30,2],[7,38,5.83],[6,40,6.52],[5,42,1.22],[4,44,1.76],[3,46,1]],"batl":[[9,640,1],[8,630,1],[7,620,1],[6,610,1],[5,600,11.02],[4,370,1.05],[3,300,5.61],[2,180,1.33]],"id":74493797}]}]}{"op":"mcm","clk":"AO8kAM4ZAPwV","pt":1784528084029,"mc":[{"id":"1.260137374","rc":[{"batb":[[9,22,2.38],[8,23,2.27],[7,24,2.17],[6,25,2.08],[5,26,2],[4,27,1.92],[3,28,6.06],[2,29,2.73],[0,34,5.41]],"id":100720598}]}]}{"op":"mcm","clk":"APMkANEZAIIW","pt":1784528084135,"mc":[{"id":"1.260137374","rc":[{"batb":[[2,29,3.51],[1,34,5.02],[0,36,2.39]],"id":100720598}]},{"id":"1.260136803","rc":[{"batb":[[9,1.51,98.04],[8,2.12,44.64],[7,3.05,24.39],[6,4.1,16.13],[5,4.6,2.88],[4,6.2,9.62],[3,16,3.2],[2,65,5.03],[1,70,2.8],[0,100,2.07]],"id":100721224},{"batl":[[9,440,2.12],[8,250,10],[7,65,2],[6,44,7.36],[5,34,15],[4,32,16.14],[3,22,9.6],[2,19,11.69]],"id":100721218},{"batl":[[9,27,2],[8,22,5.36],[7,18,3.05],[6,16,15],[5,8.4,5.82],[4,8.2,41.98],[3,6.8,20.23]],"id":100721219},{"batb":[[9,3.45,2.45],[8,4.1,16.13],[7,4.9,11.44],[6,5.7,50.55],[5,5.8,16.14],[4,6.2,5.79],[3,6.4,6.5],[2,6.6,1.75],[1,6.8,18.08]],"batl":[[9,920,2.1],[8,600,12.1],[7,440,2.12],[6,250,10],[5,100,2],[4,32,16.14],[3,20,14.92],[2,18,12.41]],"id":77728021}]}]}{"op":"mcm","clk":"APYkANMZAIQW","pt":1784528084233,"mc":[{"id":"1.260136803","rc":[{"batb":[[9,2.12,44.64],[8,3.05,24.39],[7,4.1,16.13],[6,4.6,2.88],[5,6.2,9.62],[4,16,3.2],[3,65,5.03],[2,70,2.6],[1,90,2.8]],"id":100721224},{"batl":[[9,250,10],[8,65,2],[7,44,7.36],[6,34,15],[5,32,16.14],[4,22,9.6],[3,21,11.17]],"id":100721218},{"batl":[[9,22,5.36],[8,18,3.05],[7,16,15],[6,8.4,5.82],[5,8.2,41.98],[4,7,11.17]],"id":100721219},{"batb":[[3,6.4,23.44]],"batl":[[9,600,12.1],[8,440,2.12],[7,250,10],[6,100,2],[5,32,16.14],[4,20,14.92],[3,19.5,6.45]],"id":77728021}]}]}{"op":"mcm","clk":"APckANQZAIQW","pt":1784528084236,"mc":[{"id":"1.260136658","rc":[{"trd":[[27,6.13]],"batb":[[9,18.5,6.54],[8,19,9.07],[7,19.5,6.7],[6,20,4.99],[5,21,6.15],[4,22,5.55],[3,23,4.05],[2,24,5.55],[1,25,2.08],[0,26,6.58]],"tv":36.12,"id":6690508},{"trd":[[1.88,8.66]],"batl":[[0,1.88,137.01]],"tv":1792.77,"id":5547183},{"trd":[[130,4.37]],"batb":[[9,3.05,24.39],[8,4.1,16.13],[7,4.6,2.88],[6,6.2,9.62],[5,16,4.47],[4,30,2],[3,46,5.8],[2,65,3.33],[1,90,1.08],[0,120,1.19]],"ltp":130,"tv":14.64,"id":99951973}],"tv":2667.01}]}{"op":"ocm","id":1,"clk":"AKMKAJ8KAKwTAPMTAOYL","pt":1784528084289,"ct":"HEARTBEAT"}{"op":"mcm","clk":"AP0kANgZAIgW","pt":1784528084341,"mc":[{"id":"1.260136658","rc":[{"batb":[[0,26,8.58]],"id":6690508},{"batb":[[0,120,3.19]],"id":99951973}]}]}{"op":"mcm","clk":"AIAlANoZAIsW","pt":1784528084438,"mc":[{"id":"1.260192491","rc":[{"batb":[[1,75,2.98]],"id":60010414},{"batb":[[9,2.12,5.36],[8,3.15,3.35]],"id":90458476},{"batb":[[2,32,5.6]],"id":43653174},{"batb":[[8,2.44,3.55]],"id":89353228},{"batb":[[6,1.27,2],[5,1.64,106.69],[4,1.71,285.01],[3,1.76,115.11],[2,1.77,86.91],[1,1.78,1]],"id":71121948}]}]}{"op":"mcm","clk":"AIQlAN4ZAI8W","pt":1784528084544,"mc":[{"id":"1.260192491","rc":[{"batb":[[9,1.8,7.5],[8,2.12,5.36],[7,3.15,3.35],[6,3.35,2],[5,3.5,32.56],[4,3.8,72.02],[3,3.85,22.91],[2,4.1,27.88]],"id":90458476}]}]}{"op":"mcm","clk":"AJMlAOsZAJ8W","pt":1784528084851,"mc":[{"id":"1.260136658","rc":[{"batb":[[9,7,17.01],[8,7.2,54.91],[7,7.4,12.11],[6,7.6,10.91],[5,7.8,26.09],[4,8,10.4],[3,8.4,13.28],[2,8.6,3.73],[1,8.8,1.1],[0,9,4.98]],"batl":[[5,11.5,4.9]],"id":100749630}]}]}{"op":"mcm","clk":"AJklAO8ZAKgW","pt":1784528084956,"mc":[{"id":"1.260136658","rc":[{"batl":[[9,24,5.13],[8,23,18.66],[7,22,3.99],[6,21,3.99],[5,20,3.99],[4,19.5,3.99],[3,19,1],[2,18.5,2.01],[1,18,6.78],[0,17.5,1.22]],"id":56407176},{"batb":[[9,7.2,54.91],[8,7.4,12.11],[7,7.6,10.91],[6,7.8,26.09],[5,8,10.28],[4,8.2,8.45]],"id":100749630}]}]}{"op":"mcm","clk":"AKclAPwZALIW","pt":1784528085357,"mc":[{"id":"1.260136658","rc":[{"batb":[[4,8.2,13.17]],"id":100749630}]}]}{"op":"mcm","clk":"AK8lAP8ZALUW","pt":1784528085463,"mc":[{"id":"1.260136803","rc":[{"batb":[[9,1.02,22],[8,1.12,100],[7,2.14,16.14],[6,2.3,83.79],[5,2.66,53.05],[4,2.76,9.23],[3,2.78,3.23],[2,2.9,118.13],[1,3.1,45.81],[0,3.15,1.87]],"id":100721219}]}]}{"op":"mcm","clk":"AL0lAIUaAMQW","pt":1784528085774,"mc":[{"id":"1.260192493","rc":[{"batb":[[1,46,1.32]],"id":44387351}]}]}{"op":"mcm","clk":"AMQlAIoaAMgW","pt":1784528085874,"mc":[{"id":"1.260192493","rc":[{"batb":[[9,32,1.61],[8,34,6.29],[7,36,1],[6,38,1.35],[5,40,16.14],[4,42,1.22],[3,44,5.84],[2,46,1.32],[1,50,3.02]],"id":44387351}]}]}{"op":"mcm","clk":"ANAlAJAaANQW","pt":1784528086128,"mc":[{"id":"1.260136658","rc":[{"batl":[[8,23,7.49]],"id":56407176}]}]}{"op":"mcm","clk":"ANUlAJMaANoW","pt":1784528086237,"mc":[{"id":"1.260136658","rc":[{"batl":[[7,22,15.16]],"id":56407176}]}]}{"op":"mcm","clk":"ANolAJYaAN0W","pt":1784528086384,"mc":[{"id":"1.260192491","rc":[{"batb":[[9,6.2,9.62],[8,12.5,1.04],[7,16,3],[6,17,1.04],[5,21,1.04],[4,30,2.29]],"id":60010414},{"batl":[[9,3.7,63.65],[8,3.4,45.13],[7,3.3,1],[6,3.25,1],[5,3.2,1],[4,3.15,1],[3,3.1,1],[2,3.05,1],[1,3,28.12]],"id":71121948}]}]}{"op":"mcm","clk":"AN8lAJsaAOEW","pt":1784528086488,"mc":[{"id":"1.260192334","rc":[{"batb":[[9,6.2,4],[8,6.4,2],[7,6.6,3.04],[6,6.8,36.77],[5,7,16.2],[4,7.2,1],[3,7.8,12.71],[2,8,12.42],[1,8.8,1.04]],"id":73793682}]}]}{"op":"mcm","clk":"AOQlAJ0aAOMW","pt":1784528086542,"mc":[{"id":"1.260136658","rc":[{"batl":[[7,44,2.99]],"id":6690508},{"batl":[[7,920,2.1],[6,600,12.1],[5,440,2.13],[4,260,1.22],[3,75,1],[2,70,1.21]],"id":69865836}]}]}{"op":"mcm","clk":"AOYlAJ4aAOUW","pt":1784528086549,"mc":[{"id":"1.260192334","rc":[{"batb":[[9,6.4,2],[8,6.6,3.04],[7,6.8,36.77],[6,7,16.2],[5,7.2,1],[4,7.8,12.71],[3,8,12.42],[2,8.2,2]],"id":73793682}]}]}{"op":"mcm","clk":"AOYlAJ8aAOUW","pt":1784528086549,"mc":[{"id":"1.260192491","rc":[{"batb":[[3,55,4.24]],"id":60010414}]}]}{"op":"mcm","clk":"AOslAKMaAOkW","pt":1784528086646,"mc":[{"id":"1.260136658","rc":[{"batb":[[0,70,3.33]],"id":74493797}]}]}{"op":"mcm","clk":"APUlAKgaAOoW","pt":1784528086754,"mc":[{"id":"1.260192491","rc":[{"batb":[[3,55,3.24]],"id":60010414}]},{"id":"1.260136658","rc":[{"batl":[[7,44,1.99]],"id":6690508},{"batb":[[9,1.6,78.94],[8,1.61,54.67],[7,1.71,388.12],[6,1.76,20.76],[5,1.78,151.41],[4,1.8,10.38],[3,1.81,18.17],[2,1.82,10.38],[1,1.85,97.77]],"id":5547183},{"batl":[[7,0,0],[6,0,0],[5,920,2.1],[4,600,12.1],[3,440,2.13],[2,260,1.43]],"id":69865836}]}]}{"op":"mcm","clk":"APslAKwaAO4W","pt":1784528086857,"mc":[{"id":"1.260192340","rc":[{"batb":[[0,8.4,1.19]],"id":62688374}]}]}{"op":"mcm","clk":"AJcmALcaAIEX","pt":1784528087360,"mc":[{"id":"1.260136658","rc":[{"batl":[[6,920,2.1],[5,600,12.1],[4,440,2.13],[3,260,1.22],[2,70,2.21]],"id":69865836}]}]}{"op":"mcm","clk":"AJ4mALkaAIYX","pt":1784528087462,"mc":[{"id":"1.260136658","rc":[{"batl":[[8,23,6.49]],"id":56407176},{"batb":[[9,7,17.01],[8,7.2,54.91],[7,7.4,12.11],[6,7.6,10.91],[5,7.8,26.09],[4,8,10.28],[3,8.2,13.17],[2,8.4,13.28],[1,8.6,3.73],[0,8.8,1.1]],"batl":[[5,11.5,2.9],[3,10.5,15.02]],"id":100749630},{"batl":[[1,65,1.76]],"id":69865836},{"batl":[[6,28,1]],"id":80934312},{"batl":[[1,580,1.23],[0,240,2.92]],"id":99951973},{"batl":[[1,8.4,10.9]],"id":79455963}]}]}{"op":"mcm","clk":"AK8mAMIaAI0X","pt":1784528087668,"mc":[{"id":"1.260136658","rc":[{"batl":[[0,9.6,6.18]],"id":100749630}]}]}{"op":"mcm","clk":"ALUmAMMaAJIX","pt":1784528087821,"mc":[{"id":"1.260136658","rc":[{"batb":[[0,16.5,2.94]],"id":56407176}]}]}{"op":"mcm","clk":"ALkmAMYaAJUX","pt":1784528087921,"mc":[{"id":"1.260136658","rc":[{"batb":[[0,70,3.58]],"id":74493797}]}]}{"op":"mcm","clk":"ALwmAMcaAJkX","pt":1784528088024,"mc":[{"id":"1.260136658","rc":[{"batb":[[0,7.6,3.93]],"id":79455963}]}]}{"op":"mcm","clk":"AL8mAMgaAJoX","pt":1784528088072,"mc":[{"id":"1.260192495","rc":[{"batb":[[9,1.51,98.04],[8,2.12,44.64],[7,3.05,24.39],[6,4.1,16.13],[5,4.6,2.88],[4,6.2,9.85],[3,120,5.29],[2,130,1],[1,140,2.6]],"id":25695674},{"batb":[[9,2.1,1],[8,2.12,45.64],[7,3.05,24.39],[6,4.1,16.13],[5,4.6,2.88],[4,6.2,9.85],[3,120,5.29],[2,130,1],[1,140,2.6]],"id":38138891}]}]}{"op":"mcm","clk":"AMAmAMoaAJ0X","pt":1784528088126,"mc":[{"id":"1.260136658","rc":[{"batb":[[0,26,9.21]],"id":6690508},{"batb":[[0,21,4.4]],"id":80934312}]}]}{"op":"mcm","clk":"AMMmAMoaAJ4X","pt":1784528088138,"mc":[{"id":"1.260136589","rc":[{"batl":[[9,90,1.56],[8,75,2],[7,44,7.36],[6,34,15],[5,18,12.34],[4,17.5,2],[3,15,17.48]],"id":62098141}]}]}{"op":"mcm","clk":"AMMmAMsaAJ4X","pt":1784528088173,"mc":[{"id":"1.260192495","rc":[{"batb":[[9,1.16,100],[8,1.51,98.04],[7,2.12,44.64],[6,3.05,24.39],[5,4.1,16.13],[4,4.6,2.88],[3,6.2,9.85],[2,120,5.29],[1,130,1],[0,140,3.11]],"id":25695674},{"batb":[[9,2.08,4],[8,2.1,1],[7,2.12,45.64],[6,3.05,24.39],[5,4.1,16.13],[4,4.6,2.88],[3,6.2,9.85],[2,120,5.29],[1,130,1],[0,140,3.11]],"id":38138891}]}]}{"op":"mcm","clk":"AMUmAMwaAJ8X","pt":1784528088228,"mc":[{"id":"1.260136658","rc":[{"batb":[[0,280,2.66]],"id":69161915},{"batb":[[0,21,5.9]],"batl":[[9,34,1],[8,32,1],[7,30,1],[6,29,1],[5,28,1],[4,27,5.78],[3,26,3.03],[2,25,2.31],[1,24,14.25],[0,23,28.9]],"id":80934312}]}]}{"op":"mcm","clk":"AMcmAMwaAKAX","pt":1784528088231,"mc":[{"id":"1.260136589","rc":[{"batl":[[9,75,2],[8,44,7.36],[7,34,15],[6,18,12.34],[5,17.5,2],[4,15,17.48],[3,13,11.17]],"id":62098141}]}]}{"op":"mcm","clk":"AM4mANIaAKcX","pt":1784528088337,"mc":[{"id":"1.260136658","rc":[{"batb":[[0,1.86,30.09]],"id":5547183},{"batl":[[0,110,2.2]],"id":74493797}]}]}{"op":"mcm","clk":"ANImANQaAKkX","pt":1784528088434,"mc":[{"id":"1.260136658","rc":[{"batb":[[0,16.5,2.06]],"id":98996178}]}]}{"op":"mcm","clk":"ANYmANwaAK4X","pt":1784528088539,"mc":[{"id":"1.260136658","rc":[{"batb":[[9,3.05,24.39],[8,4.1,16.13],[7,4.6,2.88],[6,6.2,10.14],[5,16,3],[4,30,2.41],[3,85,6.58],[2,140,1.59],[1,190,2.24],[0,200,1.07]],"id":78977433},{"batb":[[0,8.8,3.02]],"id":100749630}]}]}{"op":"mcm","clk":"ANkmAOAaALEX","pt":1784528088641,"mc":[{"id":"1.260136658","rc":[{"batb":[[0,46,2.96]],"id":69865836}]}]}{"op":"mcm","clk":"AN0mAOIaALQX","pt":1784528088744,"mc":[{"id":"1.260136658","rc":[{"batb":[[0,120,3.33]],"id":99951973}]}]}{"op":"mcm","clk":"AOomAOMaALkX","pt":1784528088853,"mc":[{"id":"1.260136589","rc":[{"batl":[[5,9.8,10.31]],"id":309962},{"batl":[[9,130,2],[8,70,3.04],[7,38,1],[6,36,14.29],[5,26,1],[4,25,1],[3,24,1.95],[2,23,2.66],[1,22,1.77],[0,21,15.34]],"id":82602855}]}]}{"op":"mcm","clk":"APEmAOoaAL0X","pt":1784528089055,"mc":[{"id":"1.260136658","rc":[{"batb":[[2,8.4,1.3]],"id":100749630}]}]}{"op":"mcm","clk":"APQmAOoaAL0X","pt":1784528089058,"mc":[{"id":"1.260137374","rc":[{"batb":[[9,15.5,3.45],[8,16,22.27],[7,16.5,3.23],[6,17,3.12],[5,17.5,3.03],[4,18,3.73],[3,19.5,9.19],[2,20,1],[1,21,1.42]],"id":82788200}]}]}{"op":"mcm","clk":"APgmAOsaAL4X","pt":1784528089153,"mc":[{"id":"1.260137374","rc":[{"batb":[[2,20,7.98]],"id":82788200}]}]}{"op":"ocm","id":1,"clk":"AI8LAL0KAMsUAOQUALYM","pt":1784528089289,"ct":"HEARTBEAT"}{"op":"mcm","clk":"AI0nAP8aAMYX","pt":1784528089566,"mc":[{"id":"1.260137374","rc":[{"batb":[[1,34,1.64]],"id":100720598}]}]}{"op":"mcm","clk":"AJEnAIAbAM0X","pt":1784528089666,"mc":[{"id":"1.260137374","rc":[{"batb":[[2,29,2.73],[1,30,4.16],[0,34,4.03]],"id":100720598}]}]}{"op":"mcm","clk":"AKAnAIUbANcX","pt":1784528090028,"mc":[{"id":"1.260136658","rc":[{"batb":[[0,21,6.75]],"id":80934312},{"trd":[[7.6,47.28]],"batb":[[0,7.6,2.92]],"ltp":7.6,"tv":350.98,"id":79455963}],"tv":2669.01}]}{"op":"mcm","clk":"AKMnAIYbANgX","pt":1784528090072,"mc":[{"id":"1.260192491","rc":[{"batl":[[0,390,4.51]],"id":43653174}]}]}{"op":"mcm","clk":"AKgnAIgbANoX","pt":1784528090180,"mc":[{"id":"1.260136658","rc":[{"batb":[[1,20,11.11]],"id":80934312}]}]}{"op":"mcm","clk":"AKknAIkbANoX","pt":1784528090186,"mc":[{"id":"1.260192491","rc":[{"batl":[[2,900,2.85]],"id":43653174}]}]}{"op":"mcm","clk":"AKwnAIwbAN0X","pt":1784528090277,"mc":[{"id":"1.260192491","rc":[{"batl":[[0,390,2.51]],"id":43653174}]}]}{"op":"mcm","clk":"ALAnAJEbAN8X","pt":1784528090382,"mc":[{"id":"1.260192491","rc":[{"batl":[[0,390,2.54]],"id":43653174}]}]}{"op":"mcm","clk":"ALwnAJgbAOUX","pt":1784528090644,"mc":[{"id":"1.260191969","rc":[{"batl":[[9,16,15],[8,8.4,2.19],[7,7.2,27.88],[6,5.8,1.52],[5,5.7,1],[4,5.5,34.1],[3,5.2,16.14],[2,4.7,16.28],[1,4.6,3.26],[0,3.65,10.9]],"id":67898814}]}]}{"op":"mcm","clk":"AL8nAJobAOcX","pt":1784528090743,"mc":[{"id":"1.260191969","rc":[{"batl":[[9,22,5.36],[8,16,15]],"id":67898814}]}]}{"op":"mcm","clk":"AMYnAKUbAO4X","pt":1784528090952,"mc":[{"id":"1.260136658","rc":[{"batl":[[5,28,4.03]],"id":80934312}]},{"id":"1.260136803","rc":[{"batb":[[7,40,2.28]],"id":100721222},{"batb":[[4,16,3],[3,46,5.55],[2,65,5.03]],"id":100721224},{"batb":[[9,1.51,98.04],[8,2.12,44.64],[7,2.6,3.75],[6,3.2,2.73]],"batl":[[4,28,15.97],[3,22,9.6],[2,21,11.69]],"id":100721218},{"batl":[[4,8,27.33],[3,7,11.17]],"id":100721219},{"batb":[[7,29,1.79]],"id":100721221},{"batb":[[8,13,4]],"batl":[[7,920,2.1],[6,600,12.1],[5,440,2.12],[4,250,10],[3,170,1],[2,130,2.17],[1,120,16.14],[0,110,11.61]],"id":99171722},{"batl":[[4,6.2,45.73],[3,5.3,57.9]],"id":94448588},{"batb":[[9,16,3],[8,28,7.65],[6,42,1.22]],"id":57883707},{"batl":[[9,920,2.1],[8,600,12.1],[7,440,2.12],[6,250,10],[5,100,2],[4,32,16.14],[3,20,14.92],[2,19.5,6.71]],"id":77728021}]}]}{"op":"mcm","clk":"AMknAKkbAPAX","pt":1784528091052,"mc":[{"id":"1.260136803","rc":[{"batb":[[9,2.12,44.64],[8,2.6,3.75],[7,3.2,2.73],[6,4.6,34.13]],"id":100721218},{"batl":[[9,600,12.1],[8,440,2.12],[7,250,10],[6,100,2],[5,32,16.14],[4,28,12.15]],"id":77728021}]}]}{"op":"mcm","clk":"AM4nAKsbAPMX","pt":1784528091160,"mc":[{"id":"1.260136803","rc":[{"batb":[[9,1.01,1154.83],[8,1.02,22],[7,1.12,100],[6,2.14,16.14],[5,2.3,83.79],[4,2.66,53.05]],"id":100721219}]}]}{"op":"mcm","clk":"AM4nAKwbAPYX","pt":1784528091165,"mc":[{"id":"1.260136658","rc":[{"batb":[[1,1.85,45.86]],"id":5547183},{"batl":[[0,970,1.53]],"id":69161915}]}]}{"op":"mcm","clk":"ANAnAK4bAPoX","pt":1784528091260,"mc":[{"id":"1.260136658","rc":[{"batl":[[0,970,1.71]],"id":69161915}]}]}{"op":"mcm","clk":"AOMnALkbAIMY","pt":17845280